ts_recv,ts_event,rtype,publisher_id,instrument_id,action,side,depth,price,size,flags,ts_in_delta,sequence,bid_px_00,bid_sz_00,bid_ct_00,bid_px_01,bid_sz_01,bid_ct_01,bid_px_02,bid_sz_02,bid_ct_02,bid_px_03,bid_sz_03,bid_ct_03,bid_px_04,bid_sz_04,bid_ct_04,bid_px_05,bid_sz_05,bid_ct_05,bid_px_06,bid_sz_06,bid_ct_06,bid_px_07,bid_sz_07,bid_ct_07,bid_px_08,bid_sz_08,bid_ct_08,bid_px_09,bid_sz_09,bid_ct_09,ask_px_00,ask_sz_00,ask_ct_00,ask_px_01,ask_sz_01,ask_ct_01,ask_px_02,ask_sz_02,ask_ct_02,ask_px_03,ask_sz_03,ask_ct_03,ask_px_04,ask_sz_04,ask_ct_04,ask_px_05,ask_sz_05,ask_ct_05,ask_px_06,ask_sz_06,ask_ct_06,ask_px_07,ask_sz_07,ask_ct_07,ask_px_08,ask_sz_08,ask_ct_08,ask_px_09,ask_sz_09,ask_ct_09,symbol,order_id
2025-07-17T13:46:10.904858553Z,2025-07-17T13:46:10.904693578Z,10,2,1108,C,A,10,14.760000000,100,84618189,164975,69628783,12.99,100,1,12.73,100,1,12.67,100,1,12.43,666,1,11.69,2,1,11.52,100,1,11.29,100,1,11.24,100,1,11.05,100,1,11.01,100,1,13.40,0,-10,13.78,0,-1,13.93,0,-2,13.94,0,-1,14.20,0,-2,14.21,0,-1,14.26,0,-1,14.27,0,-1,14.28,0,-1,14.29,0,-4,ARL,0
2025-07-17T13:46:11.840882444Z,2025-07-17T13:46:11.840717150Z,10,2,1108,A,A,10,14.870000000,100,84708037,165294,69663346,12.99,100,1,12.73,100,1,12.67,100,1,12.43,666,1,11.69,2,1,11.52,100,1,11.29,100,1,11.24,100,1,11.05,100,1,11.01,100,1,13.40,0,-10,13.78,0,-1,13.93,0,-2,13.94,0,-1,14.20,0,-2,14.21,0,-1,14.26,0,-1,14.27,0,-1,14.28,0,-1,14.29,0,-4,ARL,0
2025-07-17T13:46:11.840894787Z,2025-07-17T13:46:11.840729407Z,10,2,1108,C,A,10,14.480000000,100,84624129,165380,69663347,12.99,100,1,12.73,100,1,12.67,100,1,12.43,666,1,11.69,2,1,11.52,100,1,11.29,100,1,11.24,100,1,11.05,100,1,11.01,100,1,13.40,0,-10,13.78,0,-1,13.93,0,-2,13.94,0,-1,14.20,0,-2,14.21,0,-1,14.26,0,-1,14.27,0,-1,14.28,0,-1,14.29,0,-4,ARL,0
2025-07-17T13:46:23.920813185Z,2025-07-17T13:46:23.920647302Z,10,2,1108,C,B,10,12.880000000,2,58709193,165883,70104076,12.99,100,1,12.73,100,1,12.67,100,1,12.43,666,1,11.69,2,1,11.52,100,1,11.29,100,1,11.24,100,1,11.05,100,1,11.01,100,1,13.40,0,-10,13.78,0,-1,13.93,0,-2,13.94,0,-1,14.20,0,-2,14.21,0,-1,14.26,0,-1,14.27,0,-1,14.28,0,-1,14.29,0,-4,ARL,0
2025-07-17T13:46:23.920813185Z,2025-07-17T13:46:23.920647302Z,10,2,1108,A,B,10,13.120000000,2,85194077,165883,70104076,13.12,2,1,12.99,100,1,12.73,100,1,12.67,100,1,12.43,666,1,11.69,2,1,11.52,100,1,11.29,100,1,11.24,100,1,11.05,100,1,13.40,0,-10,13.78,0,-1,13.93,0,-2,13.94,0,-1,14.20,0,-2,14.21,0,-1,14.26,0,-1,14.27,0,-1,14.28,0,-1,14.29,0,-4,ARL,0
2025-07-17T13:46:45.786579604Z,2025-07-17T13:46:45.786413307Z,10,2,1108,C,B,10,13.120000000,2,85194077,166297,70834235,12.99,100,1,12.73,100,1,12.67,100,1,12.43,666,1,11.69,2,1,11.52,100,1,11.29,100,1,11.24,100,1,11.05,100,1,11.01,100,1,13.40,0,-10,13.78,0,-1,13.93,0,-2,13.94,0,-1,14.20,0,-2,14.21,0,-1,14.26,0,-1,14.27,0,-1,14.28,0,-1,14.29,0,-4,ARL,0
2025-07-17T13:46:45.786579604Z,2025-07-17T13:46:45.786413307Z,10,2,1108,A,B,10,13.200000000,2,86056033,166297,70834235,13.20,2,1,12.99,100,1,12.73,100,1,12.67,100,1,12.43,666,1,11.69,2,1,11.52,100,1,11.29,100,1,11.24,100,1,11.05,100,1,13.40,0,-10,13.78,0,-1,13.93,0,-2,13.94,0,-1,14.20,0,-2,14.21,0,-1,14.26,0,-1,14.27,0,-1,14.28,0,-1,14.29,0,-4,ARL,0
2025-07-17T13:47:34.987167177Z,2025-07-17T13:47:34.987001473Z,10,2,1108,C,B,10,13.200000000,2,86056033,165704,72269967,12.99,100,1,12.73,100,1,12.67,100,1,12.43,666,1,11.69,2,1,11.52,100,1,11.29,100,1,11.24,100,1,11.05,100,1,11.01,100,1,13.40,0,-10,13.78,0,-1,13.93,0,-2,13.94,0,-1,14.20,0,-2,14.21,0,-1,14.26,0,-1,14.27,0,-1,14.28,0,-1,14.29,0,-4,ARL,0
2025-07-17T13:47:34.987167177Z,2025-07-17T13:47:34.987001473Z,10,2,1108,A,B,10,13.260000000,2,87750309,165704,72269967,13.26,2,1,12.99,100,1,12.73,100,1,12.67,100,1,12.43,666,1,11.69,2,1,11.52,100,1,11.29,100,1,11.24,100,1,11.05,100,1,13.40,0,-10,13.78,0,-1,13.93,0,-2,13.94,0,-1,14.20,0,-2,14.21,0,-1,14.26,0,-1,14.27,0,-1,14.28,0,-1,14.29,0,-4,ARL,0
2025-07-17T13:49:46.533586484Z,2025-07-17T13:49:46.533420775Z,10,2,1108,C,A,10,14.300000000,100,77910357,165709,76393090,12.99,100,1,12.73,100,1,12.67,100,1,12.43,666,1,11.69,2,1,11.52,100,1,11.29,100,1,11.24,100,1,11.05,100,1,11.01,100,1,13.40,0,-10,13.78,0,-1,13.93,0,-2,13.94,0,-1,14.20,0,-2,14.21,0,-1,14.26,0,-1,14.27,0,-1,14.28,0,-1,14.29,0,-4,ARL,0
2025-07-17T13:49:46.533586484Z,2025-07-17T13:49:46.533420775Z,10,2,1108,A,A,10,15.260000000,100,92510725,165709,76393090,12.99,100,1,12.73,100,1,12.67,100,1,12.43,666,1,11.69,2,1,11.52,100,1,11.29,100,1,11.24,100,1,11.05,100,1,11.01,100,1,13.40,0,-10,13.78,0,-1,13.93,0,-2,13.94,0,-1,14.20,0,-2,14.21,0,-1,14.26,0,-1,14.27,0,-1,14.28,0,-1,14.29,0,-4,ARL,0
2025-07-17T13:49:46.533732414Z,2025-07-17T13:49:46.533566805Z,10,2,1108,C,A,10,14.300000000,100,74589605,165609,76393092,12.99,100,1,12.73,100,1,12.67,100,1,12.43,666,1,11.69,2,1,11.52,100,1,11.29,100,1,11.24,100,1,11.05,100,1,11.01,100,1,13.40,0,-10,13.78,0,-1,13.93,0,-2,13.94,0,-1,14.20,0,-2,14.21,0,-1,14.26,0,-1,14.27,0,-1,14.28,0,-1,14.29,0,-4,ARL,0
2025-07-17T13:49:46.533732414Z,2025-07-17T13:49:46.533566805Z,10,2,1108,A,A,10,15.260000000,100,92510729,165609,76393092,12.99,100,1,12.73,100,1,12.67,100,1,12.43,666,1,11.69,2,1,11.52,100,1,11.29,100,1,11.24,100,1,11.05,100,1,11.01,100,1,13.40,0,-10,13.78,0,-1,13.93,0,-2,13.94,0,-1,14.20,0,-2,14.21,0,-1,14.26,0,-1,14.27,0,-1,14.28,0,-1,14.29,0,-4,ARL,0
2025-07-17T13:49:46.533768662Z,2025-07-17T13:49:46.533603070Z,10,2,1108,C,A,10,14.910000000,700,84628761,165592,76393093,12.99,100,1,12.73,100,1,12.67,100,1,12.43,666,1,11.69,2,1,11.52,100,1,11.29,100,1,11.24,100,1,11.05,100,1,11.01,100,1,13.40,0,-10,13.78,0,-1,13.93,0,-2,13.94,0,-1,14.20,0,-2,14.21,0,-1,14.26,0,-1,14.27,0,-1,14.28,0,-1,14.29,0,-4,ARL,0
2025-07-17T13:49:46.533810238Z,2025-07-17T13:49:46.533644528Z,10,2,1108,A,A,10,15.070000000,700,92510741,165710,76393094,12.99,100,1,12.73,100,1,12.67,100,1,12.43,666,1,11.69,2,1,11.52,100,1,11.29,100,1,11.24,100,1,11.05,100,1,11.01,100,1,13.40,0,-10,13.78,0,-1,13.93,0,-2,13.94,0,-1,14.20,0,-2,14.21,0,-1,14.26,0,-1,14.27,0,-1,14.28,0,-1,14.29,0,-4,ARL,0
2025-07-17T13:49:46.534488891Z,2025-07-17T13:49:46.534323177Z,10,2,1108,C,A,10,15.410000000,100,84630217,165714,76393099,12.99,100,1,12.73,100,1,12.67,100,1,12.43,666,1,11.69,2,1,11.52,100,1,11.29,100,1,11.24,100,1,11.05,100,1,11.01,100,1,13.40,0,-10,13.78,0,-1,13.93,0,-2,13.94,0,-1,14.20,0,-2,14.21,0,-1,14.26,0,-1,14.27,0,-1,14.28,0,-1,14.29,0,-4,ARL,0
2025-07-17T13:49:46.534488891Z,2025-07-17T13:49:46.534323177Z,10,2,1108,A,A,10,15.460000000,100,92510753,165714,76393099,12.99,100,1,12.73,100,1,12.67,100,1,12.43,666,1,11.69,2,1,11.52,100,1,11.29,100,1,11.24,100,1,11.05,100,1,11.01,100,1,13.40,0,-10,13.78,0,-1,13.93,0,-2,13.94,0,-1,14.20,0,-2,14.21,0,-1,14.26,0,-1,14.27,0,-1,14.28,0,-1,14.29,0,-4,ARL,0
2025-07-17T13:49:46.534555834Z,2025-07-17T13:49:46.534390219Z,10,2,1108,C,A,10,15.200000000,100,84628801,165615,76393100,12.99,100,1,12.73,100,1,12.67,100,1,12.43,666,1,11.69,2,1,11.52,100,1,11.29,100,1,11.24,100,1,11.05,100,1,11.01,100,1,13.40,0,-10,13.78,0,-1,13.93,0,-2,13.94,0,-1,14.20,0,-2,14.21,0,-1,14.26,0,-1,14.27,0,-1,14.28,0,-1,14.29,0,-4,ARL,0
2025-07-17T13:49:46.534555834Z,2025-07-17T13:49:46.534390219Z,10,2,1108,A,A,10,15.360000000,100,92510761,165615,76393100,12.99,100,1,12.73,100,1,12.67,100,1,12.43,666,1,11.69,2,1,11.52,100,1,11.29,100,1,11.24,100,1,11.05,100,1,11.01,100,1,13.40,0,-10,13.78,0,-1,13.93,0,-2,13.94,0,-1,14.20,0,-2,14.21,0,-1,14.26,0,-1,14.27,0,-1,14.28,0,-1,14.29,0,-4,ARL,0
2025-07-17T13:49:46.535182699Z,2025-07-17T13:49:46.535017084Z,10,2,1108,C,A,10,16.350000000,100,84629065,165615,76393115,12.99,100,1,12.73,100,1,12.67,100,1,12.43,666,1,11.69,2,1,11.52,100,1,11.29,100,1,11.24,100,1,11.05,100,1,11.01,100,1,13.40,0,-10,13.78,0,-1,13.93,0,-2,13.94,0,-1,14.20,0,-2,14.21,0,-1,14.26,0,-1,14.27,0,-1,14.28,0,-1,14.29,0,-4,ARL,0
2025-07-17T13:49:46.535182699Z,2025-07-17T13:49:46.535017084Z,10,2,1108,A,A,10,16.510000000,100,92510813,165615,76393115,12.99,100,1,12.73,100,1,12.67,100,1,12.43,666,1,11.69,2,1,11.52,100,1,11.29,100,1,11.24,100,1,11.05,100,1,11.01,100,1,13.40,0,-10,13.78,0,-1,13.93,0,-2,13.94,0,-1,14.20,0,-2,14.21,0,-1,14.26,0,-1,14.27,0,-1,14.28,0,-1,14.29,0,-4,ARL,0
2025-07-17T13:49:46.535737854Z,2025-07-17T13:49:46.535572067Z,10,2,1108,C,A,10,18.050000000,100,84628913,165787,76393138,12.99,100,1,12.73,100,1,12.67,100,1,12.43,666,1,11.69,2,1,11.52,100,1,11.29,100,1,11.24,100,1,11.05,100,1,11.01,100,1,13.40,0,-10,13.78,0,-1,13.93,0,-2,13.94,0,-1,14.20,0,-2,14.21,0,-1,14.26,0,-1,14.27,0,-1,14.28,0,-1,14.29,0,-4,ARL,0
2025-07-17T13:49:46.535737854Z,2025-07-17T13:49:46.535572067Z,10,2,1108,A,A,10,18.230000000,100,92510841,165787,76393138,12.99,100,1,12.73,100,1,12.67,100,1,12.43,666,1,11.69,2,1,11.52,100,1,11.29,100,1,11.24,100,1,11.05,100,1,11.01,100,1,13.40,0,-10,13.78,0,-1,13.93,0,-2,13.94,0,-1,14.20,0,-2,14.21,0,-1,14.26,0,-1,14.27,0,-1,14.28,0,-1,14.29,0,-4,ARL,0
2025-07-17T13:56:11.001810226Z,2025-07-17T13:56:11.001642441Z,10,2,1108,A,B,10,13.280000000,1,107702381,167785,89819278,13.28,1,1,12.99,100,1,12.73,100,1,12.67,100,1,12.43,666,1,11.69,2,1,11.52,100,1,11.29,100,1,11.24,100,1,11.05,100,1,13.40,0,-10,13.78,0,-1,13.93,0,-2,13.94,0,-1,14.20,0,-2,14.21,0,-1,14.26,0,-1,14.27,0,-1,14.28,0,-1,14.29,0,-4,ARL,0
2025-07-17T13:56:11.005550129Z,2025-07-17T13:56:11.005384065Z,10,2,1108,A,B,10,13.280000000,10,107702861,166064,89819705,13.28,11,2,12.99,100,1,12.73,100,1,12.67,100,1,12.43,666,1,11.69,2,1,11.52,100,1,11.29,100,1,11.24,100,1,11.05,100,1,13.40,0,-10,13.78,0,-1,13.93,0,-2,13.94,0,-1,14.20,0,-2,14.21,0,-1,14.26,0,-1,14.27,0,-1,14.28,0,-1,14.29,0,-4,ARL,0
2025-07-17T13:56:11.005550669Z,2025-07-17T13:56:11.005385425Z,10,2,1108,A,A,10,13.940000000,10,107702865,165244,89819706,13.28,11,2,12.99,100,1,12.73,100,1,12.67,100,1,12.43,666,1,11.69,2,1,11.52,100,1,11.29,100,1,11.24,100,1,11.05,100,1,13.40,0,-10,13.78,0,-1,13.93,0,-2,13.94,0,-1,14.20,0,-2,14.21,0,-1,14.26,0,-1,14.27,0,-1,14.28,0,-1,14.29,0,-4,ARL,0
2025-07-17T13:56:11.013819857Z,2025-07-17T13:56:11.013654317Z,10,2,1108,C,A,10,15.260000000,100,92510729,165540,89820163,13.28,11,2,12.99,100,1,12.73,100,1,12.67,100,1,12.43,666,1,11.69,2,1,11.52,100,1,11.29,100,1,11.24,100,1,11.05,100,1,13.40,0,-10,13.78,0,-1,13.93,0,-2,13.94,0,-2,14.20,0,-2,14.21,0,-1,14.26,0,-1,14.27,0,-1,14.28,0,-1,14.29,0,-4,ARL,0
2025-07-17T13:56:11.013819857Z,2025-07-17T13:56:11.013654317Z,10,2,1108,A,A,10,14.840000000,100,107703205,165540,89820163,13.28,11,2,12.99,100,1,12.73,100,1,12.67,100,1,12.43,666,1,11.69,2,1,11.52,100,1,11.29,100,1,11.24,100,1,11.05,100,1,13.40,0,-10,13.78,0,-1,13.93,0,-2,13.94,0,-2,14.20,0,-2,14.21,0,-1,14.26,0,-1,14.27,0,-1,14.28,0,-1,14.29,0,-4,ARL,0
2025-07-17T13:56:11.026680779Z,2025-07-17T13:56:11.026515306Z,10,2,1108,C,A,10,15.260000000,100,92510725,165473,89820408,13.28,11,2,12.99,100,1,12.73,100,1,12.67,100,1,12.43,666,1,11.69,2,1,11.52,100,1,11.29,100,1,11.24,100,1,11.05,100,1,13.40,0,-10,13.78,0,-1,13.93,0,-2,13.94,0,-2,14.20,0,-2,14.21,0,-1,14.26,0,-1,14.27,0,-1,14.28,0,-1,14.29,0,-4,ARL,0
2025-07-17T13:56:11.026680779Z,2025-07-17T13:56:11.026515306Z,10,2,1108,A,A,10,14.840000000,100,107703433,165473,89820408,13.28,11,2,12.99,100,1,12.73,100,1,12.67,100,1,12.43,666,1,11.69,2,1,11.52,100,1,11.29,100,1,11.24,100,1,11.05,100,1,13.40,0,-10,13.78,0,-1,13.93,0,-2,13.94,0,-2,14.20,0,-2,14.21,0,-1,14.26,0,-1,14.27,0,-1,14.28,0,-1,14.29,0,-4,ARL,0
2025-07-17T13:56:11.101916770Z,2025-07-17T13:56:11.101751649Z,10,2,1108,C,B,10,13.280000000,1,107702381,165121,89823845,13.28,11,2,12.99,100,1,12.73,100,1,12.67,100,1,12.43,666,1,11.69,2,1,11.52,100,1,11.29,100,1,11.24,100,1,11.05,100,1,13.40,0,-10,13.78,0,-1,13.93,0,-2,13.94,0,-2,14.20,0,-2,14.21,0,-1,14.26,0,-1,14.27,0,-1,14.28,0,-1,14.29,0,-4,ARL,0
2025-07-17T13:56:19.511755342Z,2025-07-17T13:56:19.511590204Z,10,2,1108,C,B,10,13.280000000,10,107702861,165138,90148349,13.28,11,2,12.99,100,1,12.73,100,1,12.67,100,1,12.43,666,1,11.69,2,1,11.52,100,1,11.29,100,1,11.24,100,1,11.05,100,1,13.40,0,-10,13.78,0,-1,13.93,0,-2,13.94,0,-2,14.20,0,-2,14.21,0,-1,14.26,0,-1,14.27,0,-1,14.28,0,-1,14.29,0,-4,ARL,0
2025-07-17T13:56:22.512134723Z,2025-07-17T13:56:22.511968820Z,10,2,1108,C,A,10,13.940000000,10,107702865,165903,90281309,13.28,11,2,12.99,100,1,12.73,100,1,12.67,100,1,12.43,666,1,11.69,2,1,11.52,100,1,11.29,100,1,11.24,100,1,11.05,100,1,13.40,0,-10,13.78,0,-1,13.93,0,-2,13.94,0,-2,14.20,0,-2,14.21,0,-1,14.26,0,-1,14.27,0,-1,14.28,0,-1,14.29,0,-4,ARL,0
2025-07-17T13:56:22.517155918Z,2025-07-17T13:56:22.516990420Z,10,2,1108,C,A,10,14.840000000,100,107703205,165498,90281853,13.28,11,2,12.99,100,1,12.73,100,1,12.67,100,1,12.43,666,1,11.69,2,1,11.52,100,1,11.29,100,1,11.24,100,1,11.05,100,1,13.40,0,-10,13.78,0,-1,13.93,0,-2,13.94,0,-2,14.20,0,-2,14.21,0,-1,14.26,0,-1,14.27,0,-1,14.28,0,-1,14.29,0,-4,ARL,0
2025-07-17T13:56:22.517155918Z,2025-07-17T13:56:22.516990420Z,10,2,1108,A,A,10,15.260000000,100,108217045,165498,90281853,13.28,11,2,12.99,100,1,12.73,100,1,12.67,100,1,12.43,666,1,11.69,2,1,11.52,100,1,11.29,100,1,11.24,100,1,11.05,100,1,13.40,0,-10,13.78,0,-1,13.93,0,-2,13.94,0,-2,14.20,0,-2,14.21,0,-1,14.26,0,-1,14.27,0,-1,14.28,0,-1,14.29,0,-4,ARL,0
2025-07-17T13:56:22.517527654Z,2025-07-17T13:56:22.517362170Z,10,2,1108,C,A,10,14.840000000,100,107703433,165484,90281893,13.28,11,2,12.99,100,1,12.73,100,1,12.67,100,1,12.43,666,1,11.69,2,1,11.52,100,1,11.29,100,1,11.24,100,1,11.05,100,1,13.40,0,-10,13.78,0,-1,13.93,0,-2,13.94,0,-2,14.20,0,-2,14.21,0,-1,14.26,0,-1,14.27,0,-1,14.28,0,-1,14.29,0,-4,ARL,0
2025-07-17T13:56:22.517527654Z,2025-07-17T13:56:22.517362170Z,10,2,1108,A,A,10,15.260000000,100,108217173,165484,90281893,13.28,11,2,12.99,100,1,12.73,100,1,12.67,100,1,12.43,666,1,11.69,2,1,11.52,100,1,11.29,100,1,11.24,100,1,11.05,100,1,13.40,0,-10,13.78,0,-1,13.93,0,-2,13.94,0,-2,14.20,0,-2,14.21,0,-1,14.26,0,-1,14.27,0,-1,14.28,0,-1,14.29,0,-4,ARL,0
2025-07-17T13:56:40.757800894Z,2025-07-17T13:56:40.757635216Z,10,2,1108,C,A,10,14.200000000,2,84628773,165678,90866180,13.28,11,2,12.99,100,1,12.73,100,1,12.67,100,1,12.43,666,1,11.69,2,1,11.52,100,1,11.29,100,1,11.24,100,1,11.05,100,1,13.40,0,-10,13.78,0,-1,13.93,0,-2,13.94,0,-2,14.20,0,-2,14.21,0,-1,14.26,0,-1,14.27,0,-1,14.28,0,-1,14.29,0,-4,ARL,0
2025-07-17T13:56:40.757800894Z,2025-07-17T13:56:40.757635216Z,10,2,1108,A,A,10,14.360000000,2,108872153,165678,90866180,13.28,11,2,12.99,100,1,12.73,100,1,12.67,100,1,12.43,666,1,11.69,2,1,11.52,100,1,11.29,100,1,11.24,100,1,11.05,100,1,13.40,0,-10,13.78,0,-1,13.93,0,-2,13.94,0,-2,14.20,0,-2,14.21,0,-1,14.26,0,-1,14.27,0,-1,14.28,0,-1,14.29,0,-4,ARL,0
2025-07-17T13:57:40.142022323Z,2025-07-17T13:57:40.141855674Z,10,2,1108,C,B,10,13.260000000,2,87750309,166649,92821039,13.28,11,2,12.99,100,1,12.73,100,1,12.67,100,1,12.43,666,1,11.69,2,1,11.52,100,1,11.29,100,1,11.24,100,1,11.05,100,1,13.40,0,-10,13.78,0,-1,13.93,0,-2,13.94,0,-2,14.20,0,-2,14.21,0,-1,14.26,0,-1,14.27,0,-1,14.28,0,-1,14.29,0,-4,ARL,0
2025-07-17T13:57:40.142022323Z,2025-07-17T13:57:40.141855674Z,10,2,1108,A,B,10,13.120000000,2,111169049,166649,92821039,13.28,11,2,13.12,2,1,12.99,100,1,12.73,100,1,12.67,100,1,12.43,666,1,11.69,2,1,11.52,100,1,11.29,100,1,11.24,100,1,13.40,0,-10,13.78,0,-1,13.93,0,-2,13.94,0,-2,14.20,0,-2,14.21,0,-1,14.26,0,-1,14.27,0,-1,14.28,0,-1,14.29,0,-4,ARL,0
2025-07-17T13:57:44.947757237Z,2025-07-17T13:57:44.947591620Z,10,2,1108,C,A,10,14.360000000,2,108872153,165617,92961696,13.28,11,2,12.99,100,1,12.73,100,1,12.67,100,1,12.43,666,1,11.69,2,1,11.52,100,1,11.29,100,1,11.24,100,1,11.05,100,1,13.40,0,-10,13.78,0,-1,13.93,0,-2,13.94,0,-2,14.20,0,-2,14.21,0,-1,14.26,0,-1,14.27,0,-1,14.28,0,-1,14.29,0,-4,ARL,0
2025-07-17T13:57:44.947757237Z,2025-07-17T13:57:44.947591620Z,10,2,1108,A,A,10,14.500000000,2,111347121,165617,92961696,13.28,11,2,12.99,100,1,12.73,100,1,12.67,100,1,12.43,666,1,11.69,2,1,11.52,100,1,11.29,100,1,11.24,100,1,11.05,100,1,13.40,0,-10,13.78,0,-1,13.93,0,-2,13.94,0,-2,14.20,0,-2,14.21,0,-1,14.26,0,-1,14.27,0,-1,14.28,0,-1,14.29,0,-4,ARL,0
2025-07-17T13:59:50.477911158Z,2025-07-17T13:59:50.477745739Z,10,2,1108,C,B,10,13.250000000,11,44586753,165419,96389796,13.28,11,2,12.99,100,1,12.73,100,1,12.67,100,1,12.43,666,1,11.69,2,1,11.52,100,1,11.29,100,1,11.24,100,1,11.05,100,1,13.40,0,-10,13.78,0,-1,13.93,0,-2,13.94,0,-2,14.20,0,-2,14.21,0,-1,14.26,0,-1,14.27,0,-1,14.28,0,-1,14.29,0,-4,ARL,0
2025-07-17T13:59:50.479576984Z,2025-07-17T13:59:50.479411482Z,10,2,1108,C,B,10,12.360000000,100,43787977,165502,96389821,13.28,11,2,12.99,100,1,12.73,100,1,12.67,100,1,12.43,666,1,11.69,2,1,11.52,100,1,11.29,100,1,11.24,100,1,11.05,100,1,13.40,0,-10,13.78,0,-1,13.93,0,-2,13.94,0,-2,14.20,0,-2,14.21,0,-1,14.26,0,-1,14.27,0,-1,14.28,0,-1,14.29,0,-4,ARL,0
2025-07-17T13:59:50.479576984Z,2025-07-17T13:59:50.479411482Z,10,2,1108,A,B,10,12.510000000,100,115474337,165502,96389821,13.28,11,2,12.99,100,1,12.73,100,1,12.67,100,1,12.51,100,1,12.43,666,1,11.69,2,1,11.52,100,1,11.29,100,1,11.24,100,1,13.40,0,-10,13.78,0,-1,13.93,0,-2,13.94,0,-2,14.20,0,-2,14.21,0,-1,14.26,0,-1,14.27,0,-1,14.28,0,-1,14.29,0,-4,ARL,0
2025-07-17T13:59:50.480863637Z,2025-07-17T13:59:50.480698233Z,10,2,1108,C,B,10,12.360000000,100,43781537,165404,96389845,13.28,11,2,12.99,100,1,12.73,100,1,12.67,100,1,12.43,666,1,11.69,2,1,11.52,100,1,11.29,100,1,11.24,100,1,11.05,100,1,13.40,0,-10,13.78,0,-1,13.93,0,-2,13.94,0,-2,14.20,0,-2,14.21,0,-1,14.26,0,-1,14.27,0,-1,14.28,0,-1,14.29,0,-4,ARL,0
2025-07-17T13:59:50.480863637Z,2025-07-17T13:59:50.480698233Z,10,2,1108,A,B,10,12.510000000,100,115474357,165404,96389845,13.28,11,2,12.99,100,1,12.73,100,1,12.67,100,1,12.51,100,1,12.43,666,1,11.69,2,1,11.52,100,1,11.29,100,1,11.24,100,1,13.40,0,-10,13.78,0,-1,13.93,0,-2,13.94,0,-2,14.20,0,-2,14.21,0,-1,14.26,0,-1,14.27,0,-1,14.28,0,-1,14.29,0,-4,ARL,0
2025-07-17T14:00:00.063037446Z,2025-07-17T14:00:00.062872132Z,10,2,1108,A,B,10,13.110000000,100,115813253,165314,96673952,13.28,11,2,13.11,100,1,12.99,100,1,12.73,100,1,12.67,100,1,12.51,100,1,12.43,666,1,11.69,2,1,11.52,100,1,11.29,100,1,13.40,0,-10,13.78,0,-1,13.93,0,-2,13.94,0,-2,14.20,0,-2,14.21,0,-1,14.26,0,-1,14.27,0,-1,14.28,0,-1,14.29,0,-4,ARL,0
2025-07-17T14:00:00.063056200Z,2025-07-17T14:00:00.062890891Z,10,2,1108,A,A,10,14.510000000,100,115813261,165309,96673954,13.28,11,2,13.11,100,1,12.99,100,1,12.73,100,1,12.67,100,1,12.51,100,1,12.43,666,1,11.69,2,1,11.52,100,1,11.29,100,1,13.40,0,-10,13.78,0,-1,13.93,0,-2,13.94,0,-2,14.20,0,-2,14.21,0,-1,14.26,0,-1,14.27,0,-1,14.28,0,-1,14.29,0,-4,ARL,0
2025-07-17T14:02:01.157985602Z,2025-07-17T14:02:01.157819863Z,10,2,1108,C,B,10,13.120000000,2,111169049,165739,101310413,13.28,11,2,13.11,100,1,12.99,100,1,12.73,100,1,12.67,100,1,12.51,100,1,12.43,666,1,11.69,2,1,11.52,100,1,11.29,100,1,13.40,0,-10,13.78,0,-1,13.93,0,-2,13.94,0,-2,14.20,0,-2,14.21,0,-1,14.26,0,-1,14.27,0,-1,14.28,0,-1,14.29,0,-4,ARL,0
2025-07-17T14:02:01.157985602Z,2025-07-17T14:02:01.157819863Z,10,2,1108,A,B,10,13.260000000,2,121098337,165739,101310413,13.28,11,2,13.26,2,1,13.11,100,1,12.99,100,1,12.73,100,1,12.67,100,1,12.51,100,1,12.43,666,1,11.69,2,1,11.52,100,1,13.40,0,-10,13.78,0,-1,13.93,0,-2,13.94,0,-2,14.20,0,-2,14.21,0,-1,14.26,0,-1,14.27,0,-1,14.28,0,-1,14.29,0,-4,ARL,0
2025-07-17T14:02:01.157986499Z,2025-07-17T14:02:01.157820985Z,10,2,1108,C,A,10,14.500000000,2,111347121,165514,101310414,13.28,11,2,13.11,100,1,12.99,100,1,12.73,100,1,12.67,100,1,12.51,100,1,12.43,666,1,11.69,2,1,11.52,100,1,11.29,100,1,13.40,0,-10,13.78,0,-1,13.93,0,-2,13.94,0,-2,14.20,0,-2,14.21,0,-1,14.26,0,-1,14.27,0,-1,14.28,0,-1,14.29,0,-4,ARL,0
2025-07-17T14:02:01.157986499Z,2025-07-17T14:02:01.157820985Z,10,2,1108,A,A,10,14.360000000,2,121098341,165514,101310414,13.28,11,2,13.11,100,1,12.99,100,1,12.73,100,1,12.67,100,1,12.51,100,1,12.43,666,1,11.69,2,1,11.52,100,1,11.29,100,1,13.40,0,-10,13.78,0,-1,13.93,0,-2,13.94,0,-2,14.20,0,-2,14.21,0,-1,14.26,0,-1,14.27,0,-1,14.28,0,-1,14.29,0,-4,ARL,0
2025-07-17T14:02:01.283528838Z,2025-07-17T14:02:01.283363185Z,10,2,1108,C,B,10,13.110000000,100,115813253,165653,101317376,13.28,11,2,13.11,100,1,12.99,100,1,12.73,100,1,12.67,100,1,12.51,100,1,12.43,666,1,11.69,2,1,11.52,100,1,11.29,100,1,13.40,0,-10,13.78,0,-1,13.93,0,-2,13.94,0,-2,14.20,0,-2,14.21,0,-1,14.26,0,-1,14.27,0,-1,14.28,0,-1,14.29,0,-4,ARL,0
2025-07-17T14:02:01.283528838Z,2025-07-17T14:02:01.283363185Z,10,2,1108,A,B,10,13.250000000,100,121107957,165653,101317376,13.28,11,2,13.25,100,1,13.11,100,1,12.99,100,1,12.73,100,1,12.67,100,1,12.51,100,1,12.43,666,1,11.69,2,1,11.52,100,1,13.40,0,-10,13.78,0,-1,13.93,0,-2,13.94,0,-2,14.20,0,-2,14.21,0,-1,14.26,0,-1,14.27,0,-1,14.28,0,-1,14.29,0,-4,ARL,0
2025-07-17T14:02:01.283544588Z,2025-07-17T14:02:01.283378637Z,10,2,1108,C,A,10,14.510000000,100,115813261,165951,101317377,13.28,11,2,13.11,100,1,12.99,100,1,12.73,100,1,12.67,100,1,12.51,100,1,12.43,666,1,11.69,2,1,11.52,100,1,11.29,100,1,13.40,0,-10,13.78,0,-1,13.93,0,-2,13.94,0,-2,14.20,0,-2,14.21,0,-1,14.26,0,-1,14.27,0,-1,14.28,0,-1,14.29,0,-4,ARL,0
2025-07-17T14:02:01.283544588Z,2025-07-17T14:02:01.283378637Z,10,2,1108,A,A,10,14.370000000,100,121107961,165951,101317377,13.28,11,2,13.11,100,1,12.99,100,1,12.73,100,1,12.67,100,1,12.51,100,1,12.43,666,1,11.69,2,1,11.52,100,1,11.29,100,1,13.40,0,-10,13.78,0,-1,13.93,0,-2,13.94,0,-2,14.20,0,-2,14.21,0,-1,14.26,0,-1,14.27,0,-1,14.28,0,-1,14.29,0,-4,ARL,0
2025-07-17T14:04:21.248906318Z,2025-07-17T14:04:21.248740930Z,10,2,1108,A,A,10,14.350000000,1,126872197,165388,106336852,13.28,11,2,13.11,100,1,12.99,100,1,12.73,100,1,12.67,100,1,12.51,100,1,12.43,666,1,11.69,2,1,11.52,100,1,11.29,100,1,13.40,0,-10,13.78,0,-1,13.93,0,-2,13.94,0,-2,14.20,0,-2,14.21,0,-1,14.26,0,-1,14.27,0,-1,14.28,0,-1,14.29,0,-4,ARL,0
2025-07-17T14:04:21.250325900Z,2025-07-17T14:04:21.250160548Z,10,2,1108,C,B,10,12.510000000,100,115474357,165352,106336976,13.28,11,2,13.11,100,1,12.99,100,1,12.73,100,1,12.67,100,1,12.51,100,1,12.43,666,1,11.69,2,1,11.52,100,1,11.29,100,1,13.40,0,-10,13.78,0,-1,13.93,0,-2,13.94,0,-2,14.20,0,-2,14.21,0,-1,14.26,0,-1,14.27,0,-1,14.28,0,-1,14.29,0,-4,ARL,0
2025-07-17T14:04:21.250325900Z,2025-07-17T14:04:21.250160548Z,10,2,1108,A,B,10,12.360000000,100,126872345,165352,106336976,13.28,11,2,13.11,100,1,12.99,100,1,12.73,100,1,12.67,100,1,12.51,100,1,12.43,666,1,12.36,100,1,11.69,2,1,11.52,100,1,13.40,0,-10,13.78,0,-1,13.93,0,-2,13.94,0,-2,14.20,0,-2,14.21,0,-1,14.26,0,-1,14.27,0,-1,14.28,0,-1,14.29,0,-4,ARL,0
2025-07-17T14:04:21.250797741Z,2025-07-17T14:04:21.250632048Z,10,2,1108,C,B,10,12.510000000,100,115474337,165693,106337002,13.28,11,2,13.11,100,1,12.99,100,1,12.73,100,1,12.67,100,1,12.51,100,1,12.43,666,1,11.69,2,1,11.52,100,1,11.29,100,1,13.40,0,-10,13.78,0,-1,13.93,0,-2,13.94,0,-2,14.20,0,-2,14.21,0,-1,14.26,0,-1,14.27,0,-1,14.28,0,-1,14.29,0,-4,ARL,0
2025-07-17T14:04:21.250797741Z,2025-07-17T14:04:21.250632048Z,10,2,1108,A,B,10,12.360000000,100,126872361,165693,106337002,13.28,11,2,13.11,100,1,12.99,100,1,12.73,100,1,12.67,100,1,12.51,100,1,12.43,666,1,12.36,100,1,11.69,2,1,11.52,100,1,13.40,0,-10,13.78,0,-1,13.93,0,-2,13.94,0,-2,14.20,0,-2,14.21,0,-1,14.26,0,-1,14.27,0,-1,14.28,0,-1,14.29,0,-4,ARL,0
2025-07-17T14:04:21.350207939Z,2025-07-17T14:04:21.350041949Z,10,2,1108,C,A,10,14.350000000,1,126872197,165990,106339204,13.28,11,2,13.11,100,1,12.99,100,1,12.73,100,1,12.67,100,1,12.51,100,1,12.43,666,1,12.36,99,1,11.69,2,1,11.52,100,1,13.40,0,-10,13.78,0,-1,13.93,0,-2,13.94,0,-2,14.20,0,-2,14.21,0,-1,14.26,0,-1,14.27,0,-1,14.28,0,-1,14.29,0,-4,ARL,0
2025-07-17T14:04:54.699926747Z,2025-07-17T14:04:54.699761263Z,10,2,1108,C,A,10,15.460000000,100,92510753,165484,107313441,13.28,11,2,13.11,100,1,12.99,100,1,12.73,100,1,12.67,100,1,12.51,100,1,12.43,666,1,11.69,2,1,11.52,100,1,11.29,100,1,13.40,0,-10,13.78,0,-1,13.93,0,-2,13.94,0,-2,14.20,0,-2,14.21,0,-1,14.26,0,-1,14.27,0,-1,14.28,0,-1,14.29,0,-4,ARL,0
2025-07-17T14:04:54.699926747Z,2025-07-17T14:04:54.699761263Z,10,2,1108,A,A,10,15.340000000,100,127999501,165484,107313441,13.28,11,2,13.11,100,1,12.99,100,1,12.73,100,1,12.67,100,1,12.51,100,1,12.43,666,1,11.69,2,1,11.52,100,1,11.29,100,1,13.40,0,-10,13.78,0,-1,13.93,0,-2,13.94,0,-2,14.20,0,-2,14.21,0,-1,14.26,0,-1,14.27,0,-1,14.28,0,-1,14.29,0,-4,ARL,0
2025-07-17T14:05:10.258855609Z,2025-07-17T14:05:10.258689253Z,10,2,1108,A,A,10,14.080000000,1,128570149,166356,107833096,13.28,11,2,13.11,100,1,12.99,100,1,12.73,100,1,12.67,100,1,12.51,100,1,12.43,666,1,11.69,2,1,11.52,100,1,11.29,100,1,13.40,0,-10,13.78,0,-1,13.93,0,-2,13.94,0,-2,14.20,0,-2,14.21,0,-1,14.26,0,-1,14.27,0,-1,14.28,0,-1,14.29,0,-4,ARL,0
2025-07-17T14:05:10.259513876Z,2025-07-17T14:05:10.259348471Z,10,2,1108,C,A,10,15.260000000,100,108217173,165405,107833168,13.28,11,2,13.11,100,1,12.99,100,1,12.73,100,1,12.67,100,1,12.51,100,1,12.43,666,1,11.69,2,1,11.52,100,1,11.29,100,1,13.40,0,-10,13.78,0,-1,13.93,0,-2,13.94,0,-2,14.08,0,-1,14.20,0,-2,14.21,0,-1,14.26,0,-1,14.27,0,-1,14.28,0,-1,ARL,0
2025-07-17T14:05:10.259513876Z,2025-07-17T14:05:10.259348471Z,10,2,1108,A,A,10,14.980000000,100,128570229,165405,107833168,13.28,11,2,13.11,100,1,12.99,100,1,12.73,100,1,12.67,100,1,12.51,100,1,12.43,666,1,11.69,2,1,11.52,100,1,11.29,100,1,13.40,0,-10,13.78,0,-1,13.93,0,-2,13.94,0,-2,14.08,0,-1,14.20,0,-2,14.21,0,-1,14.26,0,-1,14.27,0,-1,14.28,0,-1,ARL,0
2025-07-17T14:05:10.259895236Z,2025-07-17T14:05:10.259729446Z,10,2,1108,C,A,10,15.260000000,100,108217045,165790,107833188,13.28,11,2,13.11,100,1,12.99,100,1,12.73,100,1,12.67,100,1,12.51,100,1,12.43,666,1,11.69,2,1,11.52,100,1,11.29,100,1,13.40,0,-10,13.78,0,-1,13.93,0,-2,13.94,0,-2,14.08,0,-1,14.20,0,-2,14.21,0,-1,14.26,0,-1,14.27,0,-1,14.28,0,-1,ARL,0
2025-07-17T14:05:10.259895236Z,2025-07-17T14:05:10.259729446Z,10,2,1108,A,A,10,14.980000000,100,128570237,165790,107833188,13.28,11,2,13.11,100,1,12.99,100,1,12.73,100,1,12.67,100,1,12.51,100,1,12.43,666,1,11.69,2,1,11.52,100,1,11.29,100,1,13.40,0,-10,13.78,0,-1,13.93,0,-2,13.94,0,-2,14.08,0,-1,14.20,0,-2,14.21,0,-1,14.26,0,-1,14.27,0,-1,14.28,0,-1,ARL,0
2025-07-17T14:05:10.262461863Z,2025-07-17T14:05:10.262295631Z,10,2,1108,C,A,10,14.370000000,100,121107961,166232,107833310,13.28,11,2,13.11,100,1,12.99,100,1,12.73,100,1,12.67,100,1,12.51,100,1,12.43,666,1,11.69,2,1,11.52,100,1,11.29,100,1,13.40,0,-10,13.78,0,-1,13.93,0,-2,13.94,0,-2,14.08,0,-1,14.20,0,-2,14.21,0,-1,14.26,0,-1,14.27,0,-1,14.28,0,-1,ARL,0
2025-07-17T14:05:10.262461863Z,2025-07-17T14:05:10.262295631Z,10,2,1108,A,A,10,14.090000000,100,128570317,166232,107833310,13.28,11,2,13.11,100,1,12.99,100,1,12.73,100,1,12.67,100,1,12.51,100,1,12.43,666,1,11.69,2,1,11.52,100,1,11.29,100,1,13.40,0,-10,13.78,0,-1,13.93,0,-2,13.94,0,-2,14.08,0,-1,14.20,0,-2,14.21,0,-1,14.26,0,-1,14.27,0,-1,14.28,0,-1,ARL,0
2025-07-17T14:05:10.262866527Z,2025-07-17T14:05:10.262701351Z,10,2,1108,C,A,10,14.080000000,1,128570149,165176,107833359,13.28,11,2,13.11,100,1,12.99,100,1,12.73,100,1,12.67,100,1,12.51,100,1,12.43,666,1,11.69,2,1,11.52,100,1,11.29,100,1,13.40,0,-10,13.78,0,-1,13.93,0,-2,13.94,0,-2,14.08,0,-1,14.20,0,-2,14.21,0,-1,14.26,0,-1,14.27,0,-1,14.28,0,-1,ARL,0
2025-07-17T14:05:10.263188035Z,2025-07-17T14:05:10.263022539Z,10,2,1108,C,A,10,15.340000000,100,127999501,165496,107833371,13.28,11,2,13.11,100,1,12.99,100,1,12.73,100,1,12.67,100,1,12.51,100,1,12.43,666,1,11.69,2,1,11.52,100,1,11.29,100,1,13.40,0,-10,13.78,0,-1,13.93,0,-2,13.94,0,-2,14.08,0,-1,14.09,0,-1,14.20,0,-2,14.21,0,-1,14.26,0,-1,14.27,0,-1,ARL,0
2025-07-17T14:05:10.263188035Z,2025-07-17T14:05:10.263022539Z,10,2,1108,A,A,10,15.180000000,100,128570417,165496,107833371,13.28,11,2,13.11,100,1,12.99,100,1,12.73,100,1,12.67,100,1,12.51,100,1,12.43,666,1,11.69,2,1,11.52,100,1,11.29,100,1,13.40,0,-10,13.78,0,-1,13.93,0,-2,13.94,0,-2,14.08,0,-1,14.09,0,-1,14.20,0,-2,14.21,0,-1,14.26,0,-1,14.27,0,-1,ARL,0
2025-07-17T14:05:10.264495078Z,2025-07-17T14:05:10.264329670Z,10,2,1108,C,A,10,15.360000000,100,92510761,165408,107833404,13.28,11,2,13.11,100,1,12.99,100,1,12.73,100,1,12.67,100,1,12.51,100,1,12.43,666,1,11.69,2,1,11.52,100,1,11.29,100,1,13.40,0,-10,13.78,0,-1,13.93,0,-2,13.94,0,-2,14.08,0,-1,14.09,0,-1,14.20,0,-2,14.21,0,-1,14.26,0,-1,14.27,0,-1,ARL,0
2025-07-17T14:05:10.264495078Z,2025-07-17T14:05:10.264329670Z,10,2,1108,A,A,10,15.080000000,100,128570449,165408,107833404,13.28,11,2,13.11,100,1,12.99,100,1,12.73,100,1,12.67,100,1,12.51,100,1,12.43,666,1,11.69,2,1,11.52,100,1,11.29,100,1,13.40,0,-10,13.78,0,-1,13.93,0,-2,13.94,0,-2,14.08,0,-1,14.09,0,-1,14.20,0,-2,14.21,0,-1,14.26,0,-1,14.27,0,-1,ARL,0
2025-07-17T14:05:10.264590318Z,2025-07-17T14:05:10.264425026Z,10,2,1108,C,A,10,15.090000000,100,84650629,165292,107833406,13.28,11,2,13.11,100,1,12.99,100,1,12.73,100,1,12.67,100,1,12.51,100,1,12.43,666,1,11.69,2,1,11.52,100,1,11.29,100,1,13.40,0,-10,13.78,0,-1,13.93,0,-2,13.94,0,-2,14.08,0,-1,14.09,0,-1,14.20,0,-2,14.21,0,-1,14.26,0,-1,14.27,0,-1,ARL,0
2025-07-17T14:05:10.264715723Z,2025-07-17T14:05:10.264550510Z,10,2,1108,A,A,10,14.890000000,100,128570453,165213,107833407,13.28,11,2,13.11,100,1,12.99,100,1,12.73,100,1,12.67,100,1,12.51,100,1,12.43,666,1,11.69,2,1,11.52,100,1,11.29,100,1,13.40,0,-10,13.78,0,-1,13.93,0,-2,13.94,0,-2,14.08,0,-1,14.09,0,-1,14.20,0,-2,14.21,0,-1,14.26,0,-1,14.27,0,-1,ARL,0
2025-07-17T14:05:10.269943051Z,2025-07-17T14:05:10.269777131Z,10,2,1108,C,A,10,14.590000000,100,84629329,165920,107833716,13.28,11,2,13.11,100,1,12.99,100,1,12.73,100,1,12.67,100,1,12.51,100,1,12.43,666,1,11.69,2,1,11.52,100,1,11.29,100,1,13.40,0,-10,13.78,0,-1,13.93,0,-2,13.94,0,-2,14.08,0,-1,14.09,0,-1,14.20,0,-2,14.21,0,-1,14.26,0,-1,14.27,0,-1,ARL,0
2025-07-17T14:05:10.269997960Z,2025-07-17T14:05:10.269832842Z,10,2,1108,A,A,10,14.370000000,100,128570621,165118,107833720,13.28,11,2,13.11,100,1,12.99,100,1,12.73,100,1,12.67,100,1,12.51,100,1,12.43,666,1,11.69,2,1,11.52,100,1,11.29,100,1,13.40,0,-10,13.78,0,-1,13.93,0,-2,13.94,0,-2,14.08,0,-1,14.09,0,-1,14.20,0,-2,14.21,0,-1,14.26,0,-1,14.27,0,-1,ARL,0
2025-07-17T14:05:10.271865423Z,2025-07-17T14:05:10.271699633Z,10,2,1108,C,A,10,18.230000000,100,92510841,165790,107833881,13.28,11,2,13.11,100,1,12.99,100,1,12.73,100,1,12.67,100,1,12.51,100,1,12.43,666,1,11.69,2,1,11.52,100,1,11.29,100,1,13.40,0,-10,13.78,0,-1,13.93,0,-2,13.94,0,-2,14.08,0,-1,14.09,0,-1,14.20,0,-2,14.21,0,-1,14.26,0,-1,14.27,0,-1,ARL,0
2025-07-17T14:05:10.271865423Z,2025-07-17T14:05:10.271699633Z,10,2,1108,A,A,10,17.900000000,100,128570685,165790,107833881,13.28,11,2,13.11,100,1,12.99,100,1,12.73,100,1,12.67,100,1,12.51,100,1,12.43,666,1,11.69,2,1,11.52,100,1,11.29,100,1,13.40,0,-10,13.78,0,-1,13.93,0,-2,13.94,0,-2,14.08,0,-1,14.09,0,-1,14.20,0,-2,14.21,0,-1,14.26,0,-1,14.27,0,-1,ARL,0
2025-07-17T14:05:10.276320920Z,2025-07-17T14:05:10.276155439Z,10,2,1108,C,A,10,16.510000000,100,92510813,165481,107834635,13.28,11,2,13.11,100,1,12.99,100,1,12.73,100,1,12.67,100,1,12.51,100,1,12.43,666,1,11.69,2,1,11.52,100,1,11.29,100,1,13.40,0,-10,13.78,0,-1,13.93,0,-2,13.94,0,-2,14.08,0,-1,14.09,0,-1,14.20,0,-2,14.21,0,-1,14.26,0,-1,14.27,0,-1,ARL,0
2025-07-17T14:05:10.276320920Z,2025-07-17T14:05:10.276155439Z,10,2,1108,A,A,10,16.210000000,100,128570977,165481,107834635,13.28,11,2,13.11,100,1,12.99,100,1,12.73,100,1,12.67,100,1,12.51,100,1,12.43,666,1,11.69,2,1,11.52,100,1,11.29,100,1,13.40,0,-10,13.78,0,-1,13.93,0,-2,13.94,0,-2,14.08,0,-1,14.09,0,-1,14.20,0,-2,14.21,0,-1,14.26,0,-1,14.27,0,-1,ARL,0
2025-07-17T14:05:10.342982797Z,2025-07-17T14:05:10.342817229Z,10,2,1108,C,A,10,15.310000000,100,84630849,165568,107837761,13.28,11,2,13.11,100,1,12.99,100,1,12.73,100,1,12.67,100,1,12.51,100,1,12.43,666,1,11.69,2,1,11.52,100,1,11.29,100,1,13.40,0,-10,13.78,0,-1,13.93,0,-2,13.94,0,-2,14.08,0,-1,14.09,0,-1,14.20,0,-2,14.21,0,-1,14.26,0,-1,14.27,0,-1,ARL,0
2025-07-17T14:05:10.342982797Z,2025-07-17T14:05:10.342817229Z,10,2,1108,A,A,10,15.080000000,100,128573957,165568,107837761,13.28,11,2,13.11,100,1,12.99,100,1,12.73,100,1,12.67,100,1,12.51,100,1,12.43,666,1,11.69,2,1,11.52,100,1,11.29,100,1,13.40,0,-10,13.78,0,-1,13.93,0,-2,13.94,0,-2,14.08,0,-1,14.09,0,-1,14.20,0,-2,14.21,0,-1,14.26,0,-1,14.27,0,-1,ARL,0
2025-07-17T14:05:31.418741362Z,2025-07-17T14:05:31.418575692Z,10,2,1108,C,A,10,14.360000000,2,121098341,165670,108664911,13.28,11,2,13.11,100,1,12.99,100,1,12.73,100,1,12.67,100,1,12.51,100,1,12.43,666,1,11.69,2,1,11.52,100,1,11.29,100,1,13.40,0,-10,13.78,0,-1,13.93,0,-2,13.94,0,-2,14.08,0,-1,14.09,0,-1,14.20,0,-2,14.21,0,-1,14.26,0,-1,14.27,0,-1,ARL,0
2025-07-17T14:05:31.418741362Z,2025-07-17T14:05:31.418575692Z,10,2,1108,A,A,10,14.260000000,2,129518753,165670,108664911,13.28,11,2,13.11,100,1,12.99,100,1,12.73,100,1,12.67,100,1,12.51,100,1,12.43,666,1,11.69,2,1,11.52,100,1,11.29,100,1,13.40,0,-10,13.78,0,-1,13.93,0,-2,13.94,0,-2,14.08,0,-1,14.09,0,-1,14.20,0,-2,14.21,0,-1,14.26,0,-1,14.27,0,-1,ARL,0
2025-07-17T14:06:01.386006059Z,2025-07-17T14:06:01.385840471Z,10,2,1108,C,B,10,13.260000000,2,121098337,165588,109685525,13.28,11,2,13.11,100,1,12.99,100,1,12.73,100,1,12.67,100,1,12.51,100,1,12.43,666,1,11.69,2,1,11.52,100,1,11.29,100,1,13.40,0,-10,13.78,0,-1,13.93,0,-2,13.94,0,-2,14.08,0,-1,14.09,0,-1,14.20,0,-2,14.21,0,-1,14.26,0,-2,14.27,0,-1,ARL,0
2025-07-17T14:06:01.386006059Z,2025-07-17T14:06:01.385840471Z,10,2,1108,A,B,10,13.150000000,2,130693973,165588,109685525,13.28,11,2,13.15,2,1,13.11,100,1,12.99,100,1,12.73,100,1,12.67,100,1,12.51,100,1,12.43,666,1,11.69,2,1,11.52,100,1,13.40,0,-10,13.78,0,-1,13.93,0,-2,13.94,0,-2,14.08,0,-1,14.09,0,-1,14.20,0,-2,14.21,0,-1,14.26,0,-2,14.27,0,-1,ARL,0
2025-07-17T14:13:11.346377890Z,2025-07-17T14:13:11.346212166Z,10,2,1108,C,A,10,15.180000000,100,128570417,165724,123937587,13.28,11,2,13.11,100,1,12.99,100,1,12.73,100,1,12.67,100,1,12.51,100,1,12.43,666,1,11.69,2,1,11.52,100,1,11.29,100,1,13.40,0,-10,13.78,0,-1,13.93,0,-2,13.94,0,-2,14.08,0,-1,14.09,0,-1,14.20,0,-2,14.21,0,-1,14.26,0,-2,14.27,0,-1,ARL,0
2025-07-17T14:13:11.346377890Z,2025-07-17T14:13:11.346212166Z,10,2,1108,A,A,10,15.090000000,100,146955361,165724,123937587,13.28,11,2,13.11,100,1,12.99,100,1,12.73,100,1,12.67,100,1,12.51,100,1,12.43,666,1,11.69,2,1,11.52,100,1,11.29,100,1,13.40,0,-10,13.78,0,-1,13.93,0,-2,13.94,0,-2,14.08,0,-1,14.09,0,-1,14.20,0,-2,14.21,0,-1,14.26,0,-2,14.27,0,-1,ARL,0
2025-07-17T14:13:11.358916626Z,2025-07-17T14:13:11.358751092Z,10,2,1108,C,A,10,14.370000000,100,128570621,165534,123938202,13.28,11,2,13.11,100,1,12.99,100,1,12.73,100,1,12.67,100,1,12.51,100,1,12.43,666,1,11.69,2,1,11.52,100,1,11.29,100,1,13.40,0,-10,13.78,0,-1,13.93,0,-2,13.94,0,-2,14.08,0,-1,14.09,0,-1,14.20,0,-2,14.21,0,-1,14.26,0,-2,14.27,0,-1,ARL,0
2025-07-17T14:13:11.358968656Z,2025-07-17T14:13:11.358802966Z,10,2,1108,A,A,10,14.280000000,100,146956357,165690,123938203,13.28,11,2,13.11,100,1,12.99,100,1,12.73,100,1,12.67,100,1,12.51,100,1,12.43,666,1,11.69,2,1,11.52,100,1,11.29,100,1,13.40,0,-10,13.78,0,-1,13.93,0,-2,13.94,0,-2,14.08,0,-1,14.09,0,-1,14.20,0,-2,14.21,0,-1,14.26,0,-2,14.27,0,-1,ARL,0
2025-07-17T14:13:11.393088913Z,2025-07-17T14:13:11.392923396Z,10,2,1108,C,A,10,15.730000000,100,84629953,165517,123939815,13.28,11,2,13.11,100,1,12.99,100,1,12.73,100,1,12.67,100,1,12.51,100,1,12.43,666,1,11.69,2,1,11.52,100,1,11.29,100,1,13.40,0,-10,13.78,0,-1,13.93,0,-2,13.94,0,-2,14.08,0,-1,14.09,0,-1,14.20,0,-2,14.21,0,-1,14.26,0,-2,14.27,0,-1,ARL,0
2025-07-17T14:13:11.393088913Z,2025-07-17T14:13:11.392923396Z,10,2,1108,A,A,10,15.400000000,100,146959177,165517,123939815,13.28,11,2,13.11,100,1,12.99,100,1,12.73,100,1,12.67,100,1,12.51,100,1,12.43,666,1,11.69,2,1,11.52,100,1,11.29,100,1,13.40,0,-10,13.78,0,-1,13.93,0,-2,13.94,0,-2,14.08,0,-1,14.09,0,-1,14.20,0,-2,14.21,0,-1,14.26,0,-2,14.27,0,-1,ARL,0
2025-07-17T14:13:11.423482323Z,2025-07-17T14:13:11.423316840Z,10,2,1108,A,A,10,14.560000000,100,146960005,165483,123940437,13.28,11,2,13.11,100,1,12.99,100,1,12.73,100,1,12.67,100,1,12.51,100,1,12.43,666,1,11.69,2,1,11.52,100,1,11.29,100,1,13.40,0,-10,13.78,0,-1,13.93,0,-2,13.94,0,-2,14.08,0,-1,14.09,0,-1,14.20,0,-2,14.21,0,-1,14.26,0,-2,14.27,0,-1,ARL,0
2025-07-17T14:13:11.423483431Z,2025-07-17T14:13:11.423317922Z,10,2,1108,C,A,10,14.870000000,100,84708037,165509,123940438,13.28,11,2,13.11,100,1,12.99,100,1,12.73,100,1,12.67,100,1,12.51,100,1,12.43,666,1,11.69,2,1,11.52,100,1,11.29,100,1,13.40,0,-10,13.78,0,-1,13.93,0,-2,13.94,0,-2,14.08,0,-1,14.09,0,-1,14.20,0,-2,14.21,0,-1,14.26,0,-2,14.27,0,-1,ARL,0
2025-07-17T14:13:11.555808541Z,2025-07-17T14:13:11.555642984Z,10,2,1108,A,A,10,14.840000000,100,146962993,165557,123942727,13.28,11,2,13.11,100,1,12.99,100,1,12.73,100,1,12.67,100,1,12.51,100,1,12.43,666,1,11.69,2,1,11.52,100,1,11.29,100,1,13.40,0,-10,13.78,0,-1,13.93,0,-2,13.94,0,-2,14.08,0,-1,14.09,0,-1,14.20,0,-2,14.21,0,-1,14.26,0,-2,14.27,0,-1,ARL,0
2025-07-17T14:13:11.555828856Z,2025-07-17T14:13:11.555663413Z,10,2,1108,C,A,10,15.160000000,100,84668677,165443,123942728,13.28,11,2,13.11,100,1,12.99,100,1,12.73,100,1,12.67,100,1,12.51,100,1,12.43,666,1,11.69,2,1,11.52,100,1,11.29,100,1,13.40,0,-10,13.78,0,-1,13.93,0,-2,13.94,0,-2,14.08,0,-1,14.09,0,-1,14.20,0,-2,14.21,0,-1,14.26,0,-2,14.27,0,-1,ARL,0
2025-07-17T14:13:19.230983072Z,2025-07-17T14:13:19.230817808Z,10,2,1108,A,A,10,14.910000000,700,147217629,165264,124169794,13.28,11,2,13.11,100,1,12.99,100,1,12.73,100,1,12.67,100,1,12.51,100,1,12.43,666,1,11.69,2,1,11.52,100,1,11.29,100,1,13.40,0,-10,13.78,0,-1,13.93,0,-2,13.94,0,-2,14.08,0,-1,14.09,0,-1,14.20,0,-2,14.21,0,-1,14.26,0,-2,14.27,0,-1,ARL,0
2025-07-17T14:13:19.231778755Z,2025-07-17T14:13:19.231613044Z,10,2,1108,C,A,10,15.140000000,700,84628829,165711,124169802,13.28,11,2,13.11,100,1,12.99,100,1,12.73,100,1,12.67,100,1,12.51,100,1,12.43,666,1,11.69,2,1,11.52,100,1,11.29,100,1,13.40,0,-10,13.78,0,-1,13.93,0,-2,13.94,0,-2,14.08,0,-1,14.09,0,-1,14.20,0,-2,14.21,0,-1,14.26,0,-2,14.27,0,-1,ARL,0
2025-07-17T14:22:28.338174848Z,2025-07-17T14:22:28.338009329Z,10,2,1108,A,A,10,14.000000000,1,168073025,165519,142657338,13.28,11,2,13.11,100,1,12.99,100,1,12.73,100,1,12.67,100,1,12.51,100,1,12.43,666,1,11.69,2,1,11.52,100,1,11.29,100,1,13.40,0,-10,13.78,0,-1,13.93,0,-2,13.94,0,-2,14.08,0,-1,14.09,0,-1,14.20,0,-2,14.21,0,-1,14.26,0,-2,14.27,0,-1,ARL,0
2025-07-17T14:22:29.994011311Z,2025-07-17T14:22:29.993845812Z,10,2,1108,C,A,10,14.090000000,100,128570317,165499,142715813,13.28,11,2,13.11,100,1,12.99,100,1,12.73,100,1,12.67,100,1,12.51,100,1,12.43,666,1,11.69,2,1,11.52,100,1,11.29,100,1,13.40,0,-10,13.78,0,-1,13.93,0,-2,13.94,0,-2,14.00,0,-1,14.08,0,-1,14.09,0,-1,14.20,0,-2,14.21,0,-1,14.26,0,-2,ARL,0
2025-07-17T14:22:29.994011311Z,2025-07-17T14:22:29.993845812Z,10,2,1108,A,A,10,14.010000000,100,168141389,165499,142715813,13.28,11,2,13.11,100,1,12.99,100,1,12.73,100,1,12.67,100,1,12.51,100,1,12.43,666,1,11.69,2,1,11.52,100,1,11.29,100,1,13.40,0,-10,13.78,0,-1,13.93,0,-2,13.94,0,-2,14.00,0,-1,14.08,0,-1,14.09,0,-1,14.20,0,-2,14.21,0,-1,14.26,0,-2,ARL,0
2025-07-17T14:32:58.233129156Z,2025-07-17T14:32:58.232963791Z,10,2,1108,C,B,10,13.250000000,100,121107957,165365,162140358,13.28,11,2,13.11,100,1,12.99,100,1,12.73,100,1,12.67,100,1,12.51,100,1,12.43,666,1,11.69,2,1,11.52,100,1,11.29,100,1,13.40,0,-10,13.78,0,-1,13.93,0,-2,13.94,0,-2,14.00,0,-1,14.01,0,-1,14.08,0,-1,14.09,0,-1,14.20,0,-2,14.21,0,-1,ARL,0
2025-07-17T14:32:58.714015555Z,2025-07-17T14:32:58.713850212Z,10,2,1108,A,B,10,13.140000000,100,190326921,165343,162149922,13.28,11,2,13.14,100,1,13.11,100,1,12.99,100,1,12.73,100,1,12.67,100,1,12.51,100,1,12.43,666,1,11.69,2,1,11.52,100,1,13.40,0,-10,13.78,0,-1,13.93,0,-2,13.94,0,-2,14.00,0,-1,14.01,0,-1,14.08,0,-1,14.09,0,-1,14.20,0,-2,14.21,0,-1,ARL,0
2025-07-17T14:34:48.346344959Z,2025-07-17T14:34:48.346179643Z,10,2,1108,C,A,10,14.000000000,1,168073025,165316,164925706,13.28,11,2,13.14,99,1,13.11,100,1,12.99,100,1,12.73,100,1,12.67,100,1,12.51,100,1,12.43,666,1,11.69,2,1,11.52,100,1,13.40,0,-10,13.78,0,-1,13.93,0,-2,13.94,0,-2,14.00,0,-1,14.01,0,-1,14.08,0,-1,14.09,0,-1,14.20,0,-2,14.21,0,-1,ARL,0
2025-07-17T14:47:30.548081358Z,2025-07-17T14:47:30.547915870Z,10,2,1108,A,B,10,13.380000000,33,215999733,165488,183466992,13.38,33,1,13.28,11,2,13.14,99,1,13.11,100,1,12.99,100,1,12.73,100,1,12.67,100,1,12.51,100,1,12.43,666,1,11.69,2,1,13.40,0,-10,13.78,0,-1,13.93,0,-2,13.94,0,-2,14.00,0,-1,14.01,0,-1,14.08,0,-1,14.09,0,-1,14.20,0,-2,14.21,0,-1,ARL,0
2025-07-17T14:47:30.548346701Z,2025-07-17T14:47:30.548180936Z,10,2,1108,C,B,10,13.140000000,100,190326921,165765,183466994,13.28,11,2,13.14,99,1,13.11,100,1,12.99,100,1,12.73,100,1,12.67,100,1,12.51,100,1,12.43,666,1,11.69,2,1,11.52,100,1,13.40,0,-10,13.78,0,-1,13.93,0,-2,13.94,0,-2,14.00,0,-1,14.01,0,-1,14.08,0,-1,14.09,0,-1,14.20,0,-2,14.21,0,-1,ARL,0
2025-07-17T14:47:30.548346701Z,2025-07-17T14:47:30.548180936Z,10,2,1108,A,B,10,13.370000000,100,215999737,165765,183466994,13.37,100,1,13.28,11,2,13.14,99,1,13.11,100,1,12.99,100,1,12.73,100,1,12.67,100,1,12.51,100,1,12.43,666,1,11.69,2,1,13.40,0,-10,13.78,0,-1,13.93,0,-2,13.94,0,-2,14.00,0,-1,14.01,0,-1,14.08,0,-1,14.09,0,-1,14.20,0,-2,14.21,0,-1,ARL,0
2025-07-17T14:47:30.548831608Z,2025-07-17T14:47:30.548666035Z,10,2,1108,C,B,10,12.360000000,100,126872345,165573,183467001,13.28,11,2,13.14,99,1,13.11,100,1,12.99,100,1,12.73,100,1,12.67,100,1,12.51,100,1,12.43,666,1,11.69,2,1,11.52,100,1,13.40,0,-10,13.78,0,-1,13.93,0,-2,13.94,0,-2,14.00,0,-1,14.01,0,-1,14.08,0,-1,14.09,0,-1,14.20,0,-2,14.21,0,-1,ARL,0
2025-07-17T14:47:30.548831608Z,2025-07-17T14:47:30.548666035Z,10,2,1108,A,B,10,12.480000000,100,215999741,165573,183467001,13.28,11,2,13.14,99,1,13.11,100,1,12.99,100,1,12.73,100,1,12.67,100,1,12.51,100,1,12.48,100,1,12.43,666,1,11.69,2,1,13.40,0,-10,13.78,0,-1,13.93,0,-2,13.94,0,-2,14.00,0,-1,14.01,0,-1,14.08,0,-1,14.09,0,-1,14.20,0,-2,14.21,0,-1,ARL,0
2025-07-17T14:47:30.549090785Z,2025-07-17T14:47:30.548925394Z,10,2,1108,C,B,10,12.230000000,100,43317473,165391,183467002,13.28,11,2,13.14,99,1,13.11,100,1,12.99,100,1,12.73,100,1,12.67,100,1,12.51,100,1,12.43,666,1,11.69,2,1,11.52,100,1,13.40,0,-10,13.78,0,-1,13.93,0,-2,13.94,0,-2,14.00,0,-1,14.01,0,-1,14.08,0,-1,14.09,0,-1,14.20,0,-2,14.21,0,-1,ARL,0
2025-07-17T14:47:30.549090785Z,2025-07-17T14:47:30.548925394Z,10,2,1108,A,B,10,12.330000000,100,215999753,165391,183467002,13.28,11,2,13.14,99,1,13.11,100,1,12.99,100,1,12.73,100,1,12.67,100,1,12.51,100,1,12.43,666,1,12.33,100,1,11.69,2,1,13.40,0,-10,13.78,0,-1,13.93,0,-2,13.94,0,-2,14.00,0,-1,14.01,0,-1,14.08,0,-1,14.09,0,-1,14.20,0,-2,14.21,0,-1,ARL,0
2025-07-17T14:47:30.549341156Z,2025-07-17T14:47:30.549175659Z,10,2,1108,C,B,10,12.360000000,100,126872361,165497,183467004,13.28,11,2,13.14,99,1,13.11,100,1,12.99,100,1,12.73,100,1,12.67,100,1,12.51,100,1,12.43,666,1,11.69,2,1,11.52,100,1,13.40,0,-10,13.78,0,-1,13.93,0,-2,13.94,0,-2,14.00,0,-1,14.01,0,-1,14.08,0,-1,14.09,0,-1,14.20,0,-2,14.21,0,-1,ARL,0
2025-07-17T14:47:30.549341156Z,2025-07-17T14:47:30.549175659Z,10,2,1108,A,B,10,12.480000000,100,215999761,165497,183467004,13.28,11,2,13.14,99,1,13.11,100,1,12.99,100,1,12.73,100,1,12.67,100,1,12.51,100,1,12.48,100,1,12.43,666,1,11.69,2,1,13.40,0,-10,13.78,0,-1,13.93,0,-2,13.94,0,-2,14.00,0,-1,14.01,0,-1,14.08,0,-1,14.09,0,-1,14.20,0,-2,14.21,0,-1,ARL,0
2025-07-17T14:47:30.571385383Z,2025-07-17T14:47:30.571220121Z,10,2,1108,C,B,10,12.990000000,100,43805737,165262,183468111,13.28,11,2,13.14,99,1,13.11,100,1,12.99,100,1,12.73,100,1,12.67,100,1,12.51,100,1,12.43,666,1,11.69,2,1,11.52,100,1,13.40,0,-10,13.78,0,-1,13.93,0,-2,13.94,0,-2,14.00,0,-1,14.01,0,-1,14.08,0,-1,14.09,0,-1,14.20,0,-2,14.21,0,-1,ARL,0
2025-07-17T14:47:30.571436944Z,2025-07-17T14:47:30.571271737Z,10,2,1108,A,B,10,13.100000000,100,216001413,165207,183468112,13.28,11,2,13.14,99,1,13.11,100,1,13.10,100,1,12.99,100,1,12.73,100,1,12.67,100,1,12.51,100,1,12.43,666,1,11.69,2,1,13.40,0,-10,13.78,0,-1,13.93,0,-2,13.94,0,-2,14.00,0,-1,14.01,0,-1,14.08,0,-1,14.09,0,-1,14.20,0,-2,14.21,0,-1,ARL,0
2025-07-17T14:47:37.384610677Z,2025-07-17T14:47:37.384441232Z,10,2,1108,A,B,10,12.500000000,700,216223005,169445,183649796,13.28,11,2,13.14,99,1,13.11,100,1,13.10,100,1,12.99,100,1,12.73,100,1,12.67,100,1,12.51,100,1,12.50,700,1,12.43,666,1,13.40,0,-10,13.78,0,-1,13.93,0,-2,13.94,0,-2,14.00,0,-1,14.01,0,-1,14.08,0,-1,14.09,0,-1,14.20,0,-2,14.21,0,-1,ARL,0
2025-07-17T14:47:37.385400265Z,2025-07-17T14:47:37.385234288Z,10,2,1108,C,B,10,12.260000000,700,44570585,165977,183649801,13.28,11,2,13.14,99,1,13.11,100,1,13.10,100,1,12.99,100,1,12.73,100,1,12.67,100,1,12.51,100,1,12.43,666,1,11.69,2,1,13.40,0,-10,13.78,0,-1,13.93,0,-2,13.94,0,-2,14.00,0,-1,14.01,0,-1,14.08,0,-1,14.09,0,-1,14.20,0,-2,14.21,0,-1,ARL,0
2025-07-17T14:52:02.610509102Z,2025-07-17T14:52:02.610343819Z,10,2,1108,A,A,10,13.710000000,1,223347833,165283,189559141,13.28,11,2,13.14,99,1,13.11,100,1,13.10,100,1,12.99,100,1,12.73,100,1,12.67,100,1,12.51,100,1,12.43,666,1,11.69,2,1,13.40,0,-10,13.78,0,-1,13.93,0,-2,13.94,0,-2,14.00,0,-1,14.01,0,-1,14.08,0,-1,14.09,0,-1,14.20,0,-2,14.21,0,-1,ARL,0
2025-07-17T14:52:02.611701408Z,2025-07-17T14:52:02.611536221Z,10,2,1108,C,A,10,13.710000000,1,223347833,165187,189559156,13.28,11,2,13.14,99,1,13.11,100,1,13.10,100,1,12.99,100,1,12.73,100,1,12.67,100,1,12.51,100,1,12.43,666,1,11.69,2,1,13.40,0,-10,13.71,0,-1,13.78,0,-1,13.93,0,-2,13.94,0,-2,14.00,0,-1,14.01,0,-1,14.08,0,-1,14.09,0,-1,14.20,0,-2,ARL,0
2025-07-17T15:00:11.560678862Z,2025-07-17T15:00:11.560513555Z,10,2,1108,C,B,10,13.380000000,33,215999733,165307,200140364,13.28,11,2,13.14,99,1,13.11,100,1,13.10,100,1,12.99,100,1,12.73,100,1,12.67,100,1,12.51,100,1,12.43,666,1,11.69,2,1,13.40,0,-10,13.71,0,-1,13.78,0,-1,13.93,0,-2,13.94,0,-2,14.00,0,-1,14.01,0,-1,14.08,0,-1,14.09,0,-1,14.20,0,-2,ARL,0
2025-07-17T15:00:11.563053782Z,2025-07-17T15:00:11.562887948Z,10,2,1108,C,B,10,12.480000000,100,215999761,165834,200140389,13.28,11,2,13.14,99,1,13.11,100,1,13.10,100,1,12.99,100,1,12.73,100,1,12.67,100,1,12.51,100,1,12.43,666,1,11.69,2,1,13.40,0,-10,13.71,0,-1,13.78,0,-1,13.93,0,-2,13.94,0,-2,14.00,0,-1,14.01,0,-1,14.08,0,-1,14.09,0,-1,14.20,0,-2,ARL,0
2025-07-17T15:00:11.563053782Z,2025-07-17T15:00:11.562887948Z,10,2,1108,A,B,10,12.650000000,100,236179089,165834,200140389,13.28,11,2,13.14,99,1,13.11,100,1,13.10,100,1,12.99,100,1,12.73,100,1,12.67,100,1,12.65,100,1,12.51,100,1,12.43,666,1,13.40,0,-10,13.71,0,-1,13.78,0,-1,13.93,0,-2,13.94,0,-2,14.00,0,-1,14.01,0,-1,14.08,0,-1,14.09,0,-1,14.20,0,-2,ARL,0
2025-07-17T15:00:12.536218524Z,2025-07-17T15:00:12.536052536Z,10,2,1108,C,B,10,12.480000000,100,215999741,165988,200161810,13.28,11,2,13.14,99,1,13.11,100,1,13.10,100,1,12.99,100,1,12.73,100,1,12.67,100,1,12.51,100,1,12.43,666,1,11.69,2,1,13.40,0,-10,13.71,0,-1,13.78,0,-1,13.93,0,-2,13.94,0,-2,14.00,0,-1,14.01,0,-1,14.08,0,-1,14.09,0,-1,14.20,0,-2,ARL,0
2025-07-17T15:00:12.536218524Z,2025-07-17T15:00:12.536052536Z,10,2,1108,A,B,10,12.650000000,100,236206261,165988,200161810,13.28,11,2,13.14,99,1,13.11,100,1,13.10,100,1,12.99,100,1,12.73,100,1,12.67,100,1,12.65,100,1,12.51,100,1,12.43,666,1,13.40,0,-10,13.71,0,-1,13.78,0,-1,13.93,0,-2,13.94,0,-2,14.00,0,-1,14.01,0,-1,14.08,0,-1,14.09,0,-1,14.20,0,-2,ARL,0
2025-07-17T15:01:11.658789910Z,2025-07-17T15:01:11.658624662Z,10,2,1108,A,A,10,13.980000000,10,237940713,165248,201616674,13.28,11,2,13.14,99,1,13.11,100,1,13.10,100,1,12.99,100,1,12.73,100,1,12.67,100,1,12.65,100,1,12.51,100,1,12.43,666,1,13.40,0,-10,13.71,0,-1,13.78,0,-1,13.93,0,-2,13.94,0,-2,14.00,0,-1,14.01,0,-1,14.08,0,-1,14.09,0,-1,14.20,0,-2,ARL,0
2025-07-17T15:01:12.948386121Z,2025-07-17T15:01:12.948220412Z,10,2,1108,C,A,10,14.010000000,100,168141389,165709,201642675,13.28,11,2,13.14,99,1,13.11,100,1,13.10,100,1,12.99,100,1,12.73,100,1,12.67,100,1,12.65,100,1,12.51,100,1,12.43,666,1,13.40,0,-10,13.71,0,-1,13.78,0,-1,13.93,0,-2,13.94,0,-2,13.98,0,-1,14.00,0,-1,14.01,0,-1,14.08,0,-1,14.09,0,-1,ARL,0
2025-07-17T15:01:12.948386121Z,2025-07-17T15:01:12.948220412Z,10,2,1108,A,A,10,13.990000000,100,237978541,165709,201642675,13.28,11,2,13.14,99,1,13.11,100,1,13.10,100,1,12.99,100,1,12.73,100,1,12.67,100,1,12.65,100,1,12.51,100,1,12.43,666,1,13.40,0,-10,13.71,0,-1,13.78,0,-1,13.93,0,-2,13.94,0,-2,13.98,0,-1,14.00,0,-1,14.01,0,-1,14.08,0,-1,14.09,0,-1,ARL,0
2025-07-17T15:01:12.949124493Z,2025-07-17T15:01:12.948959226Z,10,2,1108,C,A,10,14.830000000,100,84628793,165267,201642712,13.28,11,2,13.14,99,1,13.11,100,1,13.10,100,1,12.99,100,1,12.73,100,1,12.67,100,1,12.65,100,1,12.51,100,1,12.43,666,1,13.40,0,-10,13.71,0,-1,13.78,0,-1,13.93,0,-2,13.94,0,-2,13.98,0,-1,13.99,0,-1,14.00,0,-1,14.01,0,-1,14.08,0,-1,ARL,0
2025-07-17T15:01:12.949484115Z,2025-07-17T15:01:12.949317198Z,10,2,1108,A,A,10,14.610000000,100,237978629,166917,201642747,13.28,11,2,13.14,99,1,13.11,100,1,13.10,100,1,12.99,100,1,12.73,100,1,12.67,100,1,12.65,100,1,12.51,100,1,12.43,666,1,13.40,0,-10,13.71,0,-1,13.78,0,-1,13.93,0,-2,13.94,0,-2,13.98,0,-1,13.99,0,-1,14.00,0,-1,14.01,0,-1,14.08,0,-1,ARL,0
2025-07-17T15:01:26.963916368Z,2025-07-17T15:01:26.963746832Z,10,2,1108,C,A,10,13.980000000,10,237940713,169536,201984003,13.28,11,2,13.14,99,1,13.11,100,1,13.10,100,1,12.99,100,1,12.73,100,1,12.67,100,1,12.65,100,1,12.51,100,1,12.43,666,1,13.40,0,-10,13.71,0,-1,13.78,0,-1,13.93,0,-2,13.94,0,-2,13.98,0,-1,13.99,0,-1,14.00,0,-1,14.01,0,-1,14.08,0,-1,ARL,0
2025-07-17T15:01:37.513312432Z,2025-07-17T15:01:37.513147090Z,10,2,1108,A,A,10,13.980000000,10,238668633,165342,202186180,13.28,11,2,13.14,99,1,13.11,100,1,13.10,100,1,12.99,100,1,12.73,100,1,12.67,100,1,12.65,100,1,12.51,100,1,12.43,666,1,13.40,0,-10,13.71,0,-1,13.78,0,-1,13.93,0,-2,13.94,0,-2,13.98,0,-1,13.99,0,-1,14.00,0,-1,14.01,0,-1,14.08,0,-1,ARL,0
2025-07-17T15:05:36.047202557Z,2025-07-17T15:05:36.047029298Z,10,2,1108,C,A,10,13.980000000,10,238668633,173259,207097179,13.28,11,2,13.14,99,1,13.11,100,1,13.10,100,1,12.99,100,1,12.73,100,1,12.67,100,1,12.65,100,1,12.51,100,1,12.43,666,1,13.40,0,-10,13.71,0,-1,13.78,0,-1,13.93,0,-2,13.94,0,-2,13.98,0,-2,13.99,0,-1,14.00,0,-1,14.01,0,-1,14.08,0,-1,ARL,0
2025-07-17T15:10:34.469866273Z,2025-07-17T15:10:34.469700487Z,10,2,1108,C,A,10,14.260000000,2,129518753,165786,213735006,13.28,11,2,13.14,99,1,13.11,100,1,13.10,100,1,12.99,100,1,12.73,100,1,12.67,100,1,12.65,100,1,12.51,100,1,12.43,666,1,13.40,0,-10,13.71,0,-1,13.78,0,-1,13.93,0,-2,13.94,0,-2,13.98,0,-2,13.99,0,-1,14.00,0,-1,14.01,0,-1,14.08,0,-1,ARL,0
2025-07-17T15:10:34.469866273Z,2025-07-17T15:10:34.469700487Z,10,2,1108,A,A,10,14.170000000,2,252720897,165786,213735006,13.28,11,2,13.14,99,1,13.11,100,1,13.10,100,1,12.99,100,1,12.73,100,1,12.67,100,1,12.65,100,1,12.51,100,1,12.43,666,1,13.40,0,-10,13.71,0,-1,13.78,0,-1,13.93,0,-2,13.94,0,-2,13.98,0,-2,13.99,0,-1,14.00,0,-1,14.01,0,-1,14.08,0,-1,ARL,0
2025-07-17T15:12:52.735414592Z,2025-07-17T15:12:52.735249178Z,10,2,1108,A,A,10,14.030000000,100,256325129,165414,216651092,13.28,11,2,13.14,99,1,13.11,100,1,13.10,100,1,12.99,100,1,12.73,100,1,12.67,100,1,12.65,100,1,12.51,100,1,12.43,666,1,13.40,0,-10,13.71,0,-1,13.78,0,-1,13.93,0,-2,13.94,0,-2,13.98,0,-2,13.99,0,-1,14.00,0,-1,14.01,0,-1,14.08,0,-1,ARL,0
2025-07-17T15:13:06.511853457Z,2025-07-17T15:13:06.511687613Z,10,2,1108,A,A,10,13.980000000,10,256739841,165844,216995105,13.28,11,2,13.14,99,1,13.11,100,1,13.10,100,1,12.99,100,1,12.73,100,1,12.67,100,1,12.65,100,1,12.51,100,1,12.43,666,1,13.40,0,-10,13.71,0,-1,13.78,0,-1,13.93,0,-2,13.94,0,-2,13.98,0,-2,13.99,0,-1,14.00,0,-1,14.01,0,-1,14.08,0,-1,ARL,0
2025-07-17T15:13:08.654089411Z,2025-07-17T15:13:08.653923821Z,10,2,1108,A,A,10,14.010000000,100,256818881,165590,217058300,13.28,11,2,13.14,99,1,13.11,100,1,13.10,100,1,12.99,100,1,12.73,100,1,12.67,100,1,12.65,100,1,12.51,100,1,12.43,666,1,13.40,0,-10,13.71,0,-1,13.78,0,-1,13.93,0,-2,13.94,0,-2,13.98,0,-2,13.99,0,-1,14.00,0,-1,14.01,0,-1,14.08,0,-1,ARL,0
2025-07-17T15:13:08.661686458Z,2025-07-17T15:13:08.661521116Z,10,2,1108,C,A,10,14.030000000,100,256325129,165342,217058550,13.28,11,2,13.14,99,1,13.11,100,1,13.10,100,1,12.99,100,1,12.73,100,1,12.67,100,1,12.65,100,1,12.51,100,1,12.43,666,1,13.40,0,-10,13.71,0,-1,13.78,0,-1,13.93,0,-2,13.94,0,-2,13.98,0,-2,13.99,0,-1,14.00,0,-1,14.01,0,-2,14.08,0,-1,ARL,0
2025-07-17T15:14:00.440728359Z,2025-07-17T15:14:00.440563034Z,10,2,1108,C,A,10,13.980000000,10,256739841,165325,218096891,13.28,11,2,13.14,99,1,13.11,100,1,13.10,100,1,12.99,100,1,12.73,100,1,12.67,100,1,12.65,100,1,12.51,100,1,12.43,666,1,13.40,0,-10,13.71,0,-1,13.78,0,-1,13.93,0,-2,13.94,0,-2,13.98,0,-2,13.99,0,-1,14.00,0,-1,14.01,0,-2,14.08,0,-1,ARL,0
2025-07-17T15:14:52.382139830Z,2025-07-17T15:14:52.381974473Z,10,2,1108,A,A,10,13.980000000,10,259546169,165357,219204095,13.28,11,2,13.14,99,1,13.11,100,1,13.10,100,1,12.99,100,1,12.73,100,1,12.67,100,1,12.65,100,1,12.51,100,1,12.43,666,1,13.40,0,-10,13.71,0,-1,13.78,0,-1,13.93,0,-2,13.94,0,-2,13.98,0,-2,13.99,0,-1,14.00,0,-1,14.01,0,-2,14.08,0,-1,ARL,0
2025-07-17T15:14:56.683309707Z,2025-07-17T15:14:56.683144163Z,10,2,1108,C,A,10,14.010000000,100,256818881,165544,219317677,13.28,11,2,13.14,99,1,13.11,100,1,13.10,100,1,12.99,100,1,12.73,100,1,12.67,100,1,12.65,100,1,12.51,100,1,12.43,666,1,13.40,0,-10,13.71,0,-1,13.78,0,-1,13.93,0,-2,13.94,0,-2,13.98,0,-3,13.99,0,-1,14.00,0,-1,14.01,0,-2,14.08,0,-1,ARL,0
2025-07-17T15:15:11.661118778Z,2025-07-17T15:15:11.660953613Z,10,2,1108,A,A,10,14.020000000,100,260184621,165165,219726276,13.28,11,2,13.14,99,1,13.11,100,1,13.10,100,1,12.99,100,1,12.73,100,1,12.67,100,1,12.65,100,1,12.51,100,1,12.43,666,1,13.40,0,-10,13.71,0,-1,13.78,0,-1,13.93,0,-2,13.94,0,-2,13.98,0,-3,13.99,0,-1,14.00,0,-1,14.01,0,-2,14.08,0,-1,ARL,0
2025-07-17T15:15:32.408863263Z,2025-07-17T15:15:32.408694312Z,10,2,1108,C,A,10,13.980000000,10,259546169,168951,220152194,13.28,11,2,13.14,99,1,13.11,100,1,13.10,100,1,12.99,100,1,12.73,100,1,12.67,100,1,12.65,100,1,12.51,100,1,12.43,666,1,13.40,0,-10,13.71,0,-1,13.78,0,-1,13.93,0,-2,13.94,0,-2,13.98,0,-3,13.99,0,-1,14.00,0,-1,14.01,0,-2,14.08,0,-1,ARL,0
2025-07-17T15:16:31.607242914Z,2025-07-17T15:16:31.607077080Z,10,2,1108,A,A,10,14.000000000,100,262279553,165834,221423516,13.28,11,2,13.14,99,1,13.11,100,1,13.10,100,1,12.99,100,1,12.73,100,1,12.67,100,1,12.65,100,1,12.51,100,1,12.43,666,1,13.40,0,-10,13.71,0,-1,13.78,0,-1,13.93,0,-2,13.94,0,-2,13.98,0,-3,13.99,0,-1,14.00,0,-1,14.01,0,-2,14.08,0,-1,ARL,0
2025-07-17T15:16:31.614370696Z,2025-07-17T15:16:31.614205345Z,10,2,1108,C,A,10,14.020000000,100,260184621,165351,221423706,13.28,11,2,13.14,99,1,13.11,100,1,13.10,100,1,12.99,100,1,12.73,100,1,12.67,100,1,12.65,100,1,12.51,100,1,12.43,666,1,13.40,0,-10,13.71,0,-1,13.78,0,-1,13.93,0,-2,13.94,0,-2,13.98,0,-3,13.99,0,-1,14.00,0,-2,14.01,0,-2,14.08,0,-1,ARL,0
2025-07-17T15:16:39.373467449Z,2025-07-17T15:16:39.373301585Z,10,2,1108,A,A,10,13.980000000,10,262432821,165864,221549244,13.28,11,2,13.14,99,1,13.11,100,1,13.10,100,1,12.99,100,1,12.73,100,1,12.67,100,1,12.65,100,1,12.51,100,1,12.43,666,1,13.40,0,-10,13.71,0,-1,13.78,0,-1,13.93,0,-2,13.94,0,-2,13.98,0,-3,13.99,0,-1,14.00,0,-2,14.01,0,-2,14.08,0,-1,ARL,0
2025-07-17T15:17:50.916325497Z,2025-07-17T15:17:50.916157330Z,10,2,1108,C,A,10,13.980000000,10,262432821,168167,223060323,13.28,11,2,13.14,99,1,13.11,100,1,13.10,100,1,12.99,100,1,12.73,100,1,12.67,100,1,12.65,100,1,12.51,100,1,12.43,666,1,13.40,0,-10,13.71,0,-1,13.78,0,-1,13.93,0,-2,13.94,0,-2,13.98,0,-4,13.99,0,-1,14.00,0,-2,14.01,0,-2,14.08,0,-1,ARL,0
2025-07-17T15:17:51.938467389Z,2025-07-17T15:17:51.938301087Z,10,2,1108,C,A,10,14.000000000,100,262279553,166302,223092013,13.28,11,2,13.14,99,1,13.11,100,1,13.10,100,1,12.99,100,1,12.73,100,1,12.67,100,1,12.65,100,1,12.51,100,1,12.43,666,1,13.40,0,-10,13.71,0,-1,13.78,0,-1,13.93,0,-2,13.94,0,-2,13.98,0,-4,13.99,0,-1,14.00,0,-2,14.01,0,-2,14.08,0,-1,ARL,0
2025-07-17T15:17:55.957423821Z,2025-07-17T15:17:55.957258362Z,10,2,1108,A,A,10,14.010000000,100,264420961,165459,223181022,13.28,11,2,13.14,99,1,13.11,100,1,13.10,100,1,12.99,100,1,12.73,100,1,12.67,100,1,12.65,100,1,12.51,100,1,12.43,666,1,13.40,0,-10,13.71,0,-1,13.78,0,-1,13.93,0,-2,13.94,0,-2,13.98,0,-4,13.99,0,-1,14.00,0,-2,14.01,0,-2,14.08,0,-1,ARL,0
2025-07-17T15:19:23.618380576Z,2025-07-17T15:19:23.618215364Z,10,2,1108,C,A,10,14.010000000,100,264420961,165212,224925658,13.28,11,2,13.14,99,1,13.11,100,1,13.10,100,1,12.99,100,1,12.73,100,1,12.67,100,1,12.65,100,1,12.51,100,1,12.43,666,1,13.40,0,-10,13.71,0,-1,13.78,0,-1,13.93,0,-2,13.94,0,-2,13.98,0,-4,13.99,0,-1,14.00,0,-2,14.01,0,-3,14.08,0,-1,ARL,0
2025-07-17T15:19:27.663790911Z,2025-07-17T15:19:27.663625107Z,10,2,1108,A,A,10,14.030000000,100,266714557,165804,224999109,13.28,11,2,13.14,99,1,13.11,100,1,13.10,100,1,12.99,100,1,12.73,100,1,12.67,100,1,12.65,100,1,12.51,100,1,12.43,666,1,13.40,0,-10,13.71,0,-1,13.78,0,-1,13.93,0,-2,13.94,0,-2,13.98,0,-4,13.99,0,-1,14.00,0,-2,14.01,0,-3,14.08,0,-1,ARL,0
2025-07-17T15:20:46.705145876Z,2025-07-17T15:20:46.704980311Z,10,2,1108,A,A,10,14.010000000,100,269075833,165565,226851430,13.28,11,2,13.14,99,1,13.11,100,1,13.10,100,1,12.99,100,1,12.73,100,1,12.67,100,1,12.65,100,1,12.51,100,1,12.43,666,1,13.40,0,-10,13.71,0,-1,13.78,0,-1,13.93,0,-2,13.94,0,-2,13.98,0,-4,13.99,0,-1,14.00,0,-2,14.01,0,-3,14.08,0,-1,ARL,0
2025-07-17T15:20:46.716698477Z,2025-07-17T15:20:46.716532886Z,10,2,1108,C,A,10,14.030000000,100,266714557,165591,226851533,13.28,11,2,13.14,99,1,13.11,100,1,13.10,100,1,12.99,100,1,12.73,100,1,12.67,100,1,12.65,100,1,12.51,100,1,12.43,666,1,13.40,0,-10,13.71,0,-1,13.78,0,-1,13.93,0,-2,13.94,0,-2,13.98,0,-4,13.99,0,-1,14.00,0,-2,14.01,0,-4,14.08,0,-1,ARL,0
2025-07-17T15:23:00.249962772Z,2025-07-17T15:23:00.249796874Z,10,2,1108,C,B,10,13.150000000,2,130693973,165898,229397485,13.28,11,2,13.14,99,1,13.11,100,1,13.10,100,1,12.99,100,1,12.73,100,1,12.67,100,1,12.65,100,1,12.51,100,1,12.43,666,1,13.40,0,-10,13.71,0,-1,13.78,0,-1,13.93,0,-2,13.94,0,-2,13.98,0,-4,13.99,0,-1,14.00,0,-2,14.01,0,-4,14.08,0,-1,ARL,0
2025-07-17T15:23:00.249962772Z,2025-07-17T15:23:00.249796874Z,10,2,1108,A,B,10,13.230000000,2,272263853,165898,229397485,13.28,11,2,13.23,2,1,13.14,99,1,13.11,100,1,13.10,100,1,12.99,100,1,12.73,100,1,12.67,100,1,12.65,100,1,12.51,100,1,13.40,0,-10,13.71,0,-1,13.78,0,-1,13.93,0,-2,13.94,0,-2,13.98,0,-4,13.99,0,-1,14.00,0,-2,14.01,0,-4,14.08,0,-1,ARL,0
2025-07-17T15:26:04.666158860Z,2025-07-17T15:26:04.665993515Z,10,2,1108,C,A,10,14.170000000,2,252720897,165345,232977340,13.28,11,2,13.14,99,1,13.11,100,1,13.10,100,1,12.99,100,1,12.73,100,1,12.67,100,1,12.65,100,1,12.51,100,1,12.43,666,1,13.40,0,-10,13.71,0,-1,13.78,0,-1,13.93,0,-2,13.94,0,-2,13.98,0,-4,13.99,0,-1,14.00,0,-2,14.01,0,-4,14.08,0,-1,ARL,0
2025-07-17T15:26:04.666158860Z,2025-07-17T15:26:04.665993515Z,10,2,1108,A,A,10,14.090000000,2,276751517,165345,232977340,13.28,11,2,13.14,99,1,13.11,100,1,13.10,100,1,12.99,100,1,12.73,100,1,12.67,100,1,12.65,100,1,12.51,100,1,12.43,666,1,13.40,0,-10,13.71,0,-1,13.78,0,-1,13.93,0,-2,13.94,0,-2,13.98,0,-4,13.99,0,-1,14.00,0,-2,14.01,0,-4,14.08,0,-1,ARL,0
2025-07-17T15:28:38.882985923Z,2025-07-17T15:28:38.882820591Z,10,2,1108,A,A,10,13.990000000,100,280387693,165332,235874491,13.28,11,2,13.14,99,1,13.11,100,1,13.10,100,1,12.99,100,1,12.73,100,1,12.67,100,1,12.65,100,1,12.51,100,1,12.43,666,1,13.40,0,-10,13.71,0,-1,13.78,0,-1,13.93,0,-2,13.94,0,-2,13.98,0,-4,13.99,0,-1,14.00,0,-2,14.01,0,-4,14.08,0,-1,ARL,0
2025-07-17T15:28:38.890789214Z,2025-07-17T15:28:38.890623989Z,10,2,1108,C,A,10,14.010000000,100,269075833,165225,235874556,13.28,11,2,13.14,99,1,13.11,100,1,13.10,100,1,12.99,100,1,12.73,100,1,12.67,100,1,12.65,100,1,12.51,100,1,12.43,666,1,13.40,0,-10,13.71,0,-1,13.78,0,-1,13.93,0,-2,13.94,0,-2,13.98,0,-4,13.99,0,-2,14.00,0,-2,14.01,0,-4,14.08,0,-1,ARL,0
2025-07-17T15:28:44.820934614Z,2025-07-17T15:28:44.820769301Z,10,2,1108,C,A,10,13.990000000,100,280387693,165313,235961324,13.28,11,2,13.14,99,1,13.11,100,1,13.10,100,1,12.99,100,1,12.73,100,1,12.67,100,1,12.65,100,1,12.51,100,1,12.43,666,1,13.40,0,-10,13.71,0,-1,13.78,0,-1,13.93,0,-2,13.94,0,-2,13.98,0,-4,13.99,0,-2,14.00,0,-2,14.01,0,-4,14.08,0,-1,ARL,0
2025-07-17T15:28:48.918811203Z,2025-07-17T15:28:48.918645728Z,10,2,1108,A,A,10,14.010000000,100,280580873,165475,236028551,13.28,11,2,13.14,99,1,13.11,100,1,13.10,100,1,12.99,100,1,12.73,100,1,12.67,100,1,12.65,100,1,12.51,100,1,12.43,666,1,13.40,0,-10,13.71,0,-1,13.78,0,-1,13.93,0,-2,13.94,0,-2,13.98,0,-4,13.99,0,-2,14.00,0,-2,14.01,0,-4,14.08,0,-1,ARL,0
2025-07-17T15:30:23.573233259Z,2025-07-17T15:30:23.573067851Z,10,2,1108,A,A,10,13.820000000,10,282775557,165408,237754758,13.28,11,2,13.14,99,1,13.11,100,1,13.10,100,1,12.99,100,1,12.73,100,1,12.67,100,1,12.65,100,1,12.51,100,1,12.43,666,1,13.40,0,-10,13.71,0,-1,13.78,0,-1,13.93,0,-2,13.94,0,-2,13.98,0,-4,13.99,0,-2,14.00,0,-2,14.01,0,-4,14.08,0,-1,ARL,0
2025-07-17T15:30:23.573528359Z,2025-07-17T15:30:23.573362522Z,10,2,1108,C,A,10,14.980000000,100,128570237,165837,237754762,13.28,11,2,13.14,99,1,13.11,100,1,13.10,100,1,12.99,100,1,12.73,100,1,12.67,100,1,12.65,100,1,12.51,100,1,12.43,666,1,13.40,0,-10,13.71,0,-1,13.78,0,-1,13.82,0,-1,13.93,0,-2,13.94,0,-2,13.98,0,-4,13.99,0,-2,14.00,0,-2,14.01,0,-4,ARL,0
2025-07-17T15:30:23.573528359Z,2025-07-17T15:30:23.573362522Z,10,2,1108,A,A,10,14.720000000,100,282775561,165837,237754762,13.28,11,2,13.14,99,1,13.11,100,1,13.10,100,1,12.99,100,1,12.73,100,1,12.67,100,1,12.65,100,1,12.51,100,1,12.43,666,1,13.40,0,-10,13.71,0,-1,13.78,0,-1,13.82,0,-1,13.93,0,-2,13.94,0,-2,13.98,0,-4,13.99,0,-2,14.00,0,-2,14.01,0,-4,ARL,0
2025-07-17T15:30:23.574854165Z,2025-07-17T15:30:23.574688647Z,10,2,1108,C,A,10,14.980000000,100,128570229,165518,237754776,13.28,11,2,13.14,99,1,13.11,100,1,13.10,100,1,12.99,100,1,12.73,100,1,12.67,100,1,12.65,100,1,12.51,100,1,12.43,666,1,13.40,0,-10,13.71,0,-1,13.78,0,-1,13.82,0,-1,13.93,0,-2,13.94,0,-2,13.98,0,-4,13.99,0,-2,14.00,0,-2,14.01,0,-4,ARL,0
2025-07-17T15:30:23.574854165Z,2025-07-17T15:30:23.574688647Z,10,2,1108,A,A,10,14.720000000,100,282775577,165518,237754776,13.28,11,2,13.14,99,1,13.11,100,1,13.10,100,1,12.99,100,1,12.73,100,1,12.67,100,1,12.65,100,1,12.51,100,1,12.43,666,1,13.40,0,-10,13.71,0,-1,13.78,0,-1,13.82,0,-1,13.93,0,-2,13.94,0,-2,13.98,0,-4,13.99,0,-2,14.00,0,-2,14.01,0,-4,ARL,0
2025-07-17T15:30:23.585191081Z,2025-07-17T15:30:23.585025490Z,10,2,1108,A,A,10,13.840000000,100,282775973,165591,237755075,13.28,11,2,13.14,99,1,13.11,100,1,13.10,100,1,12.99,100,1,12.73,100,1,12.67,100,1,12.65,100,1,12.51,100,1,12.43,666,1,13.40,0,-10,13.71,0,-1,13.78,0,-1,13.82,0,-1,13.93,0,-2,13.94,0,-2,13.98,0,-4,13.99,0,-2,14.00,0,-2,14.01,0,-4,ARL,0
2025-07-17T15:30:23.585960886Z,2025-07-17T15:30:23.585795327Z,10,2,1108,C,A,10,15.090000000,100,146955361,165559,237755081,13.28,11,2,13.14,99,1,13.11,100,1,13.10,100,1,12.99,100,1,12.73,100,1,12.67,100,1,12.65,100,1,12.51,100,1,12.43,666,1,13.40,0,-10,13.71,0,-1,13.78,0,-1,13.82,0,-1,13.84,0,-1,13.93,0,-2,13.94,0,-2,13.98,0,-4,13.99,0,-2,14.00,0,-2,ARL,0
2025-07-17T15:30:23.585960886Z,2025-07-17T15:30:23.585795327Z,10,2,1108,A,A,10,14.910000000,100,282776009,165559,237755081,13.28,11,2,13.14,99,1,13.11,100,1,13.10,100,1,12.99,100,1,12.73,100,1,12.67,100,1,12.65,100,1,12.51,100,1,12.43,666,1,13.40,0,-10,13.71,0,-1,13.78,0,-1,13.82,0,-1,13.84,0,-1,13.93,0,-2,13.94,0,-2,13.98,0,-4,13.99,0,-2,14.00,0,-2,ARL,0
2025-07-17T15:30:23.586719371Z,2025-07-17T15:30:23.586553674Z,10,2,1108,C,A,10,14.890000000,100,128570453,165697,237755086,13.28,11,2,13.14,99,1,13.11,100,1,13.10,100,1,12.99,100,1,12.73,100,1,12.67,100,1,12.65,100,1,12.51,100,1,12.43,666,1,13.40,0,-10,13.71,0,-1,13.78,0,-1,13.82,0,-1,13.84,0,-1,13.93,0,-2,13.94,0,-2,13.98,0,-4,13.99,0,-2,14.00,0,-2,ARL,0
2025-07-17T15:30:23.586719371Z,2025-07-17T15:30:23.586553674Z,10,2,1108,A,A,10,14.650000000,100,282776013,165697,237755086,13.28,11,2,13.14,99,1,13.11,100,1,13.10,100,1,12.99,100,1,12.73,100,1,12.67,100,1,12.65,100,1,12.51,100,1,12.43,666,1,13.40,0,-10,13.71,0,-1,13.78,0,-1,13.82,0,-1,13.84,0,-1,13.93,0,-2,13.94,0,-2,13.98,0,-4,13.99,0,-2,14.00,0,-2,ARL,0
2025-07-17T15:30:23.586762105Z,2025-07-17T15:30:23.586596452Z,10,2,1108,C,A,10,15.640000000,100,84628833,165653,237755087,13.28,11,2,13.14,99,1,13.11,100,1,13.10,100,1,12.99,100,1,12.73,100,1,12.67,100,1,12.65,100,1,12.51,100,1,12.43,666,1,13.40,0,-10,13.71,0,-1,13.78,0,-1,13.82,0,-1,13.84,0,-1,13.93,0,-2,13.94,0,-2,13.98,0,-4,13.99,0,-2,14.00,0,-2,ARL,0
2025-07-17T15:30:23.586762105Z,2025-07-17T15:30:23.586596452Z,10,2,1108,A,A,10,15.230000000,100,282776017,165653,237755087,13.28,11,2,13.14,99,1,13.11,100,1,13.10,100,1,12.99,100,1,12.73,100,1,12.67,100,1,12.65,100,1,12.51,100,1,12.43,666,1,13.40,0,-10,13.71,0,-1,13.78,0,-1,13.82,0,-1,13.84,0,-1,13.93,0,-2,13.94,0,-2,13.98,0,-4,13.99,0,-2,14.00,0,-2,ARL,0
2025-07-17T15:30:23.587432517Z,2025-07-17T15:30:23.587267064Z,10,2,1108,C,A,10,17.900000000,100,128570685,165453,237755097,13.28,11,2,13.14,99,1,13.11,100,1,13.10,100,1,12.99,100,1,12.73,100,1,12.67,100,1,12.65,100,1,12.51,100,1,12.43,666,1,13.40,0,-10,13.71,0,-1,13.78,0,-1,13.82,0,-1,13.84,0,-1,13.93,0,-2,13.94,0,-2,13.98,0,-4,13.99,0,-2,14.00,0,-2,ARL,0
2025-07-17T15:30:23.587432517Z,2025-07-17T15:30:23.587267064Z,10,2,1108,A,A,10,17.580000000,100,282776025,165453,237755097,13.28,11,2,13.14,99,1,13.11,100,1,13.10,100,1,12.99,100,1,12.73,100,1,12.67,100,1,12.65,100,1,12.51,100,1,12.43,666,1,13.40,0,-10,13.71,0,-1,13.78,0,-1,13.82,0,-1,13.84,0,-1,13.93,0,-2,13.94,0,-2,13.98,0,-4,13.99,0,-2,14.00,0,-2,ARL,0
2025-07-17T15:30:23.587581881Z,2025-07-17T15:30:23.587416236Z,10,2,1108,C,A,10,15.080000000,100,128570449,165645,237755098,13.28,11,2,13.14,99,1,13.11,100,1,13.10,100,1,12.99,100,1,12.73,100,1,12.67,100,1,12.65,100,1,12.51,100,1,12.43,666,1,13.40,0,-10,13.71,0,-1,13.78,0,-1,13.82,0,-1,13.84,0,-1,13.93,0,-2,13.94,0,-2,13.98,0,-4,13.99,0,-2,14.00,0,-2,ARL,0
2025-07-17T15:30:23.587581881Z,2025-07-17T15:30:23.587416236Z,10,2,1108,A,A,10,14.810000000,100,282776029,165645,237755098,13.28,11,2,13.14,99,1,13.11,100,1,13.10,100,1,12.99,100,1,12.73,100,1,12.67,100,1,12.65,100,1,12.51,100,1,12.43,666,1,13.40,0,-10,13.71,0,-1,13.78,0,-1,13.82,0,-1,13.84,0,-1,13.93,0,-2,13.94,0,-2,13.98,0,-4,13.99,0,-2,14.00,0,-2,ARL,0
2025-07-17T15:30:23.587611440Z,2025-07-17T15:30:23.587445922Z,10,2,1108,C,A,10,16.210000000,100,128570977,165518,237755099,13.28,11,2,13.14,99,1,13.11,100,1,13.10,100,1,12.99,100,1,12.73,100,1,12.67,100,1,12.65,100,1,12.51,100,1,12.43,666,1,13.40,0,-10,13.71,0,-1,13.78,0,-1,13.82,0,-1,13.84,0,-1,13.93,0,-2,13.94,0,-2,13.98,0,-4,13.99,0,-2,14.00,0,-2,ARL,0
2025-07-17T15:30:23.587611440Z,2025-07-17T15:30:23.587445922Z,10,2,1108,A,A,10,15.920000000,100,282776033,165518,237755099,13.28,11,2,13.14,99,1,13.11,100,1,13.10,100,1,12.99,100,1,12.73,100,1,12.67,100,1,12.65,100,1,12.51,100,1,12.43,666,1,13.40,0,-10,13.71,0,-1,13.78,0,-1,13.82,0,-1,13.84,0,-1,13.93,0,-2,13.94,0,-2,13.98,0,-4,13.99,0,-2,14.00,0,-2,ARL,0
2025-07-17T15:30:23.590261792Z,2025-07-17T15:30:23.590096343Z,10,2,1108,C,A,10,15.080000000,100,128573957,165449,237755128,13.28,11,2,13.14,99,1,13.11,100,1,13.10,100,1,12.99,100,1,12.73,100,1,12.67,100,1,12.65,100,1,12.51,100,1,12.43,666,1,13.40,0,-10,13.71,0,-1,13.78,0,-1,13.82,0,-1,13.84,0,-1,13.93,0,-2,13.94,0,-2,13.98,0,-4,13.99,0,-2,14.00,0,-2,ARL,0
2025-07-17T15:30:23.590261792Z,2025-07-17T15:30:23.590096343Z,10,2,1108,A,A,10,14.810000000,100,282776089,165449,237755128,13.28,11,2,13.14,99,1,13.11,100,1,13.10,100,1,12.99,100,1,12.73,100,1,12.67,100,1,12.65,100,1,12.51,100,1,12.43,666,1,13.40,0,-10,13.71,0,-1,13.78,0,-1,13.82,0,-1,13.84,0,-1,13.93,0,-2,13.94,0,-2,13.98,0,-4,13.99,0,-2,14.00,0,-2,ARL,0
2025-07-17T15:30:23.591959120Z,2025-07-17T15:30:23.591793735Z,10,2,1108,C,A,10,14.010000000,100,280580873,165385,237755138,13.28,11,2,13.14,99,1,13.11,100,1,13.10,100,1,12.99,100,1,12.73,100,1,12.67,100,1,12.65,100,1,12.51,100,1,12.43,666,1,13.40,0,-10,13.71,0,-1,13.78,0,-1,13.82,0,-1,13.84,0,-1,13.93,0,-2,13.94,0,-2,13.98,0,-4,13.99,0,-2,14.00,0,-2,ARL,0
2025-07-17T15:30:23.602992439Z,2025-07-17T15:30:23.602827102Z,10,2,1108,C,A,10,14.280000000,100,146956357,165337,237755229,13.28,11,2,13.14,99,1,13.11,100,1,13.10,100,1,12.99,100,1,12.73,100,1,12.67,100,1,12.65,100,1,12.51,100,1,12.43,666,1,13.40,0,-10,13.71,0,-1,13.78,0,-1,13.82,0,-1,13.84,0,-1,13.93,0,-2,13.94,0,-2,13.98,0,-4,13.99,0,-2,14.00,0,-2,ARL,0
2025-07-17T15:30:23.603046460Z,2025-07-17T15:30:23.602881129Z,10,2,1108,A,A,10,14.120000000,100,282776285,165331,237755230,13.28,11,2,13.14,99,1,13.11,100,1,13.10,100,1,12.99,100,1,12.73,100,1,12.67,100,1,12.65,100,1,12.51,100,1,12.43,666,1,13.40,0,-10,13.71,0,-1,13.78,0,-1,13.82,0,-1,13.84,0,-1,13.93,0,-2,13.94,0,-2,13.98,0,-4,13.99,0,-2,14.00,0,-2,ARL,0
2025-07-17T15:30:23.628720816Z,2025-07-17T15:30:23.628555135Z,10,2,1108,A,A,10,15.780000000,100,282776733,165681,237755415,13.28,11,2,13.14,99,1,13.11,100,1,13.10,100,1,12.99,100,1,12.73,100,1,12.67,100,1,12.65,100,1,12.51,100,1,12.43,666,1,13.40,0,-10,13.71,0,-1,13.78,0,-1,13.82,0,-1,13.84,0,-1,13.93,0,-2,13.94,0,-2,13.98,0,-4,13.99,0,-2,14.00,0,-2,ARL,0
2025-07-17T15:30:23.628732597Z,2025-07-17T15:30:23.628567293Z,10,2,1108,C,A,10,16.200000000,100,84628765,165304,237755416,13.28,11,2,13.14,99,1,13.11,100,1,13.10,100,1,12.99,100,1,12.73,100,1,12.67,100,1,12.65,100,1,12.51,100,1,12.43,666,1,13.40,0,-10,13.71,0,-1,13.78,0,-1,13.82,0,-1,13.84,0,-1,13.93,0,-2,13.94,0,-2,13.98,0,-4,13.99,0,-2,14.00,0,-2,ARL,0
2025-07-17T15:30:23.952122580Z,2025-07-17T15:30:23.951957017Z,10,2,1108,C,A,10,13.990000000,100,237978541,165563,237759683,13.28,11,2,13.14,99,1,13.11,100,1,13.10,100,1,12.99,100,1,12.73,100,1,12.67,100,1,12.65,100,1,12.51,100,1,12.43,666,1,13.40,0,-10,13.71,0,-1,13.78,0,-1,13.82,0,-1,13.84,0,-1,13.93,0,-2,13.94,0,-2,13.98,0,-4,13.99,0,-2,14.00,0,-2,ARL,0
2025-07-17T15:30:23.952122580Z,2025-07-17T15:30:23.951957017Z,10,2,1108,A,A,10,13.830000000,100,282781741,165563,237759683,13.28,11,2,13.14,99,1,13.11,100,1,13.10,100,1,12.99,100,1,12.73,100,1,12.67,100,1,12.65,100,1,12.51,100,1,12.43,666,1,13.40,0,-10,13.71,0,-1,13.78,0,-1,13.82,0,-1,13.84,0,-1,13.93,0,-2,13.94,0,-2,13.98,0,-4,13.99,0,-2,14.00,0,-2,ARL,0
2025-07-17T15:30:24.769074814Z,2025-07-17T15:30:24.768909757Z,10,2,1108,C,A,10,13.820000000,10,282775557,165057,237771822,13.28,11,2,13.14,99,1,13.11,100,1,13.10,100,1,12.99,100,1,12.73,100,1,12.67,100,1,12.65,100,1,12.51,100,1,12.43,666,1,13.40,0,-10,13.71,0,-1,13.78,0,-1,13.82,0,-1,13.84,0,-1,13.93,0,-2,13.94,0,-2,13.98,0,-4,13.99,0,-2,14.00,0,-2,ARL,0
2025-07-17T15:30:28.617337198Z,2025-07-17T15:30:28.617171810Z,10,2,1108,A,A,10,14.530000000,700,282881853,165388,237840336,13.28,11,2,13.14,99,1,13.11,100,1,13.10,100,1,12.99,100,1,12.73,100,1,12.67,100,1,12.65,100,1,12.51,100,1,12.43,666,1,13.40,0,-10,13.71,0,-1,13.78,0,-1,13.82,0,-1,13.84,0,-1,13.93,0,-2,13.94,0,-2,13.98,0,-4,13.99,0,-2,14.00,0,-2,ARL,0
2025-07-17T15:30:28.617387294Z,2025-07-17T15:30:28.617221981Z,10,2,1108,C,A,10,15.070000000,700,92510741,165313,237840337,13.28,11,2,13.14,99,1,13.11,100,1,13.10,100,1,12.99,100,1,12.73,100,1,12.67,100,1,12.65,100,1,12.51,100,1,12.43,666,1,13.40,0,-10,13.71,0,-1,13.78,0,-1,13.82,0,-1,13.84,0,-1,13.93,0,-2,13.94,0,-2,13.98,0,-4,13.99,0,-2,14.00,0,-2,ARL,0
2025-07-17T15:30:30.767213907Z,2025-07-17T15:30:30.767048606Z,10,2,1108,A,A,10,14.600000000,700,282920685,165301,237873135,13.28,11,2,13.14,99,1,13.11,100,1,13.10,100,1,12.99,100,1,12.73,100,1,12.67,100,1,12.65,100,1,12.51,100,1,12.43,666,1,13.40,0,-10,13.71,0,-1,13.78,0,-1,13.82,0,-1,13.84,0,-1,13.93,0,-2,13.94,0,-2,13.98,0,-4,13.99,0,-2,14.00,0,-2,ARL,0
2025-07-17T15:30:30.767267001Z,2025-07-17T15:30:30.767101317Z,10,2,1108,C,A,10,14.990000000,700,84628757,165684,237873136,13.28,11,2,13.14,99,1,13.11,100,1,13.10,100,1,12.99,100,1,12.73,100,1,12.67,100,1,12.65,100,1,12.51,100,1,12.43,666,1,13.40,0,-10,13.71,0,-1,13.78,0,-1,13.82,0,-1,13.84,0,-1,13.93,0,-2,13.94,0,-2,13.98,0,-4,13.99,0,-2,14.00,0,-2,ARL,0
2025-07-17T15:30:33.016987097Z,2025-07-17T15:30:33.016821395Z,10,2,1108,A,A,10,14.560000000,700,282969973,165702,237915946,13.28,11,2,13.14,99,1,13.11,100,1,13.10,100,1,12.99,100,1,12.73,100,1,12.67,100,1,12.65,100,1,12.51,100,1,12.43,666,1,13.40,0,-10,13.71,0,-1,13.78,0,-1,13.82,0,-1,13.84,0,-1,13.93,0,-2,13.94,0,-2,13.98,0,-4,13.99,0,-2,14.00,0,-2,ARL,0
2025-07-17T15:30:33.017384279Z,2025-07-17T15:30:33.017218657Z,10,2,1108,C,A,10,14.950000000,700,84628797,165622,237915951,13.28,11,2,13.14,99,1,13.11,100,1,13.10,100,1,12.99,100,1,12.73,100,1,12.67,100,1,12.65,100,1,12.51,100,1,12.43,666,1,13.40,0,-10,13.71,0,-1,13.78,0,-1,13.82,0,-1,13.84,0,-1,13.93,0,-2,13.94,0,-2,13.98,0,-4,13.99,0,-2,14.00,0,-2,ARL,0
2025-07-17T15:30:49.985906754Z,2025-07-17T15:30:49.985741094Z,10,2,1108,C,A,10,14.090000000,2,276751517,165660,238230724,13.28,11,2,13.14,99,1,13.11,100,1,13.10,100,1,12.99,100,1,12.73,100,1,12.67,100,1,12.65,100,1,12.51,100,1,12.43,666,1,13.40,0,-10,13.71,0,-1,13.78,0,-1,13.82,0,-1,13.84,0,-1,13.93,0,-2,13.94,0,-2,13.98,0,-4,13.99,0,-2,14.00,0,-2,ARL,0
2025-07-17T15:30:49.985906754Z,2025-07-17T15:30:49.985741094Z,10,2,1108,A,A,10,14.020000000,2,283348193,165660,238230724,13.28,11,2,13.14,99,1,13.11,100,1,13.10,100,1,12.99,100,1,12.73,100,1,12.67,100,1,12.65,100,1,12.51,100,1,12.43,666,1,13.40,0,-10,13.71,0,-1,13.78,0,-1,13.82,0,-1,13.84,0,-1,13.93,0,-2,13.94,0,-2,13.98,0,-4,13.99,0,-2,14.00,0,-2,ARL,0
2025-07-17T15:30:59.996516554Z,2025-07-17T15:30:59.996351383Z,10,2,1108,C,A,10,13.830000000,100,282781741,165171,238442318,13.28,11,2,13.14,99,1,13.11,100,1,13.10,100,1,12.99,100,1,12.73,100,1,12.67,100,1,12.65,100,1,12.51,100,1,12.43,666,1,13.40,0,-10,13.71,0,-1,13.78,0,-1,13.82,0,-1,13.84,0,-1,13.93,0,-2,13.94,0,-2,13.98,0,-4,13.99,0,-2,14.00,0,-2,ARL,0
2025-07-17T15:31:00.002203922Z,2025-07-17T15:31:00.002038446Z,10,2,1108,C,A,10,13.840000000,100,282775973,165476,238442443,13.28,11,2,13.14,99,1,13.11,100,1,13.10,100,1,12.99,100,1,12.73,100,1,12.67,100,1,12.65,100,1,12.51,100,1,12.43,666,1,13.40,0,-10,13.71,0,-1,13.78,0,-1,13.82,0,-1,13.84,0,-1,13.93,0,-2,13.94,0,-2,13.98,0,-4,13.99,0,-2,14.00,0,-2,ARL,0
2025-07-17T15:31:00.002478393Z,2025-07-17T15:31:00.002313250Z,10,2,1108,C,A,10,14.530000000,700,282881853,165143,238442461,13.28,11,2,13.14,99,1,13.11,100,1,13.10,100,1,12.99,100,1,12.73,100,1,12.67,100,1,12.65,100,1,12.51,100,1,12.43,666,1,13.40,0,-10,13.71,0,-1,13.78,0,-1,13.82,0,-1,13.84,0,-1,13.93,0,-2,13.94,0,-2,13.98,0,-4,13.99,0,-2,14.00,0,-2,ARL,0
2025-07-17T15:31:00.002525213Z,2025-07-17T15:31:00.002359969Z,10,2,1108,A,A,10,14.680000000,700,283592941,165244,238442467,13.28,11,2,13.14,99,1,13.11,100,1,13.10,100,1,12.99,100,1,12.73,100,1,12.67,100,1,12.65,100,1,12.51,100,1,12.43,666,1,13.40,0,-10,13.71,0,-1,13.78,0,-1,13.82,0,-1,13.84,0,-1,13.93,0,-2,13.94,0,-2,13.98,0,-4,13.99,0,-2,14.00,0,-2,ARL,0
2025-07-17T15:31:00.002938332Z,2025-07-17T15:31:00.002772683Z,10,2,1108,C,A,10,14.720000000,100,282775577,165649,238442486,13.28,11,2,13.14,99,1,13.11,100,1,13.10,100,1,12.99,100,1,12.73,100,1,12.67,100,1,12.65,100,1,12.51,100,1,12.43,666,1,13.40,0,-10,13.71,0,-1,13.78,0,-1,13.82,0,-1,13.84,0,-1,13.93,0,-2,13.94,0,-2,13.98,0,-4,13.99,0,-2,14.00,0,-2,ARL,0
2025-07-17T15:31:00.002938332Z,2025-07-17T15:31:00.002772683Z,10,2,1108,A,A,10,14.970000000,100,283592993,165649,238442486,13.28,11,2,13.14,99,1,13.11,100,1,13.10,100,1,12.99,100,1,12.73,100,1,12.67,100,1,12.65,100,1,12.51,100,1,12.43,666,1,13.40,0,-10,13.71,0,-1,13.78,0,-1,13.82,0,-1,13.84,0,-1,13.93,0,-2,13.94,0,-2,13.98,0,-4,13.99,0,-2,14.00,0,-2,ARL,0
2025-07-17T15:31:00.002953704Z,2025-07-17T15:31:00.002788190Z,10,2,1108,C,A,10,14.910000000,100,282776009,165514,238442490,13.28,11,2,13.14,99,1,13.11,100,1,13.10,100,1,12.99,100,1,12.73,100,1,12.67,100,1,12.65,100,1,12.51,100,1,12.43,666,1,13.40,0,-10,13.71,0,-1,13.78,0,-1,13.82,0,-1,13.84,0,-1,13.93,0,-2,13.94,0,-2,13.98,0,-4,13.99,0,-2,14.00,0,-2,ARL,0
2025-07-17T15:31:00.002953704Z,2025-07-17T15:31:00.002788190Z,10,2,1108,A,A,10,14.960000000,100,283592997,165514,238442490,13.28,11,2,13.14,99,1,13.11,100,1,13.10,100,1,12.99,100,1,12.73,100,1,12.67,100,1,12.65,100,1,12.51,100,1,12.43,666,1,13.40,0,-10,13.71,0,-1,13.78,0,-1,13.82,0,-1,13.84,0,-1,13.93,0,-2,13.94,0,-2,13.98,0,-4,13.99,0,-2,14.00,0,-2,ARL,0
2025-07-17T15:31:00.003368272Z,2025-07-17T15:31:00.003202003Z,10,2,1108,C,A,10,14.720000000,100,282775561,166269,238442510,13.28,11,2,13.14,99,1,13.11,100,1,13.10,100,1,12.99,100,1,12.73,100,1,12.67,100,1,12.65,100,1,12.51,100,1,12.43,666,1,13.40,0,-10,13.71,0,-1,13.78,0,-1,13.82,0,-1,13.84,0,-1,13.93,0,-2,13.94,0,-2,13.98,0,-4,13.99,0,-2,14.00,0,-2,ARL,0
2025-07-17T15:31:00.003368272Z,2025-07-17T15:31:00.003202003Z,10,2,1108,A,A,10,14.970000000,100,283593041,166269,238442510,13.28,11,2,13.14,99,1,13.11,100,1,13.10,100,1,12.99,100,1,12.73,100,1,12.67,100,1,12.65,100,1,12.51,100,1,12.43,666,1,13.40,0,-10,13.71,0,-1,13.78,0,-1,13.82,0,-1,13.84,0,-1,13.93,0,-2,13.94,0,-2,13.98,0,-4,13.99,0,-2,14.00,0,-2,ARL,0
2025-07-17T15:31:00.006784947Z,2025-07-17T15:31:00.006618398Z,10,2,1108,C,A,10,14.650000000,100,282776013,166549,238442608,13.28,11,2,13.14,99,1,13.11,100,1,13.10,100,1,12.99,100,1,12.73,100,1,12.67,100,1,12.65,100,1,12.51,100,1,12.43,666,1,13.40,0,-10,13.71,0,-1,13.78,0,-1,13.82,0,-1,13.84,0,-1,13.93,0,-2,13.94,0,-2,13.98,0,-4,13.99,0,-2,14.00,0,-2,ARL,0
2025-07-17T15:31:00.006950491Z,2025-07-17T15:31:00.006784814Z,10,2,1108,A,A,10,14.790000000,100,283593313,165677,238442616,13.28,11,2,13.14,99,1,13.11,100,1,13.10,100,1,12.99,100,1,12.73,100,1,12.67,100,1,12.65,100,1,12.51,100,1,12.43,666,1,13.40,0,-10,13.71,0,-1,13.78,0,-1,13.82,0,-1,13.84,0,-1,13.93,0,-2,13.94,0,-2,13.98,0,-4,13.99,0,-2,14.00,0,-2,ARL,0
2025-07-17T15:31:00.017759891Z,2025-07-17T15:31:00.017594312Z,10,2,1108,C,A,10,17.580000000,100,282776025,165579,238443214,13.28,11,2,13.14,99,1,13.11,100,1,13.10,100,1,12.99,100,1,12.73,100,1,12.67,100,1,12.65,100,1,12.51,100,1,12.43,666,1,13.40,0,-10,13.71,0,-1,13.78,0,-1,13.82,0,-1,13.84,0,-1,13.93,0,-2,13.94,0,-2,13.98,0,-4,13.99,0,-2,14.00,0,-2,ARL,0
2025-07-17T15:31:00.017759891Z,2025-07-17T15:31:00.017594312Z,10,2,1108,A,A,10,17.760000000,100,283594173,165579,238443214,13.28,11,2,13.14,99,1,13.11,100,1,13.10,100,1,12.99,100,1,12.73,100,1,12.67,100,1,12.65,100,1,12.51,100,1,12.43,666,1,13.40,0,-10,13.71,0,-1,13.78,0,-1,13.82,0,-1,13.84,0,-1,13.93,0,-2,13.94,0,-2,13.98,0,-4,13.99,0,-2,14.00,0,-2,ARL,0
2025-07-17T15:31:00.028894478Z,2025-07-17T15:31:00.028729168Z,10,2,1108,C,A,10,14.120000000,100,282776285,165310,238443996,13.28,11,2,13.14,99,1,13.11,100,1,13.10,100,1,12.99,100,1,12.73,100,1,12.67,100,1,12.65,100,1,12.51,100,1,12.43,666,1,13.40,0,-10,13.71,0,-1,13.78,0,-1,13.82,0,-1,13.84,0,-1,13.93,0,-2,13.94,0,-2,13.98,0,-4,13.99,0,-2,14.00,0,-2,ARL,0
2025-07-17T15:31:00.028947312Z,2025-07-17T15:31:00.028782030Z,10,2,1108,A,A,10,14.260000000,100,283595181,165282,238443998,13.28,11,2,13.14,99,1,13.11,100,1,13.10,100,1,12.99,100,1,12.73,100,1,12.67,100,1,12.65,100,1,12.51,100,1,12.43,666,1,13.40,0,-10,13.71,0,-1,13.78,0,-1,13.82,0,-1,13.84,0,-1,13.93,0,-2,13.94,0,-2,13.98,0,-4,13.99,0,-2,14.00,0,-2,ARL,0
2025-07-17T15:31:00.053107210Z,2025-07-17T15:31:00.052941898Z,10,2,1108,C,A,10,14.960000000,100,283592997,165312,238444735,13.28,11,2,13.14,99,1,13.11,100,1,13.10,100,1,12.99,100,1,12.73,100,1,12.67,100,1,12.65,100,1,12.51,100,1,12.43,666,1,13.40,0,-10,13.71,0,-1,13.78,0,-1,13.82,0,-1,13.84,0,-1,13.93,0,-2,13.94,0,-2,13.98,0,-4,13.99,0,-2,14.00,0,-2,ARL,0
2025-07-17T15:31:00.053107210Z,2025-07-17T15:31:00.052941898Z,10,2,1108,A,A,10,15.060000000,100,283596673,165312,238444735,13.28,11,2,13.14,99,1,13.11,100,1,13.10,100,1,12.99,100,1,12.73,100,1,12.67,100,1,12.65,100,1,12.51,100,1,12.43,666,1,13.40,0,-10,13.71,0,-1,13.78,0,-1,13.82,0,-1,13.84,0,-1,13.93,0,-2,13.94,0,-2,13.98,0,-4,13.99,0,-2,14.00,0,-2,ARL,0
2025-07-17T15:31:00.054830847Z,2025-07-17T15:31:00.054665340Z,10,2,1108,C,A,10,14.810000000,100,282776089,165507,238444759,13.28,11,2,13.14,99,1,13.11,100,1,13.10,100,1,12.99,100,1,12.73,100,1,12.67,100,1,12.65,100,1,12.51,100,1,12.43,666,1,13.40,0,-10,13.71,0,-1,13.78,0,-1,13.82,0,-1,13.84,0,-1,13.93,0,-2,13.94,0,-2,13.98,0,-4,13.99,0,-2,14.00,0,-2,ARL,0
2025-07-17T15:31:00.054830847Z,2025-07-17T15:31:00.054665340Z,10,2,1108,A,A,10,14.960000000,100,283596721,165507,238444759,13.28,11,2,13.14,99,1,13.11,100,1,13.10,100,1,12.99,100,1,12.73,100,1,12.67,100,1,12.65,100,1,12.51,100,1,12.43,666,1,13.40,0,-10,13.71,0,-1,13.78,0,-1,13.82,0,-1,13.84,0,-1,13.93,0,-2,13.94,0,-2,13.98,0,-4,13.99,0,-2,14.00,0,-2,ARL,0
2025-07-17T15:31:00.071409275Z,2025-07-17T15:31:00.071243665Z,10,2,1108,C,A,10,14.810000000,100,282776029,165610,238444961,13.28,11,2,13.14,99,1,13.11,100,1,13.10,100,1,12.99,100,1,12.73,100,1,12.67,100,1,12.65,100,1,12.51,100,1,12.43,666,1,13.40,0,-10,13.71,0,-1,13.78,0,-1,13.82,0,-1,13.84,0,-1,13.93,0,-2,13.94,0,-2,13.98,0,-4,13.99,0,-2,14.00,0,-2,ARL,0
2025-07-17T15:31:00.071409275Z,2025-07-17T15:31:00.071243665Z,10,2,1108,A,A,10,14.960000000,100,283596945,165610,238444961,13.28,11,2,13.14,99,1,13.11,100,1,13.10,100,1,12.99,100,1,12.73,100,1,12.67,100,1,12.65,100,1,12.51,100,1,12.43,666,1,13.40,0,-10,13.71,0,-1,13.78,0,-1,13.82,0,-1,13.84,0,-1,13.93,0,-2,13.94,0,-2,13.98,0,-4,13.99,0,-2,14.00,0,-2,ARL,0
2025-07-17T15:31:00.243369582Z,2025-07-17T15:31:00.243203860Z,10,2,1108,C,A,10,15.920000000,100,282776033,165722,238447595,13.28,11,2,13.14,99,1,13.11,100,1,13.10,100,1,12.99,100,1,12.73,100,1,12.67,100,1,12.65,100,1,12.51,100,1,12.43,666,1,13.40,0,-10,13.71,0,-1,13.78,0,-1,13.82,0,-1,13.84,0,-1,13.93,0,-2,13.94,0,-2,13.98,0,-4,13.99,0,-2,14.00,0,-2,ARL,0
2025-07-17T15:31:00.243369582Z,2025-07-17T15:31:00.243203860Z,10,2,1108,A,A,10,16.080000000,100,283599609,165722,238447595,13.28,11,2,13.14,99,1,13.11,100,1,13.10,100,1,12.99,100,1,12.73,100,1,12.67,100,1,12.65,100,1,12.51,100,1,12.43,666,1,13.40,0,-10,13.71,0,-1,13.78,0,-1,13.82,0,-1,13.84,0,-1,13.93,0,-2,13.94,0,-2,13.98,0,-4,13.99,0,-2,14.00,0,-2,ARL,0
2025-07-17T15:31:00.347828545Z,2025-07-17T15:31:00.347663441Z,10,2,1108,A,A,10,14.030000000,100,283604173,165104,238450791,13.28,11,2,13.14,99,1,13.11,100,1,13.10,100,1,12.99,100,1,12.73,100,1,12.67,100,1,12.65,100,1,12.51,100,1,12.43,666,1,13.40,0,-10,13.71,0,-1,13.78,0,-1,13.82,0,-1,13.84,0,-1,13.93,0,-2,13.94,0,-2,13.98,0,-4,13.99,0,-2,14.00,0,-2,ARL,0
2025-07-17T15:31:04.014590575Z,2025-07-17T15:31:04.014425425Z,10,2,1108,A,A,10,14.000000000,100,283694233,165150,238529875,13.28,11,2,13.14,99,1,13.11,100,1,13.10,100,1,12.99,100,1,12.73,100,1,12.67,100,1,12.65,100,1,12.51,100,1,12.43,666,1,13.40,0,-10,13.71,0,-1,13.78,0,-1,13.82,0,-1,13.84,0,-1,13.93,0,-2,13.94,0,-2,13.98,0,-4,13.99,0,-2,14.00,0,-2,ARL,0
2025-07-17T15:31:04.124577845Z,2025-07-17T15:31:04.124411850Z,10,2,1108,C,A,10,14.030000000,100,283604173,165995,238531822,13.28,11,2,13.14,99,1,13.11,100,1,13.10,100,1,12.99,100,1,12.73,100,1,12.67,100,1,12.65,100,1,12.51,100,1,12.43,666,1,13.40,0,-10,13.71,0,-1,13.78,0,-1,13.82,0,-1,13.84,0,-1,13.93,0,-2,13.94,0,-2,13.98,0,-4,13.99,0,-2,14.00,0,-3,ARL,0
2025-07-17T15:31:04.124577845Z,2025-07-17T15:31:04.124411850Z,10,2,1108,A,A,10,14.010000000,100,283695933,165995,238531822,13.28,11,2,13.14,99,1,13.11,100,1,13.10,100,1,12.99,100,1,12.73,100,1,12.67,100,1,12.65,100,1,12.51,100,1,12.43,666,1,13.40,0,-10,13.71,0,-1,13.78,0,-1,13.82,0,-1,13.84,0,-1,13.93,0,-2,13.94,0,-2,13.98,0,-4,13.99,0,-2,14.00,0,-3,ARL,0
2025-07-17T15:32:28.644506279Z,2025-07-17T15:32:28.644335983Z,10,2,1108,A,B,10,13.550000000,10,285545121,170296,239938946,13.55,10,1,13.28,11,2,13.14,99,1,13.11,100,1,13.10,100,1,12.99,100,1,12.73,100,1,12.67,100,1,12.65,100,1,12.51,100,1,13.40,0,-10,13.71,0,-1,13.78,0,-1,13.82,0,-1,13.84,0,-1,13.93,0,-2,13.94,0,-2,13.98,0,-4,13.99,0,-2,14.00,0,-3,ARL,0
2025-07-17T15:32:28.653238729Z,2025-07-17T15:32:28.653073176Z,10,2,1108,C,B,10,13.370000000,100,215999737,165553,239940048,13.28,11,2,13.14,99,1,13.11,100,1,13.10,100,1,12.99,100,1,12.73,100,1,12.67,100,1,12.65,100,1,12.51,100,1,12.43,666,1,13.40,0,-10,13.71,0,-1,13.78,0,-1,13.82,0,-1,13.84,0,-1,13.93,0,-2,13.94,0,-2,13.98,0,-4,13.99,0,-2,14.00,0,-3,ARL,0
2025-07-17T15:32:28.653238729Z,2025-07-17T15:32:28.653073176Z,10,2,1108,A,B,10,13.540000000,100,285545885,165553,239940048,13.54,100,1,13.28,11,2,13.14,99,1,13.11,100,1,13.10,100,1,12.99,100,1,12.73,100,1,12.67,100,1,12.65,100,1,12.51,100,1,13.40,0,-10,13.71,0,-1,13.78,0,-1,13.82,0,-1,13.84,0,-1,13.93,0,-2,13.94,0,-2,13.98,0,-4,13.99,0,-2,14.00,0,-3,ARL,0
2025-07-17T15:32:28.653978501Z,2025-07-17T15:32:28.653812889Z,10,2,1108,C,B,10,12.330000000,100,215999753,165612,239940096,13.28,11,2,13.14,99,1,13.11,100,1,13.10,100,1,12.99,100,1,12.73,100,1,12.67,100,1,12.65,100,1,12.51,100,1,12.43,666,1,13.40,0,-10,13.71,0,-1,13.78,0,-1,13.82,0,-1,13.84,0,-1,13.93,0,-2,13.94,0,-2,13.98,0,-4,13.99,0,-2,14.00,0,-3,ARL,0
2025-07-17T15:32:28.653978501Z,2025-07-17T15:32:28.653812889Z,10,2,1108,A,B,10,12.490000000,100,285545945,165612,239940096,13.28,11,2,13.14,99,1,13.11,100,1,13.10,100,1,12.99,100,1,12.73,100,1,12.67,100,1,12.65,100,1,12.51,100,1,12.49,100,1,13.40,0,-10,13.71,0,-1,13.78,0,-1,13.82,0,-1,13.84,0,-1,13.93,0,-2,13.94,0,-2,13.98,0,-4,13.99,0,-2,14.00,0,-3,ARL,0
2025-07-17T15:32:28.653980648Z,2025-07-17T15:32:28.653815154Z,10,2,1108,C,B,10,12.670000000,100,43663229,165494,239940097,13.28,11,2,13.14,99,1,13.11,100,1,13.10,100,1,12.99,100,1,12.73,100,1,12.67,100,1,12.65,100,1,12.51,100,1,12.43,666,1,13.40,0,-10,13.71,0,-1,13.78,0,-1,13.82,0,-1,13.84,0,-1,13.93,0,-2,13.94,0,-2,13.98,0,-4,13.99,0,-2,14.00,0,-3,ARL,0
2025-07-17T15:32:28.654336987Z,2025-07-17T15:32:28.654171723Z,10,2,1108,A,B,10,12.940000000,100,285545953,165264,239940109,13.28,11,2,13.14,99,1,13.11,100,1,13.10,100,1,12.99,100,1,12.94,100,1,12.73,100,1,12.67,100,1,12.65,100,1,12.51,100,1,13.40,0,-10,13.71,0,-1,13.78,0,-1,13.82,0,-1,13.84,0,-1,13.93,0,-2,13.94,0,-2,13.98,0,-4,13.99,0,-2,14.00,0,-3,ARL,0
2025-07-17T15:32:28.657073743Z,2025-07-17T15:32:28.656908386Z,10,2,1108,C,B,10,12.470000000,100,43554133,165357,239940358,13.28,11,2,13.14,99,1,13.11,100,1,13.10,100,1,12.99,100,1,12.73,100,1,12.67,100,1,12.65,100,1,12.51,100,1,12.43,666,1,13.40,0,-10,13.71,0,-1,13.78,0,-1,13.82,0,-1,13.84,0,-1,13.93,0,-2,13.94,0,-2,13.98,0,-4,13.99,0,-2,14.00,0,-3,ARL,0
2025-07-17T15:32:28.657173856Z,2025-07-17T15:32:28.657008222Z,10,2,1108,A,B,10,12.730000000,100,285546061,165634,239940359,13.28,11,2,13.14,99,1,13.11,100,1,13.10,100,1,12.99,100,1,12.73,200,2,12.67,100,1,12.65,100,1,12.51,100,1,12.43,666,1,13.40,0,-10,13.71,0,-1,13.78,0,-1,13.82,0,-1,13.84,0,-1,13.93,0,-2,13.94,0,-2,13.98,0,-4,13.99,0,-2,14.00,0,-3,ARL,0
2025-07-17T15:32:28.667074437Z,2025-07-17T15:32:28.666909194Z,10,2,1108,C,B,10,13.100000000,100,216001413,165243,239940810,13.28,11,2,13.14,99,1,13.11,100,1,13.10,100,1,12.99,100,1,12.73,100,1,12.67,100,1,12.65,100,1,12.51,100,1,12.43,666,1,13.40,0,-10,13.71,0,-1,13.78,0,-1,13.82,0,-1,13.84,0,-1,13.93,0,-2,13.94,0,-2,13.98,0,-4,13.99,0,-2,14.00,0,-3,ARL,0
2025-07-17T15:32:28.667126637Z,2025-07-17T15:32:28.666961018Z,10,2,1108,A,B,10,13.270000000,100,285546673,165619,239940813,13.28,11,2,13.27,100,1,13.14,99,1,13.11,100,1,13.10,100,1,12.99,100,1,12.73,100,1,12.67,100,1,12.65,100,1,12.51,100,1,13.40,0,-10,13.71,0,-1,13.78,0,-1,13.82,0,-1,13.84,0,-1,13.93,0,-2,13.94,0,-2,13.98,0,-4,13.99,0,-2,14.00,0,-3,ARL,0
2025-07-17T15:32:28.674444711Z,2025-07-17T15:32:28.674279259Z,10,2,1108,C,B,10,12.330000000,100,43755813,165452,239941057,13.28,11,2,13.14,99,1,13.11,100,1,13.10,100,1,12.99,100,1,12.73,100,1,12.67,100,1,12.65,100,1,12.51,100,1,12.43,666,1,13.40,0,-10,13.71,0,-1,13.78,0,-1,13.82,0,-1,13.84,0,-1,13.93,0,-2,13.94,0,-2,13.98,0,-4,13.99,0,-2,14.00,0,-3,ARL,0
2025-07-17T15:32:28.674444711Z,2025-07-17T15:32:28.674279259Z,10,2,1108,A,B,10,12.590000000,100,285546893,165452,239941057,13.28,11,2,13.14,99,1,13.11,100,1,13.10,100,1,12.99,100,1,12.73,100,1,12.67,100,1,12.65,100,1,12.59,100,1,12.51,100,1,13.40,0,-10,13.71,0,-1,13.78,0,-1,13.82,0,-1,13.84,0,-1,13.93,0,-2,13.94,0,-2,13.98,0,-4,13.99,0,-2,14.00,0,-3,ARL,0
2025-07-17T15:32:28.691264796Z,2025-07-17T15:32:28.691099298Z,10,2,1108,C,B,10,9.670000000,100,44082961,165498,239941825,13.28,11,2,13.14,99,1,13.11,100,1,13.10,100,1,12.99,100,1,12.73,100,1,12.67,100,1,12.65,100,1,12.51,100,1,12.43,666,1,13.40,0,-10,13.71,0,-1,13.78,0,-1,13.82,0,-1,13.84,0,-1,13.93,0,-2,13.94,0,-2,13.98,0,-4,13.99,0,-2,14.00,0,-3,ARL,0
2025-07-17T15:32:28.691264796Z,2025-07-17T15:32:28.691099298Z,10,2,1108,A,B,10,9.880000000,100,285548137,165498,239941825,13.28,11,2,13.14,99,1,13.11,100,1,13.10,100,1,12.99,100,1,12.73,100,1,12.67,100,1,12.65,100,1,12.51,100,1,12.43,666,1,13.40,0,-10,13.71,0,-1,13.78,0,-1,13.82,0,-1,13.84,0,-1,13.93,0,-2,13.94,0,-2,13.98,0,-4,13.99,0,-2,14.00,0,-3,ARL,0
2025-07-17T15:32:28.711494526Z,2025-07-17T15:32:28.711329066Z,10,2,1108,C,B,10,11.270000000,100,43826785,165460,239942732,13.28,11,2,13.14,99,1,13.11,100,1,13.10,100,1,12.99,100,1,12.73,100,1,12.67,100,1,12.65,100,1,12.51,100,1,12.43,666,1,13.40,0,-10,13.71,0,-1,13.78,0,-1,13.82,0,-1,13.84,0,-1,13.93,0,-2,13.94,0,-2,13.98,0,-4,13.99,0,-2,14.00,0,-3,ARL,0
2025-07-17T15:32:28.711494526Z,2025-07-17T15:32:28.711329066Z,10,2,1108,A,B,10,11.500000000,100,285549537,165460,239942732,13.28,11,2,13.14,99,1,13.11,100,1,13.10,100,1,12.99,100,1,12.73,100,1,12.67,100,1,12.65,100,1,12.51,100,1,12.43,666,1,13.40,0,-10,13.71,0,-1,13.78,0,-1,13.82,0,-1,13.84,0,-1,13.93,0,-2,13.94,0,-2,13.98,0,-4,13.99,0,-2,14.00,0,-3,ARL,0
2025-07-17T15:32:28.771995987Z,2025-07-17T15:32:28.771830554Z,10,2,1108,C,B,10,13.550000000,10,285545121,165433,239945992,13.28,11,2,13.14,99,1,13.11,100,1,13.10,100,1,12.99,100,1,12.73,100,1,12.67,100,1,12.65,100,1,12.51,100,1,12.43,666,1,13.40,0,-10,13.71,0,-1,13.78,0,-1,13.82,0,-1,13.84,0,-1,13.93,0,-2,13.94,0,-2,13.98,0,-4,13.99,0,-2,14.00,0,-3,ARL,0
2025-07-17T15:32:28.806930722Z,2025-07-17T15:32:28.806765209Z,10,2,1108,C,B,10,12.330000000,100,44088633,165513,239948319,13.28,11,2,13.14,99,1,13.11,100,1,13.10,100,1,12.99,100,1,12.73,100,1,12.67,100,1,12.65,100,1,12.51,100,1,12.43,666,1,13.40,0,-10,13.71,0,-1,13.78,0,-1,13.82,0,-1,13.84,0,-1,13.93,0,-2,13.94,0,-2,13.98,0,-4,13.99,0,-2,14.00,0,-3,ARL,0
2025-07-17T15:32:28.806930722Z,2025-07-17T15:32:28.806765209Z,10,2,1108,A,B,10,12.590000000,100,285553901,165513,239948319,13.28,11,2,13.14,99,1,13.11,100,1,13.10,100,1,12.99,100,1,12.73,100,1,12.67,100,1,12.65,100,1,12.59,100,1,12.51,100,1,13.40,0,-10,13.71,0,-1,13.78,0,-1,13.82,0,-1,13.84,0,-1,13.93,0,-2,13.94,0,-2,13.98,0,-4,13.99,0,-2,14.00,0,-3,ARL,0
2025-07-17T15:32:28.850288215Z,2025-07-17T15:32:28.850122877Z,10,2,1108,A,A,10,13.980000000,100,285556869,165338,239950805,13.28,11,2,13.14,99,1,13.11,100,1,13.10,100,1,12.99,100,1,12.73,100,1,12.67,100,1,12.65,100,1,12.59,100,1,12.51,100,1,13.40,0,-10,13.71,0,-1,13.78,0,-1,13.82,0,-1,13.84,0,-1,13.93,0,-2,13.94,0,-2,13.98,0,-4,13.99,0,-2,14.00,0,-3,ARL,0
2025-07-17T15:32:28.857140107Z,2025-07-17T15:32:28.856973845Z,10,2,1108,C,A,10,14.000000000,100,283694233,166262,239951361,13.28,11,2,13.14,99,1,13.11,100,1,13.10,100,1,12.99,100,1,12.73,100,1,12.67,100,1,12.65,100,1,12.59,100,1,12.51,100,1,13.40,0,-10,13.71,0,-1,13.78,0,-1,13.82,0,-1,13.84,0,-1,13.93,0,-2,13.94,0,-2,13.98,0,-5,13.99,0,-2,14.00,0,-3,ARL,0
2025-07-17T15:32:29.573634202Z,2025-07-17T15:32:29.573469021Z,10,2,1108,C,B,10,13.540000000,100,285545885,165181,239975997,13.28,11,2,13.14,99,1,13.11,100,1,13.10,100,1,12.99,100,1,12.73,100,1,12.67,100,1,12.65,100,1,12.59,100,1,12.51,100,1,13.40,0,-10,13.71,0,-1,13.78,0,-1,13.82,0,-1,13.84,0,-1,13.93,0,-2,13.94,0,-2,13.98,0,-5,13.99,0,-2,14.00,0,-3,ARL,0
2025-07-17T15:32:29.574368326Z,2025-07-17T15:32:29.574202467Z,10,2,1108,C,B,10,12.490000000,100,285545945,165859,239976004,13.28,11,2,13.14,99,1,13.11,100,1,13.10,100,1,12.99,100,1,12.73,100,1,12.67,100,1,12.65,100,1,12.59,100,1,12.51,100,1,13.40,0,-10,13.71,0,-1,13.78,0,-1,13.82,0,-1,13.84,0,-1,13.93,0,-2,13.94,0,-2,13.98,0,-5,13.99,0,-2,14.00,0,-3,ARL,0
2025-07-17T15:32:29.574368326Z,2025-07-17T15:32:29.574202467Z,10,2,1108,A,B,10,12.270000000,100,285586089,165859,239976004,13.28,11,2,13.14,99,1,13.11,100,1,13.10,100,1,12.99,100,1,12.73,100,1,12.67,100,1,12.65,100,1,12.59,100,1,12.51,100,1,13.40,0,-10,13.71,0,-1,13.78,0,-1,13.82,0,-1,13.84,0,-1,13.93,0,-2,13.94,0,-2,13.98,0,-5,13.99,0,-2,14.00,0,-3,ARL,0
2025-07-17T15:32:29.574371866Z,2025-07-17T15:32:29.574206685Z,10,2,1108,C,B,10,12.940000000,100,285545953,165181,239976005,13.28,11,2,13.14,99,1,13.11,100,1,13.10,100,1,12.99,100,1,12.73,100,1,12.67,100,1,12.65,100,1,12.59,100,1,12.51,100,1,13.40,0,-10,13.71,0,-1,13.78,0,-1,13.82,0,-1,13.84,0,-1,13.93,0,-2,13.94,0,-2,13.98,0,-5,13.99,0,-2,14.00,0,-3,ARL,0
2025-07-17T15:32:29.574722141Z,2025-07-17T15:32:29.574556760Z,10,2,1108,A,B,10,12.710000000,100,285586093,165381,239976069,13.28,11,2,13.14,99,1,13.11,100,1,13.10,100,1,12.99,100,1,12.73,100,1,12.71,100,1,12.67,100,1,12.65,100,1,12.59,100,1,13.40,0,-10,13.71,0,-1,13.78,0,-1,13.82,0,-1,13.84,0,-1,13.93,0,-2,13.94,0,-2,13.98,0,-5,13.99,0,-2,14.00,0,-3,ARL,0
2025-07-17T15:32:29.575134655Z,2025-07-17T15:32:29.574968914Z,10,2,1108,C,B,10,12.590000000,100,285546893,165741,239976143,13.28,11,2,13.14,99,1,13.11,100,1,13.10,100,1,12.99,100,1,12.73,100,1,12.67,100,1,12.65,100,1,12.59,100,1,12.51,100,1,13.40,0,-10,13.71,0,-1,13.78,0,-1,13.82,0,-1,13.84,0,-1,13.93,0,-2,13.94,0,-2,13.98,0,-5,13.99,0,-2,14.00,0,-3,ARL,0
2025-07-17T15:32:29.575134655Z,2025-07-17T15:32:29.574968914Z,10,2,1108,A,B,10,12.340000000,100,285586113,165741,239976143,13.28,11,2,13.14,99,1,13.11,100,1,13.10,100,1,12.99,100,1,12.73,100,1,12.67,100,1,12.65,100,1,12.59,100,1,12.51,100,1,13.40,0,-10,13.71,0,-1,13.78,0,-1,13.82,0,-1,13.84,0,-1,13.93,0,-2,13.94,0,-2,13.98,0,-5,13.99,0,-2,14.00,0,-3,ARL,0
2025-07-17T15:32:29.575550333Z,2025-07-17T15:32:29.575384940Z,10,2,1108,C,B,10,11.500000000,100,285549537,165393,239976173,13.28,11,2,13.14,99,1,13.11,100,1,13.10,100,1,12.99,100,1,12.73,100,1,12.67,100,1,12.65,100,1,12.59,100,1,12.51,100,1,13.40,0,-10,13.71,0,-1,13.78,0,-1,13.82,0,-1,13.84,0,-1,13.93,0,-2,13.94,0,-2,13.98,0,-5,13.99,0,-2,14.00,0,-3,ARL,0
2025-07-17T15:32:29.575550333Z,2025-07-17T15:32:29.575384940Z,10,2,1108,A,B,10,11.270000000,100,285586145,165393,239976173,13.28,11,2,13.14,99,1,13.11,100,1,13.10,100,1,12.99,100,1,12.73,100,1,12.67,100,1,12.65,100,1,12.59,100,1,12.51,100,1,13.40,0,-10,13.71,0,-1,13.78,0,-1,13.82,0,-1,13.84,0,-1,13.93,0,-2,13.94,0,-2,13.98,0,-5,13.99,0,-2,14.00,0,-3,ARL,0
2025-07-17T15:32:29.575821091Z,2025-07-17T15:32:29.575655631Z,10,2,1108,C,B,10,9.880000000,100,285548137,165460,239976183,13.28,11,2,13.14,99,1,13.11,100,1,13.10,100,1,12.99,100,1,12.73,100,1,12.67,100,1,12.65,100,1,12.59,100,1,12.51,100,1,13.40,0,-10,13.71,0,-1,13.78,0,-1,13.82,0,-1,13.84,0,-1,13.93,0,-2,13.94,0,-2,13.98,0,-5,13.99,0,-2,14.00,0,-3,ARL,0
2025-07-17T15:32:29.575821091Z,2025-07-17T15:32:29.575655631Z,10,2,1108,A,B,10,9.680000000,100,285586157,165460,239976183,13.28,11,2,13.14,99,1,13.11,100,1,13.10,100,1,12.99,100,1,12.73,100,1,12.67,100,1,12.65,100,1,12.59,100,1,12.51,100,1,13.40,0,-10,13.71,0,-1,13.78,0,-1,13.82,0,-1,13.84,0,-1,13.93,0,-2,13.94,0,-2,13.98,0,-5,13.99,0,-2,14.00,0,-3,ARL,0
2025-07-17T15:32:29.578317238Z,2025-07-17T15:32:29.578151593Z,10,2,1108,C,B,10,12.590000000,100,285553901,165645,239976225,13.28,11,2,13.14,99,1,13.11,100,1,13.10,100,1,12.99,100,1,12.73,100,1,12.67,100,1,12.65,100,1,12.59,100,1,12.51,100,1,13.40,0,-10,13.71,0,-1,13.78,0,-1,13.82,0,-1,13.84,0,-1,13.93,0,-2,13.94,0,-2,13.98,0,-5,13.99,0,-2,14.00,0,-3,ARL,0
2025-07-17T15:32:29.578317238Z,2025-07-17T15:32:29.578151593Z,10,2,1108,A,B,10,12.340000000,100,285586189,165645,239976225,13.28,11,2,13.14,99,1,13.11,100,1,13.10,100,1,12.99,100,1,12.73,100,1,12.67,100,1,12.65,100,1,12.59,100,1,12.51,100,1,13.40,0,-10,13.71,0,-1,13.78,0,-1,13.82,0,-1,13.84,0,-1,13.93,0,-2,13.94,0,-2,13.98,0,-5,13.99,0,-2,14.00,0,-3,ARL,0
2025-07-17T15:32:29.580933155Z,2025-07-17T15:32:29.580767960Z,10,2,1108,A,B,10,13.260000000,100,285586221,165195,239976262,13.28,11,2,13.26,100,1,13.14,99,1,13.11,100,1,13.10,100,1,12.99,100,1,12.73,100,1,12.67,100,1,12.65,100,1,12.59,100,1,13.40,0,-10,13.71,0,-1,13.78,0,-1,13.82,0,-1,13.84,0,-1,13.93,0,-2,13.94,0,-2,13.98,0,-5,13.99,0,-2,14.00,0,-3,ARL,0
2025-07-17T15:32:29.580952045Z,2025-07-17T15:32:29.580786478Z,10,2,1108,C,A,10,14.010000000,100,283695933,165567,239976263,13.28,11,2,13.14,99,1,13.11,100,1,13.10,100,1,12.99,100,1,12.73,100,1,12.67,100,1,12.65,100,1,12.59,100,1,12.51,100,1,13.40,0,-10,13.71,0,-1,13.78,0,-1,13.82,0,-1,13.84,0,-1,13.93,0,-2,13.94,0,-2,13.98,0,-5,13.99,0,-2,14.00,0,-3,ARL,0
2025-07-17T15:32:29.580952045Z,2025-07-17T15:32:29.580786478Z,10,2,1108,A,A,10,13.990000000,100,285586225,165567,239976263,13.28,11,2,13.14,99,1,13.11,100,1,13.10,100,1,12.99,100,1,12.73,100,1,12.67,100,1,12.65,100,1,12.59,100,1,12.51,100,1,13.40,0,-10,13.71,0,-1,13.78,0,-1,13.82,0,-1,13.84,0,-1,13.93,0,-2,13.94,0,-2,13.98,0,-5,13.99,0,-2,14.00,0,-3,ARL,0
2025-07-17T15:32:29.587192852Z,2025-07-17T15:32:29.587027681Z,10,2,1108,C,B,10,13.270000000,100,285546673,165171,239976327,13.28,11,2,13.14,99,1,13.11,100,1,13.10,100,1,12.99,100,1,12.73,100,1,12.67,100,1,12.65,100,1,12.59,100,1,12.51,100,1,13.40,0,-10,13.71,0,-1,13.78,0,-1,13.82,0,-1,13.84,0,-1,13.93,0,-2,13.94,0,-2,13.98,0,-5,13.99,0,-3,14.00,0,-3,ARL,0
2025-07-17T15:32:29.587246470Z,2025-07-17T15:32:29.587081086Z,10,2,1108,A,B,10,13.030000000,100,285586293,165384,239976336,13.28,11,2,13.14,99,1,13.11,100,1,13.10,100,1,13.03,100,1,12.99,100,1,12.73,100,1,12.67,100,1,12.65,100,1,12.59,100,1,13.40,0,-10,13.71,0,-1,13.78,0,-1,13.82,0,-1,13.84,0,-1,13.93,0,-2,13.94,0,-2,13.98,0,-5,13.99,0,-3,14.00,0,-3,ARL,0
2025-07-17T15:32:29.659679280Z,2025-07-17T15:32:29.659513918Z,10,2,1108,C,B,10,12.730000000,100,285546061,165362,239977574,13.28,11,2,13.14,99,1,13.11,100,1,13.10,100,1,12.99,100,1,12.73,100,1,12.67,100,1,12.65,100,1,12.59,100,1,12.51,100,1,13.40,0,-10,13.71,0,-1,13.78,0,-1,13.82,0,-1,13.84,0,-1,13.93,0,-2,13.94,0,-2,13.98,0,-5,13.99,0,-3,14.00,0,-3,ARL,0
2025-07-17T15:32:29.659679280Z,2025-07-17T15:32:29.659513918Z,10,2,1108,A,B,10,12.460000000,100,285587281,165362,239977574,13.28,11,2,13.14,99,1,13.11,100,1,13.10,100,1,12.99,100,1,12.73,100,1,12.67,100,1,12.65,100,1,12.59,100,1,12.51,100,1,13.40,0,-10,13.71,0,-1,13.78,0,-1,13.82,0,-1,13.84,0,-1,13.93,0,-2,13.94,0,-2,13.98,0,-5,13.99,0,-3,14.00,0,-3,ARL,0
2025-07-17T15:33:04.248156868Z,2025-07-17T15:33:04.247990788Z,10,2,1108,C,A,10,14.970000000,100,283592993,166080,240885845,13.28,11,2,13.14,99,1,13.11,100,1,13.10,100,1,12.99,100,1,12.73,100,1,12.67,100,1,12.65,100,1,12.59,100,1,12.51,100,1,13.40,0,-10,13.71,0,-1,13.78,0,-1,13.82,0,-1,13.84,0,-1,13.93,0,-2,13.94,0,-2,13.98,0,-5,13.99,0,-3,14.00,0,-3,ARL,0
2025-07-17T15:33:04.248156868Z,2025-07-17T15:33:04.247990788Z,10,2,1108,A,A,10,14.720000000,100,286680573,166080,240885845,13.28,11,2,13.14,99,1,13.11,100,1,13.10,100,1,12.99,100,1,12.73,100,1,12.67,100,1,12.65,100,1,12.59,100,1,12.51,100,1,13.40,0,-10,13.71,0,-1,13.78,0,-1,13.82,0,-1,13.84,0,-1,13.93,0,-2,13.94,0,-2,13.98,0,-5,13.99,0,-3,14.00,0,-3,ARL,0
2025-07-17T15:33:04.248189408Z,2025-07-17T15:33:04.248023883Z,10,2,1108,C,A,10,14.970000000,100,283593041,165525,240885847,13.28,11,2,13.14,99,1,13.11,100,1,13.10,100,1,12.99,100,1,12.73,100,1,12.67,100,1,12.65,100,1,12.59,100,1,12.51,100,1,13.40,0,-10,13.71,0,-1,13.78,0,-1,13.82,0,-1,13.84,0,-1,13.93,0,-2,13.94,0,-2,13.98,0,-5,13.99,0,-3,14.00,0,-3,ARL,0
2025-07-17T15:33:04.248189408Z,2025-07-17T15:33:04.248023883Z,10,2,1108,A,A,10,14.720000000,100,286680577,165525,240885847,13.28,11,2,13.14,99,1,13.11,100,1,13.10,100,1,12.99,100,1,12.73,100,1,12.67,100,1,12.65,100,1,12.59,100,1,12.51,100,1,13.40,0,-10,13.71,0,-1,13.78,0,-1,13.82,0,-1,13.84,0,-1,13.93,0,-2,13.94,0,-2,13.98,0,-5,13.99,0,-3,14.00,0,-3,ARL,0
2025-07-17T15:33:04.255712050Z,2025-07-17T15:33:04.255546094Z,10,2,1108,A,A,10,13.840000000,100,286680685,165956,240886132,13.28,11,2,13.14,99,1,13.11,100,1,13.10,100,1,12.99,100,1,12.73,100,1,12.67,100,1,12.65,100,1,12.59,100,1,12.51,100,1,13.40,0,-10,13.71,0,-1,13.78,0,-1,13.82,0,-1,13.84,0,-1,13.93,0,-2,13.94,0,-2,13.98,0,-5,13.99,0,-3,14.00,0,-3,ARL,0
2025-07-17T15:33:04.255777981Z,2025-07-17T15:33:04.255612126Z,10,2,1108,C,B,10,12.270000000,100,285586089,165855,240886133,13.28,11,2,13.14,99,1,13.11,100,1,13.10,100,1,12.99,100,1,12.73,100,1,12.67,100,1,12.65,100,1,12.59,100,1,12.51,100,1,13.40,0,-10,13.71,0,-1,13.78,0,-1,13.82,0,-1,13.84,0,-2,13.93,0,-2,13.94,0,-2,13.98,0,-5,13.99,0,-3,14.00,0,-3,ARL,0
2025-07-17T15:33:04.255777981Z,2025-07-17T15:33:04.255612126Z,10,2,1108,A,B,10,12.230000000,100,286680693,165855,240886133,13.28,11,2,13.14,99,1,13.11,100,1,13.10,100,1,12.99,100,1,12.73,100,1,12.67,100,1,12.65,100,1,12.59,100,1,12.51,100,1,13.40,0,-10,13.71,0,-1,13.78,0,-1,13.82,0,-1,13.84,0,-2,13.93,0,-2,13.94,0,-2,13.98,0,-5,13.99,0,-3,14.00,0,-3,ARL,0
2025-07-17T15:33:04.256438228Z,2025-07-17T15:33:04.256272676Z,10,2,1108,C,A,10,15.060000000,100,283596673,165552,240886147,13.28,11,2,13.14,99,1,13.11,100,1,13.10,100,1,12.99,100,1,12.73,100,1,12.67,100,1,12.65,100,1,12.59,100,1,12.51,100,1,13.40,0,-10,13.71,0,-1,13.78,0,-1,13.82,0,-1,13.84,0,-2,13.93,0,-2,13.94,0,-2,13.98,0,-5,13.99,0,-3,14.00,0,-3,ARL,0
2025-07-17T15:33:04.256438228Z,2025-07-17T15:33:04.256272676Z,10,2,1108,A,A,10,14.910000000,100,286680721,165552,240886147,13.28,11,2,13.14,99,1,13.11,100,1,13.10,100,1,12.99,100,1,12.73,100,1,12.67,100,1,12.65,100,1,12.59,100,1,12.51,100,1,13.40,0,-10,13.71,0,-1,13.78,0,-1,13.82,0,-1,13.84,0,-2,13.93,0,-2,13.94,0,-2,13.98,0,-5,13.99,0,-3,14.00,0,-3,ARL,0
2025-07-17T15:33:04.258080504Z,2025-07-17T15:33:04.257914956Z,10,2,1108,C,A,10,14.960000000,100,283596945,165548,240886188,13.28,11,2,13.14,99,1,13.11,100,1,13.10,100,1,12.99,100,1,12.73,100,1,12.67,100,1,12.65,100,1,12.59,100,1,12.51,100,1,13.40,0,-10,13.71,0,-1,13.78,0,-1,13.82,0,-1,13.84,0,-2,13.93,0,-2,13.94,0,-2,13.98,0,-5,13.99,0,-3,14.00,0,-3,ARL,0
2025-07-17T15:33:04.258080504Z,2025-07-17T15:33:04.257914956Z,10,2,1108,A,A,10,14.810000000,100,286680741,165548,240886188,13.28,11,2,13.14,99,1,13.11,100,1,13.10,100,1,12.99,100,1,12.73,100,1,12.67,100,1,12.65,100,1,12.59,100,1,12.51,100,1,13.40,0,-10,13.71,0,-1,13.78,0,-1,13.82,0,-1,13.84,0,-2,13.93,0,-2,13.94,0,-2,13.98,0,-5,13.99,0,-3,14.00,0,-3,ARL,0
2025-07-17T15:33:04.261684319Z,2025-07-17T15:33:04.261518776Z,10,2,1108,C,A,10,14.790000000,100,283593313,165543,240886271,13.28,11,2,13.14,99,1,13.11,100,1,13.10,100,1,12.99,100,1,12.73,100,1,12.67,100,1,12.65,100,1,12.59,100,1,12.51,100,1,13.40,0,-10,13.71,0,-1,13.78,0,-1,13.82,0,-1,13.84,0,-2,13.93,0,-2,13.94,0,-2,13.98,0,-5,13.99,0,-3,14.00,0,-3,ARL,0
2025-07-17T15:33:04.261684319Z,2025-07-17T15:33:04.261518776Z,10,2,1108,A,A,10,14.650000000,100,286680905,165543,240886271,13.28,11,2,13.14,99,1,13.11,100,1,13.10,100,1,12.99,100,1,12.73,100,1,12.67,100,1,12.65,100,1,12.59,100,1,12.51,100,1,13.40,0,-10,13.71,0,-1,13.78,0,-1,13.82,0,-1,13.84,0,-2,13.93,0,-2,13.94,0,-2,13.98,0,-5,13.99,0,-3,14.00,0,-3,ARL,0
2025-07-17T15:33:04.263011314Z,2025-07-17T15:33:04.262845834Z,10,2,1108,C,A,10,14.260000000,100,283595181,165480,240886294,13.28,11,2,13.14,99,1,13.11,100,1,13.10,100,1,12.99,100,1,12.73,100,1,12.67,100,1,12.65,100,1,12.59,100,1,12.51,100,1,13.40,0,-10,13.71,0,-1,13.78,0,-1,13.82,0,-1,13.84,0,-2,13.93,0,-2,13.94,0,-2,13.98,0,-5,13.99,0,-3,14.00,0,-3,ARL,0
2025-07-17T15:33:04.263052660Z,2025-07-17T15:33:04.262887184Z,10,2,1108,C,A,10,13.980000000,100,285556869,165476,240886296,13.28,11,2,13.14,99,1,13.11,100,1,13.10,100,1,12.99,100,1,12.73,100,1,12.67,100,1,12.65,100,1,12.59,100,1,12.51,100,1,13.40,0,-10,13.71,0,-1,13.78,0,-1,13.82,0,-1,13.84,0,-2,13.93,0,-2,13.94,0,-2,13.98,0,-5,13.99,0,-3,14.00,0,-3,ARL,0
2025-07-17T15:33:04.263065252Z,2025-07-17T15:33:04.262899981Z,10,2,1108,A,A,10,14.120000000,100,286680917,165271,240886297,13.28,11,2,13.14,99,1,13.11,100,1,13.10,100,1,12.99,100,1,12.73,100,1,12.67,100,1,12.65,100,1,12.59,100,1,12.51,100,1,13.40,0,-10,13.71,0,-1,13.78,0,-1,13.82,0,-1,13.84,0,-2,13.93,0,-2,13.94,0,-2,13.98,0,-5,13.99,0,-3,14.00,0,-3,ARL,0
2025-07-17T15:33:04.271212113Z,2025-07-17T15:33:04.271046430Z,10,2,1108,C,A,10,17.760000000,100,283594173,165683,240886583,13.28,11,2,13.14,99,1,13.11,100,1,13.10,100,1,12.99,100,1,12.73,100,1,12.67,100,1,12.65,100,1,12.59,100,1,12.51,100,1,13.40,0,-10,13.71,0,-1,13.78,0,-1,13.82,0,-1,13.84,0,-2,13.93,0,-2,13.94,0,-2,13.98,0,-5,13.99,0,-3,14.00,0,-3,ARL,0
2025-07-17T15:33:04.271212113Z,2025-07-17T15:33:04.271046430Z,10,2,1108,A,A,10,17.580000000,100,286681057,165683,240886583,13.28,11,2,13.14,99,1,13.11,100,1,13.10,100,1,12.99,100,1,12.73,100,1,12.67,100,1,12.65,100,1,12.59,100,1,12.51,100,1,13.40,0,-10,13.71,0,-1,13.78,0,-1,13.82,0,-1,13.84,0,-2,13.93,0,-2,13.94,0,-2,13.98,0,-5,13.99,0,-3,14.00,0,-3,ARL,0
2025-07-17T15:33:04.277880725Z,2025-07-17T15:33:04.277715123Z,10,2,1108,C,A,10,16.080000000,100,283599609,165602,240886720,13.28,11,2,13.14,99,1,13.11,100,1,13.10,100,1,12.99,100,1,12.73,100,1,12.67,100,1,12.65,100,1,12.59,100,1,12.51,100,1,13.40,0,-10,13.71,0,-1,13.78,0,-1,13.82,0,-1,13.84,0,-2,13.93,0,-2,13.94,0,-2,13.98,0,-5,13.99,0,-3,14.00,0,-3,ARL,0
2025-07-17T15:33:04.277880725Z,2025-07-17T15:33:04.277715123Z,10,2,1108,A,A,10,15.920000000,100,286681229,165602,240886720,13.28,11,2,13.14,99,1,13.11,100,1,13.10,100,1,12.99,100,1,12.73,100,1,12.67,100,1,12.65,100,1,12.59,100,1,12.51,100,1,13.40,0,-10,13.71,0,-1,13.78,0,-1,13.82,0,-1,13.84,0,-2,13.93,0,-2,13.94,0,-2,13.98,0,-5,13.99,0,-3,14.00,0,-3,ARL,0
2025-07-17T15:33:04.418840148Z,2025-07-17T15:33:04.418674487Z,10,2,1108,C,A,10,14.960000000,100,283596721,165661,240888774,13.28,11,2,13.14,99,1,13.11,100,1,13.10,100,1,12.99,100,1,12.73,100,1,12.67,100,1,12.65,100,1,12.59,100,1,12.51,100,1,13.40,0,-10,13.71,0,-1,13.78,0,-1,13.82,0,-1,13.84,0,-2,13.93,0,-2,13.94,0,-2,13.98,0,-5,13.99,0,-3,14.00,0,-3,ARL,0
2025-07-17T15:33:04.418840148Z,2025-07-17T15:33:04.418674487Z,10,2,1108,A,A,10,14.810000000,100,286684005,165661,240888774,13.28,11,2,13.14,99,1,13.11,100,1,13.10,100,1,12.99,100,1,12.73,100,1,12.67,100,1,12.65,100,1,12.59,100,1,12.51,100,1,13.40,0,-10,13.71,0,-1,13.78,0,-1,13.82,0,-1,13.84,0,-2,13.93,0,-2,13.94,0,-2,13.98,0,-5,13.99,0,-3,14.00,0,-3,ARL,0
2025-07-17T15:33:05.330854217Z,2025-07-17T15:33:05.330688486Z,10,2,1108,C,A,10,13.990000000,100,285586225,165731,240911093,13.28,11,2,13.14,99,1,13.11,100,1,13.10,100,1,12.99,100,1,12.73,100,1,12.67,100,1,12.65,100,1,12.59,100,1,12.51,100,1,13.40,0,-10,13.71,0,-1,13.78,0,-1,13.82,0,-1,13.84,0,-2,13.93,0,-2,13.94,0,-2,13.98,0,-5,13.99,0,-3,14.00,0,-3,ARL,0
2025-07-17T15:33:05.330854217Z,2025-07-17T15:33:05.330688486Z,10,2,1108,A,A,10,13.850000000,100,286704785,165731,240911093,13.28,11,2,13.14,99,1,13.11,100,1,13.10,100,1,12.99,100,1,12.73,100,1,12.67,100,1,12.65,100,1,12.59,100,1,12.51,100,1,13.40,0,-10,13.71,0,-1,13.78,0,-1,13.82,0,-1,13.84,0,-2,13.93,0,-2,13.94,0,-2,13.98,0,-5,13.99,0,-3,14.00,0,-3,ARL,0
2025-07-17T15:33:06.455979270Z,2025-07-17T15:33:06.455814002Z,10,2,1108,C,A,10,13.840000000,100,286680685,165268,240936407,13.28,11,2,13.14,99,1,13.11,100,1,13.10,100,1,12.99,100,1,12.73,100,1,12.67,100,1,12.65,100,1,12.59,100,1,12.51,100,1,13.40,0,-10,13.71,0,-1,13.78,0,-1,13.82,0,-1,13.84,0,-2,13.85,0,-1,13.93,0,-2,13.94,0,-2,13.98,0,-5,13.99,0,-3,ARL,0
2025-07-17T15:33:10.468005342Z,2025-07-17T15:33:10.467840054Z,10,2,1108,A,A,10,13.870000000,100,286828253,165288,241000095,13.28,11,2,13.14,99,1,13.11,100,1,13.10,100,1,12.99,100,1,12.73,100,1,12.67,100,1,12.65,100,1,12.59,100,1,12.51,100,1,13.40,0,-10,13.71,0,-1,13.78,0,-1,13.82,0,-1,13.84,0,-2,13.85,0,-1,13.93,0,-2,13.94,0,-2,13.98,0,-5,13.99,0,-3,ARL,0
2025-07-17T15:33:40.986585803Z,2025-07-17T15:33:40.986420127Z,10,2,1108,C,A,10,14.020000000,2,283348193,165676,241593788,13.28,11,2,13.14,99,1,13.11,100,1,13.10,100,1,12.99,100,1,12.73,100,1,12.67,100,1,12.65,100,1,12.59,100,1,12.51,100,1,13.40,0,-10,13.71,0,-1,13.78,0,-1,13.82,0,-1,13.84,0,-2,13.85,0,-1,13.93,0,-2,13.94,0,-2,13.98,0,-5,13.99,0,-3,ARL,0
2025-07-17T15:33:40.986585803Z,2025-07-17T15:33:40.986420127Z,10,2,1108,A,A,10,13.950000000,2,287540393,165676,241593788,13.28,11,2,13.14,99,1,13.11,100,1,13.10,100,1,12.99,100,1,12.73,100,1,12.67,100,1,12.65,100,1,12.59,100,1,12.51,100,1,13.40,0,-10,13.71,0,-1,13.78,0,-1,13.82,0,-1,13.84,0,-2,13.85,0,-1,13.93,0,-2,13.94,0,-2,13.98,0,-5,13.99,0,-3,ARL,0
2025-07-17T15:33:41.766184571Z,2025-07-17T15:33:41.766018916Z,10,2,1108,A,A,10,13.820000000,10,287560109,165655,241612289,13.28,11,2,13.14,99,1,13.11,100,1,13.10,100,1,12.99,100,1,12.73,100,1,12.67,100,1,12.65,100,1,12.59,100,1,12.51,100,1,13.40,0,-10,13.71,0,-1,13.78,0,-1,13.82,0,-1,13.84,0,-2,13.85,0,-1,13.93,0,-2,13.94,0,-2,13.98,0,-5,13.99,0,-3,ARL,0
2025-07-17T15:33:41.766265703Z,2025-07-17T15:33:41.766100204Z,10,2,1108,C,A,10,13.850000000,100,286704785,165499,241612294,13.28,11,2,13.14,99,1,13.11,100,1,13.10,100,1,12.99,100,1,12.73,100,1,12.67,100,1,12.65,100,1,12.59,100,1,12.51,100,1,13.40,0,-10,13.71,0,-1,13.78,0,-1,13.82,0,-2,13.84,0,-2,13.85,0,-1,13.93,0,-2,13.94,0,-2,13.98,0,-5,13.99,0,-3,ARL,0
2025-07-17T15:33:41.766265703Z,2025-07-17T15:33:41.766100204Z,10,2,1108,A,A,10,13.830000000,100,287560121,165499,241612294,13.28,11,2,13.14,99,1,13.11,100,1,13.10,100,1,12.99,100,1,12.73,100,1,12.67,100,1,12.65,100,1,12.59,100,1,12.51,100,1,13.40,0,-10,13.71,0,-1,13.78,0,-1,13.82,0,-2,13.84,0,-2,13.85,0,-1,13.93,0,-2,13.94,0,-2,13.98,0,-5,13.99,0,-3,ARL,0
2025-07-17T15:33:41.777404666Z,2025-07-17T15:33:41.777239400Z,10,2,1108,A,A,10,13.850000000,100,287560333,165266,241612426,13.28,11,2,13.14,99,1,13.11,100,1,13.10,100,1,12.99,100,1,12.73,100,1,12.67,100,1,12.65,100,1,12.59,100,1,12.51,100,1,13.40,0,-10,13.71,0,-1,13.78,0,-1,13.82,0,-2,13.84,0,-2,13.85,0,-1,13.93,0,-2,13.94,0,-2,13.98,0,-5,13.99,0,-3,ARL,0
2025-07-17T15:33:41.784121031Z,2025-07-17T15:33:41.783955668Z,10,2,1108,C,A,10,13.870000000,100,286828253,165363,241612450,13.28,11,2,13.14,99,1,13.11,100,1,13.10,100,1,12.99,100,1,12.73,100,1,12.67,100,1,12.65,100,1,12.59,100,1,12.51,100,1,13.40,0,-10,13.71,0,-1,13.78,0,-1,13.82,0,-2,13.84,0,-2,13.85,0,-2,13.93,0,-2,13.94,0,-2,13.98,0,-5,13.99,0,-3,ARL,0
2025-07-17T15:33:42.773141775Z,2025-07-17T15:33:42.772976862Z,10,2,1108,C,A,10,13.820000000,10,287560109,164913,241630390,13.28,11,2,13.14,99,1,13.11,100,1,13.10,100,1,12.99,100,1,12.73,100,1,12.67,100,1,12.65,100,1,12.59,100,1,12.51,100,1,13.40,0,-10,13.71,0,-1,13.78,0,-1,13.82,0,-2,13.84,0,-2,13.85,0,-2,13.93,0,-2,13.94,0,-2,13.98,0,-5,13.99,0,-3,ARL,0
2025-07-17T15:34:28.155773560Z,2025-07-17T15:34:28.155608087Z,10,2,1108,A,A,10,14.200000000,50,288723725,165473,242513312,13.28,11,2,13.14,99,1,13.11,100,1,13.10,100,1,12.99,100,1,12.73,100,1,12.67,100,1,12.65,100,1,12.59,100,1,12.51,100,1,13.40,0,-10,13.71,0,-1,13.78,0,-1,13.82,0,-2,13.84,0,-2,13.85,0,-2,13.93,0,-2,13.94,0,-2,13.98,0,-5,13.99,0,-3,ARL,0
2025-07-17T15:34:28.156815057Z,2025-07-17T15:34:28.156649544Z,10,2,1108,C,B,10,12.650000000,100,236206261,165513,242513329,13.28,11,2,13.14,99,1,13.11,100,1,13.10,100,1,12.99,100,1,12.73,100,1,12.67,100,1,12.65,100,1,12.59,100,1,12.51,100,1,13.40,0,-10,13.71,0,-1,13.78,0,-1,13.82,0,-2,13.84,0,-2,13.85,0,-2,13.93,0,-2,13.94,0,-2,13.98,0,-5,13.99,0,-3,ARL,0
2025-07-17T15:34:28.156815057Z,2025-07-17T15:34:28.156649544Z,10,2,1108,A,B,10,12.360000000,100,288723813,165513,242513329,13.28,11,2,13.14,99,1,13.11,100,1,13.10,100,1,12.99,100,1,12.73,100,1,12.67,100,1,12.65,100,1,12.59,100,1,12.51,100,1,13.40,0,-10,13.71,0,-1,13.78,0,-1,13.82,0,-2,13.84,0,-2,13.85,0,-2,13.93,0,-2,13.94,0,-2,13.98,0,-5,13.99,0,-3,ARL,0
2025-07-17T15:34:28.156884900Z,2025-07-17T15:34:28.156719339Z,10,2,1108,C,B,10,12.650000000,100,236179089,165561,242513330,13.28,11,2,13.14,99,1,13.11,100,1,13.10,100,1,12.99,100,1,12.73,100,1,12.67,100,1,12.65,100,1,12.59,100,1,12.51,100,1,13.40,0,-10,13.71,0,-1,13.78,0,-1,13.82,0,-2,13.84,0,-2,13.85,0,-2,13.93,0,-2,13.94,0,-2,13.98,0,-5,13.99,0,-3,ARL,0
2025-07-17T15:34:28.156884900Z,2025-07-17T15:34:28.156719339Z,10,2,1108,A,B,10,12.360000000,100,288723817,165561,242513330,13.28,11,2,13.14,99,1,13.11,100,1,13.10,100,1,12.99,100,1,12.73,100,1,12.67,100,1,12.65,100,1,12.59,100,1,12.51,100,1,13.40,0,-10,13.71,0,-1,13.78,0,-1,13.82,0,-2,13.84,0,-2,13.85,0,-2,13.93,0,-2,13.94,0,-2,13.98,0,-5,13.99,0,-3,ARL,0
2025-07-17T15:34:28.170740864Z,2025-07-17T15:34:28.170575785Z,10,2,1108,A,A,10,13.810000000,50,288724173,165079,242513651,13.28,11,2,13.14,99,1,13.11,100,1,13.10,100,1,12.99,100,1,12.73,100,1,12.67,100,1,12.65,100,1,12.59,100,1,12.51,100,1,13.40,0,-10,13.71,0,-1,13.78,0,-1,13.82,0,-2,13.84,0,-2,13.85,0,-2,13.93,0,-2,13.94,0,-2,13.98,0,-5,13.99,0,-3,ARL,0
2025-07-17T15:34:28.170792211Z,2025-07-17T15:34:28.170626756Z,10,2,1108,C,B,10,13.260000000,100,285586221,165455,242513653,13.28,11,2,13.14,99,1,13.11,100,1,13.10,100,1,12.99,100,1,12.73,100,1,12.67,100,1,12.65,100,1,12.59,100,1,12.51,100,1,13.40,0,-10,13.71,0,-1,13.78,0,-1,13.81,0,-1,13.82,0,-2,13.84,0,-2,13.85,0,-2,13.93,0,-2,13.94,0,-2,13.98,0,-5,ARL,0
2025-07-17T15:34:28.171437442Z,2025-07-17T15:34:28.171272157Z,10,2,1108,A,A,10,13.780000000,2,288724201,165285,242513665,13.28,11,2,13.14,99,1,13.11,100,1,13.10,100,1,12.99,100,1,12.73,100,1,12.67,100,1,12.65,100,1,12.59,100,1,12.51,100,1,13.40,0,-10,13.71,0,-1,13.78,0,-1,13.81,0,-1,13.82,0,-2,13.84,0,-2,13.85,0,-2,13.93,0,-2,13.94,0,-2,13.98,0,-5,ARL,0
2025-07-17T15:34:28.172057926Z,2025-07-17T15:34:28.171892519Z,10,2,1108,A,B,10,13.310000000,10,288724225,165407,242513691,13.31,10,1,13.28,11,2,13.14,99,1,13.11,100,1,13.10,100,1,12.99,100,1,12.73,100,1,12.67,100,1,12.65,100,1,12.59,100,1,13.40,0,-10,13.71,0,-1,13.78,0,-1,13.81,0,-1,13.82,0,-2,13.84,0,-2,13.85,0,-2,13.93,0,-2,13.94,0,-2,13.98,0,-5,ARL,0
2025-07-17T15:34:28.172058708Z,2025-07-17T15:34:28.171893498Z,10,2,1108,A,A,10,13.820000000,10,288724229,165210,242513692,13.31,10,1,13.28,11,2,13.14,99,1,13.11,100,1,13.10,100,1,12.99,100,1,12.73,100,1,12.67,100,1,12.65,100,1,12.59,100,1,13.40,0,-10,13.71,0,-1,13.78,0,-1,13.81,0,-1,13.82,0,-2,13.84,0,-2,13.85,0,-2,13.93,0,-2,13.94,0,-2,13.98,0,-5,ARL,0
2025-07-17T15:34:28.175011712Z,2025-07-17T15:34:28.174846475Z,10,2,1108,A,B,10,13.300000000,100,288724429,165237,242513742,13.31,10,1,13.30,100,1,13.28,11,2,13.14,99,1,13.11,100,1,13.10,100,1,12.99,100,1,12.73,100,1,12.67,100,1,12.65,100,1,13.40,0,-10,13.71,0,-1,13.78,0,-1,13.81,0,-1,13.82,0,-2,13.84,0,-2,13.85,0,-2,13.93,0,-2,13.94,0,-2,13.98,0,-5,ARL,0
2025-07-17T15:34:28.175030125Z,2025-07-17T15:34:28.174864618Z,10,2,1108,C,A,10,13.830000000,100,287560121,165507,242513743,13.31,10,1,13.28,11,2,13.14,99,1,13.11,100,1,13.10,100,1,12.99,100,1,12.73,100,1,12.67,100,1,12.65,100,1,12.59,100,1,13.40,0,-10,13.71,0,-1,13.78,0,-1,13.81,0,-1,13.82,0,-2,13.84,0,-2,13.85,0,-2,13.93,0,-2,13.94,0,-2,13.98,0,-5,ARL,0
2025-07-17T15:34:28.175030125Z,2025-07-17T15:34:28.174864618Z,10,2,1108,A,A,10,13.790000000,100,288724433,165507,242513743,13.31,10,1,13.28,11,2,13.14,99,1,13.11,100,1,13.10,100,1,12.99,100,1,12.73,100,1,12.67,100,1,12.65,100,1,12.59,100,1,13.40,0,-10,13.71,0,-1,13.78,0,-1,13.81,0,-1,13.82,0,-2,13.84,0,-2,13.85,0,-2,13.93,0,-2,13.94,0,-2,13.98,0,-5,ARL,0
2025-07-17T15:34:28.175329569Z,2025-07-17T15:34:28.175164464Z,10,2,1108,C,A,10,13.780000000,2,288724201,165105,242513747,13.31,10,1,13.28,11,2,13.14,99,1,13.11,100,1,13.10,100,1,12.99,100,1,12.73,100,1,12.67,100,1,12.65,100,1,12.59,100,1,13.40,0,-10,13.71,0,-1,13.78,0,-1,13.81,0,-1,13.82,0,-2,13.84,0,-2,13.85,0,-2,13.93,0,-2,13.94,0,-2,13.98,0,-5,ARL,0
2025-07-17T15:34:28.175752130Z,2025-07-17T15:34:28.175586497Z,10,2,1108,C,B,10,12.230000000,100,286680693,165633,242513748,13.31,10,1,13.28,11,2,13.14,99,1,13.11,100,1,13.10,100,1,12.99,100,1,12.73,100,1,12.67,100,1,12.65,100,1,12.59,100,1,13.40,0,-10,13.71,0,-1,13.78,0,-1,13.79,0,-1,13.81,0,-1,13.82,0,-2,13.84,0,-2,13.85,0,-2,13.93,0,-2,13.94,0,-2,ARL,0
2025-07-17T15:34:28.175752130Z,2025-07-17T15:34:28.175586497Z,10,2,1108,A,B,10,12.270000000,100,288724485,165633,242513748,13.31,10,1,13.28,11,2,13.14,99,1,13.11,100,1,13.10,100,1,12.99,100,1,12.73,100,1,12.67,100,1,12.65,100,1,12.59,100,1,13.40,0,-10,13.71,0,-1,13.78,0,-1,13.79,0,-1,13.81,0,-1,13.82,0,-2,13.84,0,-2,13.85,0,-2,13.93,0,-2,13.94,0,-2,ARL,0
2025-07-17T15:34:28.175767666Z,2025-07-17T15:34:28.175602100Z,10,2,1108,C,A,10,14.910000000,100,286680721,165566,242513749,13.31,10,1,13.28,11,2,13.14,99,1,13.11,100,1,13.10,100,1,12.99,100,1,12.73,100,1,12.67,100,1,12.65,100,1,12.59,100,1,13.40,0,-10,13.71,0,-1,13.78,0,-1,13.79,0,-1,13.81,0,-1,13.82,0,-2,13.84,0,-2,13.85,0,-2,13.93,0,-2,13.94,0,-2,ARL,0
2025-07-17T15:34:28.175767666Z,2025-07-17T15:34:28.175602100Z,10,2,1108,A,A,10,14.860000000,100,288724489,165566,242513749,13.31,10,1,13.28,11,2,13.14,99,1,13.11,100,1,13.10,100,1,12.99,100,1,12.73,100,1,12.67,100,1,12.65,100,1,12.59,100,1,13.40,0,-10,13.71,0,-1,13.78,0,-1,13.79,0,-1,13.81,0,-1,13.82,0,-2,13.84,0,-2,13.85,0,-2,13.93,0,-2,13.94,0,-2,ARL,0
2025-07-17T15:34:28.180356536Z,2025-07-17T15:34:28.180191067Z,10,2,1108,A,A,10,13.800000000,100,288724565,165469,242513781,13.31,10,1,13.28,11,2,13.14,99,1,13.11,100,1,13.10,100,1,12.99,100,1,12.73,100,1,12.67,100,1,12.65,100,1,12.59,100,1,13.40,0,-10,13.71,0,-1,13.78,0,-1,13.79,0,-1,13.81,0,-1,13.82,0,-2,13.84,0,-2,13.85,0,-2,13.93,0,-2,13.94,0,-2,ARL,0
2025-07-17T15:34:28.187237384Z,2025-07-17T15:34:28.187072050Z,10,2,1108,C,A,10,13.850000000,100,287560333,165334,242513907,13.31,10,1,13.28,11,2,13.14,99,1,13.11,100,1,13.10,100,1,12.99,100,1,12.73,100,1,12.67,100,1,12.65,100,1,12.59,100,1,13.40,0,-10,13.71,0,-1,13.78,0,-1,13.79,0,-1,13.80,0,-1,13.81,0,-1,13.82,0,-2,13.84,0,-2,13.85,0,-2,13.93,0,-2,ARL,0
2025-07-17T15:34:28.192269421Z,2025-07-17T15:34:28.192104387Z,10,2,1108,C,A,10,13.790000000,100,288724433,165034,242513974,13.31,10,1,13.28,11,2,13.14,99,1,13.11,100,1,13.10,100,1,12.99,100,1,12.73,100,1,12.67,100,1,12.65,100,1,12.59,100,1,13.40,0,-10,13.71,0,-1,13.78,0,-1,13.79,0,-1,13.80,0,-1,13.81,0,-1,13.82,0,-2,13.84,0,-2,13.85,0,-2,13.93,0,-2,ARL,0
2025-07-17T15:34:28.231601320Z,2025-07-17T15:34:28.231436134Z,10,2,1108,A,A,10,13.830000000,100,288725173,165186,242514372,13.31,10,1,13.28,11,2,13.14,99,1,13.11,100,1,13.10,100,1,12.99,100,1,12.73,100,1,12.67,100,1,12.65,100,1,12.59,100,1,13.40,0,-10,13.71,0,-1,13.78,0,-1,13.79,0,-1,13.80,0,-1,13.81,0,-1,13.82,0,-2,13.84,0,-2,13.85,0,-2,13.93,0,-2,ARL,0
2025-07-17T15:34:28.256123809Z,2025-07-17T15:34:28.255958718Z,10,2,1108,C,A,10,14.200000000,50,288723725,165091,242514761,13.31,10,1,13.28,11,2,13.14,99,1,13.11,100,1,13.10,100,1,12.99,100,1,12.73,100,1,12.67,100,1,12.65,100,1,12.59,100,1,13.40,0,-10,13.71,0,-1,13.78,0,-1,13.79,0,-1,13.80,0,-1,13.81,0,-1,13.82,0,-2,13.84,0,-2,13.85,0,-2,13.93,0,-2,ARL,0
2025-07-17T15:34:28.271275449Z,2025-07-17T15:34:28.271110273Z,10,2,1108,C,A,10,13.810000000,50,288724173,165176,242515164,13.31,10,1,13.28,11,2,13.14,99,1,13.11,100,1,13.10,100,1,12.99,100,1,12.73,100,1,12.67,100,1,12.65,100,1,12.59,100,1,13.40,0,-10,13.71,0,-1,13.78,0,-1,13.79,0,-1,13.80,0,-1,13.81,0,-1,13.82,0,-2,13.83,0,-1,13.84,0,-2,13.85,0,-2,ARL,0
2025-07-17T15:34:28.281217370Z,2025-07-17T15:34:28.281052249Z,10,2,1108,C,A,10,13.800000000,100,288724565,165121,242515254,13.31,10,1,13.28,11,2,13.14,99,1,13.11,100,1,13.10,100,1,12.99,100,1,12.73,100,1,12.67,100,1,12.65,100,1,12.59,100,1,13.40,0,-10,13.71,0,-1,13.78,0,-1,13.79,0,-1,13.80,0,-1,13.81,0,-1,13.82,0,-2,13.83,0,-1,13.84,0,-2,13.85,0,-2,ARL,0
2025-07-17T15:34:28.281945481Z,2025-07-17T15:34:28.281780230Z,10,2,1108,C,A,10,14.860000000,100,288724489,165251,242515263,13.31,10,1,13.28,11,2,13.14,99,1,13.11,100,1,13.10,100,1,12.99,100,1,12.73,100,1,12.67,100,1,12.65,100,1,12.59,100,1,13.40,0,-10,13.71,0,-1,13.78,0,-1,13.79,0,-1,13.80,0,-1,13.81,0,-1,13.82,0,-2,13.83,0,-1,13.84,0,-2,13.85,0,-2,ARL,0
2025-07-17T15:34:28.281945481Z,2025-07-17T15:34:28.281780230Z,10,2,1108,A,A,10,14.900000000,100,288726085,165251,242515263,13.31,10,1,13.28,11,2,13.14,99,1,13.11,100,1,13.10,100,1,12.99,100,1,12.73,100,1,12.67,100,1,12.65,100,1,12.59,100,1,13.40,0,-10,13.71,0,-1,13.78,0,-1,13.79,0,-1,13.80,0,-1,13.81,0,-1,13.82,0,-2,13.83,0,-1,13.84,0,-2,13.85,0,-2,ARL,0
2025-07-17T15:34:32.289409612Z,2025-07-17T15:34:32.289244370Z,10,2,1108,A,A,10,13.840000000,100,288845417,165242,242598225,13.31,10,1,13.28,11,2,13.14,99,1,13.11,100,1,13.10,100,1,12.99,100,1,12.73,100,1,12.67,100,1,12.65,100,1,12.59,100,1,13.40,0,-10,13.71,0,-1,13.78,0,-1,13.79,0,-1,13.80,0,-1,13.81,0,-1,13.82,0,-2,13.83,0,-1,13.84,0,-2,13.85,0,-2,ARL,0
2025-07-17T15:34:39.864692027Z,2025-07-17T15:34:39.864526516Z,10,2,1108,A,A,10,13.800000000,15,289055901,165511,242774235,13.31,10,1,13.28,11,2,13.14,99,1,13.11,100,1,13.10,100,1,12.99,100,1,12.73,100,1,12.67,100,1,12.65,100,1,12.59,100,1,13.40,0,-10,13.71,0,-1,13.78,0,-1,13.79,0,-1,13.80,0,-1,13.81,0,-1,13.82,0,-2,13.83,0,-1,13.84,0,-2,13.85,0,-2,ARL,0
2025-07-17T15:34:39.865337932Z,2025-07-17T15:34:39.865171719Z,10,2,1108,C,A,10,13.830000000,100,288725173,166213,242774299,13.31,10,1,13.28,11,2,13.14,99,1,13.11,100,1,13.10,100,1,12.99,100,1,12.73,100,1,12.67,100,1,12.65,100,1,12.59,100,1,13.40,0,-10,13.71,0,-1,13.78,0,-1,13.79,0,-1,13.80,0,-2,13.81,0,-1,13.82,0,-2,13.83,0,-1,13.84,0,-2,13.85,0,-2,ARL,0
2025-07-17T15:34:39.865337932Z,2025-07-17T15:34:39.865171719Z,10,2,1108,A,A,10,13.810000000,100,289056097,166213,242774299,13.31,10,1,13.28,11,2,13.14,99,1,13.11,100,1,13.10,100,1,12.99,100,1,12.73,100,1,12.67,100,1,12.65,100,1,12.59,100,1,13.40,0,-10,13.71,0,-1,13.78,0,-1,13.79,0,-1,13.80,0,-2,13.81,0,-1,13.82,0,-2,13.83,0,-1,13.84,0,-2,13.85,0,-2,ARL,0
2025-07-17T15:34:39.871606986Z,2025-07-17T15:34:39.871441822Z,10,2,1108,A,A,10,13.810000000,100,289056353,165164,242774468,13.31,10,1,13.28,11,2,13.14,99,1,13.11,100,1,13.10,100,1,12.99,100,1,12.73,100,1,12.67,100,1,12.65,100,1,12.59,100,1,13.40,0,-10,13.71,0,-1,13.78,0,-1,13.79,0,-1,13.80,0,-2,13.81,0,-1,13.82,0,-2,13.83,0,-1,13.84,0,-2,13.85,0,-2,ARL,0
2025-07-17T15:34:39.878645012Z,2025-07-17T15:34:39.878479562Z,10,2,1108,C,A,10,13.840000000,100,288845417,165450,242774619,13.31,10,1,13.28,11,2,13.14,99,1,13.11,100,1,13.10,100,1,12.99,100,1,12.73,100,1,12.67,100,1,12.65,100,1,12.59,100,1,13.40,0,-10,13.71,0,-1,13.78,0,-1,13.79,0,-1,13.80,0,-2,13.81,0,-2,13.82,0,-2,13.83,0,-1,13.84,0,-2,13.85,0,-2,ARL,0
2025-07-17T15:34:42.774190041Z,2025-07-17T15:34:42.774024574Z,10,2,1108,C,B,10,13.310000000,10,288724225,165467,242816556,13.31,10,1,13.28,11,2,13.14,99,1,13.11,100,1,13.10,100,1,12.99,100,1,12.73,100,1,12.67,100,1,12.65,100,1,12.59,100,1,13.40,0,-10,13.71,0,-1,13.78,0,-1,13.79,0,-1,13.80,0,-2,13.81,0,-2,13.82,0,-2,13.83,0,-1,13.84,0,-2,13.85,0,-2,ARL,0
2025-07-17T15:34:42.775304741Z,2025-07-17T15:34:42.775139521Z,10,2,1108,C,A,10,13.810000000,100,289056353,165220,242816563,13.31,10,1,13.28,11,2,13.14,99,1,13.11,100,1,13.10,100,1,12.99,100,1,12.73,100,1,12.67,100,1,12.65,100,1,12.59,100,1,13.40,0,-10,13.71,0,-1,13.78,0,-1,13.79,0,-1,13.80,0,-2,13.81,0,-2,13.82,0,-2,13.83,0,-1,13.84,0,-2,13.85,0,-2,ARL,0
2025-07-17T15:34:46.774087945Z,2025-07-17T15:34:46.773922586Z,10,2,1108,C,A,10,13.800000000,15,289055901,165359,242893860,13.31,10,1,13.28,11,2,13.14,99,1,13.11,100,1,13.10,100,1,12.99,100,1,12.73,100,1,12.67,100,1,12.65,100,1,12.59,100,1,13.40,0,-10,13.71,0,-1,13.78,0,-1,13.79,0,-1,13.80,0,-2,13.81,0,-2,13.82,0,-2,13.83,0,-1,13.84,0,-2,13.85,0,-2,ARL,0
2025-07-17T15:34:46.800955057Z,2025-07-17T15:34:46.800789632Z,10,2,1108,A,A,10,13.830000000,100,289199221,165425,242894153,13.31,10,1,13.28,11,2,13.14,99,1,13.11,100,1,13.10,100,1,12.99,100,1,12.73,100,1,12.67,100,1,12.65,100,1,12.59,100,1,13.40,0,-10,13.71,0,-1,13.78,0,-1,13.79,0,-1,13.80,0,-2,13.81,0,-2,13.82,0,-2,13.83,0,-1,13.84,0,-2,13.85,0,-2,ARL,0
2025-07-17T15:34:53.545830704Z,2025-07-17T15:34:53.545665068Z,10,2,1108,C,A,10,13.820000000,10,288724229,165636,243011340,13.31,10,1,13.28,11,2,13.14,99,1,13.11,100,1,13.10,100,1,12.99,100,1,12.73,100,1,12.67,100,1,12.65,100,1,12.59,100,1,13.40,0,-10,13.71,0,-1,13.78,0,-1,13.79,0,-1,13.80,0,-2,13.81,0,-2,13.82,0,-2,13.83,0,-1,13.84,0,-2,13.85,0,-2,ARL,0
2025-07-17T15:35:05.620763928Z,2025-07-17T15:35:05.620598378Z,10,2,1108,A,A,10,13.770000000,15,289722397,165550,243344672,13.31,10,1,13.28,11,2,13.14,99,1,13.11,100,1,13.10,100,1,12.99,100,1,12.73,100,1,12.67,100,1,12.65,100,1,12.59,100,1,13.40,0,-10,13.71,0,-1,13.78,0,-1,13.79,0,-1,13.80,0,-2,13.81,0,-2,13.82,0,-2,13.83,0,-1,13.84,0,-2,13.85,0,-2,ARL,0
2025-07-17T15:35:05.712575243Z,2025-07-17T15:35:05.712409728Z,10,2,1108,C,A,10,13.810000000,100,289056097,165515,243347940,13.31,10,1,13.28,11,2,13.14,99,1,13.11,100,1,13.10,100,1,12.99,100,1,12.73,100,1,12.67,100,1,12.65,100,1,12.59,100,1,13.40,0,-10,13.71,0,-1,13.77,0,-1,13.78,0,-1,13.79,0,-1,13.80,0,-2,13.81,0,-2,13.82,0,-2,13.83,0,-1,13.84,0,-2,ARL,0
2025-07-17T15:35:05.712575243Z,2025-07-17T15:35:05.712409728Z,10,2,1108,A,A,10,13.780000000,100,289726281,165515,243347940,13.31,10,1,13.28,11,2,13.14,99,1,13.11,100,1,13.10,100,1,12.99,100,1,12.73,100,1,12.67,100,1,12.65,100,1,12.59,100,1,13.40,0,-10,13.71,0,-1,13.77,0,-1,13.78,0,-1,13.79,0,-1,13.80,0,-2,13.81,0,-2,13.82,0,-2,13.83,0,-1,13.84,0,-2,ARL,0
2025-07-17T15:35:05.713315450Z,2025-07-17T15:35:05.713150123Z,10,2,1108,C,A,10,14.610000000,100,237978629,165327,243347987,13.31,10,1,13.28,11,2,13.14,99,1,13.11,100,1,13.10,100,1,12.99,100,1,12.73,100,1,12.67,100,1,12.65,100,1,12.59,100,1,13.40,0,-10,13.71,0,-1,13.77,0,-1,13.78,0,-2,13.79,0,-1,13.80,0,-2,13.81,0,-2,13.82,0,-2,13.83,0,-1,13.84,0,-2,ARL,0
2025-07-17T15:35:05.713322577Z,2025-07-17T15:35:05.713157077Z,10,2,1108,C,A,10,14.900000000,100,288726085,165500,243347988,13.31,10,1,13.28,11,2,13.14,99,1,13.11,100,1,13.10,100,1,12.99,100,1,12.73,100,1,12.67,100,1,12.65,100,1,12.59,100,1,13.40,0,-10,13.71,0,-1,13.77,0,-1,13.78,0,-2,13.79,0,-1,13.80,0,-2,13.81,0,-2,13.82,0,-2,13.83,0,-1,13.84,0,-2,ARL,0
2025-07-17T15:35:05.713322577Z,2025-07-17T15:35:05.713157077Z,10,2,1108,A,A,10,14.850000000,100,289726349,165500,243347988,13.31,10,1,13.28,11,2,13.14,99,1,13.11,100,1,13.10,100,1,12.99,100,1,12.73,100,1,12.67,100,1,12.65,100,1,12.59,100,1,13.40,0,-10,13.71,0,-1,13.77,0,-1,13.78,0,-2,13.79,0,-1,13.80,0,-2,13.81,0,-2,13.82,0,-2,13.83,0,-1,13.84,0,-2,ARL,0
2025-07-17T15:35:05.713677091Z,2025-07-17T15:35:05.713508657Z,10,2,1108,A,A,10,14.400000000,100,289726421,168434,243348032,13.31,10,1,13.28,11,2,13.14,99,1,13.11,100,1,13.10,100,1,12.99,100,1,12.73,100,1,12.67,100,1,12.65,100,1,12.59,100,1,13.40,0,-10,13.71,0,-1,13.77,0,-1,13.78,0,-2,13.79,0,-1,13.80,0,-2,13.81,0,-2,13.82,0,-2,13.83,0,-1,13.84,0,-2,ARL,0
2025-07-17T15:35:05.729568877Z,2025-07-17T15:35:05.729398505Z,10,2,1108,A,A,10,13.800000000,100,289730309,170372,243351264,13.31,10,1,13.28,11,2,13.14,99,1,13.11,100,1,13.10,100,1,12.99,100,1,12.73,100,1,12.67,100,1,12.65,100,1,12.59,100,1,13.40,0,-10,13.71,0,-1,13.77,0,-1,13.78,0,-2,13.79,0,-1,13.80,0,-2,13.81,0,-2,13.82,0,-2,13.83,0,-1,13.84,0,-2,ARL,0
2025-07-17T15:35:05.737967956Z,2025-07-17T15:35:05.737802616Z,10,2,1108,C,A,10,13.830000000,100,289199221,165340,243352644,13.31,10,1,13.28,11,2,13.14,99,1,13.11,100,1,13.10,100,1,12.99,100,1,12.73,100,1,12.67,100,1,12.65,100,1,12.59,100,1,13.40,0,-10,13.71,0,-1,13.77,0,-1,13.78,0,-2,13.79,0,-1,13.80,0,-3,13.81,0,-2,13.82,0,-2,13.83,0,-1,13.84,0,-2,ARL,0
2025-07-17T15:35:06.286572335Z,2025-07-17T15:35:06.286407017Z,10,2,1108,C,A,10,13.770000000,15,289722397,165318,243362628,13.31,10,1,13.28,11,2,13.14,99,1,13.11,100,1,13.10,100,1,12.99,100,1,12.73,100,1,12.67,100,1,12.65,100,1,12.59,100,1,13.40,0,-10,13.71,0,-1,13.77,0,-1,13.78,0,-2,13.79,0,-1,13.80,0,-3,13.81,0,-2,13.82,0,-2,13.83,0,-1,13.84,0,-2,ARL,0
2025-07-17T15:35:09.788280931Z,2025-07-17T15:35:09.788115219Z,10,2,1108,C,B,10,13.230000000,2,272263853,165712,243432828,13.31,10,1,13.28,11,2,13.14,99,1,13.11,100,1,13.10,100,1,12.99,100,1,12.73,100,1,12.67,100,1,12.65,100,1,12.59,100,1,13.40,0,-10,13.71,0,-1,13.77,0,-1,13.78,0,-2,13.79,0,-1,13.80,0,-3,13.81,0,-2,13.82,0,-2,13.83,0,-1,13.84,0,-2,ARL,0
2025-07-17T15:35:09.788280931Z,2025-07-17T15:35:09.788115219Z,10,2,1108,A,B,10,13.140000000,2,289828293,165712,243432828,13.31,10,1,13.28,11,2,13.14,101,2,13.11,100,1,13.10,100,1,12.99,100,1,12.73,100,1,12.67,100,1,12.65,100,1,12.59,100,1,13.40,0,-10,13.71,0,-1,13.77,0,-1,13.78,0,-2,13.79,0,-1,13.80,0,-3,13.81,0,-2,13.82,0,-2,13.83,0,-1,13.84,0,-2,ARL,0
2025-07-17T15:35:11.891867009Z,2025-07-17T15:35:11.891701845Z,10,2,1108,C,A,10,13.800000000,100,289730309,165164,243482295,13.31,10,1,13.28,11,2,13.14,1,1,13.11,100,1,13.10,100,1,12.99,100,1,12.73,100,1,12.67,100,1,12.65,100,1,12.59,100,1,13.40,0,-10,13.71,0,-1,13.77,0,-1,13.78,0,-2,13.79,0,-1,13.80,0,-3,13.81,0,-2,13.82,0,-2,13.83,0,-1,13.84,0,-2,ARL,0
2025-07-17T15:35:14.301647013Z,2025-07-17T15:35:14.301481698Z,10,2,1108,A,A,10,14.680000000,700,289932801,165315,243521615,13.31,10,1,13.28,11,2,13.14,1,1,13.11,100,1,13.10,100,1,12.99,100,1,12.73,100,1,12.67,100,1,12.65,100,1,12.59,100,1,13.40,0,-10,13.71,0,-1,13.77,0,-1,13.78,0,-2,13.79,0,-1,13.80,0,-3,13.81,0,-2,13.82,0,-2,13.83,0,-1,13.84,0,-2,ARL,0
2025-07-17T15:35:14.302443648Z,2025-07-17T15:35:14.302278179Z,10,2,1108,C,A,10,14.910000000,700,147217629,165469,243521616,13.31,10,1,13.28,11,2,13.14,1,1,13.11,100,1,13.10,100,1,12.99,100,1,12.73,100,1,12.67,100,1,12.65,100,1,12.59,100,1,13.40,0,-10,13.71,0,-1,13.77,0,-1,13.78,0,-2,13.79,0,-1,13.80,0,-3,13.81,0,-2,13.82,0,-2,13.83,0,-1,13.84,0,-2,ARL,0
2025-07-17T15:35:15.940644416Z,2025-07-17T15:35:15.940479233Z,10,2,1108,A,A,10,13.820000000,100,289976125,165183,243557058,13.31,10,1,13.28,11,2,13.14,1,1,13.11,100,1,13.10,100,1,12.99,100,1,12.73,100,1,12.67,100,1,12.65,100,1,12.59,100,1,13.40,0,-10,13.71,0,-1,13.77,0,-1,13.78,0,-2,13.79,0,-1,13.80,0,-3,13.81,0,-2,13.82,0,-2,13.83,0,-1,13.84,0,-2,ARL,0
2025-07-17T15:35:23.746674314Z,2025-07-17T15:35:23.746509184Z,10,2,1108,A,A,10,13.800000000,100,290159301,165130,243692012,13.31,10,1,13.28,11,2,13.14,1,1,13.11,100,1,13.10,100,1,12.99,100,1,12.73,100,1,12.67,100,1,12.65,100,1,12.59,100,1,13.40,0,-10,13.71,0,-1,13.77,0,-1,13.78,0,-2,13.79,0,-1,13.80,0,-3,13.81,0,-2,13.82,0,-2,13.83,0,-1,13.84,0,-2,ARL,0
2025-07-17T15:35:23.754618546Z,2025-07-17T15:35:23.754453294Z,10,2,1108,C,A,10,13.820000000,100,289976125,165252,243692501,13.31,10,1,13.28,11,2,13.14,1,1,13.11,100,1,13.10,100,1,12.99,100,1,12.73,100,1,12.67,100,1,12.65,100,1,12.59,100,1,13.40,0,-10,13.71,0,-1,13.77,0,-1,13.78,0,-2,13.79,0,-1,13.80,0,-4,13.81,0,-2,13.82,0,-2,13.83,0,-1,13.84,0,-2,ARL,0
2025-07-17T15:35:39.056679600Z,2025-07-17T15:35:39.056513985Z,10,2,1108,C,A,10,13.800000000,100,290159301,165615,243992725,13.31,10,1,13.28,11,2,13.14,1,1,13.11,100,1,13.10,100,1,12.99,100,1,12.73,100,1,12.67,100,1,12.65,100,1,12.59,100,1,13.40,0,-10,13.71,0,-1,13.77,0,-1,13.78,0,-2,13.79,0,-1,13.80,0,-4,13.81,0,-2,13.82,0,-2,13.83,0,-1,13.84,0,-2,ARL,0
2025-07-17T15:35:43.128809717Z,2025-07-17T15:35:43.128644252Z,10,2,1108,A,A,10,13.820000000,100,290630573,165465,244078096,13.31,10,1,13.28,11,2,13.14,1,1,13.11,100,1,13.10,100,1,12.99,100,1,12.73,100,1,12.67,100,1,12.65,100,1,12.59,100,1,13.40,0,-10,13.71,0,-1,13.77,0,-1,13.78,0,-2,13.79,0,-1,13.80,0,-4,13.81,0,-2,13.82,0,-2,13.83,0,-1,13.84,0,-2,ARL,0
2025-07-17T15:36:30.044094509Z,2025-07-17T15:36:30.043928872Z,10,2,1108,A,A,10,13.800000000,100,291778909,165637,245013624,13.31,10,1,13.28,11,2,13.14,1,1,13.11,100,1,13.10,100,1,12.99,100,1,12.73,100,1,12.67,100,1,12.65,100,1,12.59,100,1,13.40,0,-10,13.71,0,-1,13.77,0,-1,13.78,0,-2,13.79,0,-1,13.80,0,-4,13.81,0,-2,13.82,0,-2,13.83,0,-1,13.84,0,-2,ARL,0
2025-07-17T15:36:30.051045453Z,2025-07-17T15:36:30.050880126Z,10,2,1108,C,A,10,13.820000000,100,290630573,165327,245013914,13.31,10,1,13.28,11,2,13.14,1,1,13.11,100,1,13.10,100,1,12.99,100,1,12.73,100,1,12.67,100,1,12.65,100,1,12.59,100,1,13.40,0,-10,13.71,0,-1,13.77,0,-1,13.78,0,-2,13.79,0,-1,13.80,0,-5,13.81,0,-2,13.82,0,-2,13.83,0,-1,13.84,0,-2,ARL,0
2025-07-17T15:36:34.298010005Z,2025-07-17T15:36:34.297844579Z,10,2,1108,C,B,10,13.300000000,100,288724429,165426,245144122,13.31,10,1,13.28,11,2,13.14,1,1,13.11,100,1,13.10,100,1,12.99,100,1,12.73,100,1,12.67,100,1,12.65,100,1,12.59,100,1,13.40,0,-10,13.71,0,-1,13.77,0,-1,13.78,0,-2,13.79,0,-1,13.80,0,-5,13.81,0,-2,13.82,0,-2,13.83,0,-1,13.84,0,-2,ARL,0
2025-07-17T15:36:35.381330809Z,2025-07-17T15:36:35.381165559Z,10,2,1108,A,B,10,13.130000000,100,291951937,165250,245161447,13.31,10,1,13.28,11,2,13.14,1,1,13.13,100,1,13.11,100,1,13.10,100,1,12.99,100,1,12.73,100,1,12.67,100,1,12.65,100,1,13.40,0,-10,13.71,0,-1,13.77,0,-1,13.78,0,-2,13.79,0,-1,13.80,0,-5,13.81,0,-2,13.82,0,-2,13.83,0,-1,13.84,0,-2,ARL,0
2025-07-17T15:36:35.532851032Z,2025-07-17T15:36:35.532685683Z,10,2,1108,A,B,10,13.270000000,10,291964737,165349,245174454,13.31,10,1,13.28,11,2,13.27,10,1,13.14,1,1,13.13,100,1,13.11,100,1,13.10,100,1,12.99,100,1,12.73,100,1,12.67,100,1,13.40,0,-10,13.71,0,-1,13.77,0,-1,13.78,0,-2,13.79,0,-1,13.80,0,-5,13.81,0,-2,13.82,0,-2,13.83,0,-1,13.84,0,-2,ARL,0
2025-07-17T15:36:35.532926951Z,2025-07-17T15:36:35.532761335Z,10,2,1108,C,B,10,12.270000000,100,288724485,165616,245174461,13.31,10,1,13.28,11,2,13.14,1,1,13.13,100,1,13.11,100,1,13.10,100,1,12.99,100,1,12.73,100,1,12.67,100,1,12.65,100,1,13.40,0,-10,13.71,0,-1,13.77,0,-1,13.78,0,-2,13.79,0,-1,13.80,0,-5,13.81,0,-2,13.82,0,-2,13.83,0,-1,13.84,0,-2,ARL,0
2025-07-17T15:36:35.532926951Z,2025-07-17T15:36:35.532761335Z,10,2,1108,A,B,10,12.230000000,100,291964745,165616,245174461,13.31,10,1,13.28,11,2,13.14,1,1,13.13,100,1,13.11,100,1,13.10,100,1,12.99,100,1,12.73,100,1,12.67,100,1,12.65,100,1,13.40,0,-10,13.71,0,-1,13.77,0,-1,13.78,0,-2,13.79,0,-1,13.80,0,-5,13.81,0,-2,13.82,0,-2,13.83,0,-1,13.84,0,-2,ARL,0
2025-07-17T15:36:36.152132527Z,2025-07-17T15:36:36.151966883Z,10,2,1108,C,B,10,13.130000000,100,291951937,165644,245183955,13.31,10,1,13.28,11,2,13.14,1,1,13.13,100,1,13.11,100,1,13.10,100,1,12.99,100,1,12.73,100,1,12.67,100,1,12.65,100,1,13.40,0,-10,13.71,0,-1,13.77,0,-1,13.78,0,-2,13.79,0,-1,13.80,0,-5,13.81,0,-2,13.82,0,-2,13.83,0,-1,13.84,0,-2,ARL,0
2025-07-17T15:36:36.152132527Z,2025-07-17T15:36:36.151966883Z,10,2,1108,A,B,10,13.260000000,100,291975017,165644,245183955,13.31,10,1,13.28,11,2,13.26,100,1,13.14,1,1,13.13,100,1,13.11,100,1,13.10,100,1,12.99,100,1,12.73,100,1,12.67,100,1,13.40,0,-10,13.71,0,-1,13.77,0,-1,13.78,0,-2,13.79,0,-1,13.80,0,-5,13.81,0,-2,13.82,0,-2,13.83,0,-1,13.84,0,-2,ARL,0
2025-07-17T15:36:46.889917278Z,2025-07-17T15:36:46.889749756Z,10,2,1108,C,B,10,13.270000000,10,291964737,167522,245499598,13.31,10,1,13.28,11,2,13.26,90,1,13.14,1,1,13.13,100,1,13.11,100,1,13.10,100,1,12.99,100,1,12.73,100,1,12.67,100,1,13.40,0,-10,13.71,0,-1,13.77,0,-1,13.78,0,-2,13.79,0,-1,13.80,0,-5,13.81,0,-2,13.82,0,-2,13.83,0,-1,13.84,0,-2,ARL,0
2025-07-17T15:36:46.986820391Z,2025-07-17T15:36:46.986655137Z,10,2,1108,C,A,10,13.800000000,100,291778909,165254,245503745,13.31,10,1,13.28,11,2,13.14,1,1,13.13,100,1,13.11,100,1,13.10,100,1,12.99,100,1,12.73,100,1,12.67,100,1,12.65,100,1,13.40,0,-10,13.71,0,-1,13.77,0,-1,13.78,0,-2,13.79,0,-1,13.80,0,-5,13.81,0,-2,13.82,0,-2,13.83,0,-1,13.84,0,-2,ARL,0
2025-07-17T15:36:50.997434689Z,2025-07-17T15:36:50.997269299Z,10,2,1108,A,A,10,13.820000000,100,292434813,165390,245564901,13.31,10,1,13.28,11,2,13.14,1,1,13.13,100,1,13.11,100,1,13.10,100,1,12.99,100,1,12.73,100,1,12.67,100,1,12.65,100,1,13.40,0,-10,13.71,0,-1,13.77,0,-1,13.78,0,-2,13.79,0,-1,13.80,0,-5,13.81,0,-2,13.82,0,-2,13.83,0,-1,13.84,0,-2,ARL,0
2025-07-17T15:37:40.389737573Z,2025-07-17T15:37:40.389572053Z,10,2,1108,C,B,10,13.140000000,2,289828293,165520,246491394,13.31,10,1,13.28,11,2,13.14,1,1,13.13,100,1,13.11,100,1,13.10,100,1,12.99,100,1,12.73,100,1,12.67,100,1,12.65,100,1,13.40,0,-10,13.71,0,-1,13.77,0,-1,13.78,0,-2,13.79,0,-1,13.80,0,-5,13.81,0,-2,13.82,0,-2,13.83,0,-1,13.84,0,-2,ARL,0
2025-07-17T15:37:40.389737573Z,2025-07-17T15:37:40.389572053Z,10,2,1108,A,B,10,13.040000000,2,293594281,165520,246491394,13.31,10,1,13.28,11,2,13.14,1,1,13.13,100,1,13.11,100,1,13.10,100,1,13.04,2,1,12.99,100,1,12.73,100,1,12.67,100,1,13.40,0,-10,13.71,0,-1,13.77,0,-1,13.78,0,-2,13.79,0,-1,13.80,0,-5,13.81,0,-2,13.82,0,-2,13.83,0,-1,13.84,0,-2,ARL,0
2025-07-17T15:39:27.070109669Z,2025-07-17T15:39:27.069942913Z,10,2,1108,A,A,10,13.800000000,100,296059685,166756,248436908,13.31,10,1,13.28,11,2,13.14,1,1,13.13,100,1,13.11,100,1,13.10,100,1,13.04,2,1,12.99,100,1,12.73,100,1,12.67,100,1,13.40,0,-10,13.71,0,-1,13.77,0,-1,13.78,0,-2,13.79,0,-1,13.80,0,-5,13.81,0,-2,13.82,0,-2,13.83,0,-1,13.84,0,-2,ARL,0
2025-07-17T15:39:27.077565902Z,2025-07-17T15:39:27.077400388Z,10,2,1108,C,A,10,13.820000000,100,292434813,165514,248437548,13.31,10,1,13.28,11,2,13.14,1,1,13.13,100,1,13.11,100,1,13.10,100,1,13.04,2,1,12.99,100,1,12.73,100,1,12.67,100,1,13.40,0,-10,13.71,0,-1,13.77,0,-1,13.78,0,-2,13.79,0,-1,13.80,0,-6,13.81,0,-2,13.82,0,-2,13.83,0,-1,13.84,0,-2,ARL,0
2025-07-17T15:39:30.509853083Z,2025-07-17T15:39:30.509687817Z,10,2,1108,A,A,10,13.760000000,15,296136617,165266,248491930,13.31,10,1,13.28,11,2,13.14,1,1,13.13,100,1,13.11,100,1,13.10,100,1,13.04,2,1,12.99,100,1,12.73,100,1,12.67,100,1,13.40,0,-10,13.71,0,-1,13.77,0,-1,13.78,0,-2,13.79,0,-1,13.80,0,-6,13.81,0,-2,13.82,0,-2,13.83,0,-1,13.84,0,-2,ARL,0
2025-07-17T15:39:30.573217843Z,2025-07-17T15:39:30.573052284Z,10,2,1108,C,A,10,13.780000000,100,289726281,165559,248492793,13.31,10,1,13.28,11,2,13.14,1,1,13.13,100,1,13.11,100,1,13.10,100,1,13.04,2,1,12.99,100,1,12.73,100,1,12.67,100,1,13.40,0,-10,13.71,0,-1,13.76,0,-1,13.77,0,-1,13.78,0,-2,13.79,0,-1,13.80,0,-6,13.81,0,-2,13.82,0,-2,13.83,0,-1,ARL,0
2025-07-17T15:39:30.573217843Z,2025-07-17T15:39:30.573052284Z,10,2,1108,A,A,10,13.770000000,100,296137537,165559,248492793,13.31,10,1,13.28,11,2,13.14,1,1,13.13,100,1,13.11,100,1,13.10,100,1,13.04,2,1,12.99,100,1,12.73,100,1,12.67,100,1,13.40,0,-10,13.71,0,-1,13.76,0,-1,13.77,0,-1,13.78,0,-2,13.79,0,-1,13.80,0,-6,13.81,0,-2,13.82,0,-2,13.83,0,-1,ARL,0
2025-07-17T15:39:30.589169820Z,2025-07-17T15:39:30.589004378Z,10,2,1108,C,A,10,14.120000000,100,286680917,165442,248493012,13.31,10,1,13.28,11,2,13.14,1,1,13.13,100,1,13.11,100,1,13.10,100,1,13.04,2,1,12.99,100,1,12.73,100,1,12.67,100,1,13.40,0,-10,13.71,0,-1,13.76,0,-1,13.77,0,-2,13.78,0,-2,13.79,0,-1,13.80,0,-6,13.81,0,-2,13.82,0,-2,13.83,0,-1,ARL,0
2025-07-17T15:39:30.589224596Z,2025-07-17T15:39:30.589059301Z,10,2,1108,A,A,10,14.050000000,100,296137769,165295,248493014,13.31,10,1,13.28,11,2,13.14,1,1,13.13,100,1,13.11,100,1,13.10,100,1,13.04,2,1,12.99,100,1,12.73,100,1,12.67,100,1,13.40,0,-10,13.71,0,-1,13.76,0,-1,13.77,0,-2,13.78,0,-2,13.79,0,-1,13.80,0,-6,13.81,0,-2,13.82,0,-2,13.83,0,-1,ARL,0
2025-07-17T15:39:31.092010369Z,2025-07-17T15:39:31.091844988Z,10,2,1108,A,A,10,13.780000000,100,296149845,165381,248502203,13.31,10,1,13.28,11,2,13.14,1,1,13.13,100,1,13.11,100,1,13.10,100,1,13.04,2,1,12.99,100,1,12.73,100,1,12.67,100,1,13.40,0,-10,13.71,0,-1,13.76,0,-1,13.77,0,-2,13.78,0,-2,13.79,0,-1,13.80,0,-6,13.81,0,-2,13.82,0,-2,13.83,0,-1,ARL,0
2025-07-17T15:39:31.098856641Z,2025-07-17T15:39:31.098691429Z,10,2,1108,C,A,10,13.800000000,100,296059685,165212,248502510,13.31,10,1,13.28,11,2,13.14,1,1,13.13,100,1,13.11,100,1,13.10,100,1,13.04,2,1,12.99,100,1,12.73,100,1,12.67,100,1,13.40,0,-10,13.71,0,-1,13.76,0,-1,13.77,0,-2,13.78,0,-3,13.79,0,-1,13.80,0,-6,13.81,0,-2,13.82,0,-2,13.83,0,-1,ARL,0
2025-07-17T15:39:40.691151435Z,2025-07-17T15:39:40.690971606Z,10,2,1108,A,A,10,13.730000000,15,296365029,179829,248666930,13.31,10,1,13.28,11,2,13.14,1,1,13.13,100,1,13.11,100,1,13.10,100,1,13.04,2,1,12.99,100,1,12.73,100,1,12.67,100,1,13.40,0,-10,13.71,0,-1,13.76,0,-1,13.77,0,-2,13.78,0,-3,13.79,0,-1,13.80,0,-6,13.81,0,-2,13.82,0,-2,13.83,0,-1,ARL,0
2025-07-17T15:39:40.696349429Z,2025-07-17T15:39:40.696182148Z,10,2,1108,C,A,10,13.770000000,100,296137537,167281,248669978,13.31,10,1,13.28,11,2,13.14,1,1,13.13,100,1,13.11,100,1,13.10,100,1,13.04,2,1,12.99,100,1,12.73,100,1,12.67,100,1,13.40,0,-10,13.71,0,-1,13.73,0,-1,13.76,0,-1,13.77,0,-2,13.78,0,-3,13.79,0,-1,13.80,0,-6,13.81,0,-2,13.82,0,-2,ARL,0
2025-07-17T15:39:40.696349429Z,2025-07-17T15:39:40.696182148Z,10,2,1108,A,A,10,13.740000000,100,296368281,167281,248669978,13.31,10,1,13.28,11,2,13.14,1,1,13.13,100,1,13.11,100,1,13.10,100,1,13.04,2,1,12.99,100,1,12.73,100,1,12.67,100,1,13.40,0,-10,13.71,0,-1,13.73,0,-1,13.76,0,-1,13.77,0,-2,13.78,0,-3,13.79,0,-1,13.80,0,-6,13.81,0,-2,13.82,0,-2,ARL,0
2025-07-17T15:39:40.697414147Z,2025-07-17T15:39:40.697247480Z,10,2,1108,C,A,10,14.850000000,100,289726349,166667,248670386,13.31,10,1,13.28,11,2,13.14,1,1,13.13,100,1,13.11,100,1,13.10,100,1,13.04,2,1,12.99,100,1,12.73,100,1,12.67,100,1,13.40,0,-10,13.71,0,-1,13.73,0,-1,13.74,0,-1,13.76,0,-1,13.77,0,-2,13.78,0,-3,13.79,0,-1,13.80,0,-6,13.81,0,-2,ARL,0
2025-07-17T15:39:40.697414147Z,2025-07-17T15:39:40.697247480Z,10,2,1108,A,A,10,14.810000000,100,296368709,166667,248670386,13.31,10,1,13.28,11,2,13.14,1,1,13.13,100,1,13.11,100,1,13.10,100,1,13.04,2,1,12.99,100,1,12.73,100,1,12.67,100,1,13.40,0,-10,13.71,0,-1,13.73,0,-1,13.74,0,-1,13.76,0,-1,13.77,0,-2,13.78,0,-3,13.79,0,-1,13.80,0,-6,13.81,0,-2,ARL,0
2025-07-17T15:39:40.708810377Z,2025-07-17T15:39:40.708645114Z,10,2,1108,A,A,10,13.760000000,100,296372577,165263,248674504,13.31,10,1,13.28,11,2,13.14,1,1,13.13,100,1,13.11,100,1,13.10,100,1,13.04,2,1,12.99,100,1,12.73,100,1,12.67,100,1,13.40,0,-10,13.71,0,-1,13.73,0,-1,13.74,0,-1,13.76,0,-1,13.77,0,-2,13.78,0,-3,13.79,0,-1,13.80,0,-6,13.81,0,-2,ARL,0
2025-07-17T15:39:40.731431547Z,2025-07-17T15:39:40.731266408Z,10,2,1108,C,A,10,13.780000000,100,296149845,165139,248676672,13.31,10,1,13.28,11,2,13.14,1,1,13.13,100,1,13.11,100,1,13.10,100,1,13.04,2,1,12.99,100,1,12.73,100,1,12.67,100,1,13.40,0,-10,13.71,0,-1,13.73,0,-1,13.74,0,-1,13.76,0,-2,13.77,0,-2,13.78,0,-3,13.79,0,-1,13.80,0,-6,13.81,0,-2,ARL,0
2025-07-17T15:39:40.908095999Z,2025-07-17T15:39:40.907929975Z,10,2,1108,C,A,10,15.400000000,100,146959177,166024,248685584,13.31,10,1,13.28,11,2,13.14,1,1,13.13,100,1,13.11,100,1,13.10,100,1,13.04,2,1,12.99,100,1,12.73,100,1,12.67,100,1,13.40,0,-10,13.71,0,-1,13.73,0,-1,13.74,0,-1,13.76,0,-2,13.77,0,-2,13.78,0,-3,13.79,0,-1,13.80,0,-6,13.81,0,-2,ARL,0
2025-07-17T15:39:40.908095999Z,2025-07-17T15:39:40.907929975Z,10,2,1108,A,A,10,15.120000000,100,296387089,166024,248685584,13.31,10,1,13.28,11,2,13.14,1,1,13.13,100,1,13.11,100,1,13.10,100,1,13.04,2,1,12.99,100,1,12.73,100,1,12.67,100,1,13.40,0,-10,13.71,0,-1,13.73,0,-1,13.74,0,-1,13.76,0,-2,13.77,0,-2,13.78,0,-3,13.79,0,-1,13.80,0,-6,13.81,0,-2,ARL,0
2025-07-17T15:39:41.085864728Z,2025-07-17T15:39:41.085699437Z,10,2,1108,A,A,10,14.560000000,100,296391881,165291,248688410,13.31,10,1,13.28,11,2,13.14,1,1,13.13,100,1,13.11,100,1,13.10,100,1,13.04,2,1,12.99,100,1,12.73,100,1,12.67,100,1,13.40,0,-10,13.71,0,-1,13.73,0,-1,13.74,0,-1,13.76,0,-2,13.77,0,-2,13.78,0,-3,13.79,0,-1,13.80,0,-6,13.81,0,-2,ARL,0
2025-07-17T15:39:41.085877317Z,2025-07-17T15:39:41.085711985Z,10,2,1108,C,A,10,14.840000000,100,146962993,165332,248688411,13.31,10,1,13.28,11,2,13.14,1,1,13.13,100,1,13.11,100,1,13.10,100,1,13.04,2,1,12.99,100,1,12.73,100,1,12.67,100,1,13.40,0,-10,13.71,0,-1,13.73,0,-1,13.74,0,-1,13.76,0,-2,13.77,0,-2,13.78,0,-3,13.79,0,-1,13.80,0,-6,13.81,0,-2,ARL,0
2025-07-17T15:39:43.773811774Z,2025-07-17T15:39:43.773645905Z,10,2,1108,C,A,10,14.720000000,100,286680577,165869,248737506,13.31,10,1,13.28,11,2,13.14,1,1,13.13,100,1,13.11,100,1,13.10,100,1,13.04,2,1,12.99,100,1,12.73,100,1,12.67,100,1,13.40,0,-10,13.71,0,-1,13.73,0,-1,13.74,0,-1,13.76,0,-2,13.77,0,-2,13.78,0,-3,13.79,0,-1,13.80,0,-6,13.81,0,-2,ARL,0
2025-07-17T15:39:43.773811774Z,2025-07-17T15:39:43.773645905Z,10,2,1108,A,A,10,14.610000000,100,296455037,165869,248737506,13.31,10,1,13.28,11,2,13.14,1,1,13.13,100,1,13.11,100,1,13.10,100,1,13.04,2,1,12.99,100,1,12.73,100,1,12.67,100,1,13.40,0,-10,13.71,0,-1,13.73,0,-1,13.74,0,-1,13.76,0,-2,13.77,0,-2,13.78,0,-3,13.79,0,-1,13.80,0,-6,13.81,0,-2,ARL,0
2025-07-17T15:39:43.773904473Z,2025-07-17T15:39:43.773738855Z,10,2,1108,C,A,10,14.720000000,100,286680573,165618,248737508,13.31,10,1,13.28,11,2,13.14,1,1,13.13,100,1,13.11,100,1,13.10,100,1,13.04,2,1,12.99,100,1,12.73,100,1,12.67,100,1,13.40,0,-10,13.71,0,-1,13.73,0,-1,13.74,0,-1,13.76,0,-2,13.77,0,-2,13.78,0,-3,13.79,0,-1,13.80,0,-6,13.81,0,-2,ARL,0
2025-07-17T15:39:43.773904473Z,2025-07-17T15:39:43.773738855Z,10,2,1108,A,A,10,14.610000000,100,296455041,165618,248737508,13.31,10,1,13.28,11,2,13.14,1,1,13.13,100,1,13.11,100,1,13.10,100,1,13.04,2,1,12.99,100,1,12.73,100,1,12.67,100,1,13.40,0,-10,13.71,0,-1,13.73,0,-1,13.74,0,-1,13.76,0,-2,13.77,0,-2,13.78,0,-3,13.79,0,-1,13.80,0,-6,13.81,0,-2,ARL,0
2025-07-17T15:39:44.428670900Z,2025-07-17T15:39:44.428505546Z,10,2,1108,C,A,10,13.760000000,15,296136617,165354,248751670,13.31,10,1,13.28,11,2,13.14,1,1,13.13,100,1,13.11,100,1,13.10,100,1,13.04,2,1,12.99,100,1,12.73,100,1,12.67,100,1,13.40,0,-10,13.71,0,-1,13.73,0,-1,13.74,0,-1,13.76,0,-2,13.77,0,-2,13.78,0,-3,13.79,0,-1,13.80,0,-6,13.81,0,-2,ARL,0
2025-07-17T15:39:44.433539292Z,2025-07-17T15:39:44.433372235Z,10,2,1108,C,A,10,13.730000000,15,296365029,167057,248752483,13.31,10,1,13.28,11,2,13.14,1,1,13.13,100,1,13.11,100,1,13.10,100,1,13.04,2,1,12.99,100,1,12.73,100,1,12.67,100,1,13.40,0,-10,13.71,0,-1,13.73,0,-1,13.74,0,-1,13.76,0,-2,13.77,0,-2,13.78,0,-3,13.79,0,-1,13.80,0,-6,13.81,0,-2,ARL,0
2025-07-17T15:39:44.436054885Z,2025-07-17T15:39:44.435889060Z,10,2,1108,C,A,10,13.740000000,100,296368281,165825,248752938,13.31,10,1,13.28,11,2,13.14,1,1,13.13,100,1,13.11,100,1,13.10,100,1,13.04,2,1,12.99,100,1,12.73,100,1,12.67,100,1,13.40,0,-10,13.71,0,-1,13.73,0,-1,13.74,0,-1,13.76,0,-2,13.77,0,-2,13.78,0,-3,13.79,0,-1,13.80,0,-6,13.81,0,-2,ARL,0
2025-07-17T15:39:44.450239090Z,2025-07-17T15:39:44.450073949Z,10,2,1108,C,A,10,13.760000000,100,296372577,165141,248753643,13.31,10,1,13.28,11,2,13.14,1,1,13.13,100,1,13.11,100,1,13.10,100,1,13.04,2,1,12.99,100,1,12.73,100,1,12.67,100,1,13.40,0,-10,13.71,0,-1,13.73,0,-1,13.74,0,-1,13.76,0,-2,13.77,0,-2,13.78,0,-3,13.79,0,-1,13.80,0,-6,13.81,0,-2,ARL,0
2025-07-17T15:39:44.450972330Z,2025-07-17T15:39:44.450806746Z,10,2,1108,C,A,10,14.810000000,100,296368709,165584,248753673,13.31,10,1,13.28,11,2,13.14,1,1,13.13,100,1,13.11,100,1,13.10,100,1,13.04,2,1,12.99,100,1,12.73,100,1,12.67,100,1,13.40,0,-10,13.71,0,-1,13.73,0,-1,13.74,0,-1,13.76,0,-2,13.77,0,-2,13.78,0,-3,13.79,0,-1,13.80,0,-6,13.81,0,-2,ARL,0
2025-07-17T15:39:44.450972330Z,2025-07-17T15:39:44.450806746Z,10,2,1108,A,A,10,15.060000000,100,296478965,165584,248753673,13.31,10,1,13.28,11,2,13.14,1,1,13.13,100,1,13.11,100,1,13.10,100,1,13.04,2,1,12.99,100,1,12.73,100,1,12.67,100,1,13.40,0,-10,13.71,0,-1,13.73,0,-1,13.74,0,-1,13.76,0,-2,13.77,0,-2,13.78,0,-3,13.79,0,-1,13.80,0,-6,13.81,0,-2,ARL,0
2025-07-17T15:39:44.451075992Z,2025-07-17T15:39:44.450910591Z,10,2,1108,C,A,10,13.950000000,2,287540393,165401,248753678,13.31,10,1,13.28,11,2,13.14,1,1,13.13,100,1,13.11,100,1,13.10,100,1,13.04,2,1,12.99,100,1,12.73,100,1,12.67,100,1,13.40,0,-10,13.71,0,-1,13.73,0,-1,13.74,0,-1,13.76,0,-2,13.77,0,-2,13.78,0,-3,13.79,0,-1,13.80,0,-6,13.81,0,-2,ARL,0
2025-07-17T15:39:44.451075992Z,2025-07-17T15:39:44.450910591Z,10,2,1108,A,A,10,14.070000000,2,296478973,165401,248753678,13.31,10,1,13.28,11,2,13.14,1,1,13.13,100,1,13.11,100,1,13.10,100,1,13.04,2,1,12.99,100,1,12.73,100,1,12.67,100,1,13.40,0,-10,13.71,0,-1,13.73,0,-1,13.74,0,-1,13.76,0,-2,13.77,0,-2,13.78,0,-3,13.79,0,-1,13.80,0,-6,13.81,0,-2,ARL,0
2025-07-17T15:39:44.455130297Z,2025-07-17T15:39:44.454964327Z,10,2,1108,C,A,10,14.810000000,100,286680741,165970,248753748,13.31,10,1,13.28,11,2,13.14,1,1,13.13,100,1,13.11,100,1,13.10,100,1,13.04,2,1,12.99,100,1,12.73,100,1,12.67,100,1,13.40,0,-10,13.71,0,-1,13.73,0,-1,13.74,0,-1,13.76,0,-2,13.77,0,-2,13.78,0,-3,13.79,0,-1,13.80,0,-6,13.81,0,-2,ARL,0
2025-07-17T15:39:44.455130297Z,2025-07-17T15:39:44.454964327Z,10,2,1108,A,A,10,14.960000000,100,296479053,165970,248753748,13.31,10,1,13.28,11,2,13.14,1,1,13.13,100,1,13.11,100,1,13.10,100,1,13.04,2,1,12.99,100,1,12.73,100,1,12.67,100,1,13.40,0,-10,13.71,0,-1,13.73,0,-1,13.74,0,-1,13.76,0,-2,13.77,0,-2,13.78,0,-3,13.79,0,-1,13.80,0,-6,13.81,0,-2,ARL,0
2025-07-17T15:39:44.456288062Z,2025-07-17T15:39:44.456122660Z,10,2,1108,C,A,10,14.650000000,100,286680905,165402,248753812,13.31,10,1,13.28,11,2,13.14,1,1,13.13,100,1,13.11,100,1,13.10,100,1,13.04,2,1,12.99,100,1,12.73,100,1,12.67,100,1,13.40,0,-10,13.71,0,-1,13.73,0,-1,13.74,0,-1,13.76,0,-2,13.77,0,-2,13.78,0,-3,13.79,0,-1,13.80,0,-6,13.81,0,-2,ARL,0
2025-07-17T15:39:44.456377500Z,2025-07-17T15:39:44.456211953Z,10,2,1108,A,A,10,14.780000000,100,296479285,165547,248753815,13.31,10,1,13.28,11,2,13.14,1,1,13.13,100,1,13.11,100,1,13.10,100,1,13.04,2,1,12.99,100,1,12.73,100,1,12.67,100,1,13.40,0,-10,13.71,0,-1,13.73,0,-1,13.74,0,-1,13.76,0,-2,13.77,0,-2,13.78,0,-3,13.79,0,-1,13.80,0,-6,13.81,0,-2,ARL,0
2025-07-17T15:39:44.462055094Z,2025-07-17T15:39:44.461889886Z,10,2,1108,C,A,10,14.050000000,100,296137769,165208,248753947,13.31,10,1,13.28,11,2,13.14,1,1,13.13,100,1,13.11,100,1,13.10,100,1,13.04,2,1,12.99,100,1,12.73,100,1,12.67,100,1,13.40,0,-10,13.71,0,-1,13.73,0,-1,13.74,0,-1,13.76,0,-2,13.77,0,-2,13.78,0,-3,13.79,0,-1,13.80,0,-6,13.81,0,-2,ARL,0
2025-07-17T15:39:44.462108809Z,2025-07-17T15:39:44.461943584Z,10,2,1108,A,A,10,14.260000000,100,296479425,165225,248753952,13.31,10,1,13.28,11,2,13.14,1,1,13.13,100,1,13.11,100,1,13.10,100,1,13.04,2,1,12.99,100,1,12.73,100,1,12.67,100,1,13.40,0,-10,13.71,0,-1,13.73,0,-1,13.74,0,-1,13.76,0,-2,13.77,0,-2,13.78,0,-3,13.79,0,-1,13.80,0,-6,13.81,0,-2,ARL,0
2025-07-17T15:39:44.478923366Z,2025-07-17T15:39:44.478757958Z,10,2,1108,C,A,10,17.580000000,100,286681057,165408,248754361,13.31,10,1,13.28,11,2,13.14,1,1,13.13,100,1,13.11,100,1,13.10,100,1,13.04,2,1,12.99,100,1,12.73,100,1,12.67,100,1,13.40,0,-10,13.71,0,-1,13.73,0,-1,13.74,0,-1,13.76,0,-2,13.77,0,-2,13.78,0,-3,13.79,0,-1,13.80,0,-6,13.81,0,-2,ARL,0
2025-07-17T15:39:44.478923366Z,2025-07-17T15:39:44.478757958Z,10,2,1108,A,A,10,17.760000000,100,296479893,165408,248754361,13.31,10,1,13.28,11,2,13.14,1,1,13.13,100,1,13.11,100,1,13.10,100,1,13.04,2,1,12.99,100,1,12.73,100,1,12.67,100,1,13.40,0,-10,13.71,0,-1,13.73,0,-1,13.74,0,-1,13.76,0,-2,13.77,0,-2,13.78,0,-3,13.79,0,-1,13.80,0,-6,13.81,0,-2,ARL,0
2025-07-17T15:39:44.491018431Z,2025-07-17T15:39:44.490852860Z,10,2,1108,C,A,10,15.920000000,100,286681229,165571,248754608,13.31,10,1,13.28,11,2,13.14,1,1,13.13,100,1,13.11,100,1,13.10,100,1,13.04,2,1,12.99,100,1,12.73,100,1,12.67,100,1,13.40,0,-10,13.71,0,-1,13.73,0,-1,13.74,0,-1,13.76,0,-2,13.77,0,-2,13.78,0,-3,13.79,0,-1,13.80,0,-6,13.81,0,-2,ARL,0
2025-07-17T15:39:44.491018431Z,2025-07-17T15:39:44.490852860Z,10,2,1108,A,A,10,16.080000000,100,296480097,165571,248754608,13.31,10,1,13.28,11,2,13.14,1,1,13.13,100,1,13.11,100,1,13.10,100,1,13.04,2,1,12.99,100,1,12.73,100,1,12.67,100,1,13.40,0,-10,13.71,0,-1,13.73,0,-1,13.74,0,-1,13.76,0,-2,13.77,0,-2,13.78,0,-3,13.79,0,-1,13.80,0,-6,13.81,0,-2,ARL,0
2025-07-17T15:39:44.593773213Z,2025-07-17T15:39:44.593607433Z,10,2,1108,C,A,10,14.810000000,100,286684005,165780,248756227,13.31,10,1,13.28,11,2,13.14,1,1,13.13,100,1,13.11,100,1,13.10,100,1,13.04,2,1,12.99,100,1,12.73,100,1,12.67,100,1,13.40,0,-10,13.71,0,-1,13.73,0,-1,13.74,0,-1,13.76,0,-2,13.77,0,-2,13.78,0,-3,13.79,0,-1,13.80,0,-6,13.81,0,-2,ARL,0
2025-07-17T15:39:44.593773213Z,2025-07-17T15:39:44.593607433Z,10,2,1108,A,A,10,14.960000000,100,296482509,165780,248756227,13.31,10,1,13.28,11,2,13.14,1,1,13.13,100,1,13.11,100,1,13.10,100,1,13.04,2,1,12.99,100,1,12.73,100,1,12.67,100,1,13.40,0,-10,13.71,0,-1,13.73,0,-1,13.74,0,-1,13.76,0,-2,13.77,0,-2,13.78,0,-3,13.79,0,-1,13.80,0,-6,13.81,0,-2,ARL,0
2025-07-17T15:39:44.859886562Z,2025-07-17T15:39:44.859720946Z,10,2,1108,C,A,10,14.610000000,100,296455041,165616,248760319,13.31,10,1,13.28,11,2,13.14,1,1,13.13,100,1,13.11,100,1,13.10,100,1,13.04,2,1,12.99,100,1,12.73,100,1,12.67,100,1,13.40,0,-10,13.71,0,-1,13.73,0,-1,13.74,0,-1,13.76,0,-2,13.77,0,-2,13.78,0,-3,13.79,0,-1,13.80,0,-6,13.81,0,-2,ARL,0
2025-07-17T15:39:44.859886562Z,2025-07-17T15:39:44.859720946Z,10,2,1108,A,A,10,15.100000000,100,296485621,165616,248760319,13.31,10,1,13.28,11,2,13.14,1,1,13.13,100,1,13.11,100,1,13.10,100,1,13.04,2,1,12.99,100,1,12.73,100,1,12.67,100,1,13.40,0,-10,13.71,0,-1,13.73,0,-1,13.74,0,-1,13.76,0,-2,13.77,0,-2,13.78,0,-3,13.79,0,-1,13.80,0,-6,13.81,0,-2,ARL,0
2025-07-17T15:39:44.860160096Z,2025-07-17T15:39:44.859994671Z,10,2,1108,A,A,10,14.080000000,100,296485629,165425,248760324,13.31,10,1,13.28,11,2,13.14,1,1,13.13,100,1,13.11,100,1,13.10,100,1,13.04,2,1,12.99,100,1,12.73,100,1,12.67,100,1,13.40,0,-10,13.71,0,-1,13.73,0,-1,13.74,0,-1,13.76,0,-2,13.77,0,-2,13.78,0,-3,13.79,0,-1,13.80,0,-6,13.81,0,-2,ARL,0
2025-07-17T15:39:44.863678795Z,2025-07-17T15:39:44.863513587Z,10,2,1108,C,A,10,14.610000000,100,296455037,165208,248760417,13.31,10,1,13.28,11,2,13.14,1,1,13.13,100,1,13.11,100,1,13.10,100,1,13.04,2,1,12.99,100,1,12.73,100,1,12.67,100,1,13.40,0,-10,13.71,0,-1,13.73,0,-1,13.74,0,-1,13.76,0,-2,13.77,0,-2,13.78,0,-3,13.79,0,-1,13.80,0,-6,13.81,0,-2,ARL,0
2025-07-17T15:39:44.863678795Z,2025-07-17T15:39:44.863513587Z,10,2,1108,A,A,10,15.100000000,100,296485649,165208,248760417,13.31,10,1,13.28,11,2,13.14,1,1,13.13,100,1,13.11,100,1,13.10,100,1,13.04,2,1,12.99,100,1,12.73,100,1,12.67,100,1,13.40,0,-10,13.71,0,-1,13.73,0,-1,13.74,0,-1,13.76,0,-2,13.77,0,-2,13.78,0,-3,13.79,0,-1,13.80,0,-6,13.81,0,-2,ARL,0
2025-07-17T15:39:54.187008224Z,2025-07-17T15:39:54.186842327Z,10,2,1108,C,A,10,15.100000000,100,296485649,165897,248915116,13.31,10,1,13.28,11,2,13.14,1,1,13.13,100,1,13.11,100,1,13.10,100,1,13.04,2,1,12.99,100,1,12.73,100,1,12.67,100,1,13.40,0,-10,13.71,0,-1,13.73,0,-1,13.74,0,-1,13.76,0,-2,13.77,0,-2,13.78,0,-3,13.79,0,-1,13.80,0,-6,13.81,0,-2,ARL,0
2025-07-17T15:39:54.187008224Z,2025-07-17T15:39:54.186842327Z,10,2,1108,A,A,10,14.880000000,100,296679277,165897,248915116,13.31,10,1,13.28,11,2,13.14,1,1,13.13,100,1,13.11,100,1,13.10,100,1,13.04,2,1,12.99,100,1,12.73,100,1,12.67,100,1,13.40,0,-10,13.71,0,-1,13.73,0,-1,13.74,0,-1,13.76,0,-2,13.77,0,-2,13.78,0,-3,13.79,0,-1,13.80,0,-6,13.81,0,-2,ARL,0
2025-07-17T15:39:54.187557412Z,2025-07-17T15:39:54.187391707Z,10,2,1108,C,A,10,15.100000000,100,296485621,165705,248915126,13.31,10,1,13.28,11,2,13.14,1,1,13.13,100,1,13.11,100,1,13.10,100,1,13.04,2,1,12.99,100,1,12.73,100,1,12.67,100,1,13.40,0,-10,13.71,0,-1,13.73,0,-1,13.74,0,-1,13.76,0,-2,13.77,0,-2,13.78,0,-3,13.79,0,-1,13.80,0,-6,13.81,0,-2,ARL,0
2025-07-17T15:39:54.187557412Z,2025-07-17T15:39:54.187391707Z,10,2,1108,A,A,10,14.880000000,100,296679285,165705,248915126,13.31,10,1,13.28,11,2,13.14,1,1,13.13,100,1,13.11,100,1,13.10,100,1,13.04,2,1,12.99,100,1,12.73,100,1,12.67,100,1,13.40,0,-10,13.71,0,-1,13.73,0,-1,13.74,0,-1,13.76,0,-2,13.77,0,-2,13.78,0,-3,13.79,0,-1,13.80,0,-6,13.81,0,-2,ARL,0
2025-07-17T15:42:06.780503054Z,2025-07-17T15:42:06.780337543Z,10,2,1108,A,A,10,13.900000000,15,299689753,165511,251407709,13.31,10,1,13.28,11,2,13.14,1,1,13.13,100,1,13.11,100,1,13.10,100,1,13.04,2,1,12.99,100,1,12.73,100,1,12.67,100,1,13.40,0,-10,13.71,0,-1,13.73,0,-1,13.74,0,-1,13.76,0,-2,13.77,0,-2,13.78,0,-3,13.79,0,-1,13.80,0,-6,13.81,0,-2,ARL,0
2025-07-17T15:42:06.780767761Z,2025-07-17T15:42:06.780602350Z,10,2,1108,C,A,10,14.080000000,100,296485629,165411,251407713,13.31,10,1,13.28,11,2,13.14,1,1,13.13,100,1,13.11,100,1,13.10,100,1,13.04,2,1,12.99,100,1,12.73,100,1,12.67,100,1,13.40,0,-10,13.71,0,-1,13.73,0,-1,13.74,0,-1,13.76,0,-2,13.77,0,-2,13.78,0,-3,13.79,0,-1,13.80,0,-6,13.81,0,-2,ARL,0
2025-07-17T15:42:06.780767761Z,2025-07-17T15:42:06.780602350Z,10,2,1108,A,A,10,13.910000000,100,299689769,165411,251407713,13.31,10,1,13.28,11,2,13.14,1,1,13.13,100,1,13.11,100,1,13.10,100,1,13.04,2,1,12.99,100,1,12.73,100,1,12.67,100,1,13.40,0,-10,13.71,0,-1,13.73,0,-1,13.74,0,-1,13.76,0,-2,13.77,0,-2,13.78,0,-3,13.79,0,-1,13.80,0,-6,13.81,0,-2,ARL,0
2025-07-17T15:42:06.781502831Z,2025-07-17T15:42:06.781336642Z,10,2,1108,C,A,10,15.060000000,100,296478965,166189,251407747,13.31,10,1,13.28,11,2,13.14,1,1,13.13,100,1,13.11,100,1,13.10,100,1,13.04,2,1,12.99,100,1,12.73,100,1,12.67,100,1,13.40,0,-10,13.71,0,-1,13.73,0,-1,13.74,0,-1,13.76,0,-2,13.77,0,-2,13.78,0,-3,13.79,0,-1,13.80,0,-6,13.81,0,-2,ARL,0
2025-07-17T15:42:06.781502831Z,2025-07-17T15:42:06.781336642Z,10,2,1108,A,A,10,14.990000000,100,299689857,166189,251407747,13.31,10,1,13.28,11,2,13.14,1,1,13.13,100,1,13.11,100,1,13.10,100,1,13.04,2,1,12.99,100,1,12.73,100,1,12.67,100,1,13.40,0,-10,13.71,0,-1,13.73,0,-1,13.74,0,-1,13.76,0,-2,13.77,0,-2,13.78,0,-3,13.79,0,-1,13.80,0,-6,13.81,0,-2,ARL,0
2025-07-17T15:42:06.795521307Z,2025-07-17T15:42:06.795355762Z,10,2,1108,C,A,10,14.260000000,100,296479425,165545,251408268,13.31,10,1,13.28,11,2,13.14,1,1,13.13,100,1,13.11,100,1,13.10,100,1,13.04,2,1,12.99,100,1,12.73,100,1,12.67,100,1,13.40,0,-10,13.71,0,-1,13.73,0,-1,13.74,0,-1,13.76,0,-2,13.77,0,-2,13.78,0,-3,13.79,0,-1,13.80,0,-6,13.81,0,-2,ARL,0
2025-07-17T15:42:06.795573392Z,2025-07-17T15:42:06.795408057Z,10,2,1108,A,A,10,14.190000000,100,299690593,165335,251408269,13.31,10,1,13.28,11,2,13.14,1,1,13.13,100,1,13.11,100,1,13.10,100,1,13.04,2,1,12.99,100,1,12.73,100,1,12.67,100,1,13.40,0,-10,13.71,0,-1,13.73,0,-1,13.74,0,-1,13.76,0,-2,13.77,0,-2,13.78,0,-3,13.79,0,-1,13.80,0,-6,13.81,0,-2,ARL,0
2025-07-17T15:42:16.264132159Z,2025-07-17T15:42:16.263966448Z,10,2,1108,C,A,10,14.880000000,100,296679285,165711,251574391,13.31,10,1,13.28,11,2,13.14,1,1,13.13,100,1,13.11,100,1,13.10,100,1,13.04,2,1,12.99,100,1,12.73,100,1,12.67,100,1,13.40,0,-10,13.71,0,-1,13.73,0,-1,13.74,0,-1,13.76,0,-2,13.77,0,-2,13.78,0,-3,13.79,0,-1,13.80,0,-6,13.81,0,-2,ARL,0
2025-07-17T15:42:16.264132159Z,2025-07-17T15:42:16.263966448Z,10,2,1108,A,A,10,14.760000000,100,299903169,165711,251574391,13.31,10,1,13.28,11,2,13.14,1,1,13.13,100,1,13.11,100,1,13.10,100,1,13.04,2,1,12.99,100,1,12.73,100,1,12.67,100,1,13.40,0,-10,13.71,0,-1,13.73,0,-1,13.74,0,-1,13.76,0,-2,13.77,0,-2,13.78,0,-3,13.79,0,-1,13.80,0,-6,13.81,0,-2,ARL,0
2025-07-17T15:42:17.356766715Z,2025-07-17T15:42:17.356601231Z,10,2,1108,A,A,10,13.830000000,15,299923773,165484,251593608,13.31,10,1,13.28,11,2,13.14,1,1,13.13,100,1,13.11,100,1,13.10,100,1,13.04,2,1,12.99,100,1,12.73,100,1,12.67,100,1,13.40,0,-10,13.71,0,-1,13.73,0,-1,13.74,0,-1,13.76,0,-2,13.77,0,-2,13.78,0,-3,13.79,0,-1,13.80,0,-6,13.81,0,-2,ARL,0
2025-07-17T15:42:17.577474246Z,2025-07-17T15:42:17.577308779Z,10,2,1108,C,A,10,13.910000000,100,299689769,165467,251595553,13.31,10,1,13.28,11,2,13.14,1,1,13.13,100,1,13.11,100,1,13.10,100,1,13.04,2,1,12.99,100,1,12.73,100,1,12.67,100,1,13.40,0,-10,13.71,0,-1,13.73,0,-1,13.74,0,-1,13.76,0,-2,13.77,0,-2,13.78,0,-3,13.79,0,-1,13.80,0,-6,13.81,0,-2,ARL,0
2025-07-17T15:42:17.577474246Z,2025-07-17T15:42:17.577308779Z,10,2,1108,A,A,10,13.840000000,100,299926781,165467,251595553,13.31,10,1,13.28,11,2,13.14,1,1,13.13,100,1,13.11,100,1,13.10,100,1,13.04,2,1,12.99,100,1,12.73,100,1,12.67,100,1,13.40,0,-10,13.71,0,-1,13.73,0,-1,13.74,0,-1,13.76,0,-2,13.77,0,-2,13.78,0,-3,13.79,0,-1,13.80,0,-6,13.81,0,-2,ARL,0
2025-07-17T15:42:17.578219175Z,2025-07-17T15:42:17.578053644Z,10,2,1108,C,A,10,14.990000000,100,299689857,165531,251595563,13.31,10,1,13.28,11,2,13.14,1,1,13.13,100,1,13.11,100,1,13.10,100,1,13.04,2,1,12.99,100,1,12.73,100,1,12.67,100,1,13.40,0,-10,13.71,0,-1,13.73,0,-1,13.74,0,-1,13.76,0,-2,13.77,0,-2,13.78,0,-3,13.79,0,-1,13.80,0,-6,13.81,0,-2,ARL,0
2025-07-17T15:42:17.578219175Z,2025-07-17T15:42:17.578053644Z,10,2,1108,A,A,10,14.910000000,100,299926801,165531,251595563,13.31,10,1,13.28,11,2,13.14,1,1,13.13,100,1,13.11,100,1,13.10,100,1,13.04,2,1,12.99,100,1,12.73,100,1,12.67,100,1,13.40,0,-10,13.71,0,-1,13.73,0,-1,13.74,0,-1,13.76,0,-2,13.77,0,-2,13.78,0,-3,13.79,0,-1,13.80,0,-6,13.81,0,-2,ARL,0
2025-07-17T15:42:17.579343189Z,2025-07-17T15:42:17.579177582Z,10,2,1108,C,A,10,14.780000000,100,296479285,165607,251595571,13.31,10,1,13.28,11,2,13.14,1,1,13.13,100,1,13.11,100,1,13.10,100,1,13.04,2,1,12.99,100,1,12.73,100,1,12.67,100,1,13.40,0,-10,13.71,0,-1,13.73,0,-1,13.74,0,-1,13.76,0,-2,13.77,0,-2,13.78,0,-3,13.79,0,-1,13.80,0,-6,13.81,0,-2,ARL,0
2025-07-17T15:42:17.579343189Z,2025-07-17T15:42:17.579177582Z,10,2,1108,A,A,10,14.640000000,100,299926813,165607,251595571,13.31,10,1,13.28,11,2,13.14,1,1,13.13,100,1,13.11,100,1,13.10,100,1,13.04,2,1,12.99,100,1,12.73,100,1,12.67,100,1,13.40,0,-10,13.71,0,-1,13.73,0,-1,13.74,0,-1,13.76,0,-2,13.77,0,-2,13.78,0,-3,13.79,0,-1,13.80,0,-6,13.81,0,-2,ARL,0
2025-07-17T15:42:17.580008869Z,2025-07-17T15:42:17.579843331Z,10,2,1108,C,A,10,14.960000000,100,296479053,165538,251595576,13.31,10,1,13.28,11,2,13.14,1,1,13.13,100,1,13.11,100,1,13.10,100,1,13.04,2,1,12.99,100,1,12.73,100,1,12.67,100,1,13.40,0,-10,13.71,0,-1,13.73,0,-1,13.74,0,-1,13.76,0,-2,13.77,0,-2,13.78,0,-3,13.79,0,-1,13.80,0,-6,13.81,0,-2,ARL,0
2025-07-17T15:42:17.580008869Z,2025-07-17T15:42:17.579843331Z,10,2,1108,A,A,10,14.810000000,100,299926849,165538,251595576,13.31,10,1,13.28,11,2,13.14,1,1,13.13,100,1,13.11,100,1,13.10,100,1,13.04,2,1,12.99,100,1,12.73,100,1,12.67,100,1,13.40,0,-10,13.71,0,-1,13.73,0,-1,13.74,0,-1,13.76,0,-2,13.77,0,-2,13.78,0,-3,13.79,0,-1,13.80,0,-6,13.81,0,-2,ARL,0
2025-07-17T15:42:17.580035793Z,2025-07-17T15:42:17.579870309Z,10,2,1108,C,A,10,16.080000000,100,296480097,165484,251595577,13.31,10,1,13.28,11,2,13.14,1,1,13.13,100,1,13.11,100,1,13.10,100,1,13.04,2,1,12.99,100,1,12.73,100,1,12.67,100,1,13.40,0,-10,13.71,0,-1,13.73,0,-1,13.74,0,-1,13.76,0,-2,13.77,0,-2,13.78,0,-3,13.79,0,-1,13.80,0,-6,13.81,0,-2,ARL,0
2025-07-17T15:42:17.580035793Z,2025-07-17T15:42:17.579870309Z,10,2,1108,A,A,10,15.920000000,100,299926853,165484,251595577,13.31,10,1,13.28,11,2,13.14,1,1,13.13,100,1,13.11,100,1,13.10,100,1,13.04,2,1,12.99,100,1,12.73,100,1,12.67,100,1,13.40,0,-10,13.71,0,-1,13.73,0,-1,13.74,0,-1,13.76,0,-2,13.77,0,-2,13.78,0,-3,13.79,0,-1,13.80,0,-6,13.81,0,-2,ARL,0
2025-07-17T15:42:17.580061097Z,2025-07-17T15:42:17.579895610Z,10,2,1108,C,A,10,14.960000000,100,296482509,165487,251595578,13.31,10,1,13.28,11,2,13.14,1,1,13.13,100,1,13.11,100,1,13.10,100,1,13.04,2,1,12.99,100,1,12.73,100,1,12.67,100,1,13.40,0,-10,13.71,0,-1,13.73,0,-1,13.74,0,-1,13.76,0,-2,13.77,0,-2,13.78,0,-3,13.79,0,-1,13.80,0,-6,13.81,0,-2,ARL,0
2025-07-17T15:42:17.580061097Z,2025-07-17T15:42:17.579895610Z,10,2,1108,A,A,10,14.810000000,100,299926857,165487,251595578,13.31,10,1,13.28,11,2,13.14,1,1,13.13,100,1,13.11,100,1,13.10,100,1,13.04,2,1,12.99,100,1,12.73,100,1,12.67,100,1,13.40,0,-10,13.71,0,-1,13.73,0,-1,13.74,0,-1,13.76,0,-2,13.77,0,-2,13.78,0,-3,13.79,0,-1,13.80,0,-6,13.81,0,-2,ARL,0
2025-07-17T15:42:17.580093535Z,2025-07-17T15:42:17.579928136Z,10,2,1108,C,A,10,17.760000000,100,296479893,165399,251595580,13.31,10,1,13.28,11,2,13.14,1,1,13.13,100,1,13.11,100,1,13.10,100,1,13.04,2,1,12.99,100,1,12.73,100,1,12.67,100,1,13.40,0,-10,13.71,0,-1,13.73,0,-1,13.74,0,-1,13.76,0,-2,13.77,0,-2,13.78,0,-3,13.79,0,-1,13.80,0,-6,13.81,0,-2,ARL,0
2025-07-17T15:42:17.580093535Z,2025-07-17T15:42:17.579928136Z,10,2,1108,A,A,10,17.580000000,100,299926861,165399,251595580,13.31,10,1,13.28,11,2,13.14,1,1,13.13,100,1,13.11,100,1,13.10,100,1,13.04,2,1,12.99,100,1,12.73,100,1,12.67,100,1,13.40,0,-10,13.71,0,-1,13.73,0,-1,13.74,0,-1,13.76,0,-2,13.77,0,-2,13.78,0,-3,13.79,0,-1,13.80,0,-6,13.81,0,-2,ARL,0
2025-07-17T15:42:17.589263550Z,2025-07-17T15:42:17.589098227Z,10,2,1108,C,A,10,14.190000000,100,299690593,165323,251595691,13.31,10,1,13.28,11,2,13.14,1,1,13.13,100,1,13.11,100,1,13.10,100,1,13.04,2,1,12.99,100,1,12.73,100,1,12.67,100,1,13.40,0,-10,13.71,0,-1,13.73,0,-1,13.74,0,-1,13.76,0,-2,13.77,0,-2,13.78,0,-3,13.79,0,-1,13.80,0,-6,13.81,0,-2,ARL,0
2025-07-17T15:42:17.589316911Z,2025-07-17T15:42:17.589151325Z,10,2,1108,A,A,10,14.120000000,100,299926965,165586,251595692,13.31,10,1,13.28,11,2,13.14,1,1,13.13,100,1,13.11,100,1,13.10,100,1,13.04,2,1,12.99,100,1,12.73,100,1,12.67,100,1,13.40,0,-10,13.71,0,-1,13.73,0,-1,13.74,0,-1,13.76,0,-2,13.77,0,-2,13.78,0,-3,13.79,0,-1,13.80,0,-6,13.81,0,-2,ARL,0
2025-07-17T15:42:18.398220000Z,2025-07-17T15:42:18.398054465Z,10,2,1108,C,A,10,14.880000000,100,296679277,165535,251612478,13.31,10,1,13.28,11,2,13.14,1,1,13.13,100,1,13.11,100,1,13.10,100,1,13.04,2,1,12.99,100,1,12.73,100,1,12.67,100,1,13.40,0,-10,13.71,0,-1,13.73,0,-1,13.74,0,-1,13.76,0,-2,13.77,0,-2,13.78,0,-3,13.79,0,-1,13.80,0,-6,13.81,0,-2,ARL,0
2025-07-17T15:42:18.398220000Z,2025-07-17T15:42:18.398054465Z,10,2,1108,A,A,10,14.730000000,100,299945073,165535,251612478,13.31,10,1,13.28,11,2,13.14,1,1,13.13,100,1,13.11,100,1,13.10,100,1,13.04,2,1,12.99,100,1,12.73,100,1,12.67,100,1,13.40,0,-10,13.71,0,-1,13.73,0,-1,13.74,0,-1,13.76,0,-2,13.77,0,-2,13.78,0,-3,13.79,0,-1,13.80,0,-6,13.81,0,-2,ARL,0
2025-07-17T15:42:21.517871714Z,2025-07-17T15:42:21.517706139Z,10,2,1108,C,A,10,13.900000000,15,299689753,165575,251668179,13.31,10,1,13.28,11,2,13.14,1,1,13.13,100,1,13.11,100,1,13.10,100,1,13.04,2,1,12.99,100,1,12.73,100,1,12.67,100,1,13.40,0,-10,13.71,0,-1,13.73,0,-1,13.74,0,-1,13.76,0,-2,13.77,0,-2,13.78,0,-3,13.79,0,-1,13.80,0,-6,13.81,0,-2,ARL,0
2025-07-17T15:42:22.522744242Z,2025-07-17T15:42:22.522578675Z,10,2,1108,A,A,10,13.790000000,15,300042293,165567,251690950,13.31,10,1,13.28,11,2,13.14,1,1,13.13,100,1,13.11,100,1,13.10,100,1,13.04,2,1,12.99,100,1,12.73,100,1,12.67,100,1,13.40,0,-10,13.71,0,-1,13.73,0,-1,13.74,0,-1,13.76,0,-2,13.77,0,-2,13.78,0,-3,13.79,0,-1,13.80,0,-6,13.81,0,-2,ARL,0
2025-07-17T15:42:22.533681479Z,2025-07-17T15:42:22.533515955Z,10,2,1108,A,A,10,13.820000000,100,300042385,165524,251691033,13.31,10,1,13.28,11,2,13.14,1,1,13.13,100,1,13.11,100,1,13.10,100,1,13.04,2,1,12.99,100,1,12.73,100,1,12.67,100,1,13.40,0,-10,13.71,0,-1,13.73,0,-1,13.74,0,-1,13.76,0,-2,13.77,0,-2,13.78,0,-3,13.79,0,-1,13.80,0,-6,13.81,0,-2,ARL,0
2025-07-17T15:42:23.490247121Z,2025-07-17T15:42:23.490079821Z,10,2,1108,C,A,10,13.840000000,100,299926781,167300,251710173,13.31,10,1,13.28,11,2,13.14,1,1,13.13,100,1,13.11,100,1,13.10,100,1,13.04,2,1,12.99,100,1,12.73,100,1,12.67,100,1,13.40,0,-10,13.71,0,-1,13.73,0,-1,13.74,0,-1,13.76,0,-2,13.77,0,-2,13.78,0,-3,13.79,0,-1,13.80,0,-6,13.81,0,-2,ARL,0
2025-07-17T15:42:23.490247121Z,2025-07-17T15:42:23.490079821Z,10,2,1108,A,A,10,13.800000000,100,300061581,167300,251710173,13.31,10,1,13.28,11,2,13.14,1,1,13.13,100,1,13.11,100,1,13.10,100,1,13.04,2,1,12.99,100,1,12.73,100,1,12.67,100,1,13.40,0,-10,13.71,0,-1,13.73,0,-1,13.74,0,-1,13.76,0,-2,13.77,0,-2,13.78,0,-3,13.79,0,-1,13.80,0,-6,13.81,0,-2,ARL,0
2025-07-17T15:42:23.491451368Z,2025-07-17T15:42:23.491285065Z,10,2,1108,C,A,10,14.910000000,100,299926801,166303,251710647,13.31,10,1,13.28,11,2,13.14,1,1,13.13,100,1,13.11,100,1,13.10,100,1,13.04,2,1,12.99,100,1,12.73,100,1,12.67,100,1,13.40,0,-10,13.71,0,-1,13.73,0,-1,13.74,0,-1,13.76,0,-2,13.77,0,-2,13.78,0,-3,13.79,0,-1,13.80,0,-7,13.81,0,-2,ARL,0
2025-07-17T15:42:23.491451368Z,2025-07-17T15:42:23.491285065Z,10,2,1108,A,A,10,14.870000000,100,300061989,166303,251710647,13.31,10,1,13.28,11,2,13.14,1,1,13.13,100,1,13.11,100,1,13.10,100,1,13.04,2,1,12.99,100,1,12.73,100,1,12.67,100,1,13.40,0,-10,13.71,0,-1,13.73,0,-1,13.74,0,-1,13.76,0,-2,13.77,0,-2,13.78,0,-3,13.79,0,-1,13.80,0,-7,13.81,0,-2,ARL,0
2025-07-17T15:42:23.589065154Z,2025-07-17T15:42:23.588899941Z,10,2,1108,C,A,10,13.790000000,15,300042293,165213,251718746,13.31,10,1,13.28,11,2,13.14,1,1,13.13,100,1,13.11,100,1,13.10,100,1,13.04,2,1,12.99,100,1,12.73,100,1,12.67,100,1,13.40,0,-10,13.71,0,-1,13.73,0,-1,13.74,0,-1,13.76,0,-2,13.77,0,-2,13.78,0,-3,13.79,0,-1,13.80,0,-7,13.81,0,-2,ARL,0
2025-07-17T15:42:23.589220778Z,2025-07-17T15:42:23.589055082Z,10,2,1108,C,A,10,13.830000000,15,299923773,165696,251718767,13.31,10,1,13.28,11,2,13.14,1,1,13.13,100,1,13.11,100,1,13.10,100,1,13.04,2,1,12.99,100,1,12.73,100,1,12.67,100,1,13.40,0,-10,13.71,0,-1,13.73,0,-1,13.74,0,-1,13.76,0,-2,13.77,0,-2,13.78,0,-3,13.79,0,-1,13.80,0,-7,13.81,0,-2,ARL,0
2025-07-17T15:42:34.003710081Z,2025-07-17T15:42:34.003544527Z,10,2,1108,C,A,10,13.800000000,100,300061581,165554,251901273,13.31,10,1,13.28,11,2,13.14,1,1,13.13,100,1,13.11,100,1,13.10,100,1,13.04,2,1,12.99,100,1,12.73,100,1,12.67,100,1,13.40,0,-10,13.71,0,-1,13.73,0,-1,13.74,0,-1,13.76,0,-2,13.77,0,-2,13.78,0,-3,13.79,0,-1,13.80,0,-7,13.81,0,-2,ARL,0
2025-07-17T15:42:34.003949340Z,2025-07-17T15:42:34.003783950Z,10,2,1108,C,A,10,13.820000000,100,300042385,165390,251901275,13.31,10,1,13.28,11,2,13.14,1,1,13.13,100,1,13.11,100,1,13.10,100,1,13.04,2,1,12.99,100,1,12.73,100,1,12.67,100,1,13.40,0,-10,13.71,0,-1,13.73,0,-1,13.74,0,-1,13.76,0,-2,13.77,0,-2,13.78,0,-3,13.79,0,-1,13.80,0,-7,13.81,0,-2,ARL,0
2025-07-17T15:42:34.004225180Z,2025-07-17T15:42:34.004059450Z,10,2,1108,C,A,10,14.730000000,100,299945073,165730,251901280,13.31,10,1,13.28,11,2,13.14,1,1,13.13,100,1,13.11,100,1,13.10,100,1,13.04,2,1,12.99,100,1,12.73,100,1,12.67,100,1,13.40,0,-10,13.71,0,-1,13.73,0,-1,13.74,0,-1,13.76,0,-2,13.77,0,-2,13.78,0,-3,13.79,0,-1,13.80,0,-7,13.81,0,-2,ARL,0
2025-07-17T15:42:34.004225180Z,2025-07-17T15:42:34.004059450Z,10,2,1108,A,A,10,14.880000000,100,300280745,165730,251901280,13.31,10,1,13.28,11,2,13.14,1,1,13.13,100,1,13.11,100,1,13.10,100,1,13.04,2,1,12.99,100,1,12.73,100,1,12.67,100,1,13.40,0,-10,13.71,0,-1,13.73,0,-1,13.74,0,-1,13.76,0,-2,13.77,0,-2,13.78,0,-3,13.79,0,-1,13.80,0,-7,13.81,0,-2,ARL,0
2025-07-17T15:42:34.004671652Z,2025-07-17T15:42:34.004506043Z,10,2,1108,C,A,10,14.870000000,100,300061989,165609,251901285,13.31,10,1,13.28,11,2,13.14,1,1,13.13,100,1,13.11,100,1,13.10,100,1,13.04,2,1,12.99,100,1,12.73,100,1,12.67,100,1,13.40,0,-10,13.71,0,-1,13.73,0,-1,13.74,0,-1,13.76,0,-2,13.77,0,-2,13.78,0,-3,13.79,0,-1,13.80,0,-7,13.81,0,-2,ARL,0
2025-07-17T15:42:34.004671652Z,2025-07-17T15:42:34.004506043Z,10,2,1108,A,A,10,15.060000000,100,300280757,165609,251901285,13.31,10,1,13.28,11,2,13.14,1,1,13.13,100,1,13.11,100,1,13.10,100,1,13.04,2,1,12.99,100,1,12.73,100,1,12.67,100,1,13.40,0,-10,13.71,0,-1,13.73,0,-1,13.74,0,-1,13.76,0,-2,13.77,0,-2,13.78,0,-3,13.79,0,-1,13.80,0,-7,13.81,0,-2,ARL,0
2025-07-17T15:42:34.004677786Z,2025-07-17T15:42:34.004512153Z,10,2,1108,C,A,10,14.760000000,100,299903169,165633,251901286,13.31,10,1,13.28,11,2,13.14,1,1,13.13,100,1,13.11,100,1,13.10,100,1,13.04,2,1,12.99,100,1,12.73,100,1,12.67,100,1,13.40,0,-10,13.71,0,-1,13.73,0,-1,13.74,0,-1,13.76,0,-2,13.77,0,-2,13.78,0,-3,13.79,0,-1,13.80,0,-7,13.81,0,-2,ARL,0
2025-07-17T15:42:34.004677786Z,2025-07-17T15:42:34.004512153Z,10,2,1108,A,A,10,14.880000000,100,300280761,165633,251901286,13.31,10,1,13.28,11,2,13.14,1,1,13.13,100,1,13.11,100,1,13.10,100,1,13.04,2,1,12.99,100,1,12.73,100,1,12.67,100,1,13.40,0,-10,13.71,0,-1,13.73,0,-1,13.74,0,-1,13.76,0,-2,13.77,0,-2,13.78,0,-3,13.79,0,-1,13.80,0,-7,13.81,0,-2,ARL,0
2025-07-17T15:42:34.005574760Z,2025-07-17T15:42:34.005409139Z,10,2,1108,C,A,10,15.920000000,100,299926853,165621,251901302,13.31,10,1,13.28,11,2,13.14,1,1,13.13,100,1,13.11,100,1,13.10,100,1,13.04,2,1,12.99,100,1,12.73,100,1,12.67,100,1,13.40,0,-10,13.71,0,-1,13.73,0,-1,13.74,0,-1,13.76,0,-2,13.77,0,-2,13.78,0,-3,13.79,0,-1,13.80,0,-7,13.81,0,-2,ARL,0
2025-07-17T15:42:34.005574760Z,2025-07-17T15:42:34.005409139Z,10,2,1108,A,A,10,16.080000000,100,300280773,165621,251901302,13.31,10,1,13.28,11,2,13.14,1,1,13.13,100,1,13.11,100,1,13.10,100,1,13.04,2,1,12.99,100,1,12.73,100,1,12.67,100,1,13.40,0,-10,13.71,0,-1,13.73,0,-1,13.74,0,-1,13.76,0,-2,13.77,0,-2,13.78,0,-3,13.79,0,-1,13.80,0,-7,13.81,0,-2,ARL,0
2025-07-17T15:42:34.005832926Z,2025-07-17T15:42:34.005667449Z,10,2,1108,C,A,10,14.810000000,100,299926849,165477,251901305,13.31,10,1,13.28,11,2,13.14,1,1,13.13,100,1,13.11,100,1,13.10,100,1,13.04,2,1,12.99,100,1,12.73,100,1,12.67,100,1,13.40,0,-10,13.71,0,-1,13.73,0,-1,13.74,0,-1,13.76,0,-2,13.77,0,-2,13.78,0,-3,13.79,0,-1,13.80,0,-7,13.81,0,-2,ARL,0
2025-07-17T15:42:34.005832926Z,2025-07-17T15:42:34.005667449Z,10,2,1108,A,A,10,14.960000000,100,300280777,165477,251901305,13.31,10,1,13.28,11,2,13.14,1,1,13.13,100,1,13.11,100,1,13.10,100,1,13.04,2,1,12.99,100,1,12.73,100,1,12.67,100,1,13.40,0,-10,13.71,0,-1,13.73,0,-1,13.74,0,-1,13.76,0,-2,13.77,0,-2,13.78,0,-3,13.79,0,-1,13.80,0,-7,13.81,0,-2,ARL,0
2025-07-17T15:42:34.006831024Z,2025-07-17T15:42:34.006665512Z,10,2,1108,C,A,10,17.580000000,100,299926861,165512,251901319,13.31,10,1,13.28,11,2,13.14,1,1,13.13,100,1,13.11,100,1,13.10,100,1,13.04,2,1,12.99,100,1,12.73,100,1,12.67,100,1,13.40,0,-10,13.71,0,-1,13.73,0,-1,13.74,0,-1,13.76,0,-2,13.77,0,-2,13.78,0,-3,13.79,0,-1,13.80,0,-7,13.81,0,-2,ARL,0
2025-07-17T15:42:34.006831024Z,2025-07-17T15:42:34.006665512Z,10,2,1108,A,A,10,17.760000000,100,300280797,165512,251901319,13.31,10,1,13.28,11,2,13.14,1,1,13.13,100,1,13.11,100,1,13.10,100,1,13.04,2,1,12.99,100,1,12.73,100,1,12.67,100,1,13.40,0,-10,13.71,0,-1,13.73,0,-1,13.74,0,-1,13.76,0,-2,13.77,0,-2,13.78,0,-3,13.79,0,-1,13.80,0,-7,13.81,0,-2,ARL,0
2025-07-17T15:42:34.007908678Z,2025-07-17T15:42:34.007743383Z,10,2,1108,C,A,10,14.640000000,100,299926813,165295,251901330,13.31,10,1,13.28,11,2,13.14,1,1,13.13,100,1,13.11,100,1,13.10,100,1,13.04,2,1,12.99,100,1,12.73,100,1,12.67,100,1,13.40,0,-10,13.71,0,-1,13.73,0,-1,13.74,0,-1,13.76,0,-2,13.77,0,-2,13.78,0,-3,13.79,0,-1,13.80,0,-7,13.81,0,-2,ARL,0
2025-07-17T15:42:34.008072663Z,2025-07-17T15:42:34.007907269Z,10,2,1108,A,A,10,14.780000000,100,300280825,165394,251901331,13.31,10,1,13.28,11,2,13.14,1,1,13.13,100,1,13.11,100,1,13.10,100,1,13.04,2,1,12.99,100,1,12.73,100,1,12.67,100,1,13.40,0,-10,13.71,0,-1,13.73,0,-1,13.74,0,-1,13.76,0,-2,13.77,0,-2,13.78,0,-3,13.79,0,-1,13.80,0,-7,13.81,0,-2,ARL,0
2025-07-17T15:42:34.010196831Z,2025-07-17T15:42:34.010031518Z,10,2,1108,C,A,10,14.120000000,100,299926965,165313,251901352,13.31,10,1,13.28,11,2,13.14,1,1,13.13,100,1,13.11,100,1,13.10,100,1,13.04,2,1,12.99,100,1,12.73,100,1,12.67,100,1,13.40,0,-10,13.71,0,-1,13.73,0,-1,13.74,0,-1,13.76,0,-2,13.77,0,-2,13.78,0,-3,13.79,0,-1,13.80,0,-7,13.81,0,-2,ARL,0
2025-07-17T15:42:34.010248842Z,2025-07-17T15:42:34.010083409Z,10,2,1108,A,A,10,14.260000000,100,300280857,165433,251901353,13.31,10,1,13.28,11,2,13.14,1,1,13.13,100,1,13.11,100,1,13.10,100,1,13.04,2,1,12.99,100,1,12.73,100,1,12.67,100,1,13.40,0,-10,13.71,0,-1,13.73,0,-1,13.74,0,-1,13.76,0,-2,13.77,0,-2,13.78,0,-3,13.79,0,-1,13.80,0,-7,13.81,0,-2,ARL,0
2025-07-17T15:42:34.010572370Z,2025-07-17T15:42:34.010406771Z,10,2,1108,C,A,10,14.810000000,100,299926857,165599,251901355,13.31,10,1,13.28,11,2,13.14,1,1,13.13,100,1,13.11,100,1,13.10,100,1,13.04,2,1,12.99,100,1,12.73,100,1,12.67,100,1,13.40,0,-10,13.71,0,-1,13.73,0,-1,13.74,0,-1,13.76,0,-2,13.77,0,-2,13.78,0,-3,13.79,0,-1,13.80,0,-7,13.81,0,-2,ARL,0
2025-07-17T15:42:34.010572370Z,2025-07-17T15:42:34.010406771Z,10,2,1108,A,A,10,14.960000000,100,300280873,165599,251901355,13.31,10,1,13.28,11,2,13.14,1,1,13.13,100,1,13.11,100,1,13.10,100,1,13.04,2,1,12.99,100,1,12.73,100,1,12.67,100,1,13.40,0,-10,13.71,0,-1,13.73,0,-1,13.74,0,-1,13.76,0,-2,13.77,0,-2,13.78,0,-3,13.79,0,-1,13.80,0,-7,13.81,0,-2,ARL,0
2025-07-17T15:42:34.952098027Z,2025-07-17T15:42:34.951932909Z,10,2,1108,A,A,10,14.080000000,100,300294885,165118,251912292,13.31,10,1,13.28,11,2,13.14,1,1,13.13,100,1,13.11,100,1,13.10,100,1,13.04,2,1,12.99,100,1,12.73,100,1,12.67,100,1,13.40,0,-10,13.71,0,-1,13.73,0,-1,13.74,0,-1,13.76,0,-2,13.77,0,-2,13.78,0,-3,13.79,0,-1,13.80,0,-7,13.81,0,-2,ARL,0
2025-07-17T15:43:21.513838949Z,2025-07-17T15:43:21.513673603Z,10,2,1108,A,A,10,13.920000000,15,301218889,165346,252622568,13.31,10,1,13.28,11,2,13.14,1,1,13.13,100,1,13.11,100,1,13.10,100,1,13.04,2,1,12.99,100,1,12.73,100,1,12.67,100,1,13.40,0,-10,13.71,0,-1,13.73,0,-1,13.74,0,-1,13.76,0,-2,13.77,0,-2,13.78,0,-3,13.79,0,-1,13.80,0,-7,13.81,0,-2,ARL,0
2025-07-17T15:43:24.878236760Z,2025-07-17T15:43:24.878071152Z,10,2,1108,C,A,10,14.080000000,100,300294885,165608,252681819,13.31,10,1,13.28,11,2,13.14,1,1,13.13,100,1,13.11,100,1,13.10,100,1,13.04,2,1,12.99,100,1,12.73,100,1,12.67,100,1,13.40,0,-10,13.71,0,-1,13.73,0,-1,13.74,0,-1,13.76,0,-2,13.77,0,-2,13.78,0,-3,13.79,0,-1,13.80,0,-7,13.81,0,-2,ARL,0
2025-07-17T15:43:24.878236760Z,2025-07-17T15:43:24.878071152Z,10,2,1108,A,A,10,13.930000000,100,301295841,165608,252681819,13.31,10,1,13.28,11,2,13.14,1,1,13.13,100,1,13.11,100,1,13.10,100,1,13.04,2,1,12.99,100,1,12.73,100,1,12.67,100,1,13.40,0,-10,13.71,0,-1,13.73,0,-1,13.74,0,-1,13.76,0,-2,13.77,0,-2,13.78,0,-3,13.79,0,-1,13.80,0,-7,13.81,0,-2,ARL,0
2025-07-17T15:43:24.879003443Z,2025-07-17T15:43:24.878837670Z,10,2,1108,C,A,10,15.060000000,100,300280757,165773,252681832,13.31,10,1,13.28,11,2,13.14,1,1,13.13,100,1,13.11,100,1,13.10,100,1,13.04,2,1,12.99,100,1,12.73,100,1,12.67,100,1,13.40,0,-10,13.71,0,-1,13.73,0,-1,13.74,0,-1,13.76,0,-2,13.77,0,-2,13.78,0,-3,13.79,0,-1,13.80,0,-7,13.81,0,-2,ARL,0
2025-07-17T15:43:24.879003443Z,2025-07-17T15:43:24.878837670Z,10,2,1108,A,A,10,15.010000000,100,301295873,165773,252681832,13.31,10,1,13.28,11,2,13.14,1,1,13.13,100,1,13.11,100,1,13.10,100,1,13.04,2,1,12.99,100,1,12.73,100,1,12.67,100,1,13.40,0,-10,13.71,0,-1,13.73,0,-1,13.74,0,-1,13.76,0,-2,13.77,0,-2,13.78,0,-3,13.79,0,-1,13.80,0,-7,13.81,0,-2,ARL,0
2025-07-17T15:43:32.780372412Z,2025-07-17T15:43:32.780206927Z,10,2,1108,A,A,10,13.880000000,15,301451057,165485,252800884,13.31,10,1,13.28,11,2,13.14,1,1,13.13,100,1,13.11,100,1,13.10,100,1,13.04,2,1,12.99,100,1,12.73,100,1,12.67,100,1,13.40,0,-10,13.71,0,-1,13.73,0,-1,13.74,0,-1,13.76,0,-2,13.77,0,-2,13.78,0,-3,13.79,0,-1,13.80,0,-7,13.81,0,-2,ARL,0
2025-07-17T15:43:32.780639619Z,2025-07-17T15:43:32.780474141Z,10,2,1108,C,A,10,13.930000000,100,301295841,165478,252800887,13.31,10,1,13.28,11,2,13.14,1,1,13.13,100,1,13.11,100,1,13.10,100,1,13.04,2,1,12.99,100,1,12.73,100,1,12.67,100,1,13.40,0,-10,13.71,0,-1,13.73,0,-1,13.74,0,-1,13.76,0,-2,13.77,0,-2,13.78,0,-3,13.79,0,-1,13.80,0,-7,13.81,0,-2,ARL,0
2025-07-17T15:43:32.780639619Z,2025-07-17T15:43:32.780474141Z,10,2,1108,A,A,10,13.890000000,100,301451061,165478,252800887,13.31,10,1,13.28,11,2,13.14,1,1,13.13,100,1,13.11,100,1,13.10,100,1,13.04,2,1,12.99,100,1,12.73,100,1,12.67,100,1,13.40,0,-10,13.71,0,-1,13.73,0,-1,13.74,0,-1,13.76,0,-2,13.77,0,-2,13.78,0,-3,13.79,0,-1,13.80,0,-7,13.81,0,-2,ARL,0
2025-07-17T15:43:32.781382162Z,2025-07-17T15:43:32.781216589Z,10,2,1108,C,A,10,15.010000000,100,301295873,165573,252800892,13.31,10,1,13.28,11,2,13.14,1,1,13.13,100,1,13.11,100,1,13.10,100,1,13.04,2,1,12.99,100,1,12.73,100,1,12.67,100,1,13.40,0,-10,13.71,0,-1,13.73,0,-1,13.74,0,-1,13.76,0,-2,13.77,0,-2,13.78,0,-3,13.79,0,-1,13.80,0,-7,13.81,0,-2,ARL,0
2025-07-17T15:43:32.781382162Z,2025-07-17T15:43:32.781216589Z,10,2,1108,A,A,10,14.970000000,100,301451077,165573,252800892,13.31,10,1,13.28,11,2,13.14,1,1,13.13,100,1,13.11,100,1,13.10,100,1,13.04,2,1,12.99,100,1,12.73,100,1,12.67,100,1,13.40,0,-10,13.71,0,-1,13.73,0,-1,13.74,0,-1,13.76,0,-2,13.77,0,-2,13.78,0,-3,13.79,0,-1,13.80,0,-7,13.81,0,-2,ARL,0
2025-07-17T15:43:32.792119698Z,2025-07-17T15:43:32.791954053Z,10,2,1108,C,A,10,14.260000000,100,300280857,165645,252801681,13.31,10,1,13.28,11,2,13.14,1,1,13.13,100,1,13.11,100,1,13.10,100,1,13.04,2,1,12.99,100,1,12.73,100,1,12.67,100,1,13.40,0,-10,13.71,0,-1,13.73,0,-1,13.74,0,-1,13.76,0,-2,13.77,0,-2,13.78,0,-3,13.79,0,-1,13.80,0,-7,13.81,0,-2,ARL,0
2025-07-17T15:43:32.792174617Z,2025-07-17T15:43:32.792008881Z,10,2,1108,A,A,10,14.170000000,100,301452785,165736,252801689,13.31,10,1,13.28,11,2,13.14,1,1,13.13,100,1,13.11,100,1,13.10,100,1,13.04,2,1,12.99,100,1,12.73,100,1,12.67,100,1,13.40,0,-10,13.71,0,-1,13.73,0,-1,13.74,0,-1,13.76,0,-2,13.77,0,-2,13.78,0,-3,13.79,0,-1,13.80,0,-7,13.81,0,-2,ARL,0
2025-07-17T15:43:44.004832641Z,2025-07-17T15:43:44.004667259Z,10,2,1108,C,A,10,13.920000000,15,301218889,165382,252977583,13.31,10,1,13.28,11,2,13.14,1,1,13.13,100,1,13.11,100,1,13.10,100,1,13.04,2,1,12.99,100,1,12.73,100,1,12.67,100,1,13.40,0,-10,13.71,0,-1,13.73,0,-1,13.74,0,-1,13.76,0,-2,13.77,0,-2,13.78,0,-3,13.79,0,-1,13.80,0,-7,13.81,0,-2,ARL,0
2025-07-17T15:43:44.005191111Z,2025-07-17T15:43:44.005025587Z,10,2,1108,C,A,10,14.880000000,100,300280761,165524,252977592,13.31,10,1,13.28,11,2,13.14,1,1,13.13,100,1,13.11,100,1,13.10,100,1,13.04,2,1,12.99,100,1,12.73,100,1,12.67,100,1,13.40,0,-10,13.71,0,-1,13.73,0,-1,13.74,0,-1,13.76,0,-2,13.77,0,-2,13.78,0,-3,13.79,0,-1,13.80,0,-7,13.81,0,-2,ARL,0
2025-07-17T15:43:44.005191111Z,2025-07-17T15:43:44.005025587Z,10,2,1108,A,A,10,14.770000000,100,301671709,165524,252977592,13.31,10,1,13.28,11,2,13.14,1,1,13.13,100,1,13.11,100,1,13.10,100,1,13.04,2,1,12.99,100,1,12.73,100,1,12.67,100,1,13.40,0,-10,13.71,0,-1,13.73,0,-1,13.74,0,-1,13.76,0,-2,13.77,0,-2,13.78,0,-3,13.79,0,-1,13.80,0,-7,13.81,0,-2,ARL,0
2025-07-17T15:43:44.005313071Z,2025-07-17T15:43:44.005147707Z,10,2,1108,C,A,10,14.880000000,100,300280745,165364,252977595,13.31,10,1,13.28,11,2,13.14,1,1,13.13,100,1,13.11,100,1,13.10,100,1,13.04,2,1,12.99,100,1,12.73,100,1,12.67,100,1,13.40,0,-10,13.71,0,-1,13.73,0,-1,13.74,0,-1,13.76,0,-2,13.77,0,-2,13.78,0,-3,13.79,0,-1,13.80,0,-7,13.81,0,-2,ARL,0
2025-07-17T15:43:44.005313071Z,2025-07-17T15:43:44.005147707Z,10,2,1108,A,A,10,14.770000000,100,301671713,165364,252977595,13.31,10,1,13.28,11,2,13.14,1,1,13.13,100,1,13.11,100,1,13.10,100,1,13.04,2,1,12.99,100,1,12.73,100,1,12.67,100,1,13.40,0,-10,13.71,0,-1,13.73,0,-1,13.74,0,-1,13.76,0,-2,13.77,0,-2,13.78,0,-3,13.79,0,-1,13.80,0,-7,13.81,0,-2,ARL,0
2025-07-17T15:43:48.787497664Z,2025-07-17T15:43:48.787332399Z,10,2,1108,A,A,10,13.830000000,15,301746941,165265,253027890,13.31,10,1,13.28,11,2,13.14,1,1,13.13,100,1,13.11,100,1,13.10,100,1,13.04,2,1,12.99,100,1,12.73,100,1,12.67,100,1,13.40,0,-10,13.71,0,-1,13.73,0,-1,13.74,0,-1,13.76,0,-2,13.77,0,-2,13.78,0,-3,13.79,0,-1,13.80,0,-7,13.81,0,-2,ARL,0
2025-07-17T15:43:48.787766907Z,2025-07-17T15:43:48.787601640Z,10,2,1108,C,A,10,13.890000000,100,301451061,165267,253027924,13.31,10,1,13.28,11,2,13.14,1,1,13.13,100,1,13.11,100,1,13.10,100,1,13.04,2,1,12.99,100,1,12.73,100,1,12.67,100,1,13.40,0,-10,13.71,0,-1,13.73,0,-1,13.74,0,-1,13.76,0,-2,13.77,0,-2,13.78,0,-3,13.79,0,-1,13.80,0,-7,13.81,0,-2,ARL,0
2025-07-17T15:43:48.787766907Z,2025-07-17T15:43:48.787601640Z,10,2,1108,A,A,10,13.840000000,100,301746949,165267,253027924,13.31,10,1,13.28,11,2,13.14,1,1,13.13,100,1,13.11,100,1,13.10,100,1,13.04,2,1,12.99,100,1,12.73,100,1,12.67,100,1,13.40,0,-10,13.71,0,-1,13.73,0,-1,13.74,0,-1,13.76,0,-2,13.77,0,-2,13.78,0,-3,13.79,0,-1,13.80,0,-7,13.81,0,-2,ARL,0
2025-07-17T15:43:48.788512022Z,2025-07-17T15:43:48.788345787Z,10,2,1108,C,A,10,14.970000000,100,301451077,166235,253027959,13.31,10,1,13.28,11,2,13.14,1,1,13.13,100,1,13.11,100,1,13.10,100,1,13.04,2,1,12.99,100,1,12.73,100,1,12.67,100,1,13.40,0,-10,13.71,0,-1,13.73,0,-1,13.74,0,-1,13.76,0,-2,13.77,0,-2,13.78,0,-3,13.79,0,-1,13.80,0,-7,13.81,0,-2,ARL,0
2025-07-17T15:43:48.788512022Z,2025-07-17T15:43:48.788345787Z,10,2,1108,A,A,10,14.910000000,100,301746969,166235,253027959,13.31,10,1,13.28,11,2,13.14,1,1,13.13,100,1,13.11,100,1,13.10,100,1,13.04,2,1,12.99,100,1,12.73,100,1,12.67,100,1,13.40,0,-10,13.71,0,-1,13.73,0,-1,13.74,0,-1,13.76,0,-2,13.77,0,-2,13.78,0,-3,13.79,0,-1,13.80,0,-7,13.81,0,-2,ARL,0
2025-07-17T15:43:48.790573820Z,2025-07-17T15:43:48.790408191Z,10,2,1108,C,A,10,14.960000000,100,300280777,165629,253028026,13.31,10,1,13.28,11,2,13.14,1,1,13.13,100,1,13.11,100,1,13.10,100,1,13.04,2,1,12.99,100,1,12.73,100,1,12.67,100,1,13.40,0,-10,13.71,0,-1,13.73,0,-1,13.74,0,-1,13.76,0,-2,13.77,0,-2,13.78,0,-3,13.79,0,-1,13.80,0,-7,13.81,0,-2,ARL,0
2025-07-17T15:43:48.790573820Z,2025-07-17T15:43:48.790408191Z,10,2,1108,A,A,10,14.810000000,100,301747001,165629,253028026,13.31,10,1,13.28,11,2,13.14,1,1,13.13,100,1,13.11,100,1,13.10,100,1,13.04,2,1,12.99,100,1,12.73,100,1,12.67,100,1,13.40,0,-10,13.71,0,-1,13.73,0,-1,13.74,0,-1,13.76,0,-2,13.77,0,-2,13.78,0,-3,13.79,0,-1,13.80,0,-7,13.81,0,-2,ARL,0
2025-07-17T15:43:48.790600546Z,2025-07-17T15:43:48.790434947Z,10,2,1108,C,A,10,14.780000000,100,300280825,165599,253028027,13.31,10,1,13.28,11,2,13.14,1,1,13.13,100,1,13.11,100,1,13.10,100,1,13.04,2,1,12.99,100,1,12.73,100,1,12.67,100,1,13.40,0,-10,13.71,0,-1,13.73,0,-1,13.74,0,-1,13.76,0,-2,13.77,0,-2,13.78,0,-3,13.79,0,-1,13.80,0,-7,13.81,0,-2,ARL,0
2025-07-17T15:43:48.790600546Z,2025-07-17T15:43:48.790434947Z,10,2,1108,A,A,10,14.640000000,100,301747005,165599,253028027,13.31,10,1,13.28,11,2,13.14,1,1,13.13,100,1,13.11,100,1,13.10,100,1,13.04,2,1,12.99,100,1,12.73,100,1,12.67,100,1,13.40,0,-10,13.71,0,-1,13.73,0,-1,13.74,0,-1,13.76,0,-2,13.77,0,-2,13.78,0,-3,13.79,0,-1,13.80,0,-7,13.81,0,-2,ARL,0
2025-07-17T15:43:48.800959598Z,2025-07-17T15:43:48.800794196Z,10,2,1108,C,A,10,17.760000000,100,300280797,165402,253028707,13.31,10,1,13.28,11,2,13.14,1,1,13.13,100,1,13.11,100,1,13.10,100,1,13.04,2,1,12.99,100,1,12.73,100,1,12.67,100,1,13.40,0,-10,13.71,0,-1,13.73,0,-1,13.74,0,-1,13.76,0,-2,13.77,0,-2,13.78,0,-3,13.79,0,-1,13.80,0,-7,13.81,0,-2,ARL,0
2025-07-17T15:43:48.800959598Z,2025-07-17T15:43:48.800794196Z,10,2,1108,A,A,10,17.580000000,100,301747261,165402,253028707,13.31,10,1,13.28,11,2,13.14,1,1,13.13,100,1,13.11,100,1,13.10,100,1,13.04,2,1,12.99,100,1,12.73,100,1,12.67,100,1,13.40,0,-10,13.71,0,-1,13.73,0,-1,13.74,0,-1,13.76,0,-2,13.77,0,-2,13.78,0,-3,13.79,0,-1,13.80,0,-7,13.81,0,-2,ARL,0
2025-07-17T15:43:48.806845249Z,2025-07-17T15:43:48.806679708Z,10,2,1108,C,A,10,16.080000000,100,300280773,165541,253028803,13.31,10,1,13.28,11,2,13.14,1,1,13.13,100,1,13.11,100,1,13.10,100,1,13.04,2,1,12.99,100,1,12.73,100,1,12.67,100,1,13.40,0,-10,13.71,0,-1,13.73,0,-1,13.74,0,-1,13.76,0,-2,13.77,0,-2,13.78,0,-3,13.79,0,-1,13.80,0,-7,13.81,0,-2,ARL,0
2025-07-17T15:43:48.806845249Z,2025-07-17T15:43:48.806679708Z,10,2,1108,A,A,10,15.920000000,100,301747301,165541,253028803,13.31,10,1,13.28,11,2,13.14,1,1,13.13,100,1,13.11,100,1,13.10,100,1,13.04,2,1,12.99,100,1,12.73,100,1,12.67,100,1,13.40,0,-10,13.71,0,-1,13.73,0,-1,13.74,0,-1,13.76,0,-2,13.77,0,-2,13.78,0,-3,13.79,0,-1,13.80,0,-7,13.81,0,-2,ARL,0
2025-07-17T15:43:48.852570853Z,2025-07-17T15:43:48.852405047Z,10,2,1108,C,A,10,14.960000000,100,300280873,165806,253029437,13.31,10,1,13.28,11,2,13.14,1,1,13.13,100,1,13.11,100,1,13.10,100,1,13.04,2,1,12.99,100,1,12.73,100,1,12.67,100,1,13.40,0,-10,13.71,0,-1,13.73,0,-1,13.74,0,-1,13.76,0,-2,13.77,0,-2,13.78,0,-3,13.79,0,-1,13.80,0,-7,13.81,0,-2,ARL,0
2025-07-17T15:43:48.852570853Z,2025-07-17T15:43:48.852405047Z,10,2,1108,A,A,10,14.810000000,100,301747957,165806,253029437,13.31,10,1,13.28,11,2,13.14,1,1,13.13,100,1,13.11,100,1,13.10,100,1,13.04,2,1,12.99,100,1,12.73,100,1,12.67,100,1,13.40,0,-10,13.71,0,-1,13.73,0,-1,13.74,0,-1,13.76,0,-2,13.77,0,-2,13.78,0,-3,13.79,0,-1,13.80,0,-7,13.81,0,-2,ARL,0
2025-07-17T15:43:53.123817759Z,2025-07-17T15:43:53.123652480Z,10,2,1108,C,A,10,13.880000000,15,301451057,165279,253100941,13.31,10,1,13.28,11,2,13.14,1,1,13.13,100,1,13.11,100,1,13.10,100,1,13.04,2,1,12.99,100,1,12.73,100,1,12.67,100,1,13.40,0,-10,13.71,0,-1,13.73,0,-1,13.74,0,-1,13.76,0,-2,13.77,0,-2,13.78,0,-3,13.79,0,-1,13.80,0,-7,13.81,0,-2,ARL,0
2025-07-17T15:43:54.126276976Z,2025-07-17T15:43:54.126111293Z,10,2,1108,A,A,10,13.810000000,15,301867541,165683,253121467,13.31,10,1,13.28,11,2,13.14,1,1,13.13,100,1,13.11,100,1,13.10,100,1,13.04,2,1,12.99,100,1,12.73,100,1,12.67,100,1,13.40,0,-10,13.71,0,-1,13.73,0,-1,13.74,0,-1,13.76,0,-2,13.77,0,-2,13.78,0,-3,13.79,0,-1,13.80,0,-7,13.81,0,-2,ARL,0
2025-07-17T15:43:54.998238933Z,2025-07-17T15:43:54.998073317Z,10,2,1108,C,A,10,13.840000000,100,301746949,165616,253137948,13.31,10,1,13.28,11,2,13.14,1,1,13.13,100,1,13.11,100,1,13.10,100,1,13.04,2,1,12.99,100,1,12.73,100,1,12.67,100,1,13.40,0,-10,13.71,0,-1,13.73,0,-1,13.74,0,-1,13.76,0,-2,13.77,0,-2,13.78,0,-3,13.79,0,-1,13.80,0,-7,13.81,0,-3,ARL,0
2025-07-17T15:43:54.998238933Z,2025-07-17T15:43:54.998073317Z,10,2,1108,A,A,10,13.820000000,100,301885353,165616,253137948,13.31,10,1,13.28,11,2,13.14,1,1,13.13,100,1,13.11,100,1,13.10,100,1,13.04,2,1,12.99,100,1,12.73,100,1,12.67,100,1,13.40,0,-10,13.71,0,-1,13.73,0,-1,13.74,0,-1,13.76,0,-2,13.77,0,-2,13.78,0,-3,13.79,0,-1,13.80,0,-7,13.81,0,-3,ARL,0
2025-07-17T15:43:55.019172741Z,2025-07-17T15:43:55.019007300Z,10,2,1108,C,A,10,14.170000000,100,301452785,165441,253138492,13.31,10,1,13.28,11,2,13.14,1,1,13.13,100,1,13.11,100,1,13.10,100,1,13.04,2,1,12.99,100,1,12.73,100,1,12.67,100,1,13.40,0,-10,13.71,0,-1,13.73,0,-1,13.74,0,-1,13.76,0,-2,13.77,0,-2,13.78,0,-3,13.79,0,-1,13.80,0,-7,13.81,0,-3,ARL,0
2025-07-17T15:43:55.019225935Z,2025-07-17T15:43:55.019060515Z,10,2,1108,A,A,10,14.100000000,100,301886057,165420,253138493,13.31,10,1,13.28,11,2,13.14,1,1,13.13,100,1,13.11,100,1,13.10,100,1,13.04,2,1,12.99,100,1,12.73,100,1,12.67,100,1,13.40,0,-10,13.71,0,-1,13.73,0,-1,13.74,0,-1,13.76,0,-2,13.77,0,-2,13.78,0,-3,13.79,0,-1,13.80,0,-7,13.81,0,-3,ARL,0
2025-07-17T15:44:01.698791467Z,2025-07-17T15:44:01.698626200Z,10,2,1108,C,A,10,13.830000000,15,301746941,165267,253246317,13.31,10,1,13.28,11,2,13.14,1,1,13.13,100,1,13.11,100,1,13.10,100,1,13.04,2,1,12.99,100,1,12.73,100,1,12.67,100,1,13.40,0,-10,13.71,0,-1,13.73,0,-1,13.74,0,-1,13.76,0,-2,13.77,0,-2,13.78,0,-3,13.79,0,-1,13.80,0,-7,13.81,0,-3,ARL,0
2025-07-17T15:44:04.014878156Z,2025-07-17T15:44:04.014712730Z,10,2,1108,A,A,10,13.830000000,100,302078553,165426,253292355,13.31,10,1,13.28,11,2,13.14,1,1,13.13,100,1,13.11,100,1,13.10,100,1,13.04,2,1,12.99,100,1,12.73,100,1,12.67,100,1,13.40,0,-10,13.71,0,-1,13.73,0,-1,13.74,0,-1,13.76,0,-2,13.77,0,-2,13.78,0,-3,13.79,0,-1,13.80,0,-7,13.81,0,-3,ARL,0
2025-07-17T15:44:05.055626948Z,2025-07-17T15:44:05.055461574Z,10,2,1108,A,A,10,13.810000000,100,302100649,165374,253307083,13.31,10,1,13.28,11,2,13.14,1,1,13.13,100,1,13.11,100,1,13.10,100,1,13.04,2,1,12.99,100,1,12.73,100,1,12.67,100,1,13.40,0,-10,13.71,0,-1,13.73,0,-1,13.74,0,-1,13.76,0,-2,13.77,0,-2,13.78,0,-3,13.79,0,-1,13.80,0,-7,13.81,0,-3,ARL,0
2025-07-17T15:44:05.062431949Z,2025-07-17T15:44:05.062266845Z,10,2,1108,C,A,10,13.830000000,100,302078553,165104,253307147,13.31,10,1,13.28,11,2,13.14,1,1,13.13,100,1,13.11,100,1,13.10,100,1,13.04,2,1,12.99,100,1,12.73,100,1,12.67,100,1,13.40,0,-10,13.71,0,-1,13.73,0,-1,13.74,0,-1,13.76,0,-2,13.77,0,-2,13.78,0,-3,13.79,0,-1,13.80,0,-7,13.81,0,-4,ARL,0
2025-07-17T15:44:09.389713730Z,2025-07-17T15:44:09.389548394Z,10,2,1108,A,A,10,13.760000000,15,302205249,165336,253384422,13.31,10,1,13.28,11,2,13.14,1,1,13.13,100,1,13.11,100,1,13.10,100,1,13.04,2,1,12.99,100,1,12.73,100,1,12.67,100,1,13.40,0,-10,13.71,0,-1,13.73,0,-1,13.74,0,-1,13.76,0,-2,13.77,0,-2,13.78,0,-3,13.79,0,-1,13.80,0,-7,13.81,0,-4,ARL,0
2025-07-17T15:44:09.390496140Z,2025-07-17T15:44:09.390329935Z,10,2,1108,C,A,10,14.770000000,100,301671709,166205,253384438,13.31,10,1,13.28,11,2,13.14,1,1,13.13,100,1,13.11,100,1,13.10,100,1,13.04,2,1,12.99,100,1,12.73,100,1,12.67,100,1,13.40,0,-10,13.71,0,-1,13.73,0,-1,13.74,0,-1,13.76,0,-3,13.77,0,-2,13.78,0,-3,13.79,0,-1,13.80,0,-7,13.81,0,-4,ARL,0
2025-07-17T15:44:09.390496140Z,2025-07-17T15:44:09.390329935Z,10,2,1108,A,A,10,14.660000000,100,302205289,166205,253384438,13.31,10,1,13.28,11,2,13.14,1,1,13.13,100,1,13.11,100,1,13.10,100,1,13.04,2,1,12.99,100,1,12.73,100,1,12.67,100,1,13.40,0,-10,13.71,0,-1,13.73,0,-1,13.74,0,-1,13.76,0,-3,13.77,0,-2,13.78,0,-3,13.79,0,-1,13.80,0,-7,13.81,0,-4,ARL,0
2025-07-17T15:44:09.391058486Z,2025-07-17T15:44:09.390893172Z,10,2,1108,C,A,10,14.770000000,100,301671713,165314,253384456,13.31,10,1,13.28,11,2,13.14,1,1,13.13,100,1,13.11,100,1,13.10,100,1,13.04,2,1,12.99,100,1,12.73,100,1,12.67,100,1,13.40,0,-10,13.71,0,-1,13.73,0,-1,13.74,0,-1,13.76,0,-3,13.77,0,-2,13.78,0,-3,13.79,0,-1,13.80,0,-7,13.81,0,-4,ARL,0
2025-07-17T15:44:09.391058486Z,2025-07-17T15:44:09.390893172Z,10,2,1108,A,A,10,14.660000000,100,302205309,165314,253384456,13.31,10,1,13.28,11,2,13.14,1,1,13.13,100,1,13.11,100,1,13.10,100,1,13.04,2,1,12.99,100,1,12.73,100,1,12.67,100,1,13.40,0,-10,13.71,0,-1,13.73,0,-1,13.74,0,-1,13.76,0,-3,13.77,0,-2,13.78,0,-3,13.79,0,-1,13.80,0,-7,13.81,0,-4,ARL,0
2025-07-17T15:44:09.395447612Z,2025-07-17T15:44:09.395281780Z,10,2,1108,C,A,10,13.820000000,100,301885353,165832,253384698,13.31,10,1,13.28,11,2,13.14,1,1,13.13,100,1,13.11,100,1,13.10,100,1,13.04,2,1,12.99,100,1,12.73,100,1,12.67,100,1,13.40,0,-10,13.71,0,-1,13.73,0,-1,13.74,0,-1,13.76,0,-3,13.77,0,-2,13.78,0,-3,13.79,0,-1,13.80,0,-7,13.81,0,-4,ARL,0
2025-07-17T15:44:09.395447612Z,2025-07-17T15:44:09.395281780Z,10,2,1108,A,A,10,13.770000000,100,302205493,165832,253384698,13.31,10,1,13.28,11,2,13.14,1,1,13.13,100,1,13.11,100,1,13.10,100,1,13.04,2,1,12.99,100,1,12.73,100,1,12.67,100,1,13.40,0,-10,13.71,0,-1,13.73,0,-1,13.74,0,-1,13.76,0,-3,13.77,0,-2,13.78,0,-3,13.79,0,-1,13.80,0,-7,13.81,0,-4,ARL,0
2025-07-17T15:44:09.396195647Z,2025-07-17T15:44:09.396030225Z,10,2,1108,C,A,10,14.910000000,100,301746969,165422,253384731,13.31,10,1,13.28,11,2,13.14,1,1,13.13,100,1,13.11,100,1,13.10,100,1,13.04,2,1,12.99,100,1,12.73,100,1,12.67,100,1,13.40,0,-10,13.71,0,-1,13.73,0,-1,13.74,0,-1,13.76,0,-3,13.77,0,-3,13.78,0,-3,13.79,0,-1,13.80,0,-7,13.81,0,-4,ARL,0
2025-07-17T15:44:09.396195647Z,2025-07-17T15:44:09.396030225Z,10,2,1108,A,A,10,14.840000000,100,302205537,165422,253384731,13.31,10,1,13.28,11,2,13.14,1,1,13.13,100,1,13.11,100,1,13.10,100,1,13.04,2,1,12.99,100,1,12.73,100,1,12.67,100,1,13.40,0,-10,13.71,0,-1,13.73,0,-1,13.74,0,-1,13.76,0,-3,13.77,0,-3,13.78,0,-3,13.79,0,-1,13.80,0,-7,13.81,0,-4,ARL,0
2025-07-17T15:44:09.398011186Z,2025-07-17T15:44:09.397845986Z,10,2,1108,A,A,10,13.790000000,100,302205561,165200,253384788,13.31,10,1,13.28,11,2,13.14,1,1,13.13,100,1,13.11,100,1,13.10,100,1,13.04,2,1,12.99,100,1,12.73,100,1,12.67,100,1,13.40,0,-10,13.71,0,-1,13.73,0,-1,13.74,0,-1,13.76,0,-3,13.77,0,-3,13.78,0,-3,13.79,0,-1,13.80,0,-7,13.81,0,-4,ARL,0
2025-07-17T15:44:09.404828956Z,2025-07-17T15:44:09.404663816Z,10,2,1108,C,A,10,13.810000000,100,302100649,165140,253385013,13.31,10,1,13.28,11,2,13.14,1,1,13.13,100,1,13.11,100,1,13.10,100,1,13.04,2,1,12.99,100,1,12.73,100,1,12.67,100,1,13.40,0,-10,13.71,0,-1,13.73,0,-1,13.74,0,-1,13.76,0,-3,13.77,0,-3,13.78,0,-3,13.79,0,-2,13.80,0,-7,13.81,0,-4,ARL,0
2025-07-17T15:44:20.402535831Z,2025-07-17T15:44:20.402370565Z,10,2,1108,C,A,10,13.810000000,15,301867541,165266,253562230,13.31,10,1,13.28,11,2,13.14,1,1,13.13,100,1,13.11,100,1,13.10,100,1,13.04,2,1,12.99,100,1,12.73,100,1,12.67,100,1,13.40,0,-10,13.71,0,-1,13.73,0,-1,13.74,0,-1,13.76,0,-3,13.77,0,-3,13.78,0,-3,13.79,0,-2,13.80,0,-7,13.81,0,-4,ARL,0
2025-07-17T15:44:21.405486122Z,2025-07-17T15:44:21.405320730Z,10,2,1108,A,A,10,13.740000000,15,302458113,165392,253582427,13.31,10,1,13.28,11,2,13.14,1,1,13.13,100,1,13.11,100,1,13.10,100,1,13.04,2,1,12.99,100,1,12.73,100,1,12.67,100,1,13.40,0,-10,13.71,0,-1,13.73,0,-1,13.74,0,-1,13.76,0,-3,13.77,0,-3,13.78,0,-3,13.79,0,-2,13.80,0,-7,13.81,0,-4,ARL,0
2025-07-17T15:44:21.843235911Z,2025-07-17T15:44:21.843070079Z,10,2,1108,C,A,10,13.770000000,100,302205493,165832,253590641,13.31,10,1,13.28,11,2,13.14,1,1,13.13,100,1,13.11,100,1,13.10,100,1,13.04,2,1,12.99,100,1,12.73,100,1,12.67,100,1,13.40,0,-10,13.71,0,-1,13.73,0,-1,13.74,0,-2,13.76,0,-3,13.77,0,-3,13.78,0,-3,13.79,0,-2,13.80,0,-7,13.81,0,-4,ARL,0
2025-07-17T15:44:21.843235911Z,2025-07-17T15:44:21.843070079Z,10,2,1108,A,A,10,13.750000000,100,302466045,165832,253590641,13.31,10,1,13.28,11,2,13.14,1,1,13.13,100,1,13.11,100,1,13.10,100,1,13.04,2,1,12.99,100,1,12.73,100,1,12.67,100,1,13.40,0,-10,13.71,0,-1,13.73,0,-1,13.74,0,-2,13.76,0,-3,13.77,0,-3,13.78,0,-3,13.79,0,-2,13.80,0,-7,13.81,0,-4,ARL,0
2025-07-17T15:44:21.855416093Z,2025-07-17T15:44:21.855250804Z,10,2,1108,C,A,10,14.100000000,100,301886057,165289,253590837,13.31,10,1,13.28,11,2,13.14,1,1,13.13,100,1,13.11,100,1,13.10,100,1,13.04,2,1,12.99,100,1,12.73,100,1,12.67,100,1,13.40,0,-10,13.71,0,-1,13.73,0,-1,13.74,0,-2,13.75,0,-1,13.76,0,-3,13.77,0,-3,13.78,0,-3,13.79,0,-2,13.80,0,-7,ARL,0
2025-07-17T15:44:21.855471158Z,2025-07-17T15:44:21.855305995Z,10,2,1108,A,A,10,14.030000000,100,302466157,165163,253590838,13.31,10,1,13.28,11,2,13.14,1,1,13.13,100,1,13.11,100,1,13.10,100,1,13.04,2,1,12.99,100,1,12.73,100,1,12.67,100,1,13.40,0,-10,13.71,0,-1,13.73,0,-1,13.74,0,-2,13.75,0,-1,13.76,0,-3,13.77,0,-3,13.78,0,-3,13.79,0,-2,13.80,0,-7,ARL,0
2025-07-17T15:44:24.447075532Z,2025-07-17T15:44:24.446910206Z,10,2,1108,A,A,10,13.770000000,100,302500469,165326,253614407,13.31,10,1,13.28,11,2,13.14,1,1,13.13,100,1,13.11,100,1,13.10,100,1,13.04,2,1,12.99,100,1,12.73,100,1,12.67,100,1,13.40,0,-10,13.71,0,-1,13.73,0,-1,13.74,0,-2,13.75,0,-1,13.76,0,-3,13.77,0,-3,13.78,0,-3,13.79,0,-2,13.80,0,-7,ARL,0
2025-07-17T15:44:24.465555818Z,2025-07-17T15:44:24.465390625Z,10,2,1108,C,A,10,13.790000000,100,302205561,165193,253614591,13.31,10,1,13.28,11,2,13.14,1,1,13.13,100,1,13.11,100,1,13.10,100,1,13.04,2,1,12.99,100,1,12.73,100,1,12.67,100,1,13.40,0,-10,13.71,0,-1,13.73,0,-1,13.74,0,-2,13.75,0,-1,13.76,0,-3,13.77,0,-4,13.78,0,-3,13.79,0,-2,13.80,0,-7,ARL,0
2025-07-17T15:44:30.846822983Z,2025-07-17T15:44:30.846657613Z,10,2,1108,C,A,10,13.760000000,15,302205249,165370,253704439,13.31,10,1,13.28,11,2,13.14,1,1,13.13,100,1,13.11,100,1,13.10,100,1,13.04,2,1,12.99,100,1,12.73,100,1,12.67,100,1,13.40,0,-10,13.71,0,-1,13.73,0,-1,13.74,0,-2,13.75,0,-1,13.76,0,-3,13.77,0,-4,13.78,0,-3,13.79,0,-2,13.80,0,-7,ARL,0
2025-07-17T15:44:31.849784693Z,2025-07-17T15:44:31.849618640Z,10,2,1108,A,A,10,13.720000000,15,302649021,166053,253721156,13.31,10,1,13.28,11,2,13.14,1,1,13.13,100,1,13.11,100,1,13.10,100,1,13.04,2,1,12.99,100,1,12.73,100,1,12.67,100,1,13.40,0,-10,13.71,0,-1,13.73,0,-1,13.74,0,-2,13.75,0,-1,13.76,0,-3,13.77,0,-4,13.78,0,-3,13.79,0,-2,13.80,0,-7,ARL,0
2025-07-17T15:44:31.849921857Z,2025-07-17T15:44:31.849756452Z,10,2,1108,A,A,10,13.750000000,100,302649029,165405,253721157,13.31,10,1,13.28,11,2,13.14,1,1,13.13,100,1,13.11,100,1,13.10,100,1,13.04,2,1,12.99,100,1,12.73,100,1,12.67,100,1,13.40,0,-10,13.71,0,-1,13.73,0,-1,13.74,0,-2,13.75,0,-1,13.76,0,-3,13.77,0,-4,13.78,0,-3,13.79,0,-2,13.80,0,-7,ARL,0
2025-07-17T15:44:31.910124978Z,2025-07-17T15:44:31.909959614Z,10,2,1108,C,A,10,13.770000000,100,302500469,165364,253722140,13.31,10,1,13.28,11,2,13.14,1,1,13.13,100,1,13.11,100,1,13.10,100,1,13.04,2,1,12.99,100,1,12.73,100,1,12.67,100,1,13.40,0,-10,13.71,0,-1,13.73,0,-1,13.74,0,-2,13.75,0,-2,13.76,0,-3,13.77,0,-4,13.78,0,-3,13.79,0,-2,13.80,0,-7,ARL,0
2025-07-17T15:44:32.484497230Z,2025-07-17T15:44:32.484331764Z,10,2,1108,C,A,10,13.750000000,100,302466045,165466,253730877,13.31,10,1,13.28,11,2,13.14,1,1,13.13,100,1,13.11,100,1,13.10,100,1,13.04,2,1,12.99,100,1,12.73,100,1,12.67,100,1,13.40,0,-10,13.71,0,-1,13.73,0,-1,13.74,0,-2,13.75,0,-2,13.76,0,-3,13.77,0,-4,13.78,0,-3,13.79,0,-2,13.80,0,-7,ARL,0
2025-07-17T15:44:32.484497230Z,2025-07-17T15:44:32.484331764Z,10,2,1108,A,A,10,13.730000000,100,302662769,165466,253730877,13.31,10,1,13.28,11,2,13.14,1,1,13.13,100,1,13.11,100,1,13.10,100,1,13.04,2,1,12.99,100,1,12.73,100,1,12.67,100,1,13.40,0,-10,13.71,0,-1,13.73,0,-1,13.74,0,-2,13.75,0,-2,13.76,0,-3,13.77,0,-4,13.78,0,-3,13.79,0,-2,13.80,0,-7,ARL,0
2025-07-17T15:44:32.485238209Z,2025-07-17T15:44:32.485072552Z,10,2,1108,C,A,10,14.840000000,100,302205537,165657,253730907,13.31,10,1,13.28,11,2,13.14,1,1,13.13,100,1,13.11,100,1,13.10,100,1,13.04,2,1,12.99,100,1,12.73,100,1,12.67,100,1,13.40,0,-10,13.71,0,-1,13.73,0,-2,13.74,0,-2,13.75,0,-2,13.76,0,-3,13.77,0,-4,13.78,0,-3,13.79,0,-2,13.80,0,-7,ARL,0
2025-07-17T15:44:32.485238209Z,2025-07-17T15:44:32.485072552Z,10,2,1108,A,A,10,14.790000000,100,302662821,165657,253730907,13.31,10,1,13.28,11,2,13.14,1,1,13.13,100,1,13.11,100,1,13.10,100,1,13.04,2,1,12.99,100,1,12.73,100,1,12.67,100,1,13.40,0,-10,13.71,0,-1,13.73,0,-2,13.74,0,-2,13.75,0,-2,13.76,0,-3,13.77,0,-4,13.78,0,-3,13.79,0,-2,13.80,0,-7,ARL,0
2025-07-17T15:44:33.389387814Z,2025-07-17T15:44:33.389222513Z,10,2,1108,A,A,10,14.280000000,100,302681357,165301,253745665,13.31,10,1,13.28,11,2,13.14,1,1,13.13,100,1,13.11,100,1,13.10,100,1,13.04,2,1,12.99,100,1,12.73,100,1,12.67,100,1,13.40,0,-10,13.71,0,-1,13.73,0,-2,13.74,0,-2,13.75,0,-2,13.76,0,-3,13.77,0,-4,13.78,0,-3,13.79,0,-2,13.80,0,-7,ARL,0
2025-07-17T15:44:33.389389030Z,2025-07-17T15:44:33.389223581Z,10,2,1108,C,A,10,14.560000000,100,146960005,165449,253745666,13.31,10,1,13.28,11,2,13.14,1,1,13.13,100,1,13.11,100,1,13.10,100,1,13.04,2,1,12.99,100,1,12.73,100,1,12.67,100,1,13.40,0,-10,13.71,0,-1,13.73,0,-2,13.74,0,-2,13.75,0,-2,13.76,0,-3,13.77,0,-4,13.78,0,-3,13.79,0,-2,13.80,0,-7,ARL,0
2025-07-17T15:44:36.362187673Z,2025-07-17T15:44:36.362022168Z,10,2,1108,C,A,10,13.740000000,15,302458113,165505,253783635,13.31,10,1,13.28,11,2,13.14,1,1,13.13,100,1,13.11,100,1,13.10,100,1,13.04,2,1,12.99,100,1,12.73,100,1,12.67,100,1,13.40,0,-10,13.71,0,-1,13.73,0,-2,13.74,0,-2,13.75,0,-2,13.76,0,-3,13.77,0,-4,13.78,0,-3,13.79,0,-2,13.80,0,-7,ARL,0
