ts_recv,ts_event,rtype,publisher_id,instrument_id,action,side,depth,price,size,flags,ts_in_delta,sequence,bid_px_00,bid_sz_00,bid_ct_00,bid_px_01,bid_sz_01,bid_ct_01,bid_px_02,bid_sz_02,bid_ct_02,bid_px_03,bid_sz_03,bid_ct_03,bid_px_04,bid_sz_04,bid_ct_04,bid_px_05,bid_sz_05,bid_ct_05,bid_px_06,bid_sz_06,bid_ct_06,bid_px_07,bid_sz_07,bid_ct_07,bid_px_08,bid_sz_08,bid_ct_08,bid_px_09,bid_sz_09,bid_ct_09,ask_px_00,ask_sz_00,ask_ct_00,ask_px_01,ask_sz_01,ask_ct_01,ask_px_02,ask_sz_02,ask_ct_02,ask_px_03,ask_sz_03,ask_ct_03,ask_px_04,ask_sz_04,ask_ct_04,ask_px_05,ask_sz_05,ask_ct_05,ask_px_06,ask_sz_06,ask_ct_06,ask_px_07,ask_sz_07,ask_ct_07,ask_px_08,ask_sz_08,ask_ct_08,ask_px_09,ask_sz_09,ask_ct_09,symbol,order_id
2025-07-17T16:02:40.806305895Z,2025-07-17T16:02:40.806140621Z,10,2,1108,C,A,10,13.830000000,15,325714721,165274,271973288,13.31,10,1,13.28,1,2,13.27,20,2,13.26,198,2,13.14,1,1,13.13,100,1,13.12,200,2,13.11,100,1,13.10,100,1,13.04,2,1,13.40,0,-10,13.53,0,-1,13.55,0,-1,13.56,0,-1,13.57,0,-1,13.58,0,-1,13.59,0,-2,13.60,0,-2,13.61,0,-2,13.63,0,-3,ARL,0
2025-07-17T16:02:43.841852430Z,2025-07-17T16:02:43.841686908Z,10,2,1108,C,B,10,13.260000000,100,325718821,165522,272014658,13.31,10,1,13.28,1,2,13.27,20,2,13.26,198,2,13.14,1,1,13.13,100,1,13.12,200,2,13.11,100,1,13.10,100,1,13.04,2,1,13.40,0,-10,13.53,0,-1,13.55,0,-1,13.56,0,-1,13.57,0,-1,13.58,0,-1,13.59,0,-2,13.60,0,-2,13.61,0,-2,13.63,0,-3,ARL,0
2025-07-17T16:02:43.841912053Z,2025-07-17T16:02:43.841746626Z,10,2,1108,A,A,10,13.900000000,4,326158809,165427,272014659,13.31,10,1,13.28,1,2,13.27,20,2,13.26,198,2,13.14,1,1,13.13,100,1,13.12,200,2,13.11,100,1,13.10,100,1,13.04,2,1,13.40,0,-10,13.53,0,-1,13.55,0,-1,13.56,0,-1,13.57,0,-1,13.58,0,-1,13.59,0,-2,13.60,0,-2,13.61,0,-2,13.63,0,-3,ARL,0
2025-07-17T16:02:43.842295427Z,2025-07-17T16:02:43.842130114Z,10,2,1108,C,A,10,13.800000000,100,326082329,165313,272014661,13.31,10,1,13.28,1,2,13.27,20,2,13.26,198,2,13.14,1,1,13.13,100,1,13.12,200,2,13.11,100,1,13.10,100,1,13.04,2,1,13.40,0,-10,13.53,0,-1,13.55,0,-1,13.56,0,-1,13.57,0,-1,13.58,0,-1,13.59,0,-2,13.60,0,-2,13.61,0,-2,13.63,0,-3,ARL,0
2025-07-17T16:02:43.843036936Z,2025-07-17T16:02:43.842871428Z,10,2,1108,C,A,10,14.870000000,100,326082353,165508,272014673,13.31,10,1,13.28,1,2,13.27,20,2,13.26,198,2,13.14,1,1,13.13,100,1,13.12,200,2,13.11,100,1,13.10,100,1,13.04,2,1,13.40,0,-10,13.53,0,-1,13.55,0,-1,13.56,0,-1,13.57,0,-1,13.58,0,-1,13.59,0,-2,13.60,0,-2,13.61,0,-2,13.63,0,-3,ARL,0
2025-07-17T16:02:43.843036936Z,2025-07-17T16:02:43.842871428Z,10,2,1108,A,A,10,14.920000000,100,326158869,165508,272014673,13.31,10,1,13.28,1,2,13.27,20,2,13.26,198,2,13.14,1,1,13.13,100,1,13.12,200,2,13.11,100,1,13.10,100,1,13.04,2,1,13.40,0,-10,13.53,0,-1,13.55,0,-1,13.56,0,-1,13.57,0,-1,13.58,0,-1,13.59,0,-2,13.60,0,-2,13.61,0,-2,13.63,0,-3,ARL,0
2025-07-17T16:02:43.843106749Z,2025-07-17T16:02:43.842941514Z,10,2,1108,A,B,10,13.110000000,100,326158877,165235,272014674,13.31,10,1,13.28,1,2,13.27,20,2,13.26,198,2,13.14,1,1,13.13,100,1,13.12,200,2,13.11,200,2,13.10,100,1,13.04,2,1,13.40,0,-10,13.53,0,-1,13.55,0,-1,13.56,0,-1,13.57,0,-1,13.58,0,-1,13.59,0,-2,13.60,0,-2,13.61,0,-2,13.63,0,-3,ARL,0
2025-07-17T16:02:43.843109026Z,2025-07-17T16:02:43.842943173Z,10,2,1108,C,A,10,14.810000000,100,325718549,165853,272014675,13.31,10,1,13.28,1,2,13.27,20,2,13.26,198,2,13.14,1,1,13.13,100,1,13.12,200,2,13.11,100,1,13.10,100,1,13.04,2,1,13.40,0,-10,13.53,0,-1,13.55,0,-1,13.56,0,-1,13.57,0,-1,13.58,0,-1,13.59,0,-2,13.60,0,-2,13.61,0,-2,13.63,0,-3,ARL,0
2025-07-17T16:02:43.843109026Z,2025-07-17T16:02:43.842943173Z,10,2,1108,A,A,10,14.960000000,100,326158881,165853,272014675,13.31,10,1,13.28,1,2,13.27,20,2,13.26,198,2,13.14,1,1,13.13,100,1,13.12,200,2,13.11,100,1,13.10,100,1,13.04,2,1,13.40,0,-10,13.53,0,-1,13.55,0,-1,13.56,0,-1,13.57,0,-1,13.58,0,-1,13.59,0,-2,13.60,0,-2,13.61,0,-2,13.63,0,-3,ARL,0
2025-07-17T16:02:43.843204692Z,2025-07-17T16:02:43.843039530Z,10,2,1108,C,A,10,13.900000000,4,326158809,165162,272014681,13.31,10,1,13.28,1,2,13.27,20,2,13.26,198,2,13.14,1,1,13.13,100,1,13.12,200,2,13.11,100,1,13.10,100,1,13.04,2,1,13.40,0,-10,13.53,0,-1,13.55,0,-1,13.56,0,-1,13.57,0,-1,13.58,0,-1,13.59,0,-2,13.60,0,-2,13.61,0,-2,13.63,0,-3,ARL,0
2025-07-17T16:02:43.843956820Z,2025-07-17T16:02:43.843791297Z,10,2,1108,C,A,10,17.580000000,100,325718557,165523,272014689,13.31,10,1,13.28,1,2,13.27,20,2,13.26,198,2,13.14,1,1,13.13,100,1,13.12,200,2,13.11,100,1,13.10,100,1,13.04,2,1,13.40,0,-10,13.53,0,-1,13.55,0,-1,13.56,0,-1,13.57,0,-1,13.58,0,-1,13.59,0,-2,13.60,0,-2,13.61,0,-2,13.63,0,-3,ARL,0
2025-07-17T16:02:43.843956820Z,2025-07-17T16:02:43.843791297Z,10,2,1108,A,A,10,17.760000000,100,326158953,165523,272014689,13.31,10,1,13.28,1,2,13.27,20,2,13.26,198,2,13.14,1,1,13.13,100,1,13.12,200,2,13.11,100,1,13.10,100,1,13.04,2,1,13.40,0,-10,13.53,0,-1,13.55,0,-1,13.56,0,-1,13.57,0,-1,13.58,0,-1,13.59,0,-2,13.60,0,-2,13.61,0,-2,13.63,0,-3,ARL,0
2025-07-17T16:02:43.844653014Z,2025-07-17T16:02:43.844487204Z,10,2,1108,C,A,10,15.920000000,100,325718525,165810,272014697,13.31,10,1,13.28,1,2,13.27,20,2,13.26,198,2,13.14,1,1,13.13,100,1,13.12,200,2,13.11,100,1,13.10,100,1,13.04,2,1,13.40,0,-10,13.53,0,-1,13.55,0,-1,13.56,0,-1,13.57,0,-1,13.58,0,-1,13.59,0,-2,13.60,0,-2,13.61,0,-2,13.63,0,-3,ARL,0
2025-07-17T16:02:43.844653014Z,2025-07-17T16:02:43.844487204Z,10,2,1108,A,A,10,16.080000000,100,326158989,165810,272014697,13.31,10,1,13.28,1,2,13.27,20,2,13.26,198,2,13.14,1,1,13.13,100,1,13.12,200,2,13.11,100,1,13.10,100,1,13.04,2,1,13.40,0,-10,13.53,0,-1,13.55,0,-1,13.56,0,-1,13.57,0,-1,13.58,0,-1,13.59,0,-2,13.60,0,-2,13.61,0,-2,13.63,0,-3,ARL,0
2025-07-17T16:02:43.844801951Z,2025-07-17T16:02:43.844636465Z,10,2,1108,C,A,10,14.810000000,100,325718517,165486,272014698,13.31,10,1,13.28,1,2,13.27,20,2,13.26,198,2,13.14,1,1,13.13,100,1,13.12,200,2,13.11,100,1,13.10,100,1,13.04,2,1,13.40,0,-10,13.53,0,-1,13.55,0,-1,13.56,0,-1,13.57,0,-1,13.58,0,-1,13.59,0,-2,13.60,0,-2,13.61,0,-2,13.63,0,-3,ARL,0
2025-07-17T16:02:43.844801951Z,2025-07-17T16:02:43.844636465Z,10,2,1108,A,A,10,14.960000000,100,326158997,165486,272014698,13.31,10,1,13.28,1,2,13.27,20,2,13.26,198,2,13.14,1,1,13.13,100,1,13.12,200,2,13.11,100,1,13.10,100,1,13.04,2,1,13.40,0,-10,13.53,0,-1,13.55,0,-1,13.56,0,-1,13.57,0,-1,13.58,0,-1,13.59,0,-2,13.60,0,-2,13.61,0,-2,13.63,0,-3,ARL,0
2025-07-17T16:02:43.847026795Z,2025-07-17T16:02:43.846861336Z,10,2,1108,C,A,10,13.920000000,2,325297093,165459,272014713,13.31,10,1,13.28,1,2,13.27,20,2,13.26,198,2,13.14,1,1,13.13,100,1,13.12,200,2,13.11,100,1,13.10,100,1,13.04,2,1,13.40,0,-10,13.53,0,-1,13.55,0,-1,13.56,0,-1,13.57,0,-1,13.58,0,-1,13.59,0,-2,13.60,0,-2,13.61,0,-2,13.63,0,-3,ARL,0
2025-07-17T16:02:43.847026795Z,2025-07-17T16:02:43.846861336Z,10,2,1108,A,A,10,14.030000000,2,326159041,165459,272014713,13.31,10,1,13.28,1,2,13.27,20,2,13.26,198,2,13.14,1,1,13.13,100,1,13.12,200,2,13.11,100,1,13.10,100,1,13.04,2,1,13.40,0,-10,13.53,0,-1,13.55,0,-1,13.56,0,-1,13.57,0,-1,13.58,0,-1,13.59,0,-2,13.60,0,-2,13.61,0,-2,13.63,0,-3,ARL,0
2025-07-17T16:02:43.847832258Z,2025-07-17T16:02:43.847666979Z,10,2,1108,C,A,10,14.730000000,100,325714613,165279,272014721,13.31,10,1,13.28,1,2,13.27,20,2,13.26,198,2,13.14,1,1,13.13,100,1,13.12,200,2,13.11,100,1,13.10,100,1,13.04,2,1,13.40,0,-10,13.53,0,-1,13.55,0,-1,13.56,0,-1,13.57,0,-1,13.58,0,-1,13.59,0,-2,13.60,0,-2,13.61,0,-2,13.63,0,-3,ARL,0
2025-07-17T16:02:43.847832258Z,2025-07-17T16:02:43.847666979Z,10,2,1108,A,A,10,14.870000000,100,326159049,165279,272014721,13.31,10,1,13.28,1,2,13.27,20,2,13.26,198,2,13.14,1,1,13.13,100,1,13.12,200,2,13.11,100,1,13.10,100,1,13.04,2,1,13.40,0,-10,13.53,0,-1,13.55,0,-1,13.56,0,-1,13.57,0,-1,13.58,0,-1,13.59,0,-2,13.60,0,-2,13.61,0,-2,13.63,0,-3,ARL,0
2025-07-17T16:02:43.848147198Z,2025-07-17T16:02:43.847981726Z,10,2,1108,C,A,10,14.730000000,100,325714577,165472,272014724,13.31,10,1,13.28,1,2,13.27,20,2,13.26,198,2,13.14,1,1,13.13,100,1,13.12,200,2,13.11,100,1,13.10,100,1,13.04,2,1,13.40,0,-10,13.53,0,-1,13.55,0,-1,13.56,0,-1,13.57,0,-1,13.58,0,-1,13.59,0,-2,13.60,0,-2,13.61,0,-2,13.63,0,-3,ARL,0
2025-07-17T16:02:43.848147198Z,2025-07-17T16:02:43.847981726Z,10,2,1108,A,A,10,14.870000000,100,326159061,165472,272014724,13.31,10,1,13.28,1,2,13.27,20,2,13.26,198,2,13.14,1,1,13.13,100,1,13.12,200,2,13.11,100,1,13.10,100,1,13.04,2,1,13.40,0,-10,13.53,0,-1,13.55,0,-1,13.56,0,-1,13.57,0,-1,13.58,0,-1,13.59,0,-2,13.60,0,-2,13.61,0,-2,13.63,0,-3,ARL,0
2025-07-17T16:02:43.860199647Z,2025-07-17T16:02:43.860034354Z,10,2,1108,C,A,10,14.120000000,100,325718637,165293,272014788,13.31,10,1,13.28,1,2,13.27,20,2,13.26,198,2,13.14,1,1,13.13,100,1,13.12,200,2,13.11,100,1,13.10,100,1,13.04,2,1,13.40,0,-10,13.53,0,-1,13.55,0,-1,13.56,0,-1,13.57,0,-1,13.58,0,-1,13.59,0,-2,13.60,0,-2,13.61,0,-2,13.63,0,-3,ARL,0
2025-07-17T16:02:43.860252446Z,2025-07-17T16:02:43.860087215Z,10,2,1108,A,A,10,14.260000000,100,326159201,165231,272014789,13.31,10,1,13.28,1,2,13.27,20,2,13.26,198,2,13.14,1,1,13.13,100,1,13.12,200,2,13.11,100,1,13.10,100,1,13.04,2,1,13.40,0,-10,13.53,0,-1,13.55,0,-1,13.56,0,-1,13.57,0,-1,13.58,0,-1,13.59,0,-2,13.60,0,-2,13.61,0,-2,13.63,0,-3,ARL,0
2025-07-17T16:02:43.893176312Z,2025-07-17T16:02:43.893011012Z,10,2,1108,C,A,10,14.920000000,100,326158869,165300,272014986,13.31,10,1,13.28,1,2,13.27,20,2,13.26,198,2,13.14,1,1,13.13,100,1,13.12,200,2,13.11,100,1,13.10,100,1,13.04,2,1,13.40,0,-10,13.53,0,-1,13.55,0,-1,13.56,0,-1,13.57,0,-1,13.58,0,-1,13.59,0,-2,13.60,0,-2,13.61,0,-2,13.63,0,-3,ARL,0
2025-07-17T16:02:43.893176312Z,2025-07-17T16:02:43.893011012Z,10,2,1108,A,A,10,15.060000000,100,326159425,165300,272014986,13.31,10,1,13.28,1,2,13.27,20,2,13.26,198,2,13.14,1,1,13.13,100,1,13.12,200,2,13.11,100,1,13.10,100,1,13.04,2,1,13.40,0,-10,13.53,0,-1,13.55,0,-1,13.56,0,-1,13.57,0,-1,13.58,0,-1,13.59,0,-2,13.60,0,-2,13.61,0,-2,13.63,0,-3,ARL,0
2025-07-17T16:02:43.946967137Z,2025-07-17T16:02:43.946801538Z,10,2,1108,C,A,10,14.630000000,100,325714653,165599,272015584,13.31,10,1,13.28,1,2,13.27,20,2,13.26,198,2,13.14,1,1,13.13,100,1,13.12,200,2,13.11,100,1,13.10,100,1,13.04,2,1,13.40,0,-10,13.53,0,-1,13.55,0,-1,13.56,0,-1,13.57,0,-1,13.58,0,-1,13.59,0,-2,13.60,0,-2,13.61,0,-2,13.63,0,-3,ARL,0
2025-07-17T16:02:43.946967137Z,2025-07-17T16:02:43.946801538Z,10,2,1108,A,A,10,14.770000000,100,326160141,165599,272015584,13.31,10,1,13.28,1,2,13.27,20,2,13.26,198,2,13.14,1,1,13.13,100,1,13.12,200,2,13.11,100,1,13.10,100,1,13.04,2,1,13.40,0,-10,13.53,0,-1,13.55,0,-1,13.56,0,-1,13.57,0,-1,13.58,0,-1,13.59,0,-2,13.60,0,-2,13.61,0,-2,13.63,0,-3,ARL,0
2025-07-17T16:02:44.664219784Z,2025-07-17T16:02:44.664054457Z,10,2,1108,A,A,10,13.990000000,100,326167529,165327,272021808,13.31,10,1,13.28,1,2,13.27,20,2,13.26,198,2,13.14,1,1,13.13,100,1,13.12,200,2,13.11,100,1,13.10,100,1,13.04,2,1,13.40,0,-10,13.53,0,-1,13.55,0,-1,13.56,0,-1,13.57,0,-1,13.58,0,-1,13.59,0,-2,13.60,0,-2,13.61,0,-2,13.63,0,-3,ARL,0
2025-07-17T16:03:02.985987598Z,2025-07-17T16:03:02.985818199Z,10,2,1108,C,A,10,14.870000000,100,326159049,169399,272331833,13.31,10,1,13.28,1,2,13.27,20,2,13.26,198,2,13.14,1,1,13.13,100,1,13.12,200,2,13.11,100,1,13.10,100,1,13.04,2,1,13.40,0,-10,13.53,0,-1,13.55,0,-1,13.56,0,-1,13.57,0,-1,13.58,0,-1,13.59,0,-2,13.60,0,-2,13.61,0,-2,13.63,0,-3,ARL,0
2025-07-17T16:03:02.985987598Z,2025-07-17T16:03:02.985818199Z,10,2,1108,A,A,10,14.700000000,100,326551237,169399,272331833,13.31,10,1,13.28,1,2,13.27,20,2,13.26,198,2,13.14,1,1,13.13,100,1,13.12,200,2,13.11,100,1,13.10,100,1,13.04,2,1,13.40,0,-10,13.53,0,-1,13.55,0,-1,13.56,0,-1,13.57,0,-1,13.58,0,-1,13.59,0,-2,13.60,0,-2,13.61,0,-2,13.63,0,-3,ARL,0
2025-07-17T16:03:02.987969729Z,2025-07-17T16:03:02.987797728Z,10,2,1108,C,A,10,14.870000000,100,326159061,172001,272332718,13.31,10,1,13.28,1,2,13.27,20,2,13.26,198,2,13.14,1,1,13.13,100,1,13.12,200,2,13.11,100,1,13.10,100,1,13.04,2,1,13.40,0,-10,13.53,0,-1,13.55,0,-1,13.56,0,-1,13.57,0,-1,13.58,0,-1,13.59,0,-2,13.60,0,-2,13.61,0,-2,13.63,0,-3,ARL,0
2025-07-17T16:03:02.987969729Z,2025-07-17T16:03:02.987797728Z,10,2,1108,A,A,10,14.700000000,100,326551829,172001,272332718,13.31,10,1,13.28,1,2,13.27,20,2,13.26,198,2,13.14,1,1,13.13,100,1,13.12,200,2,13.11,100,1,13.10,100,1,13.04,2,1,13.40,0,-10,13.53,0,-1,13.55,0,-1,13.56,0,-1,13.57,0,-1,13.58,0,-1,13.59,0,-2,13.60,0,-2,13.61,0,-2,13.63,0,-3,ARL,0
2025-07-17T16:03:10.807446975Z,2025-07-17T16:03:10.807281669Z,10,2,1108,A,A,10,13.720000000,15,326729677,165306,272474575,13.31,10,1,13.28,1,2,13.27,20,2,13.26,198,2,13.14,1,1,13.13,100,1,13.12,200,2,13.11,100,1,13.10,100,1,13.04,2,1,13.40,0,-10,13.53,0,-1,13.55,0,-1,13.56,0,-1,13.57,0,-1,13.58,0,-1,13.59,0,-2,13.60,0,-2,13.61,0,-2,13.63,0,-3,ARL,0
2025-07-17T16:03:10.807714421Z,2025-07-17T16:03:10.807548848Z,10,2,1108,C,A,10,13.990000000,100,326167529,165573,272474576,13.31,10,1,13.28,1,2,13.27,20,2,13.26,198,2,13.14,1,1,13.13,100,1,13.12,200,2,13.11,100,1,13.10,100,1,13.04,2,1,13.40,0,-10,13.53,0,-1,13.55,0,-1,13.56,0,-1,13.57,0,-1,13.58,0,-1,13.59,0,-2,13.60,0,-2,13.61,0,-2,13.63,0,-3,ARL,0
2025-07-17T16:03:10.807714421Z,2025-07-17T16:03:10.807548848Z,10,2,1108,A,A,10,13.730000000,100,326729685,165573,272474576,13.31,10,1,13.28,1,2,13.27,20,2,13.26,198,2,13.14,1,1,13.13,100,1,13.12,200,2,13.11,100,1,13.10,100,1,13.04,2,1,13.40,0,-10,13.53,0,-1,13.55,0,-1,13.56,0,-1,13.57,0,-1,13.58,0,-1,13.59,0,-2,13.60,0,-2,13.61,0,-2,13.63,0,-3,ARL,0
2025-07-17T16:03:10.808457278Z,2025-07-17T16:03:10.808290914Z,10,2,1108,C,A,10,15.060000000,100,326159425,166364,272474580,13.31,10,1,13.28,1,2,13.27,20,2,13.26,198,2,13.14,1,1,13.13,100,1,13.12,200,2,13.11,100,1,13.10,100,1,13.04,2,1,13.40,0,-10,13.53,0,-1,13.55,0,-1,13.56,0,-1,13.57,0,-1,13.58,0,-1,13.59,0,-2,13.60,0,-2,13.61,0,-2,13.63,0,-3,ARL,0
2025-07-17T16:03:10.808457278Z,2025-07-17T16:03:10.808290914Z,10,2,1108,A,A,10,14.790000000,100,326729705,166364,272474580,13.31,10,1,13.28,1,2,13.27,20,2,13.26,198,2,13.14,1,1,13.13,100,1,13.12,200,2,13.11,100,1,13.10,100,1,13.04,2,1,13.40,0,-10,13.53,0,-1,13.55,0,-1,13.56,0,-1,13.57,0,-1,13.58,0,-1,13.59,0,-2,13.60,0,-2,13.61,0,-2,13.63,0,-3,ARL,0
2025-07-17T16:03:10.809707274Z,2025-07-17T16:03:10.809541651Z,10,2,1108,C,A,10,14.960000000,100,326158881,165623,272474585,13.31,10,1,13.28,1,2,13.27,20,2,13.26,198,2,13.14,1,1,13.13,100,1,13.12,200,2,13.11,100,1,13.10,100,1,13.04,2,1,13.40,0,-10,13.53,0,-1,13.55,0,-1,13.56,0,-1,13.57,0,-1,13.58,0,-1,13.59,0,-2,13.60,0,-2,13.61,0,-2,13.63,0,-3,ARL,0
2025-07-17T16:03:10.809707274Z,2025-07-17T16:03:10.809541651Z,10,2,1108,A,A,10,14.700000000,100,326729721,165623,272474585,13.31,10,1,13.28,1,2,13.27,20,2,13.26,198,2,13.14,1,1,13.13,100,1,13.12,200,2,13.11,100,1,13.10,100,1,13.04,2,1,13.40,0,-10,13.53,0,-1,13.55,0,-1,13.56,0,-1,13.57,0,-1,13.58,0,-1,13.59,0,-2,13.60,0,-2,13.61,0,-2,13.63,0,-3,ARL,0
2025-07-17T16:03:10.809936821Z,2025-07-17T16:03:10.809771527Z,10,2,1108,C,A,10,14.770000000,100,326160141,165294,272474594,13.31,10,1,13.28,1,2,13.27,20,2,13.26,198,2,13.14,1,1,13.13,100,1,13.12,200,2,13.11,100,1,13.10,100,1,13.04,2,1,13.40,0,-10,13.53,0,-1,13.55,0,-1,13.56,0,-1,13.57,0,-1,13.58,0,-1,13.59,0,-2,13.60,0,-2,13.61,0,-2,13.63,0,-3,ARL,0
2025-07-17T16:03:10.809963577Z,2025-07-17T16:03:10.809798084Z,10,2,1108,C,A,10,17.760000000,100,326158953,165493,272474595,13.31,10,1,13.28,1,2,13.27,20,2,13.26,198,2,13.14,1,1,13.13,100,1,13.12,200,2,13.11,100,1,13.10,100,1,13.04,2,1,13.40,0,-10,13.53,0,-1,13.55,0,-1,13.56,0,-1,13.57,0,-1,13.58,0,-1,13.59,0,-2,13.60,0,-2,13.61,0,-2,13.63,0,-3,ARL,0
2025-07-17T16:03:10.809963577Z,2025-07-17T16:03:10.809798084Z,10,2,1108,A,A,10,17.440000000,100,326729725,165493,272474595,13.31,10,1,13.28,1,2,13.27,20,2,13.26,198,2,13.14,1,1,13.13,100,1,13.12,200,2,13.11,100,1,13.10,100,1,13.04,2,1,13.40,0,-10,13.53,0,-1,13.55,0,-1,13.56,0,-1,13.57,0,-1,13.58,0,-1,13.59,0,-2,13.60,0,-2,13.61,0,-2,13.63,0,-3,ARL,0
2025-07-17T16:03:10.810059442Z,2025-07-17T16:03:10.809894317Z,10,2,1108,A,A,10,14.520000000,100,326729729,165125,272474597,13.31,10,1,13.28,1,2,13.27,20,2,13.26,198,2,13.14,1,1,13.13,100,1,13.12,200,2,13.11,100,1,13.10,100,1,13.04,2,1,13.40,0,-10,13.53,0,-1,13.55,0,-1,13.56,0,-1,13.57,0,-1,13.58,0,-1,13.59,0,-2,13.60,0,-2,13.61,0,-2,13.63,0,-3,ARL,0
2025-07-17T16:03:10.810478524Z,2025-07-17T16:03:10.810312923Z,10,2,1108,C,A,10,16.080000000,100,326158989,165601,272474600,13.31,10,1,13.28,1,2,13.27,20,2,13.26,198,2,13.14,1,1,13.13,100,1,13.12,200,2,13.11,100,1,13.10,100,1,13.04,2,1,13.40,0,-10,13.53,0,-1,13.55,0,-1,13.56,0,-1,13.57,0,-1,13.58,0,-1,13.59,0,-2,13.60,0,-2,13.61,0,-2,13.63,0,-3,ARL,0
2025-07-17T16:03:10.810478524Z,2025-07-17T16:03:10.810312923Z,10,2,1108,A,A,10,15.790000000,100,326729733,165601,272474600,13.31,10,1,13.28,1,2,13.27,20,2,13.26,198,2,13.14,1,1,13.13,100,1,13.12,200,2,13.11,100,1,13.10,100,1,13.04,2,1,13.40,0,-10,13.53,0,-1,13.55,0,-1,13.56,0,-1,13.57,0,-1,13.58,0,-1,13.59,0,-2,13.60,0,-2,13.61,0,-2,13.63,0,-3,ARL,0
2025-07-17T16:03:10.814646270Z,2025-07-17T16:03:10.814480532Z,10,2,1108,C,A,10,14.960000000,100,326158997,165738,272474635,13.31,10,1,13.28,1,2,13.27,20,2,13.26,198,2,13.14,1,1,13.13,100,1,13.12,200,2,13.11,100,1,13.10,100,1,13.04,2,1,13.40,0,-10,13.53,0,-1,13.55,0,-1,13.56,0,-1,13.57,0,-1,13.58,0,-1,13.59,0,-2,13.60,0,-2,13.61,0,-2,13.63,0,-3,ARL,0
2025-07-17T16:03:10.814646270Z,2025-07-17T16:03:10.814480532Z,10,2,1108,A,A,10,14.700000000,100,326729821,165738,272474635,13.31,10,1,13.28,1,2,13.27,20,2,13.26,198,2,13.14,1,1,13.13,100,1,13.12,200,2,13.11,100,1,13.10,100,1,13.04,2,1,13.40,0,-10,13.53,0,-1,13.55,0,-1,13.56,0,-1,13.57,0,-1,13.58,0,-1,13.59,0,-2,13.60,0,-2,13.61,0,-2,13.63,0,-3,ARL,0
2025-07-17T16:03:10.817866066Z,2025-07-17T16:03:10.817700664Z,10,2,1108,C,A,10,14.260000000,100,326159201,165402,272474675,13.31,10,1,13.28,1,2,13.27,20,2,13.26,198,2,13.14,1,1,13.13,100,1,13.12,200,2,13.11,100,1,13.10,100,1,13.04,2,1,13.40,0,-10,13.53,0,-1,13.55,0,-1,13.56,0,-1,13.57,0,-1,13.58,0,-1,13.59,0,-2,13.60,0,-2,13.61,0,-2,13.63,0,-3,ARL,0
2025-07-17T16:03:10.817919970Z,2025-07-17T16:03:10.817754737Z,10,2,1108,A,A,10,14.000000000,100,326729929,165233,272474676,13.31,10,1,13.28,1,2,13.27,20,2,13.26,198,2,13.14,1,1,13.13,100,1,13.12,200,2,13.11,100,1,13.10,100,1,13.04,2,1,13.40,0,-10,13.53,0,-1,13.55,0,-1,13.56,0,-1,13.57,0,-1,13.58,0,-1,13.59,0,-2,13.60,0,-2,13.61,0,-2,13.63,0,-3,ARL,0
2025-07-17T16:03:10.843337845Z,2025-07-17T16:03:10.843172549Z,10,2,1108,A,A,10,15.660000000,100,326730513,165296,272474826,13.31,10,1,13.28,1,2,13.27,20,2,13.26,198,2,13.14,1,1,13.13,100,1,13.12,200,2,13.11,100,1,13.10,100,1,13.04,2,1,13.40,0,-10,13.53,0,-1,13.55,0,-1,13.56,0,-1,13.57,0,-1,13.58,0,-1,13.59,0,-2,13.60,0,-2,13.61,0,-2,13.63,0,-3,ARL,0
2025-07-17T16:03:10.843350160Z,2025-07-17T16:03:10.843184785Z,10,2,1108,C,A,10,15.940000000,100,325714909,165375,272474827,13.31,10,1,13.28,1,2,13.27,20,2,13.26,198,2,13.14,1,1,13.13,100,1,13.12,200,2,13.11,100,1,13.10,100,1,13.04,2,1,13.40,0,-10,13.53,0,-1,13.55,0,-1,13.56,0,-1,13.57,0,-1,13.58,0,-1,13.59,0,-2,13.60,0,-2,13.61,0,-2,13.63,0,-3,ARL,0
2025-07-17T16:03:10.843615537Z,2025-07-17T16:03:10.843448998Z,10,2,1108,C,A,10,13.980000000,100,325719357,166539,272474828,13.31,10,1,13.28,1,2,13.27,20,2,13.26,198,2,13.14,1,1,13.13,100,1,13.12,200,2,13.11,100,1,13.10,100,1,13.04,2,1,13.40,0,-10,13.53,0,-1,13.55,0,-1,13.56,0,-1,13.57,0,-1,13.58,0,-1,13.59,0,-2,13.60,0,-2,13.61,0,-2,13.63,0,-3,ARL,0
2025-07-17T16:03:10.843615537Z,2025-07-17T16:03:10.843449402Z,10,2,1108,C,A,10,13.980000000,100,325719353,166135,272474829,13.31,10,1,13.28,1,2,13.27,20,2,13.26,198,2,13.14,1,1,13.13,100,1,13.12,200,2,13.11,100,1,13.10,100,1,13.04,2,1,13.40,0,-10,13.53,0,-1,13.55,0,-1,13.56,0,-1,13.57,0,-1,13.58,0,-1,13.59,0,-2,13.60,0,-2,13.61,0,-2,13.63,0,-3,ARL,0
2025-07-17T16:03:10.843628246Z,2025-07-17T16:03:10.843462898Z,10,2,1108,A,A,10,13.870000000,100,326730517,165348,272474830,13.31,10,1,13.28,1,2,13.27,20,2,13.26,198,2,13.14,1,1,13.13,100,1,13.12,200,2,13.11,100,1,13.10,100,1,13.04,2,1,13.40,0,-10,13.53,0,-1,13.55,0,-1,13.56,0,-1,13.57,0,-1,13.58,0,-1,13.59,0,-2,13.60,0,-2,13.61,0,-2,13.63,0,-3,ARL,0
2025-07-17T16:03:10.843629633Z,2025-07-17T16:03:10.843464369Z,10,2,1108,A,A,10,13.870000000,100,326730521,165264,272474831,13.31,10,1,13.28,1,2,13.27,20,2,13.26,198,2,13.14,1,1,13.13,100,1,13.12,200,2,13.11,100,1,13.10,100,1,13.04,2,1,13.40,0,-10,13.53,0,-1,13.55,0,-1,13.56,0,-1,13.57,0,-1,13.58,0,-1,13.59,0,-2,13.60,0,-2,13.61,0,-2,13.63,0,-3,ARL,0
2025-07-17T16:03:16.348189077Z,2025-07-17T16:03:16.348023740Z,10,2,1108,A,A,10,13.690000000,15,326835877,165337,272557172,13.31,10,1,13.28,1,2,13.27,20,2,13.26,198,2,13.14,1,1,13.13,100,1,13.12,200,2,13.11,100,1,13.10,100,1,13.04,2,1,13.40,0,-10,13.53,0,-1,13.55,0,-1,13.56,0,-1,13.57,0,-1,13.58,0,-1,13.59,0,-2,13.60,0,-2,13.61,0,-2,13.63,0,-3,ARL,0
2025-07-17T16:03:16.348468824Z,2025-07-17T16:03:16.348302787Z,10,2,1108,C,A,10,14.700000000,100,326551829,166037,272557230,13.31,10,1,13.28,1,2,13.27,20,2,13.26,198,2,13.14,1,1,13.13,100,1,13.12,200,2,13.11,100,1,13.10,100,1,13.04,2,1,13.40,0,-10,13.53,0,-1,13.55,0,-1,13.56,0,-1,13.57,0,-1,13.58,0,-1,13.59,0,-2,13.60,0,-2,13.61,0,-2,13.63,0,-3,ARL,0
2025-07-17T16:03:16.348468824Z,2025-07-17T16:03:16.348302787Z,10,2,1108,A,A,10,14.580000000,100,326835885,166037,272557230,13.31,10,1,13.28,1,2,13.27,20,2,13.26,198,2,13.14,1,1,13.13,100,1,13.12,200,2,13.11,100,1,13.10,100,1,13.04,2,1,13.40,0,-10,13.53,0,-1,13.55,0,-1,13.56,0,-1,13.57,0,-1,13.58,0,-1,13.59,0,-2,13.60,0,-2,13.61,0,-2,13.63,0,-3,ARL,0
2025-07-17T16:03:16.349679949Z,2025-07-17T16:03:16.349513354Z,10,2,1108,C,A,10,14.700000000,100,326551237,166595,272557430,13.31,10,1,13.28,1,2,13.27,20,2,13.26,198,2,13.14,1,1,13.13,100,1,13.12,200,2,13.11,100,1,13.10,100,1,13.04,2,1,13.40,0,-10,13.53,0,-1,13.55,0,-1,13.56,0,-1,13.57,0,-1,13.58,0,-1,13.59,0,-2,13.60,0,-2,13.61,0,-2,13.63,0,-3,ARL,0
2025-07-17T16:03:16.349679949Z,2025-07-17T16:03:16.349513354Z,10,2,1108,A,A,10,14.580000000,100,326836085,166595,272557430,13.31,10,1,13.28,1,2,13.27,20,2,13.26,198,2,13.14,1,1,13.13,100,1,13.12,200,2,13.11,100,1,13.10,100,1,13.04,2,1,13.40,0,-10,13.53,0,-1,13.55,0,-1,13.56,0,-1,13.57,0,-1,13.58,0,-1,13.59,0,-2,13.60,0,-2,13.61,0,-2,13.63,0,-3,ARL,0
2025-07-17T16:03:16.352011831Z,2025-07-17T16:03:16.351845457Z,10,2,1108,C,A,10,13.730000000,100,326729685,166374,272557789,13.31,10,1,13.28,1,2,13.27,20,2,13.26,198,2,13.14,1,1,13.13,100,1,13.12,200,2,13.11,100,1,13.10,100,1,13.04,2,1,13.40,0,-10,13.53,0,-1,13.55,0,-1,13.56,0,-1,13.57,0,-1,13.58,0,-1,13.59,0,-2,13.60,0,-2,13.61,0,-2,13.63,0,-3,ARL,0
2025-07-17T16:03:16.352011831Z,2025-07-17T16:03:16.351845457Z,10,2,1108,A,A,10,13.700000000,100,326836533,166374,272557789,13.31,10,1,13.28,1,2,13.27,20,2,13.26,198,2,13.14,1,1,13.13,100,1,13.12,200,2,13.11,100,1,13.10,100,1,13.04,2,1,13.40,0,-10,13.53,0,-1,13.55,0,-1,13.56,0,-1,13.57,0,-1,13.58,0,-1,13.59,0,-2,13.60,0,-2,13.61,0,-2,13.63,0,-3,ARL,0
2025-07-17T16:03:16.365985162Z,2025-07-17T16:03:16.365819243Z,10,2,1108,C,A,10,15.380000000,100,325714965,165919,272559024,13.31,10,1,13.28,1,2,13.27,20,2,13.26,198,2,13.14,1,1,13.13,100,1,13.12,200,2,13.11,100,1,13.10,100,1,13.04,2,1,13.40,0,-10,13.53,0,-1,13.55,0,-1,13.56,0,-1,13.57,0,-1,13.58,0,-1,13.59,0,-2,13.60,0,-2,13.61,0,-2,13.63,0,-3,ARL,0
2025-07-17T16:03:16.365985162Z,2025-07-17T16:03:16.365819243Z,10,2,1108,A,A,10,15.070000000,100,326837501,165919,272559024,13.31,10,1,13.28,1,2,13.27,20,2,13.26,198,2,13.14,1,1,13.13,100,1,13.12,200,2,13.11,100,1,13.10,100,1,13.04,2,1,13.40,0,-10,13.53,0,-1,13.55,0,-1,13.56,0,-1,13.57,0,-1,13.58,0,-1,13.59,0,-2,13.60,0,-2,13.61,0,-2,13.63,0,-3,ARL,0
2025-07-17T16:03:18.804325078Z,2025-07-17T16:03:18.804159952Z,10,2,1108,C,A,10,13.690000000,15,326835877,165126,272609485,13.31,10,1,13.28,1,2,13.27,20,2,13.26,198,2,13.14,1,1,13.13,100,1,13.12,200,2,13.11,100,1,13.10,100,1,13.04,2,1,13.40,0,-10,13.53,0,-1,13.55,0,-1,13.56,0,-1,13.57,0,-1,13.58,0,-1,13.59,0,-2,13.60,0,-2,13.61,0,-2,13.63,0,-3,ARL,0
2025-07-17T16:03:18.804367560Z,2025-07-17T16:03:18.804202246Z,10,2,1108,C,A,10,13.700000000,100,326836533,165314,272609486,13.31,10,1,13.28,1,2,13.27,20,2,13.26,198,2,13.14,1,1,13.13,100,1,13.12,200,2,13.11,100,1,13.10,100,1,13.04,2,1,13.40,0,-10,13.53,0,-1,13.55,0,-1,13.56,0,-1,13.57,0,-1,13.58,0,-1,13.59,0,-2,13.60,0,-2,13.61,0,-2,13.63,0,-3,ARL,0
2025-07-17T16:03:18.805099118Z,2025-07-17T16:03:18.804933488Z,10,2,1108,C,A,10,14.790000000,100,326729705,165630,272609510,13.31,10,1,13.28,1,2,13.27,20,2,13.26,198,2,13.14,1,1,13.13,100,1,13.12,200,2,13.11,100,1,13.10,100,1,13.04,2,1,13.40,0,-10,13.53,0,-1,13.55,0,-1,13.56,0,-1,13.57,0,-1,13.58,0,-1,13.59,0,-2,13.60,0,-2,13.61,0,-2,13.63,0,-3,ARL,0
2025-07-17T16:03:18.805099118Z,2025-07-17T16:03:18.804933488Z,10,2,1108,A,A,10,14.950000000,100,326892717,165630,272609510,13.31,10,1,13.28,1,2,13.27,20,2,13.26,198,2,13.14,1,1,13.13,100,1,13.12,200,2,13.11,100,1,13.10,100,1,13.04,2,1,13.40,0,-10,13.53,0,-1,13.55,0,-1,13.56,0,-1,13.57,0,-1,13.58,0,-1,13.59,0,-2,13.60,0,-2,13.61,0,-2,13.63,0,-3,ARL,0
2025-07-17T16:03:18.805291629Z,2025-07-17T16:03:18.805126035Z,10,2,1108,C,A,10,14.700000000,100,326729721,165594,272609526,13.31,10,1,13.28,1,2,13.27,20,2,13.26,198,2,13.14,1,1,13.13,100,1,13.12,200,2,13.11,100,1,13.10,100,1,13.04,2,1,13.40,0,-10,13.53,0,-1,13.55,0,-1,13.56,0,-1,13.57,0,-1,13.58,0,-1,13.59,0,-2,13.60,0,-2,13.61,0,-2,13.63,0,-3,ARL,0
2025-07-17T16:03:18.805291629Z,2025-07-17T16:03:18.805126035Z,10,2,1108,A,A,10,14.850000000,100,326892721,165594,272609526,13.31,10,1,13.28,1,2,13.27,20,2,13.26,198,2,13.14,1,1,13.13,100,1,13.12,200,2,13.11,100,1,13.10,100,1,13.04,2,1,13.40,0,-10,13.53,0,-1,13.55,0,-1,13.56,0,-1,13.57,0,-1,13.58,0,-1,13.59,0,-2,13.60,0,-2,13.61,0,-2,13.63,0,-3,ARL,0
2025-07-17T16:03:18.805449089Z,2025-07-17T16:03:18.805283236Z,10,2,1108,C,A,10,13.720000000,15,326729677,165853,272609541,13.31,10,1,13.28,1,2,13.27,20,2,13.26,198,2,13.14,1,1,13.13,100,1,13.12,200,2,13.11,100,1,13.10,100,1,13.04,2,1,13.40,0,-10,13.53,0,-1,13.55,0,-1,13.56,0,-1,13.57,0,-1,13.58,0,-1,13.59,0,-2,13.60,0,-2,13.61,0,-2,13.63,0,-3,ARL,0
2025-07-17T16:03:18.806535903Z,2025-07-17T16:03:18.806370373Z,10,2,1108,C,A,10,14.580000000,100,326835885,165530,272609577,13.31,10,1,13.28,1,2,13.27,20,2,13.26,198,2,13.14,1,1,13.13,100,1,13.12,200,2,13.11,100,1,13.10,100,1,13.04,2,1,13.40,0,-10,13.53,0,-1,13.55,0,-1,13.56,0,-1,13.57,0,-1,13.58,0,-1,13.59,0,-2,13.60,0,-2,13.61,0,-2,13.63,0,-3,ARL,0
2025-07-17T16:03:18.806535903Z,2025-07-17T16:03:18.806370373Z,10,2,1108,A,A,10,14.760000000,100,326892817,165530,272609577,13.31,10,1,13.28,1,2,13.27,20,2,13.26,198,2,13.14,1,1,13.13,100,1,13.12,200,2,13.11,100,1,13.10,100,1,13.04,2,1,13.40,0,-10,13.53,0,-1,13.55,0,-1,13.56,0,-1,13.57,0,-1,13.58,0,-1,13.59,0,-2,13.60,0,-2,13.61,0,-2,13.63,0,-3,ARL,0
2025-07-17T16:03:18.806802589Z,2025-07-17T16:03:18.806637004Z,10,2,1108,C,A,10,14.580000000,100,326836085,165585,272609583,13.31,10,1,13.28,1,2,13.27,20,2,13.26,198,2,13.14,1,1,13.13,100,1,13.12,200,2,13.11,100,1,13.10,100,1,13.04,2,1,13.40,0,-10,13.53,0,-1,13.55,0,-1,13.56,0,-1,13.57,0,-1,13.58,0,-1,13.59,0,-2,13.60,0,-2,13.61,0,-2,13.63,0,-3,ARL,0
2025-07-17T16:03:18.806802589Z,2025-07-17T16:03:18.806637004Z,10,2,1108,A,A,10,14.760000000,100,326892825,165585,272609583,13.31,10,1,13.28,1,2,13.27,20,2,13.26,198,2,13.14,1,1,13.13,100,1,13.12,200,2,13.11,100,1,13.10,100,1,13.04,2,1,13.40,0,-10,13.53,0,-1,13.55,0,-1,13.56,0,-1,13.57,0,-1,13.58,0,-1,13.59,0,-2,13.60,0,-2,13.61,0,-2,13.63,0,-3,ARL,0
2025-07-17T16:03:18.809706334Z,2025-07-17T16:03:18.809540733Z,10,2,1108,C,A,10,14.520000000,100,326729729,165601,272609656,13.31,10,1,13.28,1,2,13.27,20,2,13.26,198,2,13.14,1,1,13.13,100,1,13.12,200,2,13.11,100,1,13.10,100,1,13.04,2,1,13.40,0,-10,13.53,0,-1,13.55,0,-1,13.56,0,-1,13.57,0,-1,13.58,0,-1,13.59,0,-2,13.60,0,-2,13.61,0,-2,13.63,0,-3,ARL,0
2025-07-17T16:03:18.809706334Z,2025-07-17T16:03:18.809540733Z,10,2,1108,A,A,10,14.660000000,100,326892885,165601,272609656,13.31,10,1,13.28,1,2,13.27,20,2,13.26,198,2,13.14,1,1,13.13,100,1,13.12,200,2,13.11,100,1,13.10,100,1,13.04,2,1,13.40,0,-10,13.53,0,-1,13.55,0,-1,13.56,0,-1,13.57,0,-1,13.58,0,-1,13.59,0,-2,13.60,0,-2,13.61,0,-2,13.63,0,-3,ARL,0
2025-07-17T16:03:18.809848665Z,2025-07-17T16:03:18.809683187Z,10,2,1108,C,A,10,15.790000000,100,326729733,165478,272609658,13.31,10,1,13.28,1,2,13.27,20,2,13.26,198,2,13.14,1,1,13.13,100,1,13.12,200,2,13.11,100,1,13.10,100,1,13.04,2,1,13.40,0,-10,13.53,0,-1,13.55,0,-1,13.56,0,-1,13.57,0,-1,13.58,0,-1,13.59,0,-2,13.60,0,-2,13.61,0,-2,13.63,0,-3,ARL,0
2025-07-17T16:03:18.809848665Z,2025-07-17T16:03:18.809683187Z,10,2,1108,A,A,10,15.960000000,100,326892889,165478,272609658,13.31,10,1,13.28,1,2,13.27,20,2,13.26,198,2,13.14,1,1,13.13,100,1,13.12,200,2,13.11,100,1,13.10,100,1,13.04,2,1,13.40,0,-10,13.53,0,-1,13.55,0,-1,13.56,0,-1,13.57,0,-1,13.58,0,-1,13.59,0,-2,13.60,0,-2,13.61,0,-2,13.63,0,-3,ARL,0
2025-07-17T16:03:18.812107206Z,2025-07-17T16:03:18.811941680Z,10,2,1108,C,A,10,17.440000000,100,326729725,165526,272609679,13.31,10,1,13.28,1,2,13.27,20,2,13.26,198,2,13.14,1,1,13.13,100,1,13.12,200,2,13.11,100,1,13.10,100,1,13.04,2,1,13.40,0,-10,13.53,0,-1,13.55,0,-1,13.56,0,-1,13.57,0,-1,13.58,0,-1,13.59,0,-2,13.60,0,-2,13.61,0,-2,13.63,0,-3,ARL,0
2025-07-17T16:03:18.812107206Z,2025-07-17T16:03:18.811941680Z,10,2,1108,A,A,10,17.620000000,100,326892921,165526,272609679,13.31,10,1,13.28,1,2,13.27,20,2,13.26,198,2,13.14,1,1,13.13,100,1,13.12,200,2,13.11,100,1,13.10,100,1,13.04,2,1,13.40,0,-10,13.53,0,-1,13.55,0,-1,13.56,0,-1,13.57,0,-1,13.58,0,-1,13.59,0,-2,13.60,0,-2,13.61,0,-2,13.63,0,-3,ARL,0
2025-07-17T16:03:18.818245629Z,2025-07-17T16:03:18.818080239Z,10,2,1108,C,A,10,14.000000000,100,326729929,165390,272609768,13.31,10,1,13.28,1,2,13.27,20,2,13.26,198,2,13.14,1,1,13.13,100,1,13.12,200,2,13.11,100,1,13.10,100,1,13.04,2,1,13.40,0,-10,13.53,0,-1,13.55,0,-1,13.56,0,-1,13.57,0,-1,13.58,0,-1,13.59,0,-2,13.60,0,-2,13.61,0,-2,13.63,0,-3,ARL,0
2025-07-17T16:03:18.818301143Z,2025-07-17T16:03:18.818135688Z,10,2,1108,A,A,10,14.150000000,100,326893213,165455,272609769,13.31,10,1,13.28,1,2,13.27,20,2,13.26,198,2,13.14,1,1,13.13,100,1,13.12,200,2,13.11,100,1,13.10,100,1,13.04,2,1,13.40,0,-10,13.53,0,-1,13.55,0,-1,13.56,0,-1,13.57,0,-1,13.58,0,-1,13.59,0,-2,13.60,0,-2,13.61,0,-2,13.63,0,-3,ARL,0
2025-07-17T16:03:18.868420503Z,2025-07-17T16:03:18.868254768Z,10,2,1108,C,A,10,14.700000000,100,326729821,165735,272610397,13.31,10,1,13.28,1,2,13.27,20,2,13.26,198,2,13.14,1,1,13.13,100,1,13.12,200,2,13.11,100,1,13.10,100,1,13.04,2,1,13.40,0,-10,13.53,0,-1,13.55,0,-1,13.56,0,-1,13.57,0,-1,13.58,0,-1,13.59,0,-2,13.60,0,-2,13.61,0,-2,13.63,0,-3,ARL,0
2025-07-17T16:03:18.868420503Z,2025-07-17T16:03:18.868254768Z,10,2,1108,A,A,10,14.850000000,100,326893961,165735,272610397,13.31,10,1,13.28,1,2,13.27,20,2,13.26,198,2,13.14,1,1,13.13,100,1,13.12,200,2,13.11,100,1,13.10,100,1,13.04,2,1,13.40,0,-10,13.53,0,-1,13.55,0,-1,13.56,0,-1,13.57,0,-1,13.58,0,-1,13.59,0,-2,13.60,0,-2,13.61,0,-2,13.63,0,-3,ARL,0
2025-07-17T16:03:19.191219507Z,2025-07-17T16:03:19.191054306Z,10,2,1108,A,A,10,13.880000000,100,326899125,165201,272614303,13.31,10,1,13.28,1,2,13.27,20,2,13.26,198,2,13.14,1,1,13.13,100,1,13.12,200,2,13.11,100,1,13.10,100,1,13.04,2,1,13.40,0,-10,13.53,0,-1,13.55,0,-1,13.56,0,-1,13.57,0,-1,13.58,0,-1,13.59,0,-2,13.60,0,-2,13.61,0,-2,13.63,0,-3,ARL,0
2025-07-17T16:03:27.436323951Z,2025-07-17T16:03:27.436158395Z,10,2,1108,A,A,10,14.250000000,53,327112281,165556,272788767,13.31,10,1,13.28,1,2,13.27,20,2,13.26,198,2,13.14,1,1,13.13,100,1,13.12,200,2,13.11,100,1,13.10,100,1,13.04,2,1,13.40,0,-10,13.53,0,-1,13.55,0,-1,13.56,0,-1,13.57,0,-1,13.58,0,-1,13.59,0,-2,13.60,0,-2,13.61,0,-2,13.63,0,-3,ARL,0
2025-07-17T16:03:27.436880768Z,2025-07-17T16:03:27.436715001Z,10,2,1108,C,B,10,12.230000000,100,291964745,165767,272788774,13.31,10,1,13.28,1,2,13.27,20,2,13.26,198,2,13.14,1,1,13.13,100,1,13.12,200,2,13.11,100,1,13.10,100,1,13.04,2,1,13.40,0,-10,13.53,0,-1,13.55,0,-1,13.56,0,-1,13.57,0,-1,13.58,0,-1,13.59,0,-2,13.60,0,-2,13.61,0,-2,13.63,0,-3,ARL,0
2025-07-17T16:03:27.436880768Z,2025-07-17T16:03:27.436715001Z,10,2,1108,A,B,10,12.100000000,100,327112289,165767,272788774,13.31,10,1,13.28,1,2,13.27,20,2,13.26,198,2,13.14,1,1,13.13,100,1,13.12,200,2,13.11,100,1,13.10,100,1,13.04,2,1,13.40,0,-10,13.53,0,-1,13.55,0,-1,13.56,0,-1,13.57,0,-1,13.58,0,-1,13.59,0,-2,13.60,0,-2,13.61,0,-2,13.63,0,-3,ARL,0
2025-07-17T16:03:27.438566971Z,2025-07-17T16:03:27.438400828Z,10,2,1108,C,B,10,12.340000000,100,285586113,166143,272788792,13.31,10,1,13.28,1,2,13.27,20,2,13.26,198,2,13.14,1,1,13.13,100,1,13.12,200,2,13.11,100,1,13.10,100,1,13.04,2,1,13.40,0,-10,13.53,0,-1,13.55,0,-1,13.56,0,-1,13.57,0,-1,13.58,0,-1,13.59,0,-2,13.60,0,-2,13.61,0,-2,13.63,0,-3,ARL,0
2025-07-17T16:03:27.438566971Z,2025-07-17T16:03:27.438400828Z,10,2,1108,A,B,10,12.200000000,100,327112385,166143,272788792,13.31,10,1,13.28,1,2,13.27,20,2,13.26,198,2,13.14,1,1,13.13,100,1,13.12,200,2,13.11,100,1,13.10,100,1,13.04,2,1,13.40,0,-10,13.53,0,-1,13.55,0,-1,13.56,0,-1,13.57,0,-1,13.58,0,-1,13.59,0,-2,13.60,0,-2,13.61,0,-2,13.63,0,-3,ARL,0
2025-07-17T16:03:27.438603564Z,2025-07-17T16:03:27.438437969Z,10,2,1108,C,B,10,12.340000000,100,285586189,165595,272788793,13.31,10,1,13.28,1,2,13.27,20,2,13.26,198,2,13.14,1,1,13.13,100,1,13.12,200,2,13.11,100,1,13.10,100,1,13.04,2,1,13.40,0,-10,13.53,0,-1,13.55,0,-1,13.56,0,-1,13.57,0,-1,13.58,0,-1,13.59,0,-2,13.60,0,-2,13.61,0,-2,13.63,0,-3,ARL,0
2025-07-17T16:03:27.438603564Z,2025-07-17T16:03:27.438437969Z,10,2,1108,A,B,10,12.200000000,100,327112393,165595,272788793,13.31,10,1,13.28,1,2,13.27,20,2,13.26,198,2,13.14,1,1,13.13,100,1,13.12,200,2,13.11,100,1,13.10,100,1,13.04,2,1,13.40,0,-10,13.53,0,-1,13.55,0,-1,13.56,0,-1,13.57,0,-1,13.58,0,-1,13.59,0,-2,13.60,0,-2,13.61,0,-2,13.63,0,-3,ARL,0
2025-07-17T16:03:27.454010355Z,2025-07-17T16:03:27.453845141Z,10,2,1108,C,B,10,13.030000000,100,285586293,165214,272788897,13.31,10,1,13.28,1,2,13.27,20,2,13.26,198,2,13.14,1,1,13.13,100,1,13.12,200,2,13.11,100,1,13.10,100,1,13.04,2,1,13.40,0,-10,13.53,0,-1,13.55,0,-1,13.56,0,-1,13.57,0,-1,13.58,0,-1,13.59,0,-2,13.60,0,-2,13.61,0,-2,13.63,0,-3,ARL,0
2025-07-17T16:03:27.454059719Z,2025-07-17T16:03:27.453894425Z,10,2,1108,A,B,10,12.950000000,100,327112565,165294,272788898,13.31,10,1,13.28,1,2,13.27,20,2,13.26,198,2,13.14,1,1,13.13,100,1,13.12,200,2,13.11,100,1,13.10,100,1,13.04,2,1,13.40,0,-10,13.53,0,-1,13.55,0,-1,13.56,0,-1,13.57,0,-1,13.58,0,-1,13.59,0,-2,13.60,0,-2,13.61,0,-2,13.63,0,-3,ARL,0
2025-07-17T16:03:27.454892321Z,2025-07-17T16:03:27.454726901Z,10,2,1108,C,B,10,12.950000000,100,327112565,165420,272788942,13.31,10,1,13.28,1,2,13.27,20,2,13.26,198,2,13.14,1,1,13.13,100,1,13.12,200,2,13.11,100,1,13.10,100,1,13.04,2,1,13.40,0,-10,13.53,0,-1,13.55,0,-1,13.56,0,-1,13.57,0,-1,13.58,0,-1,13.59,0,-2,13.60,0,-2,13.61,0,-2,13.63,0,-3,ARL,0
2025-07-17T16:03:27.454939600Z,2025-07-17T16:03:27.454773691Z,10,2,1108,A,B,10,12.860000000,100,327112577,165909,272788943,13.31,10,1,13.28,1,2,13.27,20,2,13.26,198,2,13.14,1,1,13.13,100,1,13.12,200,2,13.11,100,1,13.10,100,1,13.04,2,1,13.40,0,-10,13.53,0,-1,13.55,0,-1,13.56,0,-1,13.57,0,-1,13.58,0,-1,13.59,0,-2,13.60,0,-2,13.61,0,-2,13.63,0,-3,ARL,0
2025-07-17T16:03:27.517751270Z,2025-07-17T16:03:27.517585374Z,10,2,1108,C,B,10,12.460000000,100,285587281,165896,272790695,13.31,10,1,13.28,1,2,13.27,20,2,13.26,198,2,13.14,1,1,13.13,100,1,13.12,200,2,13.11,100,1,13.10,100,1,13.04,2,1,13.40,0,-10,13.53,0,-1,13.55,0,-1,13.56,0,-1,13.57,0,-1,13.58,0,-1,13.59,0,-2,13.60,0,-2,13.61,0,-2,13.63,0,-3,ARL,0
2025-07-17T16:03:27.517864675Z,2025-07-17T16:03:27.517699408Z,10,2,1108,A,B,10,12.330000000,100,327114465,165267,272790696,13.31,10,1,13.28,1,2,13.27,20,2,13.26,198,2,13.14,1,1,13.13,100,1,13.12,200,2,13.11,100,1,13.10,100,1,13.04,2,1,13.40,0,-10,13.53,0,-1,13.55,0,-1,13.56,0,-1,13.57,0,-1,13.58,0,-1,13.59,0,-2,13.60,0,-2,13.61,0,-2,13.63,0,-3,ARL,0
2025-07-17T16:03:27.536343943Z,2025-07-17T16:03:27.536178718Z,10,2,1108,C,A,10,14.250000000,53,327112281,165225,272791410,13.31,10,1,13.28,1,2,13.27,20,2,13.26,198,2,13.14,1,1,13.13,100,1,13.12,200,2,13.11,100,1,13.10,100,1,13.04,2,1,13.40,0,-10,13.53,0,-1,13.55,0,-1,13.56,0,-1,13.57,0,-1,13.58,0,-1,13.59,0,-2,13.60,0,-2,13.61,0,-2,13.63,0,-3,ARL,0
2025-07-17T16:03:56.548348047Z,2025-07-17T16:03:56.548182793Z,10,2,1108,A,A,10,13.800000000,15,327675057,165254,273208310,13.31,10,1,13.28,1,2,13.27,20,2,13.26,198,2,13.14,1,1,13.13,100,1,13.12,200,2,13.11,100,1,13.10,100,1,13.04,2,1,13.40,0,-10,13.53,0,-1,13.55,0,-1,13.56,0,-1,13.57,0,-1,13.58,0,-1,13.59,0,-2,13.60,0,-2,13.61,0,-2,13.63,0,-3,ARL,0
2025-07-17T16:03:56.548611716Z,2025-07-17T16:03:56.548446336Z,10,2,1108,C,A,10,13.880000000,100,326899125,165380,273208316,13.31,10,1,13.28,1,2,13.27,20,2,13.26,198,2,13.14,1,1,13.13,100,1,13.12,200,2,13.11,100,1,13.10,100,1,13.04,2,1,13.40,0,-10,13.53,0,-1,13.55,0,-1,13.56,0,-1,13.57,0,-1,13.58,0,-1,13.59,0,-2,13.60,0,-2,13.61,0,-2,13.63,0,-3,ARL,0
2025-07-17T16:03:56.548611716Z,2025-07-17T16:03:56.548446336Z,10,2,1108,A,A,10,13.810000000,100,327675065,165380,273208316,13.31,10,1,13.28,1,2,13.27,20,2,13.26,198,2,13.14,1,1,13.13,100,1,13.12,200,2,13.11,100,1,13.10,100,1,13.04,2,1,13.40,0,-10,13.53,0,-1,13.55,0,-1,13.56,0,-1,13.57,0,-1,13.58,0,-1,13.59,0,-2,13.60,0,-2,13.61,0,-2,13.63,0,-3,ARL,0
2025-07-17T16:03:56.549354405Z,2025-07-17T16:03:56.549188993Z,10,2,1108,C,A,10,14.950000000,100,326892717,165412,273208325,13.31,10,1,13.28,1,2,13.27,20,2,13.26,198,2,13.14,1,1,13.13,100,1,13.12,200,2,13.11,100,1,13.10,100,1,13.04,2,1,13.40,0,-10,13.53,0,-1,13.55,0,-1,13.56,0,-1,13.57,0,-1,13.58,0,-1,13.59,0,-2,13.60,0,-2,13.61,0,-2,13.63,0,-3,ARL,0
2025-07-17T16:03:56.549354405Z,2025-07-17T16:03:56.549188993Z,10,2,1108,A,A,10,14.880000000,100,327675093,165412,273208325,13.31,10,1,13.28,1,2,13.27,20,2,13.26,198,2,13.14,1,1,13.13,100,1,13.12,200,2,13.11,100,1,13.10,100,1,13.04,2,1,13.40,0,-10,13.53,0,-1,13.55,0,-1,13.56,0,-1,13.57,0,-1,13.58,0,-1,13.59,0,-2,13.60,0,-2,13.61,0,-2,13.63,0,-3,ARL,0
2025-07-17T16:04:06.233858611Z,2025-07-17T16:04:06.233692491Z,10,2,1108,C,A,10,14.760000000,100,326892825,166120,273345719,13.31,10,1,13.28,1,2,13.27,20,2,13.26,198,2,13.14,1,1,13.13,100,1,13.12,200,2,13.11,100,1,13.10,100,1,13.04,2,1,13.40,0,-10,13.53,0,-1,13.55,0,-1,13.56,0,-1,13.57,0,-1,13.58,0,-1,13.59,0,-2,13.60,0,-2,13.61,0,-2,13.63,0,-3,ARL,0
2025-07-17T16:04:06.233858611Z,2025-07-17T16:04:06.233692491Z,10,2,1108,A,A,10,14.640000000,100,327856297,166120,273345719,13.31,10,1,13.28,1,2,13.27,20,2,13.26,198,2,13.14,1,1,13.13,100,1,13.12,200,2,13.11,100,1,13.10,100,1,13.04,2,1,13.40,0,-10,13.53,0,-1,13.55,0,-1,13.56,0,-1,13.57,0,-1,13.58,0,-1,13.59,0,-2,13.60,0,-2,13.61,0,-2,13.63,0,-3,ARL,0
2025-07-17T16:04:06.234600198Z,2025-07-17T16:04:06.234433294Z,10,2,1108,C,A,10,14.760000000,100,326892817,166904,273345721,13.31,10,1,13.28,1,2,13.27,20,2,13.26,198,2,13.14,1,1,13.13,100,1,13.12,200,2,13.11,100,1,13.10,100,1,13.04,2,1,13.40,0,-10,13.53,0,-1,13.55,0,-1,13.56,0,-1,13.57,0,-1,13.58,0,-1,13.59,0,-2,13.60,0,-2,13.61,0,-2,13.63,0,-3,ARL,0
2025-07-17T16:04:06.234600198Z,2025-07-17T16:04:06.234433294Z,10,2,1108,A,A,10,14.640000000,100,327856309,166904,273345721,13.31,10,1,13.28,1,2,13.27,20,2,13.26,198,2,13.14,1,1,13.13,100,1,13.12,200,2,13.11,100,1,13.10,100,1,13.04,2,1,13.40,0,-10,13.53,0,-1,13.55,0,-1,13.56,0,-1,13.57,0,-1,13.58,0,-1,13.59,0,-2,13.60,0,-2,13.61,0,-2,13.63,0,-3,ARL,0
2025-07-17T16:04:06.510914101Z,2025-07-17T16:04:06.510748731Z,10,2,1108,A,A,10,13.720000000,15,327863853,165370,273352664,13.31,10,1,13.28,1,2,13.27,20,2,13.26,198,2,13.14,1,1,13.13,100,1,13.12,200,2,13.11,100,1,13.10,100,1,13.04,2,1,13.40,0,-10,13.53,0,-1,13.55,0,-1,13.56,0,-1,13.57,0,-1,13.58,0,-1,13.59,0,-2,13.60,0,-2,13.61,0,-2,13.63,0,-3,ARL,0
2025-07-17T16:04:06.512413102Z,2025-07-17T16:04:06.512244746Z,10,2,1108,C,A,10,13.810000000,100,327675065,168356,273352888,13.31,10,1,13.28,1,2,13.27,20,2,13.26,198,2,13.14,1,1,13.13,100,1,13.12,200,2,13.11,100,1,13.10,100,1,13.04,2,1,13.40,0,-10,13.53,0,-1,13.55,0,-1,13.56,0,-1,13.57,0,-1,13.58,0,-1,13.59,0,-2,13.60,0,-2,13.61,0,-2,13.63,0,-3,ARL,0
2025-07-17T16:04:06.512413102Z,2025-07-17T16:04:06.512244746Z,10,2,1108,A,A,10,13.730000000,100,327864137,168356,273352888,13.31,10,1,13.28,1,2,13.27,20,2,13.26,198,2,13.14,1,1,13.13,100,1,13.12,200,2,13.11,100,1,13.10,100,1,13.04,2,1,13.40,0,-10,13.53,0,-1,13.55,0,-1,13.56,0,-1,13.57,0,-1,13.58,0,-1,13.59,0,-2,13.60,0,-2,13.61,0,-2,13.63,0,-3,ARL,0
2025-07-17T16:04:06.513675299Z,2025-07-17T16:04:06.513497276Z,10,2,1108,C,A,10,14.880000000,100,327675093,178023,273353923,13.31,10,1,13.28,1,2,13.27,20,2,13.26,198,2,13.14,1,1,13.13,100,1,13.12,200,2,13.11,100,1,13.10,100,1,13.04,2,1,13.40,0,-10,13.53,0,-1,13.55,0,-1,13.56,0,-1,13.57,0,-1,13.58,0,-1,13.59,0,-2,13.60,0,-2,13.61,0,-2,13.63,0,-3,ARL,0
2025-07-17T16:04:06.513675299Z,2025-07-17T16:04:06.513497276Z,10,2,1108,A,A,10,14.790000000,100,327864893,178023,273353923,13.31,10,1,13.28,1,2,13.27,20,2,13.26,198,2,13.14,1,1,13.13,100,1,13.12,200,2,13.11,100,1,13.10,100,1,13.04,2,1,13.40,0,-10,13.53,0,-1,13.55,0,-1,13.56,0,-1,13.57,0,-1,13.58,0,-1,13.59,0,-2,13.60,0,-2,13.61,0,-2,13.63,0,-3,ARL,0
2025-07-17T16:04:06.522853161Z,2025-07-17T16:04:06.522687474Z,10,2,1108,C,A,10,14.850000000,100,326892721,165687,273357758,13.31,10,1,13.28,1,2,13.27,20,2,13.26,198,2,13.14,1,1,13.13,100,1,13.12,200,2,13.11,100,1,13.10,100,1,13.04,2,1,13.40,0,-10,13.53,0,-1,13.55,0,-1,13.56,0,-1,13.57,0,-1,13.58,0,-1,13.59,0,-2,13.60,0,-2,13.61,0,-2,13.63,0,-3,ARL,0
2025-07-17T16:04:06.522853161Z,2025-07-17T16:04:06.522687474Z,10,2,1108,A,A,10,14.700000000,100,327868421,165687,273357758,13.31,10,1,13.28,1,2,13.27,20,2,13.26,198,2,13.14,1,1,13.13,100,1,13.12,200,2,13.11,100,1,13.10,100,1,13.04,2,1,13.40,0,-10,13.53,0,-1,13.55,0,-1,13.56,0,-1,13.57,0,-1,13.58,0,-1,13.59,0,-2,13.60,0,-2,13.61,0,-2,13.63,0,-3,ARL,0
2025-07-17T16:04:06.525550815Z,2025-07-17T16:04:06.525385108Z,10,2,1108,C,A,10,14.150000000,100,326893213,165707,273358260,13.31,10,1,13.28,1,2,13.27,20,2,13.26,198,2,13.14,1,1,13.13,100,1,13.12,200,2,13.11,100,1,13.10,100,1,13.04,2,1,13.40,0,-10,13.53,0,-1,13.55,0,-1,13.56,0,-1,13.57,0,-1,13.58,0,-1,13.59,0,-2,13.60,0,-2,13.61,0,-2,13.63,0,-3,ARL,0
2025-07-17T16:04:06.525608746Z,2025-07-17T16:04:06.525442486Z,10,2,1108,A,A,10,14.000000000,100,327869193,166260,273358273,13.31,10,1,13.28,1,2,13.27,20,2,13.26,198,2,13.14,1,1,13.13,100,1,13.12,200,2,13.11,100,1,13.10,100,1,13.04,2,1,13.40,0,-10,13.53,0,-1,13.55,0,-1,13.56,0,-1,13.57,0,-1,13.58,0,-1,13.59,0,-2,13.60,0,-2,13.61,0,-2,13.63,0,-3,ARL,0
2025-07-17T16:04:06.528210755Z,2025-07-17T16:04:06.528043934Z,10,2,1108,C,A,10,14.660000000,100,326892885,166821,273358598,13.31,10,1,13.28,1,2,13.27,20,2,13.26,198,2,13.14,1,1,13.13,100,1,13.12,200,2,13.11,100,1,13.10,100,1,13.04,2,1,13.40,0,-10,13.53,0,-1,13.55,0,-1,13.56,0,-1,13.57,0,-1,13.58,0,-1,13.59,0,-2,13.60,0,-2,13.61,0,-2,13.63,0,-3,ARL,0
2025-07-17T16:04:06.528329048Z,2025-07-17T16:04:06.528161631Z,10,2,1108,A,A,10,14.520000000,100,327869529,167417,273358642,13.31,10,1,13.28,1,2,13.27,20,2,13.26,198,2,13.14,1,1,13.13,100,1,13.12,200,2,13.11,100,1,13.10,100,1,13.04,2,1,13.40,0,-10,13.53,0,-1,13.55,0,-1,13.56,0,-1,13.57,0,-1,13.58,0,-1,13.59,0,-2,13.60,0,-2,13.61,0,-2,13.63,0,-3,ARL,0
2025-07-17T16:04:06.543480312Z,2025-07-17T16:04:06.543314706Z,10,2,1108,C,A,10,17.620000000,100,326892921,165606,273359491,13.31,10,1,13.28,1,2,13.27,20,2,13.26,198,2,13.14,1,1,13.13,100,1,13.12,200,2,13.11,100,1,13.10,100,1,13.04,2,1,13.40,0,-10,13.53,0,-1,13.55,0,-1,13.56,0,-1,13.57,0,-1,13.58,0,-1,13.59,0,-2,13.60,0,-2,13.61,0,-2,13.63,0,-3,ARL,0
2025-07-17T16:04:06.543480312Z,2025-07-17T16:04:06.543314706Z,10,2,1108,A,A,10,17.440000000,100,327870217,165606,273359491,13.31,10,1,13.28,1,2,13.27,20,2,13.26,198,2,13.14,1,1,13.13,100,1,13.12,200,2,13.11,100,1,13.10,100,1,13.04,2,1,13.40,0,-10,13.53,0,-1,13.55,0,-1,13.56,0,-1,13.57,0,-1,13.58,0,-1,13.59,0,-2,13.60,0,-2,13.61,0,-2,13.63,0,-3,ARL,0
2025-07-17T16:04:06.548945239Z,2025-07-17T16:04:06.548778200Z,10,2,1108,C,A,10,15.960000000,100,326892889,167039,273359672,13.31,10,1,13.28,1,2,13.27,20,2,13.26,198,2,13.14,1,1,13.13,100,1,13.12,200,2,13.11,100,1,13.10,100,1,13.04,2,1,13.40,0,-10,13.53,0,-1,13.55,0,-1,13.56,0,-1,13.57,0,-1,13.58,0,-1,13.59,0,-2,13.60,0,-2,13.61,0,-2,13.63,0,-3,ARL,0
2025-07-17T16:04:06.548945239Z,2025-07-17T16:04:06.548778200Z,10,2,1108,A,A,10,15.790000000,100,327870361,167039,273359672,13.31,10,1,13.28,1,2,13.27,20,2,13.26,198,2,13.14,1,1,13.13,100,1,13.12,200,2,13.11,100,1,13.10,100,1,13.04,2,1,13.40,0,-10,13.53,0,-1,13.55,0,-1,13.56,0,-1,13.57,0,-1,13.58,0,-1,13.59,0,-2,13.60,0,-2,13.61,0,-2,13.63,0,-3,ARL,0
2025-07-17T16:04:06.648109829Z,2025-07-17T16:04:06.647944313Z,10,2,1108,C,A,10,14.850000000,100,326893961,165516,273361957,13.31,10,1,13.28,1,2,13.27,20,2,13.26,198,2,13.14,1,1,13.13,100,1,13.12,200,2,13.11,100,1,13.10,100,1,13.04,2,1,13.40,0,-10,13.53,0,-1,13.55,0,-1,13.56,0,-1,13.57,0,-1,13.58,0,-1,13.59,0,-2,13.60,0,-2,13.61,0,-2,13.63,0,-3,ARL,0
2025-07-17T16:04:06.648109829Z,2025-07-17T16:04:06.647944313Z,10,2,1108,A,A,10,14.700000000,100,327873009,165516,273361957,13.31,10,1,13.28,1,2,13.27,20,2,13.26,198,2,13.14,1,1,13.13,100,1,13.12,200,2,13.11,100,1,13.10,100,1,13.04,2,1,13.40,0,-10,13.53,0,-1,13.55,0,-1,13.56,0,-1,13.57,0,-1,13.58,0,-1,13.59,0,-2,13.60,0,-2,13.61,0,-2,13.63,0,-3,ARL,0
2025-07-17T16:04:06.805500523Z,2025-07-17T16:04:06.805335354Z,10,2,1108,C,A,10,13.720000000,15,327863853,165169,273364089,13.31,10,1,13.28,1,2,13.27,20,2,13.26,198,2,13.14,1,1,13.13,100,1,13.12,200,2,13.11,100,1,13.10,100,1,13.04,2,1,13.40,0,-10,13.53,0,-1,13.55,0,-1,13.56,0,-1,13.57,0,-1,13.58,0,-1,13.59,0,-2,13.60,0,-2,13.61,0,-2,13.63,0,-3,ARL,0
2025-07-17T16:04:06.806217584Z,2025-07-17T16:04:06.806052396Z,10,2,1108,C,A,10,13.800000000,15,327675057,165188,273364090,13.31,10,1,13.28,1,2,13.27,20,2,13.26,198,2,13.14,1,1,13.13,100,1,13.12,200,2,13.11,100,1,13.10,100,1,13.04,2,1,13.40,0,-10,13.53,0,-1,13.55,0,-1,13.56,0,-1,13.57,0,-1,13.58,0,-1,13.59,0,-2,13.60,0,-2,13.61,0,-2,13.63,0,-3,ARL,0
2025-07-17T16:04:21.277142662Z,2025-07-17T16:04:21.276976977Z,10,2,1108,A,A,10,13.770000000,100,328239293,165685,273687857,13.31,10,1,13.28,1,2,13.27,20,2,13.26,198,2,13.14,1,1,13.13,100,1,13.12,200,2,13.11,100,1,13.10,100,1,13.04,2,1,13.40,0,-10,13.53,0,-1,13.55,0,-1,13.56,0,-1,13.57,0,-1,13.58,0,-1,13.59,0,-2,13.60,0,-2,13.61,0,-2,13.63,0,-3,ARL,0
2025-07-17T16:04:27.791055146Z,2025-07-17T16:04:27.790889618Z,10,2,1108,C,A,10,14.030000000,2,326159041,165528,273775264,13.31,10,1,13.28,1,2,13.27,20,2,13.26,198,2,13.14,1,1,13.13,100,1,13.12,200,2,13.11,100,1,13.10,100,1,13.04,2,1,13.40,0,-10,13.53,0,-1,13.55,0,-1,13.56,0,-1,13.57,0,-1,13.58,0,-1,13.59,0,-2,13.60,0,-2,13.61,0,-2,13.63,0,-3,ARL,0
2025-07-17T16:04:27.791055146Z,2025-07-17T16:04:27.790889618Z,10,2,1108,A,A,10,13.940000000,2,328351217,165528,273775264,13.31,10,1,13.28,1,2,13.27,20,2,13.26,198,2,13.14,1,1,13.13,100,1,13.12,200,2,13.11,100,1,13.10,100,1,13.04,2,1,13.40,0,-10,13.53,0,-1,13.55,0,-1,13.56,0,-1,13.57,0,-1,13.58,0,-1,13.59,0,-2,13.60,0,-2,13.61,0,-2,13.63,0,-3,ARL,0
2025-07-17T16:04:31.232053154Z,2025-07-17T16:04:31.231887784Z,10,2,1108,A,A,10,13.680000000,15,328437797,165370,273846737,13.31,10,1,13.28,1,2,13.27,20,2,13.26,198,2,13.14,1,1,13.13,100,1,13.12,200,2,13.11,100,1,13.10,100,1,13.04,2,1,13.40,0,-10,13.53,0,-1,13.55,0,-1,13.56,0,-1,13.57,0,-1,13.58,0,-1,13.59,0,-2,13.60,0,-2,13.61,0,-2,13.63,0,-3,ARL,0
2025-07-17T16:04:31.232606440Z,2025-07-17T16:04:31.232440773Z,10,2,1108,A,A,10,13.720000000,100,328437805,165667,273846745,13.31,10,1,13.28,1,2,13.27,20,2,13.26,198,2,13.14,1,1,13.13,100,1,13.12,200,2,13.11,100,1,13.10,100,1,13.04,2,1,13.40,0,-10,13.53,0,-1,13.55,0,-1,13.56,0,-1,13.57,0,-1,13.58,0,-1,13.59,0,-2,13.60,0,-2,13.61,0,-2,13.63,0,-3,ARL,0
2025-07-17T16:04:31.246681162Z,2025-07-17T16:04:31.246515467Z,10,2,1108,C,A,10,13.770000000,100,328239293,165695,273847000,13.31,10,1,13.28,1,2,13.27,20,2,13.26,198,2,13.14,1,1,13.13,100,1,13.12,200,2,13.11,100,1,13.10,100,1,13.04,2,1,13.40,0,-10,13.53,0,-1,13.55,0,-1,13.56,0,-1,13.57,0,-1,13.58,0,-1,13.59,0,-2,13.60,0,-2,13.61,0,-2,13.63,0,-3,ARL,0
2025-07-17T16:04:32.836802111Z,2025-07-17T16:04:32.836635838Z,10,2,1108,C,A,10,13.730000000,100,327864137,166273,273882084,13.31,10,1,13.28,1,2,13.27,20,2,13.26,198,2,13.14,1,1,13.13,100,1,13.12,200,2,13.11,100,1,13.10,100,1,13.04,2,1,13.40,0,-10,13.53,0,-1,13.55,0,-1,13.56,0,-1,13.57,0,-1,13.58,0,-1,13.59,0,-2,13.60,0,-2,13.61,0,-2,13.63,0,-3,ARL,0
2025-07-17T16:04:32.836802111Z,2025-07-17T16:04:32.836635838Z,10,2,1108,A,A,10,13.690000000,100,328489153,166273,273882084,13.31,10,1,13.28,1,2,13.27,20,2,13.26,198,2,13.14,1,1,13.13,100,1,13.12,200,2,13.11,100,1,13.10,100,1,13.04,2,1,13.40,0,-10,13.53,0,-1,13.55,0,-1,13.56,0,-1,13.57,0,-1,13.58,0,-1,13.59,0,-2,13.60,0,-2,13.61,0,-2,13.63,0,-3,ARL,0
2025-07-17T16:04:32.837165431Z,2025-07-17T16:04:32.837000154Z,10,2,1108,C,B,10,13.120000000,100,325718833,165277,273882201,13.31,10,1,13.28,1,2,13.27,20,2,13.26,198,2,13.14,1,1,13.13,100,1,13.12,200,2,13.11,100,1,13.10,100,1,13.04,2,1,13.40,0,-10,13.53,0,-1,13.55,0,-1,13.56,0,-1,13.57,0,-1,13.58,0,-1,13.59,0,-2,13.60,0,-2,13.61,0,-2,13.63,0,-3,ARL,0
2025-07-17T16:04:32.837169083Z,2025-07-17T16:04:32.837002825Z,10,2,1108,C,B,10,13.120000000,100,325718837,166258,273882202,13.31,10,1,13.28,1,2,13.27,20,2,13.26,198,2,13.14,1,1,13.13,100,1,13.12,200,2,13.11,100,1,13.10,100,1,13.04,2,1,13.40,0,-10,13.53,0,-1,13.55,0,-1,13.56,0,-1,13.57,0,-1,13.58,0,-1,13.59,0,-2,13.60,0,-2,13.61,0,-2,13.63,0,-3,ARL,0
2025-07-17T16:04:32.837179568Z,2025-07-17T16:04:32.837013456Z,10,2,1108,A,B,10,12.980000000,100,328489377,166112,273882207,13.31,10,1,13.28,1,2,13.27,20,2,13.26,198,2,13.14,1,1,13.13,100,1,13.12,200,2,13.11,100,1,13.10,100,1,13.04,2,1,13.40,0,-10,13.53,0,-1,13.55,0,-1,13.56,0,-1,13.57,0,-1,13.58,0,-1,13.59,0,-2,13.60,0,-2,13.61,0,-2,13.63,0,-3,ARL,0
2025-07-17T16:04:32.837181582Z,2025-07-17T16:04:32.837016087Z,10,2,1108,A,B,10,12.980000000,100,328489385,165495,273882208,13.31,10,1,13.28,1,2,13.27,20,2,13.26,198,2,13.14,1,1,13.13,100,1,13.12,200,2,13.11,100,1,13.10,100,1,13.04,2,1,13.40,0,-10,13.53,0,-1,13.55,0,-1,13.56,0,-1,13.57,0,-1,13.58,0,-1,13.59,0,-2,13.60,0,-2,13.61,0,-2,13.63,0,-3,ARL,0
2025-07-17T16:04:32.837536434Z,2025-07-17T16:04:32.837369811Z,10,2,1108,C,A,10,14.790000000,100,327864893,166623,273882286,13.31,10,1,13.28,1,2,13.27,20,2,13.26,198,2,13.14,1,1,13.13,100,1,13.12,200,2,13.11,100,1,13.10,100,1,13.04,2,1,13.40,0,-10,13.53,0,-1,13.55,0,-1,13.56,0,-1,13.57,0,-1,13.58,0,-1,13.59,0,-2,13.60,0,-2,13.61,0,-2,13.63,0,-3,ARL,0
2025-07-17T16:04:32.837536434Z,2025-07-17T16:04:32.837369811Z,10,2,1108,A,A,10,14.750000000,100,328489481,166623,273882286,13.31,10,1,13.28,1,2,13.27,20,2,13.26,198,2,13.14,1,1,13.13,100,1,13.12,200,2,13.11,100,1,13.10,100,1,13.04,2,1,13.40,0,-10,13.53,0,-1,13.55,0,-1,13.56,0,-1,13.57,0,-1,13.58,0,-1,13.59,0,-2,13.60,0,-2,13.61,0,-2,13.63,0,-3,ARL,0
2025-07-17T16:04:36.810717146Z,2025-07-17T16:04:36.810551890Z,10,2,1108,A,A,10,13.650000000,15,328603377,165256,273963456,13.31,10,1,13.28,1,2,13.27,20,2,13.26,198,2,13.14,1,1,13.13,100,1,13.12,200,2,13.11,100,1,13.10,100,1,13.04,2,1,13.40,0,-10,13.53,0,-1,13.55,0,-1,13.56,0,-1,13.57,0,-1,13.58,0,-1,13.59,0,-2,13.60,0,-2,13.61,0,-2,13.63,0,-3,ARL,0
2025-07-17T16:04:37.026937493Z,2025-07-17T16:04:37.026771973Z,10,2,1108,A,A,10,13.690000000,100,328606289,165520,273965417,13.31,10,1,13.28,1,2,13.27,20,2,13.26,198,2,13.14,1,1,13.13,100,1,13.12,200,2,13.11,100,1,13.10,100,1,13.04,2,1,13.40,0,-10,13.53,0,-1,13.55,0,-1,13.56,0,-1,13.57,0,-1,13.58,0,-1,13.59,0,-2,13.60,0,-2,13.61,0,-2,13.63,0,-3,ARL,0
2025-07-17T16:04:37.033554557Z,2025-07-17T16:04:37.033389265Z,10,2,1108,C,A,10,13.720000000,100,328437805,165292,273965562,13.31,10,1,13.28,1,2,13.27,20,2,13.26,198,2,13.14,1,1,13.13,100,1,13.12,200,2,13.11,100,1,13.10,100,1,13.04,2,1,13.40,0,-10,13.53,0,-1,13.55,0,-1,13.56,0,-1,13.57,0,-1,13.58,0,-1,13.59,0,-2,13.60,0,-2,13.61,0,-2,13.63,0,-3,ARL,0
2025-07-17T16:04:37.542961161Z,2025-07-17T16:04:37.542795711Z,10,2,1108,C,A,10,13.690000000,100,328489153,165450,273971021,13.31,10,1,13.28,1,2,13.27,20,2,13.26,198,2,13.14,1,1,13.13,100,1,13.12,200,2,13.11,100,1,13.10,100,1,13.04,2,1,13.40,0,-10,13.53,0,-1,13.55,0,-1,13.56,0,-1,13.57,0,-1,13.58,0,-1,13.59,0,-2,13.60,0,-2,13.61,0,-2,13.63,0,-3,ARL,0
2025-07-17T16:04:37.542961161Z,2025-07-17T16:04:37.542795711Z,10,2,1108,A,A,10,13.660000000,100,328614509,165450,273971021,13.31,10,1,13.28,1,2,13.27,20,2,13.26,198,2,13.14,1,1,13.13,100,1,13.12,200,2,13.11,100,1,13.10,100,1,13.04,2,1,13.40,0,-10,13.53,0,-1,13.55,0,-1,13.56,0,-1,13.57,0,-1,13.58,0,-1,13.59,0,-2,13.60,0,-2,13.61,0,-2,13.63,0,-3,ARL,0
2025-07-17T16:04:37.543230680Z,2025-07-17T16:04:37.543063240Z,10,2,1108,C,A,10,13.870000000,100,326730517,167440,273971035,13.31,10,1,13.28,1,2,13.27,20,2,13.26,198,2,13.14,1,1,13.13,100,1,13.12,200,2,13.11,100,1,13.10,100,1,13.04,2,1,13.40,0,-10,13.53,0,-1,13.55,0,-1,13.56,0,-1,13.57,0,-1,13.58,0,-1,13.59,0,-2,13.60,0,-2,13.61,0,-2,13.63,0,-3,ARL,0
2025-07-17T16:04:37.543230680Z,2025-07-17T16:04:37.543064690Z,10,2,1108,C,A,10,13.870000000,100,326730521,165990,273971037,13.31,10,1,13.28,1,2,13.27,20,2,13.26,198,2,13.14,1,1,13.13,100,1,13.12,200,2,13.11,100,1,13.10,100,1,13.04,2,1,13.40,0,-10,13.53,0,-1,13.55,0,-1,13.56,0,-1,13.57,0,-1,13.58,0,-1,13.59,0,-2,13.60,0,-2,13.61,0,-2,13.63,0,-3,ARL,0
2025-07-17T16:04:37.543242390Z,2025-07-17T16:04:37.543077174Z,10,2,1108,A,A,10,13.800000000,100,328614525,165216,273971040,13.31,10,1,13.28,1,2,13.27,20,2,13.26,198,2,13.14,1,1,13.13,100,1,13.12,200,2,13.11,100,1,13.10,100,1,13.04,2,1,13.40,0,-10,13.53,0,-1,13.55,0,-1,13.56,0,-1,13.57,0,-1,13.58,0,-1,13.59,0,-2,13.60,0,-2,13.61,0,-2,13.63,0,-3,ARL,0
2025-07-17T16:04:37.543244193Z,2025-07-17T16:04:37.543078532Z,10,2,1108,A,A,10,13.800000000,100,328614529,165661,273971041,13.31,10,1,13.28,1,2,13.27,20,2,13.26,198,2,13.14,1,1,13.13,100,1,13.12,200,2,13.11,100,1,13.10,100,1,13.04,2,1,13.40,0,-10,13.53,0,-1,13.55,0,-1,13.56,0,-1,13.57,0,-1,13.58,0,-1,13.59,0,-2,13.60,0,-2,13.61,0,-2,13.63,0,-3,ARL,0
2025-07-17T16:04:37.549684713Z,2025-07-17T16:04:37.549519006Z,10,2,1108,C,A,10,14.000000000,100,327869193,165707,273973481,13.31,10,1,13.28,1,2,13.27,20,2,13.26,198,2,13.14,1,1,13.13,100,1,13.12,200,2,13.11,100,1,13.10,100,1,13.04,2,1,13.40,0,-10,13.53,0,-1,13.55,0,-1,13.56,0,-1,13.57,0,-1,13.58,0,-1,13.59,0,-2,13.60,0,-2,13.61,0,-2,13.63,0,-3,ARL,0
2025-07-17T16:04:37.549735824Z,2025-07-17T16:04:37.549570649Z,10,2,1108,A,A,10,13.930000000,100,328616925,165175,273973485,13.31,10,1,13.28,1,2,13.27,20,2,13.26,198,2,13.14,1,1,13.13,100,1,13.12,200,2,13.11,100,1,13.10,100,1,13.04,2,1,13.40,0,-10,13.53,0,-1,13.55,0,-1,13.56,0,-1,13.57,0,-1,13.58,0,-1,13.59,0,-2,13.60,0,-2,13.61,0,-2,13.63,0,-3,ARL,0
2025-07-17T16:04:44.524526545Z,2025-07-17T16:04:44.524360626Z,10,2,1108,C,A,10,13.680000000,15,328437797,165919,274066152,13.31,10,1,13.28,1,2,13.27,20,2,13.26,198,2,13.14,1,1,13.13,100,1,13.12,200,2,13.11,100,1,13.10,100,1,13.04,2,1,13.40,0,-10,13.53,0,-1,13.55,0,-1,13.56,0,-1,13.57,0,-1,13.58,0,-1,13.59,0,-2,13.60,0,-2,13.61,0,-2,13.63,0,-3,ARL,0
2025-07-17T16:04:45.528000143Z,2025-07-17T16:04:45.527835033Z,10,2,1108,A,A,10,13.630000000,15,328780565,165110,274088918,13.31,10,1,13.28,1,2,13.27,20,2,13.26,198,2,13.14,1,1,13.13,100,1,13.12,200,2,13.11,100,1,13.10,100,1,13.04,2,1,13.40,0,-10,13.53,0,-1,13.55,0,-1,13.56,0,-1,13.57,0,-1,13.58,0,-1,13.59,0,-2,13.60,0,-2,13.61,0,-2,13.63,0,-3,ARL,0
2025-07-17T16:04:45.528629613Z,2025-07-17T16:04:45.528464092Z,10,2,1108,C,A,10,14.640000000,100,327856309,165521,274088922,13.31,10,1,13.28,1,2,13.27,20,2,13.26,198,2,13.14,1,1,13.13,100,1,13.12,200,2,13.11,100,1,13.10,100,1,13.04,2,1,13.40,0,-10,13.53,0,-1,13.55,0,-1,13.56,0,-1,13.57,0,-1,13.58,0,-1,13.59,0,-2,13.60,0,-2,13.61,0,-2,13.63,0,-4,ARL,0
2025-07-17T16:04:45.528629613Z,2025-07-17T16:04:45.528464092Z,10,2,1108,A,A,10,14.520000000,100,328780577,165521,274088922,13.31,10,1,13.28,1,2,13.27,20,2,13.26,198,2,13.14,1,1,13.13,100,1,13.12,200,2,13.11,100,1,13.10,100,1,13.04,2,1,13.40,0,-10,13.53,0,-1,13.55,0,-1,13.56,0,-1,13.57,0,-1,13.58,0,-1,13.59,0,-2,13.60,0,-2,13.61,0,-2,13.63,0,-4,ARL,0
2025-07-17T16:04:45.530418278Z,2025-07-17T16:04:45.530252804Z,10,2,1108,C,A,10,14.640000000,100,327856297,165474,274088937,13.31,10,1,13.28,1,2,13.27,20,2,13.26,198,2,13.14,1,1,13.13,100,1,13.12,200,2,13.11,100,1,13.10,100,1,13.04,2,1,13.40,0,-10,13.53,0,-1,13.55,0,-1,13.56,0,-1,13.57,0,-1,13.58,0,-1,13.59,0,-2,13.60,0,-2,13.61,0,-2,13.63,0,-4,ARL,0
2025-07-17T16:04:45.530418278Z,2025-07-17T16:04:45.530252804Z,10,2,1108,A,A,10,14.520000000,100,328780597,165474,274088937,13.31,10,1,13.28,1,2,13.27,20,2,13.26,198,2,13.14,1,1,13.13,100,1,13.12,200,2,13.11,100,1,13.10,100,1,13.04,2,1,13.40,0,-10,13.53,0,-1,13.55,0,-1,13.56,0,-1,13.57,0,-1,13.58,0,-1,13.59,0,-2,13.60,0,-2,13.61,0,-2,13.63,0,-4,ARL,0
2025-07-17T16:04:45.533067029Z,2025-07-17T16:04:45.532901874Z,10,2,1108,C,A,10,13.660000000,100,328614509,165155,274088955,13.31,10,1,13.28,1,2,13.27,20,2,13.26,198,2,13.14,1,1,13.13,100,1,13.12,200,2,13.11,100,1,13.10,100,1,13.04,2,1,13.40,0,-10,13.53,0,-1,13.55,0,-1,13.56,0,-1,13.57,0,-1,13.58,0,-1,13.59,0,-2,13.60,0,-2,13.61,0,-2,13.63,0,-4,ARL,0
2025-07-17T16:04:45.533067029Z,2025-07-17T16:04:45.532901874Z,10,2,1108,A,A,10,13.640000000,100,328780669,165155,274088955,13.31,10,1,13.28,1,2,13.27,20,2,13.26,198,2,13.14,1,1,13.13,100,1,13.12,200,2,13.11,100,1,13.10,100,1,13.04,2,1,13.40,0,-10,13.53,0,-1,13.55,0,-1,13.56,0,-1,13.57,0,-1,13.58,0,-1,13.59,0,-2,13.60,0,-2,13.61,0,-2,13.63,0,-4,ARL,0
2025-07-17T16:04:45.533804768Z,2025-07-17T16:04:45.533639142Z,10,2,1108,C,A,10,14.750000000,100,328489481,165626,274088957,13.31,10,1,13.28,1,2,13.27,20,2,13.26,198,2,13.14,1,1,13.13,100,1,13.12,200,2,13.11,100,1,13.10,100,1,13.04,2,1,13.40,0,-10,13.53,0,-1,13.55,0,-1,13.56,0,-1,13.57,0,-1,13.58,0,-1,13.59,0,-2,13.60,0,-2,13.61,0,-2,13.63,0,-4,ARL,0
2025-07-17T16:04:45.533804768Z,2025-07-17T16:04:45.533639142Z,10,2,1108,A,A,10,14.700000000,100,328780685,165626,274088957,13.31,10,1,13.28,1,2,13.27,20,2,13.26,198,2,13.14,1,1,13.13,100,1,13.12,200,2,13.11,100,1,13.10,100,1,13.04,2,1,13.40,0,-10,13.53,0,-1,13.55,0,-1,13.56,0,-1,13.57,0,-1,13.58,0,-1,13.59,0,-2,13.60,0,-2,13.61,0,-2,13.63,0,-4,ARL,0
2025-07-17T16:04:45.533870711Z,2025-07-17T16:04:45.533705428Z,10,2,1108,A,A,10,13.670000000,100,328780689,165283,274088959,13.31,10,1,13.28,1,2,13.27,20,2,13.26,198,2,13.14,1,1,13.13,100,1,13.12,200,2,13.11,100,1,13.10,100,1,13.04,2,1,13.40,0,-10,13.53,0,-1,13.55,0,-1,13.56,0,-1,13.57,0,-1,13.58,0,-1,13.59,0,-2,13.60,0,-2,13.61,0,-2,13.63,0,-4,ARL,0
2025-07-17T16:04:45.563137443Z,2025-07-17T16:04:45.562972204Z,10,2,1108,C,A,10,13.690000000,100,328606289,165239,274089319,13.31,10,1,13.28,1,2,13.27,20,2,13.26,198,2,13.14,1,1,13.13,100,1,13.12,200,2,13.11,100,1,13.10,100,1,13.04,2,1,13.40,0,-10,13.53,0,-1,13.55,0,-1,13.56,0,-1,13.57,0,-1,13.58,0,-1,13.59,0,-2,13.60,0,-2,13.61,0,-2,13.63,0,-4,ARL,0
2025-07-17T16:04:56.809749973Z,2025-07-17T16:04:56.809584701Z,10,2,1108,C,A,10,13.650000000,15,328603377,165272,274293432,13.31,10,1,13.28,1,2,13.27,20,2,13.26,198,2,13.14,1,1,13.13,100,1,13.12,200,2,13.11,100,1,13.10,100,1,13.04,2,1,13.40,0,-10,13.53,0,-1,13.55,0,-1,13.56,0,-1,13.57,0,-1,13.58,0,-1,13.59,0,-2,13.60,0,-2,13.61,0,-2,13.63,0,-4,ARL,0
2025-07-17T16:04:57.827079009Z,2025-07-17T16:04:57.826913717Z,10,2,1108,A,A,10,13.610000000,15,329068341,165292,274310244,13.31,10,1,13.28,1,2,13.27,20,2,13.26,198,2,13.14,1,1,13.13,100,1,13.12,200,2,13.11,100,1,13.10,100,1,13.04,2,1,13.40,0,-10,13.53,0,-1,13.55,0,-1,13.56,0,-1,13.57,0,-1,13.58,0,-1,13.59,0,-2,13.60,0,-2,13.61,0,-2,13.63,0,-4,ARL,0
2025-07-17T16:04:57.970616610Z,2025-07-17T16:04:57.970451236Z,10,2,1108,C,A,10,13.640000000,100,328780669,165374,274316281,13.31,10,1,13.28,1,2,13.27,20,2,13.26,198,2,13.14,1,1,13.13,100,1,13.12,200,2,13.11,100,1,13.10,100,1,13.04,2,1,13.40,0,-10,13.53,0,-1,13.55,0,-1,13.56,0,-1,13.57,0,-1,13.58,0,-1,13.59,0,-2,13.60,0,-2,13.61,0,-3,13.63,0,-4,ARL,0
2025-07-17T16:04:57.970616610Z,2025-07-17T16:04:57.970451236Z,10,2,1108,A,A,10,13.620000000,100,329074609,165374,274316281,13.31,10,1,13.28,1,2,13.27,20,2,13.26,198,2,13.14,1,1,13.13,100,1,13.12,200,2,13.11,100,1,13.10,100,1,13.04,2,1,13.40,0,-10,13.53,0,-1,13.55,0,-1,13.56,0,-1,13.57,0,-1,13.58,0,-1,13.59,0,-2,13.60,0,-2,13.61,0,-3,13.63,0,-4,ARL,0
2025-07-17T16:04:57.971360344Z,2025-07-17T16:04:57.971193734Z,10,2,1108,C,A,10,14.450000000,100,325714601,166610,274316507,13.31,10,1,13.28,1,2,13.27,20,2,13.26,198,2,13.14,1,1,13.13,100,1,13.12,200,2,13.11,100,1,13.10,100,1,13.04,2,1,13.40,0,-10,13.53,0,-1,13.55,0,-1,13.56,0,-1,13.57,0,-1,13.58,0,-1,13.59,0,-2,13.60,0,-2,13.61,0,-3,13.62,0,-1,ARL,0
2025-07-17T16:04:57.971717511Z,2025-07-17T16:04:57.971552262Z,10,2,1108,A,A,10,14.230000000,100,329074833,165249,274316527,13.31,10,1,13.28,1,2,13.27,20,2,13.26,198,2,13.14,1,1,13.13,100,1,13.12,200,2,13.11,100,1,13.10,100,1,13.04,2,1,13.40,0,-10,13.53,0,-1,13.55,0,-1,13.56,0,-1,13.57,0,-1,13.58,0,-1,13.59,0,-2,13.60,0,-2,13.61,0,-3,13.62,0,-1,ARL,0
2025-07-17T16:04:57.992131878Z,2025-07-17T16:04:57.991966904Z,10,2,1108,C,A,10,13.610000000,15,329068341,164974,274318490,13.31,10,1,13.28,1,2,13.27,20,2,13.26,198,2,13.14,1,1,13.13,100,1,13.12,200,2,13.11,100,1,13.10,100,1,13.04,2,1,13.40,0,-10,13.53,0,-1,13.55,0,-1,13.56,0,-1,13.57,0,-1,13.58,0,-1,13.59,0,-2,13.60,0,-2,13.61,0,-3,13.62,0,-1,ARL,0
2025-07-17T16:04:57.993141438Z,2025-07-17T16:04:57.992976406Z,10,2,1108,C,A,10,13.620000000,100,329074609,165032,274318579,13.31,10,1,13.28,1,2,13.27,20,2,13.26,198,2,13.14,1,1,13.13,100,1,13.12,200,2,13.11,100,1,13.10,100,1,13.04,2,1,13.40,0,-10,13.53,0,-1,13.55,0,-1,13.56,0,-1,13.57,0,-1,13.58,0,-1,13.59,0,-2,13.60,0,-2,13.61,0,-3,13.62,0,-1,ARL,0
2025-07-17T16:04:57.993309561Z,2025-07-17T16:04:57.993143873Z,10,2,1108,C,A,10,13.630000000,15,328780565,165688,274318603,13.31,10,1,13.28,1,2,13.27,20,2,13.26,198,2,13.14,1,1,13.13,100,1,13.12,200,2,13.11,100,1,13.10,100,1,13.04,2,1,13.40,0,-10,13.53,0,-1,13.55,0,-1,13.56,0,-1,13.57,0,-1,13.58,0,-1,13.59,0,-2,13.60,0,-2,13.61,0,-3,13.62,0,-1,ARL,0
2025-07-17T16:04:58.002259715Z,2025-07-17T16:04:58.002094377Z,10,2,1108,C,A,10,13.670000000,100,328780689,165338,274319058,13.31,10,1,13.28,1,2,13.27,20,2,13.26,198,2,13.14,1,1,13.13,100,1,13.12,200,2,13.11,100,1,13.10,100,1,13.04,2,1,13.40,0,-10,13.53,0,-1,13.55,0,-1,13.56,0,-1,13.57,0,-1,13.58,0,-1,13.59,0,-2,13.60,0,-2,13.61,0,-3,13.62,0,-1,ARL,0
2025-07-17T16:04:58.002989430Z,2025-07-17T16:04:58.002823841Z,10,2,1108,C,A,10,14.700000000,100,328780685,165589,274319069,13.31,10,1,13.28,1,2,13.27,20,2,13.26,198,2,13.14,1,1,13.13,100,1,13.12,200,2,13.11,100,1,13.10,100,1,13.04,2,1,13.40,0,-10,13.53,0,-1,13.55,0,-1,13.56,0,-1,13.57,0,-1,13.58,0,-1,13.59,0,-2,13.60,0,-2,13.61,0,-3,13.62,0,-1,ARL,0
2025-07-17T16:04:58.002989430Z,2025-07-17T16:04:58.002823841Z,10,2,1108,A,A,10,14.870000000,100,329078553,165589,274319069,13.31,10,1,13.28,1,2,13.27,20,2,13.26,198,2,13.14,1,1,13.13,100,1,13.12,200,2,13.11,100,1,13.10,100,1,13.04,2,1,13.40,0,-10,13.53,0,-1,13.55,0,-1,13.56,0,-1,13.57,0,-1,13.58,0,-1,13.59,0,-2,13.60,0,-2,13.61,0,-3,13.62,0,-1,ARL,0
2025-07-17T16:04:58.013904697Z,2025-07-17T16:04:58.013739242Z,10,2,1108,C,A,10,13.930000000,100,328616925,165455,274319298,13.31,10,1,13.28,1,2,13.27,20,2,13.26,198,2,13.14,1,1,13.13,100,1,13.12,200,2,13.11,100,1,13.10,100,1,13.04,2,1,13.40,0,-10,13.53,0,-1,13.55,0,-1,13.56,0,-1,13.57,0,-1,13.58,0,-1,13.59,0,-2,13.60,0,-2,13.61,0,-3,13.62,0,-1,ARL,0
2025-07-17T16:04:58.013959233Z,2025-07-17T16:04:58.013793974Z,10,2,1108,A,A,10,14.080000000,100,329078953,165259,274319304,13.31,10,1,13.28,1,2,13.27,20,2,13.26,198,2,13.14,1,1,13.13,100,1,13.12,200,2,13.11,100,1,13.10,100,1,13.04,2,1,13.40,0,-10,13.53,0,-1,13.55,0,-1,13.56,0,-1,13.57,0,-1,13.58,0,-1,13.59,0,-2,13.60,0,-2,13.61,0,-3,13.62,0,-1,ARL,0
2025-07-17T16:04:58.536617917Z,2025-07-17T16:04:58.536452621Z,10,2,1108,A,A,10,13.810000000,100,329088265,165296,274326535,13.31,10,1,13.28,1,2,13.27,20,2,13.26,198,2,13.14,1,1,13.13,100,1,13.12,200,2,13.11,100,1,13.10,100,1,13.04,2,1,13.40,0,-10,13.53,0,-1,13.55,0,-1,13.56,0,-1,13.57,0,-1,13.58,0,-1,13.59,0,-2,13.60,0,-2,13.61,0,-3,13.62,0,-1,ARL,0
2025-07-17T16:05:46.594131664Z,2025-07-17T16:05:46.593966383Z,10,2,1108,A,A,10,13.760000000,100,330066537,165281,275083968,13.31,10,1,13.28,1,2,13.27,20,2,13.26,198,2,13.14,1,1,13.13,100,1,13.12,200,2,13.11,100,1,13.10,100,1,13.04,2,1,13.40,0,-10,13.53,0,-1,13.55,0,-1,13.56,0,-1,13.57,0,-1,13.58,0,-1,13.59,0,-2,13.60,0,-2,13.61,0,-3,13.62,0,-1,ARL,0
2025-07-17T16:05:46.594871336Z,2025-07-17T16:05:46.594705962Z,10,2,1108,C,A,10,14.870000000,100,329078553,165374,275083970,13.31,10,1,13.28,1,2,13.27,20,2,13.26,198,2,13.14,1,1,13.13,100,1,13.12,200,2,13.11,100,1,13.10,100,1,13.04,2,1,13.40,0,-10,13.53,0,-1,13.55,0,-1,13.56,0,-1,13.57,0,-1,13.58,0,-1,13.59,0,-2,13.60,0,-2,13.61,0,-3,13.62,0,-1,ARL,0
2025-07-17T16:05:46.594871336Z,2025-07-17T16:05:46.594705962Z,10,2,1108,A,A,10,14.830000000,100,330066553,165374,275083970,13.31,10,1,13.28,1,2,13.27,20,2,13.26,198,2,13.14,1,1,13.13,100,1,13.12,200,2,13.11,100,1,13.10,100,1,13.04,2,1,13.40,0,-10,13.53,0,-1,13.55,0,-1,13.56,0,-1,13.57,0,-1,13.58,0,-1,13.59,0,-2,13.60,0,-2,13.61,0,-3,13.62,0,-1,ARL,0
2025-07-17T16:05:46.996003552Z,2025-07-17T16:05:46.995837526Z,10,2,1108,C,A,10,13.810000000,100,329088265,166026,275092978,13.31,10,1,13.28,1,2,13.27,20,2,13.26,198,2,13.14,1,1,13.13,100,1,13.12,200,2,13.11,100,1,13.10,100,1,13.04,2,1,13.40,0,-10,13.53,0,-1,13.55,0,-1,13.56,0,-1,13.57,0,-1,13.58,0,-1,13.59,0,-2,13.60,0,-2,13.61,0,-3,13.62,0,-1,ARL,0
2025-07-17T16:05:46.996003552Z,2025-07-17T16:05:46.995837526Z,10,2,1108,A,A,10,13.770000000,100,330075425,166026,275092978,13.31,10,1,13.28,1,2,13.27,20,2,13.26,198,2,13.14,1,1,13.13,100,1,13.12,200,2,13.11,100,1,13.10,100,1,13.04,2,1,13.40,0,-10,13.53,0,-1,13.55,0,-1,13.56,0,-1,13.57,0,-1,13.58,0,-1,13.59,0,-2,13.60,0,-2,13.61,0,-3,13.62,0,-1,ARL,0
2025-07-17T16:05:50.680333151Z,2025-07-17T16:05:50.680167632Z,10,2,1108,A,A,10,13.680000000,15,330143813,165519,275152014,13.31,10,1,13.28,1,2,13.27,20,2,13.26,198,2,13.14,1,1,13.13,100,1,13.12,200,2,13.11,100,1,13.10,100,1,13.04,2,1,13.40,0,-10,13.53,0,-1,13.55,0,-1,13.56,0,-1,13.57,0,-1,13.58,0,-1,13.59,0,-2,13.60,0,-2,13.61,0,-3,13.62,0,-1,ARL,0
2025-07-17T16:05:50.697170320Z,2025-07-17T16:05:50.697005084Z,10,2,1108,A,A,10,13.720000000,100,330144301,165236,275152383,13.31,10,1,13.28,1,2,13.27,20,2,13.26,198,2,13.14,1,1,13.13,100,1,13.12,200,2,13.11,100,1,13.10,100,1,13.04,2,1,13.40,0,-10,13.53,0,-1,13.55,0,-1,13.56,0,-1,13.57,0,-1,13.58,0,-1,13.59,0,-2,13.60,0,-2,13.61,0,-3,13.62,0,-1,ARL,0
2025-07-17T16:05:50.697905372Z,2025-07-17T16:05:50.697739933Z,10,2,1108,C,A,10,14.830000000,100,330066553,165439,275152385,13.31,10,1,13.28,1,2,13.27,20,2,13.26,198,2,13.14,1,1,13.13,100,1,13.12,200,2,13.11,100,1,13.10,100,1,13.04,2,1,13.40,0,-10,13.53,0,-1,13.55,0,-1,13.56,0,-1,13.57,0,-1,13.58,0,-1,13.59,0,-2,13.60,0,-2,13.61,0,-3,13.62,0,-1,ARL,0
2025-07-17T16:05:50.697905372Z,2025-07-17T16:05:50.697739933Z,10,2,1108,A,A,10,14.780000000,100,330144321,165439,275152385,13.31,10,1,13.28,1,2,13.27,20,2,13.26,198,2,13.14,1,1,13.13,100,1,13.12,200,2,13.11,100,1,13.10,100,1,13.04,2,1,13.40,0,-10,13.53,0,-1,13.55,0,-1,13.56,0,-1,13.57,0,-1,13.58,0,-1,13.59,0,-2,13.60,0,-2,13.61,0,-3,13.62,0,-1,ARL,0
2025-07-17T16:05:50.704531748Z,2025-07-17T16:05:50.704366332Z,10,2,1108,C,A,10,13.760000000,100,330066537,165416,275152443,13.31,10,1,13.28,1,2,13.27,20,2,13.26,198,2,13.14,1,1,13.13,100,1,13.12,200,2,13.11,100,1,13.10,100,1,13.04,2,1,13.40,0,-10,13.53,0,-1,13.55,0,-1,13.56,0,-1,13.57,0,-1,13.58,0,-1,13.59,0,-2,13.60,0,-2,13.61,0,-3,13.62,0,-1,ARL,0
2025-07-17T16:05:50.708879311Z,2025-07-17T16:05:50.708714027Z,10,2,1108,C,A,10,14.080000000,100,329078953,165284,275152465,13.31,10,1,13.28,1,2,13.27,20,2,13.26,198,2,13.14,1,1,13.13,100,1,13.12,200,2,13.11,100,1,13.10,100,1,13.04,2,1,13.40,0,-10,13.53,0,-1,13.55,0,-1,13.56,0,-1,13.57,0,-1,13.58,0,-1,13.59,0,-2,13.60,0,-2,13.61,0,-3,13.62,0,-1,ARL,0
2025-07-17T16:05:50.708931189Z,2025-07-17T16:05:50.708766050Z,10,2,1108,A,A,10,13.990000000,100,330144513,165139,275152466,13.31,10,1,13.28,1,2,13.27,20,2,13.26,198,2,13.14,1,1,13.13,100,1,13.12,200,2,13.11,100,1,13.10,100,1,13.04,2,1,13.40,0,-10,13.53,0,-1,13.55,0,-1,13.56,0,-1,13.57,0,-1,13.58,0,-1,13.59,0,-2,13.60,0,-2,13.61,0,-3,13.62,0,-1,ARL,0
2025-07-17T16:05:50.913476268Z,2025-07-17T16:05:50.913310799Z,10,2,1108,C,A,10,13.770000000,100,330075425,165469,275159685,13.31,10,1,13.28,1,2,13.27,20,2,13.26,198,2,13.14,1,1,13.13,100,1,13.12,200,2,13.11,100,1,13.10,100,1,13.04,2,1,13.40,0,-10,13.53,0,-1,13.55,0,-1,13.56,0,-1,13.57,0,-1,13.58,0,-1,13.59,0,-2,13.60,0,-2,13.61,0,-3,13.62,0,-1,ARL,0
2025-07-17T16:05:50.913476268Z,2025-07-17T16:05:50.913310799Z,10,2,1108,A,A,10,13.690000000,100,330151389,165469,275159685,13.31,10,1,13.28,1,2,13.27,20,2,13.26,198,2,13.14,1,1,13.13,100,1,13.12,200,2,13.11,100,1,13.10,100,1,13.04,2,1,13.40,0,-10,13.53,0,-1,13.55,0,-1,13.56,0,-1,13.57,0,-1,13.58,0,-1,13.59,0,-2,13.60,0,-2,13.61,0,-3,13.62,0,-1,ARL,0
2025-07-17T16:05:59.704955970Z,2025-07-17T16:05:59.704790753Z,10,2,1108,A,A,10,13.640000000,15,330357473,165217,275325555,13.31,10,1,13.28,1,2,13.27,20,2,13.26,198,2,13.14,1,1,13.13,100,1,13.12,200,2,13.11,100,1,13.10,100,1,13.04,2,1,13.40,0,-10,13.53,0,-1,13.55,0,-1,13.56,0,-1,13.57,0,-1,13.58,0,-1,13.59,0,-2,13.60,0,-2,13.61,0,-3,13.62,0,-1,ARL,0
2025-07-17T16:05:59.715090662Z,2025-07-17T16:05:59.714925412Z,10,2,1108,A,A,10,13.680000000,100,330357633,165250,275325807,13.31,10,1,13.28,1,2,13.27,20,2,13.26,198,2,13.14,1,1,13.13,100,1,13.12,200,2,13.11,100,1,13.10,100,1,13.04,2,1,13.40,0,-10,13.53,0,-1,13.55,0,-1,13.56,0,-1,13.57,0,-1,13.58,0,-1,13.59,0,-2,13.60,0,-2,13.61,0,-3,13.62,0,-1,ARL,0
2025-07-17T16:05:59.722895750Z,2025-07-17T16:05:59.722730507Z,10,2,1108,C,A,10,13.720000000,100,330144301,165243,275325854,13.31,10,1,13.28,1,2,13.27,20,2,13.26,198,2,13.14,1,1,13.13,100,1,13.12,200,2,13.11,100,1,13.10,100,1,13.04,2,1,13.40,0,-10,13.53,0,-1,13.55,0,-1,13.56,0,-1,13.57,0,-1,13.58,0,-1,13.59,0,-2,13.60,0,-2,13.61,0,-3,13.62,0,-1,ARL,0
2025-07-17T16:05:59.802762087Z,2025-07-17T16:05:59.802596747Z,10,2,1108,C,A,10,13.690000000,100,330151389,165340,275327082,13.31,10,1,13.28,1,2,13.27,20,2,13.26,198,2,13.14,1,1,13.13,100,1,13.12,200,2,13.11,100,1,13.10,100,1,13.04,2,1,13.40,0,-10,13.53,0,-1,13.55,0,-1,13.56,0,-1,13.57,0,-1,13.58,0,-1,13.59,0,-2,13.60,0,-2,13.61,0,-3,13.62,0,-1,ARL,0
2025-07-17T16:05:59.802762087Z,2025-07-17T16:05:59.802596747Z,10,2,1108,A,A,10,13.650000000,100,330359197,165340,275327082,13.31,10,1,13.28,1,2,13.27,20,2,13.26,198,2,13.14,1,1,13.13,100,1,13.12,200,2,13.11,100,1,13.10,100,1,13.04,2,1,13.40,0,-10,13.53,0,-1,13.55,0,-1,13.56,0,-1,13.57,0,-1,13.58,0,-1,13.59,0,-2,13.60,0,-2,13.61,0,-3,13.62,0,-1,ARL,0
2025-07-17T16:05:59.803504658Z,2025-07-17T16:05:59.803338996Z,10,2,1108,C,A,10,14.780000000,100,330144321,165662,275327093,13.31,10,1,13.28,1,2,13.27,20,2,13.26,198,2,13.14,1,1,13.13,100,1,13.12,200,2,13.11,100,1,13.10,100,1,13.04,2,1,13.40,0,-10,13.53,0,-1,13.55,0,-1,13.56,0,-1,13.57,0,-1,13.58,0,-1,13.59,0,-2,13.60,0,-2,13.61,0,-3,13.62,0,-1,ARL,0
2025-07-17T16:05:59.803504658Z,2025-07-17T16:05:59.803338996Z,10,2,1108,A,A,10,14.710000000,100,330359225,165662,275327093,13.31,10,1,13.28,1,2,13.27,20,2,13.26,198,2,13.14,1,1,13.13,100,1,13.12,200,2,13.11,100,1,13.10,100,1,13.04,2,1,13.40,0,-10,13.53,0,-1,13.55,0,-1,13.56,0,-1,13.57,0,-1,13.58,0,-1,13.59,0,-2,13.60,0,-2,13.61,0,-3,13.62,0,-1,ARL,0
2025-07-17T16:05:59.827787837Z,2025-07-17T16:05:59.827622529Z,10,2,1108,C,A,10,13.990000000,100,330144513,165308,275327416,13.31,10,1,13.28,1,2,13.27,20,2,13.26,198,2,13.14,1,1,13.13,100,1,13.12,200,2,13.11,100,1,13.10,100,1,13.04,2,1,13.40,0,-10,13.53,0,-1,13.55,0,-1,13.56,0,-1,13.57,0,-1,13.58,0,-1,13.59,0,-2,13.60,0,-2,13.61,0,-3,13.62,0,-1,ARL,0
2025-07-17T16:05:59.827839802Z,2025-07-17T16:05:59.827674437Z,10,2,1108,A,A,10,13.920000000,100,330359625,165365,275327417,13.31,10,1,13.28,1,2,13.27,20,2,13.26,198,2,13.14,1,1,13.13,100,1,13.12,200,2,13.11,100,1,13.10,100,1,13.04,2,1,13.40,0,-10,13.53,0,-1,13.55,0,-1,13.56,0,-1,13.57,0,-1,13.58,0,-1,13.59,0,-2,13.60,0,-2,13.61,0,-3,13.62,0,-1,ARL,0
2025-07-17T16:06:02.724446337Z,2025-07-17T16:06:02.724280161Z,10,2,1108,C,A,10,13.680000000,15,330143813,166176,275430576,13.31,10,1,13.28,1,2,13.27,20,2,13.26,198,2,13.14,1,1,13.13,100,1,13.12,200,2,13.11,100,1,13.10,100,1,13.04,2,1,13.40,0,-10,13.53,0,-1,13.55,0,-1,13.56,0,-1,13.57,0,-1,13.58,0,-1,13.59,0,-2,13.60,0,-2,13.61,0,-3,13.62,0,-1,ARL,0
2025-07-17T16:06:03.729377770Z,2025-07-17T16:06:03.729212428Z,10,2,1108,A,A,10,13.620000000,15,330577045,165342,275517342,13.31,10,1,13.28,1,2,13.27,20,2,13.26,198,2,13.14,1,1,13.13,100,1,13.12,200,2,13.11,100,1,13.10,100,1,13.04,2,1,13.40,0,-10,13.53,0,-1,13.55,0,-1,13.56,0,-1,13.57,0,-1,13.58,0,-1,13.59,0,-2,13.60,0,-2,13.61,0,-3,13.62,0,-1,ARL,0
2025-07-17T16:06:03.738497645Z,2025-07-17T16:06:03.738332427Z,10,2,1108,A,A,10,13.650000000,100,330577773,165218,275517997,13.31,10,1,13.28,1,2,13.27,20,2,13.26,198,2,13.14,1,1,13.13,100,1,13.12,200,2,13.11,100,1,13.10,100,1,13.04,2,1,13.40,0,-10,13.53,0,-1,13.55,0,-1,13.56,0,-1,13.57,0,-1,13.58,0,-1,13.59,0,-2,13.60,0,-2,13.61,0,-3,13.62,0,-1,ARL,0
2025-07-17T16:06:03.747495669Z,2025-07-17T16:06:03.747330178Z,10,2,1108,C,A,10,13.680000000,100,330357633,165491,275518621,13.31,10,1,13.28,1,2,13.27,20,2,13.26,198,2,13.14,1,1,13.13,100,1,13.12,200,2,13.11,100,1,13.10,100,1,13.04,2,1,13.40,0,-10,13.53,0,-1,13.55,0,-1,13.56,0,-1,13.57,0,-1,13.58,0,-1,13.59,0,-2,13.60,0,-2,13.61,0,-3,13.62,0,-1,ARL,0
2025-07-17T16:06:03.887274670Z,2025-07-17T16:06:03.887107153Z,10,2,1108,C,A,10,13.650000000,100,330359197,167517,275532429,13.31,10,1,13.28,1,2,13.27,20,2,13.26,198,2,13.14,1,1,13.13,100,1,13.12,200,2,13.11,100,1,13.10,100,1,13.04,2,1,13.40,0,-10,13.53,0,-1,13.55,0,-1,13.56,0,-1,13.57,0,-1,13.58,0,-1,13.59,0,-2,13.60,0,-2,13.61,0,-3,13.62,0,-1,ARL,0
2025-07-17T16:06:03.887274670Z,2025-07-17T16:06:03.887107153Z,10,2,1108,A,A,10,13.630000000,100,330592465,167517,275532429,13.31,10,1,13.28,1,2,13.27,20,2,13.26,198,2,13.14,1,1,13.13,100,1,13.12,200,2,13.11,100,1,13.10,100,1,13.04,2,1,13.40,0,-10,13.53,0,-1,13.55,0,-1,13.56,0,-1,13.57,0,-1,13.58,0,-1,13.59,0,-2,13.60,0,-2,13.61,0,-3,13.62,0,-1,ARL,0
2025-07-17T16:06:07.510050758Z,2025-07-17T16:06:07.509885114Z,10,2,1108,C,A,10,13.640000000,15,330357473,165644,275647392,13.31,10,1,13.28,1,2,13.27,20,2,13.26,198,2,13.14,1,1,13.13,100,1,13.12,200,2,13.11,100,1,13.10,100,1,13.04,2,1,13.40,0,-10,13.53,0,-1,13.55,0,-1,13.56,0,-1,13.57,0,-1,13.58,0,-1,13.59,0,-2,13.60,0,-2,13.61,0,-3,13.62,0,-1,ARL,0
2025-07-17T16:06:09.885143909Z,2025-07-17T16:06:09.884978592Z,10,2,1108,A,A,10,13.600000000,15,330788421,165317,275699092,13.31,10,1,13.28,1,2,13.27,20,2,13.26,198,2,13.14,1,1,13.13,100,1,13.12,200,2,13.11,100,1,13.10,100,1,13.04,2,1,13.40,0,-10,13.53,0,-1,13.55,0,-1,13.56,0,-1,13.57,0,-1,13.58,0,-1,13.59,0,-2,13.60,0,-2,13.61,0,-3,13.62,0,-1,ARL,0
2025-07-17T16:06:09.967608061Z,2025-07-17T16:06:09.967442600Z,10,2,1108,C,A,10,13.630000000,100,330592465,165461,275700261,13.31,10,1,13.28,1,2,13.27,20,2,13.26,198,2,13.14,1,1,13.13,100,1,13.12,200,2,13.11,100,1,13.10,100,1,13.04,2,1,13.40,0,-10,13.53,0,-1,13.55,0,-1,13.56,0,-1,13.57,0,-1,13.58,0,-1,13.59,0,-2,13.60,0,-3,13.61,0,-3,13.62,0,-1,ARL,0
2025-07-17T16:06:09.967608061Z,2025-07-17T16:06:09.967442600Z,10,2,1108,A,A,10,13.610000000,100,330789481,165461,275700261,13.31,10,1,13.28,1,2,13.27,20,2,13.26,198,2,13.14,1,1,13.13,100,1,13.12,200,2,13.11,100,1,13.10,100,1,13.04,2,1,13.40,0,-10,13.53,0,-1,13.55,0,-1,13.56,0,-1,13.57,0,-1,13.58,0,-1,13.59,0,-2,13.60,0,-3,13.61,0,-3,13.62,0,-1,ARL,0
2025-07-17T16:06:09.968352066Z,2025-07-17T16:06:09.968186617Z,10,2,1108,C,A,10,14.710000000,100,330359225,165449,275700270,13.31,10,1,13.28,1,2,13.27,20,2,13.26,198,2,13.14,1,1,13.13,100,1,13.12,200,2,13.11,100,1,13.10,100,1,13.04,2,1,13.40,0,-10,13.53,0,-1,13.55,0,-1,13.56,0,-1,13.57,0,-1,13.58,0,-1,13.59,0,-2,13.60,0,-3,13.61,0,-4,13.62,0,-1,ARL,0
2025-07-17T16:06:09.968352066Z,2025-07-17T16:06:09.968186617Z,10,2,1108,A,A,10,14.670000000,100,330789501,165449,275700270,13.31,10,1,13.28,1,2,13.27,20,2,13.26,198,2,13.14,1,1,13.13,100,1,13.12,200,2,13.11,100,1,13.10,100,1,13.04,2,1,13.40,0,-10,13.53,0,-1,13.55,0,-1,13.56,0,-1,13.57,0,-1,13.58,0,-1,13.59,0,-2,13.60,0,-3,13.61,0,-4,13.62,0,-1,ARL,0
2025-07-17T16:06:09.970040686Z,2025-07-17T16:06:09.969875190Z,10,2,1108,C,A,10,17.440000000,100,327870217,165496,275700282,13.31,10,1,13.28,1,2,13.27,20,2,13.26,198,2,13.14,1,1,13.13,100,1,13.12,200,2,13.11,100,1,13.10,100,1,13.04,2,1,13.40,0,-10,13.53,0,-1,13.55,0,-1,13.56,0,-1,13.57,0,-1,13.58,0,-1,13.59,0,-2,13.60,0,-3,13.61,0,-4,13.62,0,-1,ARL,0
2025-07-17T16:06:09.970040686Z,2025-07-17T16:06:09.969875190Z,10,2,1108,A,A,10,17.290000000,100,330789509,165496,275700282,13.31,10,1,13.28,1,2,13.27,20,2,13.26,198,2,13.14,1,1,13.13,100,1,13.12,200,2,13.11,100,1,13.10,100,1,13.04,2,1,13.40,0,-10,13.53,0,-1,13.55,0,-1,13.56,0,-1,13.57,0,-1,13.58,0,-1,13.59,0,-2,13.60,0,-3,13.61,0,-4,13.62,0,-1,ARL,0
2025-07-17T16:06:20.470889851Z,2025-07-17T16:06:20.470724464Z,10,2,1108,A,A,10,13.630000000,100,331018065,165387,275896138,13.31,10,1,13.28,1,2,13.27,20,2,13.26,198,2,13.14,1,1,13.13,100,1,13.12,200,2,13.11,100,1,13.10,100,1,13.04,2,1,13.40,0,-10,13.53,0,-1,13.55,0,-1,13.56,0,-1,13.57,0,-1,13.58,0,-1,13.59,0,-2,13.60,0,-3,13.61,0,-4,13.62,0,-1,ARL,0
2025-07-17T16:06:20.477598578Z,2025-07-17T16:06:20.477432988Z,10,2,1108,C,A,10,13.650000000,100,330577773,165590,275896242,13.31,10,1,13.28,1,2,13.27,20,2,13.26,198,2,13.14,1,1,13.13,100,1,13.12,200,2,13.11,100,1,13.10,100,1,13.04,2,1,13.40,0,-10,13.53,0,-1,13.55,0,-1,13.56,0,-1,13.57,0,-1,13.58,0,-1,13.59,0,-2,13.60,0,-3,13.61,0,-4,13.62,0,-1,ARL,0
2025-07-17T16:06:20.811164178Z,2025-07-17T16:06:20.810998706Z,10,2,1108,C,A,10,13.620000000,15,330577045,165472,275900161,13.31,10,1,13.28,1,2,13.27,20,2,13.26,198,2,13.14,1,1,13.13,100,1,13.12,200,2,13.11,100,1,13.10,100,1,13.04,2,1,13.40,0,-10,13.53,0,-1,13.55,0,-1,13.56,0,-1,13.57,0,-1,13.58,0,-1,13.59,0,-2,13.60,0,-3,13.61,0,-4,13.62,0,-1,ARL,0
2025-07-17T16:06:22.151222819Z,2025-07-17T16:06:22.151057292Z,10,2,1108,A,A,10,13.580000000,15,331050981,165527,275926927,13.31,10,1,13.28,1,2,13.27,20,2,13.26,198,2,13.14,1,1,13.13,100,1,13.12,200,2,13.11,100,1,13.10,100,1,13.04,2,1,13.40,0,-10,13.53,0,-1,13.55,0,-1,13.56,0,-1,13.57,0,-1,13.58,0,-1,13.59,0,-2,13.60,0,-3,13.61,0,-4,13.62,0,-1,ARL,0
2025-07-17T16:06:22.151491832Z,2025-07-17T16:06:22.151326300Z,10,2,1108,C,A,10,13.610000000,100,330789481,165532,275926940,13.31,10,1,13.28,1,2,13.27,20,2,13.26,198,2,13.14,1,1,13.13,100,1,13.12,200,2,13.11,100,1,13.10,100,1,13.04,2,1,13.40,0,-10,13.53,0,-1,13.55,0,-1,13.56,0,-1,13.57,0,-1,13.58,0,-2,13.59,0,-2,13.60,0,-3,13.61,0,-4,13.62,0,-1,ARL,0
2025-07-17T16:06:22.151491832Z,2025-07-17T16:06:22.151326300Z,10,2,1108,A,A,10,13.590000000,100,331050989,165532,275926940,13.31,10,1,13.28,1,2,13.27,20,2,13.26,198,2,13.14,1,1,13.13,100,1,13.12,200,2,13.11,100,1,13.10,100,1,13.04,2,1,13.40,0,-10,13.53,0,-1,13.55,0,-1,13.56,0,-1,13.57,0,-1,13.58,0,-2,13.59,0,-2,13.60,0,-3,13.61,0,-4,13.62,0,-1,ARL,0
2025-07-17T16:06:22.151761329Z,2025-07-17T16:06:22.151595415Z,10,2,1108,C,A,10,13.800000000,100,328614525,165914,275926966,13.31,10,1,13.28,1,2,13.27,20,2,13.26,198,2,13.14,1,1,13.13,100,1,13.12,200,2,13.11,100,1,13.10,100,1,13.04,2,1,13.40,0,-10,13.53,0,-1,13.55,0,-1,13.56,0,-1,13.57,0,-1,13.58,0,-2,13.59,0,-3,13.60,0,-3,13.61,0,-4,13.62,0,-1,ARL,0
2025-07-17T16:06:22.151761329Z,2025-07-17T16:06:22.151595781Z,10,2,1108,C,A,10,13.800000000,100,328614529,165548,275926967,13.31,10,1,13.28,1,2,13.27,20,2,13.26,198,2,13.14,1,1,13.13,100,1,13.12,200,2,13.11,100,1,13.10,100,1,13.04,2,1,13.40,0,-10,13.53,0,-1,13.55,0,-1,13.56,0,-1,13.57,0,-1,13.58,0,-2,13.59,0,-3,13.60,0,-3,13.61,0,-4,13.62,0,-1,ARL,0
2025-07-17T16:06:22.153148893Z,2025-07-17T16:06:22.152983326Z,10,2,1108,C,A,10,15.790000000,100,327870361,165567,275927034,13.31,10,1,13.28,1,2,13.27,20,2,13.26,198,2,13.14,1,1,13.13,100,1,13.12,200,2,13.11,100,1,13.10,100,1,13.04,2,1,13.40,0,-10,13.53,0,-1,13.55,0,-1,13.56,0,-1,13.57,0,-1,13.58,0,-2,13.59,0,-3,13.60,0,-3,13.61,0,-4,13.62,0,-1,ARL,0
2025-07-17T16:06:22.153148893Z,2025-07-17T16:06:22.152983326Z,10,2,1108,A,A,10,15.630000000,100,331051145,165567,275927034,13.31,10,1,13.28,1,2,13.27,20,2,13.26,198,2,13.14,1,1,13.13,100,1,13.12,200,2,13.11,100,1,13.10,100,1,13.04,2,1,13.40,0,-10,13.53,0,-1,13.55,0,-1,13.56,0,-1,13.57,0,-1,13.58,0,-2,13.59,0,-3,13.60,0,-3,13.61,0,-4,13.62,0,-1,ARL,0
2025-07-17T16:06:22.153916169Z,2025-07-17T16:06:22.153749481Z,10,2,1108,C,A,10,14.700000000,100,327868421,166688,275927046,13.31,10,1,13.28,1,2,13.27,20,2,13.26,198,2,13.14,1,1,13.13,100,1,13.12,200,2,13.11,100,1,13.10,100,1,13.04,2,1,13.40,0,-10,13.53,0,-1,13.55,0,-1,13.56,0,-1,13.57,0,-1,13.58,0,-2,13.59,0,-3,13.60,0,-3,13.61,0,-4,13.62,0,-1,ARL,0
2025-07-17T16:06:22.153916169Z,2025-07-17T16:06:22.153749481Z,10,2,1108,A,A,10,14.550000000,100,331051173,166688,275927046,13.31,10,1,13.28,1,2,13.27,20,2,13.26,198,2,13.14,1,1,13.13,100,1,13.12,200,2,13.11,100,1,13.10,100,1,13.04,2,1,13.40,0,-10,13.53,0,-1,13.55,0,-1,13.56,0,-1,13.57,0,-1,13.58,0,-2,13.59,0,-3,13.60,0,-3,13.61,0,-4,13.62,0,-1,ARL,0
2025-07-17T16:06:22.156070698Z,2025-07-17T16:06:22.155905240Z,10,2,1108,C,A,10,14.520000000,100,327869529,165458,275927117,13.31,10,1,13.28,1,2,13.27,20,2,13.26,198,2,13.14,1,1,13.13,100,1,13.12,200,2,13.11,100,1,13.10,100,1,13.04,2,1,13.40,0,-10,13.53,0,-1,13.55,0,-1,13.56,0,-1,13.57,0,-1,13.58,0,-2,13.59,0,-3,13.60,0,-3,13.61,0,-4,13.62,0,-1,ARL,0
2025-07-17T16:06:22.156070698Z,2025-07-17T16:06:22.155905240Z,10,2,1108,A,A,10,14.380000000,100,331051369,165458,275927117,13.31,10,1,13.28,1,2,13.27,20,2,13.26,198,2,13.14,1,1,13.13,100,1,13.12,200,2,13.11,100,1,13.10,100,1,13.04,2,1,13.40,0,-10,13.53,0,-1,13.55,0,-1,13.56,0,-1,13.57,0,-1,13.58,0,-2,13.59,0,-3,13.60,0,-3,13.61,0,-4,13.62,0,-1,ARL,0
2025-07-17T16:06:22.178044675Z,2025-07-17T16:06:22.177879233Z,10,2,1108,C,A,10,14.700000000,100,327873009,165442,275927444,13.31,10,1,13.28,1,2,13.27,20,2,13.26,198,2,13.14,1,1,13.13,100,1,13.12,200,2,13.11,100,1,13.10,100,1,13.04,2,1,13.40,0,-10,13.53,0,-1,13.55,0,-1,13.56,0,-1,13.57,0,-1,13.58,0,-2,13.59,0,-3,13.60,0,-3,13.61,0,-4,13.62,0,-1,ARL,0
2025-07-17T16:06:22.178044675Z,2025-07-17T16:06:22.177879233Z,10,2,1108,A,A,10,14.550000000,100,331052197,165442,275927444,13.31,10,1,13.28,1,2,13.27,20,2,13.26,198,2,13.14,1,1,13.13,100,1,13.12,200,2,13.11,100,1,13.10,100,1,13.04,2,1,13.40,0,-10,13.53,0,-1,13.55,0,-1,13.56,0,-1,13.57,0,-1,13.58,0,-2,13.59,0,-3,13.60,0,-3,13.61,0,-4,13.62,0,-1,ARL,0
2025-07-17T16:06:24.519511128Z,2025-07-17T16:06:24.519345743Z,10,2,1108,A,A,10,13.600000000,100,331104725,165385,275968354,13.31,10,1,13.28,1,2,13.27,20,2,13.26,198,2,13.14,1,1,13.13,100,1,13.12,200,2,13.11,100,1,13.10,100,1,13.04,2,1,13.40,0,-10,13.53,0,-1,13.55,0,-1,13.56,0,-1,13.57,0,-1,13.58,0,-2,13.59,0,-3,13.60,0,-3,13.61,0,-4,13.62,0,-1,ARL,0
2025-07-17T16:06:24.526359716Z,2025-07-17T16:06:24.526194457Z,10,2,1108,C,A,10,13.630000000,100,331018065,165259,275968393,13.31,10,1,13.28,1,2,13.27,20,2,13.26,198,2,13.14,1,1,13.13,100,1,13.12,200,2,13.11,100,1,13.10,100,1,13.04,2,1,13.40,0,-10,13.53,0,-1,13.55,0,-1,13.56,0,-1,13.57,0,-1,13.58,0,-2,13.59,0,-3,13.60,0,-4,13.61,0,-4,13.62,0,-1,ARL,0
2025-07-17T16:06:26.610345800Z,2025-07-17T16:06:26.610180184Z,10,2,1108,C,A,10,13.940000000,2,328351217,165616,276013080,13.31,10,1,13.28,1,2,13.27,20,2,13.26,198,2,13.14,1,1,13.13,100,1,13.12,200,2,13.11,100,1,13.10,100,1,13.04,2,1,13.40,0,-10,13.53,0,-1,13.55,0,-1,13.56,0,-1,13.57,0,-1,13.58,0,-2,13.59,0,-3,13.60,0,-4,13.61,0,-4,13.62,0,-1,ARL,0
2025-07-17T16:06:26.610345800Z,2025-07-17T16:06:26.610180184Z,10,2,1108,A,A,10,13.850000000,2,331155889,165616,276013080,13.31,10,1,13.28,1,2,13.27,20,2,13.26,198,2,13.14,1,1,13.13,100,1,13.12,200,2,13.11,100,1,13.10,100,1,13.04,2,1,13.40,0,-10,13.53,0,-1,13.55,0,-1,13.56,0,-1,13.57,0,-1,13.58,0,-2,13.59,0,-3,13.60,0,-4,13.61,0,-4,13.62,0,-1,ARL,0
2025-07-17T16:06:30.625877214Z,2025-07-17T16:06:30.625711923Z,10,2,1108,A,A,10,14.270000000,700,331257169,165291,276103282,13.31,10,1,13.28,1,2,13.27,20,2,13.26,198,2,13.14,1,1,13.13,100,1,13.12,200,2,13.11,100,1,13.10,100,1,13.04,2,1,13.40,0,-10,13.53,0,-1,13.55,0,-1,13.56,0,-1,13.57,0,-1,13.58,0,-2,13.59,0,-3,13.60,0,-4,13.61,0,-4,13.62,0,-1,ARL,0
2025-07-17T16:06:30.625956307Z,2025-07-17T16:06:30.625790910Z,10,2,1108,C,A,10,14.680000000,700,325716945,165397,276103283,13.31,10,1,13.28,1,2,13.27,20,2,13.26,198,2,13.14,1,1,13.13,100,1,13.12,200,2,13.11,100,1,13.10,100,1,13.04,2,1,13.40,0,-10,13.53,0,-1,13.55,0,-1,13.56,0,-1,13.57,0,-1,13.58,0,-2,13.59,0,-3,13.60,0,-4,13.61,0,-4,13.62,0,-1,ARL,0
2025-07-17T16:06:31.127827805Z,2025-07-17T16:06:31.127662311Z,10,2,1108,A,A,10,14.480000000,700,331272997,165494,276118990,13.31,10,1,13.28,1,2,13.27,20,2,13.26,198,2,13.14,1,1,13.13,100,1,13.12,200,2,13.11,100,1,13.10,100,1,13.04,2,1,13.40,0,-10,13.53,0,-1,13.55,0,-1,13.56,0,-1,13.57,0,-1,13.58,0,-2,13.59,0,-3,13.60,0,-4,13.61,0,-4,13.62,0,-1,ARL,0
2025-07-17T16:06:31.128581831Z,2025-07-17T16:06:31.128416336Z,10,2,1108,C,A,10,14.680000000,700,289932801,165495,276119017,13.31,10,1,13.28,1,2,13.27,20,2,13.26,198,2,13.14,1,1,13.13,100,1,13.12,200,2,13.11,100,1,13.10,100,1,13.04,2,1,13.40,0,-10,13.53,0,-1,13.55,0,-1,13.56,0,-1,13.57,0,-1,13.58,0,-2,13.59,0,-3,13.60,0,-4,13.61,0,-4,13.62,0,-1,ARL,0
2025-07-17T16:06:31.990649229Z,2025-07-17T16:06:31.990483799Z,10,2,1108,C,A,10,13.600000000,15,330788421,165430,276135226,13.31,10,1,13.28,1,2,13.27,20,2,13.26,198,2,13.14,1,1,13.13,100,1,13.12,200,2,13.11,100,1,13.10,100,1,13.04,2,1,13.40,0,-10,13.53,0,-1,13.55,0,-1,13.56,0,-1,13.57,0,-1,13.58,0,-2,13.59,0,-3,13.60,0,-4,13.61,0,-4,13.62,0,-1,ARL,0
2025-07-17T16:06:42.812807096Z,2025-07-17T16:06:42.812641697Z,10,2,1108,A,A,10,13.560000000,15,331488089,165399,276276783,13.31,10,1,13.28,1,2,13.27,20,2,13.26,198,2,13.14,1,1,13.13,100,1,13.12,200,2,13.11,100,1,13.10,100,1,13.04,2,1,13.40,0,-10,13.53,0,-1,13.55,0,-1,13.56,0,-1,13.57,0,-1,13.58,0,-2,13.59,0,-3,13.60,0,-4,13.61,0,-4,13.62,0,-1,ARL,0
2025-07-17T16:06:43.012965957Z,2025-07-17T16:06:43.012799164Z,10,2,1108,C,A,10,13.590000000,100,331050989,166793,276279311,13.31,10,1,13.28,1,2,13.27,20,2,13.26,198,2,13.14,1,1,13.13,100,1,13.12,200,2,13.11,100,1,13.10,100,1,13.04,2,1,13.40,0,-10,13.53,0,-1,13.55,0,-1,13.56,0,-2,13.57,0,-1,13.58,0,-2,13.59,0,-3,13.60,0,-4,13.61,0,-4,13.62,0,-1,ARL,0
2025-07-17T16:06:43.012965957Z,2025-07-17T16:06:43.012799164Z,10,2,1108,A,A,10,13.570000000,100,331491049,166793,276279311,13.31,10,1,13.28,1,2,13.27,20,2,13.26,198,2,13.14,1,1,13.13,100,1,13.12,200,2,13.11,100,1,13.10,100,1,13.04,2,1,13.40,0,-10,13.53,0,-1,13.55,0,-1,13.56,0,-2,13.57,0,-1,13.58,0,-2,13.59,0,-3,13.60,0,-4,13.61,0,-4,13.62,0,-1,ARL,0
2025-07-17T16:06:43.013716205Z,2025-07-17T16:06:43.013550575Z,10,2,1108,C,A,10,14.670000000,100,330789501,165630,276279331,13.31,10,1,13.28,1,2,13.27,20,2,13.26,198,2,13.14,1,1,13.13,100,1,13.12,200,2,13.11,100,1,13.10,100,1,13.04,2,1,13.40,0,-10,13.53,0,-1,13.55,0,-1,13.56,0,-2,13.57,0,-2,13.58,0,-2,13.59,0,-3,13.60,0,-4,13.61,0,-4,13.62,0,-1,ARL,0
2025-07-17T16:06:43.013716205Z,2025-07-17T16:06:43.013550575Z,10,2,1108,A,A,10,14.620000000,100,331491077,165630,276279331,13.31,10,1,13.28,1,2,13.27,20,2,13.26,198,2,13.14,1,1,13.13,100,1,13.12,200,2,13.11,100,1,13.10,100,1,13.04,2,1,13.40,0,-10,13.53,0,-1,13.55,0,-1,13.56,0,-2,13.57,0,-2,13.58,0,-2,13.59,0,-3,13.60,0,-4,13.61,0,-4,13.62,0,-1,ARL,0
2025-07-17T16:06:43.024656023Z,2025-07-17T16:06:43.024490355Z,10,2,1108,C,A,10,13.920000000,100,330359625,165668,276279620,13.31,10,1,13.28,1,2,13.27,20,2,13.26,198,2,13.14,1,1,13.13,100,1,13.12,200,2,13.11,100,1,13.10,100,1,13.04,2,1,13.40,0,-10,13.53,0,-1,13.55,0,-1,13.56,0,-2,13.57,0,-2,13.58,0,-2,13.59,0,-3,13.60,0,-4,13.61,0,-4,13.62,0,-1,ARL,0
2025-07-17T16:06:43.024708304Z,2025-07-17T16:06:43.024543099Z,10,2,1108,A,A,10,13.840000000,100,331491269,165205,276279621,13.31,10,1,13.28,1,2,13.27,20,2,13.26,198,2,13.14,1,1,13.13,100,1,13.12,200,2,13.11,100,1,13.10,100,1,13.04,2,1,13.40,0,-10,13.53,0,-1,13.55,0,-1,13.56,0,-2,13.57,0,-2,13.58,0,-2,13.59,0,-3,13.60,0,-4,13.61,0,-4,13.62,0,-1,ARL,0
2025-07-17T16:06:49.613941821Z,2025-07-17T16:06:49.613776144Z,10,2,1108,C,A,10,13.580000000,15,331050981,165677,276382302,13.31,10,1,13.28,1,2,13.27,20,2,13.26,198,2,13.14,1,1,13.13,100,1,13.12,200,2,13.11,100,1,13.10,100,1,13.04,2,1,13.40,0,-10,13.53,0,-1,13.55,0,-1,13.56,0,-2,13.57,0,-2,13.58,0,-2,13.59,0,-3,13.60,0,-4,13.61,0,-4,13.62,0,-1,ARL,0
2025-07-17T16:06:50.618669843Z,2025-07-17T16:06:50.618504506Z,10,2,1108,A,A,10,13.540000000,15,331666961,165337,276408477,13.31,10,1,13.28,1,2,13.27,20,2,13.26,198,2,13.14,1,1,13.13,100,1,13.12,200,2,13.11,100,1,13.10,100,1,13.04,2,1,13.40,0,-10,13.53,0,-1,13.55,0,-1,13.56,0,-2,13.57,0,-2,13.58,0,-2,13.59,0,-3,13.60,0,-4,13.61,0,-4,13.62,0,-1,ARL,0
2025-07-17T16:06:50.626438205Z,2025-07-17T16:06:50.626272828Z,10,2,1108,A,A,10,13.580000000,100,331667121,165377,276408566,13.31,10,1,13.28,1,2,13.27,20,2,13.26,198,2,13.14,1,1,13.13,100,1,13.12,200,2,13.11,100,1,13.10,100,1,13.04,2,1,13.40,0,-10,13.53,0,-1,13.55,0,-1,13.56,0,-2,13.57,0,-2,13.58,0,-2,13.59,0,-3,13.60,0,-4,13.61,0,-4,13.62,0,-1,ARL,0
2025-07-17T16:06:50.633113557Z,2025-07-17T16:06:50.632947998Z,10,2,1108,C,A,10,13.600000000,100,331104725,165559,276408644,13.31,10,1,13.28,1,2,13.27,20,2,13.26,198,2,13.14,1,1,13.13,100,1,13.12,200,2,13.11,100,1,13.10,100,1,13.04,2,1,13.40,0,-10,13.53,0,-1,13.55,0,-1,13.56,0,-2,13.57,0,-2,13.58,0,-3,13.59,0,-3,13.60,0,-4,13.61,0,-4,13.62,0,-1,ARL,0
2025-07-17T16:06:51.754576322Z,2025-07-17T16:06:51.754410704Z,10,2,1108,C,A,10,13.570000000,100,331491049,165618,276428315,13.31,10,1,13.28,1,2,13.27,20,2,13.26,198,2,13.14,1,1,13.13,100,1,13.12,200,2,13.11,100,1,13.10,100,1,13.04,2,1,13.40,0,-10,13.53,0,-1,13.55,0,-1,13.56,0,-2,13.57,0,-2,13.58,0,-3,13.59,0,-3,13.60,0,-4,13.61,0,-4,13.62,0,-1,ARL,0
2025-07-17T16:06:51.754576322Z,2025-07-17T16:06:51.754410704Z,10,2,1108,A,A,10,13.550000000,100,331694265,165618,276428315,13.31,10,1,13.28,1,2,13.27,20,2,13.26,198,2,13.14,1,1,13.13,100,1,13.12,200,2,13.11,100,1,13.10,100,1,13.04,2,1,13.40,0,-10,13.53,0,-1,13.55,0,-1,13.56,0,-2,13.57,0,-2,13.58,0,-3,13.59,0,-3,13.60,0,-4,13.61,0,-4,13.62,0,-1,ARL,0
2025-07-17T16:06:51.757403109Z,2025-07-17T16:06:51.757237300Z,10,2,1108,C,B,10,13.000000000,2,325967705,165809,276428333,13.31,10,1,13.28,1,2,13.27,20,2,13.26,198,2,13.14,1,1,13.13,100,1,13.12,200,2,13.11,100,1,13.10,100,1,13.04,2,1,13.40,0,-10,13.53,0,-1,13.55,0,-1,13.56,0,-2,13.57,0,-2,13.58,0,-3,13.59,0,-3,13.60,0,-4,13.61,0,-4,13.62,0,-1,ARL,0
2025-07-17T16:06:51.757403109Z,2025-07-17T16:06:51.757237300Z,10,2,1108,A,B,10,12.900000000,2,331694297,165809,276428333,13.31,10,1,13.28,1,2,13.27,20,2,13.26,198,2,13.14,1,1,13.13,100,1,13.12,200,2,13.11,100,1,13.10,100,1,13.04,2,1,13.40,0,-10,13.53,0,-1,13.55,0,-1,13.56,0,-2,13.57,0,-2,13.58,0,-3,13.59,0,-3,13.60,0,-4,13.61,0,-4,13.62,0,-1,ARL,0
2025-07-17T16:06:55.056300861Z,2025-07-17T16:06:55.056135380Z,10,2,1108,C,A,10,13.540000000,15,331666961,165481,276516227,13.31,10,1,13.28,1,2,13.27,20,2,13.26,198,2,13.14,1,1,13.13,100,1,13.12,200,2,13.11,100,1,13.10,100,1,13.04,2,1,13.40,0,-10,13.53,0,-1,13.55,0,-1,13.56,0,-2,13.57,0,-2,13.58,0,-3,13.59,0,-3,13.60,0,-4,13.61,0,-4,13.62,0,-1,ARL,0
2025-07-17T16:06:55.056466231Z,2025-07-17T16:06:55.056301001Z,10,2,1108,C,A,10,13.560000000,15,331488089,165230,276516239,13.31,10,1,13.28,1,2,13.27,20,2,13.26,198,2,13.14,1,1,13.13,100,1,13.12,200,2,13.11,100,1,13.10,100,1,13.04,2,1,13.40,0,-10,13.53,0,-1,13.55,0,-1,13.56,0,-2,13.57,0,-2,13.58,0,-3,13.59,0,-3,13.60,0,-4,13.61,0,-4,13.62,0,-1,ARL,0
2025-07-17T16:07:00.010995558Z,2025-07-17T16:07:00.010829521Z,10,2,1108,C,A,10,13.550000000,100,331694265,166037,276611719,13.31,10,1,13.28,1,2,13.27,20,2,13.26,198,2,13.14,1,1,13.13,100,1,13.12,200,2,13.11,100,1,13.10,100,1,13.04,2,1,13.40,0,-10,13.53,0,-1,13.55,0,-1,13.56,0,-2,13.57,0,-2,13.58,0,-3,13.59,0,-3,13.60,0,-4,13.61,0,-4,13.62,0,-1,ARL,0
2025-07-17T16:07:00.023849180Z,2025-07-17T16:07:00.023683961Z,10,2,1108,C,A,10,13.580000000,100,331667121,165219,276613073,13.31,10,1,13.28,1,2,13.27,20,2,13.26,198,2,13.14,1,1,13.13,100,1,13.12,200,2,13.11,100,1,13.10,100,1,13.04,2,1,13.40,0,-10,13.53,0,-1,13.55,0,-1,13.56,0,-2,13.57,0,-2,13.58,0,-3,13.59,0,-3,13.60,0,-4,13.61,0,-4,13.62,0,-1,ARL,0
2025-07-17T16:07:00.023917543Z,2025-07-17T16:07:00.023752163Z,10,2,1108,C,A,10,14.270000000,700,331257169,165380,276613077,13.31,10,1,13.28,1,2,13.27,20,2,13.26,198,2,13.14,1,1,13.13,100,1,13.12,200,2,13.11,100,1,13.10,100,1,13.04,2,1,13.40,0,-10,13.53,0,-1,13.55,0,-1,13.56,0,-2,13.57,0,-2,13.58,0,-3,13.59,0,-3,13.60,0,-4,13.61,0,-4,13.62,0,-1,ARL,0
2025-07-17T16:07:00.023980805Z,2025-07-17T16:07:00.023815326Z,10,2,1108,A,A,10,14.510000000,700,331926981,165479,276613078,13.31,10,1,13.28,1,2,13.27,20,2,13.26,198,2,13.14,1,1,13.13,100,1,13.12,200,2,13.11,100,1,13.10,100,1,13.04,2,1,13.40,0,-10,13.53,0,-1,13.55,0,-1,13.56,0,-2,13.57,0,-2,13.58,0,-3,13.59,0,-3,13.60,0,-4,13.61,0,-4,13.62,0,-1,ARL,0
2025-07-17T16:07:00.024590283Z,2025-07-17T16:07:00.024424816Z,10,2,1108,C,A,10,14.620000000,100,331491077,165467,276613110,13.31,10,1,13.28,1,2,13.27,20,2,13.26,198,2,13.14,1,1,13.13,100,1,13.12,200,2,13.11,100,1,13.10,100,1,13.04,2,1,13.40,0,-10,13.53,0,-1,13.55,0,-1,13.56,0,-2,13.57,0,-2,13.58,0,-3,13.59,0,-3,13.60,0,-4,13.61,0,-4,13.62,0,-1,ARL,0
2025-07-17T16:07:00.024590283Z,2025-07-17T16:07:00.024424816Z,10,2,1108,A,A,10,14.880000000,100,331927017,165467,276613110,13.31,10,1,13.28,1,2,13.27,20,2,13.26,198,2,13.14,1,1,13.13,100,1,13.12,200,2,13.11,100,1,13.10,100,1,13.04,2,1,13.40,0,-10,13.53,0,-1,13.55,0,-1,13.56,0,-2,13.57,0,-2,13.58,0,-3,13.59,0,-3,13.60,0,-4,13.61,0,-4,13.62,0,-1,ARL,0
2025-07-17T16:07:00.025231164Z,2025-07-17T16:07:00.025064913Z,10,2,1108,C,A,10,14.230000000,100,329074833,166251,276613157,13.31,10,1,13.28,1,2,13.27,20,2,13.26,198,2,13.14,1,1,13.13,100,1,13.12,200,2,13.11,100,1,13.10,100,1,13.04,2,1,13.40,0,-10,13.53,0,-1,13.55,0,-1,13.56,0,-2,13.57,0,-2,13.58,0,-3,13.59,0,-3,13.60,0,-4,13.61,0,-4,13.62,0,-1,ARL,0
2025-07-17T16:07:00.025587549Z,2025-07-17T16:07:00.025422082Z,10,2,1108,A,A,10,14.460000000,100,331927161,165467,276613175,13.31,10,1,13.28,1,2,13.27,20,2,13.26,198,2,13.14,1,1,13.13,100,1,13.12,200,2,13.11,100,1,13.10,100,1,13.04,2,1,13.40,0,-10,13.53,0,-1,13.55,0,-1,13.56,0,-2,13.57,0,-2,13.58,0,-3,13.59,0,-3,13.60,0,-4,13.61,0,-4,13.62,0,-1,ARL,0
2025-07-17T16:07:00.025793260Z,2025-07-17T16:07:00.025628157Z,10,2,1108,A,A,10,13.590000000,100,331927177,165103,276613194,13.31,10,1,13.28,1,2,13.27,20,2,13.26,198,2,13.14,1,1,13.13,100,1,13.12,200,2,13.11,100,1,13.10,100,1,13.04,2,1,13.40,0,-10,13.53,0,-1,13.55,0,-1,13.56,0,-2,13.57,0,-2,13.58,0,-3,13.59,0,-3,13.60,0,-4,13.61,0,-4,13.62,0,-1,ARL,0
2025-07-17T16:07:00.026998695Z,2025-07-17T16:07:00.026833761Z,10,2,1108,C,A,10,13.590000000,100,331927177,164934,276613224,13.31,10,1,13.28,1,2,13.27,20,2,13.26,198,2,13.14,1,1,13.13,100,1,13.12,200,2,13.11,100,1,13.10,100,1,13.04,2,1,13.40,0,-10,13.53,0,-1,13.55,0,-1,13.56,0,-2,13.57,0,-2,13.58,0,-3,13.59,0,-4,13.60,0,-4,13.61,0,-4,13.62,0,-1,ARL,0
2025-07-17T16:07:00.032762182Z,2025-07-17T16:07:00.032596898Z,10,2,1108,C,A,10,14.380000000,100,331051369,165284,276613329,13.31,10,1,13.28,1,2,13.27,20,2,13.26,198,2,13.14,1,1,13.13,100,1,13.12,200,2,13.11,100,1,13.10,100,1,13.04,2,1,13.40,0,-10,13.53,0,-1,13.55,0,-1,13.56,0,-2,13.57,0,-2,13.58,0,-3,13.59,0,-4,13.60,0,-4,13.61,0,-4,13.62,0,-1,ARL,0
2025-07-17T16:07:00.032876947Z,2025-07-17T16:07:00.032711777Z,10,2,1108,A,A,10,14.630000000,100,331927477,165170,276613336,13.31,10,1,13.28,1,2,13.27,20,2,13.26,198,2,13.14,1,1,13.13,100,1,13.12,200,2,13.11,100,1,13.10,100,1,13.04,2,1,13.40,0,-10,13.53,0,-1,13.55,0,-1,13.56,0,-2,13.57,0,-2,13.58,0,-3,13.59,0,-4,13.60,0,-4,13.61,0,-4,13.62,0,-1,ARL,0
2025-07-17T16:07:00.045525047Z,2025-07-17T16:07:00.045359807Z,10,2,1108,C,A,10,13.840000000,100,331491269,165240,276613663,13.31,10,1,13.28,1,2,13.27,20,2,13.26,198,2,13.14,1,1,13.13,100,1,13.12,200,2,13.11,100,1,13.10,100,1,13.04,2,1,13.40,0,-10,13.53,0,-1,13.55,0,-1,13.56,0,-2,13.57,0,-2,13.58,0,-3,13.59,0,-4,13.60,0,-4,13.61,0,-4,13.62,0,-1,ARL,0
2025-07-17T16:07:00.045559272Z,2025-07-17T16:07:00.045394317Z,10,2,1108,C,A,10,14.510000000,700,331926981,164955,276613664,13.31,10,1,13.28,1,2,13.27,20,2,13.26,198,2,13.14,1,1,13.13,100,1,13.12,200,2,13.11,100,1,13.10,100,1,13.04,2,1,13.40,0,-10,13.53,0,-1,13.55,0,-1,13.56,0,-2,13.57,0,-2,13.58,0,-3,13.59,0,-4,13.60,0,-4,13.61,0,-4,13.62,0,-1,ARL,0
2025-07-17T16:07:00.045574786Z,2025-07-17T16:07:00.045409635Z,10,2,1108,A,A,10,14.090000000,100,331927857,165151,276613665,13.31,10,1,13.28,1,2,13.27,20,2,13.26,198,2,13.14,1,1,13.13,100,1,13.12,200,2,13.11,100,1,13.10,100,1,13.04,2,1,13.40,0,-10,13.53,0,-1,13.55,0,-1,13.56,0,-2,13.57,0,-2,13.58,0,-3,13.59,0,-4,13.60,0,-4,13.61,0,-4,13.62,0,-1,ARL,0
2025-07-17T16:07:00.046838602Z,2025-07-17T16:07:00.046672908Z,10,2,1108,C,A,10,14.090000000,100,331927857,165694,276613680,13.31,10,1,13.28,1,2,13.27,20,2,13.26,198,2,13.14,1,1,13.13,100,1,13.12,200,2,13.11,100,1,13.10,100,1,13.04,2,1,13.40,0,-10,13.53,0,-1,13.55,0,-1,13.56,0,-2,13.57,0,-2,13.58,0,-3,13.59,0,-4,13.60,0,-4,13.61,0,-4,13.62,0,-1,ARL,0
2025-07-17T16:07:00.046887005Z,2025-07-17T16:07:00.046721624Z,10,2,1108,A,A,10,13.860000000,100,331927877,165381,276613681,13.31,10,1,13.28,1,2,13.27,20,2,13.26,198,2,13.14,1,1,13.13,100,1,13.12,200,2,13.11,100,1,13.10,100,1,13.04,2,1,13.40,0,-10,13.53,0,-1,13.55,0,-1,13.56,0,-2,13.57,0,-2,13.58,0,-3,13.59,0,-4,13.60,0,-4,13.61,0,-4,13.62,0,-1,ARL,0
2025-07-17T16:07:00.047708936Z,2025-07-17T16:07:00.047544064Z,10,2,1108,C,A,10,13.860000000,100,331927877,164872,276613692,13.31,10,1,13.28,1,2,13.27,20,2,13.26,198,2,13.14,1,1,13.13,100,1,13.12,200,2,13.11,100,1,13.10,100,1,13.04,2,1,13.40,0,-10,13.53,0,-1,13.55,0,-1,13.56,0,-2,13.57,0,-2,13.58,0,-3,13.59,0,-4,13.60,0,-4,13.61,0,-4,13.62,0,-1,ARL,0
2025-07-17T16:07:00.047755498Z,2025-07-17T16:07:00.047590313Z,10,2,1108,A,A,10,14.120000000,100,331927921,165185,276613693,13.31,10,1,13.28,1,2,13.27,20,2,13.26,198,2,13.14,1,1,13.13,100,1,13.12,200,2,13.11,100,1,13.10,100,1,13.04,2,1,13.40,0,-10,13.53,0,-1,13.55,0,-1,13.56,0,-2,13.57,0,-2,13.58,0,-3,13.59,0,-4,13.60,0,-4,13.61,0,-4,13.62,0,-1,ARL,0
2025-07-17T16:07:00.053448670Z,2025-07-17T16:07:00.053283700Z,10,2,1108,C,A,10,14.120000000,100,331927921,164970,276613731,13.31,10,1,13.28,1,2,13.27,20,2,13.26,198,2,13.14,1,1,13.13,100,1,13.12,200,2,13.11,100,1,13.10,100,1,13.04,2,1,13.40,0,-10,13.53,0,-1,13.55,0,-1,13.56,0,-2,13.57,0,-2,13.58,0,-3,13.59,0,-4,13.60,0,-4,13.61,0,-4,13.62,0,-1,ARL,0
2025-07-17T16:07:00.053495095Z,2025-07-17T16:07:00.053329959Z,10,2,1108,A,A,10,14.260000000,100,331928009,165136,276613732,13.31,10,1,13.28,1,2,13.27,20,2,13.26,198,2,13.14,1,1,13.13,100,1,13.12,200,2,13.11,100,1,13.10,100,1,13.04,2,1,13.40,0,-10,13.53,0,-1,13.55,0,-1,13.56,0,-2,13.57,0,-2,13.58,0,-3,13.59,0,-4,13.60,0,-4,13.61,0,-4,13.62,0,-1,ARL,0
2025-07-17T16:07:00.057809857Z,2025-07-17T16:07:00.057644427Z,10,2,1108,C,A,10,14.550000000,100,331052197,165430,276613800,13.31,10,1,13.28,1,2,13.27,20,2,13.26,198,2,13.14,1,1,13.13,100,1,13.12,200,2,13.11,100,1,13.10,100,1,13.04,2,1,13.40,0,-10,13.53,0,-1,13.55,0,-1,13.56,0,-2,13.57,0,-2,13.58,0,-3,13.59,0,-4,13.60,0,-4,13.61,0,-4,13.62,0,-1,ARL,0
2025-07-17T16:07:00.057809857Z,2025-07-17T16:07:00.057644427Z,10,2,1108,A,A,10,14.960000000,100,331928129,165430,276613800,13.31,10,1,13.28,1,2,13.27,20,2,13.26,198,2,13.14,1,1,13.13,100,1,13.12,200,2,13.11,100,1,13.10,100,1,13.04,2,1,13.40,0,-10,13.53,0,-1,13.55,0,-1,13.56,0,-2,13.57,0,-2,13.58,0,-3,13.59,0,-4,13.60,0,-4,13.61,0,-4,13.62,0,-1,ARL,0
2025-07-17T16:07:00.070490835Z,2025-07-17T16:07:00.070325784Z,10,2,1108,C,A,10,14.260000000,100,331928009,165051,276614087,13.31,10,1,13.28,1,2,13.27,20,2,13.26,198,2,13.14,1,1,13.13,100,1,13.12,200,2,13.11,100,1,13.10,100,1,13.04,2,1,13.40,0,-10,13.53,0,-1,13.55,0,-1,13.56,0,-2,13.57,0,-2,13.58,0,-3,13.59,0,-4,13.60,0,-4,13.61,0,-4,13.62,0,-1,ARL,0
2025-07-17T16:07:00.070539222Z,2025-07-17T16:07:00.070373975Z,10,2,1108,A,A,10,14.140000000,100,331929033,165247,276614089,13.31,10,1,13.28,1,2,13.27,20,2,13.26,198,2,13.14,1,1,13.13,100,1,13.12,200,2,13.11,100,1,13.10,100,1,13.04,2,1,13.40,0,-10,13.53,0,-1,13.55,0,-1,13.56,0,-2,13.57,0,-2,13.58,0,-3,13.59,0,-4,13.60,0,-4,13.61,0,-4,13.62,0,-1,ARL,0
2025-07-17T16:07:00.071359350Z,2025-07-17T16:07:00.071194493Z,10,2,1108,C,A,10,14.140000000,100,331929033,164857,276614094,13.31,10,1,13.28,1,2,13.27,20,2,13.26,198,2,13.14,1,1,13.13,100,1,13.12,200,2,13.11,100,1,13.10,100,1,13.04,2,1,13.40,0,-10,13.53,0,-1,13.55,0,-1,13.56,0,-2,13.57,0,-2,13.58,0,-3,13.59,0,-4,13.60,0,-4,13.61,0,-4,13.62,0,-1,ARL,0
2025-07-17T16:07:00.071405105Z,2025-07-17T16:07:00.071239867Z,10,2,1108,A,A,10,14.260000000,100,331929041,165238,276614095,13.31,10,1,13.28,1,2,13.27,20,2,13.26,198,2,13.14,1,1,13.13,100,1,13.12,200,2,13.11,100,1,13.10,100,1,13.04,2,1,13.40,0,-10,13.53,0,-1,13.55,0,-1,13.56,0,-2,13.57,0,-2,13.58,0,-3,13.59,0,-4,13.60,0,-4,13.61,0,-4,13.62,0,-1,ARL,0
2025-07-17T16:07:00.074580946Z,2025-07-17T16:07:00.074415631Z,10,2,1108,C,A,10,14.880000000,100,331927017,165315,276614119,13.31,10,1,13.28,1,2,13.27,20,2,13.26,198,2,13.14,1,1,13.13,100,1,13.12,200,2,13.11,100,1,13.10,100,1,13.04,2,1,13.40,0,-10,13.53,0,-1,13.55,0,-1,13.56,0,-2,13.57,0,-2,13.58,0,-3,13.59,0,-4,13.60,0,-4,13.61,0,-4,13.62,0,-1,ARL,0
2025-07-17T16:07:00.074580946Z,2025-07-17T16:07:00.074415631Z,10,2,1108,A,A,10,15.060000000,100,331929065,165315,276614119,13.31,10,1,13.28,1,2,13.27,20,2,13.26,198,2,13.14,1,1,13.13,100,1,13.12,200,2,13.11,100,1,13.10,100,1,13.04,2,1,13.40,0,-10,13.53,0,-1,13.55,0,-1,13.56,0,-2,13.57,0,-2,13.58,0,-3,13.59,0,-4,13.60,0,-4,13.61,0,-4,13.62,0,-1,ARL,0
2025-07-17T16:07:00.085131263Z,2025-07-17T16:07:00.084965637Z,10,2,1108,C,A,10,15.070000000,100,326837501,165626,276614295,13.31,10,1,13.28,1,2,13.27,20,2,13.26,198,2,13.14,1,1,13.13,100,1,13.12,200,2,13.11,100,1,13.10,100,1,13.04,2,1,13.40,0,-10,13.53,0,-1,13.55,0,-1,13.56,0,-2,13.57,0,-2,13.58,0,-3,13.59,0,-4,13.60,0,-4,13.61,0,-4,13.62,0,-1,ARL,0
2025-07-17T16:07:00.085131263Z,2025-07-17T16:07:00.084965637Z,10,2,1108,A,A,10,15.380000000,100,331929445,165626,276614295,13.31,10,1,13.28,1,2,13.27,20,2,13.26,198,2,13.14,1,1,13.13,100,1,13.12,200,2,13.11,100,1,13.10,100,1,13.04,2,1,13.40,0,-10,13.53,0,-1,13.55,0,-1,13.56,0,-2,13.57,0,-2,13.58,0,-3,13.59,0,-4,13.60,0,-4,13.61,0,-4,13.62,0,-1,ARL,0
2025-07-17T16:07:00.090359757Z,2025-07-17T16:07:00.090194106Z,10,2,1108,C,A,10,14.550000000,100,331051173,165651,276614378,13.31,10,1,13.28,1,2,13.27,20,2,13.26,198,2,13.14,1,1,13.13,100,1,13.12,200,2,13.11,100,1,13.10,100,1,13.04,2,1,13.40,0,-10,13.53,0,-1,13.55,0,-1,13.56,0,-2,13.57,0,-2,13.58,0,-3,13.59,0,-4,13.60,0,-4,13.61,0,-4,13.62,0,-1,ARL,0
2025-07-17T16:07:00.090359757Z,2025-07-17T16:07:00.090194106Z,10,2,1108,A,A,10,14.960000000,100,331929633,165651,276614378,13.31,10,1,13.28,1,2,13.27,20,2,13.26,198,2,13.14,1,1,13.13,100,1,13.12,200,2,13.11,100,1,13.10,100,1,13.04,2,1,13.40,0,-10,13.53,0,-1,13.55,0,-1,13.56,0,-2,13.57,0,-2,13.58,0,-3,13.59,0,-4,13.60,0,-4,13.61,0,-4,13.62,0,-1,ARL,0
2025-07-17T16:07:00.102092147Z,2025-07-17T16:07:00.101927028Z,10,2,1108,A,A,10,14.680000000,700,331929977,165119,276614699,13.31,10,1,13.28,1,2,13.27,20,2,13.26,198,2,13.14,1,1,13.13,100,1,13.12,200,2,13.11,100,1,13.10,100,1,13.04,2,1,13.40,0,-10,13.53,0,-1,13.55,0,-1,13.56,0,-2,13.57,0,-2,13.58,0,-3,13.59,0,-4,13.60,0,-4,13.61,0,-4,13.62,0,-1,ARL,0
2025-07-17T16:07:00.287582448Z,2025-07-17T16:07:00.287416733Z,10,2,1108,C,A,10,17.290000000,100,330789509,165715,276617288,13.31,10,1,13.28,1,2,13.27,20,2,13.26,198,2,13.14,1,1,13.13,100,1,13.12,200,2,13.11,100,1,13.10,100,1,13.04,2,1,13.40,0,-10,13.53,0,-1,13.55,0,-1,13.56,0,-2,13.57,0,-2,13.58,0,-3,13.59,0,-4,13.60,0,-4,13.61,0,-4,13.62,0,-1,ARL,0
2025-07-17T16:07:00.287582448Z,2025-07-17T16:07:00.287416733Z,10,2,1108,A,A,10,17.760000000,100,331934277,165715,276617288,13.31,10,1,13.28,1,2,13.27,20,2,13.26,198,2,13.14,1,1,13.13,100,1,13.12,200,2,13.11,100,1,13.10,100,1,13.04,2,1,13.40,0,-10,13.53,0,-1,13.55,0,-1,13.56,0,-2,13.57,0,-2,13.58,0,-3,13.59,0,-4,13.60,0,-4,13.61,0,-4,13.62,0,-1,ARL,0
2025-07-17T16:07:00.293620434Z,2025-07-17T16:07:00.293454856Z,10,2,1108,C,A,10,15.630000000,100,331051145,165578,276617317,13.31,10,1,13.28,1,2,13.27,20,2,13.26,198,2,13.14,1,1,13.13,100,1,13.12,200,2,13.11,100,1,13.10,100,1,13.04,2,1,13.40,0,-10,13.53,0,-1,13.55,0,-1,13.56,0,-2,13.57,0,-2,13.58,0,-3,13.59,0,-4,13.60,0,-4,13.61,0,-4,13.62,0,-1,ARL,0
2025-07-17T16:07:00.293620434Z,2025-07-17T16:07:00.293454856Z,10,2,1108,A,A,10,16.080000000,100,331934377,165578,276617317,13.31,10,1,13.28,1,2,13.27,20,2,13.26,198,2,13.14,1,1,13.13,100,1,13.12,200,2,13.11,100,1,13.10,100,1,13.04,2,1,13.40,0,-10,13.53,0,-1,13.55,0,-1,13.56,0,-2,13.57,0,-2,13.58,0,-3,13.59,0,-4,13.60,0,-4,13.61,0,-4,13.62,0,-1,ARL,0
2025-07-17T16:07:00.494657495Z,2025-07-17T16:07:00.494492099Z,10,2,1108,A,A,10,13.860000000,100,331942821,165396,276622423,13.31,10,1,13.28,1,2,13.27,20,2,13.26,198,2,13.14,1,1,13.13,100,1,13.12,200,2,13.11,100,1,13.10,100,1,13.04,2,1,13.40,0,-10,13.53,0,-1,13.55,0,-1,13.56,0,-2,13.57,0,-2,13.58,0,-3,13.59,0,-4,13.60,0,-4,13.61,0,-4,13.62,0,-1,ARL,0
2025-07-17T16:07:00.495318245Z,2025-07-17T16:07:00.495152219Z,10,2,1108,C,B,10,12.360000000,100,288723817,166026,276622452,13.31,10,1,13.28,1,2,13.27,20,2,13.26,198,2,13.14,1,1,13.13,100,1,13.12,200,2,13.11,100,1,13.10,100,1,13.04,2,1,13.40,0,-10,13.53,0,-1,13.55,0,-1,13.56,0,-2,13.57,0,-2,13.58,0,-3,13.59,0,-4,13.60,0,-4,13.61,0,-4,13.62,0,-1,ARL,0
2025-07-17T16:07:00.495318245Z,2025-07-17T16:07:00.495152219Z,10,2,1108,A,B,10,12.490000000,100,331942901,166026,276622452,13.31,10,1,13.28,1,2,13.27,20,2,13.26,198,2,13.14,1,1,13.13,100,1,13.12,200,2,13.11,100,1,13.10,100,1,13.04,2,1,13.40,0,-10,13.53,0,-1,13.55,0,-1,13.56,0,-2,13.57,0,-2,13.58,0,-3,13.59,0,-4,13.60,0,-4,13.61,0,-4,13.62,0,-1,ARL,0
2025-07-17T16:07:00.495398644Z,2025-07-17T16:07:00.495233001Z,10,2,1108,C,A,10,15.060000000,100,331929065,165643,276622455,13.31,10,1,13.28,1,2,13.27,20,2,13.26,198,2,13.14,1,1,13.13,100,1,13.12,200,2,13.11,100,1,13.10,100,1,13.04,2,1,13.40,0,-10,13.53,0,-1,13.55,0,-1,13.56,0,-2,13.57,0,-2,13.58,0,-3,13.59,0,-4,13.60,0,-4,13.61,0,-4,13.62,0,-1,ARL,0
2025-07-17T16:07:00.495398644Z,2025-07-17T16:07:00.495233001Z,10,2,1108,A,A,10,14.930000000,100,331942913,165643,276622455,13.31,10,1,13.28,1,2,13.27,20,2,13.26,198,2,13.14,1,1,13.13,100,1,13.12,200,2,13.11,100,1,13.10,100,1,13.04,2,1,13.40,0,-10,13.53,0,-1,13.55,0,-1,13.56,0,-2,13.57,0,-2,13.58,0,-3,13.59,0,-4,13.60,0,-4,13.61,0,-4,13.62,0,-1,ARL,0
2025-07-17T16:07:00.495989598Z,2025-07-17T16:07:00.495823953Z,10,2,1108,C,B,10,12.360000000,100,288723813,165645,276622469,13.31,10,1,13.28,1,2,13.27,20,2,13.26,198,2,13.14,1,1,13.13,100,1,13.12,200,2,13.11,100,1,13.10,100,1,13.04,2,1,13.40,0,-10,13.53,0,-1,13.55,0,-1,13.56,0,-2,13.57,0,-2,13.58,0,-3,13.59,0,-4,13.60,0,-4,13.61,0,-4,13.62,0,-1,ARL,0
2025-07-17T16:07:00.495989598Z,2025-07-17T16:07:00.495823953Z,10,2,1108,A,B,10,12.490000000,100,331942945,165645,276622469,13.31,10,1,13.28,1,2,13.27,20,2,13.26,198,2,13.14,1,1,13.13,100,1,13.12,200,2,13.11,100,1,13.10,100,1,13.04,2,1,13.40,0,-10,13.53,0,-1,13.55,0,-1,13.56,0,-2,13.57,0,-2,13.58,0,-3,13.59,0,-4,13.60,0,-4,13.61,0,-4,13.62,0,-1,ARL,0
2025-07-17T16:07:00.496483460Z,2025-07-17T16:07:00.496317847Z,10,2,1108,C,A,10,17.760000000,100,331934277,165613,276622478,13.31,10,1,13.28,1,2,13.27,20,2,13.26,198,2,13.14,1,1,13.13,100,1,13.12,200,2,13.11,100,1,13.10,100,1,13.04,2,1,13.40,0,-10,13.53,0,-1,13.55,0,-1,13.56,0,-2,13.57,0,-2,13.58,0,-3,13.59,0,-4,13.60,0,-4,13.61,0,-4,13.62,0,-1,ARL,0
2025-07-17T16:07:00.496483460Z,2025-07-17T16:07:00.496317847Z,10,2,1108,A,A,10,17.610000000,100,331942981,165613,276622478,13.31,10,1,13.28,1,2,13.27,20,2,13.26,198,2,13.14,1,1,13.13,100,1,13.12,200,2,13.11,100,1,13.10,100,1,13.04,2,1,13.40,0,-10,13.53,0,-1,13.55,0,-1,13.56,0,-2,13.57,0,-2,13.58,0,-3,13.59,0,-4,13.60,0,-4,13.61,0,-4,13.62,0,-1,ARL,0
2025-07-17T16:07:00.499666149Z,2025-07-17T16:07:00.499501052Z,10,2,1108,C,A,10,14.260000000,100,331929041,165097,276622569,13.31,10,1,13.28,1,2,13.27,20,2,13.26,198,2,13.14,1,1,13.13,100,1,13.12,200,2,13.11,100,1,13.10,100,1,13.04,2,1,13.40,0,-10,13.53,0,-1,13.55,0,-1,13.56,0,-2,13.57,0,-2,13.58,0,-3,13.59,0,-4,13.60,0,-4,13.61,0,-4,13.62,0,-1,ARL,0
2025-07-17T16:07:00.499714918Z,2025-07-17T16:07:00.499549738Z,10,2,1108,A,A,10,14.140000000,100,331943133,165180,276622571,13.31,10,1,13.28,1,2,13.27,20,2,13.26,198,2,13.14,1,1,13.13,100,1,13.12,200,2,13.11,100,1,13.10,100,1,13.04,2,1,13.40,0,-10,13.53,0,-1,13.55,0,-1,13.56,0,-2,13.57,0,-2,13.58,0,-3,13.59,0,-4,13.60,0,-4,13.61,0,-4,13.62,0,-1,ARL,0
2025-07-17T16:07:22.814941809Z,2025-07-17T16:07:22.814776694Z,10,2,1108,A,A,10,13.690000000,15,332385317,165115,276946179,13.31,10,1,13.28,1,2,13.27,20,2,13.26,198,2,13.14,1,1,13.13,100,1,13.12,200,2,13.11,100,1,13.10,100,1,13.04,2,1,13.40,0,-10,13.53,0,-1,13.55,0,-1,13.56,0,-2,13.57,0,-2,13.58,0,-3,13.59,0,-4,13.60,0,-4,13.61,0,-4,13.62,0,-1,ARL,0
2025-07-17T16:07:22.815057507Z,2025-07-17T16:07:22.814891345Z,10,2,1108,C,A,10,13.860000000,100,331942821,166162,276946183,13.31,10,1,13.28,1,2,13.27,20,2,13.26,198,2,13.14,1,1,13.13,100,1,13.12,200,2,13.11,100,1,13.10,100,1,13.04,2,1,13.40,0,-10,13.53,0,-1,13.55,0,-1,13.56,0,-2,13.57,0,-2,13.58,0,-3,13.59,0,-4,13.60,0,-4,13.61,0,-4,13.62,0,-1,ARL,0
2025-07-17T16:07:22.815057507Z,2025-07-17T16:07:22.814891345Z,10,2,1108,A,A,10,13.700000000,100,332385325,166162,276946183,13.31,10,1,13.28,1,2,13.27,20,2,13.26,198,2,13.14,1,1,13.13,100,1,13.12,200,2,13.11,100,1,13.10,100,1,13.04,2,1,13.40,0,-10,13.53,0,-1,13.55,0,-1,13.56,0,-2,13.57,0,-2,13.58,0,-3,13.59,0,-4,13.60,0,-4,13.61,0,-4,13.62,0,-1,ARL,0
2025-07-17T16:07:22.815790890Z,2025-07-17T16:07:22.815625345Z,10,2,1108,C,A,10,14.930000000,100,331942913,165545,276946264,13.31,10,1,13.28,1,2,13.27,20,2,13.26,198,2,13.14,1,1,13.13,100,1,13.12,200,2,13.11,100,1,13.10,100,1,13.04,2,1,13.40,0,-10,13.53,0,-1,13.55,0,-1,13.56,0,-2,13.57,0,-2,13.58,0,-3,13.59,0,-4,13.60,0,-4,13.61,0,-4,13.62,0,-1,ARL,0
2025-07-17T16:07:22.815790890Z,2025-07-17T16:07:22.815625345Z,10,2,1108,A,A,10,14.760000000,100,332385501,165545,276946264,13.31,10,1,13.28,1,2,13.27,20,2,13.26,198,2,13.14,1,1,13.13,100,1,13.12,200,2,13.11,100,1,13.10,100,1,13.04,2,1,13.40,0,-10,13.53,0,-1,13.55,0,-1,13.56,0,-2,13.57,0,-2,13.58,0,-3,13.59,0,-4,13.60,0,-4,13.61,0,-4,13.62,0,-1,ARL,0
2025-07-17T16:07:22.817507809Z,2025-07-17T16:07:22.817341789Z,10,2,1108,C,A,10,14.960000000,100,331929633,166020,276946309,13.31,10,1,13.28,1,2,13.27,20,2,13.26,198,2,13.14,1,1,13.13,100,1,13.12,200,2,13.11,100,1,13.10,100,1,13.04,2,1,13.40,0,-10,13.53,0,-1,13.55,0,-1,13.56,0,-2,13.57,0,-2,13.58,0,-3,13.59,0,-4,13.60,0,-4,13.61,0,-4,13.62,0,-1,ARL,0
2025-07-17T16:07:22.817507809Z,2025-07-17T16:07:22.817341789Z,10,2,1108,A,A,10,14.660000000,100,332385565,166020,276946309,13.31,10,1,13.28,1,2,13.27,20,2,13.26,198,2,13.14,1,1,13.13,100,1,13.12,200,2,13.11,100,1,13.10,100,1,13.04,2,1,13.40,0,-10,13.53,0,-1,13.55,0,-1,13.56,0,-2,13.57,0,-2,13.58,0,-3,13.59,0,-4,13.60,0,-4,13.61,0,-4,13.62,0,-1,ARL,0
2025-07-17T16:07:22.817624699Z,2025-07-17T16:07:22.817459170Z,10,2,1108,C,A,10,15.380000000,100,331929445,165529,276946313,13.31,10,1,13.28,1,2,13.27,20,2,13.26,198,2,13.14,1,1,13.13,100,1,13.12,200,2,13.11,100,1,13.10,100,1,13.04,2,1,13.40,0,-10,13.53,0,-1,13.55,0,-1,13.56,0,-2,13.57,0,-2,13.58,0,-3,13.59,0,-4,13.60,0,-4,13.61,0,-4,13.62,0,-1,ARL,0
2025-07-17T16:07:22.817624699Z,2025-07-17T16:07:22.817459170Z,10,2,1108,A,A,10,15.070000000,100,332385569,165529,276946313,13.31,10,1,13.28,1,2,13.27,20,2,13.26,198,2,13.14,1,1,13.13,100,1,13.12,200,2,13.11,100,1,13.10,100,1,13.04,2,1,13.40,0,-10,13.53,0,-1,13.55,0,-1,13.56,0,-2,13.57,0,-2,13.58,0,-3,13.59,0,-4,13.60,0,-4,13.61,0,-4,13.62,0,-1,ARL,0
2025-07-17T16:07:22.818565766Z,2025-07-17T16:07:22.818400003Z,10,2,1108,C,A,10,16.080000000,100,331934377,165763,276946327,13.31,10,1,13.28,1,2,13.27,20,2,13.26,198,2,13.14,1,1,13.13,100,1,13.12,200,2,13.11,100,1,13.10,100,1,13.04,2,1,13.40,0,-10,13.53,0,-1,13.55,0,-1,13.56,0,-2,13.57,0,-2,13.58,0,-3,13.59,0,-4,13.60,0,-4,13.61,0,-4,13.62,0,-1,ARL,0
2025-07-17T16:07:22.818565766Z,2025-07-17T16:07:22.818400003Z,10,2,1108,A,A,10,15.760000000,100,332385585,165763,276946327,13.31,10,1,13.28,1,2,13.27,20,2,13.26,198,2,13.14,1,1,13.13,100,1,13.12,200,2,13.11,100,1,13.10,100,1,13.04,2,1,13.40,0,-10,13.53,0,-1,13.55,0,-1,13.56,0,-2,13.57,0,-2,13.58,0,-3,13.59,0,-4,13.60,0,-4,13.61,0,-4,13.62,0,-1,ARL,0
2025-07-17T16:07:22.819710983Z,2025-07-17T16:07:22.819545360Z,10,2,1108,C,A,10,17.610000000,100,331942981,165623,276946336,13.31,10,1,13.28,1,2,13.27,20,2,13.26,198,2,13.14,1,1,13.13,100,1,13.12,200,2,13.11,100,1,13.10,100,1,13.04,2,1,13.40,0,-10,13.53,0,-1,13.55,0,-1,13.56,0,-2,13.57,0,-2,13.58,0,-3,13.59,0,-4,13.60,0,-4,13.61,0,-4,13.62,0,-1,ARL,0
2025-07-17T16:07:22.819710983Z,2025-07-17T16:07:22.819545360Z,10,2,1108,A,A,10,17.400000000,100,332385593,165623,276946336,13.31,10,1,13.28,1,2,13.27,20,2,13.26,198,2,13.14,1,1,13.13,100,1,13.12,200,2,13.11,100,1,13.10,100,1,13.04,2,1,13.40,0,-10,13.53,0,-1,13.55,0,-1,13.56,0,-2,13.57,0,-2,13.58,0,-3,13.59,0,-4,13.60,0,-4,13.61,0,-4,13.62,0,-1,ARL,0
2025-07-17T16:07:22.819772408Z,2025-07-17T16:07:22.819606945Z,10,2,1108,C,A,10,14.630000000,100,331927477,165463,276946337,13.31,10,1,13.28,1,2,13.27,20,2,13.26,198,2,13.14,1,1,13.13,100,1,13.12,200,2,13.11,100,1,13.10,100,1,13.04,2,1,13.40,0,-10,13.53,0,-1,13.55,0,-1,13.56,0,-2,13.57,0,-2,13.58,0,-3,13.59,0,-4,13.60,0,-4,13.61,0,-4,13.62,0,-1,ARL,0
2025-07-17T16:07:22.819772408Z,2025-07-17T16:07:22.819606945Z,10,2,1108,A,A,10,14.490000000,100,332385597,165463,276946337,13.31,10,1,13.28,1,2,13.27,20,2,13.26,198,2,13.14,1,1,13.13,100,1,13.12,200,2,13.11,100,1,13.10,100,1,13.04,2,1,13.40,0,-10,13.53,0,-1,13.55,0,-1,13.56,0,-2,13.57,0,-2,13.58,0,-3,13.59,0,-4,13.60,0,-4,13.61,0,-4,13.62,0,-1,ARL,0
2025-07-17T16:07:22.821165451Z,2025-07-17T16:07:22.821000003Z,10,2,1108,C,A,10,14.140000000,100,331943133,165448,276946343,13.31,10,1,13.28,1,2,13.27,20,2,13.26,198,2,13.14,1,1,13.13,100,1,13.12,200,2,13.11,100,1,13.10,100,1,13.04,2,1,13.40,0,-10,13.53,0,-1,13.55,0,-1,13.56,0,-2,13.57,0,-2,13.58,0,-3,13.59,0,-4,13.60,0,-4,13.61,0,-4,13.62,0,-1,ARL,0
2025-07-17T16:07:22.821218207Z,2025-07-17T16:07:22.821052982Z,10,2,1108,A,A,10,13.970000000,100,332385613,165225,276946344,13.31,10,1,13.28,1,2,13.27,20,2,13.26,198,2,13.14,1,1,13.13,100,1,13.12,200,2,13.11,100,1,13.10,100,1,13.04,2,1,13.40,0,-10,13.53,0,-1,13.55,0,-1,13.56,0,-2,13.57,0,-2,13.58,0,-3,13.59,0,-4,13.60,0,-4,13.61,0,-4,13.62,0,-1,ARL,0
2025-07-17T16:07:22.832119220Z,2025-07-17T16:07:22.831949887Z,10,2,1108,C,A,10,14.960000000,100,331928129,169333,276946801,13.31,10,1,13.28,1,2,13.27,20,2,13.26,198,2,13.14,1,1,13.13,100,1,13.12,200,2,13.11,100,1,13.10,100,1,13.04,2,1,13.40,0,-10,13.53,0,-1,13.55,0,-1,13.56,0,-2,13.57,0,-2,13.58,0,-3,13.59,0,-4,13.60,0,-4,13.61,0,-4,13.62,0,-1,ARL,0
2025-07-17T16:07:22.832119220Z,2025-07-17T16:07:22.831949887Z,10,2,1108,A,A,10,14.660000000,100,332386121,169333,276946801,13.31,10,1,13.28,1,2,13.27,20,2,13.26,198,2,13.14,1,1,13.13,100,1,13.12,200,2,13.11,100,1,13.10,100,1,13.04,2,1,13.40,0,-10,13.53,0,-1,13.55,0,-1,13.56,0,-2,13.57,0,-2,13.58,0,-3,13.59,0,-4,13.60,0,-4,13.61,0,-4,13.62,0,-1,ARL,0
2025-07-17T16:07:28.273823608Z,2025-07-17T16:07:28.273658191Z,10,2,1108,C,A,10,13.690000000,15,332385317,165417,277012951,13.31,10,1,13.28,1,2,13.27,20,2,13.26,198,2,13.14,1,1,13.13,100,1,13.12,200,2,13.11,100,1,13.10,100,1,13.04,2,1,13.40,0,-10,13.53,0,-1,13.55,0,-1,13.56,0,-2,13.57,0,-2,13.58,0,-3,13.59,0,-4,13.60,0,-4,13.61,0,-4,13.62,0,-1,ARL,0
2025-07-17T16:07:28.700981149Z,2025-07-17T16:07:28.700815737Z,10,2,1108,C,A,10,13.700000000,100,332385325,165412,277019711,13.31,10,1,13.28,1,2,13.27,20,2,13.26,198,2,13.14,1,1,13.13,100,1,13.12,200,2,13.11,100,1,13.10,100,1,13.04,2,1,13.40,0,-10,13.53,0,-1,13.55,0,-1,13.56,0,-2,13.57,0,-2,13.58,0,-3,13.59,0,-4,13.60,0,-4,13.61,0,-4,13.62,0,-1,ARL,0
2025-07-17T16:07:28.701396669Z,2025-07-17T16:07:28.701230409Z,10,2,1108,C,B,10,12.900000000,2,331694297,166260,277019718,13.31,10,1,13.28,1,2,13.27,20,2,13.26,198,2,13.14,1,1,13.13,100,1,13.12,200,2,13.11,100,1,13.10,100,1,13.04,2,1,13.40,0,-10,13.53,0,-1,13.55,0,-1,13.56,0,-2,13.57,0,-2,13.58,0,-3,13.59,0,-4,13.60,0,-4,13.61,0,-4,13.62,0,-1,ARL,0
2025-07-17T16:07:28.701396669Z,2025-07-17T16:07:28.701230409Z,10,2,1108,A,B,10,13.010000000,2,332494213,166260,277019718,13.31,10,1,13.28,1,2,13.27,20,2,13.26,198,2,13.14,1,1,13.13,100,1,13.12,200,2,13.11,100,1,13.10,100,1,13.04,2,1,13.40,0,-10,13.53,0,-1,13.55,0,-1,13.56,0,-2,13.57,0,-2,13.58,0,-3,13.59,0,-4,13.60,0,-4,13.61,0,-4,13.62,0,-1,ARL,0
2025-07-17T16:07:28.701713232Z,2025-07-17T16:07:28.701547540Z,10,2,1108,C,A,10,14.760000000,100,332385501,165692,277019720,13.31,10,1,13.28,1,2,13.27,20,2,13.26,198,2,13.14,1,1,13.13,100,1,13.12,200,2,13.11,100,1,13.10,100,1,13.04,2,1,13.40,0,-10,13.53,0,-1,13.55,0,-1,13.56,0,-2,13.57,0,-2,13.58,0,-3,13.59,0,-4,13.60,0,-4,13.61,0,-4,13.62,0,-1,ARL,0
2025-07-17T16:07:28.701713232Z,2025-07-17T16:07:28.701547540Z,10,2,1108,A,A,10,14.820000000,100,332494229,165692,277019720,13.31,10,1,13.28,1,2,13.27,20,2,13.26,198,2,13.14,1,1,13.13,100,1,13.12,200,2,13.11,100,1,13.10,100,1,13.04,2,1,13.40,0,-10,13.53,0,-1,13.55,0,-1,13.56,0,-2,13.57,0,-2,13.58,0,-3,13.59,0,-4,13.60,0,-4,13.61,0,-4,13.62,0,-1,ARL,0
2025-07-17T16:07:28.702166297Z,2025-07-17T16:07:28.702000772Z,10,2,1108,C,A,10,15.760000000,100,332385585,165525,277019722,13.31,10,1,13.28,1,2,13.27,20,2,13.26,198,2,13.14,1,1,13.13,100,1,13.12,200,2,13.11,100,1,13.10,100,1,13.04,2,1,13.40,0,-10,13.53,0,-1,13.55,0,-1,13.56,0,-2,13.57,0,-2,13.58,0,-3,13.59,0,-4,13.60,0,-4,13.61,0,-4,13.62,0,-1,ARL,0
2025-07-17T16:07:28.702166297Z,2025-07-17T16:07:28.702000772Z,10,2,1108,A,A,10,16.010000000,100,332494245,165525,277019722,13.31,10,1,13.28,1,2,13.27,20,2,13.26,198,2,13.14,1,1,13.13,100,1,13.12,200,2,13.11,100,1,13.10,100,1,13.04,2,1,13.40,0,-10,13.53,0,-1,13.55,0,-1,13.56,0,-2,13.57,0,-2,13.58,0,-3,13.59,0,-4,13.60,0,-4,13.61,0,-4,13.62,0,-1,ARL,0
2025-07-17T16:07:28.702642020Z,2025-07-17T16:07:28.702476699Z,10,2,1108,C,A,10,14.660000000,100,332386121,165321,277019729,13.31,10,1,13.28,1,2,13.27,20,2,13.26,198,2,13.14,1,1,13.13,100,1,13.12,200,2,13.11,100,1,13.10,100,1,13.04,2,1,13.40,0,-10,13.53,0,-1,13.55,0,-1,13.56,0,-2,13.57,0,-2,13.58,0,-3,13.59,0,-4,13.60,0,-4,13.61,0,-4,13.62,0,-1,ARL,0
2025-07-17T16:07:28.702642020Z,2025-07-17T16:07:28.702476699Z,10,2,1108,A,A,10,14.950000000,100,332494281,165321,277019729,13.31,10,1,13.28,1,2,13.27,20,2,13.26,198,2,13.14,1,1,13.13,100,1,13.12,200,2,13.11,100,1,13.10,100,1,13.04,2,1,13.40,0,-10,13.53,0,-1,13.55,0,-1,13.56,0,-2,13.57,0,-2,13.58,0,-3,13.59,0,-4,13.60,0,-4,13.61,0,-4,13.62,0,-1,ARL,0
2025-07-17T16:07:28.703523092Z,2025-07-17T16:07:28.703357714Z,10,2,1108,C,A,10,14.660000000,100,332385565,165378,277019733,13.31,10,1,13.28,1,2,13.27,20,2,13.26,198,2,13.14,1,1,13.13,100,1,13.12,200,2,13.11,100,1,13.10,100,1,13.04,2,1,13.40,0,-10,13.53,0,-1,13.55,0,-1,13.56,0,-2,13.57,0,-2,13.58,0,-3,13.59,0,-4,13.60,0,-4,13.61,0,-4,13.62,0,-1,ARL,0
2025-07-17T16:07:28.703523092Z,2025-07-17T16:07:28.703357714Z,10,2,1108,A,A,10,14.950000000,100,332494285,165378,277019733,13.31,10,1,13.28,1,2,13.27,20,2,13.26,198,2,13.14,1,1,13.13,100,1,13.12,200,2,13.11,100,1,13.10,100,1,13.04,2,1,13.40,0,-10,13.53,0,-1,13.55,0,-1,13.56,0,-2,13.57,0,-2,13.58,0,-3,13.59,0,-4,13.60,0,-4,13.61,0,-4,13.62,0,-1,ARL,0
2025-07-17T16:07:28.703920336Z,2025-07-17T16:07:28.703754662Z,10,2,1108,C,A,10,15.070000000,100,332385569,165674,277019735,13.31,10,1,13.28,1,2,13.27,20,2,13.26,198,2,13.14,1,1,13.13,100,1,13.12,200,2,13.11,100,1,13.10,100,1,13.04,2,1,13.40,0,-10,13.53,0,-1,13.55,0,-1,13.56,0,-2,13.57,0,-2,13.58,0,-3,13.59,0,-4,13.60,0,-4,13.61,0,-4,13.62,0,-1,ARL,0
2025-07-17T16:07:28.703920336Z,2025-07-17T16:07:28.703754662Z,10,2,1108,A,A,10,15.370000000,100,332494289,165674,277019735,13.31,10,1,13.28,1,2,13.27,20,2,13.26,198,2,13.14,1,1,13.13,100,1,13.12,200,2,13.11,100,1,13.10,100,1,13.04,2,1,13.40,0,-10,13.53,0,-1,13.55,0,-1,13.56,0,-2,13.57,0,-2,13.58,0,-3,13.59,0,-4,13.60,0,-4,13.61,0,-4,13.62,0,-1,ARL,0
2025-07-17T16:07:28.704198103Z,2025-07-17T16:07:28.704032725Z,10,2,1108,C,A,10,17.400000000,100,332385593,165378,277019738,13.31,10,1,13.28,1,2,13.27,20,2,13.26,198,2,13.14,1,1,13.13,100,1,13.12,200,2,13.11,100,1,13.10,100,1,13.04,2,1,13.40,0,-10,13.53,0,-1,13.55,0,-1,13.56,0,-2,13.57,0,-2,13.58,0,-3,13.59,0,-4,13.60,0,-4,13.61,0,-4,13.62,0,-1,ARL,0
2025-07-17T16:07:28.704198103Z,2025-07-17T16:07:28.704032725Z,10,2,1108,A,A,10,17.750000000,100,332494297,165378,277019738,13.31,10,1,13.28,1,2,13.27,20,2,13.26,198,2,13.14,1,1,13.13,100,1,13.12,200,2,13.11,100,1,13.10,100,1,13.04,2,1,13.40,0,-10,13.53,0,-1,13.55,0,-1,13.56,0,-2,13.57,0,-2,13.58,0,-3,13.59,0,-4,13.60,0,-4,13.61,0,-4,13.62,0,-1,ARL,0
2025-07-17T16:07:28.724201840Z,2025-07-17T16:07:28.724036175Z,10,2,1108,C,A,10,13.970000000,100,332385613,165665,277019926,13.31,10,1,13.28,1,2,13.27,20,2,13.26,198,2,13.14,1,1,13.13,100,1,13.12,200,2,13.11,100,1,13.10,100,1,13.04,2,1,13.40,0,-10,13.53,0,-1,13.55,0,-1,13.56,0,-2,13.57,0,-2,13.58,0,-3,13.59,0,-4,13.60,0,-4,13.61,0,-4,13.62,0,-1,ARL,0
2025-07-17T16:07:28.724250835Z,2025-07-17T16:07:28.724085453Z,10,2,1108,A,A,10,14.200000000,100,332494893,165382,277019929,13.31,10,1,13.28,1,2,13.27,20,2,13.26,198,2,13.14,1,1,13.13,100,1,13.12,200,2,13.11,100,1,13.10,100,1,13.04,2,1,13.40,0,-10,13.53,0,-1,13.55,0,-1,13.56,0,-2,13.57,0,-2,13.58,0,-3,13.59,0,-4,13.60,0,-4,13.61,0,-4,13.62,0,-1,ARL,0
2025-07-17T16:07:28.751828120Z,2025-07-17T16:07:28.751662660Z,10,2,1108,C,A,10,14.820000000,100,332494229,165460,277020284,13.31,10,1,13.28,1,2,13.27,20,2,13.26,198,2,13.14,1,1,13.13,100,1,13.12,200,2,13.11,100,1,13.10,100,1,13.04,2,1,13.40,0,-10,13.53,0,-1,13.55,0,-1,13.56,0,-2,13.57,0,-2,13.58,0,-3,13.59,0,-4,13.60,0,-4,13.61,0,-4,13.62,0,-1,ARL,0
2025-07-17T16:07:28.751828120Z,2025-07-17T16:07:28.751662660Z,10,2,1108,A,A,10,15.050000000,100,332495781,165460,277020284,13.31,10,1,13.28,1,2,13.27,20,2,13.26,198,2,13.14,1,1,13.13,100,1,13.12,200,2,13.11,100,1,13.10,100,1,13.04,2,1,13.40,0,-10,13.53,0,-1,13.55,0,-1,13.56,0,-2,13.57,0,-2,13.58,0,-3,13.59,0,-4,13.60,0,-4,13.61,0,-4,13.62,0,-1,ARL,0
2025-07-17T16:07:28.831160987Z,2025-07-17T16:07:28.830995364Z,10,2,1108,C,A,10,14.490000000,100,332385597,165623,277021007,13.31,10,1,13.28,1,2,13.27,20,2,13.26,198,2,13.14,1,1,13.13,100,1,13.12,200,2,13.11,100,1,13.10,100,1,13.04,2,1,13.40,0,-10,13.53,0,-1,13.55,0,-1,13.56,0,-2,13.57,0,-2,13.58,0,-3,13.59,0,-4,13.60,0,-4,13.61,0,-4,13.62,0,-1,ARL,0
2025-07-17T16:07:28.831291377Z,2025-07-17T16:07:28.831125667Z,10,2,1108,A,A,10,14.770000000,100,332497653,165710,277021012,13.31,10,1,13.28,1,2,13.27,20,2,13.26,198,2,13.14,1,1,13.13,100,1,13.12,200,2,13.11,100,1,13.10,100,1,13.04,2,1,13.40,0,-10,13.53,0,-1,13.55,0,-1,13.56,0,-2,13.57,0,-2,13.58,0,-3,13.59,0,-4,13.60,0,-4,13.61,0,-4,13.62,0,-1,ARL,0
2025-07-17T16:07:29.214667270Z,2025-07-17T16:07:29.214500816Z,10,2,1108,A,A,10,13.860000000,100,332508813,166454,277029015,13.31,10,1,13.28,1,2,13.27,20,2,13.26,198,2,13.14,1,1,13.13,100,1,13.12,200,2,13.11,100,1,13.10,100,1,13.04,2,1,13.40,0,-10,13.53,0,-1,13.55,0,-1,13.56,0,-2,13.57,0,-2,13.58,0,-3,13.59,0,-4,13.60,0,-4,13.61,0,-4,13.62,0,-1,ARL,0
2025-07-17T16:07:29.215458844Z,2025-07-17T16:07:29.215292291Z,10,2,1108,C,A,10,15.050000000,100,332495781,166553,277029273,13.31,10,1,13.28,1,2,13.27,20,2,13.26,198,2,13.14,1,1,13.13,100,1,13.12,200,2,13.11,100,1,13.10,100,1,13.04,2,1,13.40,0,-10,13.53,0,-1,13.55,0,-1,13.56,0,-2,13.57,0,-2,13.58,0,-3,13.59,0,-4,13.60,0,-4,13.61,0,-4,13.62,0,-1,ARL,0
2025-07-17T16:07:29.215458844Z,2025-07-17T16:07:29.215292291Z,10,2,1108,A,A,10,14.930000000,100,332508997,166553,277029273,13.31,10,1,13.28,1,2,13.27,20,2,13.26,198,2,13.14,1,1,13.13,100,1,13.12,200,2,13.11,100,1,13.10,100,1,13.04,2,1,13.40,0,-10,13.53,0,-1,13.55,0,-1,13.56,0,-2,13.57,0,-2,13.58,0,-3,13.59,0,-4,13.60,0,-4,13.61,0,-4,13.62,0,-1,ARL,0
2025-07-17T16:08:20.816252850Z,2025-07-17T16:08:20.816087447Z,10,2,1108,A,A,10,13.680000000,15,333436357,165403,277732167,13.31,10,1,13.28,1,2,13.27,20,2,13.26,198,2,13.14,1,1,13.13,100,1,13.12,200,2,13.11,100,1,13.10,100,1,13.04,2,1,13.40,0,-10,13.53,0,-1,13.55,0,-1,13.56,0,-2,13.57,0,-2,13.58,0,-3,13.59,0,-4,13.60,0,-4,13.61,0,-4,13.62,0,-1,ARL,0
2025-07-17T16:08:20.816366205Z,2025-07-17T16:08:20.816200644Z,10,2,1108,C,A,10,13.860000000,100,332508813,165561,277732170,13.31,10,1,13.28,1,2,13.27,20,2,13.26,198,2,13.14,1,1,13.13,100,1,13.12,200,2,13.11,100,1,13.10,100,1,13.04,2,1,13.40,0,-10,13.53,0,-1,13.55,0,-1,13.56,0,-2,13.57,0,-2,13.58,0,-3,13.59,0,-4,13.60,0,-4,13.61,0,-4,13.62,0,-1,ARL,0
2025-07-17T16:08:20.816366205Z,2025-07-17T16:08:20.816200644Z,10,2,1108,A,A,10,13.690000000,100,333436361,165561,277732170,13.31,10,1,13.28,1,2,13.27,20,2,13.26,198,2,13.14,1,1,13.13,100,1,13.12,200,2,13.11,100,1,13.10,100,1,13.04,2,1,13.40,0,-10,13.53,0,-1,13.55,0,-1,13.56,0,-2,13.57,0,-2,13.58,0,-3,13.59,0,-4,13.60,0,-4,13.61,0,-4,13.62,0,-1,ARL,0
2025-07-17T16:08:20.817097587Z,2025-07-17T16:08:20.816932150Z,10,2,1108,C,A,10,14.930000000,100,332508997,165437,277732194,13.31,10,1,13.28,1,2,13.27,20,2,13.26,198,2,13.14,1,1,13.13,100,1,13.12,200,2,13.11,100,1,13.10,100,1,13.04,2,1,13.40,0,-10,13.53,0,-1,13.55,0,-1,13.56,0,-2,13.57,0,-2,13.58,0,-3,13.59,0,-4,13.60,0,-4,13.61,0,-4,13.62,0,-1,ARL,0
2025-07-17T16:08:20.817097587Z,2025-07-17T16:08:20.816932150Z,10,2,1108,A,A,10,14.750000000,100,333436397,165437,277732194,13.31,10,1,13.28,1,2,13.27,20,2,13.26,198,2,13.14,1,1,13.13,100,1,13.12,200,2,13.11,100,1,13.10,100,1,13.04,2,1,13.40,0,-10,13.53,0,-1,13.55,0,-1,13.56,0,-2,13.57,0,-2,13.58,0,-3,13.59,0,-4,13.60,0,-4,13.61,0,-4,13.62,0,-1,ARL,0
2025-07-17T16:08:20.818725102Z,2025-07-17T16:08:20.818559377Z,10,2,1108,C,A,10,15.370000000,100,332494289,165725,277732213,13.31,10,1,13.28,1,2,13.27,20,2,13.26,198,2,13.14,1,1,13.13,100,1,13.12,200,2,13.11,100,1,13.10,100,1,13.04,2,1,13.40,0,-10,13.53,0,-1,13.55,0,-1,13.56,0,-2,13.57,0,-2,13.58,0,-3,13.59,0,-4,13.60,0,-4,13.61,0,-4,13.62,0,-1,ARL,0
2025-07-17T16:08:20.818725102Z,2025-07-17T16:08:20.818559377Z,10,2,1108,A,A,10,15.060000000,100,333436421,165725,277732213,13.31,10,1,13.28,1,2,13.27,20,2,13.26,198,2,13.14,1,1,13.13,100,1,13.12,200,2,13.11,100,1,13.10,100,1,13.04,2,1,13.40,0,-10,13.53,0,-1,13.55,0,-1,13.56,0,-2,13.57,0,-2,13.58,0,-3,13.59,0,-4,13.60,0,-4,13.61,0,-4,13.62,0,-1,ARL,0
2025-07-17T16:08:20.819130820Z,2025-07-17T16:08:20.818965359Z,10,2,1108,C,A,10,14.950000000,100,332494285,165461,277732216,13.31,10,1,13.28,1,2,13.27,20,2,13.26,198,2,13.14,1,1,13.13,100,1,13.12,200,2,13.11,100,1,13.10,100,1,13.04,2,1,13.40,0,-10,13.53,0,-1,13.55,0,-1,13.56,0,-2,13.57,0,-2,13.58,0,-3,13.59,0,-4,13.60,0,-4,13.61,0,-4,13.62,0,-1,ARL,0
2025-07-17T16:08:20.819130820Z,2025-07-17T16:08:20.818965359Z,10,2,1108,A,A,10,14.650000000,100,333436425,165461,277732216,13.31,10,1,13.28,1,2,13.27,20,2,13.26,198,2,13.14,1,1,13.13,100,1,13.12,200,2,13.11,100,1,13.10,100,1,13.04,2,1,13.40,0,-10,13.53,0,-1,13.55,0,-1,13.56,0,-2,13.57,0,-2,13.58,0,-3,13.59,0,-4,13.60,0,-4,13.61,0,-4,13.62,0,-1,ARL,0
2025-07-17T16:08:20.819767091Z,2025-07-17T16:08:20.819601669Z,10,2,1108,C,A,10,17.750000000,100,332494297,165422,277732221,13.31,10,1,13.28,1,2,13.27,20,2,13.26,198,2,13.14,1,1,13.13,100,1,13.12,200,2,13.11,100,1,13.10,100,1,13.04,2,1,13.40,0,-10,13.53,0,-1,13.55,0,-1,13.56,0,-2,13.57,0,-2,13.58,0,-3,13.59,0,-4,13.60,0,-4,13.61,0,-4,13.62,0,-1,ARL,0
2025-07-17T16:08:20.819767091Z,2025-07-17T16:08:20.819601669Z,10,2,1108,A,A,10,17.390000000,100,333436441,165422,277732221,13.31,10,1,13.28,1,2,13.27,20,2,13.26,198,2,13.14,1,1,13.13,100,1,13.12,200,2,13.11,100,1,13.10,100,1,13.04,2,1,13.40,0,-10,13.53,0,-1,13.55,0,-1,13.56,0,-2,13.57,0,-2,13.58,0,-3,13.59,0,-4,13.60,0,-4,13.61,0,-4,13.62,0,-1,ARL,0
2025-07-17T16:08:20.820666169Z,2025-07-17T16:08:20.820500575Z,10,2,1108,C,A,10,16.010000000,100,332494245,165594,277732228,13.31,10,1,13.28,1,2,13.27,20,2,13.26,198,2,13.14,1,1,13.13,100,1,13.12,200,2,13.11,100,1,13.10,100,1,13.04,2,1,13.40,0,-10,13.53,0,-1,13.55,0,-1,13.56,0,-2,13.57,0,-2,13.58,0,-3,13.59,0,-4,13.60,0,-4,13.61,0,-4,13.62,0,-1,ARL,0
2025-07-17T16:08:20.820666169Z,2025-07-17T16:08:20.820500575Z,10,2,1108,A,A,10,15.750000000,100,333436449,165594,277732228,13.31,10,1,13.28,1,2,13.27,20,2,13.26,198,2,13.14,1,1,13.13,100,1,13.12,200,2,13.11,100,1,13.10,100,1,13.04,2,1,13.40,0,-10,13.53,0,-1,13.55,0,-1,13.56,0,-2,13.57,0,-2,13.58,0,-3,13.59,0,-4,13.60,0,-4,13.61,0,-4,13.62,0,-1,ARL,0
2025-07-17T16:08:20.822089544Z,2025-07-17T16:08:20.821924168Z,10,2,1108,C,A,10,14.200000000,100,332494893,165376,277732239,13.31,10,1,13.28,1,2,13.27,20,2,13.26,198,2,13.14,1,1,13.13,100,1,13.12,200,2,13.11,100,1,13.10,100,1,13.04,2,1,13.40,0,-10,13.53,0,-1,13.55,0,-1,13.56,0,-2,13.57,0,-2,13.58,0,-3,13.59,0,-4,13.60,0,-4,13.61,0,-4,13.62,0,-1,ARL,0
2025-07-17T16:08:20.822139541Z,2025-07-17T16:08:20.821974299Z,10,2,1108,A,A,10,13.960000000,100,333436473,165242,277732240,13.31,10,1,13.28,1,2,13.27,20,2,13.26,198,2,13.14,1,1,13.13,100,1,13.12,200,2,13.11,100,1,13.10,100,1,13.04,2,1,13.40,0,-10,13.53,0,-1,13.55,0,-1,13.56,0,-2,13.57,0,-2,13.58,0,-3,13.59,0,-4,13.60,0,-4,13.61,0,-4,13.62,0,-1,ARL,0
2025-07-17T16:08:20.830110499Z,2025-07-17T16:08:20.829945074Z,10,2,1108,C,A,10,14.950000000,100,332494281,165425,277732299,13.31,10,1,13.28,1,2,13.27,20,2,13.26,198,2,13.14,1,1,13.13,100,1,13.12,200,2,13.11,100,1,13.10,100,1,13.04,2,1,13.40,0,-10,13.53,0,-1,13.55,0,-1,13.56,0,-2,13.57,0,-2,13.58,0,-3,13.59,0,-4,13.60,0,-4,13.61,0,-4,13.62,0,-1,ARL,0
2025-07-17T16:08:20.830110499Z,2025-07-17T16:08:20.829945074Z,10,2,1108,A,A,10,14.650000000,100,333436589,165425,277732299,13.31,10,1,13.28,1,2,13.27,20,2,13.26,198,2,13.14,1,1,13.13,100,1,13.12,200,2,13.11,100,1,13.10,100,1,13.04,2,1,13.40,0,-10,13.53,0,-1,13.55,0,-1,13.56,0,-2,13.57,0,-2,13.58,0,-3,13.59,0,-4,13.60,0,-4,13.61,0,-4,13.62,0,-1,ARL,0
2025-07-17T16:08:20.966229266Z,2025-07-17T16:08:20.966063681Z,10,2,1108,C,A,10,14.770000000,100,332497653,165585,277733304,13.31,10,1,13.28,1,2,13.27,20,2,13.26,198,2,13.14,1,1,13.13,100,1,13.12,200,2,13.11,100,1,13.10,100,1,13.04,2,1,13.40,0,-10,13.53,0,-1,13.55,0,-1,13.56,0,-2,13.57,0,-2,13.58,0,-3,13.59,0,-4,13.60,0,-4,13.61,0,-4,13.62,0,-1,ARL,0
2025-07-17T16:08:20.966229266Z,2025-07-17T16:08:20.966063681Z,10,2,1108,A,A,10,14.480000000,100,333438545,165585,277733304,13.31,10,1,13.28,1,2,13.27,20,2,13.26,198,2,13.14,1,1,13.13,100,1,13.12,200,2,13.11,100,1,13.10,100,1,13.04,2,1,13.40,0,-10,13.53,0,-1,13.55,0,-1,13.56,0,-2,13.57,0,-2,13.58,0,-3,13.59,0,-4,13.60,0,-4,13.61,0,-4,13.62,0,-1,ARL,0
2025-07-17T16:08:22.998168186Z,2025-07-17T16:08:22.998002821Z,10,2,1108,C,A,10,13.680000000,15,333436357,165365,277766492,13.31,10,1,13.28,1,2,13.27,20,2,13.26,198,2,13.14,1,1,13.13,100,1,13.12,200,2,13.11,100,1,13.10,100,1,13.04,2,1,13.40,0,-10,13.53,0,-1,13.55,0,-1,13.56,0,-2,13.57,0,-2,13.58,0,-3,13.59,0,-4,13.60,0,-4,13.61,0,-4,13.62,0,-1,ARL,0
2025-07-17T16:08:27.482509684Z,2025-07-17T16:08:27.482344236Z,10,2,1108,C,A,10,13.690000000,100,333436361,165448,277841171,13.31,10,1,13.28,1,2,13.27,20,2,13.26,198,2,13.14,1,1,13.13,100,1,13.12,200,2,13.11,100,1,13.10,100,1,13.04,2,1,13.40,0,-10,13.53,0,-1,13.55,0,-1,13.56,0,-2,13.57,0,-2,13.58,0,-3,13.59,0,-4,13.60,0,-4,13.61,0,-4,13.62,0,-1,ARL,0
2025-07-17T16:08:27.483241007Z,2025-07-17T16:08:27.483075481Z,10,2,1108,C,A,10,14.750000000,100,333436397,165526,277841175,13.31,10,1,13.28,1,2,13.27,20,2,13.26,198,2,13.14,1,1,13.13,100,1,13.12,200,2,13.11,100,1,13.10,100,1,13.04,2,1,13.40,0,-10,13.53,0,-1,13.55,0,-1,13.56,0,-2,13.57,0,-2,13.58,0,-3,13.59,0,-4,13.60,0,-4,13.61,0,-4,13.62,0,-1,ARL,0
2025-07-17T16:08:27.483241007Z,2025-07-17T16:08:27.483075481Z,10,2,1108,A,A,10,14.990000000,100,333581389,165526,277841175,13.31,10,1,13.28,1,2,13.27,20,2,13.26,198,2,13.14,1,1,13.13,100,1,13.12,200,2,13.11,100,1,13.10,100,1,13.04,2,1,13.40,0,-10,13.53,0,-1,13.55,0,-1,13.56,0,-2,13.57,0,-2,13.58,0,-3,13.59,0,-4,13.60,0,-4,13.61,0,-4,13.62,0,-1,ARL,0
2025-07-17T16:08:27.483585892Z,2025-07-17T16:08:27.483420069Z,10,2,1108,C,A,10,14.520000000,100,328780577,165823,277841178,13.31,10,1,13.28,1,2,13.27,20,2,13.26,198,2,13.14,1,1,13.13,100,1,13.12,200,2,13.11,100,1,13.10,100,1,13.04,2,1,13.40,0,-10,13.53,0,-1,13.55,0,-1,13.56,0,-2,13.57,0,-2,13.58,0,-3,13.59,0,-4,13.60,0,-4,13.61,0,-4,13.62,0,-1,ARL,0
2025-07-17T16:08:27.483585892Z,2025-07-17T16:08:27.483420069Z,10,2,1108,A,A,10,14.740000000,100,333581393,165823,277841178,13.31,10,1,13.28,1,2,13.27,20,2,13.26,198,2,13.14,1,1,13.13,100,1,13.12,200,2,13.11,100,1,13.10,100,1,13.04,2,1,13.40,0,-10,13.53,0,-1,13.55,0,-1,13.56,0,-2,13.57,0,-2,13.58,0,-3,13.59,0,-4,13.60,0,-4,13.61,0,-4,13.62,0,-1,ARL,0
2025-07-17T16:08:27.484079224Z,2025-07-17T16:08:27.483913735Z,10,2,1108,C,A,10,14.650000000,100,333436589,165489,277841218,13.31,10,1,13.28,1,2,13.27,20,2,13.26,198,2,13.14,1,1,13.13,100,1,13.12,200,2,13.11,100,1,13.10,100,1,13.04,2,1,13.40,0,-10,13.53,0,-1,13.55,0,-1,13.56,0,-2,13.57,0,-2,13.58,0,-3,13.59,0,-4,13.60,0,-4,13.61,0,-4,13.62,0,-1,ARL,0
2025-07-17T16:08:27.484079224Z,2025-07-17T16:08:27.483913735Z,10,2,1108,A,A,10,14.940000000,100,333581409,165489,277841218,13.31,10,1,13.28,1,2,13.27,20,2,13.26,198,2,13.14,1,1,13.13,100,1,13.12,200,2,13.11,100,1,13.10,100,1,13.04,2,1,13.40,0,-10,13.53,0,-1,13.55,0,-1,13.56,0,-2,13.57,0,-2,13.58,0,-3,13.59,0,-4,13.60,0,-4,13.61,0,-4,13.62,0,-1,ARL,0
2025-07-17T16:08:27.484859188Z,2025-07-17T16:08:27.484693568Z,10,2,1108,C,A,10,17.390000000,100,333436441,165620,277841226,13.31,10,1,13.28,1,2,13.27,20,2,13.26,198,2,13.14,1,1,13.13,100,1,13.12,200,2,13.11,100,1,13.10,100,1,13.04,2,1,13.40,0,-10,13.53,0,-1,13.55,0,-1,13.56,0,-2,13.57,0,-2,13.58,0,-3,13.59,0,-4,13.60,0,-4,13.61,0,-4,13.62,0,-1,ARL,0
2025-07-17T16:08:27.484859188Z,2025-07-17T16:08:27.484693568Z,10,2,1108,A,A,10,17.730000000,100,333581425,165620,277841226,13.31,10,1,13.28,1,2,13.27,20,2,13.26,198,2,13.14,1,1,13.13,100,1,13.12,200,2,13.11,100,1,13.10,100,1,13.04,2,1,13.40,0,-10,13.53,0,-1,13.55,0,-1,13.56,0,-2,13.57,0,-2,13.58,0,-3,13.59,0,-4,13.60,0,-4,13.61,0,-4,13.62,0,-1,ARL,0
2025-07-17T16:08:27.484965957Z,2025-07-17T16:08:27.484800296Z,10,2,1108,C,A,10,14.650000000,100,333436425,165661,277841228,13.31,10,1,13.28,1,2,13.27,20,2,13.26,198,2,13.14,1,1,13.13,100,1,13.12,200,2,13.11,100,1,13.10,100,1,13.04,2,1,13.40,0,-10,13.53,0,-1,13.55,0,-1,13.56,0,-2,13.57,0,-2,13.58,0,-3,13.59,0,-4,13.60,0,-4,13.61,0,-4,13.62,0,-1,ARL,0
2025-07-17T16:08:27.484965957Z,2025-07-17T16:08:27.484800296Z,10,2,1108,A,A,10,14.940000000,100,333581429,165661,277841228,13.31,10,1,13.28,1,2,13.27,20,2,13.26,198,2,13.14,1,1,13.13,100,1,13.12,200,2,13.11,100,1,13.10,100,1,13.04,2,1,13.40,0,-10,13.53,0,-1,13.55,0,-1,13.56,0,-2,13.57,0,-2,13.58,0,-3,13.59,0,-4,13.60,0,-4,13.61,0,-4,13.62,0,-1,ARL,0
2025-07-17T16:08:27.484978859Z,2025-07-17T16:08:27.484813280Z,10,2,1108,C,A,10,15.750000000,100,333436449,165579,277841229,13.31,10,1,13.28,1,2,13.27,20,2,13.26,198,2,13.14,1,1,13.13,100,1,13.12,200,2,13.11,100,1,13.10,100,1,13.04,2,1,13.40,0,-10,13.53,0,-1,13.55,0,-1,13.56,0,-2,13.57,0,-2,13.58,0,-3,13.59,0,-4,13.60,0,-4,13.61,0,-4,13.62,0,-1,ARL,0
2025-07-17T16:08:27.484978859Z,2025-07-17T16:08:27.484813280Z,10,2,1108,A,A,10,16.060000000,100,333581433,165579,277841229,13.31,10,1,13.28,1,2,13.27,20,2,13.26,198,2,13.14,1,1,13.13,100,1,13.12,200,2,13.11,100,1,13.10,100,1,13.04,2,1,13.40,0,-10,13.53,0,-1,13.55,0,-1,13.56,0,-2,13.57,0,-2,13.58,0,-3,13.59,0,-4,13.60,0,-4,13.61,0,-4,13.62,0,-1,ARL,0
2025-07-17T16:08:27.485352204Z,2025-07-17T16:08:27.485186411Z,10,2,1108,C,A,10,15.060000000,100,333436421,165793,277841231,13.31,10,1,13.28,1,2,13.27,20,2,13.26,198,2,13.14,1,1,13.13,100,1,13.12,200,2,13.11,100,1,13.10,100,1,13.04,2,1,13.40,0,-10,13.53,0,-1,13.55,0,-1,13.56,0,-2,13.57,0,-2,13.58,0,-3,13.59,0,-4,13.60,0,-4,13.61,0,-4,13.62,0,-1,ARL,0
2025-07-17T16:08:27.485352204Z,2025-07-17T16:08:27.485186411Z,10,2,1108,A,A,10,15.360000000,100,333581441,165793,277841231,13.31,10,1,13.28,1,2,13.27,20,2,13.26,198,2,13.14,1,1,13.13,100,1,13.12,200,2,13.11,100,1,13.10,100,1,13.04,2,1,13.40,0,-10,13.53,0,-1,13.55,0,-1,13.56,0,-2,13.57,0,-2,13.58,0,-3,13.59,0,-4,13.60,0,-4,13.61,0,-4,13.62,0,-1,ARL,0
2025-07-17T16:08:27.487263276Z,2025-07-17T16:08:27.487097702Z,10,2,1108,C,A,10,14.520000000,100,328780597,165574,277841319,13.31,10,1,13.28,1,2,13.27,20,2,13.26,198,2,13.14,1,1,13.13,100,1,13.12,200,2,13.11,100,1,13.10,100,1,13.04,2,1,13.40,0,-10,13.53,0,-1,13.55,0,-1,13.56,0,-2,13.57,0,-2,13.58,0,-3,13.59,0,-4,13.60,0,-4,13.61,0,-4,13.62,0,-1,ARL,0
2025-07-17T16:08:27.487263276Z,2025-07-17T16:08:27.487097702Z,10,2,1108,A,A,10,14.740000000,100,333581481,165574,277841319,13.31,10,1,13.28,1,2,13.27,20,2,13.26,198,2,13.14,1,1,13.13,100,1,13.12,200,2,13.11,100,1,13.10,100,1,13.04,2,1,13.40,0,-10,13.53,0,-1,13.55,0,-1,13.56,0,-2,13.57,0,-2,13.58,0,-3,13.59,0,-4,13.60,0,-4,13.61,0,-4,13.62,0,-1,ARL,0
2025-07-17T16:08:27.492258906Z,2025-07-17T16:08:27.492093401Z,10,2,1108,C,A,10,14.480000000,100,333438545,165505,277841396,13.31,10,1,13.28,1,2,13.27,20,2,13.26,198,2,13.14,1,1,13.13,100,1,13.12,200,2,13.11,100,1,13.10,100,1,13.04,2,1,13.40,0,-10,13.53,0,-1,13.55,0,-1,13.56,0,-2,13.57,0,-2,13.58,0,-3,13.59,0,-4,13.60,0,-4,13.61,0,-4,13.62,0,-1,ARL,0
2025-07-17T16:08:27.492385750Z,2025-07-17T16:08:27.492220454Z,10,2,1108,A,A,10,14.750000000,100,333581569,165296,277841397,13.31,10,1,13.28,1,2,13.27,20,2,13.26,198,2,13.14,1,1,13.13,100,1,13.12,200,2,13.11,100,1,13.10,100,1,13.04,2,1,13.40,0,-10,13.53,0,-1,13.55,0,-1,13.56,0,-2,13.57,0,-2,13.58,0,-3,13.59,0,-4,13.60,0,-4,13.61,0,-4,13.62,0,-1,ARL,0
2025-07-17T16:08:27.496936122Z,2025-07-17T16:08:27.496770678Z,10,2,1108,C,A,10,13.960000000,100,333436473,165444,277841427,13.31,10,1,13.28,1,2,13.27,20,2,13.26,198,2,13.14,1,1,13.13,100,1,13.12,200,2,13.11,100,1,13.10,100,1,13.04,2,1,13.40,0,-10,13.53,0,-1,13.55,0,-1,13.56,0,-2,13.57,0,-2,13.58,0,-3,13.59,0,-4,13.60,0,-4,13.61,0,-4,13.62,0,-1,ARL,0
2025-07-17T16:08:27.496987832Z,2025-07-17T16:08:27.496822540Z,10,2,1108,A,A,10,14.190000000,100,333581625,165292,277841428,13.31,10,1,13.28,1,2,13.27,20,2,13.26,198,2,13.14,1,1,13.13,100,1,13.12,200,2,13.11,100,1,13.10,100,1,13.04,2,1,13.40,0,-10,13.53,0,-1,13.55,0,-1,13.56,0,-2,13.57,0,-2,13.58,0,-3,13.59,0,-4,13.60,0,-4,13.61,0,-4,13.62,0,-1,ARL,0
2025-07-17T16:08:27.501093618Z,2025-07-17T16:08:27.500928061Z,10,2,1108,C,A,10,13.850000000,2,331155889,165557,277841469,13.31,10,1,13.28,1,2,13.27,20,2,13.26,198,2,13.14,1,1,13.13,100,1,13.12,200,2,13.11,100,1,13.10,100,1,13.04,2,1,13.40,0,-10,13.53,0,-1,13.55,0,-1,13.56,0,-2,13.57,0,-2,13.58,0,-3,13.59,0,-4,13.60,0,-4,13.61,0,-4,13.62,0,-1,ARL,0
2025-07-17T16:08:27.501093618Z,2025-07-17T16:08:27.500928061Z,10,2,1108,A,A,10,13.980000000,2,333581677,165557,277841469,13.31,10,1,13.28,1,2,13.27,20,2,13.26,198,2,13.14,1,1,13.13,100,1,13.12,200,2,13.11,100,1,13.10,100,1,13.04,2,1,13.40,0,-10,13.53,0,-1,13.55,0,-1,13.56,0,-2,13.57,0,-2,13.58,0,-3,13.59,0,-4,13.60,0,-4,13.61,0,-4,13.62,0,-1,ARL,0
2025-07-17T16:08:27.516614373Z,2025-07-17T16:08:27.516449334Z,10,2,1108,C,A,10,14.190000000,100,333581625,165039,277841551,13.31,10,1,13.28,1,2,13.27,20,2,13.26,198,2,13.14,1,1,13.13,100,1,13.12,200,2,13.11,100,1,13.10,100,1,13.04,2,1,13.40,0,-10,13.53,0,-1,13.55,0,-1,13.56,0,-2,13.57,0,-2,13.58,0,-3,13.59,0,-4,13.60,0,-4,13.61,0,-4,13.62,0,-1,ARL,0
2025-07-17T16:08:27.516662099Z,2025-07-17T16:08:27.516496962Z,10,2,1108,A,A,10,14.260000000,100,333581765,165137,277841552,13.31,10,1,13.28,1,2,13.27,20,2,13.26,198,2,13.14,1,1,13.13,100,1,13.12,200,2,13.11,100,1,13.10,100,1,13.04,2,1,13.40,0,-10,13.53,0,-1,13.55,0,-1,13.56,0,-2,13.57,0,-2,13.58,0,-3,13.59,0,-4,13.60,0,-4,13.61,0,-4,13.62,0,-1,ARL,0
2025-07-17T16:08:27.533938450Z,2025-07-17T16:08:27.533773259Z,10,2,1108,C,A,10,14.990000000,100,333581389,165191,277841588,13.31,10,1,13.28,1,2,13.27,20,2,13.26,198,2,13.14,1,1,13.13,100,1,13.12,200,2,13.11,100,1,13.10,100,1,13.04,2,1,13.40,0,-10,13.53,0,-1,13.55,0,-1,13.56,0,-2,13.57,0,-2,13.58,0,-3,13.59,0,-4,13.60,0,-4,13.61,0,-4,13.62,0,-1,ARL,0
2025-07-17T16:08:27.533938450Z,2025-07-17T16:08:27.533773259Z,10,2,1108,A,A,10,15.040000000,100,333581845,165191,277841588,13.31,10,1,13.28,1,2,13.27,20,2,13.26,198,2,13.14,1,1,13.13,100,1,13.12,200,2,13.11,100,1,13.10,100,1,13.04,2,1,13.40,0,-10,13.53,0,-1,13.55,0,-1,13.56,0,-2,13.57,0,-2,13.58,0,-3,13.59,0,-4,13.60,0,-4,13.61,0,-4,13.62,0,-1,ARL,0
2025-07-17T16:08:27.987678739Z,2025-07-17T16:08:27.987513451Z,10,2,1108,A,A,10,13.990000000,100,333590057,165288,277846288,13.31,10,1,13.28,1,2,13.27,20,2,13.26,198,2,13.14,1,1,13.13,100,1,13.12,200,2,13.11,100,1,13.10,100,1,13.04,2,1,13.40,0,-10,13.53,0,-1,13.55,0,-1,13.56,0,-2,13.57,0,-2,13.58,0,-3,13.59,0,-4,13.60,0,-4,13.61,0,-4,13.62,0,-1,ARL,0
2025-07-17T16:08:58.024979382Z,2025-07-17T16:08:58.024814068Z,10,2,1108,A,A,10,13.810000000,15,334141429,165314,278261182,13.31,10,1,13.28,1,2,13.27,20,2,13.26,198,2,13.14,1,1,13.13,100,1,13.12,200,2,13.11,100,1,13.10,100,1,13.04,2,1,13.40,0,-10,13.53,0,-1,13.55,0,-1,13.56,0,-2,13.57,0,-2,13.58,0,-3,13.59,0,-4,13.60,0,-4,13.61,0,-4,13.62,0,-1,ARL,0
2025-07-17T16:09:00.222675234Z,2025-07-17T16:09:00.222509491Z,10,2,1108,C,A,10,13.990000000,100,333590057,165743,278295684,13.31,10,1,13.28,1,2,13.27,20,2,13.26,198,2,13.14,1,1,13.13,100,1,13.12,200,2,13.11,100,1,13.10,100,1,13.04,2,1,13.40,0,-10,13.53,0,-1,13.55,0,-1,13.56,0,-2,13.57,0,-2,13.58,0,-3,13.59,0,-4,13.60,0,-4,13.61,0,-4,13.62,0,-1,ARL,0
2025-07-17T16:09:00.222675234Z,2025-07-17T16:09:00.222509491Z,10,2,1108,A,A,10,13.820000000,100,334189729,165743,278295684,13.31,10,1,13.28,1,2,13.27,20,2,13.26,198,2,13.14,1,1,13.13,100,1,13.12,200,2,13.11,100,1,13.10,100,1,13.04,2,1,13.40,0,-10,13.53,0,-1,13.55,0,-1,13.56,0,-2,13.57,0,-2,13.58,0,-3,13.59,0,-4,13.60,0,-4,13.61,0,-4,13.62,0,-1,ARL,0
2025-07-17T16:09:00.223436757Z,2025-07-17T16:09:00.223269382Z,10,2,1108,C,A,10,15.040000000,100,333581845,167375,278295848,13.31,10,1,13.28,1,2,13.27,20,2,13.26,198,2,13.14,1,1,13.13,100,1,13.12,200,2,13.11,100,1,13.10,100,1,13.04,2,1,13.40,0,-10,13.53,0,-1,13.55,0,-1,13.56,0,-2,13.57,0,-2,13.58,0,-3,13.59,0,-4,13.60,0,-4,13.61,0,-4,13.62,0,-1,ARL,0
2025-07-17T16:09:00.223436757Z,2025-07-17T16:09:00.223269382Z,10,2,1108,A,A,10,14.890000000,100,334189777,167375,278295848,13.31,10,1,13.28,1,2,13.27,20,2,13.26,198,2,13.14,1,1,13.13,100,1,13.12,200,2,13.11,100,1,13.10,100,1,13.04,2,1,13.40,0,-10,13.53,0,-1,13.55,0,-1,13.56,0,-2,13.57,0,-2,13.58,0,-3,13.59,0,-4,13.60,0,-4,13.61,0,-4,13.62,0,-1,ARL,0
2025-07-17T16:09:00.226504346Z,2025-07-17T16:09:00.226338384Z,10,2,1108,C,A,10,14.750000000,100,333581569,165962,278296281,13.31,10,1,13.28,1,2,13.27,20,2,13.26,198,2,13.14,1,1,13.13,100,1,13.12,200,2,13.11,100,1,13.10,100,1,13.04,2,1,13.40,0,-10,13.53,0,-1,13.55,0,-1,13.56,0,-2,13.57,0,-2,13.58,0,-3,13.59,0,-4,13.60,0,-4,13.61,0,-4,13.62,0,-1,ARL,0
2025-07-17T16:09:00.226504346Z,2025-07-17T16:09:00.226338384Z,10,2,1108,A,A,10,14.610000000,100,334190189,165962,278296281,13.31,10,1,13.28,1,2,13.27,20,2,13.26,198,2,13.14,1,1,13.13,100,1,13.12,200,2,13.11,100,1,13.10,100,1,13.04,2,1,13.40,0,-10,13.53,0,-1,13.55,0,-1,13.56,0,-2,13.57,0,-2,13.58,0,-3,13.59,0,-4,13.60,0,-4,13.61,0,-4,13.62,0,-1,ARL,0
2025-07-17T16:09:00.227929061Z,2025-07-17T16:09:00.227763275Z,10,2,1108,C,A,10,14.260000000,100,333581765,165786,278296402,13.31,10,1,13.28,1,2,13.27,20,2,13.26,198,2,13.14,1,1,13.13,100,1,13.12,200,2,13.11,100,1,13.10,100,1,13.04,2,1,13.40,0,-10,13.53,0,-1,13.55,0,-1,13.56,0,-2,13.57,0,-2,13.58,0,-3,13.59,0,-4,13.60,0,-4,13.61,0,-4,13.62,0,-1,ARL,0
2025-07-17T16:09:00.227983483Z,2025-07-17T16:09:00.227818153Z,10,2,1108,A,A,10,14.100000000,100,334190225,165330,278296411,13.31,10,1,13.28,1,2,13.27,20,2,13.26,198,2,13.14,1,1,13.13,100,1,13.12,200,2,13.11,100,1,13.10,100,1,13.04,2,1,13.40,0,-10,13.53,0,-1,13.55,0,-1,13.56,0,-2,13.57,0,-2,13.58,0,-3,13.59,0,-4,13.60,0,-4,13.61,0,-4,13.62,0,-1,ARL,0
2025-07-17T16:09:00.232908882Z,2025-07-17T16:09:00.232743323Z,10,2,1108,C,A,10,14.940000000,100,333581429,165559,278296544,13.31,10,1,13.28,1,2,13.27,20,2,13.26,198,2,13.14,1,1,13.13,100,1,13.12,200,2,13.11,100,1,13.10,100,1,13.04,2,1,13.40,0,-10,13.53,0,-1,13.55,0,-1,13.56,0,-2,13.57,0,-2,13.58,0,-3,13.59,0,-4,13.60,0,-4,13.61,0,-4,13.62,0,-1,ARL,0
2025-07-17T16:09:00.232908882Z,2025-07-17T16:09:00.232743323Z,10,2,1108,A,A,10,14.790000000,100,334190353,165559,278296544,13.31,10,1,13.28,1,2,13.27,20,2,13.26,198,2,13.14,1,1,13.13,100,1,13.12,200,2,13.11,100,1,13.10,100,1,13.04,2,1,13.40,0,-10,13.53,0,-1,13.55,0,-1,13.56,0,-2,13.57,0,-2,13.58,0,-3,13.59,0,-4,13.60,0,-4,13.61,0,-4,13.62,0,-1,ARL,0
2025-07-17T16:09:00.326293286Z,2025-07-17T16:09:00.326127587Z,10,2,1108,C,A,10,17.730000000,100,333581425,165699,278298302,13.31,10,1,13.28,1,2,13.27,20,2,13.26,198,2,13.14,1,1,13.13,100,1,13.12,200,2,13.11,100,1,13.10,100,1,13.04,2,1,13.40,0,-10,13.53,0,-1,13.55,0,-1,13.56,0,-2,13.57,0,-2,13.58,0,-3,13.59,0,-4,13.60,0,-4,13.61,0,-4,13.62,0,-1,ARL,0
2025-07-17T16:09:00.326293286Z,2025-07-17T16:09:00.326127587Z,10,2,1108,A,A,10,17.560000000,100,334192253,165699,278298302,13.31,10,1,13.28,1,2,13.27,20,2,13.26,198,2,13.14,1,1,13.13,100,1,13.12,200,2,13.11,100,1,13.10,100,1,13.04,2,1,13.40,0,-10,13.53,0,-1,13.55,0,-1,13.56,0,-2,13.57,0,-2,13.58,0,-3,13.59,0,-4,13.60,0,-4,13.61,0,-4,13.62,0,-1,ARL,0
2025-07-17T16:09:00.335607827Z,2025-07-17T16:09:00.335442266Z,10,2,1108,C,A,10,16.060000000,100,333581433,165561,278298372,13.31,10,1,13.28,1,2,13.27,20,2,13.26,198,2,13.14,1,1,13.13,100,1,13.12,200,2,13.11,100,1,13.10,100,1,13.04,2,1,13.40,0,-10,13.53,0,-1,13.55,0,-1,13.56,0,-2,13.57,0,-2,13.58,0,-3,13.59,0,-4,13.60,0,-4,13.61,0,-4,13.62,0,-1,ARL,0
2025-07-17T16:09:00.335607827Z,2025-07-17T16:09:00.335442266Z,10,2,1108,A,A,10,15.900000000,100,334192405,165561,278298372,13.31,10,1,13.28,1,2,13.27,20,2,13.26,198,2,13.14,1,1,13.13,100,1,13.12,200,2,13.11,100,1,13.10,100,1,13.04,2,1,13.40,0,-10,13.53,0,-1,13.55,0,-1,13.56,0,-2,13.57,0,-2,13.58,0,-3,13.59,0,-4,13.60,0,-4,13.61,0,-4,13.62,0,-1,ARL,0
2025-07-17T16:09:00.695776010Z,2025-07-17T16:09:00.695610142Z,10,2,1108,C,A,10,14.940000000,100,333581409,165868,278304343,13.31,10,1,13.28,1,2,13.27,20,2,13.26,198,2,13.14,1,1,13.13,100,1,13.12,200,2,13.11,100,1,13.10,100,1,13.04,2,1,13.40,0,-10,13.53,0,-1,13.55,0,-1,13.56,0,-2,13.57,0,-2,13.58,0,-3,13.59,0,-4,13.60,0,-4,13.61,0,-4,13.62,0,-1,ARL,0
2025-07-17T16:09:00.695776010Z,2025-07-17T16:09:00.695610142Z,10,2,1108,A,A,10,14.790000000,100,334199009,165868,278304343,13.31,10,1,13.28,1,2,13.27,20,2,13.26,198,2,13.14,1,1,13.13,100,1,13.12,200,2,13.11,100,1,13.10,100,1,13.04,2,1,13.40,0,-10,13.53,0,-1,13.55,0,-1,13.56,0,-2,13.57,0,-2,13.58,0,-3,13.59,0,-4,13.60,0,-4,13.61,0,-4,13.62,0,-1,ARL,0
2025-07-17T16:09:08.719690693Z,2025-07-17T16:09:08.719524374Z,10,2,1108,A,A,10,13.750000000,15,334366613,166319,278436950,13.31,10,1,13.28,1,2,13.27,20,2,13.26,198,2,13.14,1,1,13.13,100,1,13.12,200,2,13.11,100,1,13.10,100,1,13.04,2,1,13.40,0,-10,13.53,0,-1,13.55,0,-1,13.56,0,-2,13.57,0,-2,13.58,0,-3,13.59,0,-4,13.60,0,-4,13.61,0,-4,13.62,0,-1,ARL,0
2025-07-17T16:09:08.719871410Z,2025-07-17T16:09:08.719706070Z,10,2,1108,C,A,10,13.820000000,100,334189729,165340,278436967,13.31,10,1,13.28,1,2,13.27,20,2,13.26,198,2,13.14,1,1,13.13,100,1,13.12,200,2,13.11,100,1,13.10,100,1,13.04,2,1,13.40,0,-10,13.53,0,-1,13.55,0,-1,13.56,0,-2,13.57,0,-2,13.58,0,-3,13.59,0,-4,13.60,0,-4,13.61,0,-4,13.62,0,-1,ARL,0
2025-07-17T16:09:08.719871410Z,2025-07-17T16:09:08.719706070Z,10,2,1108,A,A,10,13.760000000,100,334366617,165340,278436967,13.31,10,1,13.28,1,2,13.27,20,2,13.26,198,2,13.14,1,1,13.13,100,1,13.12,200,2,13.11,100,1,13.10,100,1,13.04,2,1,13.40,0,-10,13.53,0,-1,13.55,0,-1,13.56,0,-2,13.57,0,-2,13.58,0,-3,13.59,0,-4,13.60,0,-4,13.61,0,-4,13.62,0,-1,ARL,0
2025-07-17T16:09:08.720607932Z,2025-07-17T16:09:08.720442245Z,10,2,1108,C,A,10,14.890000000,100,334189777,165687,278436994,13.31,10,1,13.28,1,2,13.27,20,2,13.26,198,2,13.14,1,1,13.13,100,1,13.12,200,2,13.11,100,1,13.10,100,1,13.04,2,1,13.40,0,-10,13.53,0,-1,13.55,0,-1,13.56,0,-2,13.57,0,-2,13.58,0,-3,13.59,0,-4,13.60,0,-4,13.61,0,-4,13.62,0,-1,ARL,0
2025-07-17T16:09:08.720607932Z,2025-07-17T16:09:08.720442245Z,10,2,1108,A,A,10,14.830000000,100,334366645,165687,278436994,13.31,10,1,13.28,1,2,13.27,20,2,13.26,198,2,13.14,1,1,13.13,100,1,13.12,200,2,13.11,100,1,13.10,100,1,13.04,2,1,13.40,0,-10,13.53,0,-1,13.55,0,-1,13.56,0,-2,13.57,0,-2,13.58,0,-3,13.59,0,-4,13.60,0,-4,13.61,0,-4,13.62,0,-1,ARL,0
2025-07-17T16:09:18.819300735Z,2025-07-17T16:09:18.819135505Z,10,2,1108,C,A,10,13.810000000,15,334141429,165230,278596985,13.31,10,1,13.28,1,2,13.27,20,2,13.26,198,2,13.14,1,1,13.13,100,1,13.12,200,2,13.11,100,1,13.10,100,1,13.04,2,1,13.40,0,-10,13.53,0,-1,13.55,0,-1,13.56,0,-2,13.57,0,-2,13.58,0,-3,13.59,0,-4,13.60,0,-4,13.61,0,-4,13.62,0,-1,ARL,0
2025-07-17T16:09:19.927205023Z,2025-07-17T16:09:19.927039122Z,10,2,1108,A,A,10,13.730000000,15,334583329,165901,278621672,13.31,10,1,13.28,1,2,13.27,20,2,13.26,198,2,13.14,1,1,13.13,100,1,13.12,200,2,13.11,100,1,13.10,100,1,13.04,2,1,13.40,0,-10,13.53,0,-1,13.55,0,-1,13.56,0,-2,13.57,0,-2,13.58,0,-3,13.59,0,-4,13.60,0,-4,13.61,0,-4,13.62,0,-1,ARL,0
2025-07-17T16:09:19.927910703Z,2025-07-17T16:09:19.927745104Z,10,2,1108,C,A,10,14.740000000,100,333581393,165599,278621693,13.31,10,1,13.28,1,2,13.27,20,2,13.26,198,2,13.14,1,1,13.13,100,1,13.12,200,2,13.11,100,1,13.10,100,1,13.04,2,1,13.40,0,-10,13.53,0,-1,13.55,0,-1,13.56,0,-2,13.57,0,-2,13.58,0,-3,13.59,0,-4,13.60,0,-4,13.61,0,-4,13.62,0,-1,ARL,0
2025-07-17T16:09:19.927910703Z,2025-07-17T16:09:19.927745104Z,10,2,1108,A,A,10,14.620000000,100,334583349,165599,278621693,13.31,10,1,13.28,1,2,13.27,20,2,13.26,198,2,13.14,1,1,13.13,100,1,13.12,200,2,13.11,100,1,13.10,100,1,13.04,2,1,13.40,0,-10,13.53,0,-1,13.55,0,-1,13.56,0,-2,13.57,0,-2,13.58,0,-3,13.59,0,-4,13.60,0,-4,13.61,0,-4,13.62,0,-1,ARL,0
2025-07-17T16:09:19.928319369Z,2025-07-17T16:09:19.928153837Z,10,2,1108,C,A,10,14.740000000,100,333581481,165532,278621695,13.31,10,1,13.28,1,2,13.27,20,2,13.26,198,2,13.14,1,1,13.13,100,1,13.12,200,2,13.11,100,1,13.10,100,1,13.04,2,1,13.40,0,-10,13.53,0,-1,13.55,0,-1,13.56,0,-2,13.57,0,-2,13.58,0,-3,13.59,0,-4,13.60,0,-4,13.61,0,-4,13.62,0,-1,ARL,0
2025-07-17T16:09:19.928319369Z,2025-07-17T16:09:19.928153837Z,10,2,1108,A,A,10,14.620000000,100,334583361,165532,278621695,13.31,10,1,13.28,1,2,13.27,20,2,13.26,198,2,13.14,1,1,13.13,100,1,13.12,200,2,13.11,100,1,13.10,100,1,13.04,2,1,13.40,0,-10,13.53,0,-1,13.55,0,-1,13.56,0,-2,13.57,0,-2,13.58,0,-3,13.59,0,-4,13.60,0,-4,13.61,0,-4,13.62,0,-1,ARL,0
2025-07-17T16:09:20.284861075Z,2025-07-17T16:09:20.284695585Z,10,2,1108,C,A,10,13.760000000,100,334366617,165490,278629057,13.31,10,1,13.28,1,2,13.27,20,2,13.26,198,2,13.14,1,1,13.13,100,1,13.12,200,2,13.11,100,1,13.10,100,1,13.04,2,1,13.40,0,-10,13.53,0,-1,13.55,0,-1,13.56,0,-2,13.57,0,-2,13.58,0,-3,13.59,0,-4,13.60,0,-4,13.61,0,-4,13.62,0,-1,ARL,0
2025-07-17T16:09:20.284861075Z,2025-07-17T16:09:20.284695585Z,10,2,1108,A,A,10,13.740000000,100,334593569,165490,278629057,13.31,10,1,13.28,1,2,13.27,20,2,13.26,198,2,13.14,1,1,13.13,100,1,13.12,200,2,13.11,100,1,13.10,100,1,13.04,2,1,13.40,0,-10,13.53,0,-1,13.55,0,-1,13.56,0,-2,13.57,0,-2,13.58,0,-3,13.59,0,-4,13.60,0,-4,13.61,0,-4,13.62,0,-1,ARL,0
2025-07-17T16:09:20.293271620Z,2025-07-17T16:09:20.293106270Z,10,2,1108,C,A,10,14.100000000,100,334190225,165350,278629219,13.31,10,1,13.28,1,2,13.27,20,2,13.26,198,2,13.14,1,1,13.13,100,1,13.12,200,2,13.11,100,1,13.10,100,1,13.04,2,1,13.40,0,-10,13.53,0,-1,13.55,0,-1,13.56,0,-2,13.57,0,-2,13.58,0,-3,13.59,0,-4,13.60,0,-4,13.61,0,-4,13.62,0,-1,ARL,0
2025-07-17T16:09:20.293326641Z,2025-07-17T16:09:20.293161454Z,10,2,1108,A,A,10,14.010000000,100,334593753,165187,278629220,13.31,10,1,13.28,1,2,13.27,20,2,13.26,198,2,13.14,1,1,13.13,100,1,13.12,200,2,13.11,100,1,13.10,100,1,13.04,2,1,13.40,0,-10,13.53,0,-1,13.55,0,-1,13.56,0,-2,13.57,0,-2,13.58,0,-3,13.59,0,-4,13.60,0,-4,13.61,0,-4,13.62,0,-1,ARL,0
2025-07-17T16:09:20.818813935Z,2025-07-17T16:09:20.818648795Z,10,2,1108,C,A,10,13.730000000,15,334583329,165140,278640667,13.31,10,1,13.28,1,2,13.27,20,2,13.26,198,2,13.14,1,1,13.13,100,1,13.12,200,2,13.11,100,1,13.10,100,1,13.04,2,1,13.40,0,-10,13.53,0,-1,13.55,0,-1,13.56,0,-2,13.57,0,-2,13.58,0,-3,13.59,0,-4,13.60,0,-4,13.61,0,-4,13.62,0,-1,ARL,0
2025-07-17T16:09:20.818926356Z,2025-07-17T16:09:20.818761228Z,10,2,1108,C,A,10,13.750000000,15,334366613,165128,278640670,13.31,10,1,13.28,1,2,13.27,20,2,13.26,198,2,13.14,1,1,13.13,100,1,13.12,200,2,13.11,100,1,13.10,100,1,13.04,2,1,13.40,0,-10,13.53,0,-1,13.55,0,-1,13.56,0,-2,13.57,0,-2,13.58,0,-3,13.59,0,-4,13.60,0,-4,13.61,0,-4,13.62,0,-1,ARL,0
2025-07-17T16:09:28.986122432Z,2025-07-17T16:09:28.985956629Z,10,2,1108,C,A,10,13.980000000,2,333581677,165803,278784943,13.31,10,1,13.28,1,2,13.27,20,2,13.26,198,2,13.14,1,1,13.13,100,1,13.12,200,2,13.11,100,1,13.10,100,1,13.04,2,1,13.40,0,-10,13.53,0,-1,13.55,0,-1,13.56,0,-2,13.57,0,-2,13.58,0,-3,13.59,0,-4,13.60,0,-4,13.61,0,-4,13.62,0,-1,ARL,0
2025-07-17T16:09:28.986122432Z,2025-07-17T16:09:28.985956629Z,10,2,1108,A,A,10,13.900000000,2,334804177,165803,278784943,13.31,10,1,13.28,1,2,13.27,20,2,13.26,198,2,13.14,1,1,13.13,100,1,13.12,200,2,13.11,100,1,13.10,100,1,13.04,2,1,13.40,0,-10,13.53,0,-1,13.55,0,-1,13.56,0,-2,13.57,0,-2,13.58,0,-3,13.59,0,-4,13.60,0,-4,13.61,0,-4,13.62,0,-1,ARL,0
2025-07-17T16:09:40.821687905Z,2025-07-17T16:09:40.821522565Z,10,2,1108,A,A,10,13.700000000,15,335003269,165340,278938091,13.31,10,1,13.28,1,2,13.27,20,2,13.26,198,2,13.14,1,1,13.13,100,1,13.12,200,2,13.11,100,1,13.10,100,1,13.04,2,1,13.40,0,-10,13.53,0,-1,13.55,0,-1,13.56,0,-2,13.57,0,-2,13.58,0,-3,13.59,0,-4,13.60,0,-4,13.61,0,-4,13.62,0,-1,ARL,0
2025-07-17T16:09:40.853604577Z,2025-07-17T16:09:40.853439053Z,10,2,1108,C,A,10,13.740000000,100,334593569,165524,278938747,13.31,10,1,13.28,1,2,13.27,20,2,13.26,198,2,13.14,1,1,13.13,100,1,13.12,200,2,13.11,100,1,13.10,100,1,13.04,2,1,13.40,0,-10,13.53,0,-1,13.55,0,-1,13.56,0,-2,13.57,0,-2,13.58,0,-3,13.59,0,-4,13.60,0,-4,13.61,0,-4,13.62,0,-1,ARL,0
2025-07-17T16:09:40.853604577Z,2025-07-17T16:09:40.853439053Z,10,2,1108,A,A,10,13.710000000,100,335003813,165524,278938747,13.31,10,1,13.28,1,2,13.27,20,2,13.26,198,2,13.14,1,1,13.13,100,1,13.12,200,2,13.11,100,1,13.10,100,1,13.04,2,1,13.40,0,-10,13.53,0,-1,13.55,0,-1,13.56,0,-2,13.57,0,-2,13.58,0,-3,13.59,0,-4,13.60,0,-4,13.61,0,-4,13.62,0,-1,ARL,0
2025-07-17T16:09:40.854356022Z,2025-07-17T16:09:40.854190408Z,10,2,1108,C,A,10,14.830000000,100,334366645,165614,278938765,13.31,10,1,13.28,1,2,13.27,20,2,13.26,198,2,13.14,1,1,13.13,100,1,13.12,200,2,13.11,100,1,13.10,100,1,13.04,2,1,13.40,0,-10,13.53,0,-1,13.55,0,-1,13.56,0,-2,13.57,0,-2,13.58,0,-3,13.59,0,-4,13.60,0,-4,13.61,0,-4,13.62,0,-1,ARL,0
2025-07-17T16:09:40.854356022Z,2025-07-17T16:09:40.854190408Z,10,2,1108,A,A,10,14.770000000,100,335003845,165614,278938765,13.31,10,1,13.28,1,2,13.27,20,2,13.26,198,2,13.14,1,1,13.13,100,1,13.12,200,2,13.11,100,1,13.10,100,1,13.04,2,1,13.40,0,-10,13.53,0,-1,13.55,0,-1,13.56,0,-2,13.57,0,-2,13.58,0,-3,13.59,0,-4,13.60,0,-4,13.61,0,-4,13.62,0,-1,ARL,0
2025-07-17T16:09:40.855724422Z,2025-07-17T16:09:40.855558831Z,10,2,1108,C,A,10,17.560000000,100,334192253,165591,278938788,13.31,10,1,13.28,1,2,13.27,20,2,13.26,198,2,13.14,1,1,13.13,100,1,13.12,200,2,13.11,100,1,13.10,100,1,13.04,2,1,13.40,0,-10,13.53,0,-1,13.55,0,-1,13.56,0,-2,13.57,0,-2,13.58,0,-3,13.59,0,-4,13.60,0,-4,13.61,0,-4,13.62,0,-1,ARL,0
2025-07-17T16:09:40.855724422Z,2025-07-17T16:09:40.855558831Z,10,2,1108,A,A,10,17.420000000,100,335003849,165591,278938788,13.31,10,1,13.28,1,2,13.27,20,2,13.26,198,2,13.14,1,1,13.13,100,1,13.12,200,2,13.11,100,1,13.10,100,1,13.04,2,1,13.40,0,-10,13.53,0,-1,13.55,0,-1,13.56,0,-2,13.57,0,-2,13.58,0,-3,13.59,0,-4,13.60,0,-4,13.61,0,-4,13.62,0,-1,ARL,0
2025-07-17T16:09:50.820949131Z,2025-07-17T16:09:50.820783486Z,10,2,1108,A,A,10,13.670000000,15,335178437,165645,279081140,13.31,10,1,13.28,1,2,13.27,20,2,13.26,198,2,13.14,1,1,13.13,100,1,13.12,200,2,13.11,100,1,13.10,100,1,13.04,2,1,13.40,0,-10,13.53,0,-1,13.55,0,-1,13.56,0,-2,13.57,0,-2,13.58,0,-3,13.59,0,-4,13.60,0,-4,13.61,0,-4,13.62,0,-1,ARL,0
2025-07-17T16:09:52.678777358Z,2025-07-17T16:09:52.678611805Z,10,2,1108,C,A,10,13.710000000,100,335003813,165553,279109959,13.31,10,1,13.28,1,2,13.27,20,2,13.26,198,2,13.14,1,1,13.13,100,1,13.12,200,2,13.11,100,1,13.10,100,1,13.04,2,1,13.40,0,-10,13.53,0,-1,13.55,0,-1,13.56,0,-2,13.57,0,-2,13.58,0,-3,13.59,0,-4,13.60,0,-4,13.61,0,-4,13.62,0,-1,ARL,0
2025-07-17T16:09:52.678777358Z,2025-07-17T16:09:52.678611805Z,10,2,1108,A,A,10,13.680000000,100,335220349,165553,279109959,13.31,10,1,13.28,1,2,13.27,20,2,13.26,198,2,13.14,1,1,13.13,100,1,13.12,200,2,13.11,100,1,13.10,100,1,13.04,2,1,13.40,0,-10,13.53,0,-1,13.55,0,-1,13.56,0,-2,13.57,0,-2,13.58,0,-3,13.59,0,-4,13.60,0,-4,13.61,0,-4,13.62,0,-1,ARL,0
2025-07-17T16:09:52.679844338Z,2025-07-17T16:09:52.679678566Z,10,2,1108,C,A,10,15.900000000,100,334192405,165772,279109991,13.31,10,1,13.28,1,2,13.27,20,2,13.26,198,2,13.14,1,1,13.13,100,1,13.12,200,2,13.11,100,1,13.10,100,1,13.04,2,1,13.40,0,-10,13.53,0,-1,13.55,0,-1,13.56,0,-2,13.57,0,-2,13.58,0,-3,13.59,0,-4,13.60,0,-4,13.61,0,-4,13.62,0,-1,ARL,0
2025-07-17T16:09:52.679844338Z,2025-07-17T16:09:52.679678566Z,10,2,1108,A,A,10,15.740000000,100,335220497,165772,279109991,13.31,10,1,13.28,1,2,13.27,20,2,13.26,198,2,13.14,1,1,13.13,100,1,13.12,200,2,13.11,100,1,13.10,100,1,13.04,2,1,13.40,0,-10,13.53,0,-1,13.55,0,-1,13.56,0,-2,13.57,0,-2,13.58,0,-3,13.59,0,-4,13.60,0,-4,13.61,0,-4,13.62,0,-1,ARL,0
2025-07-17T16:09:52.679936826Z,2025-07-17T16:09:52.679769832Z,10,2,1108,C,A,10,14.790000000,100,334190353,166994,279109996,13.31,10,1,13.28,1,2,13.27,20,2,13.26,198,2,13.14,1,1,13.13,100,1,13.12,200,2,13.11,100,1,13.10,100,1,13.04,2,1,13.40,0,-10,13.53,0,-1,13.55,0,-1,13.56,0,-2,13.57,0,-2,13.58,0,-3,13.59,0,-4,13.60,0,-4,13.61,0,-4,13.62,0,-1,ARL,0
2025-07-17T16:09:52.679936826Z,2025-07-17T16:09:52.679769832Z,10,2,1108,A,A,10,14.640000000,100,335220525,166994,279109996,13.31,10,1,13.28,1,2,13.27,20,2,13.26,198,2,13.14,1,1,13.13,100,1,13.12,200,2,13.11,100,1,13.10,100,1,13.04,2,1,13.40,0,-10,13.53,0,-1,13.55,0,-1,13.56,0,-2,13.57,0,-2,13.58,0,-3,13.59,0,-4,13.60,0,-4,13.61,0,-4,13.62,0,-1,ARL,0
2025-07-17T16:09:52.680837736Z,2025-07-17T16:09:52.680672148Z,10,2,1108,C,A,10,15.360000000,100,333581441,165588,279110032,13.31,10,1,13.28,1,2,13.27,20,2,13.26,198,2,13.14,1,1,13.13,100,1,13.12,200,2,13.11,100,1,13.10,100,1,13.04,2,1,13.40,0,-10,13.53,0,-1,13.55,0,-1,13.56,0,-2,13.57,0,-2,13.58,0,-3,13.59,0,-4,13.60,0,-4,13.61,0,-4,13.62,0,-1,ARL,0
2025-07-17T16:09:52.680837736Z,2025-07-17T16:09:52.680672148Z,10,2,1108,A,A,10,15.050000000,100,335220549,165588,279110032,13.31,10,1,13.28,1,2,13.27,20,2,13.26,198,2,13.14,1,1,13.13,100,1,13.12,200,2,13.11,100,1,13.10,100,1,13.04,2,1,13.40,0,-10,13.53,0,-1,13.55,0,-1,13.56,0,-2,13.57,0,-2,13.58,0,-3,13.59,0,-4,13.60,0,-4,13.61,0,-4,13.62,0,-1,ARL,0
2025-07-17T16:09:52.682009938Z,2025-07-17T16:09:52.681844377Z,10,2,1108,C,A,10,14.610000000,100,334190189,165561,279110066,13.31,10,1,13.28,1,2,13.27,20,2,13.26,198,2,13.14,1,1,13.13,100,1,13.12,200,2,13.11,100,1,13.10,100,1,13.04,2,1,13.40,0,-10,13.53,0,-1,13.55,0,-1,13.56,0,-2,13.57,0,-2,13.58,0,-3,13.59,0,-4,13.60,0,-4,13.61,0,-4,13.62,0,-1,ARL,0
2025-07-17T16:09:52.682127530Z,2025-07-17T16:09:52.681961200Z,10,2,1108,A,A,10,14.470000000,100,335220561,166330,279110068,13.31,10,1,13.28,1,2,13.27,20,2,13.26,198,2,13.14,1,1,13.13,100,1,13.12,200,2,13.11,100,1,13.10,100,1,13.04,2,1,13.40,0,-10,13.53,0,-1,13.55,0,-1,13.56,0,-2,13.57,0,-2,13.58,0,-3,13.59,0,-4,13.60,0,-4,13.61,0,-4,13.62,0,-1,ARL,0
2025-07-17T16:09:52.683922707Z,2025-07-17T16:09:52.683757265Z,10,2,1108,C,A,10,14.790000000,100,334199009,165442,279110090,13.31,10,1,13.28,1,2,13.27,20,2,13.26,198,2,13.14,1,1,13.13,100,1,13.12,200,2,13.11,100,1,13.10,100,1,13.04,2,1,13.40,0,-10,13.53,0,-1,13.55,0,-1,13.56,0,-2,13.57,0,-2,13.58,0,-3,13.59,0,-4,13.60,0,-4,13.61,0,-4,13.62,0,-1,ARL,0
2025-07-17T16:09:52.683922707Z,2025-07-17T16:09:52.683757265Z,10,2,1108,A,A,10,14.640000000,100,335220629,165442,279110090,13.31,10,1,13.28,1,2,13.27,20,2,13.26,198,2,13.14,1,1,13.13,100,1,13.12,200,2,13.11,100,1,13.10,100,1,13.04,2,1,13.40,0,-10,13.53,0,-1,13.55,0,-1,13.56,0,-2,13.57,0,-2,13.58,0,-3,13.59,0,-4,13.60,0,-4,13.61,0,-4,13.62,0,-1,ARL,0
2025-07-17T16:10:04.521471804Z,2025-07-17T16:10:04.521306513Z,10,2,1108,C,A,10,13.670000000,15,335178437,165291,279306715,13.31,10,1,13.28,1,2,13.27,20,2,13.26,198,2,13.14,1,1,13.13,100,1,13.12,200,2,13.11,100,1,13.10,100,1,13.04,2,1,13.40,0,-10,13.53,0,-1,13.55,0,-1,13.56,0,-2,13.57,0,-2,13.58,0,-3,13.59,0,-4,13.60,0,-4,13.61,0,-4,13.62,0,-1,ARL,0
2025-07-17T16:10:04.561854856Z,2025-07-17T16:10:04.561688313Z,10,2,1108,C,A,10,13.700000000,15,335003269,166543,279312083,13.31,10,1,13.28,1,2,13.27,20,2,13.26,198,2,13.14,1,1,13.13,100,1,13.12,200,2,13.11,100,1,13.10,100,1,13.04,2,1,13.40,0,-10,13.53,0,-1,13.55,0,-1,13.56,0,-2,13.57,0,-2,13.58,0,-3,13.59,0,-4,13.60,0,-4,13.61,0,-4,13.62,0,-1,ARL,0
2025-07-17T16:10:32.822660498Z,2025-07-17T16:10:32.822495087Z,10,2,1108,A,A,10,13.650000000,15,335996705,165411,279705339,13.31,10,1,13.28,1,2,13.27,20,2,13.26,198,2,13.14,1,1,13.13,100,1,13.12,200,2,13.11,100,1,13.10,100,1,13.04,2,1,13.40,0,-10,13.53,0,-1,13.55,0,-1,13.56,0,-2,13.57,0,-2,13.58,0,-3,13.59,0,-4,13.60,0,-4,13.61,0,-4,13.62,0,-1,ARL,0
2025-07-17T16:10:32.822923138Z,2025-07-17T16:10:32.822757517Z,10,2,1108,C,A,10,13.680000000,100,335220349,165621,279705347,13.31,10,1,13.28,1,2,13.27,20,2,13.26,198,2,13.14,1,1,13.13,100,1,13.12,200,2,13.11,100,1,13.10,100,1,13.04,2,1,13.40,0,-10,13.53,0,-1,13.55,0,-1,13.56,0,-2,13.57,0,-2,13.58,0,-3,13.59,0,-4,13.60,0,-4,13.61,0,-4,13.62,0,-1,ARL,0
2025-07-17T16:10:32.822923138Z,2025-07-17T16:10:32.822757517Z,10,2,1108,A,A,10,13.660000000,100,335996709,165621,279705347,13.31,10,1,13.28,1,2,13.27,20,2,13.26,198,2,13.14,1,1,13.13,100,1,13.12,200,2,13.11,100,1,13.10,100,1,13.04,2,1,13.40,0,-10,13.53,0,-1,13.55,0,-1,13.56,0,-2,13.57,0,-2,13.58,0,-3,13.59,0,-4,13.60,0,-4,13.61,0,-4,13.62,0,-1,ARL,0
2025-07-17T16:10:32.823656903Z,2025-07-17T16:10:32.823491276Z,10,2,1108,C,A,10,14.770000000,100,335003845,165627,279705362,13.31,10,1,13.28,1,2,13.27,20,2,13.26,198,2,13.14,1,1,13.13,100,1,13.12,200,2,13.11,100,1,13.10,100,1,13.04,2,1,13.40,0,-10,13.53,0,-1,13.55,0,-1,13.56,0,-2,13.57,0,-2,13.58,0,-3,13.59,0,-4,13.60,0,-4,13.61,0,-4,13.62,0,-1,ARL,0
2025-07-17T16:10:32.823656903Z,2025-07-17T16:10:32.823491276Z,10,2,1108,A,A,10,14.720000000,100,335996725,165627,279705362,13.31,10,1,13.28,1,2,13.27,20,2,13.26,198,2,13.14,1,1,13.13,100,1,13.12,200,2,13.11,100,1,13.10,100,1,13.04,2,1,13.40,0,-10,13.53,0,-1,13.55,0,-1,13.56,0,-2,13.57,0,-2,13.58,0,-3,13.59,0,-4,13.60,0,-4,13.61,0,-4,13.62,0,-1,ARL,0
2025-07-17T16:10:32.830200844Z,2025-07-17T16:10:32.830032662Z,10,2,1108,C,A,10,14.010000000,100,334593753,168182,279705485,13.31,10,1,13.28,1,2,13.27,20,2,13.26,198,2,13.14,1,1,13.13,100,1,13.12,200,2,13.11,100,1,13.10,100,1,13.04,2,1,13.40,0,-10,13.53,0,-1,13.55,0,-1,13.56,0,-2,13.57,0,-2,13.58,0,-3,13.59,0,-4,13.60,0,-4,13.61,0,-4,13.62,0,-1,ARL,0
2025-07-17T16:10:32.830250720Z,2025-07-17T16:10:32.830085472Z,10,2,1108,A,A,10,13.930000000,100,335996777,165248,279705486,13.31,10,1,13.28,1,2,13.27,20,2,13.26,198,2,13.14,1,1,13.13,100,1,13.12,200,2,13.11,100,1,13.10,100,1,13.04,2,1,13.40,0,-10,13.53,0,-1,13.55,0,-1,13.56,0,-2,13.57,0,-2,13.58,0,-3,13.59,0,-4,13.60,0,-4,13.61,0,-4,13.62,0,-1,ARL,0
2025-07-17T16:10:42.822354869Z,2025-07-17T16:10:42.822189504Z,10,2,1108,A,A,10,13.630000000,15,336161333,165365,279834760,13.31,10,1,13.28,1,2,13.27,20,2,13.26,198,2,13.14,1,1,13.13,100,1,13.12,200,2,13.11,100,1,13.10,100,1,13.04,2,1,13.40,0,-10,13.53,0,-1,13.55,0,-1,13.56,0,-2,13.57,0,-2,13.58,0,-3,13.59,0,-4,13.60,0,-4,13.61,0,-4,13.62,0,-1,ARL,0
2025-07-17T16:10:42.822424663Z,2025-07-17T16:10:42.822258887Z,10,2,1108,C,A,10,13.660000000,100,335996709,165776,279834761,13.31,10,1,13.28,1,2,13.27,20,2,13.26,198,2,13.14,1,1,13.13,100,1,13.12,200,2,13.11,100,1,13.10,100,1,13.04,2,1,13.40,0,-10,13.53,0,-1,13.55,0,-1,13.56,0,-2,13.57,0,-2,13.58,0,-3,13.59,0,-4,13.60,0,-4,13.61,0,-4,13.62,0,-1,ARL,0
2025-07-17T16:10:42.822424663Z,2025-07-17T16:10:42.822258887Z,10,2,1108,A,A,10,13.640000000,100,336161337,165776,279834761,13.31,10,1,13.28,1,2,13.27,20,2,13.26,198,2,13.14,1,1,13.13,100,1,13.12,200,2,13.11,100,1,13.10,100,1,13.04,2,1,13.40,0,-10,13.53,0,-1,13.55,0,-1,13.56,0,-2,13.57,0,-2,13.58,0,-3,13.59,0,-4,13.60,0,-4,13.61,0,-4,13.62,0,-1,ARL,0
2025-07-17T16:10:42.823163929Z,2025-07-17T16:10:42.822998664Z,10,2,1108,C,A,10,14.460000000,100,331927161,165265,279834765,13.31,10,1,13.28,1,2,13.27,20,2,13.26,198,2,13.14,1,1,13.13,100,1,13.12,200,2,13.11,100,1,13.10,100,1,13.04,2,1,13.40,0,-10,13.53,0,-1,13.55,0,-1,13.56,0,-2,13.57,0,-2,13.58,0,-3,13.59,0,-4,13.60,0,-4,13.61,0,-4,13.62,0,-1,ARL,0
2025-07-17T16:10:42.823517444Z,2025-07-17T16:10:42.823352130Z,10,2,1108,A,A,10,14.250000000,100,336161365,165314,279834767,13.31,10,1,13.28,1,2,13.27,20,2,13.26,198,2,13.14,1,1,13.13,100,1,13.12,200,2,13.11,100,1,13.10,100,1,13.04,2,1,13.40,0,-10,13.53,0,-1,13.55,0,-1,13.56,0,-2,13.57,0,-2,13.58,0,-3,13.59,0,-4,13.60,0,-4,13.61,0,-4,13.62,0,-1,ARL,0
2025-07-17T16:10:46.534055942Z,2025-07-17T16:10:46.533890361Z,10,2,1108,C,A,10,14.620000000,100,334583349,165581,279921726,13.31,10,1,13.28,1,2,13.27,20,2,13.26,198,2,13.14,1,1,13.13,100,1,13.12,200,2,13.11,100,1,13.10,100,1,13.04,2,1,13.40,0,-10,13.53,0,-1,13.55,0,-1,13.56,0,-2,13.57,0,-2,13.58,0,-3,13.59,0,-4,13.60,0,-4,13.61,0,-4,13.62,0,-1,ARL,0
2025-07-17T16:10:46.534055942Z,2025-07-17T16:10:46.533890361Z,10,2,1108,A,A,10,14.510000000,100,336259225,165581,279921726,13.31,10,1,13.28,1,2,13.27,20,2,13.26,198,2,13.14,1,1,13.13,100,1,13.12,200,2,13.11,100,1,13.10,100,1,13.04,2,1,13.40,0,-10,13.53,0,-1,13.55,0,-1,13.56,0,-2,13.57,0,-2,13.58,0,-3,13.59,0,-4,13.60,0,-4,13.61,0,-4,13.62,0,-1,ARL,0
2025-07-17T16:10:46.538158874Z,2025-07-17T16:10:46.537992315Z,10,2,1108,C,A,10,13.650000000,15,335996705,166559,279921911,13.31,10,1,13.28,1,2,13.27,20,2,13.26,198,2,13.14,1,1,13.13,100,1,13.12,200,2,13.11,100,1,13.10,100,1,13.04,2,1,13.40,0,-10,13.53,0,-1,13.55,0,-1,13.56,0,-2,13.57,0,-2,13.58,0,-3,13.59,0,-4,13.60,0,-4,13.61,0,-4,13.62,0,-1,ARL,0
2025-07-17T16:10:46.561246030Z,2025-07-17T16:10:46.561080616Z,10,2,1108,C,A,10,14.620000000,100,334583361,165414,279924883,13.31,10,1,13.28,1,2,13.27,20,2,13.26,198,2,13.14,1,1,13.13,100,1,13.12,200,2,13.11,100,1,13.10,100,1,13.04,2,1,13.40,0,-10,13.53,0,-1,13.55,0,-1,13.56,0,-2,13.57,0,-2,13.58,0,-3,13.59,0,-4,13.60,0,-4,13.61,0,-4,13.62,0,-1,ARL,0
2025-07-17T16:10:46.561246030Z,2025-07-17T16:10:46.561080616Z,10,2,1108,A,A,10,14.510000000,100,336261905,165414,279924883,13.31,10,1,13.28,1,2,13.27,20,2,13.26,198,2,13.14,1,1,13.13,100,1,13.12,200,2,13.11,100,1,13.10,100,1,13.04,2,1,13.40,0,-10,13.53,0,-1,13.55,0,-1,13.56,0,-2,13.57,0,-2,13.58,0,-3,13.59,0,-4,13.60,0,-4,13.61,0,-4,13.62,0,-1,ARL,0
2025-07-17T16:10:47.543404001Z,2025-07-17T16:10:47.543238729Z,10,2,1108,A,A,10,13.610000000,15,336278197,165272,279938097,13.31,10,1,13.28,1,2,13.27,20,2,13.26,198,2,13.14,1,1,13.13,100,1,13.12,200,2,13.11,100,1,13.10,100,1,13.04,2,1,13.40,0,-10,13.53,0,-1,13.55,0,-1,13.56,0,-2,13.57,0,-2,13.58,0,-3,13.59,0,-4,13.60,0,-4,13.61,0,-4,13.62,0,-1,ARL,0
2025-07-17T16:10:48.657456395Z,2025-07-17T16:10:48.657290980Z,10,2,1108,C,A,10,13.640000000,100,336161337,165415,279952266,13.31,10,1,13.28,1,2,13.27,20,2,13.26,198,2,13.14,1,1,13.13,100,1,13.12,200,2,13.11,100,1,13.10,100,1,13.04,2,1,13.40,0,-10,13.53,0,-1,13.55,0,-1,13.56,0,-2,13.57,0,-2,13.58,0,-3,13.59,0,-4,13.60,0,-4,13.61,0,-5,13.62,0,-1,ARL,0
2025-07-17T16:10:48.657456395Z,2025-07-17T16:10:48.657290980Z,10,2,1108,A,A,10,13.620000000,100,336295769,165415,279952266,13.31,10,1,13.28,1,2,13.27,20,2,13.26,198,2,13.14,1,1,13.13,100,1,13.12,200,2,13.11,100,1,13.10,100,1,13.04,2,1,13.40,0,-10,13.53,0,-1,13.55,0,-1,13.56,0,-2,13.57,0,-2,13.58,0,-3,13.59,0,-4,13.60,0,-4,13.61,0,-5,13.62,0,-1,ARL,0
2025-07-17T16:10:48.658199425Z,2025-07-17T16:10:48.658033954Z,10,2,1108,C,A,10,14.720000000,100,335996725,165471,279952282,13.31,10,1,13.28,1,2,13.27,20,2,13.26,198,2,13.14,1,1,13.13,100,1,13.12,200,2,13.11,100,1,13.10,100,1,13.04,2,1,13.40,0,-10,13.53,0,-1,13.55,0,-1,13.56,0,-2,13.57,0,-2,13.58,0,-3,13.59,0,-4,13.60,0,-4,13.61,0,-5,13.62,0,-2,ARL,0
2025-07-17T16:10:48.658199425Z,2025-07-17T16:10:48.658033954Z,10,2,1108,A,A,10,14.680000000,100,336295845,165471,279952282,13.31,10,1,13.28,1,2,13.27,20,2,13.26,198,2,13.14,1,1,13.13,100,1,13.12,200,2,13.11,100,1,13.10,100,1,13.04,2,1,13.40,0,-10,13.53,0,-1,13.55,0,-1,13.56,0,-2,13.57,0,-2,13.58,0,-3,13.59,0,-4,13.60,0,-4,13.61,0,-5,13.62,0,-2,ARL,0
2025-07-17T16:10:51.059044292Z,2025-07-17T16:10:51.058878264Z,10,2,1108,C,A,10,13.610000000,15,336278197,166028,280001840,13.31,10,1,13.28,1,2,13.27,20,2,13.26,198,2,13.14,1,1,13.13,100,1,13.12,200,2,13.11,100,1,13.10,100,1,13.04,2,1,13.40,0,-10,13.53,0,-1,13.55,0,-1,13.56,0,-2,13.57,0,-2,13.58,0,-3,13.59,0,-4,13.60,0,-4,13.61,0,-5,13.62,0,-2,ARL,0
2025-07-17T16:10:51.059183923Z,2025-07-17T16:10:51.059016199Z,10,2,1108,C,A,10,13.630000000,15,336161333,167724,280001873,13.31,10,1,13.28,1,2,13.27,20,2,13.26,198,2,13.14,1,1,13.13,100,1,13.12,200,2,13.11,100,1,13.10,100,1,13.04,2,1,13.40,0,-10,13.53,0,-1,13.55,0,-1,13.56,0,-2,13.57,0,-2,13.58,0,-3,13.59,0,-4,13.60,0,-4,13.61,0,-5,13.62,0,-2,ARL,0
2025-07-17T16:10:51.059608753Z,2025-07-17T16:10:51.059443298Z,10,2,1108,C,A,10,13.620000000,100,336295769,165455,280001952,13.31,10,1,13.28,1,2,13.27,20,2,13.26,198,2,13.14,1,1,13.13,100,1,13.12,200,2,13.11,100,1,13.10,100,1,13.04,2,1,13.40,0,-10,13.53,0,-1,13.55,0,-1,13.56,0,-2,13.57,0,-2,13.58,0,-3,13.59,0,-4,13.60,0,-4,13.61,0,-5,13.62,0,-2,ARL,0
2025-07-17T16:10:51.170710609Z,2025-07-17T16:10:51.170545251Z,10,2,1108,A,A,10,13.910000000,100,336351081,165358,280003702,13.31,10,1,13.28,1,2,13.27,20,2,13.26,198,2,13.14,1,1,13.13,100,1,13.12,200,2,13.11,100,1,13.10,100,1,13.04,2,1,13.40,0,-10,13.53,0,-1,13.55,0,-1,13.56,0,-2,13.57,0,-2,13.58,0,-3,13.59,0,-4,13.60,0,-4,13.61,0,-5,13.62,0,-2,ARL,0
2025-07-17T16:10:52.958453641Z,2025-07-17T16:10:52.958288317Z,10,2,1108,A,A,10,13.600000000,15,336402845,165324,280050139,13.31,10,1,13.28,1,2,13.27,20,2,13.26,198,2,13.14,1,1,13.13,100,1,13.12,200,2,13.11,100,1,13.10,100,1,13.04,2,1,13.40,0,-10,13.53,0,-1,13.55,0,-1,13.56,0,-2,13.57,0,-2,13.58,0,-3,13.59,0,-4,13.60,0,-4,13.61,0,-5,13.62,0,-2,ARL,0
2025-07-17T16:10:53.102037173Z,2025-07-17T16:10:53.101871639Z,10,2,1108,C,A,10,13.910000000,100,336351081,165534,280057228,13.31,10,1,13.28,1,2,13.27,20,2,13.26,198,2,13.14,1,1,13.13,100,1,13.12,200,2,13.11,100,1,13.10,100,1,13.04,2,1,13.40,0,-10,13.53,0,-1,13.55,0,-1,13.56,0,-2,13.57,0,-2,13.58,0,-3,13.59,0,-4,13.60,0,-5,13.61,0,-5,13.62,0,-2,ARL,0
2025-07-17T16:10:53.102037173Z,2025-07-17T16:10:53.101871639Z,10,2,1108,A,A,10,13.610000000,100,336410125,165534,280057228,13.31,10,1,13.28,1,2,13.27,20,2,13.26,198,2,13.14,1,1,13.13,100,1,13.12,200,2,13.11,100,1,13.10,100,1,13.04,2,1,13.40,0,-10,13.53,0,-1,13.55,0,-1,13.56,0,-2,13.57,0,-2,13.58,0,-3,13.59,0,-4,13.60,0,-5,13.61,0,-5,13.62,0,-2,ARL,0
2025-07-17T16:10:54.959307592Z,2025-07-17T16:10:54.959141873Z,10,2,1108,C,A,10,13.900000000,2,334804177,165719,280084546,13.31,10,1,13.28,1,2,13.27,20,2,13.26,198,2,13.14,1,1,13.13,100,1,13.12,200,2,13.11,100,1,13.10,100,1,13.04,2,1,13.40,0,-10,13.53,0,-1,13.55,0,-1,13.56,0,-2,13.57,0,-2,13.58,0,-3,13.59,0,-4,13.60,0,-5,13.61,0,-5,13.62,0,-2,ARL,0
2025-07-17T16:10:54.959307592Z,2025-07-17T16:10:54.959141873Z,10,2,1108,A,A,10,13.820000000,2,336447325,165719,280084546,13.31,10,1,13.28,1,2,13.27,20,2,13.26,198,2,13.14,1,1,13.13,100,1,13.12,200,2,13.11,100,1,13.10,100,1,13.04,2,1,13.40,0,-10,13.53,0,-1,13.55,0,-1,13.56,0,-2,13.57,0,-2,13.58,0,-3,13.59,0,-4,13.60,0,-5,13.61,0,-5,13.62,0,-2,ARL,0
2025-07-17T16:10:59.518035805Z,2025-07-17T16:10:59.517870358Z,10,2,1108,A,A,10,13.580000000,15,336555153,165447,280173685,13.31,10,1,13.28,1,2,13.27,20,2,13.26,198,2,13.14,1,1,13.13,100,1,13.12,200,2,13.11,100,1,13.10,100,1,13.04,2,1,13.40,0,-10,13.53,0,-1,13.55,0,-1,13.56,0,-2,13.57,0,-2,13.58,0,-3,13.59,0,-4,13.60,0,-5,13.61,0,-5,13.62,0,-2,ARL,0
2025-07-17T16:11:00.215885294Z,2025-07-17T16:11:00.215719725Z,10,2,1108,C,A,10,13.610000000,100,336410125,165569,280184406,13.31,10,1,13.28,1,2,13.27,20,2,13.26,198,2,13.14,1,1,13.13,100,1,13.12,200,2,13.11,100,1,13.10,100,1,13.04,2,1,13.40,0,-10,13.53,0,-1,13.55,0,-1,13.56,0,-2,13.57,0,-2,13.58,0,-4,13.59,0,-4,13.60,0,-5,13.61,0,-5,13.62,0,-2,ARL,0
2025-07-17T16:11:00.215885294Z,2025-07-17T16:11:00.215719725Z,10,2,1108,A,A,10,13.590000000,100,336567189,165569,280184406,13.31,10,1,13.28,1,2,13.27,20,2,13.26,198,2,13.14,1,1,13.13,100,1,13.12,200,2,13.11,100,1,13.10,100,1,13.04,2,1,13.40,0,-10,13.53,0,-1,13.55,0,-1,13.56,0,-2,13.57,0,-2,13.58,0,-4,13.59,0,-4,13.60,0,-5,13.61,0,-5,13.62,0,-2,ARL,0
2025-07-17T16:11:00.216622121Z,2025-07-17T16:11:00.216456547Z,10,2,1108,C,A,10,14.680000000,100,336295845,165574,280184418,13.31,10,1,13.28,1,2,13.27,20,2,13.26,198,2,13.14,1,1,13.13,100,1,13.12,200,2,13.11,100,1,13.10,100,1,13.04,2,1,13.40,0,-10,13.53,0,-1,13.55,0,-1,13.56,0,-2,13.57,0,-2,13.58,0,-4,13.59,0,-5,13.60,0,-5,13.61,0,-5,13.62,0,-2,ARL,0
2025-07-17T16:11:00.216622121Z,2025-07-17T16:11:00.216456547Z,10,2,1108,A,A,10,14.640000000,100,336567213,165574,280184418,13.31,10,1,13.28,1,2,13.27,20,2,13.26,198,2,13.14,1,1,13.13,100,1,13.12,200,2,13.11,100,1,13.10,100,1,13.04,2,1,13.40,0,-10,13.53,0,-1,13.55,0,-1,13.56,0,-2,13.57,0,-2,13.58,0,-4,13.59,0,-5,13.60,0,-5,13.61,0,-5,13.62,0,-2,ARL,0
2025-07-17T16:11:00.228999377Z,2025-07-17T16:11:00.228833925Z,10,2,1108,C,A,10,13.930000000,100,335996777,165452,280184613,13.31,10,1,13.28,1,2,13.27,20,2,13.26,198,2,13.14,1,1,13.13,100,1,13.12,200,2,13.11,100,1,13.10,100,1,13.04,2,1,13.40,0,-10,13.53,0,-1,13.55,0,-1,13.56,0,-2,13.57,0,-2,13.58,0,-4,13.59,0,-5,13.60,0,-5,13.61,0,-5,13.62,0,-2,ARL,0
2025-07-17T16:11:00.229051124Z,2025-07-17T16:11:00.228885790Z,10,2,1108,A,A,10,13.860000000,100,336567333,165334,280184614,13.31,10,1,13.28,1,2,13.27,20,2,13.26,198,2,13.14,1,1,13.13,100,1,13.12,200,2,13.11,100,1,13.10,100,1,13.04,2,1,13.40,0,-10,13.53,0,-1,13.55,0,-1,13.56,0,-2,13.57,0,-2,13.58,0,-4,13.59,0,-5,13.60,0,-5,13.61,0,-5,13.62,0,-2,ARL,0
2025-07-17T16:11:00.313087129Z,2025-07-17T16:11:00.312921679Z,10,2,1108,C,A,10,17.420000000,100,335003849,165450,280188038,13.31,10,1,13.28,1,2,13.27,20,2,13.26,198,2,13.14,1,1,13.13,100,1,13.12,200,2,13.11,100,1,13.10,100,1,13.04,2,1,13.40,0,-10,13.53,0,-1,13.55,0,-1,13.56,0,-2,13.57,0,-2,13.58,0,-4,13.59,0,-5,13.60,0,-5,13.61,0,-5,13.62,0,-2,ARL,0
2025-07-17T16:11:00.313087129Z,2025-07-17T16:11:00.312921679Z,10,2,1108,A,A,10,17.260000000,100,336570921,165450,280188038,13.31,10,1,13.28,1,2,13.27,20,2,13.26,198,2,13.14,1,1,13.13,100,1,13.12,200,2,13.11,100,1,13.10,100,1,13.04,2,1,13.40,0,-10,13.53,0,-1,13.55,0,-1,13.56,0,-2,13.57,0,-2,13.58,0,-4,13.59,0,-5,13.60,0,-5,13.61,0,-5,13.62,0,-2,ARL,0
2025-07-17T16:11:00.366811541Z,2025-07-17T16:11:00.366645846Z,10,2,1108,A,A,10,13.620000000,1,336572049,165695,280189435,13.31,10,1,13.28,1,2,13.27,20,2,13.26,198,2,13.14,1,1,13.13,100,1,13.12,200,2,13.11,100,1,13.10,100,1,13.04,2,1,13.40,0,-10,13.53,0,-1,13.55,0,-1,13.56,0,-2,13.57,0,-2,13.58,0,-4,13.59,0,-5,13.60,0,-5,13.61,0,-5,13.62,0,-2,ARL,0
2025-07-17T16:11:00.367374773Z,2025-07-17T16:11:00.367209243Z,10,2,1108,C,B,10,12.490000000,100,331942945,165530,280189439,13.31,10,1,13.28,1,2,13.27,20,2,13.26,198,2,13.14,1,1,13.13,100,1,13.12,200,2,13.11,100,1,13.10,100,1,13.04,2,1,13.40,0,-10,13.53,0,-1,13.55,0,-1,13.56,0,-2,13.57,0,-2,13.58,0,-4,13.59,0,-5,13.60,0,-5,13.61,0,-5,13.62,0,-3,ARL,0
2025-07-17T16:11:00.367374773Z,2025-07-17T16:11:00.367209243Z,10,2,1108,A,B,10,12.360000000,100,336572057,165530,280189439,13.31,10,1,13.28,1,2,13.27,20,2,13.26,198,2,13.14,1,1,13.13,100,1,13.12,200,2,13.11,100,1,13.10,100,1,13.04,2,1,13.40,0,-10,13.53,0,-1,13.55,0,-1,13.56,0,-2,13.57,0,-2,13.58,0,-4,13.59,0,-5,13.60,0,-5,13.61,0,-5,13.62,0,-3,ARL,0
2025-07-17T16:11:00.367485094Z,2025-07-17T16:11:00.367319059Z,10,2,1108,C,B,10,12.490000000,100,331942901,166035,280189441,13.31,10,1,13.28,1,2,13.27,20,2,13.26,198,2,13.14,1,1,13.13,100,1,13.12,200,2,13.11,100,1,13.10,100,1,13.04,2,1,13.40,0,-10,13.53,0,-1,13.55,0,-1,13.56,0,-2,13.57,0,-2,13.58,0,-4,13.59,0,-5,13.60,0,-5,13.61,0,-5,13.62,0,-3,ARL,0
2025-07-17T16:11:00.367485094Z,2025-07-17T16:11:00.367319059Z,10,2,1108,A,B,10,12.360000000,100,336572069,166035,280189441,13.31,10,1,13.28,1,2,13.27,20,2,13.26,198,2,13.14,1,1,13.13,100,1,13.12,200,2,13.11,100,1,13.10,100,1,13.04,2,1,13.40,0,-10,13.53,0,-1,13.55,0,-1,13.56,0,-2,13.57,0,-2,13.58,0,-4,13.59,0,-5,13.60,0,-5,13.61,0,-5,13.62,0,-3,ARL,0
2025-07-17T16:11:00.466868624Z,2025-07-17T16:11:00.466703632Z,10,2,1108,C,A,10,13.620000000,1,336572049,164992,280191783,13.31,10,1,13.28,1,2,13.27,20,2,13.26,198,2,13.14,1,1,13.13,100,1,13.12,200,2,13.11,100,1,13.10,100,1,13.04,2,1,13.40,0,-10,13.53,0,-1,13.55,0,-1,13.56,0,-2,13.57,0,-2,13.58,0,-4,13.59,0,-5,13.60,0,-5,13.61,0,-5,13.62,0,-3,ARL,0
2025-07-17T16:11:06.626831799Z,2025-07-17T16:11:06.626666474Z,10,2,1108,A,A,10,14.270000000,700,336747457,165325,280342316,13.31,10,1,13.28,1,2,13.27,20,2,13.26,198,2,13.14,1,1,13.13,100,1,13.12,200,2,13.11,100,1,13.10,100,1,13.04,2,1,13.40,0,-10,13.53,0,-1,13.55,0,-1,13.56,0,-2,13.57,0,-2,13.58,0,-4,13.59,0,-5,13.60,0,-5,13.61,0,-5,13.62,0,-3,ARL,0
2025-07-17T16:11:06.626906700Z,2025-07-17T16:11:06.626741446Z,10,2,1108,C,A,10,14.680000000,700,331929977,165254,280342318,13.31,10,1,13.28,1,2,13.27,20,2,13.26,198,2,13.14,1,1,13.13,100,1,13.12,200,2,13.11,100,1,13.10,100,1,13.04,2,1,13.40,0,-10,13.53,0,-1,13.55,0,-1,13.56,0,-2,13.57,0,-2,13.58,0,-4,13.59,0,-5,13.60,0,-5,13.61,0,-5,13.62,0,-3,ARL,0
2025-07-17T16:11:08.308034538Z,2025-07-17T16:11:08.307868957Z,10,2,1108,C,A,10,13.600000000,15,336402845,165581,280374785,13.31,10,1,13.28,1,2,13.27,20,2,13.26,198,2,13.14,1,1,13.13,100,1,13.12,200,2,13.11,100,1,13.10,100,1,13.04,2,1,13.40,0,-10,13.53,0,-1,13.55,0,-1,13.56,0,-2,13.57,0,-2,13.58,0,-4,13.59,0,-5,13.60,0,-5,13.61,0,-5,13.62,0,-3,ARL,0
2025-07-17T16:11:09.568536292Z,2025-07-17T16:11:09.568370995Z,10,2,1108,A,A,10,13.560000000,15,336816813,165297,280401189,13.31,10,1,13.28,1,2,13.27,20,2,13.26,198,2,13.14,1,1,13.13,100,1,13.12,200,2,13.11,100,1,13.10,100,1,13.04,2,1,13.40,0,-10,13.53,0,-1,13.55,0,-1,13.56,0,-2,13.57,0,-2,13.58,0,-4,13.59,0,-5,13.60,0,-5,13.61,0,-5,13.62,0,-3,ARL,0
2025-07-17T16:11:10.341953971Z,2025-07-17T16:11:10.341788521Z,10,2,1108,C,A,10,13.590000000,100,336567189,165450,280411396,13.31,10,1,13.28,1,2,13.27,20,2,13.26,198,2,13.14,1,1,13.13,100,1,13.12,200,2,13.11,100,1,13.10,100,1,13.04,2,1,13.40,0,-10,13.53,0,-1,13.55,0,-1,13.56,0,-3,13.57,0,-2,13.58,0,-4,13.59,0,-5,13.60,0,-5,13.61,0,-5,13.62,0,-3,ARL,0
2025-07-17T16:11:10.341953971Z,2025-07-17T16:11:10.341788521Z,10,2,1108,A,A,10,13.570000000,100,336828765,165450,280411396,13.31,10,1,13.28,1,2,13.27,20,2,13.26,198,2,13.14,1,1,13.13,100,1,13.12,200,2,13.11,100,1,13.10,100,1,13.04,2,1,13.40,0,-10,13.53,0,-1,13.55,0,-1,13.56,0,-3,13.57,0,-2,13.58,0,-4,13.59,0,-5,13.60,0,-5,13.61,0,-5,13.62,0,-3,ARL,0
2025-07-17T16:11:14.610701450Z,2025-07-17T16:11:14.610535763Z,10,2,1108,C,A,10,13.580000000,15,336555153,165687,280482371,13.31,10,1,13.28,1,2,13.27,20,2,13.26,198,2,13.14,1,1,13.13,100,1,13.12,200,2,13.11,100,1,13.10,100,1,13.04,2,1,13.40,0,-10,13.53,0,-1,13.55,0,-1,13.56,0,-3,13.57,0,-2,13.58,0,-4,13.59,0,-5,13.60,0,-5,13.61,0,-5,13.62,0,-3,ARL,0
2025-07-17T16:11:16.025458231Z,2025-07-17T16:11:16.025292936Z,10,2,1108,C,A,10,13.560000000,15,336816813,165295,280514282,13.31,10,1,13.28,1,2,13.27,20,2,13.26,198,2,13.14,1,1,13.13,100,1,13.12,200,2,13.11,100,1,13.10,100,1,13.04,2,1,13.40,0,-10,13.53,0,-1,13.55,0,-1,13.56,0,-3,13.57,0,-2,13.58,0,-4,13.59,0,-5,13.60,0,-5,13.61,0,-5,13.62,0,-3,ARL,0
2025-07-17T16:11:50.026837358Z,2025-07-17T16:11:50.026672014Z,10,2,1108,A,A,10,13.550000000,15,337690189,165344,281078802,13.31,10,1,13.28,1,2,13.27,20,2,13.26,198,2,13.14,1,1,13.13,100,1,13.12,200,2,13.11,100,1,13.10,100,1,13.04,2,1,13.40,0,-10,13.53,0,-1,13.55,0,-1,13.56,0,-3,13.57,0,-2,13.58,0,-4,13.59,0,-5,13.60,0,-5,13.61,0,-5,13.62,0,-3,ARL,0
2025-07-17T16:11:50.027004977Z,2025-07-17T16:11:50.026839463Z,10,2,1108,C,A,10,13.570000000,100,336828765,165514,281078803,13.31,10,1,13.28,1,2,13.27,20,2,13.26,198,2,13.14,1,1,13.13,100,1,13.12,200,2,13.11,100,1,13.10,100,1,13.04,2,1,13.40,0,-10,13.53,0,-1,13.55,0,-2,13.56,0,-3,13.57,0,-2,13.58,0,-4,13.59,0,-5,13.60,0,-5,13.61,0,-5,13.62,0,-3,ARL,0
2025-07-17T16:11:50.027004977Z,2025-07-17T16:11:50.026839463Z,10,2,1108,A,A,10,13.560000000,100,337690193,165514,281078803,13.31,10,1,13.28,1,2,13.27,20,2,13.26,198,2,13.14,1,1,13.13,100,1,13.12,200,2,13.11,100,1,13.10,100,1,13.04,2,1,13.40,0,-10,13.53,0,-1,13.55,0,-2,13.56,0,-3,13.57,0,-2,13.58,0,-4,13.59,0,-5,13.60,0,-5,13.61,0,-5,13.62,0,-3,ARL,0
2025-07-17T16:11:50.033010798Z,2025-07-17T16:11:50.032845393Z,10,2,1108,C,A,10,15.740000000,100,335220497,165405,281078903,13.31,10,1,13.28,1,2,13.27,20,2,13.26,198,2,13.14,1,1,13.13,100,1,13.12,200,2,13.11,100,1,13.10,100,1,13.04,2,1,13.40,0,-10,13.53,0,-1,13.55,0,-2,13.56,0,-4,13.57,0,-2,13.58,0,-4,13.59,0,-5,13.60,0,-5,13.61,0,-5,13.62,0,-3,ARL,0
2025-07-17T16:11:50.033010798Z,2025-07-17T16:11:50.032845393Z,10,2,1108,A,A,10,15.600000000,100,337690641,165405,281078903,13.31,10,1,13.28,1,2,13.27,20,2,13.26,198,2,13.14,1,1,13.13,100,1,13.12,200,2,13.11,100,1,13.10,100,1,13.04,2,1,13.40,0,-10,13.53,0,-1,13.55,0,-2,13.56,0,-4,13.57,0,-2,13.58,0,-4,13.59,0,-5,13.60,0,-5,13.61,0,-5,13.62,0,-3,ARL,0
2025-07-17T16:11:53.859909462Z,2025-07-17T16:11:53.859743991Z,10,2,1108,A,A,10,13.530000000,15,337772837,165471,281142794,13.31,10,1,13.28,1,2,13.27,20,2,13.26,198,2,13.14,1,1,13.13,100,1,13.12,200,2,13.11,100,1,13.10,100,1,13.04,2,1,13.40,0,-10,13.53,0,-1,13.55,0,-2,13.56,0,-4,13.57,0,-2,13.58,0,-4,13.59,0,-5,13.60,0,-5,13.61,0,-5,13.62,0,-3,ARL,0
2025-07-17T16:11:54.662527332Z,2025-07-17T16:11:54.662361841Z,10,2,1108,C,A,10,13.560000000,100,337690193,165491,281156215,13.31,10,1,13.28,1,2,13.27,20,2,13.26,198,2,13.14,1,1,13.13,100,1,13.12,200,2,13.11,100,1,13.10,100,1,13.04,2,1,13.40,0,-10,13.53,0,-2,13.55,0,-2,13.56,0,-4,13.57,0,-2,13.58,0,-4,13.59,0,-5,13.60,0,-5,13.61,0,-5,13.62,0,-3,ARL,0
2025-07-17T16:11:54.662527332Z,2025-07-17T16:11:54.662361841Z,10,2,1108,A,A,10,13.540000000,100,337790717,165491,281156215,13.31,10,1,13.28,1,2,13.27,20,2,13.26,198,2,13.14,1,1,13.13,100,1,13.12,200,2,13.11,100,1,13.10,100,1,13.04,2,1,13.40,0,-10,13.53,0,-2,13.55,0,-2,13.56,0,-4,13.57,0,-2,13.58,0,-4,13.59,0,-5,13.60,0,-5,13.61,0,-5,13.62,0,-3,ARL,0
2025-07-17T16:11:54.663278200Z,2025-07-17T16:11:54.663112543Z,10,2,1108,C,A,10,14.640000000,100,336567213,165657,281156222,13.31,10,1,13.28,1,2,13.27,20,2,13.26,198,2,13.14,1,1,13.13,100,1,13.12,200,2,13.11,100,1,13.10,100,1,13.04,2,1,13.40,0,-10,13.53,0,-2,13.54,0,-1,13.55,0,-2,13.56,0,-4,13.57,0,-2,13.58,0,-4,13.59,0,-5,13.60,0,-5,13.61,0,-5,ARL,0
2025-07-17T16:11:54.663278200Z,2025-07-17T16:11:54.663112543Z,10,2,1108,A,A,10,14.590000000,100,337790737,165657,281156222,13.31,10,1,13.28,1,2,13.27,20,2,13.26,198,2,13.14,1,1,13.13,100,1,13.12,200,2,13.11,100,1,13.10,100,1,13.04,2,1,13.40,0,-10,13.53,0,-2,13.54,0,-1,13.55,0,-2,13.56,0,-4,13.57,0,-2,13.58,0,-4,13.59,0,-5,13.60,0,-5,13.61,0,-5,ARL,0
2025-07-17T16:11:54.664134026Z,2025-07-17T16:11:54.663968656Z,10,2,1108,C,A,10,14.640000000,100,335220525,165370,281156223,13.31,10,1,13.28,1,2,13.27,20,2,13.26,198,2,13.14,1,1,13.13,100,1,13.12,200,2,13.11,100,1,13.10,100,1,13.04,2,1,13.40,0,-10,13.53,0,-2,13.54,0,-1,13.55,0,-2,13.56,0,-4,13.57,0,-2,13.58,0,-4,13.59,0,-5,13.60,0,-5,13.61,0,-5,ARL,0
2025-07-17T16:11:54.664134026Z,2025-07-17T16:11:54.663968656Z,10,2,1108,A,A,10,14.490000000,100,337790745,165370,281156223,13.31,10,1,13.28,1,2,13.27,20,2,13.26,198,2,13.14,1,1,13.13,100,1,13.12,200,2,13.11,100,1,13.10,100,1,13.04,2,1,13.40,0,-10,13.53,0,-2,13.54,0,-1,13.55,0,-2,13.56,0,-4,13.57,0,-2,13.58,0,-4,13.59,0,-5,13.60,0,-5,13.61,0,-5,ARL,0
2025-07-17T16:11:54.666326600Z,2025-07-17T16:11:54.666160990Z,10,2,1108,C,A,10,14.470000000,100,335220561,165610,281156243,13.31,10,1,13.28,1,2,13.27,20,2,13.26,198,2,13.14,1,1,13.13,100,1,13.12,200,2,13.11,100,1,13.10,100,1,13.04,2,1,13.40,0,-10,13.53,0,-2,13.54,0,-1,13.55,0,-2,13.56,0,-4,13.57,0,-2,13.58,0,-4,13.59,0,-5,13.60,0,-5,13.61,0,-5,ARL,0
2025-07-17T16:11:54.666326600Z,2025-07-17T16:11:54.666160990Z,10,2,1108,A,A,10,14.330000000,100,337790761,165610,281156243,13.31,10,1,13.28,1,2,13.27,20,2,13.26,198,2,13.14,1,1,13.13,100,1,13.12,200,2,13.11,100,1,13.10,100,1,13.04,2,1,13.40,0,-10,13.53,0,-2,13.54,0,-1,13.55,0,-2,13.56,0,-4,13.57,0,-2,13.58,0,-4,13.59,0,-5,13.60,0,-5,13.61,0,-5,ARL,0
2025-07-17T16:11:54.667504546Z,2025-07-17T16:11:54.667339002Z,10,2,1108,C,A,10,14.640000000,100,335220629,165544,281156250,13.31,10,1,13.28,1,2,13.27,20,2,13.26,198,2,13.14,1,1,13.13,100,1,13.12,200,2,13.11,100,1,13.10,100,1,13.04,2,1,13.40,0,-10,13.53,0,-2,13.54,0,-1,13.55,0,-2,13.56,0,-4,13.57,0,-2,13.58,0,-4,13.59,0,-5,13.60,0,-5,13.61,0,-5,ARL,0
2025-07-17T16:11:54.667504546Z,2025-07-17T16:11:54.667339002Z,10,2,1108,A,A,10,14.490000000,100,337790777,165544,281156250,13.31,10,1,13.28,1,2,13.27,20,2,13.26,198,2,13.14,1,1,13.13,100,1,13.12,200,2,13.11,100,1,13.10,100,1,13.04,2,1,13.40,0,-10,13.53,0,-2,13.54,0,-1,13.55,0,-2,13.56,0,-4,13.57,0,-2,13.58,0,-4,13.59,0,-5,13.60,0,-5,13.61,0,-5,ARL,0
2025-07-17T16:11:59.382515678Z,2025-07-17T16:11:59.382350338Z,10,2,1108,C,A,10,13.550000000,15,337690189,165340,281270010,13.31,10,1,13.28,1,2,13.27,20,2,13.26,198,2,13.14,1,1,13.13,100,1,13.12,200,2,13.11,100,1,13.10,100,1,13.04,2,1,13.40,0,-10,13.53,0,-2,13.54,0,-1,13.55,0,-2,13.56,0,-4,13.57,0,-2,13.58,0,-4,13.59,0,-5,13.60,0,-5,13.61,0,-5,ARL,0
2025-07-17T16:12:02.982078719Z,2025-07-17T16:12:02.981913204Z,10,2,1108,A,A,10,13.510000000,15,338041605,165515,281348152,13.31,10,1,13.28,1,2,13.27,20,2,13.26,198,2,13.14,1,1,13.13,100,1,13.12,200,2,13.11,100,1,13.10,100,1,13.04,2,1,13.40,0,-10,13.53,0,-2,13.54,0,-1,13.55,0,-2,13.56,0,-4,13.57,0,-2,13.58,0,-4,13.59,0,-5,13.60,0,-5,13.61,0,-5,ARL,0
2025-07-17T16:12:03.064162605Z,2025-07-17T16:12:03.063997054Z,10,2,1108,C,A,10,13.540000000,100,337790717,165551,281351122,13.31,10,1,13.28,1,2,13.27,20,2,13.26,198,2,13.14,1,1,13.13,100,1,13.12,200,2,13.11,100,1,13.10,100,1,13.04,2,1,13.40,0,-10,13.51,0,-1,13.53,0,-2,13.54,0,-1,13.55,0,-2,13.56,0,-4,13.57,0,-2,13.58,0,-4,13.59,0,-5,13.60,0,-5,ARL,0
2025-07-17T16:12:03.064162605Z,2025-07-17T16:12:03.063997054Z,10,2,1108,A,A,10,13.520000000,100,338044041,165551,281351122,13.31,10,1,13.28,1,2,13.27,20,2,13.26,198,2,13.14,1,1,13.13,100,1,13.12,200,2,13.11,100,1,13.10,100,1,13.04,2,1,13.40,0,-10,13.51,0,-1,13.53,0,-2,13.54,0,-1,13.55,0,-2,13.56,0,-4,13.57,0,-2,13.58,0,-4,13.59,0,-5,13.60,0,-5,ARL,0
2025-07-17T16:12:03.068467146Z,2025-07-17T16:12:03.068301745Z,10,2,1108,C,B,10,13.010000000,2,332494213,165401,281351235,13.31,10,1,13.28,1,2,13.27,20,2,13.26,198,2,13.14,1,1,13.13,100,1,13.12,200,2,13.11,100,1,13.10,100,1,13.04,2,1,13.40,0,-10,13.51,0,-1,13.53,0,-2,13.54,0,-1,13.55,0,-2,13.56,0,-4,13.57,0,-2,13.58,0,-4,13.59,0,-5,13.60,0,-5,ARL,0
2025-07-17T16:12:03.068467146Z,2025-07-17T16:12:03.068301745Z,10,2,1108,A,B,10,12.920000000,2,338044113,165401,281351235,13.31,10,1,13.28,1,2,13.27,20,2,13.26,198,2,13.14,1,1,13.13,100,1,13.12,200,2,13.11,100,1,13.10,100,1,13.04,2,1,13.40,0,-10,13.51,0,-1,13.53,0,-2,13.54,0,-1,13.55,0,-2,13.56,0,-4,13.57,0,-2,13.58,0,-4,13.59,0,-5,13.60,0,-5,ARL,0
2025-07-17T16:12:03.075200038Z,2025-07-17T16:12:03.075034550Z,10,2,1108,C,A,10,13.860000000,100,336567333,165488,281351372,13.31,10,1,13.28,1,2,13.27,20,2,13.26,198,2,13.14,1,1,13.13,100,1,13.12,200,2,13.11,100,1,13.10,100,1,13.04,2,1,13.40,0,-10,13.51,0,-1,13.53,0,-2,13.54,0,-1,13.55,0,-2,13.56,0,-4,13.57,0,-2,13.58,0,-4,13.59,0,-5,13.60,0,-5,ARL,0
2025-07-17T16:12:03.075260529Z,2025-07-17T16:12:03.075095341Z,10,2,1108,A,A,10,13.790000000,100,338044233,165188,281351373,13.31,10,1,13.28,1,2,13.27,20,2,13.26,198,2,13.14,1,1,13.13,100,1,13.12,200,2,13.11,100,1,13.10,100,1,13.04,2,1,13.40,0,-10,13.51,0,-1,13.53,0,-2,13.54,0,-1,13.55,0,-2,13.56,0,-4,13.57,0,-2,13.58,0,-4,13.59,0,-5,13.60,0,-5,ARL,0
2025-07-17T16:12:06.775177637Z,2025-07-17T16:12:06.775011783Z,10,2,1108,C,A,10,14.510000000,100,336259225,165854,281422697,13.31,10,1,13.28,1,2,13.27,20,2,13.26,198,2,13.14,1,1,13.13,100,1,13.12,200,2,13.11,100,1,13.10,100,1,13.04,2,1,13.40,0,-10,13.51,0,-1,13.53,0,-2,13.54,0,-1,13.55,0,-2,13.56,0,-4,13.57,0,-2,13.58,0,-4,13.59,0,-5,13.60,0,-5,ARL,0
2025-07-17T16:12:06.775177637Z,2025-07-17T16:12:06.775011783Z,10,2,1108,A,A,10,14.400000000,100,338139585,165854,281422697,13.31,10,1,13.28,1,2,13.27,20,2,13.26,198,2,13.14,1,1,13.13,100,1,13.12,200,2,13.11,100,1,13.10,100,1,13.04,2,1,13.40,0,-10,13.51,0,-1,13.53,0,-2,13.54,0,-1,13.55,0,-2,13.56,0,-4,13.57,0,-2,13.58,0,-4,13.59,0,-5,13.60,0,-5,ARL,0
2025-07-17T16:12:06.775614536Z,2025-07-17T16:12:06.775449017Z,10,2,1108,C,A,10,14.510000000,100,336261905,165519,281422702,13.31,10,1,13.28,1,2,13.27,20,2,13.26,198,2,13.14,1,1,13.13,100,1,13.12,200,2,13.11,100,1,13.10,100,1,13.04,2,1,13.40,0,-10,13.51,0,-1,13.53,0,-2,13.54,0,-1,13.55,0,-2,13.56,0,-4,13.57,0,-2,13.58,0,-4,13.59,0,-5,13.60,0,-5,ARL,0
2025-07-17T16:12:06.775614536Z,2025-07-17T16:12:06.775449017Z,10,2,1108,A,A,10,14.400000000,100,338139601,165519,281422702,13.31,10,1,13.28,1,2,13.27,20,2,13.26,198,2,13.14,1,1,13.13,100,1,13.12,200,2,13.11,100,1,13.10,100,1,13.04,2,1,13.40,0,-10,13.51,0,-1,13.53,0,-2,13.54,0,-1,13.55,0,-2,13.56,0,-4,13.57,0,-2,13.58,0,-4,13.59,0,-5,13.60,0,-5,ARL,0
2025-07-17T16:12:06.779705717Z,2025-07-17T16:12:06.779540143Z,10,2,1108,C,A,10,13.530000000,15,337772837,165574,281422782,13.31,10,1,13.28,1,2,13.27,20,2,13.26,198,2,13.14,1,1,13.13,100,1,13.12,200,2,13.11,100,1,13.10,100,1,13.04,2,1,13.40,0,-10,13.51,0,-1,13.53,0,-2,13.54,0,-1,13.55,0,-2,13.56,0,-4,13.57,0,-2,13.58,0,-4,13.59,0,-5,13.60,0,-5,ARL,0
2025-07-17T16:12:07.784698893Z,2025-07-17T16:12:07.784533539Z,10,2,1108,A,A,10,13.490000000,15,338167057,165354,281443568,13.31,10,1,13.28,1,2,13.27,20,2,13.26,198,2,13.14,1,1,13.13,100,1,13.12,200,2,13.11,100,1,13.10,100,1,13.04,2,1,13.40,0,-10,13.51,0,-1,13.53,0,-2,13.54,0,-1,13.55,0,-2,13.56,0,-4,13.57,0,-2,13.58,0,-4,13.59,0,-5,13.60,0,-5,ARL,0
2025-07-17T16:12:08.585194585Z,2025-07-17T16:12:08.585029039Z,10,2,1108,C,A,10,13.520000000,100,338044041,165546,281451898,13.31,10,1,13.28,1,2,13.27,20,2,13.26,198,2,13.14,1,1,13.13,100,1,13.12,200,2,13.11,100,1,13.10,100,1,13.04,2,1,13.40,0,-10,13.49,0,-1,13.51,0,-1,13.53,0,-2,13.54,0,-1,13.55,0,-2,13.56,0,-4,13.57,0,-2,13.58,0,-4,13.59,0,-5,ARL,0
2025-07-17T16:12:08.585194585Z,2025-07-17T16:12:08.585029039Z,10,2,1108,A,A,10,13.500000000,100,338180793,165546,281451898,13.31,10,1,13.28,1,2,13.27,20,2,13.26,198,2,13.14,1,1,13.13,100,1,13.12,200,2,13.11,100,1,13.10,100,1,13.04,2,1,13.40,0,-10,13.49,0,-1,13.51,0,-1,13.53,0,-2,13.54,0,-1,13.55,0,-2,13.56,0,-4,13.57,0,-2,13.58,0,-4,13.59,0,-5,ARL,0
2025-07-17T16:12:08.585942049Z,2025-07-17T16:12:08.585776508Z,10,2,1108,C,A,10,14.590000000,100,337790737,165541,281451903,13.31,10,1,13.28,1,2,13.27,20,2,13.26,198,2,13.14,1,1,13.13,100,1,13.12,200,2,13.11,100,1,13.10,100,1,13.04,2,1,13.40,0,-10,13.49,0,-1,13.50,0,-1,13.51,0,-1,13.53,0,-2,13.54,0,-1,13.55,0,-2,13.56,0,-4,13.57,0,-2,13.58,0,-4,ARL,0
2025-07-17T16:12:08.585942049Z,2025-07-17T16:12:08.585776508Z,10,2,1108,A,A,10,14.550000000,100,338180841,165541,281451903,13.31,10,1,13.28,1,2,13.27,20,2,13.26,198,2,13.14,1,1,13.13,100,1,13.12,200,2,13.11,100,1,13.10,100,1,13.04,2,1,13.40,0,-10,13.49,0,-1,13.50,0,-1,13.51,0,-1,13.53,0,-2,13.54,0,-1,13.55,0,-2,13.56,0,-4,13.57,0,-2,13.58,0,-4,ARL,0
2025-07-17T16:12:18.789922022Z,2025-07-17T16:12:18.789756367Z,10,2,1108,C,A,10,13.820000000,2,336447325,165655,281613266,13.31,10,1,13.28,1,2,13.27,20,2,13.26,198,2,13.14,1,1,13.13,100,1,13.12,200,2,13.11,100,1,13.10,100,1,13.04,2,1,13.40,0,-10,13.49,0,-1,13.50,0,-1,13.51,0,-1,13.53,0,-2,13.54,0,-1,13.55,0,-2,13.56,0,-4,13.57,0,-2,13.58,0,-4,ARL,0
2025-07-17T16:12:18.789922022Z,2025-07-17T16:12:18.789756367Z,10,2,1108,A,A,10,13.740000000,2,338371797,165655,281613266,13.31,10,1,13.28,1,2,13.27,20,2,13.26,198,2,13.14,1,1,13.13,100,1,13.12,200,2,13.11,100,1,13.10,100,1,13.04,2,1,13.40,0,-10,13.49,0,-1,13.50,0,-1,13.51,0,-1,13.53,0,-2,13.54,0,-1,13.55,0,-2,13.56,0,-4,13.57,0,-2,13.58,0,-4,ARL,0
2025-07-17T16:12:19.370986404Z,2025-07-17T16:12:19.370820933Z,10,2,1108,A,A,10,14.270000000,700,338382329,165471,281622545,13.31,10,1,13.28,1,2,13.27,20,2,13.26,198,2,13.14,1,1,13.13,100,1,13.12,200,2,13.11,100,1,13.10,100,1,13.04,2,1,13.40,0,-10,13.49,0,-1,13.50,0,-1,13.51,0,-1,13.53,0,-2,13.54,0,-1,13.55,0,-2,13.56,0,-4,13.57,0,-2,13.58,0,-4,ARL,0
2025-07-17T16:12:19.371041049Z,2025-07-17T16:12:19.370875240Z,10,2,1108,C,A,10,14.600000000,700,282920685,165809,281622547,13.31,10,1,13.28,1,2,13.27,20,2,13.26,198,2,13.14,1,1,13.13,100,1,13.12,200,2,13.11,100,1,13.10,100,1,13.04,2,1,13.40,0,-10,13.49,0,-1,13.50,0,-1,13.51,0,-1,13.53,0,-2,13.54,0,-1,13.55,0,-2,13.56,0,-4,13.57,0,-2,13.58,0,-4,ARL,0
2025-07-17T16:12:19.696689718Z,2025-07-17T16:12:19.696521343Z,10,2,1108,C,A,10,13.490000000,15,338167057,168375,281630053,13.31,10,1,13.28,1,2,13.27,20,2,13.26,198,2,13.14,1,1,13.13,100,1,13.12,200,2,13.11,100,1,13.10,100,1,13.04,2,1,13.40,0,-10,13.49,0,-1,13.50,0,-1,13.51,0,-1,13.53,0,-2,13.54,0,-1,13.55,0,-2,13.56,0,-4,13.57,0,-2,13.58,0,-4,ARL,0
2025-07-17T16:12:19.711773364Z,2025-07-17T16:12:19.711591494Z,10,2,1108,C,A,10,13.510000000,15,338041605,181870,281634812,13.31,10,1,13.28,1,2,13.27,20,2,13.26,198,2,13.14,1,1,13.13,100,1,13.12,200,2,13.11,100,1,13.10,100,1,13.04,2,1,13.40,0,-10,13.49,0,-1,13.50,0,-1,13.51,0,-1,13.53,0,-2,13.54,0,-1,13.55,0,-2,13.56,0,-4,13.57,0,-2,13.58,0,-4,ARL,0
2025-07-17T16:12:32.761277424Z,2025-07-17T16:12:32.761112078Z,10,2,1108,A,A,10,13.480000000,15,338707945,165346,281880398,13.31,10,1,13.28,1,2,13.27,20,2,13.26,198,2,13.14,1,1,13.13,100,1,13.12,200,2,13.11,100,1,13.10,100,1,13.04,2,1,13.40,0,-10,13.49,0,-1,13.50,0,-1,13.51,0,-1,13.53,0,-2,13.54,0,-1,13.55,0,-2,13.56,0,-4,13.57,0,-2,13.58,0,-4,ARL,0
2025-07-17T16:12:32.761413202Z,2025-07-17T16:12:32.761246859Z,10,2,1108,C,A,10,13.500000000,100,338180793,166343,281880409,13.31,10,1,13.28,1,2,13.27,20,2,13.26,198,2,13.14,1,1,13.13,100,1,13.12,200,2,13.11,100,1,13.10,100,1,13.04,2,1,13.40,0,-10,13.48,0,-1,13.49,0,-1,13.50,0,-1,13.51,0,-1,13.53,0,-2,13.54,0,-1,13.55,0,-2,13.56,0,-4,13.57,0,-2,ARL,0
2025-07-17T16:12:32.761413202Z,2025-07-17T16:12:32.761246859Z,10,2,1108,A,A,10,13.490000000,100,338707949,166343,281880409,13.31,10,1,13.28,1,2,13.27,20,2,13.26,198,2,13.14,1,1,13.13,100,1,13.12,200,2,13.11,100,1,13.10,100,1,13.04,2,1,13.40,0,-10,13.48,0,-1,13.49,0,-1,13.50,0,-1,13.51,0,-1,13.53,0,-2,13.54,0,-1,13.55,0,-2,13.56,0,-4,13.57,0,-2,ARL,0
2025-07-17T16:12:32.779055996Z,2025-07-17T16:12:32.778890447Z,10,2,1108,C,A,10,15.120000000,100,296387089,165549,281880579,13.31,10,1,13.28,1,2,13.27,20,2,13.26,198,2,13.14,1,1,13.13,100,1,13.12,200,2,13.11,100,1,13.10,100,1,13.04,2,1,13.40,0,-10,13.48,0,-1,13.49,0,-2,13.50,0,-1,13.51,0,-1,13.53,0,-2,13.54,0,-1,13.55,0,-2,13.56,0,-4,13.57,0,-2,ARL,0
2025-07-17T16:12:32.779055996Z,2025-07-17T16:12:32.778890447Z,10,2,1108,A,A,10,14.840000000,100,338708241,165549,281880579,13.31,10,1,13.28,1,2,13.27,20,2,13.26,198,2,13.14,1,1,13.13,100,1,13.12,200,2,13.11,100,1,13.10,100,1,13.04,2,1,13.40,0,-10,13.48,0,-1,13.49,0,-2,13.50,0,-1,13.51,0,-1,13.53,0,-2,13.54,0,-1,13.55,0,-2,13.56,0,-4,13.57,0,-2,ARL,0
2025-07-17T16:12:32.804318005Z,2025-07-17T16:12:32.804152457Z,10,2,1108,A,A,10,15.380000000,100,338709513,165548,281880972,13.31,10,1,13.28,1,2,13.27,20,2,13.26,198,2,13.14,1,1,13.13,100,1,13.12,200,2,13.11,100,1,13.10,100,1,13.04,2,1,13.40,0,-10,13.48,0,-1,13.49,0,-2,13.50,0,-1,13.51,0,-1,13.53,0,-2,13.54,0,-1,13.55,0,-2,13.56,0,-4,13.57,0,-2,ARL,0
2025-07-17T16:12:32.804332586Z,2025-07-17T16:12:32.804166092Z,10,2,1108,C,A,10,15.660000000,100,326730513,166494,281880973,13.31,10,1,13.28,1,2,13.27,20,2,13.26,198,2,13.14,1,1,13.13,100,1,13.12,200,2,13.11,100,1,13.10,100,1,13.04,2,1,13.40,0,-10,13.48,0,-1,13.49,0,-2,13.50,0,-1,13.51,0,-1,13.53,0,-2,13.54,0,-1,13.55,0,-2,13.56,0,-4,13.57,0,-2,ARL,0
2025-07-17T16:12:40.993064296Z,2025-07-17T16:12:40.992898990Z,10,2,1108,C,A,10,13.490000000,100,338707949,165306,282007871,13.31,10,1,13.28,1,2,13.27,20,2,13.26,198,2,13.14,1,1,13.13,100,1,13.12,200,2,13.11,100,1,13.10,100,1,13.04,2,1,13.40,0,-10,13.48,0,-1,13.49,0,-2,13.50,0,-1,13.51,0,-1,13.53,0,-2,13.54,0,-1,13.55,0,-2,13.56,0,-4,13.57,0,-2,ARL,0
2025-07-17T16:12:40.993332664Z,2025-07-17T16:12:40.993167418Z,10,2,1108,C,A,10,14.270000000,700,338382329,165246,282007875,13.31,10,1,13.28,1,2,13.27,20,2,13.26,198,2,13.14,1,1,13.13,100,1,13.12,200,2,13.11,100,1,13.10,100,1,13.04,2,1,13.40,0,-10,13.48,0,-1,13.49,0,-2,13.50,0,-1,13.51,0,-1,13.53,0,-2,13.54,0,-1,13.55,0,-2,13.56,0,-4,13.57,0,-2,ARL,0
2025-07-17T16:12:40.993333790Z,2025-07-17T16:12:40.993168470Z,10,2,1108,C,A,10,14.270000000,700,336747457,165320,282007876,13.31,10,1,13.28,1,2,13.27,20,2,13.26,198,2,13.14,1,1,13.13,100,1,13.12,200,2,13.11,100,1,13.10,100,1,13.04,2,1,13.40,0,-10,13.48,0,-1,13.49,0,-2,13.50,0,-1,13.51,0,-1,13.53,0,-2,13.54,0,-1,13.55,0,-2,13.56,0,-4,13.57,0,-2,ARL,0
2025-07-17T16:12:40.993379626Z,2025-07-17T16:12:40.993214193Z,10,2,1108,A,A,10,14.540000000,700,338864169,165433,282007877,13.31,10,1,13.28,1,2,13.27,20,2,13.26,198,2,13.14,1,1,13.13,100,1,13.12,200,2,13.11,100,1,13.10,100,1,13.04,2,1,13.40,0,-10,13.48,0,-1,13.49,0,-2,13.50,0,-1,13.51,0,-1,13.53,0,-2,13.54,0,-1,13.55,0,-2,13.56,0,-4,13.57,0,-2,ARL,0
2025-07-17T16:12:40.993393440Z,2025-07-17T16:12:40.993227993Z,10,2,1108,A,A,10,14.470000000,700,338864173,165447,282007878,13.31,10,1,13.28,1,2,13.27,20,2,13.26,198,2,13.14,1,1,13.13,100,1,13.12,200,2,13.11,100,1,13.10,100,1,13.04,2,1,13.40,0,-10,13.48,0,-1,13.49,0,-2,13.50,0,-1,13.51,0,-1,13.53,0,-2,13.54,0,-1,13.55,0,-2,13.56,0,-4,13.57,0,-2,ARL,0
2025-07-17T16:12:40.993432115Z,2025-07-17T16:12:40.993266591Z,10,2,1108,A,A,10,15.710000000,100,338864177,165524,282007879,13.31,10,1,13.28,1,2,13.27,20,2,13.26,198,2,13.14,1,1,13.13,100,1,13.12,200,2,13.11,100,1,13.10,100,1,13.04,2,1,13.40,0,-10,13.48,0,-1,13.49,0,-2,13.50,0,-1,13.51,0,-1,13.53,0,-2,13.54,0,-1,13.55,0,-2,13.56,0,-4,13.57,0,-2,ARL,0
2025-07-17T16:12:40.993445042Z,2025-07-17T16:12:40.993279810Z,10,2,1108,C,A,10,15.380000000,100,338709513,165232,282007880,13.31,10,1,13.28,1,2,13.27,20,2,13.26,198,2,13.14,1,1,13.13,100,1,13.12,200,2,13.11,100,1,13.10,100,1,13.04,2,1,13.40,0,-10,13.48,0,-1,13.49,0,-2,13.50,0,-1,13.51,0,-1,13.53,0,-2,13.54,0,-1,13.55,0,-2,13.56,0,-4,13.57,0,-2,ARL,0
2025-07-17T16:12:40.993818130Z,2025-07-17T16:12:40.993652511Z,10,2,1108,C,A,10,14.550000000,100,338180841,165619,282007882,13.31,10,1,13.28,1,2,13.27,20,2,13.26,198,2,13.14,1,1,13.13,100,1,13.12,200,2,13.11,100,1,13.10,100,1,13.04,2,1,13.40,0,-10,13.48,0,-1,13.49,0,-2,13.50,0,-1,13.51,0,-1,13.53,0,-2,13.54,0,-1,13.55,0,-2,13.56,0,-4,13.57,0,-2,ARL,0
