ts_recv,ts_event,rtype,publisher_id,instrument_id,action,side,depth,price,size,flags,ts_in_delta,sequence,bid_px_00,bid_sz_00,bid_ct_00,bid_px_01,bid_sz_01,bid_ct_01,bid_px_02,bid_sz_02,bid_ct_02,bid_px_03,bid_sz_03,bid_ct_03,bid_px_04,bid_sz_04,bid_ct_04,bid_px_05,bid_sz_05,bid_ct_05,bid_px_06,bid_sz_06,bid_ct_06,bid_px_07,bid_sz_07,bid_ct_07,bid_px_08,bid_sz_08,bid_ct_08,bid_px_09,bid_sz_09,bid_ct_09,ask_px_00,ask_sz_00,ask_ct_00,ask_px_01,ask_sz_01,ask_ct_01,ask_px_02,ask_sz_02,ask_ct_02,ask_px_03,ask_sz_03,ask_ct_03,ask_px_04,ask_sz_04,ask_ct_04,ask_px_05,ask_sz_05,ask_ct_05,ask_px_06,ask_sz_06,ask_ct_06,ask_px_07,ask_sz_07,ask_ct_07,ask_px_08,ask_sz_08,ask_ct_08,ask_px_09,ask_sz_09,ask_ct_09,symbol,order_id
2025-07-17T15:44:37.364377419Z,2025-07-17T15:44:37.364212109Z,10,2,1108,A,A,10,13.700000000,15,302750929,165310,253797506,13.31,10,1,13.28,11,2,13.14,1,1,13.13,100,1,13.11,100,1,13.10,100,1,13.04,2,1,12.99,100,1,12.73,100,1,12.67,100,1,13.40,0,-10,13.71,0,-1,13.73,0,-2,13.74,0,-2,13.75,0,-2,13.76,0,-3,13.77,0,-4,13.78,0,-3,13.79,0,-2,13.80,0,-7,ARL,0
2025-07-17T15:44:37.364519067Z,2025-07-17T15:44:37.364353897Z,10,2,1108,A,A,10,13.730000000,100,302750937,165170,253797510,13.31,10,1,13.28,11,2,13.14,1,1,13.13,100,1,13.11,100,1,13.10,100,1,13.04,2,1,12.99,100,1,12.73,100,1,12.67,100,1,13.40,0,-10,13.71,0,-1,13.73,0,-2,13.74,0,-2,13.75,0,-2,13.76,0,-3,13.77,0,-4,13.78,0,-3,13.79,0,-2,13.80,0,-7,ARL,0
2025-07-17T15:44:37.458119494Z,2025-07-17T15:44:37.457954350Z,10,2,1108,C,A,10,13.750000000,100,302649029,165144,253798432,13.31,10,1,13.28,11,2,13.14,1,1,13.13,100,1,13.11,100,1,13.10,100,1,13.04,2,1,12.99,100,1,12.73,100,1,12.67,100,1,13.40,0,-10,13.71,0,-1,13.73,0,-3,13.74,0,-2,13.75,0,-2,13.76,0,-3,13.77,0,-4,13.78,0,-3,13.79,0,-2,13.80,0,-7,ARL,0
2025-07-17T15:44:38.432460509Z,2025-07-17T15:44:38.432294362Z,10,2,1108,C,A,10,13.730000000,100,302662769,166147,253807786,13.31,10,1,13.28,11,2,13.14,1,1,13.13,100,1,13.11,100,1,13.10,100,1,13.04,2,1,12.99,100,1,12.73,100,1,12.67,100,1,13.40,0,-10,13.71,0,-1,13.73,0,-3,13.74,0,-2,13.75,0,-2,13.76,0,-3,13.77,0,-4,13.78,0,-3,13.79,0,-2,13.80,0,-7,ARL,0
2025-07-17T15:44:38.432460509Z,2025-07-17T15:44:38.432294362Z,10,2,1108,A,A,10,13.710000000,100,302763889,166147,253807786,13.31,10,1,13.28,11,2,13.14,1,1,13.13,100,1,13.11,100,1,13.10,100,1,13.04,2,1,12.99,100,1,12.73,100,1,12.67,100,1,13.40,0,-10,13.71,0,-1,13.73,0,-3,13.74,0,-2,13.75,0,-2,13.76,0,-3,13.77,0,-4,13.78,0,-3,13.79,0,-2,13.80,0,-7,ARL,0
2025-07-17T15:44:38.439253975Z,2025-07-17T15:44:38.439088042Z,10,2,1108,C,A,10,15.920000000,100,301747301,165933,253808105,13.31,10,1,13.28,11,2,13.14,1,1,13.13,100,1,13.11,100,1,13.10,100,1,13.04,2,1,12.99,100,1,12.73,100,1,12.67,100,1,13.40,0,-10,13.71,0,-2,13.73,0,-3,13.74,0,-2,13.75,0,-2,13.76,0,-3,13.77,0,-4,13.78,0,-3,13.79,0,-2,13.80,0,-7,ARL,0
2025-07-17T15:44:38.439253975Z,2025-07-17T15:44:38.439088042Z,10,2,1108,A,A,10,15.770000000,100,302764121,165933,253808105,13.31,10,1,13.28,11,2,13.14,1,1,13.13,100,1,13.11,100,1,13.10,100,1,13.04,2,1,12.99,100,1,12.73,100,1,12.67,100,1,13.40,0,-10,13.71,0,-2,13.73,0,-3,13.74,0,-2,13.75,0,-2,13.76,0,-3,13.77,0,-4,13.78,0,-3,13.79,0,-2,13.80,0,-7,ARL,0
2025-07-17T15:44:38.440321697Z,2025-07-17T15:44:38.440156077Z,10,2,1108,C,A,10,17.580000000,100,301747261,165620,253808122,13.31,10,1,13.28,11,2,13.14,1,1,13.13,100,1,13.11,100,1,13.10,100,1,13.04,2,1,12.99,100,1,12.73,100,1,12.67,100,1,13.40,0,-10,13.71,0,-2,13.73,0,-3,13.74,0,-2,13.75,0,-2,13.76,0,-3,13.77,0,-4,13.78,0,-3,13.79,0,-2,13.80,0,-7,ARL,0
2025-07-17T15:44:38.440321697Z,2025-07-17T15:44:38.440156077Z,10,2,1108,A,A,10,17.420000000,100,302764137,165620,253808122,13.31,10,1,13.28,11,2,13.14,1,1,13.13,100,1,13.11,100,1,13.10,100,1,13.04,2,1,12.99,100,1,12.73,100,1,12.67,100,1,13.40,0,-10,13.71,0,-2,13.73,0,-3,13.74,0,-2,13.75,0,-2,13.76,0,-3,13.77,0,-4,13.78,0,-3,13.79,0,-2,13.80,0,-7,ARL,0
2025-07-17T15:44:43.019262217Z,2025-07-17T15:44:43.019083502Z,10,2,1108,C,A,10,13.700000000,15,302750929,178715,253875920,13.31,10,1,13.28,11,2,13.14,1,1,13.13,100,1,13.11,100,1,13.10,100,1,13.04,2,1,12.99,100,1,12.73,100,1,12.67,100,1,13.40,0,-10,13.71,0,-2,13.73,0,-3,13.74,0,-2,13.75,0,-2,13.76,0,-3,13.77,0,-4,13.78,0,-3,13.79,0,-2,13.80,0,-7,ARL,0
2025-07-17T15:44:43.019352658Z,2025-07-17T15:44:43.019184132Z,10,2,1108,C,A,10,13.720000000,15,302649021,168526,253876010,13.31,10,1,13.28,11,2,13.14,1,1,13.13,100,1,13.11,100,1,13.10,100,1,13.04,2,1,12.99,100,1,12.73,100,1,12.67,100,1,13.40,0,-10,13.71,0,-2,13.73,0,-3,13.74,0,-2,13.75,0,-2,13.76,0,-3,13.77,0,-4,13.78,0,-3,13.79,0,-2,13.80,0,-7,ARL,0
2025-07-17T15:44:44.076009999Z,2025-07-17T15:44:44.075843113Z,10,2,1108,A,A,10,13.700000000,15,302867209,166886,253892869,13.31,10,1,13.28,11,2,13.14,1,1,13.13,100,1,13.11,100,1,13.10,100,1,13.04,2,1,12.99,100,1,12.73,100,1,12.67,100,1,13.40,0,-10,13.71,0,-2,13.73,0,-3,13.74,0,-2,13.75,0,-2,13.76,0,-3,13.77,0,-4,13.78,0,-3,13.79,0,-2,13.80,0,-7,ARL,0
2025-07-17T15:44:44.781630732Z,2025-07-17T15:44:44.781464821Z,10,2,1108,C,A,10,13.700000000,15,302867209,165911,253901222,13.31,10,1,13.28,11,2,13.14,1,1,13.13,100,1,13.11,100,1,13.10,100,1,13.04,2,1,12.99,100,1,12.73,100,1,12.67,100,1,13.40,0,-10,13.70,0,-1,13.71,0,-2,13.73,0,-3,13.74,0,-2,13.75,0,-2,13.76,0,-3,13.77,0,-4,13.78,0,-3,13.79,0,-2,ARL,0
2025-07-17T15:44:53.143249270Z,2025-07-17T15:44:53.143083969Z,10,2,1108,C,A,10,13.730000000,100,302750937,165301,254011871,13.31,10,1,13.28,11,2,13.14,1,1,13.13,100,1,13.11,100,1,13.10,100,1,13.04,2,1,12.99,100,1,12.73,100,1,12.67,100,1,13.40,0,-10,13.70,0,-1,13.71,0,-2,13.73,0,-3,13.74,0,-2,13.75,0,-2,13.76,0,-3,13.77,0,-4,13.78,0,-3,13.79,0,-2,ARL,0
2025-07-17T15:44:57.191188470Z,2025-07-17T15:44:57.191023026Z,10,2,1108,A,A,10,13.750000000,100,303118785,165444,254079162,13.31,10,1,13.28,11,2,13.14,1,1,13.13,100,1,13.11,100,1,13.10,100,1,13.04,2,1,12.99,100,1,12.73,100,1,12.67,100,1,13.40,0,-10,13.70,0,-1,13.71,0,-2,13.73,0,-3,13.74,0,-2,13.75,0,-2,13.76,0,-3,13.77,0,-4,13.78,0,-3,13.79,0,-2,ARL,0
2025-07-17T15:45:07.065756574Z,2025-07-17T15:45:07.065587919Z,10,2,1108,C,A,10,13.710000000,100,302763889,168655,254244597,13.31,10,1,13.28,11,2,13.14,1,1,13.13,100,1,13.11,100,1,13.10,100,1,13.04,2,1,12.99,100,1,12.73,100,1,12.67,100,1,13.40,0,-10,13.70,0,-1,13.71,0,-2,13.73,0,-3,13.74,0,-2,13.75,0,-3,13.76,0,-3,13.77,0,-4,13.78,0,-3,13.79,0,-2,ARL,0
2025-07-17T15:45:07.080131505Z,2025-07-17T15:45:07.079966224Z,10,2,1108,C,A,10,13.750000000,100,303118785,165281,254245492,13.31,10,1,13.28,11,2,13.14,1,1,13.13,100,1,13.11,100,1,13.10,100,1,13.04,2,1,12.99,100,1,12.73,100,1,12.67,100,1,13.40,0,-10,13.70,0,-1,13.71,0,-2,13.73,0,-3,13.74,0,-2,13.75,0,-3,13.76,0,-3,13.77,0,-4,13.78,0,-3,13.79,0,-2,ARL,0
2025-07-17T15:45:07.080687215Z,2025-07-17T15:45:07.080521807Z,10,2,1108,C,A,10,14.660000000,100,302205289,165408,254245505,13.31,10,1,13.28,11,2,13.14,1,1,13.13,100,1,13.11,100,1,13.10,100,1,13.04,2,1,12.99,100,1,12.73,100,1,12.67,100,1,13.40,0,-10,13.70,0,-1,13.71,0,-2,13.73,0,-3,13.74,0,-2,13.75,0,-3,13.76,0,-3,13.77,0,-4,13.78,0,-3,13.79,0,-2,ARL,0
2025-07-17T15:45:07.080687215Z,2025-07-17T15:45:07.080521807Z,10,2,1108,A,A,10,14.890000000,100,303330477,165408,254245505,13.31,10,1,13.28,11,2,13.14,1,1,13.13,100,1,13.11,100,1,13.10,100,1,13.04,2,1,12.99,100,1,12.73,100,1,12.67,100,1,13.40,0,-10,13.70,0,-1,13.71,0,-2,13.73,0,-3,13.74,0,-2,13.75,0,-3,13.76,0,-3,13.77,0,-4,13.78,0,-3,13.79,0,-2,ARL,0
2025-07-17T15:45:07.080872245Z,2025-07-17T15:45:07.080706110Z,10,2,1108,C,A,10,14.790000000,100,302662821,166135,254245511,13.31,10,1,13.28,11,2,13.14,1,1,13.13,100,1,13.11,100,1,13.10,100,1,13.04,2,1,12.99,100,1,12.73,100,1,12.67,100,1,13.40,0,-10,13.70,0,-1,13.71,0,-2,13.73,0,-3,13.74,0,-2,13.75,0,-3,13.76,0,-3,13.77,0,-4,13.78,0,-3,13.79,0,-2,ARL,0
2025-07-17T15:45:07.080872245Z,2025-07-17T15:45:07.080706110Z,10,2,1108,A,A,10,15.060000000,100,303330485,166135,254245511,13.31,10,1,13.28,11,2,13.14,1,1,13.13,100,1,13.11,100,1,13.10,100,1,13.04,2,1,12.99,100,1,12.73,100,1,12.67,100,1,13.40,0,-10,13.70,0,-1,13.71,0,-2,13.73,0,-3,13.74,0,-2,13.75,0,-3,13.76,0,-3,13.77,0,-4,13.78,0,-3,13.79,0,-2,ARL,0
2025-07-17T15:45:07.081578064Z,2025-07-17T15:45:07.081407507Z,10,2,1108,C,A,10,14.810000000,100,301747001,170557,254245568,13.31,10,1,13.28,11,2,13.14,1,1,13.13,100,1,13.11,100,1,13.10,100,1,13.04,2,1,12.99,100,1,12.73,100,1,12.67,100,1,13.40,0,-10,13.70,0,-1,13.71,0,-2,13.73,0,-3,13.74,0,-2,13.75,0,-3,13.76,0,-3,13.77,0,-4,13.78,0,-3,13.79,0,-2,ARL,0
2025-07-17T15:45:07.081578064Z,2025-07-17T15:45:07.081407507Z,10,2,1108,A,A,10,14.960000000,100,303330509,170557,254245568,13.31,10,1,13.28,11,2,13.14,1,1,13.13,100,1,13.11,100,1,13.10,100,1,13.04,2,1,12.99,100,1,12.73,100,1,12.67,100,1,13.40,0,-10,13.70,0,-1,13.71,0,-2,13.73,0,-3,13.74,0,-2,13.75,0,-3,13.76,0,-3,13.77,0,-4,13.78,0,-3,13.79,0,-2,ARL,0
2025-07-17T15:45:07.081607970Z,2025-07-17T15:45:07.081441134Z,10,2,1108,C,A,10,14.660000000,100,302205309,166836,254245576,13.31,10,1,13.28,11,2,13.14,1,1,13.13,100,1,13.11,100,1,13.10,100,1,13.04,2,1,12.99,100,1,12.73,100,1,12.67,100,1,13.40,0,-10,13.70,0,-1,13.71,0,-2,13.73,0,-3,13.74,0,-2,13.75,0,-3,13.76,0,-3,13.77,0,-4,13.78,0,-3,13.79,0,-2,ARL,0
2025-07-17T15:45:07.081607970Z,2025-07-17T15:45:07.081441134Z,10,2,1108,A,A,10,14.890000000,100,303330521,166836,254245576,13.31,10,1,13.28,11,2,13.14,1,1,13.13,100,1,13.11,100,1,13.10,100,1,13.04,2,1,12.99,100,1,12.73,100,1,12.67,100,1,13.40,0,-10,13.70,0,-1,13.71,0,-2,13.73,0,-3,13.74,0,-2,13.75,0,-3,13.76,0,-3,13.77,0,-4,13.78,0,-3,13.79,0,-2,ARL,0
2025-07-17T15:45:07.083898999Z,2025-07-17T15:45:07.083732443Z,10,2,1108,C,A,10,17.420000000,100,302764137,166556,254246327,13.31,10,1,13.28,11,2,13.14,1,1,13.13,100,1,13.11,100,1,13.10,100,1,13.04,2,1,12.99,100,1,12.73,100,1,12.67,100,1,13.40,0,-10,13.70,0,-1,13.71,0,-2,13.73,0,-3,13.74,0,-2,13.75,0,-3,13.76,0,-3,13.77,0,-4,13.78,0,-3,13.79,0,-2,ARL,0
2025-07-17T15:45:07.083898999Z,2025-07-17T15:45:07.083732443Z,10,2,1108,A,A,10,17.760000000,100,303331309,166556,254246327,13.31,10,1,13.28,11,2,13.14,1,1,13.13,100,1,13.11,100,1,13.10,100,1,13.04,2,1,12.99,100,1,12.73,100,1,12.67,100,1,13.40,0,-10,13.70,0,-1,13.71,0,-2,13.73,0,-3,13.74,0,-2,13.75,0,-3,13.76,0,-3,13.77,0,-4,13.78,0,-3,13.79,0,-2,ARL,0
2025-07-17T15:45:07.085222525Z,2025-07-17T15:45:07.085057258Z,10,2,1108,C,A,10,14.030000000,100,302466157,165267,254246434,13.31,10,1,13.28,11,2,13.14,1,1,13.13,100,1,13.11,100,1,13.10,100,1,13.04,2,1,12.99,100,1,12.73,100,1,12.67,100,1,13.40,0,-10,13.70,0,-1,13.71,0,-2,13.73,0,-3,13.74,0,-2,13.75,0,-3,13.76,0,-3,13.77,0,-4,13.78,0,-3,13.79,0,-2,ARL,0
2025-07-17T15:45:07.085274852Z,2025-07-17T15:45:07.085109545Z,10,2,1108,A,A,10,14.260000000,100,303331401,165307,254246437,13.31,10,1,13.28,11,2,13.14,1,1,13.13,100,1,13.11,100,1,13.10,100,1,13.04,2,1,12.99,100,1,12.73,100,1,12.67,100,1,13.40,0,-10,13.70,0,-1,13.71,0,-2,13.73,0,-3,13.74,0,-2,13.75,0,-3,13.76,0,-3,13.77,0,-4,13.78,0,-3,13.79,0,-2,ARL,0
2025-07-17T15:45:07.086534700Z,2025-07-17T15:45:07.086368957Z,10,2,1108,C,A,10,14.640000000,100,301747005,165743,254246501,13.31,10,1,13.28,11,2,13.14,1,1,13.13,100,1,13.11,100,1,13.10,100,1,13.04,2,1,12.99,100,1,12.73,100,1,12.67,100,1,13.40,0,-10,13.70,0,-1,13.71,0,-2,13.73,0,-3,13.74,0,-2,13.75,0,-3,13.76,0,-3,13.77,0,-4,13.78,0,-3,13.79,0,-2,ARL,0
2025-07-17T15:45:07.086660325Z,2025-07-17T15:45:07.086494745Z,10,2,1108,A,A,10,14.780000000,100,303331425,165580,254246502,13.31,10,1,13.28,11,2,13.14,1,1,13.13,100,1,13.11,100,1,13.10,100,1,13.04,2,1,12.99,100,1,12.73,100,1,12.67,100,1,13.40,0,-10,13.70,0,-1,13.71,0,-2,13.73,0,-3,13.74,0,-2,13.75,0,-3,13.76,0,-3,13.77,0,-4,13.78,0,-3,13.79,0,-2,ARL,0
2025-07-17T15:45:07.087389466Z,2025-07-17T15:45:07.087223859Z,10,2,1108,C,A,10,15.770000000,100,302764121,165607,254246529,13.31,10,1,13.28,11,2,13.14,1,1,13.13,100,1,13.11,100,1,13.10,100,1,13.04,2,1,12.99,100,1,12.73,100,1,12.67,100,1,13.40,0,-10,13.70,0,-1,13.71,0,-2,13.73,0,-3,13.74,0,-2,13.75,0,-3,13.76,0,-3,13.77,0,-4,13.78,0,-3,13.79,0,-2,ARL,0
2025-07-17T15:45:07.087389466Z,2025-07-17T15:45:07.087223859Z,10,2,1108,A,A,10,16.080000000,100,303331429,165607,254246529,13.31,10,1,13.28,11,2,13.14,1,1,13.13,100,1,13.11,100,1,13.10,100,1,13.04,2,1,12.99,100,1,12.73,100,1,12.67,100,1,13.40,0,-10,13.70,0,-1,13.71,0,-2,13.73,0,-3,13.74,0,-2,13.75,0,-3,13.76,0,-3,13.77,0,-4,13.78,0,-3,13.79,0,-2,ARL,0
2025-07-17T15:45:07.133978488Z,2025-07-17T15:45:07.133812895Z,10,2,1108,C,A,10,14.810000000,100,301747957,165593,254250625,13.31,10,1,13.28,11,2,13.14,1,1,13.13,100,1,13.11,100,1,13.10,100,1,13.04,2,1,12.99,100,1,12.73,100,1,12.67,100,1,13.40,0,-10,13.70,0,-1,13.71,0,-2,13.73,0,-3,13.74,0,-2,13.75,0,-3,13.76,0,-3,13.77,0,-4,13.78,0,-3,13.79,0,-2,ARL,0
2025-07-17T15:45:07.133978488Z,2025-07-17T15:45:07.133812895Z,10,2,1108,A,A,10,14.960000000,100,303334253,165593,254250625,13.31,10,1,13.28,11,2,13.14,1,1,13.13,100,1,13.11,100,1,13.10,100,1,13.04,2,1,12.99,100,1,12.73,100,1,12.67,100,1,13.40,0,-10,13.70,0,-1,13.71,0,-2,13.73,0,-3,13.74,0,-2,13.75,0,-3,13.76,0,-3,13.77,0,-4,13.78,0,-3,13.79,0,-2,ARL,0
2025-07-17T15:45:07.469961302Z,2025-07-17T15:45:07.469796155Z,10,2,1108,A,A,10,14.080000000,100,303340405,165147,254258029,13.31,10,1,13.28,11,2,13.14,1,1,13.13,100,1,13.11,100,1,13.10,100,1,13.04,2,1,12.99,100,1,12.73,100,1,12.67,100,1,13.40,0,-10,13.70,0,-1,13.71,0,-2,13.73,0,-3,13.74,0,-2,13.75,0,-3,13.76,0,-3,13.77,0,-4,13.78,0,-3,13.79,0,-2,ARL,0
2025-07-17T15:45:08.094768552Z,2025-07-17T15:45:08.094603115Z,10,2,1108,C,A,10,14.890000000,100,303330521,165437,254266885,13.31,10,1,13.28,11,2,13.14,1,1,13.13,100,1,13.11,100,1,13.10,100,1,13.04,2,1,12.99,100,1,12.73,100,1,12.67,100,1,13.40,0,-10,13.70,0,-1,13.71,0,-2,13.73,0,-3,13.74,0,-2,13.75,0,-3,13.76,0,-3,13.77,0,-4,13.78,0,-3,13.79,0,-2,ARL,0
2025-07-17T15:45:08.094768552Z,2025-07-17T15:45:08.094603115Z,10,2,1108,A,A,10,15.100000000,100,303349309,165437,254266885,13.31,10,1,13.28,11,2,13.14,1,1,13.13,100,1,13.11,100,1,13.10,100,1,13.04,2,1,12.99,100,1,12.73,100,1,12.67,100,1,13.40,0,-10,13.70,0,-1,13.71,0,-2,13.73,0,-3,13.74,0,-2,13.75,0,-3,13.76,0,-3,13.77,0,-4,13.78,0,-3,13.79,0,-2,ARL,0
2025-07-17T15:45:08.103306644Z,2025-07-17T15:45:08.103141155Z,10,2,1108,C,A,10,14.890000000,100,303330477,165489,254266971,13.31,10,1,13.28,11,2,13.14,1,1,13.13,100,1,13.11,100,1,13.10,100,1,13.04,2,1,12.99,100,1,12.73,100,1,12.67,100,1,13.40,0,-10,13.70,0,-1,13.71,0,-2,13.73,0,-3,13.74,0,-2,13.75,0,-3,13.76,0,-3,13.77,0,-4,13.78,0,-3,13.79,0,-2,ARL,0
2025-07-17T15:45:08.103306644Z,2025-07-17T15:45:08.103141155Z,10,2,1108,A,A,10,15.100000000,100,303349377,165489,254266971,13.31,10,1,13.28,11,2,13.14,1,1,13.13,100,1,13.11,100,1,13.10,100,1,13.04,2,1,12.99,100,1,12.73,100,1,12.67,100,1,13.40,0,-10,13.70,0,-1,13.71,0,-2,13.73,0,-3,13.74,0,-2,13.75,0,-3,13.76,0,-3,13.77,0,-4,13.78,0,-3,13.79,0,-2,ARL,0
2025-07-17T15:45:24.187008278Z,2025-07-17T15:45:24.186842413Z,10,2,1108,C,A,10,15.100000000,100,303349309,165865,254547413,13.31,10,1,13.28,11,2,13.14,1,1,13.13,100,1,13.11,100,1,13.10,100,1,13.04,2,1,12.99,100,1,12.73,100,1,12.67,100,1,13.40,0,-10,13.70,0,-1,13.71,0,-2,13.73,0,-3,13.74,0,-2,13.75,0,-3,13.76,0,-3,13.77,0,-4,13.78,0,-3,13.79,0,-2,ARL,0
2025-07-17T15:45:24.187008278Z,2025-07-17T15:45:24.186842413Z,10,2,1108,A,A,10,14.880000000,100,303682385,165865,254547413,13.31,10,1,13.28,11,2,13.14,1,1,13.13,100,1,13.11,100,1,13.10,100,1,13.04,2,1,12.99,100,1,12.73,100,1,12.67,100,1,13.40,0,-10,13.70,0,-1,13.71,0,-2,13.73,0,-3,13.74,0,-2,13.75,0,-3,13.76,0,-3,13.77,0,-4,13.78,0,-3,13.79,0,-2,ARL,0
2025-07-17T15:45:24.187441892Z,2025-07-17T15:45:24.187276389Z,10,2,1108,C,A,10,15.100000000,100,303349377,165503,254547415,13.31,10,1,13.28,11,2,13.14,1,1,13.13,100,1,13.11,100,1,13.10,100,1,13.04,2,1,12.99,100,1,12.73,100,1,12.67,100,1,13.40,0,-10,13.70,0,-1,13.71,0,-2,13.73,0,-3,13.74,0,-2,13.75,0,-3,13.76,0,-3,13.77,0,-4,13.78,0,-3,13.79,0,-2,ARL,0
2025-07-17T15:45:24.187441892Z,2025-07-17T15:45:24.187276389Z,10,2,1108,A,A,10,14.880000000,100,303682389,165503,254547415,13.31,10,1,13.28,11,2,13.14,1,1,13.13,100,1,13.11,100,1,13.10,100,1,13.04,2,1,12.99,100,1,12.73,100,1,12.67,100,1,13.40,0,-10,13.70,0,-1,13.71,0,-2,13.73,0,-3,13.74,0,-2,13.75,0,-3,13.76,0,-3,13.77,0,-4,13.78,0,-3,13.79,0,-2,ARL,0
2025-07-17T15:45:37.509454888Z,2025-07-17T15:45:37.509289536Z,10,2,1108,A,A,10,13.940000000,15,304056997,165352,254851462,13.31,10,1,13.28,11,2,13.14,1,1,13.13,100,1,13.11,100,1,13.10,100,1,13.04,2,1,12.99,100,1,12.73,100,1,12.67,100,1,13.40,0,-10,13.70,0,-1,13.71,0,-2,13.73,0,-3,13.74,0,-2,13.75,0,-3,13.76,0,-3,13.77,0,-4,13.78,0,-3,13.79,0,-2,ARL,0
2025-07-17T15:45:37.998133497Z,2025-07-17T15:45:37.997967775Z,10,2,1108,C,A,10,14.080000000,100,303340405,165722,254864588,13.31,10,1,13.28,11,2,13.14,1,1,13.13,100,1,13.11,100,1,13.10,100,1,13.04,2,1,12.99,100,1,12.73,100,1,12.67,100,1,13.40,0,-10,13.70,0,-1,13.71,0,-2,13.73,0,-3,13.74,0,-2,13.75,0,-3,13.76,0,-3,13.77,0,-4,13.78,0,-3,13.79,0,-2,ARL,0
2025-07-17T15:45:37.998133497Z,2025-07-17T15:45:37.997967775Z,10,2,1108,A,A,10,13.950000000,100,304072245,165722,254864588,13.31,10,1,13.28,11,2,13.14,1,1,13.13,100,1,13.11,100,1,13.10,100,1,13.04,2,1,12.99,100,1,12.73,100,1,12.67,100,1,13.40,0,-10,13.70,0,-1,13.71,0,-2,13.73,0,-3,13.74,0,-2,13.75,0,-3,13.76,0,-3,13.77,0,-4,13.78,0,-3,13.79,0,-2,ARL,0
2025-07-17T15:45:44.700593408Z,2025-07-17T15:45:44.700428155Z,10,2,1108,A,A,10,13.890000000,15,304238913,165253,254999429,13.31,10,1,13.28,11,2,13.14,1,1,13.13,100,1,13.11,100,1,13.10,100,1,13.04,2,1,12.99,100,1,12.73,100,1,12.67,100,1,13.40,0,-10,13.70,0,-1,13.71,0,-2,13.73,0,-3,13.74,0,-2,13.75,0,-3,13.76,0,-3,13.77,0,-4,13.78,0,-3,13.79,0,-2,ARL,0
2025-07-17T15:45:45.262537122Z,2025-07-17T15:45:45.262371701Z,10,2,1108,C,A,10,13.950000000,100,304072245,165421,255010979,13.31,10,1,13.28,11,2,13.14,1,1,13.13,100,1,13.11,100,1,13.10,100,1,13.04,2,1,12.99,100,1,12.73,100,1,12.67,100,1,13.40,0,-10,13.70,0,-1,13.71,0,-2,13.73,0,-3,13.74,0,-2,13.75,0,-3,13.76,0,-3,13.77,0,-4,13.78,0,-3,13.79,0,-2,ARL,0
2025-07-17T15:45:45.262537122Z,2025-07-17T15:45:45.262371701Z,10,2,1108,A,A,10,13.900000000,100,304252313,165421,255010979,13.31,10,1,13.28,11,2,13.14,1,1,13.13,100,1,13.11,100,1,13.10,100,1,13.04,2,1,12.99,100,1,12.73,100,1,12.67,100,1,13.40,0,-10,13.70,0,-1,13.71,0,-2,13.73,0,-3,13.74,0,-2,13.75,0,-3,13.76,0,-3,13.77,0,-4,13.78,0,-3,13.79,0,-2,ARL,0
2025-07-17T15:45:45.263289023Z,2025-07-17T15:45:45.263123432Z,10,2,1108,C,A,10,15.060000000,100,303330485,165591,255010987,13.31,10,1,13.28,11,2,13.14,1,1,13.13,100,1,13.11,100,1,13.10,100,1,13.04,2,1,12.99,100,1,12.73,100,1,12.67,100,1,13.40,0,-10,13.70,0,-1,13.71,0,-2,13.73,0,-3,13.74,0,-2,13.75,0,-3,13.76,0,-3,13.77,0,-4,13.78,0,-3,13.79,0,-2,ARL,0
2025-07-17T15:45:45.263289023Z,2025-07-17T15:45:45.263123432Z,10,2,1108,A,A,10,14.980000000,100,304252333,165591,255010987,13.31,10,1,13.28,11,2,13.14,1,1,13.13,100,1,13.11,100,1,13.10,100,1,13.04,2,1,12.99,100,1,12.73,100,1,12.67,100,1,13.40,0,-10,13.70,0,-1,13.71,0,-2,13.73,0,-3,13.74,0,-2,13.75,0,-3,13.76,0,-3,13.77,0,-4,13.78,0,-3,13.79,0,-2,ARL,0
2025-07-17T15:45:45.274360382Z,2025-07-17T15:45:45.274194870Z,10,2,1108,C,A,10,14.260000000,100,303331401,165512,255011158,13.31,10,1,13.28,11,2,13.14,1,1,13.13,100,1,13.11,100,1,13.10,100,1,13.04,2,1,12.99,100,1,12.73,100,1,12.67,100,1,13.40,0,-10,13.70,0,-1,13.71,0,-2,13.73,0,-3,13.74,0,-2,13.75,0,-3,13.76,0,-3,13.77,0,-4,13.78,0,-3,13.79,0,-2,ARL,0
2025-07-17T15:45:45.274410721Z,2025-07-17T15:45:45.274245387Z,10,2,1108,A,A,10,14.180000000,100,304252469,165334,255011161,13.31,10,1,13.28,11,2,13.14,1,1,13.13,100,1,13.11,100,1,13.10,100,1,13.04,2,1,12.99,100,1,12.73,100,1,12.67,100,1,13.40,0,-10,13.70,0,-1,13.71,0,-2,13.73,0,-3,13.74,0,-2,13.75,0,-3,13.76,0,-3,13.77,0,-4,13.78,0,-3,13.79,0,-2,ARL,0
2025-07-17T15:45:58.419783333Z,2025-07-17T15:45:58.419617935Z,10,2,1108,C,A,10,13.940000000,15,304056997,165398,255183198,13.31,10,1,13.28,11,2,13.14,1,1,13.13,100,1,13.11,100,1,13.10,100,1,13.04,2,1,12.99,100,1,12.73,100,1,12.67,100,1,13.40,0,-10,13.70,0,-1,13.71,0,-2,13.73,0,-3,13.74,0,-2,13.75,0,-3,13.76,0,-3,13.77,0,-4,13.78,0,-3,13.79,0,-2,ARL,0
2025-07-17T15:45:58.420278691Z,2025-07-17T15:45:58.420113307Z,10,2,1108,C,A,10,14.880000000,100,303682389,165384,255183203,13.31,10,1,13.28,11,2,13.14,1,1,13.13,100,1,13.11,100,1,13.10,100,1,13.04,2,1,12.99,100,1,12.73,100,1,12.67,100,1,13.40,0,-10,13.70,0,-1,13.71,0,-2,13.73,0,-3,13.74,0,-2,13.75,0,-3,13.76,0,-3,13.77,0,-4,13.78,0,-3,13.79,0,-2,ARL,0
2025-07-17T15:45:58.420278691Z,2025-07-17T15:45:58.420113307Z,10,2,1108,A,A,10,14.770000000,100,304503585,165384,255183203,13.31,10,1,13.28,11,2,13.14,1,1,13.13,100,1,13.11,100,1,13.10,100,1,13.04,2,1,12.99,100,1,12.73,100,1,12.67,100,1,13.40,0,-10,13.70,0,-1,13.71,0,-2,13.73,0,-3,13.74,0,-2,13.75,0,-3,13.76,0,-3,13.77,0,-4,13.78,0,-3,13.79,0,-2,ARL,0
2025-07-17T15:45:58.420755889Z,2025-07-17T15:45:58.420590199Z,10,2,1108,C,A,10,14.880000000,100,303682385,165690,255183204,13.31,10,1,13.28,11,2,13.14,1,1,13.13,100,1,13.11,100,1,13.10,100,1,13.04,2,1,12.99,100,1,12.73,100,1,12.67,100,1,13.40,0,-10,13.70,0,-1,13.71,0,-2,13.73,0,-3,13.74,0,-2,13.75,0,-3,13.76,0,-3,13.77,0,-4,13.78,0,-3,13.79,0,-2,ARL,0
2025-07-17T15:45:58.420755889Z,2025-07-17T15:45:58.420590199Z,10,2,1108,A,A,10,14.770000000,100,304503593,165690,255183204,13.31,10,1,13.28,11,2,13.14,1,1,13.13,100,1,13.11,100,1,13.10,100,1,13.04,2,1,12.99,100,1,12.73,100,1,12.67,100,1,13.40,0,-10,13.70,0,-1,13.71,0,-2,13.73,0,-3,13.74,0,-2,13.75,0,-3,13.76,0,-3,13.77,0,-4,13.78,0,-3,13.79,0,-2,ARL,0
2025-07-17T15:45:58.782892109Z,2025-07-17T15:45:58.782726994Z,10,2,1108,C,A,10,13.890000000,15,304238913,165115,255189425,13.31,10,1,13.28,11,2,13.14,1,1,13.13,100,1,13.11,100,1,13.10,100,1,13.04,2,1,12.99,100,1,12.73,100,1,12.67,100,1,13.40,0,-10,13.70,0,-1,13.71,0,-2,13.73,0,-3,13.74,0,-2,13.75,0,-3,13.76,0,-3,13.77,0,-4,13.78,0,-3,13.79,0,-2,ARL,0
2025-07-17T15:46:16.783057616Z,2025-07-17T15:46:16.782892334Z,10,2,1108,A,A,10,13.880000000,15,304949689,165282,255552962,13.31,10,1,13.28,11,2,13.14,1,1,13.13,100,1,13.11,100,1,13.10,100,1,13.04,2,1,12.99,100,1,12.73,100,1,12.67,100,1,13.40,0,-10,13.70,0,-1,13.71,0,-2,13.73,0,-3,13.74,0,-2,13.75,0,-3,13.76,0,-3,13.77,0,-4,13.78,0,-3,13.79,0,-2,ARL,0
2025-07-17T15:46:16.783326241Z,2025-07-17T15:46:16.783160795Z,10,2,1108,C,A,10,13.900000000,100,304252313,165446,255552970,13.31,10,1,13.28,11,2,13.14,1,1,13.13,100,1,13.11,100,1,13.10,100,1,13.04,2,1,12.99,100,1,12.73,100,1,12.67,100,1,13.40,0,-10,13.70,0,-1,13.71,0,-2,13.73,0,-3,13.74,0,-2,13.75,0,-3,13.76,0,-3,13.77,0,-4,13.78,0,-3,13.79,0,-2,ARL,0
2025-07-17T15:46:16.783326241Z,2025-07-17T15:46:16.783160795Z,10,2,1108,A,A,10,13.890000000,100,304949697,165446,255552970,13.31,10,1,13.28,11,2,13.14,1,1,13.13,100,1,13.11,100,1,13.10,100,1,13.04,2,1,12.99,100,1,12.73,100,1,12.67,100,1,13.40,0,-10,13.70,0,-1,13.71,0,-2,13.73,0,-3,13.74,0,-2,13.75,0,-3,13.76,0,-3,13.77,0,-4,13.78,0,-3,13.79,0,-2,ARL,0
2025-07-17T15:46:18.782897570Z,2025-07-17T15:46:18.782732218Z,10,2,1108,C,A,10,13.880000000,15,304949689,165352,255587336,13.31,10,1,13.28,11,2,13.14,1,1,13.13,100,1,13.11,100,1,13.10,100,1,13.04,2,1,12.99,100,1,12.73,100,1,12.67,100,1,13.40,0,-10,13.70,0,-1,13.71,0,-2,13.73,0,-3,13.74,0,-2,13.75,0,-3,13.76,0,-3,13.77,0,-4,13.78,0,-3,13.79,0,-2,ARL,0
2025-07-17T15:46:28.474166897Z,2025-07-17T15:46:28.474001551Z,10,2,1108,C,A,10,13.890000000,100,304949697,165346,255746167,13.31,10,1,13.28,11,2,13.14,1,1,13.13,100,1,13.11,100,1,13.10,100,1,13.04,2,1,12.99,100,1,12.73,100,1,12.67,100,1,13.40,0,-10,13.70,0,-1,13.71,0,-2,13.73,0,-3,13.74,0,-2,13.75,0,-3,13.76,0,-3,13.77,0,-4,13.78,0,-3,13.79,0,-2,ARL,0
2025-07-17T15:46:28.474726594Z,2025-07-17T15:46:28.474561156Z,10,2,1108,C,A,10,14.770000000,100,304503593,165438,255746173,13.31,10,1,13.28,11,2,13.14,1,1,13.13,100,1,13.11,100,1,13.10,100,1,13.04,2,1,12.99,100,1,12.73,100,1,12.67,100,1,13.40,0,-10,13.70,0,-1,13.71,0,-2,13.73,0,-3,13.74,0,-2,13.75,0,-3,13.76,0,-3,13.77,0,-4,13.78,0,-3,13.79,0,-2,ARL,0
2025-07-17T15:46:28.474726594Z,2025-07-17T15:46:28.474561156Z,10,2,1108,A,A,10,14.880000000,100,305184937,165438,255746173,13.31,10,1,13.28,11,2,13.14,1,1,13.13,100,1,13.11,100,1,13.10,100,1,13.04,2,1,12.99,100,1,12.73,100,1,12.67,100,1,13.40,0,-10,13.70,0,-1,13.71,0,-2,13.73,0,-3,13.74,0,-2,13.75,0,-3,13.76,0,-3,13.77,0,-4,13.78,0,-3,13.79,0,-2,ARL,0
2025-07-17T15:46:28.474896460Z,2025-07-17T15:46:28.474730225Z,10,2,1108,C,A,10,14.770000000,100,304503585,166235,255746176,13.31,10,1,13.28,11,2,13.14,1,1,13.13,100,1,13.11,100,1,13.10,100,1,13.04,2,1,12.99,100,1,12.73,100,1,12.67,100,1,13.40,0,-10,13.70,0,-1,13.71,0,-2,13.73,0,-3,13.74,0,-2,13.75,0,-3,13.76,0,-3,13.77,0,-4,13.78,0,-3,13.79,0,-2,ARL,0
2025-07-17T15:46:28.474896460Z,2025-07-17T15:46:28.474730225Z,10,2,1108,A,A,10,14.880000000,100,305184953,166235,255746176,13.31,10,1,13.28,11,2,13.14,1,1,13.13,100,1,13.11,100,1,13.10,100,1,13.04,2,1,12.99,100,1,12.73,100,1,12.67,100,1,13.40,0,-10,13.70,0,-1,13.71,0,-2,13.73,0,-3,13.74,0,-2,13.75,0,-3,13.76,0,-3,13.77,0,-4,13.78,0,-3,13.79,0,-2,ARL,0
2025-07-17T15:46:28.474902154Z,2025-07-17T15:46:28.474736101Z,10,2,1108,C,A,10,14.980000000,100,304252333,166053,255746178,13.31,10,1,13.28,11,2,13.14,1,1,13.13,100,1,13.11,100,1,13.10,100,1,13.04,2,1,12.99,100,1,12.73,100,1,12.67,100,1,13.40,0,-10,13.70,0,-1,13.71,0,-2,13.73,0,-3,13.74,0,-2,13.75,0,-3,13.76,0,-3,13.77,0,-4,13.78,0,-3,13.79,0,-2,ARL,0
2025-07-17T15:46:28.474902154Z,2025-07-17T15:46:28.474736101Z,10,2,1108,A,A,10,15.030000000,100,305184957,166053,255746178,13.31,10,1,13.28,11,2,13.14,1,1,13.13,100,1,13.11,100,1,13.10,100,1,13.04,2,1,12.99,100,1,12.73,100,1,12.67,100,1,13.40,0,-10,13.70,0,-1,13.71,0,-2,13.73,0,-3,13.74,0,-2,13.75,0,-3,13.76,0,-3,13.77,0,-4,13.78,0,-3,13.79,0,-2,ARL,0
2025-07-17T15:46:28.492881980Z,2025-07-17T15:46:28.492716775Z,10,2,1108,C,A,10,14.180000000,100,304252469,165205,255746619,13.31,10,1,13.28,11,2,13.14,1,1,13.13,100,1,13.11,100,1,13.10,100,1,13.04,2,1,12.99,100,1,12.73,100,1,12.67,100,1,13.40,0,-10,13.70,0,-1,13.71,0,-2,13.73,0,-3,13.74,0,-2,13.75,0,-3,13.76,0,-3,13.77,0,-4,13.78,0,-3,13.79,0,-2,ARL,0
2025-07-17T15:46:28.492931279Z,2025-07-17T15:46:28.492765859Z,10,2,1108,A,A,10,14.260000000,100,305185529,165420,255746621,13.31,10,1,13.28,11,2,13.14,1,1,13.13,100,1,13.11,100,1,13.10,100,1,13.04,2,1,12.99,100,1,12.73,100,1,12.67,100,1,13.40,0,-10,13.70,0,-1,13.71,0,-2,13.73,0,-3,13.74,0,-2,13.75,0,-3,13.76,0,-3,13.77,0,-4,13.78,0,-3,13.79,0,-2,ARL,0
2025-07-17T15:46:28.646273467Z,2025-07-17T15:46:28.646108242Z,10,2,1108,A,A,10,14.080000000,100,305187077,165225,255748568,13.31,10,1,13.28,11,2,13.14,1,1,13.13,100,1,13.11,100,1,13.10,100,1,13.04,2,1,12.99,100,1,12.73,100,1,12.67,100,1,13.40,0,-10,13.70,0,-1,13.71,0,-2,13.73,0,-3,13.74,0,-2,13.75,0,-3,13.76,0,-3,13.77,0,-4,13.78,0,-3,13.79,0,-2,ARL,0
2025-07-17T15:46:57.524024658Z,2025-07-17T15:46:57.523859388Z,10,2,1108,A,A,10,13.920000000,15,305862145,165270,256268482,13.31,10,1,13.28,11,2,13.14,1,1,13.13,100,1,13.11,100,1,13.10,100,1,13.04,2,1,12.99,100,1,12.73,100,1,12.67,100,1,13.40,0,-10,13.70,0,-1,13.71,0,-2,13.73,0,-3,13.74,0,-2,13.75,0,-3,13.76,0,-3,13.77,0,-4,13.78,0,-3,13.79,0,-2,ARL,0
2025-07-17T15:46:57.932842994Z,2025-07-17T15:46:57.932677299Z,10,2,1108,C,A,10,14.080000000,100,305187077,165695,256280751,13.31,10,1,13.28,11,2,13.14,1,1,13.13,100,1,13.11,100,1,13.10,100,1,13.04,2,1,12.99,100,1,12.73,100,1,12.67,100,1,13.40,0,-10,13.70,0,-1,13.71,0,-2,13.73,0,-3,13.74,0,-2,13.75,0,-3,13.76,0,-3,13.77,0,-4,13.78,0,-3,13.79,0,-2,ARL,0
2025-07-17T15:46:57.932842994Z,2025-07-17T15:46:57.932677299Z,10,2,1108,A,A,10,13.930000000,100,305878881,165695,256280751,13.31,10,1,13.28,11,2,13.14,1,1,13.13,100,1,13.11,100,1,13.10,100,1,13.04,2,1,12.99,100,1,12.73,100,1,12.67,100,1,13.40,0,-10,13.70,0,-1,13.71,0,-2,13.73,0,-3,13.74,0,-2,13.75,0,-3,13.76,0,-3,13.77,0,-4,13.78,0,-3,13.79,0,-2,ARL,0
2025-07-17T15:47:06.609456251Z,2025-07-17T15:47:06.609290857Z,10,2,1108,A,A,10,13.880000000,15,306121113,165394,256488374,13.31,10,1,13.28,11,2,13.14,1,1,13.13,100,1,13.11,100,1,13.10,100,1,13.04,2,1,12.99,100,1,12.73,100,1,12.67,100,1,13.40,0,-10,13.70,0,-1,13.71,0,-2,13.73,0,-3,13.74,0,-2,13.75,0,-3,13.76,0,-3,13.77,0,-4,13.78,0,-3,13.79,0,-2,ARL,0
2025-07-17T15:47:08.787695144Z,2025-07-17T15:47:08.787529505Z,10,2,1108,C,A,10,13.930000000,100,305878881,165639,256532991,13.31,10,1,13.28,11,2,13.14,1,1,13.13,100,1,13.11,100,1,13.10,100,1,13.04,2,1,12.99,100,1,12.73,100,1,12.67,100,1,13.40,0,-10,13.70,0,-1,13.71,0,-2,13.73,0,-3,13.74,0,-2,13.75,0,-3,13.76,0,-3,13.77,0,-4,13.78,0,-3,13.79,0,-2,ARL,0
2025-07-17T15:47:08.787695144Z,2025-07-17T15:47:08.787529505Z,10,2,1108,A,A,10,13.890000000,100,306170837,165639,256532991,13.31,10,1,13.28,11,2,13.14,1,1,13.13,100,1,13.11,100,1,13.10,100,1,13.04,2,1,12.99,100,1,12.73,100,1,12.67,100,1,13.40,0,-10,13.70,0,-1,13.71,0,-2,13.73,0,-3,13.74,0,-2,13.75,0,-3,13.76,0,-3,13.77,0,-4,13.78,0,-3,13.79,0,-2,ARL,0
2025-07-17T15:47:08.788440762Z,2025-07-17T15:47:08.788275184Z,10,2,1108,C,A,10,15.030000000,100,305184957,165578,256533005,13.31,10,1,13.28,11,2,13.14,1,1,13.13,100,1,13.11,100,1,13.10,100,1,13.04,2,1,12.99,100,1,12.73,100,1,12.67,100,1,13.40,0,-10,13.70,0,-1,13.71,0,-2,13.73,0,-3,13.74,0,-2,13.75,0,-3,13.76,0,-3,13.77,0,-4,13.78,0,-3,13.79,0,-2,ARL,0
2025-07-17T15:47:08.788440762Z,2025-07-17T15:47:08.788275184Z,10,2,1108,A,A,10,14.970000000,100,306170869,165578,256533005,13.31,10,1,13.28,11,2,13.14,1,1,13.13,100,1,13.11,100,1,13.10,100,1,13.04,2,1,12.99,100,1,12.73,100,1,12.67,100,1,13.40,0,-10,13.70,0,-1,13.71,0,-2,13.73,0,-3,13.74,0,-2,13.75,0,-3,13.76,0,-3,13.77,0,-4,13.78,0,-3,13.79,0,-2,ARL,0
2025-07-17T15:47:08.805983406Z,2025-07-17T15:47:08.805818249Z,10,2,1108,C,A,10,14.260000000,100,305185529,165157,256533442,13.31,10,1,13.28,11,2,13.14,1,1,13.13,100,1,13.11,100,1,13.10,100,1,13.04,2,1,12.99,100,1,12.73,100,1,12.67,100,1,13.40,0,-10,13.70,0,-1,13.71,0,-2,13.73,0,-3,13.74,0,-2,13.75,0,-3,13.76,0,-3,13.77,0,-4,13.78,0,-3,13.79,0,-2,ARL,0
2025-07-17T15:47:08.806033773Z,2025-07-17T15:47:08.805868059Z,10,2,1108,A,A,10,14.170000000,100,306171457,165714,256533443,13.31,10,1,13.28,11,2,13.14,1,1,13.13,100,1,13.11,100,1,13.10,100,1,13.04,2,1,12.99,100,1,12.73,100,1,12.67,100,1,13.40,0,-10,13.70,0,-1,13.71,0,-2,13.73,0,-3,13.74,0,-2,13.75,0,-3,13.76,0,-3,13.77,0,-4,13.78,0,-3,13.79,0,-2,ARL,0
2025-07-17T15:47:13.121454355Z,2025-07-17T15:47:13.121288953Z,10,2,1108,C,A,10,13.880000000,15,306121113,165402,256612694,13.31,10,1,13.28,11,2,13.14,1,1,13.13,100,1,13.11,100,1,13.10,100,1,13.04,2,1,12.99,100,1,12.73,100,1,12.67,100,1,13.40,0,-10,13.70,0,-1,13.71,0,-2,13.73,0,-3,13.74,0,-2,13.75,0,-3,13.76,0,-3,13.77,0,-4,13.78,0,-3,13.79,0,-2,ARL,0
2025-07-17T15:47:13.122562533Z,2025-07-17T15:47:13.122396816Z,10,2,1108,C,A,10,13.920000000,15,305862145,165717,256612757,13.31,10,1,13.28,11,2,13.14,1,1,13.13,100,1,13.11,100,1,13.10,100,1,13.04,2,1,12.99,100,1,12.73,100,1,12.67,100,1,13.40,0,-10,13.70,0,-1,13.71,0,-2,13.73,0,-3,13.74,0,-2,13.75,0,-3,13.76,0,-3,13.77,0,-4,13.78,0,-3,13.79,0,-2,ARL,0
2025-07-17T15:47:24.786476266Z,2025-07-17T15:47:24.786310694Z,10,2,1108,A,A,10,13.870000000,15,306519385,165572,256812416,13.31,10,1,13.28,11,2,13.14,1,1,13.13,100,1,13.11,100,1,13.10,100,1,13.04,2,1,12.99,100,1,12.73,100,1,12.67,100,1,13.40,0,-10,13.70,0,-1,13.71,0,-2,13.73,0,-3,13.74,0,-2,13.75,0,-3,13.76,0,-3,13.77,0,-4,13.78,0,-3,13.79,0,-2,ARL,0
2025-07-17T15:47:24.786745657Z,2025-07-17T15:47:24.786580061Z,10,2,1108,C,A,10,13.890000000,100,306170837,165596,256812420,13.31,10,1,13.28,11,2,13.14,1,1,13.13,100,1,13.11,100,1,13.10,100,1,13.04,2,1,12.99,100,1,12.73,100,1,12.67,100,1,13.40,0,-10,13.70,0,-1,13.71,0,-2,13.73,0,-3,13.74,0,-2,13.75,0,-3,13.76,0,-3,13.77,0,-4,13.78,0,-3,13.79,0,-2,ARL,0
2025-07-17T15:47:24.786745657Z,2025-07-17T15:47:24.786580061Z,10,2,1108,A,A,10,13.880000000,100,306519397,165596,256812420,13.31,10,1,13.28,11,2,13.14,1,1,13.13,100,1,13.11,100,1,13.10,100,1,13.04,2,1,12.99,100,1,12.73,100,1,12.67,100,1,13.40,0,-10,13.70,0,-1,13.71,0,-2,13.73,0,-3,13.74,0,-2,13.75,0,-3,13.76,0,-3,13.77,0,-4,13.78,0,-3,13.79,0,-2,ARL,0
2025-07-17T15:47:24.786925729Z,2025-07-17T15:47:24.786759805Z,10,2,1108,C,A,10,14.880000000,100,305184937,165924,256812422,13.31,10,1,13.28,11,2,13.14,1,1,13.13,100,1,13.11,100,1,13.10,100,1,13.04,2,1,12.99,100,1,12.73,100,1,12.67,100,1,13.40,0,-10,13.70,0,-1,13.71,0,-2,13.73,0,-3,13.74,0,-2,13.75,0,-3,13.76,0,-3,13.77,0,-4,13.78,0,-3,13.79,0,-2,ARL,0
2025-07-17T15:47:24.786925729Z,2025-07-17T15:47:24.786759805Z,10,2,1108,A,A,10,14.770000000,100,306519409,165924,256812422,13.31,10,1,13.28,11,2,13.14,1,1,13.13,100,1,13.11,100,1,13.10,100,1,13.04,2,1,12.99,100,1,12.73,100,1,12.67,100,1,13.40,0,-10,13.70,0,-1,13.71,0,-2,13.73,0,-3,13.74,0,-2,13.75,0,-3,13.76,0,-3,13.77,0,-4,13.78,0,-3,13.79,0,-2,ARL,0
2025-07-17T15:47:24.800616004Z,2025-07-17T15:47:24.800449950Z,10,2,1108,C,A,10,14.880000000,100,305184953,166054,256812578,13.31,10,1,13.28,11,2,13.14,1,1,13.13,100,1,13.11,100,1,13.10,100,1,13.04,2,1,12.99,100,1,12.73,100,1,12.67,100,1,13.40,0,-10,13.70,0,-1,13.71,0,-2,13.73,0,-3,13.74,0,-2,13.75,0,-3,13.76,0,-3,13.77,0,-4,13.78,0,-3,13.79,0,-2,ARL,0
2025-07-17T15:47:24.800616004Z,2025-07-17T15:47:24.800449950Z,10,2,1108,A,A,10,14.750000000,100,306519741,166054,256812578,13.31,10,1,13.28,11,2,13.14,1,1,13.13,100,1,13.11,100,1,13.10,100,1,13.04,2,1,12.99,100,1,12.73,100,1,12.67,100,1,13.40,0,-10,13.70,0,-1,13.71,0,-2,13.73,0,-3,13.74,0,-2,13.75,0,-3,13.76,0,-3,13.77,0,-4,13.78,0,-3,13.79,0,-2,ARL,0
2025-07-17T15:47:27.860272892Z,2025-07-17T15:47:27.860107552Z,10,2,1108,A,A,10,13.830000000,15,306587393,165340,256866835,13.31,10,1,13.28,11,2,13.14,1,1,13.13,100,1,13.11,100,1,13.10,100,1,13.04,2,1,12.99,100,1,12.73,100,1,12.67,100,1,13.40,0,-10,13.70,0,-1,13.71,0,-2,13.73,0,-3,13.74,0,-2,13.75,0,-3,13.76,0,-3,13.77,0,-4,13.78,0,-3,13.79,0,-2,ARL,0
2025-07-17T15:47:31.407029312Z,2025-07-17T15:47:31.406863918Z,10,2,1108,C,A,10,13.880000000,100,306519397,165394,256910124,13.31,10,1,13.28,11,2,13.14,1,1,13.13,100,1,13.11,100,1,13.10,100,1,13.04,2,1,12.99,100,1,12.73,100,1,12.67,100,1,13.40,0,-10,13.70,0,-1,13.71,0,-2,13.73,0,-3,13.74,0,-2,13.75,0,-3,13.76,0,-3,13.77,0,-4,13.78,0,-3,13.79,0,-2,ARL,0
2025-07-17T15:47:31.407029312Z,2025-07-17T15:47:31.406863918Z,10,2,1108,A,A,10,13.840000000,100,306647425,165394,256910124,13.31,10,1,13.28,11,2,13.14,1,1,13.13,100,1,13.11,100,1,13.10,100,1,13.04,2,1,12.99,100,1,12.73,100,1,12.67,100,1,13.40,0,-10,13.70,0,-1,13.71,0,-2,13.73,0,-3,13.74,0,-2,13.75,0,-3,13.76,0,-3,13.77,0,-4,13.78,0,-3,13.79,0,-2,ARL,0
2025-07-17T15:47:31.407771110Z,2025-07-17T15:47:31.407605685Z,10,2,1108,C,A,10,14.970000000,100,306170869,165425,256910129,13.31,10,1,13.28,11,2,13.14,1,1,13.13,100,1,13.11,100,1,13.10,100,1,13.04,2,1,12.99,100,1,12.73,100,1,12.67,100,1,13.40,0,-10,13.70,0,-1,13.71,0,-2,13.73,0,-3,13.74,0,-2,13.75,0,-3,13.76,0,-3,13.77,0,-4,13.78,0,-3,13.79,0,-2,ARL,0
2025-07-17T15:47:31.407771110Z,2025-07-17T15:47:31.407605685Z,10,2,1108,A,A,10,14.910000000,100,306647445,165425,256910129,13.31,10,1,13.28,11,2,13.14,1,1,13.13,100,1,13.11,100,1,13.10,100,1,13.04,2,1,12.99,100,1,12.73,100,1,12.67,100,1,13.40,0,-10,13.70,0,-1,13.71,0,-2,13.73,0,-3,13.74,0,-2,13.75,0,-3,13.76,0,-3,13.77,0,-4,13.78,0,-3,13.79,0,-2,ARL,0
2025-07-17T15:47:31.413491477Z,2025-07-17T15:47:31.413325908Z,10,2,1108,C,A,10,14.780000000,100,303331425,165569,256910184,13.31,10,1,13.28,11,2,13.14,1,1,13.13,100,1,13.11,100,1,13.10,100,1,13.04,2,1,12.99,100,1,12.73,100,1,12.67,100,1,13.40,0,-10,13.70,0,-1,13.71,0,-2,13.73,0,-3,13.74,0,-2,13.75,0,-3,13.76,0,-3,13.77,0,-4,13.78,0,-3,13.79,0,-2,ARL,0
2025-07-17T15:47:31.413491477Z,2025-07-17T15:47:31.413325908Z,10,2,1108,A,A,10,14.640000000,100,306647521,165569,256910184,13.31,10,1,13.28,11,2,13.14,1,1,13.13,100,1,13.11,100,1,13.10,100,1,13.04,2,1,12.99,100,1,12.73,100,1,12.67,100,1,13.40,0,-10,13.70,0,-1,13.71,0,-2,13.73,0,-3,13.74,0,-2,13.75,0,-3,13.76,0,-3,13.77,0,-4,13.78,0,-3,13.79,0,-2,ARL,0
2025-07-17T15:47:31.433486283Z,2025-07-17T15:47:31.433320466Z,10,2,1108,C,A,10,14.960000000,100,303330509,165817,256910721,13.31,10,1,13.28,11,2,13.14,1,1,13.13,100,1,13.11,100,1,13.10,100,1,13.04,2,1,12.99,100,1,12.73,100,1,12.67,100,1,13.40,0,-10,13.70,0,-1,13.71,0,-2,13.73,0,-3,13.74,0,-2,13.75,0,-3,13.76,0,-3,13.77,0,-4,13.78,0,-3,13.79,0,-2,ARL,0
2025-07-17T15:47:31.433486283Z,2025-07-17T15:47:31.433320466Z,10,2,1108,A,A,10,14.810000000,100,306649913,165817,256910721,13.31,10,1,13.28,11,2,13.14,1,1,13.13,100,1,13.11,100,1,13.10,100,1,13.04,2,1,12.99,100,1,12.73,100,1,12.67,100,1,13.40,0,-10,13.70,0,-1,13.71,0,-2,13.73,0,-3,13.74,0,-2,13.75,0,-3,13.76,0,-3,13.77,0,-4,13.78,0,-3,13.79,0,-2,ARL,0
2025-07-17T15:47:31.574128504Z,2025-07-17T15:47:31.573963059Z,10,2,1108,C,A,10,16.080000000,100,303331429,165445,256912087,13.31,10,1,13.28,11,2,13.14,1,1,13.13,100,1,13.11,100,1,13.10,100,1,13.04,2,1,12.99,100,1,12.73,100,1,12.67,100,1,13.40,0,-10,13.70,0,-1,13.71,0,-2,13.73,0,-3,13.74,0,-2,13.75,0,-3,13.76,0,-3,13.77,0,-4,13.78,0,-3,13.79,0,-2,ARL,0
2025-07-17T15:47:31.574128504Z,2025-07-17T15:47:31.573963059Z,10,2,1108,A,A,10,15.920000000,100,306652001,165445,256912087,13.31,10,1,13.28,11,2,13.14,1,1,13.13,100,1,13.11,100,1,13.10,100,1,13.04,2,1,12.99,100,1,12.73,100,1,12.67,100,1,13.40,0,-10,13.70,0,-1,13.71,0,-2,13.73,0,-3,13.74,0,-2,13.75,0,-3,13.76,0,-3,13.77,0,-4,13.78,0,-3,13.79,0,-2,ARL,0
2025-07-17T15:47:31.575374481Z,2025-07-17T15:47:31.575209032Z,10,2,1108,C,A,10,17.760000000,100,303331309,165449,256912094,13.31,10,1,13.28,11,2,13.14,1,1,13.13,100,1,13.11,100,1,13.10,100,1,13.04,2,1,12.99,100,1,12.73,100,1,12.67,100,1,13.40,0,-10,13.70,0,-1,13.71,0,-2,13.73,0,-3,13.74,0,-2,13.75,0,-3,13.76,0,-3,13.77,0,-4,13.78,0,-3,13.79,0,-2,ARL,0
2025-07-17T15:47:31.575374481Z,2025-07-17T15:47:31.575209032Z,10,2,1108,A,A,10,17.580000000,100,306652017,165449,256912094,13.31,10,1,13.28,11,2,13.14,1,1,13.13,100,1,13.11,100,1,13.10,100,1,13.04,2,1,12.99,100,1,12.73,100,1,12.67,100,1,13.40,0,-10,13.70,0,-1,13.71,0,-2,13.73,0,-3,13.74,0,-2,13.75,0,-3,13.76,0,-3,13.77,0,-4,13.78,0,-3,13.79,0,-2,ARL,0
2025-07-17T15:47:31.740095714Z,2025-07-17T15:47:31.739930142Z,10,2,1108,C,A,10,14.960000000,100,303334253,165572,256914067,13.31,10,1,13.28,11,2,13.14,1,1,13.13,100,1,13.11,100,1,13.10,100,1,13.04,2,1,12.99,100,1,12.73,100,1,12.67,100,1,13.40,0,-10,13.70,0,-1,13.71,0,-2,13.73,0,-3,13.74,0,-2,13.75,0,-3,13.76,0,-3,13.77,0,-4,13.78,0,-3,13.79,0,-2,ARL,0
2025-07-17T15:47:31.740095714Z,2025-07-17T15:47:31.739930142Z,10,2,1108,A,A,10,14.810000000,100,306653713,165572,256914067,13.31,10,1,13.28,11,2,13.14,1,1,13.13,100,1,13.11,100,1,13.10,100,1,13.04,2,1,12.99,100,1,12.73,100,1,12.67,100,1,13.40,0,-10,13.70,0,-1,13.71,0,-2,13.73,0,-3,13.74,0,-2,13.75,0,-3,13.76,0,-3,13.77,0,-4,13.78,0,-3,13.79,0,-2,ARL,0
2025-07-17T15:47:37.159589804Z,2025-07-17T15:47:37.159424166Z,10,2,1108,C,A,10,13.870000000,15,306519385,165638,256983942,13.31,10,1,13.28,11,2,13.14,1,1,13.13,100,1,13.11,100,1,13.10,100,1,13.04,2,1,12.99,100,1,12.73,100,1,12.67,100,1,13.40,0,-10,13.70,0,-1,13.71,0,-2,13.73,0,-3,13.74,0,-2,13.75,0,-3,13.76,0,-3,13.77,0,-4,13.78,0,-3,13.79,0,-2,ARL,0
2025-07-17T15:47:37.172000440Z,2025-07-17T15:47:37.171834941Z,10,2,1108,A,A,10,13.850000000,100,306749753,165499,256984053,13.31,10,1,13.28,11,2,13.14,1,1,13.13,100,1,13.11,100,1,13.10,100,1,13.04,2,1,12.99,100,1,12.73,100,1,12.67,100,1,13.40,0,-10,13.70,0,-1,13.71,0,-2,13.73,0,-3,13.74,0,-2,13.75,0,-3,13.76,0,-3,13.77,0,-4,13.78,0,-3,13.79,0,-2,ARL,0
2025-07-17T15:47:38.161181283Z,2025-07-17T15:47:38.161015969Z,10,2,1108,A,A,10,13.790000000,15,306770041,165314,256998606,13.31,10,1,13.28,11,2,13.14,1,1,13.13,100,1,13.11,100,1,13.10,100,1,13.04,2,1,12.99,100,1,12.73,100,1,12.67,100,1,13.40,0,-10,13.70,0,-1,13.71,0,-2,13.73,0,-3,13.74,0,-2,13.75,0,-3,13.76,0,-3,13.77,0,-4,13.78,0,-3,13.79,0,-2,ARL,0
2025-07-17T15:47:38.794962245Z,2025-07-17T15:47:38.794795887Z,10,2,1108,C,A,10,13.840000000,100,306647425,166358,257010989,13.31,10,1,13.28,11,2,13.14,1,1,13.13,100,1,13.11,100,1,13.10,100,1,13.04,2,1,12.99,100,1,12.73,100,1,12.67,100,1,13.40,0,-10,13.70,0,-1,13.71,0,-2,13.73,0,-3,13.74,0,-2,13.75,0,-3,13.76,0,-3,13.77,0,-4,13.78,0,-3,13.79,0,-3,ARL,0
2025-07-17T15:47:38.794962245Z,2025-07-17T15:47:38.794795887Z,10,2,1108,A,A,10,13.800000000,100,306784133,166358,257010989,13.31,10,1,13.28,11,2,13.14,1,1,13.13,100,1,13.11,100,1,13.10,100,1,13.04,2,1,12.99,100,1,12.73,100,1,12.67,100,1,13.40,0,-10,13.70,0,-1,13.71,0,-2,13.73,0,-3,13.74,0,-2,13.75,0,-3,13.76,0,-3,13.77,0,-4,13.78,0,-3,13.79,0,-3,ARL,0
2025-07-17T15:47:38.795723570Z,2025-07-17T15:47:38.795557785Z,10,2,1108,C,A,10,14.910000000,100,306647445,165785,257011058,13.31,10,1,13.28,11,2,13.14,1,1,13.13,100,1,13.11,100,1,13.10,100,1,13.04,2,1,12.99,100,1,12.73,100,1,12.67,100,1,13.40,0,-10,13.70,0,-1,13.71,0,-2,13.73,0,-3,13.74,0,-2,13.75,0,-3,13.76,0,-3,13.77,0,-4,13.78,0,-3,13.79,0,-3,ARL,0
2025-07-17T15:47:38.795723570Z,2025-07-17T15:47:38.795557785Z,10,2,1108,A,A,10,14.870000000,100,306784201,165785,257011058,13.31,10,1,13.28,11,2,13.14,1,1,13.13,100,1,13.11,100,1,13.10,100,1,13.04,2,1,12.99,100,1,12.73,100,1,12.67,100,1,13.40,0,-10,13.70,0,-1,13.71,0,-2,13.73,0,-3,13.74,0,-2,13.75,0,-3,13.76,0,-3,13.77,0,-4,13.78,0,-3,13.79,0,-3,ARL,0
2025-07-17T15:47:38.804624258Z,2025-07-17T15:47:38.804458744Z,10,2,1108,C,A,10,14.170000000,100,306171457,165514,257011716,13.31,10,1,13.28,11,2,13.14,1,1,13.13,100,1,13.11,100,1,13.10,100,1,13.04,2,1,12.99,100,1,12.73,100,1,12.67,100,1,13.40,0,-10,13.70,0,-1,13.71,0,-2,13.73,0,-3,13.74,0,-2,13.75,0,-3,13.76,0,-3,13.77,0,-4,13.78,0,-3,13.79,0,-3,ARL,0
2025-07-17T15:47:38.804679592Z,2025-07-17T15:47:38.804513793Z,10,2,1108,A,A,10,14.080000000,100,306784853,165799,257011717,13.31,10,1,13.28,11,2,13.14,1,1,13.13,100,1,13.11,100,1,13.10,100,1,13.04,2,1,12.99,100,1,12.73,100,1,12.67,100,1,13.40,0,-10,13.70,0,-1,13.71,0,-2,13.73,0,-3,13.74,0,-2,13.75,0,-3,13.76,0,-3,13.77,0,-4,13.78,0,-3,13.79,0,-3,ARL,0
2025-07-17T15:47:39.092472059Z,2025-07-17T15:47:39.092305947Z,10,2,1108,C,A,10,13.790000000,15,306770041,166112,257018687,13.31,10,1,13.28,11,2,13.14,1,1,13.13,100,1,13.11,100,1,13.10,100,1,13.04,2,1,12.99,100,1,12.73,100,1,12.67,100,1,13.40,0,-10,13.70,0,-1,13.71,0,-2,13.73,0,-3,13.74,0,-2,13.75,0,-3,13.76,0,-3,13.77,0,-4,13.78,0,-3,13.79,0,-3,ARL,0
2025-07-17T15:47:39.095920859Z,2025-07-17T15:47:39.095755335Z,10,2,1108,C,A,10,13.830000000,15,306587393,165524,257018796,13.31,10,1,13.28,11,2,13.14,1,1,13.13,100,1,13.11,100,1,13.10,100,1,13.04,2,1,12.99,100,1,12.73,100,1,12.67,100,1,13.40,0,-10,13.70,0,-1,13.71,0,-2,13.73,0,-3,13.74,0,-2,13.75,0,-3,13.76,0,-3,13.77,0,-4,13.78,0,-3,13.79,0,-3,ARL,0
2025-07-17T15:48:08.909366905Z,2025-07-17T15:48:08.909201576Z,10,2,1108,A,A,10,13.830000000,100,307567929,165329,257603755,13.31,10,1,13.28,11,2,13.14,1,1,13.13,100,1,13.11,100,1,13.10,100,1,13.04,2,1,12.99,100,1,12.73,100,1,12.67,100,1,13.40,0,-10,13.70,0,-1,13.71,0,-2,13.73,0,-3,13.74,0,-2,13.75,0,-3,13.76,0,-3,13.77,0,-4,13.78,0,-3,13.79,0,-3,ARL,0
2025-07-17T15:48:08.916721098Z,2025-07-17T15:48:08.916555821Z,10,2,1108,C,A,10,13.850000000,100,306749753,165277,257604057,13.31,10,1,13.28,11,2,13.14,1,1,13.13,100,1,13.11,100,1,13.10,100,1,13.04,2,1,12.99,100,1,12.73,100,1,12.67,100,1,13.40,0,-10,13.70,0,-1,13.71,0,-2,13.73,0,-3,13.74,0,-2,13.75,0,-3,13.76,0,-3,13.77,0,-4,13.78,0,-3,13.79,0,-3,ARL,0
2025-07-17T15:48:09.653473465Z,2025-07-17T15:48:09.653308042Z,10,2,1108,A,A,10,13.780000000,15,307587873,165423,257621095,13.31,10,1,13.28,11,2,13.14,1,1,13.13,100,1,13.11,100,1,13.10,100,1,13.04,2,1,12.99,100,1,12.73,100,1,12.67,100,1,13.40,0,-10,13.70,0,-1,13.71,0,-2,13.73,0,-3,13.74,0,-2,13.75,0,-3,13.76,0,-3,13.77,0,-4,13.78,0,-3,13.79,0,-3,ARL,0
2025-07-17T15:48:11.166689254Z,2025-07-17T15:48:11.166517494Z,10,2,1108,C,A,10,13.780000000,15,307587873,171760,257644020,13.31,10,1,13.28,11,2,13.14,1,1,13.13,100,1,13.11,100,1,13.10,100,1,13.04,2,1,12.99,100,1,12.73,100,1,12.67,100,1,13.40,0,-10,13.70,0,-1,13.71,0,-2,13.73,0,-3,13.74,0,-2,13.75,0,-3,13.76,0,-3,13.77,0,-4,13.78,0,-4,13.79,0,-3,ARL,0
2025-07-17T15:48:13.509078553Z,2025-07-17T15:48:13.508913083Z,10,2,1108,A,A,10,13.780000000,15,307714769,165470,257727039,13.31,10,1,13.28,11,2,13.14,1,1,13.13,100,1,13.11,100,1,13.10,100,1,13.04,2,1,12.99,100,1,12.73,100,1,12.67,100,1,13.40,0,-10,13.70,0,-1,13.71,0,-2,13.73,0,-3,13.74,0,-2,13.75,0,-3,13.76,0,-3,13.77,0,-4,13.78,0,-4,13.79,0,-3,ARL,0
2025-07-17T15:48:13.525953545Z,2025-07-17T15:48:13.525788139Z,10,2,1108,A,A,10,13.810000000,100,307715101,165406,257727301,13.31,10,1,13.28,11,2,13.14,1,1,13.13,100,1,13.11,100,1,13.10,100,1,13.04,2,1,12.99,100,1,12.73,100,1,12.67,100,1,13.40,0,-10,13.70,0,-1,13.71,0,-2,13.73,0,-3,13.74,0,-2,13.75,0,-3,13.76,0,-3,13.77,0,-4,13.78,0,-4,13.79,0,-3,ARL,0
2025-07-17T15:48:13.532608874Z,2025-07-17T15:48:13.532443045Z,10,2,1108,C,A,10,13.830000000,100,307567929,165829,257727457,13.31,10,1,13.28,11,2,13.14,1,1,13.13,100,1,13.11,100,1,13.10,100,1,13.04,2,1,12.99,100,1,12.73,100,1,12.67,100,1,13.40,0,-10,13.70,0,-1,13.71,0,-2,13.73,0,-3,13.74,0,-2,13.75,0,-3,13.76,0,-3,13.77,0,-4,13.78,0,-4,13.79,0,-3,ARL,0
2025-07-17T15:48:15.568544154Z,2025-07-17T15:48:15.568378275Z,10,2,1108,C,A,10,13.800000000,100,306784133,165879,257757458,13.31,10,1,13.28,11,2,13.14,1,1,13.13,100,1,13.11,100,1,13.10,100,1,13.04,2,1,12.99,100,1,12.73,100,1,12.67,100,1,13.40,0,-10,13.70,0,-1,13.71,0,-2,13.73,0,-3,13.74,0,-2,13.75,0,-3,13.76,0,-3,13.77,0,-4,13.78,0,-4,13.79,0,-3,ARL,0
2025-07-17T15:48:15.568544154Z,2025-07-17T15:48:15.568378275Z,10,2,1108,A,A,10,13.790000000,100,307753241,165879,257757458,13.31,10,1,13.28,11,2,13.14,1,1,13.13,100,1,13.11,100,1,13.10,100,1,13.04,2,1,12.99,100,1,12.73,100,1,12.67,100,1,13.40,0,-10,13.70,0,-1,13.71,0,-2,13.73,0,-3,13.74,0,-2,13.75,0,-3,13.76,0,-3,13.77,0,-4,13.78,0,-4,13.79,0,-3,ARL,0
2025-07-17T15:48:24.009355346Z,2025-07-17T15:48:24.009190157Z,10,2,1108,A,A,10,13.750000000,15,307964605,165189,257928318,13.31,10,1,13.28,11,2,13.14,1,1,13.13,100,1,13.11,100,1,13.10,100,1,13.04,2,1,12.99,100,1,12.73,100,1,12.67,100,1,13.40,0,-10,13.70,0,-1,13.71,0,-2,13.73,0,-3,13.74,0,-2,13.75,0,-3,13.76,0,-3,13.77,0,-4,13.78,0,-4,13.79,0,-3,ARL,0
2025-07-17T15:48:24.009522633Z,2025-07-17T15:48:24.009357442Z,10,2,1108,A,A,10,13.790000000,100,307964609,165191,257928319,13.31,10,1,13.28,11,2,13.14,1,1,13.13,100,1,13.11,100,1,13.10,100,1,13.04,2,1,12.99,100,1,12.73,100,1,12.67,100,1,13.40,0,-10,13.70,0,-1,13.71,0,-2,13.73,0,-3,13.74,0,-2,13.75,0,-3,13.76,0,-3,13.77,0,-4,13.78,0,-4,13.79,0,-3,ARL,0
2025-07-17T15:48:24.009944381Z,2025-07-17T15:48:24.009778967Z,10,2,1108,C,A,10,13.790000000,100,307753241,165414,257928325,13.31,10,1,13.28,11,2,13.14,1,1,13.13,100,1,13.11,100,1,13.10,100,1,13.04,2,1,12.99,100,1,12.73,100,1,12.67,100,1,13.40,0,-10,13.70,0,-1,13.71,0,-2,13.73,0,-3,13.74,0,-2,13.75,0,-3,13.76,0,-3,13.77,0,-4,13.78,0,-4,13.79,0,-4,ARL,0
2025-07-17T15:48:24.009944381Z,2025-07-17T15:48:24.009778967Z,10,2,1108,A,A,10,13.760000000,100,307964621,165414,257928325,13.31,10,1,13.28,11,2,13.14,1,1,13.13,100,1,13.11,100,1,13.10,100,1,13.04,2,1,12.99,100,1,12.73,100,1,12.67,100,1,13.40,0,-10,13.70,0,-1,13.71,0,-2,13.73,0,-3,13.74,0,-2,13.75,0,-3,13.76,0,-3,13.77,0,-4,13.78,0,-4,13.79,0,-4,ARL,0
2025-07-17T15:48:24.009974166Z,2025-07-17T15:48:24.009808793Z,10,2,1108,C,A,10,13.810000000,100,307715101,165373,257928326,13.31,10,1,13.28,11,2,13.14,1,1,13.13,100,1,13.11,100,1,13.10,100,1,13.04,2,1,12.99,100,1,12.73,100,1,12.67,100,1,13.40,0,-10,13.70,0,-1,13.71,0,-2,13.73,0,-3,13.74,0,-2,13.75,0,-3,13.76,0,-4,13.77,0,-4,13.78,0,-4,13.79,0,-4,ARL,0
2025-07-17T15:48:24.010555416Z,2025-07-17T15:48:24.010390029Z,10,2,1108,C,A,10,14.770000000,100,306519409,165387,257928333,13.31,10,1,13.28,11,2,13.14,1,1,13.13,100,1,13.11,100,1,13.10,100,1,13.04,2,1,12.99,100,1,12.73,100,1,12.67,100,1,13.40,0,-10,13.70,0,-1,13.71,0,-2,13.73,0,-3,13.74,0,-2,13.75,0,-3,13.76,0,-4,13.77,0,-4,13.78,0,-4,13.79,0,-4,ARL,0
2025-07-17T15:48:24.010555416Z,2025-07-17T15:48:24.010390029Z,10,2,1108,A,A,10,14.650000000,100,307964661,165387,257928333,13.31,10,1,13.28,11,2,13.14,1,1,13.13,100,1,13.11,100,1,13.10,100,1,13.04,2,1,12.99,100,1,12.73,100,1,12.67,100,1,13.40,0,-10,13.70,0,-1,13.71,0,-2,13.73,0,-3,13.74,0,-2,13.75,0,-3,13.76,0,-4,13.77,0,-4,13.78,0,-4,13.79,0,-4,ARL,0
2025-07-17T15:48:24.010677522Z,2025-07-17T15:48:24.010512050Z,10,2,1108,C,A,10,14.870000000,100,306784201,165472,257928340,13.31,10,1,13.28,11,2,13.14,1,1,13.13,100,1,13.11,100,1,13.10,100,1,13.04,2,1,12.99,100,1,12.73,100,1,12.67,100,1,13.40,0,-10,13.70,0,-1,13.71,0,-2,13.73,0,-3,13.74,0,-2,13.75,0,-3,13.76,0,-4,13.77,0,-4,13.78,0,-4,13.79,0,-4,ARL,0
2025-07-17T15:48:24.010677522Z,2025-07-17T15:48:24.010512050Z,10,2,1108,A,A,10,14.830000000,100,307964665,165472,257928340,13.31,10,1,13.28,11,2,13.14,1,1,13.13,100,1,13.11,100,1,13.10,100,1,13.04,2,1,12.99,100,1,12.73,100,1,12.67,100,1,13.40,0,-10,13.70,0,-1,13.71,0,-2,13.73,0,-3,13.74,0,-2,13.75,0,-3,13.76,0,-4,13.77,0,-4,13.78,0,-4,13.79,0,-4,ARL,0
2025-07-17T15:48:42.009954046Z,2025-07-17T15:48:42.009788565Z,10,2,1108,C,A,10,13.780000000,15,307714769,165481,258199397,13.31,10,1,13.28,11,2,13.14,1,1,13.13,100,1,13.11,100,1,13.10,100,1,13.04,2,1,12.99,100,1,12.73,100,1,12.67,100,1,13.40,0,-10,13.70,0,-1,13.71,0,-2,13.73,0,-3,13.74,0,-2,13.75,0,-3,13.76,0,-4,13.77,0,-4,13.78,0,-4,13.79,0,-4,ARL,0
2025-07-17T15:48:42.011846392Z,2025-07-17T15:48:42.011680742Z,10,2,1108,C,A,10,14.750000000,100,306519741,165650,258199535,13.31,10,1,13.28,11,2,13.14,1,1,13.13,100,1,13.11,100,1,13.10,100,1,13.04,2,1,12.99,100,1,12.73,100,1,12.67,100,1,13.40,0,-10,13.70,0,-1,13.71,0,-2,13.73,0,-3,13.74,0,-2,13.75,0,-3,13.76,0,-4,13.77,0,-4,13.78,0,-4,13.79,0,-4,ARL,0
2025-07-17T15:48:42.011846392Z,2025-07-17T15:48:42.011680742Z,10,2,1108,A,A,10,14.640000000,100,308296381,165650,258199535,13.31,10,1,13.28,11,2,13.14,1,1,13.13,100,1,13.11,100,1,13.10,100,1,13.04,2,1,12.99,100,1,12.73,100,1,12.67,100,1,13.40,0,-10,13.70,0,-1,13.71,0,-2,13.73,0,-3,13.74,0,-2,13.75,0,-3,13.76,0,-4,13.77,0,-4,13.78,0,-4,13.79,0,-4,ARL,0
2025-07-17T15:48:42.016761374Z,2025-07-17T15:48:42.016595806Z,10,2,1108,A,A,10,13.770000000,100,308296741,165568,258199787,13.31,10,1,13.28,11,2,13.14,1,1,13.13,100,1,13.11,100,1,13.10,100,1,13.04,2,1,12.99,100,1,12.73,100,1,12.67,100,1,13.40,0,-10,13.70,0,-1,13.71,0,-2,13.73,0,-3,13.74,0,-2,13.75,0,-3,13.76,0,-4,13.77,0,-4,13.78,0,-4,13.79,0,-4,ARL,0
2025-07-17T15:48:42.023432407Z,2025-07-17T15:48:42.023266760Z,10,2,1108,C,A,10,13.790000000,100,307964609,165647,258199990,13.31,10,1,13.28,11,2,13.14,1,1,13.13,100,1,13.11,100,1,13.10,100,1,13.04,2,1,12.99,100,1,12.73,100,1,12.67,100,1,13.40,0,-10,13.70,0,-1,13.71,0,-2,13.73,0,-3,13.74,0,-2,13.75,0,-3,13.76,0,-4,13.77,0,-5,13.78,0,-4,13.79,0,-4,ARL,0
2025-07-17T15:48:46.750088490Z,2025-07-17T15:48:46.749922127Z,10,2,1108,A,A,10,13.730000000,15,308374537,166363,258260871,13.31,10,1,13.28,11,2,13.14,1,1,13.13,100,1,13.11,100,1,13.10,100,1,13.04,2,1,12.99,100,1,12.73,100,1,12.67,100,1,13.40,0,-10,13.70,0,-1,13.71,0,-2,13.73,0,-3,13.74,0,-2,13.75,0,-3,13.76,0,-4,13.77,0,-5,13.78,0,-4,13.79,0,-4,ARL,0
2025-07-17T15:48:46.758551033Z,2025-07-17T15:48:46.758385367Z,10,2,1108,C,A,10,13.760000000,100,307964621,165666,258261154,13.31,10,1,13.28,11,2,13.14,1,1,13.13,100,1,13.11,100,1,13.10,100,1,13.04,2,1,12.99,100,1,12.73,100,1,12.67,100,1,13.40,0,-10,13.70,0,-1,13.71,0,-2,13.73,0,-4,13.74,0,-2,13.75,0,-3,13.76,0,-4,13.77,0,-5,13.78,0,-4,13.79,0,-4,ARL,0
2025-07-17T15:48:46.758551033Z,2025-07-17T15:48:46.758385367Z,10,2,1108,A,A,10,13.740000000,100,308374881,165666,258261154,13.31,10,1,13.28,11,2,13.14,1,1,13.13,100,1,13.11,100,1,13.10,100,1,13.04,2,1,12.99,100,1,12.73,100,1,12.67,100,1,13.40,0,-10,13.70,0,-1,13.71,0,-2,13.73,0,-4,13.74,0,-2,13.75,0,-3,13.76,0,-4,13.77,0,-5,13.78,0,-4,13.79,0,-4,ARL,0
2025-07-17T15:48:46.773668988Z,2025-07-17T15:48:46.773503306Z,10,2,1108,C,A,10,14.080000000,100,306784853,165682,258261538,13.31,10,1,13.28,11,2,13.14,1,1,13.13,100,1,13.11,100,1,13.10,100,1,13.04,2,1,12.99,100,1,12.73,100,1,12.67,100,1,13.40,0,-10,13.70,0,-1,13.71,0,-2,13.73,0,-4,13.74,0,-3,13.75,0,-3,13.76,0,-4,13.77,0,-5,13.78,0,-4,13.79,0,-4,ARL,0
2025-07-17T15:48:46.773720726Z,2025-07-17T15:48:46.773555566Z,10,2,1108,A,A,10,14.010000000,100,308375185,165160,258261539,13.31,10,1,13.28,11,2,13.14,1,1,13.13,100,1,13.11,100,1,13.10,100,1,13.04,2,1,12.99,100,1,12.73,100,1,12.67,100,1,13.40,0,-10,13.70,0,-1,13.71,0,-2,13.73,0,-4,13.74,0,-3,13.75,0,-3,13.76,0,-4,13.77,0,-5,13.78,0,-4,13.79,0,-4,ARL,0
2025-07-17T15:49:02.010494480Z,2025-07-17T15:49:02.010329052Z,10,2,1108,A,A,10,13.750000000,100,308705489,165428,258502869,13.31,10,1,13.28,11,2,13.14,1,1,13.13,100,1,13.11,100,1,13.10,100,1,13.04,2,1,12.99,100,1,12.73,100,1,12.67,100,1,13.40,0,-10,13.70,0,-1,13.71,0,-2,13.73,0,-4,13.74,0,-3,13.75,0,-3,13.76,0,-4,13.77,0,-5,13.78,0,-4,13.79,0,-4,ARL,0
2025-07-17T15:49:02.019989567Z,2025-07-17T15:49:02.019824230Z,10,2,1108,C,A,10,13.770000000,100,308296741,165337,258502929,13.31,10,1,13.28,11,2,13.14,1,1,13.13,100,1,13.11,100,1,13.10,100,1,13.04,2,1,12.99,100,1,12.73,100,1,12.67,100,1,13.40,0,-10,13.70,0,-1,13.71,0,-2,13.73,0,-4,13.74,0,-3,13.75,0,-4,13.76,0,-4,13.77,0,-5,13.78,0,-4,13.79,0,-4,ARL,0
2025-07-17T15:49:03.406005590Z,2025-07-17T15:49:03.405840358Z,10,2,1108,C,A,10,13.750000000,15,307964605,165232,258527308,13.31,10,1,13.28,11,2,13.14,1,1,13.13,100,1,13.11,100,1,13.10,100,1,13.04,2,1,12.99,100,1,12.73,100,1,12.67,100,1,13.40,0,-10,13.70,0,-1,13.71,0,-2,13.73,0,-4,13.74,0,-3,13.75,0,-4,13.76,0,-4,13.77,0,-5,13.78,0,-4,13.79,0,-4,ARL,0
2025-07-17T15:49:04.713997925Z,2025-07-17T15:49:04.713831675Z,10,2,1108,A,A,10,13.710000000,15,308763065,166250,258547335,13.31,10,1,13.28,11,2,13.14,1,1,13.13,100,1,13.11,100,1,13.10,100,1,13.04,2,1,12.99,100,1,12.73,100,1,12.67,100,1,13.40,0,-10,13.70,0,-1,13.71,0,-2,13.73,0,-4,13.74,0,-3,13.75,0,-4,13.76,0,-4,13.77,0,-5,13.78,0,-4,13.79,0,-4,ARL,0
2025-07-17T15:49:06.013111941Z,2025-07-17T15:49:06.012946379Z,10,2,1108,A,A,10,13.730000000,100,308786185,165562,258567259,13.31,10,1,13.28,11,2,13.14,1,1,13.13,100,1,13.11,100,1,13.10,100,1,13.04,2,1,12.99,100,1,12.73,100,1,12.67,100,1,13.40,0,-10,13.70,0,-1,13.71,0,-2,13.73,0,-4,13.74,0,-3,13.75,0,-4,13.76,0,-4,13.77,0,-5,13.78,0,-4,13.79,0,-4,ARL,0
2025-07-17T15:49:06.023292147Z,2025-07-17T15:49:06.023126600Z,10,2,1108,C,A,10,13.750000000,100,308705489,165547,258567405,13.31,10,1,13.28,11,2,13.14,1,1,13.13,100,1,13.11,100,1,13.10,100,1,13.04,2,1,12.99,100,1,12.73,100,1,12.67,100,1,13.40,0,-10,13.70,0,-1,13.71,0,-2,13.73,0,-5,13.74,0,-3,13.75,0,-4,13.76,0,-4,13.77,0,-5,13.78,0,-4,13.79,0,-4,ARL,0
2025-07-17T15:49:06.344356890Z,2025-07-17T15:49:06.344191321Z,10,2,1108,C,A,10,13.740000000,100,308374881,165569,258574949,13.31,10,1,13.28,11,2,13.14,1,1,13.13,100,1,13.11,100,1,13.10,100,1,13.04,2,1,12.99,100,1,12.73,100,1,12.67,100,1,13.40,0,-10,13.70,0,-1,13.71,0,-2,13.73,0,-5,13.74,0,-3,13.75,0,-4,13.76,0,-4,13.77,0,-5,13.78,0,-4,13.79,0,-4,ARL,0
2025-07-17T15:49:06.344356890Z,2025-07-17T15:49:06.344191321Z,10,2,1108,A,A,10,13.720000000,100,308797069,165569,258574949,13.31,10,1,13.28,11,2,13.14,1,1,13.13,100,1,13.11,100,1,13.10,100,1,13.04,2,1,12.99,100,1,12.73,100,1,12.67,100,1,13.40,0,-10,13.70,0,-1,13.71,0,-2,13.73,0,-5,13.74,0,-3,13.75,0,-4,13.76,0,-4,13.77,0,-5,13.78,0,-4,13.79,0,-4,ARL,0
2025-07-17T15:49:06.345104491Z,2025-07-17T15:49:06.344938975Z,10,2,1108,C,A,10,14.830000000,100,307964665,165516,258575013,13.31,10,1,13.28,11,2,13.14,1,1,13.13,100,1,13.11,100,1,13.10,100,1,13.04,2,1,12.99,100,1,12.73,100,1,12.67,100,1,13.40,0,-10,13.70,0,-1,13.71,0,-2,13.72,0,-1,13.73,0,-5,13.74,0,-3,13.75,0,-4,13.76,0,-4,13.77,0,-5,13.78,0,-4,ARL,0
2025-07-17T15:49:06.345104491Z,2025-07-17T15:49:06.344938975Z,10,2,1108,A,A,10,14.780000000,100,308797245,165516,258575013,13.31,10,1,13.28,11,2,13.14,1,1,13.13,100,1,13.11,100,1,13.10,100,1,13.04,2,1,12.99,100,1,12.73,100,1,12.67,100,1,13.40,0,-10,13.70,0,-1,13.71,0,-2,13.72,0,-1,13.73,0,-5,13.74,0,-3,13.75,0,-4,13.76,0,-4,13.77,0,-5,13.78,0,-4,ARL,0
2025-07-17T15:49:06.362945410Z,2025-07-17T15:49:06.362779870Z,10,2,1108,C,A,10,17.580000000,100,306652017,165540,258575963,13.31,10,1,13.28,11,2,13.14,1,1,13.13,100,1,13.11,100,1,13.10,100,1,13.04,2,1,12.99,100,1,12.73,100,1,12.67,100,1,13.40,0,-10,13.70,0,-1,13.71,0,-2,13.72,0,-1,13.73,0,-5,13.74,0,-3,13.75,0,-4,13.76,0,-4,13.77,0,-5,13.78,0,-4,ARL,0
2025-07-17T15:49:06.362945410Z,2025-07-17T15:49:06.362779870Z,10,2,1108,A,A,10,17.430000000,100,308799373,165540,258575963,13.31,10,1,13.28,11,2,13.14,1,1,13.13,100,1,13.11,100,1,13.10,100,1,13.04,2,1,12.99,100,1,12.73,100,1,12.67,100,1,13.40,0,-10,13.70,0,-1,13.71,0,-2,13.72,0,-1,13.73,0,-5,13.74,0,-3,13.75,0,-4,13.76,0,-4,13.77,0,-5,13.78,0,-4,ARL,0
2025-07-17T15:49:10.459317885Z,2025-07-17T15:49:10.459152457Z,10,2,1108,C,A,10,13.730000000,15,308374537,165428,258636400,13.31,10,1,13.28,11,2,13.14,1,1,13.13,100,1,13.11,100,1,13.10,100,1,13.04,2,1,12.99,100,1,12.73,100,1,12.67,100,1,13.40,0,-10,13.70,0,-1,13.71,0,-2,13.72,0,-1,13.73,0,-5,13.74,0,-3,13.75,0,-4,13.76,0,-4,13.77,0,-5,13.78,0,-4,ARL,0
2025-07-17T15:49:11.460597600Z,2025-07-17T15:49:11.460432218Z,10,2,1108,A,A,10,13.690000000,15,308893737,165382,258650544,13.31,10,1,13.28,11,2,13.14,1,1,13.13,100,1,13.11,100,1,13.10,100,1,13.04,2,1,12.99,100,1,12.73,100,1,12.67,100,1,13.40,0,-10,13.70,0,-1,13.71,0,-2,13.72,0,-1,13.73,0,-5,13.74,0,-3,13.75,0,-4,13.76,0,-4,13.77,0,-5,13.78,0,-4,ARL,0
2025-07-17T15:49:11.891643099Z,2025-07-17T15:49:11.891477604Z,10,2,1108,C,A,10,13.720000000,100,308797069,165495,258658721,13.31,10,1,13.28,11,2,13.14,1,1,13.13,100,1,13.11,100,1,13.10,100,1,13.04,2,1,12.99,100,1,12.73,100,1,12.67,100,1,13.40,0,-10,13.69,0,-1,13.70,0,-1,13.71,0,-2,13.72,0,-1,13.73,0,-5,13.74,0,-3,13.75,0,-4,13.76,0,-4,13.77,0,-5,ARL,0
2025-07-17T15:49:11.891643099Z,2025-07-17T15:49:11.891477604Z,10,2,1108,A,A,10,13.700000000,100,308901793,165495,258658721,13.31,10,1,13.28,11,2,13.14,1,1,13.13,100,1,13.11,100,1,13.10,100,1,13.04,2,1,12.99,100,1,12.73,100,1,12.67,100,1,13.40,0,-10,13.69,0,-1,13.70,0,-1,13.71,0,-2,13.72,0,-1,13.73,0,-5,13.74,0,-3,13.75,0,-4,13.76,0,-4,13.77,0,-5,ARL,0
2025-07-17T15:49:11.893989071Z,2025-07-17T15:49:11.893823458Z,10,2,1108,C,A,10,14.810000000,100,306649913,165613,258658835,13.31,10,1,13.28,11,2,13.14,1,1,13.13,100,1,13.11,100,1,13.10,100,1,13.04,2,1,12.99,100,1,12.73,100,1,12.67,100,1,13.40,0,-10,13.69,0,-1,13.70,0,-2,13.71,0,-2,13.72,0,-1,13.73,0,-5,13.74,0,-3,13.75,0,-4,13.76,0,-4,13.77,0,-5,ARL,0
2025-07-17T15:49:11.893989071Z,2025-07-17T15:49:11.893823458Z,10,2,1108,A,A,10,14.660000000,100,308901981,165613,258658835,13.31,10,1,13.28,11,2,13.14,1,1,13.13,100,1,13.11,100,1,13.10,100,1,13.04,2,1,12.99,100,1,12.73,100,1,12.67,100,1,13.40,0,-10,13.69,0,-1,13.70,0,-2,13.71,0,-2,13.72,0,-1,13.73,0,-5,13.74,0,-3,13.75,0,-4,13.76,0,-4,13.77,0,-5,ARL,0
2025-07-17T15:49:11.904231149Z,2025-07-17T15:49:11.904065674Z,10,2,1108,C,A,10,15.920000000,100,306652001,165475,258659039,13.31,10,1,13.28,11,2,13.14,1,1,13.13,100,1,13.11,100,1,13.10,100,1,13.04,2,1,12.99,100,1,12.73,100,1,12.67,100,1,13.40,0,-10,13.69,0,-1,13.70,0,-2,13.71,0,-2,13.72,0,-1,13.73,0,-5,13.74,0,-3,13.75,0,-4,13.76,0,-4,13.77,0,-5,ARL,0
2025-07-17T15:49:11.904231149Z,2025-07-17T15:49:11.904065674Z,10,2,1108,A,A,10,15.760000000,100,308902229,165475,258659039,13.31,10,1,13.28,11,2,13.14,1,1,13.13,100,1,13.11,100,1,13.10,100,1,13.04,2,1,12.99,100,1,12.73,100,1,12.67,100,1,13.40,0,-10,13.69,0,-1,13.70,0,-2,13.71,0,-2,13.72,0,-1,13.73,0,-5,13.74,0,-3,13.75,0,-4,13.76,0,-4,13.77,0,-5,ARL,0
2025-07-17T15:49:11.935521687Z,2025-07-17T15:49:11.935356090Z,10,2,1108,C,A,10,14.810000000,100,306653713,165597,258659320,13.31,10,1,13.28,11,2,13.14,1,1,13.13,100,1,13.11,100,1,13.10,100,1,13.04,2,1,12.99,100,1,12.73,100,1,12.67,100,1,13.40,0,-10,13.69,0,-1,13.70,0,-2,13.71,0,-2,13.72,0,-1,13.73,0,-5,13.74,0,-3,13.75,0,-4,13.76,0,-4,13.77,0,-5,ARL,0
2025-07-17T15:49:11.935521687Z,2025-07-17T15:49:11.935356090Z,10,2,1108,A,A,10,14.660000000,100,308903001,165597,258659320,13.31,10,1,13.28,11,2,13.14,1,1,13.13,100,1,13.11,100,1,13.10,100,1,13.04,2,1,12.99,100,1,12.73,100,1,12.67,100,1,13.40,0,-10,13.69,0,-1,13.70,0,-2,13.71,0,-2,13.72,0,-1,13.73,0,-5,13.74,0,-3,13.75,0,-4,13.76,0,-4,13.77,0,-5,ARL,0
2025-07-17T15:49:11.948701049Z,2025-07-17T15:49:11.948535655Z,10,2,1108,C,A,10,14.640000000,100,306647521,165394,258659496,13.31,10,1,13.28,11,2,13.14,1,1,13.13,100,1,13.11,100,1,13.10,100,1,13.04,2,1,12.99,100,1,12.73,100,1,12.67,100,1,13.40,0,-10,13.69,0,-1,13.70,0,-2,13.71,0,-2,13.72,0,-1,13.73,0,-5,13.74,0,-3,13.75,0,-4,13.76,0,-4,13.77,0,-5,ARL,0
2025-07-17T15:49:11.948829112Z,2025-07-17T15:49:11.948663655Z,10,2,1108,A,A,10,14.500000000,100,308903349,165457,258659499,13.31,10,1,13.28,11,2,13.14,1,1,13.13,100,1,13.11,100,1,13.10,100,1,13.04,2,1,12.99,100,1,12.73,100,1,12.67,100,1,13.40,0,-10,13.69,0,-1,13.70,0,-2,13.71,0,-2,13.72,0,-1,13.73,0,-5,13.74,0,-3,13.75,0,-4,13.76,0,-4,13.77,0,-5,ARL,0
2025-07-17T15:49:12.221221367Z,2025-07-17T15:49:12.221056085Z,10,2,1108,A,A,10,13.710000000,100,308909249,165282,258663292,13.31,10,1,13.28,11,2,13.14,1,1,13.13,100,1,13.11,100,1,13.10,100,1,13.04,2,1,12.99,100,1,12.73,100,1,12.67,100,1,13.40,0,-10,13.69,0,-1,13.70,0,-2,13.71,0,-2,13.72,0,-1,13.73,0,-5,13.74,0,-3,13.75,0,-4,13.76,0,-4,13.77,0,-5,ARL,0
2025-07-17T15:49:12.227986905Z,2025-07-17T15:49:12.227821500Z,10,2,1108,C,A,10,13.730000000,100,308786185,165405,258663378,13.31,10,1,13.28,11,2,13.14,1,1,13.13,100,1,13.11,100,1,13.10,100,1,13.04,2,1,12.99,100,1,12.73,100,1,12.67,100,1,13.40,0,-10,13.69,0,-1,13.70,0,-2,13.71,0,-3,13.72,0,-1,13.73,0,-5,13.74,0,-3,13.75,0,-4,13.76,0,-4,13.77,0,-5,ARL,0
2025-07-17T15:49:14.463229121Z,2025-07-17T15:49:14.463063539Z,10,2,1108,C,A,10,13.710000000,15,308763065,165582,258702625,13.31,10,1,13.28,11,2,13.14,1,1,13.13,100,1,13.11,100,1,13.10,100,1,13.04,2,1,12.99,100,1,12.73,100,1,12.67,100,1,13.40,0,-10,13.69,0,-1,13.70,0,-2,13.71,0,-3,13.72,0,-1,13.73,0,-5,13.74,0,-3,13.75,0,-4,13.76,0,-4,13.77,0,-5,ARL,0
2025-07-17T15:49:15.466365122Z,2025-07-17T15:49:15.466199239Z,10,2,1108,A,A,10,13.670000000,15,308980305,165883,258716863,13.31,10,1,13.28,11,2,13.14,1,1,13.13,100,1,13.11,100,1,13.10,100,1,13.04,2,1,12.99,100,1,12.73,100,1,12.67,100,1,13.40,0,-10,13.69,0,-1,13.70,0,-2,13.71,0,-3,13.72,0,-1,13.73,0,-5,13.74,0,-3,13.75,0,-4,13.76,0,-4,13.77,0,-5,ARL,0
2025-07-17T15:49:16.351024588Z,2025-07-17T15:49:16.350859152Z,10,2,1108,C,A,10,13.700000000,100,308901793,165436,258727929,13.31,10,1,13.28,11,2,13.14,1,1,13.13,100,1,13.11,100,1,13.10,100,1,13.04,2,1,12.99,100,1,12.73,100,1,12.67,100,1,13.40,0,-10,13.67,0,-1,13.69,0,-1,13.70,0,-2,13.71,0,-3,13.72,0,-1,13.73,0,-5,13.74,0,-3,13.75,0,-4,13.76,0,-4,ARL,0
2025-07-17T15:49:16.351024588Z,2025-07-17T15:49:16.350859152Z,10,2,1108,A,A,10,13.680000000,100,308998225,165436,258727929,13.31,10,1,13.28,11,2,13.14,1,1,13.13,100,1,13.11,100,1,13.10,100,1,13.04,2,1,12.99,100,1,12.73,100,1,12.67,100,1,13.40,0,-10,13.67,0,-1,13.69,0,-1,13.70,0,-2,13.71,0,-3,13.72,0,-1,13.73,0,-5,13.74,0,-3,13.75,0,-4,13.76,0,-4,ARL,0
2025-07-17T15:49:16.351759618Z,2025-07-17T15:49:16.351594042Z,10,2,1108,C,A,10,14.780000000,100,308797245,165576,258727956,13.31,10,1,13.28,11,2,13.14,1,1,13.13,100,1,13.11,100,1,13.10,100,1,13.04,2,1,12.99,100,1,12.73,100,1,12.67,100,1,13.40,0,-10,13.67,0,-1,13.68,0,-1,13.69,0,-1,13.70,0,-2,13.71,0,-3,13.72,0,-1,13.73,0,-5,13.74,0,-3,13.75,0,-4,ARL,0
2025-07-17T15:49:16.351759618Z,2025-07-17T15:49:16.351594042Z,10,2,1108,A,A,10,14.740000000,100,308998341,165576,258727956,13.31,10,1,13.28,11,2,13.14,1,1,13.13,100,1,13.11,100,1,13.10,100,1,13.04,2,1,12.99,100,1,12.73,100,1,12.67,100,1,13.40,0,-10,13.67,0,-1,13.68,0,-1,13.69,0,-1,13.70,0,-2,13.71,0,-3,13.72,0,-1,13.73,0,-5,13.74,0,-3,13.75,0,-4,ARL,0
2025-07-17T15:49:16.494111490Z,2025-07-17T15:49:16.493946243Z,10,2,1108,A,A,10,13.690000000,100,309001525,165247,258729266,13.31,10,1,13.28,11,2,13.14,1,1,13.13,100,1,13.11,100,1,13.10,100,1,13.04,2,1,12.99,100,1,12.73,100,1,12.67,100,1,13.40,0,-10,13.67,0,-1,13.68,0,-1,13.69,0,-1,13.70,0,-2,13.71,0,-3,13.72,0,-1,13.73,0,-5,13.74,0,-3,13.75,0,-4,ARL,0
2025-07-17T15:49:16.557924863Z,2025-07-17T15:49:16.557759633Z,10,2,1108,C,A,10,13.710000000,100,308909249,165230,258730034,13.31,10,1,13.28,11,2,13.14,1,1,13.13,100,1,13.11,100,1,13.10,100,1,13.04,2,1,12.99,100,1,12.73,100,1,12.67,100,1,13.40,0,-10,13.67,0,-1,13.68,0,-1,13.69,0,-2,13.70,0,-2,13.71,0,-3,13.72,0,-1,13.73,0,-5,13.74,0,-3,13.75,0,-4,ARL,0
2025-07-17T15:49:21.186150487Z,2025-07-17T15:49:21.185984774Z,10,2,1108,C,A,10,14.070000000,2,296478973,165713,258786552,13.31,10,1,13.28,11,2,13.14,1,1,13.13,100,1,13.11,100,1,13.10,100,1,13.04,2,1,12.99,100,1,12.73,100,1,12.67,100,1,13.40,0,-10,13.67,0,-1,13.68,0,-1,13.69,0,-2,13.70,0,-2,13.71,0,-3,13.72,0,-1,13.73,0,-5,13.74,0,-3,13.75,0,-4,ARL,0
2025-07-17T15:49:21.186150487Z,2025-07-17T15:49:21.185984774Z,10,2,1108,A,A,10,13.980000000,2,309091513,165713,258786552,13.31,10,1,13.28,11,2,13.14,1,1,13.13,100,1,13.11,100,1,13.10,100,1,13.04,2,1,12.99,100,1,12.73,100,1,12.67,100,1,13.40,0,-10,13.67,0,-1,13.68,0,-1,13.69,0,-2,13.70,0,-2,13.71,0,-3,13.72,0,-1,13.73,0,-5,13.74,0,-3,13.75,0,-4,ARL,0
2025-07-17T15:49:24.283152112Z,2025-07-17T15:49:24.282985894Z,10,2,1108,C,A,10,13.690000000,15,308893737,166218,258838460,13.31,10,1,13.28,11,2,13.14,1,1,13.13,100,1,13.11,100,1,13.10,100,1,13.04,2,1,12.99,100,1,12.73,100,1,12.67,100,1,13.40,0,-10,13.67,0,-1,13.68,0,-1,13.69,0,-2,13.70,0,-2,13.71,0,-3,13.72,0,-1,13.73,0,-5,13.74,0,-3,13.75,0,-4,ARL,0
2025-07-17T15:49:34.570197134Z,2025-07-17T15:49:34.570031718Z,10,2,1108,C,A,10,13.670000000,15,308980305,165416,258980876,13.31,10,1,13.28,11,2,13.14,1,1,13.13,100,1,13.11,100,1,13.10,100,1,13.04,2,1,12.99,100,1,12.73,100,1,12.67,100,1,13.40,0,-10,13.67,0,-1,13.68,0,-1,13.69,0,-2,13.70,0,-2,13.71,0,-3,13.72,0,-1,13.73,0,-5,13.74,0,-3,13.75,0,-4,ARL,0
2025-07-17T15:49:34.591512915Z,2025-07-17T15:49:34.591347169Z,10,2,1108,C,A,10,13.690000000,100,309001525,165746,258983321,13.31,10,1,13.28,11,2,13.14,1,1,13.13,100,1,13.11,100,1,13.10,100,1,13.04,2,1,12.99,100,1,12.73,100,1,12.67,100,1,13.40,0,-10,13.67,0,-1,13.68,0,-1,13.69,0,-2,13.70,0,-2,13.71,0,-3,13.72,0,-1,13.73,0,-5,13.74,0,-3,13.75,0,-4,ARL,0
2025-07-17T15:49:38.610017394Z,2025-07-17T15:49:38.609851985Z,10,2,1108,A,A,10,13.720000000,100,309410565,165409,259031220,13.31,10,1,13.28,11,2,13.14,1,1,13.13,100,1,13.11,100,1,13.10,100,1,13.04,2,1,12.99,100,1,12.73,100,1,12.67,100,1,13.40,0,-10,13.67,0,-1,13.68,0,-1,13.69,0,-2,13.70,0,-2,13.71,0,-3,13.72,0,-1,13.73,0,-5,13.74,0,-3,13.75,0,-4,ARL,0
2025-07-17T15:49:38.610073334Z,2025-07-17T15:49:38.609907720Z,10,2,1108,C,B,10,13.260000000,100,291975017,165614,259031221,13.31,10,1,13.28,11,2,13.14,1,1,13.13,100,1,13.11,100,1,13.10,100,1,13.04,2,1,12.99,100,1,12.73,100,1,12.67,100,1,13.40,0,-10,13.67,0,-1,13.68,0,-1,13.69,0,-2,13.70,0,-2,13.71,0,-3,13.72,0,-2,13.73,0,-5,13.74,0,-3,13.75,0,-4,ARL,0
2025-07-17T15:49:39.068515005Z,2025-07-17T15:49:39.068349660Z,10,2,1108,A,B,10,13.020000000,100,309415429,165345,259035032,13.31,10,1,13.28,11,2,13.14,1,1,13.13,100,1,13.11,100,1,13.10,100,1,13.04,2,1,13.02,100,1,12.99,100,1,12.73,100,1,13.40,0,-10,13.67,0,-1,13.68,0,-1,13.69,0,-2,13.70,0,-2,13.71,0,-3,13.72,0,-2,13.73,0,-5,13.74,0,-3,13.75,0,-4,ARL,0
2025-07-17T15:49:44.788414401Z,2025-07-17T15:49:44.788249210Z,10,2,1108,A,A,10,13.670000000,15,309524921,165191,259105347,13.31,10,1,13.28,11,2,13.14,1,1,13.13,100,1,13.11,100,1,13.10,100,1,13.04,2,1,13.02,100,1,12.99,100,1,12.73,100,1,13.40,0,-10,13.67,0,-1,13.68,0,-1,13.69,0,-2,13.70,0,-2,13.71,0,-3,13.72,0,-2,13.73,0,-5,13.74,0,-3,13.75,0,-4,ARL,0
2025-07-17T15:49:44.789020757Z,2025-07-17T15:49:44.788855587Z,10,2,1108,A,A,10,13.700000000,100,309524933,165170,259105361,13.31,10,1,13.28,11,2,13.14,1,1,13.13,100,1,13.11,100,1,13.10,100,1,13.04,2,1,13.02,100,1,12.99,100,1,12.73,100,1,13.40,0,-10,13.67,0,-1,13.68,0,-1,13.69,0,-2,13.70,0,-2,13.71,0,-3,13.72,0,-2,13.73,0,-5,13.74,0,-3,13.75,0,-4,ARL,0
2025-07-17T15:49:44.789702916Z,2025-07-17T15:49:44.789537536Z,10,2,1108,C,A,10,13.720000000,100,309410565,165380,259105380,13.31,10,1,13.28,11,2,13.14,1,1,13.13,100,1,13.11,100,1,13.10,100,1,13.04,2,1,13.02,100,1,12.99,100,1,12.73,100,1,13.40,0,-10,13.67,0,-1,13.68,0,-1,13.69,0,-2,13.70,0,-3,13.71,0,-3,13.72,0,-2,13.73,0,-5,13.74,0,-3,13.75,0,-4,ARL,0
2025-07-17T15:49:54.788658841Z,2025-07-17T15:49:54.788493605Z,10,2,1108,A,A,10,13.650000000,15,309707269,165236,259253294,13.31,10,1,13.28,11,2,13.14,1,1,13.13,100,1,13.11,100,1,13.10,100,1,13.04,2,1,13.02,100,1,12.99,100,1,12.73,100,1,13.40,0,-10,13.67,0,-1,13.68,0,-1,13.69,0,-2,13.70,0,-3,13.71,0,-3,13.72,0,-2,13.73,0,-5,13.74,0,-3,13.75,0,-4,ARL,0
2025-07-17T15:49:54.799535744Z,2025-07-17T15:49:54.799370442Z,10,2,1108,A,A,10,13.680000000,100,309707413,165302,259253527,13.31,10,1,13.28,11,2,13.14,1,1,13.13,100,1,13.11,100,1,13.10,100,1,13.04,2,1,13.02,100,1,12.99,100,1,12.73,100,1,13.40,0,-10,13.67,0,-1,13.68,0,-1,13.69,0,-2,13.70,0,-3,13.71,0,-3,13.72,0,-2,13.73,0,-5,13.74,0,-3,13.75,0,-4,ARL,0
2025-07-17T15:49:54.820634917Z,2025-07-17T15:49:54.820469390Z,10,2,1108,C,A,10,13.700000000,100,309524933,165527,259253732,13.31,10,1,13.28,11,2,13.14,1,1,13.13,100,1,13.11,100,1,13.10,100,1,13.04,2,1,13.02,100,1,12.99,100,1,12.73,100,1,13.40,0,-10,13.67,0,-1,13.68,0,-2,13.69,0,-2,13.70,0,-3,13.71,0,-3,13.72,0,-2,13.73,0,-5,13.74,0,-3,13.75,0,-4,ARL,0
2025-07-17T15:49:59.512104064Z,2025-07-17T15:49:59.511938438Z,10,2,1108,C,A,10,13.680000000,100,308998225,165626,259313537,13.31,10,1,13.28,11,2,13.14,1,1,13.13,100,1,13.11,100,1,13.10,100,1,13.04,2,1,13.02,100,1,12.99,100,1,12.73,100,1,13.40,0,-10,13.67,0,-1,13.68,0,-2,13.69,0,-2,13.70,0,-3,13.71,0,-3,13.72,0,-2,13.73,0,-5,13.74,0,-3,13.75,0,-4,ARL,0
2025-07-17T15:49:59.512104064Z,2025-07-17T15:49:59.511938438Z,10,2,1108,A,A,10,13.660000000,100,309782481,165626,259313537,13.31,10,1,13.28,11,2,13.14,1,1,13.13,100,1,13.11,100,1,13.10,100,1,13.04,2,1,13.02,100,1,12.99,100,1,12.73,100,1,13.40,0,-10,13.67,0,-1,13.68,0,-2,13.69,0,-2,13.70,0,-3,13.71,0,-3,13.72,0,-2,13.73,0,-5,13.74,0,-3,13.75,0,-4,ARL,0
2025-07-17T15:49:59.534062634Z,2025-07-17T15:49:59.533897369Z,10,2,1108,C,A,10,14.010000000,100,308375185,165265,259314032,13.31,10,1,13.28,11,2,13.14,1,1,13.13,100,1,13.11,100,1,13.10,100,1,13.04,2,1,13.02,100,1,12.99,100,1,12.73,100,1,13.40,0,-10,13.66,0,-1,13.67,0,-1,13.68,0,-2,13.69,0,-2,13.70,0,-3,13.71,0,-3,13.72,0,-2,13.73,0,-5,13.74,0,-3,ARL,0
2025-07-17T15:49:59.534115275Z,2025-07-17T15:49:59.533948952Z,10,2,1108,A,A,10,13.930000000,100,309782973,166323,259314033,13.31,10,1,13.28,11,2,13.14,1,1,13.13,100,1,13.11,100,1,13.10,100,1,13.04,2,1,13.02,100,1,12.99,100,1,12.73,100,1,13.40,0,-10,13.66,0,-1,13.67,0,-1,13.68,0,-2,13.69,0,-2,13.70,0,-3,13.71,0,-3,13.72,0,-2,13.73,0,-5,13.74,0,-3,ARL,0
2025-07-17T15:50:00.547404972Z,2025-07-17T15:50:00.547239401Z,10,2,1108,C,A,10,13.670000000,15,309524921,165571,259349868,13.31,10,1,13.28,11,2,13.14,1,1,13.13,100,1,13.11,100,1,13.10,100,1,13.04,2,1,13.02,100,1,12.99,100,1,12.73,100,1,13.40,0,-10,13.66,0,-1,13.67,0,-1,13.68,0,-2,13.69,0,-2,13.70,0,-3,13.71,0,-3,13.72,0,-2,13.73,0,-5,13.74,0,-3,ARL,0
2025-07-17T15:50:00.555536688Z,2025-07-17T15:50:00.555363249Z,10,2,1108,C,A,10,14.650000000,100,307964661,173439,259353226,13.31,10,1,13.28,11,2,13.14,1,1,13.13,100,1,13.11,100,1,13.10,100,1,13.04,2,1,13.02,100,1,12.99,100,1,12.73,100,1,13.40,0,-10,13.66,0,-1,13.67,0,-1,13.68,0,-2,13.69,0,-2,13.70,0,-3,13.71,0,-3,13.72,0,-2,13.73,0,-5,13.74,0,-3,ARL,0
2025-07-17T15:50:00.555536688Z,2025-07-17T15:50:00.555363249Z,10,2,1108,A,A,10,14.540000000,100,309823025,173439,259353226,13.31,10,1,13.28,11,2,13.14,1,1,13.13,100,1,13.11,100,1,13.10,100,1,13.04,2,1,13.02,100,1,12.99,100,1,12.73,100,1,13.40,0,-10,13.66,0,-1,13.67,0,-1,13.68,0,-2,13.69,0,-2,13.70,0,-3,13.71,0,-3,13.72,0,-2,13.73,0,-5,13.74,0,-3,ARL,0
2025-07-17T15:50:03.412422880Z,2025-07-17T15:50:03.412257475Z,10,2,1108,A,A,10,13.630000000,15,309899025,165405,259413272,13.31,10,1,13.28,11,2,13.14,1,1,13.13,100,1,13.11,100,1,13.10,100,1,13.04,2,1,13.02,100,1,12.99,100,1,12.73,100,1,13.40,0,-10,13.66,0,-1,13.67,0,-1,13.68,0,-2,13.69,0,-2,13.70,0,-3,13.71,0,-3,13.72,0,-2,13.73,0,-5,13.74,0,-3,ARL,0
2025-07-17T15:50:03.415527372Z,2025-07-17T15:50:03.415361851Z,10,2,1108,C,A,10,14.640000000,100,308296381,165521,259413427,13.31,10,1,13.28,11,2,13.14,1,1,13.13,100,1,13.11,100,1,13.10,100,1,13.04,2,1,13.02,100,1,12.99,100,1,12.73,100,1,13.40,0,-10,13.63,0,-1,13.66,0,-1,13.67,0,-1,13.68,0,-2,13.69,0,-2,13.70,0,-3,13.71,0,-3,13.72,0,-2,13.73,0,-5,ARL,0
2025-07-17T15:50:03.415527372Z,2025-07-17T15:50:03.415361851Z,10,2,1108,A,A,10,14.530000000,100,309899141,165521,259413427,13.31,10,1,13.28,11,2,13.14,1,1,13.13,100,1,13.11,100,1,13.10,100,1,13.04,2,1,13.02,100,1,12.99,100,1,12.73,100,1,13.40,0,-10,13.63,0,-1,13.66,0,-1,13.67,0,-1,13.68,0,-2,13.69,0,-2,13.70,0,-3,13.71,0,-3,13.72,0,-2,13.73,0,-5,ARL,0
2025-07-17T15:50:03.824292152Z,2025-07-17T15:50:03.824126753Z,10,2,1108,C,A,10,13.660000000,100,309782481,165399,259418661,13.31,10,1,13.28,11,2,13.14,1,1,13.13,100,1,13.11,100,1,13.10,100,1,13.04,2,1,13.02,100,1,12.99,100,1,12.73,100,1,13.40,0,-10,13.63,0,-1,13.66,0,-1,13.67,0,-1,13.68,0,-2,13.69,0,-2,13.70,0,-3,13.71,0,-3,13.72,0,-2,13.73,0,-5,ARL,0
2025-07-17T15:50:03.824292152Z,2025-07-17T15:50:03.824126753Z,10,2,1108,A,A,10,13.640000000,100,309903973,165399,259418661,13.31,10,1,13.28,11,2,13.14,1,1,13.13,100,1,13.11,100,1,13.10,100,1,13.04,2,1,13.02,100,1,12.99,100,1,12.73,100,1,13.40,0,-10,13.63,0,-1,13.66,0,-1,13.67,0,-1,13.68,0,-2,13.69,0,-2,13.70,0,-3,13.71,0,-3,13.72,0,-2,13.73,0,-5,ARL,0
2025-07-17T15:50:03.825028460Z,2025-07-17T15:50:03.824863026Z,10,2,1108,C,A,10,14.740000000,100,308998341,165434,259418664,13.31,10,1,13.28,11,2,13.14,1,1,13.13,100,1,13.11,100,1,13.10,100,1,13.04,2,1,13.02,100,1,12.99,100,1,12.73,100,1,13.40,0,-10,13.63,0,-1,13.64,0,-1,13.66,0,-1,13.67,0,-1,13.68,0,-2,13.69,0,-2,13.70,0,-3,13.71,0,-3,13.72,0,-2,ARL,0
2025-07-17T15:50:03.825028460Z,2025-07-17T15:50:03.824863026Z,10,2,1108,A,A,10,14.700000000,100,309903993,165434,259418664,13.31,10,1,13.28,11,2,13.14,1,1,13.13,100,1,13.11,100,1,13.10,100,1,13.04,2,1,13.02,100,1,12.99,100,1,12.73,100,1,13.40,0,-10,13.63,0,-1,13.64,0,-1,13.66,0,-1,13.67,0,-1,13.68,0,-2,13.69,0,-2,13.70,0,-3,13.71,0,-3,13.72,0,-2,ARL,0
2025-07-17T15:50:04.484898759Z,2025-07-17T15:50:04.484733438Z,10,2,1108,A,A,10,13.660000000,100,309922345,165321,259433904,13.31,10,1,13.28,11,2,13.14,1,1,13.13,100,1,13.11,100,1,13.10,100,1,13.04,2,1,13.02,100,1,12.99,100,1,12.73,100,1,13.40,0,-10,13.63,0,-1,13.64,0,-1,13.66,0,-1,13.67,0,-1,13.68,0,-2,13.69,0,-2,13.70,0,-3,13.71,0,-3,13.72,0,-2,ARL,0
2025-07-17T15:50:04.524729039Z,2025-07-17T15:50:04.524563568Z,10,2,1108,C,A,10,13.680000000,100,309707413,165471,259434652,13.31,10,1,13.28,11,2,13.14,1,1,13.13,100,1,13.11,100,1,13.10,100,1,13.04,2,1,13.02,100,1,12.99,100,1,12.73,100,1,13.40,0,-10,13.63,0,-1,13.64,0,-1,13.66,0,-2,13.67,0,-1,13.68,0,-2,13.69,0,-2,13.70,0,-3,13.71,0,-3,13.72,0,-2,ARL,0
2025-07-17T15:50:06.787826975Z,2025-07-17T15:50:06.787661846Z,10,2,1108,C,A,10,13.630000000,15,309899025,165129,259472951,13.31,10,1,13.28,11,2,13.14,1,1,13.13,100,1,13.11,100,1,13.10,100,1,13.04,2,1,13.02,100,1,12.99,100,1,12.73,100,1,13.40,0,-10,13.63,0,-1,13.64,0,-1,13.66,0,-2,13.67,0,-1,13.68,0,-2,13.69,0,-2,13.70,0,-3,13.71,0,-3,13.72,0,-2,ARL,0
2025-07-17T15:50:09.185499367Z,2025-07-17T15:50:09.185334126Z,10,2,1108,A,A,10,13.610000000,15,310030465,165241,259516855,13.31,10,1,13.28,11,2,13.14,1,1,13.13,100,1,13.11,100,1,13.10,100,1,13.04,2,1,13.02,100,1,12.99,100,1,12.73,100,1,13.40,0,-10,13.63,0,-1,13.64,0,-1,13.66,0,-2,13.67,0,-1,13.68,0,-2,13.69,0,-2,13.70,0,-3,13.71,0,-3,13.72,0,-2,ARL,0
2025-07-17T15:50:09.198476437Z,2025-07-17T15:50:09.198311198Z,10,2,1108,A,A,10,13.640000000,100,310031625,165239,259517754,13.31,10,1,13.28,11,2,13.14,1,1,13.13,100,1,13.11,100,1,13.10,100,1,13.04,2,1,13.02,100,1,12.99,100,1,12.73,100,1,13.40,0,-10,13.63,0,-1,13.64,0,-1,13.66,0,-2,13.67,0,-1,13.68,0,-2,13.69,0,-2,13.70,0,-3,13.71,0,-3,13.72,0,-2,ARL,0
2025-07-17T15:50:09.205487416Z,2025-07-17T15:50:09.205322092Z,10,2,1108,C,A,10,13.660000000,100,309922345,165324,259517973,13.31,10,1,13.28,11,2,13.14,1,1,13.13,100,1,13.11,100,1,13.10,100,1,13.04,2,1,13.02,100,1,12.99,100,1,12.73,100,1,13.40,0,-10,13.63,0,-1,13.64,0,-2,13.66,0,-2,13.67,0,-1,13.68,0,-2,13.69,0,-2,13.70,0,-3,13.71,0,-3,13.72,0,-2,ARL,0
2025-07-17T15:50:09.330738153Z,2025-07-17T15:50:09.330572653Z,10,2,1108,C,A,10,13.640000000,100,309903973,165500,259522708,13.31,10,1,13.28,11,2,13.14,1,1,13.13,100,1,13.11,100,1,13.10,100,1,13.04,2,1,13.02,100,1,12.99,100,1,12.73,100,1,13.40,0,-10,13.63,0,-1,13.64,0,-2,13.66,0,-2,13.67,0,-1,13.68,0,-2,13.69,0,-2,13.70,0,-3,13.71,0,-3,13.72,0,-2,ARL,0
2025-07-17T15:50:09.330738153Z,2025-07-17T15:50:09.330572653Z,10,2,1108,A,A,10,13.620000000,100,310037965,165500,259522708,13.31,10,1,13.28,11,2,13.14,1,1,13.13,100,1,13.11,100,1,13.10,100,1,13.04,2,1,13.02,100,1,12.99,100,1,12.73,100,1,13.40,0,-10,13.63,0,-1,13.64,0,-2,13.66,0,-2,13.67,0,-1,13.68,0,-2,13.69,0,-2,13.70,0,-3,13.71,0,-3,13.72,0,-2,ARL,0
2025-07-17T15:50:20.204539185Z,2025-07-17T15:50:20.204373858Z,10,2,1108,C,A,10,13.650000000,15,309707269,165327,259737768,13.31,10,1,13.28,11,2,13.14,1,1,13.13,100,1,13.11,100,1,13.10,100,1,13.04,2,1,13.02,100,1,12.99,100,1,12.73,100,1,13.40,0,-10,13.63,0,-1,13.64,0,-2,13.66,0,-2,13.67,0,-1,13.68,0,-2,13.69,0,-2,13.70,0,-3,13.71,0,-3,13.72,0,-2,ARL,0
2025-07-17T15:50:25.935579034Z,2025-07-17T15:50:25.935412900Z,10,2,1108,A,A,10,13.590000000,15,310424077,166134,259828644,13.31,10,1,13.28,11,2,13.14,1,1,13.13,100,1,13.11,100,1,13.10,100,1,13.04,2,1,13.02,100,1,12.99,100,1,12.73,100,1,13.40,0,-10,13.63,0,-1,13.64,0,-2,13.66,0,-2,13.67,0,-1,13.68,0,-2,13.69,0,-2,13.70,0,-3,13.71,0,-3,13.72,0,-2,ARL,0
2025-07-17T15:50:26.954828150Z,2025-07-17T15:50:26.954662143Z,10,2,1108,C,A,10,13.620000000,100,310037965,166007,259847181,13.31,10,1,13.28,11,2,13.14,1,1,13.13,100,1,13.11,100,1,13.10,100,1,13.04,2,1,13.02,100,1,12.99,100,1,12.73,100,1,13.40,0,-10,13.59,0,-1,13.63,0,-1,13.64,0,-2,13.66,0,-2,13.67,0,-1,13.68,0,-2,13.69,0,-2,13.70,0,-3,13.71,0,-3,ARL,0
2025-07-17T15:50:26.954828150Z,2025-07-17T15:50:26.954662143Z,10,2,1108,A,A,10,13.600000000,100,310446249,166007,259847181,13.31,10,1,13.28,11,2,13.14,1,1,13.13,100,1,13.11,100,1,13.10,100,1,13.04,2,1,13.02,100,1,12.99,100,1,12.73,100,1,13.40,0,-10,13.59,0,-1,13.63,0,-1,13.64,0,-2,13.66,0,-2,13.67,0,-1,13.68,0,-2,13.69,0,-2,13.70,0,-3,13.71,0,-3,ARL,0
2025-07-17T15:50:26.955565904Z,2025-07-17T15:50:26.955400327Z,10,2,1108,C,A,10,14.700000000,100,309903993,165577,259847190,13.31,10,1,13.28,11,2,13.14,1,1,13.13,100,1,13.11,100,1,13.10,100,1,13.04,2,1,13.02,100,1,12.99,100,1,12.73,100,1,13.40,0,-10,13.59,0,-1,13.60,0,-1,13.63,0,-1,13.64,0,-2,13.66,0,-2,13.67,0,-1,13.68,0,-2,13.69,0,-2,13.70,0,-3,ARL,0
2025-07-17T15:50:26.955565904Z,2025-07-17T15:50:26.955400327Z,10,2,1108,A,A,10,14.650000000,100,310446269,165577,259847190,13.31,10,1,13.28,11,2,13.14,1,1,13.13,100,1,13.11,100,1,13.10,100,1,13.04,2,1,13.02,100,1,12.99,100,1,12.73,100,1,13.40,0,-10,13.59,0,-1,13.60,0,-1,13.63,0,-1,13.64,0,-2,13.66,0,-2,13.67,0,-1,13.68,0,-2,13.69,0,-2,13.70,0,-3,ARL,0
2025-07-17T15:50:26.956259508Z,2025-07-17T15:50:26.956094101Z,10,2,1108,C,A,10,17.430000000,100,308799373,165407,259847199,13.31,10,1,13.28,11,2,13.14,1,1,13.13,100,1,13.11,100,1,13.10,100,1,13.04,2,1,13.02,100,1,12.99,100,1,12.73,100,1,13.40,0,-10,13.59,0,-1,13.60,0,-1,13.63,0,-1,13.64,0,-2,13.66,0,-2,13.67,0,-1,13.68,0,-2,13.69,0,-2,13.70,0,-3,ARL,0
2025-07-17T15:50:26.956259508Z,2025-07-17T15:50:26.956094101Z,10,2,1108,A,A,10,17.280000000,100,310446293,165407,259847199,13.31,10,1,13.28,11,2,13.14,1,1,13.13,100,1,13.11,100,1,13.10,100,1,13.04,2,1,13.02,100,1,12.99,100,1,12.73,100,1,13.40,0,-10,13.59,0,-1,13.60,0,-1,13.63,0,-1,13.64,0,-2,13.66,0,-2,13.67,0,-1,13.68,0,-2,13.69,0,-2,13.70,0,-3,ARL,0
2025-07-17T15:50:26.983044736Z,2025-07-17T15:50:26.982879448Z,10,2,1108,A,A,10,15.510000000,100,310447441,165288,259847556,13.31,10,1,13.28,11,2,13.14,1,1,13.13,100,1,13.11,100,1,13.10,100,1,13.04,2,1,13.02,100,1,12.99,100,1,12.73,100,1,13.40,0,-10,13.59,0,-1,13.60,0,-1,13.63,0,-1,13.64,0,-2,13.66,0,-2,13.67,0,-1,13.68,0,-2,13.69,0,-2,13.70,0,-3,ARL,0
2025-07-17T15:50:26.983057675Z,2025-07-17T15:50:26.982892468Z,10,2,1108,C,A,10,15.780000000,100,282776733,165207,259847557,13.31,10,1,13.28,11,2,13.14,1,1,13.13,100,1,13.11,100,1,13.10,100,1,13.04,2,1,13.02,100,1,12.99,100,1,12.73,100,1,13.40,0,-10,13.59,0,-1,13.60,0,-1,13.63,0,-1,13.64,0,-2,13.66,0,-2,13.67,0,-1,13.68,0,-2,13.69,0,-2,13.70,0,-3,ARL,0
2025-07-17T15:50:30.046879569Z,2025-07-17T15:50:30.046714265Z,10,2,1108,C,A,10,13.590000000,15,310424077,165304,259916670,13.31,10,1,13.28,11,2,13.14,1,1,13.13,100,1,13.11,100,1,13.10,100,1,13.04,2,1,13.02,100,1,12.99,100,1,12.73,100,1,13.40,0,-10,13.59,0,-1,13.60,0,-1,13.63,0,-1,13.64,0,-2,13.66,0,-2,13.67,0,-1,13.68,0,-2,13.69,0,-2,13.70,0,-3,ARL,0
2025-07-17T15:50:30.047015114Z,2025-07-17T15:50:30.046849726Z,10,2,1108,C,A,10,13.610000000,15,310030465,165388,259916674,13.31,10,1,13.28,11,2,13.14,1,1,13.13,100,1,13.11,100,1,13.10,100,1,13.04,2,1,13.02,100,1,12.99,100,1,12.73,100,1,13.40,0,-10,13.59,0,-1,13.60,0,-1,13.63,0,-1,13.64,0,-2,13.66,0,-2,13.67,0,-1,13.68,0,-2,13.69,0,-2,13.70,0,-3,ARL,0
2025-07-17T15:51:37.986158330Z,2025-07-17T15:51:37.985992174Z,10,2,1108,C,A,10,13.980000000,2,309091513,166156,261130345,13.31,10,1,13.28,11,2,13.14,1,1,13.13,100,1,13.11,100,1,13.10,100,1,13.04,2,1,13.02,100,1,12.99,100,1,12.73,100,1,13.40,0,-10,13.59,0,-1,13.60,0,-1,13.63,0,-1,13.64,0,-2,13.66,0,-2,13.67,0,-1,13.68,0,-2,13.69,0,-2,13.70,0,-3,ARL,0
2025-07-17T15:51:37.986158330Z,2025-07-17T15:51:37.985992174Z,10,2,1108,A,A,10,13.890000000,2,311979125,166156,261130345,13.31,10,1,13.28,11,2,13.14,1,1,13.13,100,1,13.11,100,1,13.10,100,1,13.04,2,1,13.02,100,1,12.99,100,1,12.73,100,1,13.40,0,-10,13.59,0,-1,13.60,0,-1,13.63,0,-1,13.64,0,-2,13.66,0,-2,13.67,0,-1,13.68,0,-2,13.69,0,-2,13.70,0,-3,ARL,0
2025-07-17T15:52:16.372434625Z,2025-07-17T15:52:16.372269170Z,10,2,1108,C,A,10,13.600000000,100,310446249,165455,261713790,13.31,10,1,13.28,11,2,13.14,1,1,13.13,100,1,13.11,100,1,13.10,100,1,13.04,2,1,13.02,100,1,12.99,100,1,12.73,100,1,13.40,0,-10,13.59,0,-1,13.60,0,-1,13.63,0,-1,13.64,0,-2,13.66,0,-2,13.67,0,-1,13.68,0,-2,13.69,0,-2,13.70,0,-3,ARL,0
2025-07-17T15:52:16.373188791Z,2025-07-17T15:52:16.373023186Z,10,2,1108,C,A,10,14.650000000,100,310446269,165605,261713830,13.31,10,1,13.28,11,2,13.14,1,1,13.13,100,1,13.11,100,1,13.10,100,1,13.04,2,1,13.02,100,1,12.99,100,1,12.73,100,1,13.40,0,-10,13.59,0,-1,13.60,0,-1,13.63,0,-1,13.64,0,-2,13.66,0,-2,13.67,0,-1,13.68,0,-2,13.69,0,-2,13.70,0,-3,ARL,0
2025-07-17T15:52:16.373188791Z,2025-07-17T15:52:16.373023186Z,10,2,1108,A,A,10,14.700000000,100,312771573,165605,261713830,13.31,10,1,13.28,11,2,13.14,1,1,13.13,100,1,13.11,100,1,13.10,100,1,13.04,2,1,13.02,100,1,12.99,100,1,12.73,100,1,13.40,0,-10,13.59,0,-1,13.60,0,-1,13.63,0,-1,13.64,0,-2,13.66,0,-2,13.67,0,-1,13.68,0,-2,13.69,0,-2,13.70,0,-3,ARL,0
2025-07-17T15:52:16.374353159Z,2025-07-17T15:52:16.374186508Z,10,2,1108,C,A,10,13.640000000,100,310031625,166651,261713870,13.31,10,1,13.28,11,2,13.14,1,1,13.13,100,1,13.11,100,1,13.10,100,1,13.04,2,1,13.02,100,1,12.99,100,1,12.73,100,1,13.40,0,-10,13.59,0,-1,13.60,0,-1,13.63,0,-1,13.64,0,-2,13.66,0,-2,13.67,0,-1,13.68,0,-2,13.69,0,-2,13.70,0,-3,ARL,0
2025-07-17T15:52:16.374480183Z,2025-07-17T15:52:16.374312976Z,10,2,1108,A,A,10,15.860000000,100,312771645,167207,261713880,13.31,10,1,13.28,11,2,13.14,1,1,13.13,100,1,13.11,100,1,13.10,100,1,13.04,2,1,13.02,100,1,12.99,100,1,12.73,100,1,13.40,0,-10,13.59,0,-1,13.60,0,-1,13.63,0,-1,13.64,0,-2,13.66,0,-2,13.67,0,-1,13.68,0,-2,13.69,0,-2,13.70,0,-3,ARL,0
2025-07-17T15:52:16.374493650Z,2025-07-17T15:52:16.374327668Z,10,2,1108,C,A,10,15.510000000,100,310447441,165982,261713884,13.31,10,1,13.28,11,2,13.14,1,1,13.13,100,1,13.11,100,1,13.10,100,1,13.04,2,1,13.02,100,1,12.99,100,1,12.73,100,1,13.40,0,-10,13.59,0,-1,13.60,0,-1,13.63,0,-1,13.64,0,-2,13.66,0,-2,13.67,0,-1,13.68,0,-2,13.69,0,-2,13.70,0,-3,ARL,0
2025-07-17T15:52:16.375388285Z,2025-07-17T15:52:16.375222836Z,10,2,1108,C,A,10,14.540000000,100,309823025,165449,261713944,13.31,10,1,13.28,11,2,13.14,1,1,13.13,100,1,13.11,100,1,13.10,100,1,13.04,2,1,13.02,100,1,12.99,100,1,12.73,100,1,13.40,0,-10,13.59,0,-1,13.60,0,-1,13.63,0,-1,13.64,0,-2,13.66,0,-2,13.67,0,-1,13.68,0,-2,13.69,0,-2,13.70,0,-3,ARL,0
2025-07-17T15:52:16.375388285Z,2025-07-17T15:52:16.375222836Z,10,2,1108,A,A,10,14.810000000,100,312771781,165449,261713944,13.31,10,1,13.28,11,2,13.14,1,1,13.13,100,1,13.11,100,1,13.10,100,1,13.04,2,1,13.02,100,1,12.99,100,1,12.73,100,1,13.40,0,-10,13.59,0,-1,13.60,0,-1,13.63,0,-1,13.64,0,-2,13.66,0,-2,13.67,0,-1,13.68,0,-2,13.69,0,-2,13.70,0,-3,ARL,0
2025-07-17T15:52:16.375414247Z,2025-07-17T15:52:16.375248654Z,10,2,1108,C,A,10,14.660000000,100,308901981,165593,261713945,13.31,10,1,13.28,11,2,13.14,1,1,13.13,100,1,13.11,100,1,13.10,100,1,13.04,2,1,13.02,100,1,12.99,100,1,12.73,100,1,13.40,0,-10,13.59,0,-1,13.60,0,-1,13.63,0,-1,13.64,0,-2,13.66,0,-2,13.67,0,-1,13.68,0,-2,13.69,0,-2,13.70,0,-3,ARL,0
2025-07-17T15:52:16.375414247Z,2025-07-17T15:52:16.375248654Z,10,2,1108,A,A,10,14.890000000,100,312771785,165593,261713945,13.31,10,1,13.28,11,2,13.14,1,1,13.13,100,1,13.11,100,1,13.10,100,1,13.04,2,1,13.02,100,1,12.99,100,1,12.73,100,1,13.40,0,-10,13.59,0,-1,13.60,0,-1,13.63,0,-1,13.64,0,-2,13.66,0,-2,13.67,0,-1,13.68,0,-2,13.69,0,-2,13.70,0,-3,ARL,0
2025-07-17T15:52:16.375828154Z,2025-07-17T15:52:16.375662552Z,10,2,1108,C,A,10,14.530000000,100,309899141,165602,261713959,13.31,10,1,13.28,11,2,13.14,1,1,13.13,100,1,13.11,100,1,13.10,100,1,13.04,2,1,13.02,100,1,12.99,100,1,12.73,100,1,13.40,0,-10,13.59,0,-1,13.60,0,-1,13.63,0,-1,13.64,0,-2,13.66,0,-2,13.67,0,-1,13.68,0,-2,13.69,0,-2,13.70,0,-3,ARL,0
2025-07-17T15:52:16.375828154Z,2025-07-17T15:52:16.375662552Z,10,2,1108,A,A,10,14.760000000,100,312771829,165602,261713959,13.31,10,1,13.28,11,2,13.14,1,1,13.13,100,1,13.11,100,1,13.10,100,1,13.04,2,1,13.02,100,1,12.99,100,1,12.73,100,1,13.40,0,-10,13.59,0,-1,13.60,0,-1,13.63,0,-1,13.64,0,-2,13.66,0,-2,13.67,0,-1,13.68,0,-2,13.69,0,-2,13.70,0,-3,ARL,0
2025-07-17T15:52:16.377345053Z,2025-07-17T15:52:16.377179230Z,10,2,1108,C,A,10,17.280000000,100,310446293,165823,261714104,13.31,10,1,13.28,11,2,13.14,1,1,13.13,100,1,13.11,100,1,13.10,100,1,13.04,2,1,13.02,100,1,12.99,100,1,12.73,100,1,13.40,0,-10,13.59,0,-1,13.60,0,-1,13.63,0,-1,13.64,0,-2,13.66,0,-2,13.67,0,-1,13.68,0,-2,13.69,0,-2,13.70,0,-3,ARL,0
2025-07-17T15:52:16.377345053Z,2025-07-17T15:52:16.377179230Z,10,2,1108,A,A,10,17.700000000,100,312772009,165823,261714104,13.31,10,1,13.28,11,2,13.14,1,1,13.13,100,1,13.11,100,1,13.10,100,1,13.04,2,1,13.02,100,1,12.99,100,1,12.73,100,1,13.40,0,-10,13.59,0,-1,13.60,0,-1,13.63,0,-1,13.64,0,-2,13.66,0,-2,13.67,0,-1,13.68,0,-2,13.69,0,-2,13.70,0,-3,ARL,0
2025-07-17T15:52:16.378239114Z,2025-07-17T15:52:16.378073674Z,10,2,1108,C,A,10,15.760000000,100,308902229,165440,261714140,13.31,10,1,13.28,11,2,13.14,1,1,13.13,100,1,13.11,100,1,13.10,100,1,13.04,2,1,13.02,100,1,12.99,100,1,12.73,100,1,13.40,0,-10,13.59,0,-1,13.60,0,-1,13.63,0,-1,13.64,0,-2,13.66,0,-2,13.67,0,-1,13.68,0,-2,13.69,0,-2,13.70,0,-3,ARL,0
2025-07-17T15:52:16.378239114Z,2025-07-17T15:52:16.378073674Z,10,2,1108,A,A,10,16.020000000,100,312772057,165440,261714140,13.31,10,1,13.28,11,2,13.14,1,1,13.13,100,1,13.11,100,1,13.10,100,1,13.04,2,1,13.02,100,1,12.99,100,1,12.73,100,1,13.40,0,-10,13.59,0,-1,13.60,0,-1,13.63,0,-1,13.64,0,-2,13.66,0,-2,13.67,0,-1,13.68,0,-2,13.69,0,-2,13.70,0,-3,ARL,0
2025-07-17T15:52:16.378385943Z,2025-07-17T15:52:16.378220434Z,10,2,1108,C,A,10,14.500000000,100,308903349,165509,261714145,13.31,10,1,13.28,11,2,13.14,1,1,13.13,100,1,13.11,100,1,13.10,100,1,13.04,2,1,13.02,100,1,12.99,100,1,12.73,100,1,13.40,0,-10,13.59,0,-1,13.60,0,-1,13.63,0,-1,13.64,0,-2,13.66,0,-2,13.67,0,-1,13.68,0,-2,13.69,0,-2,13.70,0,-3,ARL,0
2025-07-17T15:52:16.378385943Z,2025-07-17T15:52:16.378220434Z,10,2,1108,A,A,10,14.720000000,100,312772061,165509,261714145,13.31,10,1,13.28,11,2,13.14,1,1,13.13,100,1,13.11,100,1,13.10,100,1,13.04,2,1,13.02,100,1,12.99,100,1,12.73,100,1,13.40,0,-10,13.59,0,-1,13.60,0,-1,13.63,0,-1,13.64,0,-2,13.66,0,-2,13.67,0,-1,13.68,0,-2,13.69,0,-2,13.70,0,-3,ARL,0
2025-07-17T15:52:16.378870638Z,2025-07-17T15:52:16.378705201Z,10,2,1108,A,B,10,13.270000000,10,312772069,165437,261714171,13.31,10,1,13.28,11,2,13.27,10,1,13.14,1,1,13.13,100,1,13.11,100,1,13.10,100,1,13.04,2,1,13.02,100,1,12.99,100,1,13.40,0,-10,13.59,0,-1,13.60,0,-1,13.63,0,-1,13.64,0,-2,13.66,0,-2,13.67,0,-1,13.68,0,-2,13.69,0,-2,13.70,0,-3,ARL,0
2025-07-17T15:52:16.378872385Z,2025-07-17T15:52:16.378707041Z,10,2,1108,A,A,10,13.860000000,15,312772073,165344,261714172,13.31,10,1,13.28,11,2,13.27,10,1,13.14,1,1,13.13,100,1,13.11,100,1,13.10,100,1,13.04,2,1,13.02,100,1,12.99,100,1,13.40,0,-10,13.59,0,-1,13.60,0,-1,13.63,0,-1,13.64,0,-2,13.66,0,-2,13.67,0,-1,13.68,0,-2,13.69,0,-2,13.70,0,-3,ARL,0
2025-07-17T15:52:16.379127782Z,2025-07-17T15:52:16.378962330Z,10,2,1108,C,B,10,13.020000000,100,309415429,165452,261714185,13.31,10,1,13.28,11,2,13.27,10,1,13.14,1,1,13.13,100,1,13.11,100,1,13.10,100,1,13.04,2,1,13.02,100,1,12.99,100,1,13.40,0,-10,13.59,0,-1,13.60,0,-1,13.63,0,-1,13.64,0,-2,13.66,0,-2,13.67,0,-1,13.68,0,-2,13.69,0,-2,13.70,0,-3,ARL,0
2025-07-17T15:52:16.379127782Z,2025-07-17T15:52:16.378962330Z,10,2,1108,A,B,10,13.260000000,100,312772077,165452,261714185,13.31,10,1,13.28,11,2,13.27,10,1,13.26,100,1,13.14,1,1,13.13,100,1,13.11,100,1,13.10,100,1,13.04,2,1,13.02,100,1,13.40,0,-10,13.59,0,-1,13.60,0,-1,13.63,0,-1,13.64,0,-2,13.66,0,-2,13.67,0,-1,13.68,0,-2,13.69,0,-2,13.70,0,-3,ARL,0
2025-07-17T15:52:16.389025469Z,2025-07-17T15:52:16.388859982Z,10,2,1108,C,A,10,13.930000000,100,309782973,165487,261714477,13.31,10,1,13.28,11,2,13.27,10,1,13.14,1,1,13.13,100,1,13.11,100,1,13.10,100,1,13.04,2,1,13.02,100,1,12.99,100,1,13.40,0,-10,13.59,0,-1,13.60,0,-1,13.63,0,-1,13.64,0,-2,13.66,0,-2,13.67,0,-1,13.68,0,-2,13.69,0,-2,13.70,0,-3,ARL,0
2025-07-17T15:52:16.389082451Z,2025-07-17T15:52:16.388917108Z,10,2,1108,A,A,10,14.190000000,100,312772501,165343,261714481,13.31,10,1,13.28,11,2,13.27,10,1,13.14,1,1,13.13,100,1,13.11,100,1,13.10,100,1,13.04,2,1,13.02,100,1,12.99,100,1,13.40,0,-10,13.59,0,-1,13.60,0,-1,13.63,0,-1,13.64,0,-2,13.66,0,-2,13.67,0,-1,13.68,0,-2,13.69,0,-2,13.70,0,-3,ARL,0
2025-07-17T15:52:16.396174502Z,2025-07-17T15:52:16.396008715Z,10,2,1108,C,A,10,14.660000000,100,308903001,165787,261714603,13.31,10,1,13.28,11,2,13.27,10,1,13.14,1,1,13.13,100,1,13.11,100,1,13.10,100,1,13.04,2,1,13.02,100,1,12.99,100,1,13.40,0,-10,13.59,0,-1,13.60,0,-1,13.63,0,-1,13.64,0,-2,13.66,0,-2,13.67,0,-1,13.68,0,-2,13.69,0,-2,13.70,0,-3,ARL,0
2025-07-17T15:52:16.396174502Z,2025-07-17T15:52:16.396008715Z,10,2,1108,A,A,10,14.960000000,100,312772869,165787,261714603,13.31,10,1,13.28,11,2,13.27,10,1,13.14,1,1,13.13,100,1,13.11,100,1,13.10,100,1,13.04,2,1,13.02,100,1,12.99,100,1,13.40,0,-10,13.59,0,-1,13.60,0,-1,13.63,0,-1,13.64,0,-2,13.66,0,-2,13.67,0,-1,13.68,0,-2,13.69,0,-2,13.70,0,-3,ARL,0
2025-07-17T15:52:16.397677681Z,2025-07-17T15:52:16.397512710Z,10,2,1108,C,A,10,14.190000000,100,312772501,164971,261714619,13.31,10,1,13.28,11,2,13.27,10,1,13.14,1,1,13.13,100,1,13.11,100,1,13.10,100,1,13.04,2,1,13.02,100,1,12.99,100,1,13.40,0,-10,13.59,0,-1,13.60,0,-1,13.63,0,-1,13.64,0,-2,13.66,0,-2,13.67,0,-1,13.68,0,-2,13.69,0,-2,13.70,0,-3,ARL,0
2025-07-17T15:52:16.397727042Z,2025-07-17T15:52:16.397561691Z,10,2,1108,A,A,10,14.260000000,100,312772901,165351,261714620,13.31,10,1,13.28,11,2,13.27,10,1,13.14,1,1,13.13,100,1,13.11,100,1,13.10,100,1,13.04,2,1,13.02,100,1,12.99,100,1,13.40,0,-10,13.59,0,-1,13.60,0,-1,13.63,0,-1,13.64,0,-2,13.66,0,-2,13.67,0,-1,13.68,0,-2,13.69,0,-2,13.70,0,-3,ARL,0
2025-07-17T15:52:16.424137423Z,2025-07-17T15:52:16.423972000Z,10,2,1108,C,A,10,14.700000000,100,312771573,165423,261714976,13.31,10,1,13.28,11,2,13.27,10,1,13.14,1,1,13.13,100,1,13.11,100,1,13.10,100,1,13.04,2,1,13.02,100,1,12.99,100,1,13.40,0,-10,13.59,0,-1,13.60,0,-1,13.63,0,-1,13.64,0,-2,13.66,0,-2,13.67,0,-1,13.68,0,-2,13.69,0,-2,13.70,0,-3,ARL,0
2025-07-17T15:52:16.424137423Z,2025-07-17T15:52:16.423972000Z,10,2,1108,A,A,10,15.060000000,100,312773353,165423,261714976,13.31,10,1,13.28,11,2,13.27,10,1,13.14,1,1,13.13,100,1,13.11,100,1,13.10,100,1,13.04,2,1,13.02,100,1,12.99,100,1,13.40,0,-10,13.59,0,-1,13.60,0,-1,13.63,0,-1,13.64,0,-2,13.66,0,-2,13.67,0,-1,13.68,0,-2,13.69,0,-2,13.70,0,-3,ARL,0
2025-07-17T15:52:16.464781343Z,2025-07-17T15:52:16.464616142Z,10,2,1108,A,A,10,13.870000000,100,312773881,165201,261715303,13.31,10,1,13.28,11,2,13.27,10,1,13.14,1,1,13.13,100,1,13.11,100,1,13.10,100,1,13.04,2,1,13.02,100,1,12.99,100,1,13.40,0,-10,13.59,0,-1,13.60,0,-1,13.63,0,-1,13.64,0,-2,13.66,0,-2,13.67,0,-1,13.68,0,-2,13.69,0,-2,13.70,0,-3,ARL,0
2025-07-17T15:52:16.473556948Z,2025-07-17T15:52:16.473391480Z,10,2,1108,C,A,10,15.060000000,100,312773353,165468,261715409,13.31,10,1,13.28,11,2,13.27,10,1,13.14,1,1,13.13,100,1,13.11,100,1,13.10,100,1,13.04,2,1,13.02,100,1,12.99,100,1,13.40,0,-10,13.59,0,-1,13.60,0,-1,13.63,0,-1,13.64,0,-2,13.66,0,-2,13.67,0,-1,13.68,0,-2,13.69,0,-2,13.70,0,-3,ARL,0
2025-07-17T15:52:16.473556948Z,2025-07-17T15:52:16.473391480Z,10,2,1108,A,A,10,14.950000000,100,312774001,165468,261715409,13.31,10,1,13.28,11,2,13.27,10,1,13.14,1,1,13.13,100,1,13.11,100,1,13.10,100,1,13.04,2,1,13.02,100,1,12.99,100,1,13.40,0,-10,13.59,0,-1,13.60,0,-1,13.63,0,-1,13.64,0,-2,13.66,0,-2,13.67,0,-1,13.68,0,-2,13.69,0,-2,13.70,0,-3,ARL,0
2025-07-17T15:52:16.480090894Z,2025-07-17T15:52:16.479925781Z,10,2,1108,C,A,10,14.260000000,100,312772901,165113,261715467,13.31,10,1,13.28,11,2,13.27,10,1,13.14,1,1,13.13,100,1,13.11,100,1,13.10,100,1,13.04,2,1,13.02,100,1,12.99,100,1,13.40,0,-10,13.59,0,-1,13.60,0,-1,13.63,0,-1,13.64,0,-2,13.66,0,-2,13.67,0,-1,13.68,0,-2,13.69,0,-2,13.70,0,-3,ARL,0
2025-07-17T15:52:16.480140131Z,2025-07-17T15:52:16.479974840Z,10,2,1108,A,A,10,14.150000000,100,312774033,165291,261715468,13.31,10,1,13.28,11,2,13.27,10,1,13.14,1,1,13.13,100,1,13.11,100,1,13.10,100,1,13.04,2,1,13.02,100,1,12.99,100,1,13.40,0,-10,13.59,0,-1,13.60,0,-1,13.63,0,-1,13.64,0,-2,13.66,0,-2,13.67,0,-1,13.68,0,-2,13.69,0,-2,13.70,0,-3,ARL,0
2025-07-17T15:52:28.787316865Z,2025-07-17T15:52:28.787151494Z,10,2,1108,C,B,10,13.270000000,10,312772069,165371,261883294,13.31,10,1,13.28,11,2,13.27,10,1,13.14,1,1,13.13,100,1,13.11,100,1,13.10,100,1,13.04,2,1,13.02,100,1,12.99,100,1,13.40,0,-10,13.59,0,-1,13.60,0,-1,13.63,0,-1,13.64,0,-2,13.66,0,-2,13.67,0,-1,13.68,0,-2,13.69,0,-2,13.70,0,-3,ARL,0
2025-07-17T15:52:28.787317827Z,2025-07-17T15:52:28.787152437Z,10,2,1108,C,A,10,13.860000000,15,312772073,165390,261883295,13.31,10,1,13.28,11,2,13.27,10,1,13.14,1,1,13.13,100,1,13.11,100,1,13.10,100,1,13.04,2,1,13.02,100,1,12.99,100,1,13.40,0,-10,13.59,0,-1,13.60,0,-1,13.63,0,-1,13.64,0,-2,13.66,0,-2,13.67,0,-1,13.68,0,-2,13.69,0,-2,13.70,0,-3,ARL,0
2025-07-17T15:52:43.128371033Z,2025-07-17T15:52:43.128203357Z,10,2,1108,C,A,10,13.890000000,2,311979125,167676,262115170,13.31,10,1,13.28,11,2,13.27,10,1,13.14,1,1,13.13,100,1,13.11,100,1,13.10,100,1,13.04,2,1,13.02,100,1,12.99,100,1,13.40,0,-10,13.59,0,-1,13.60,0,-1,13.63,0,-1,13.64,0,-2,13.66,0,-2,13.67,0,-1,13.68,0,-2,13.69,0,-2,13.70,0,-3,ARL,0
2025-07-17T15:52:43.128371033Z,2025-07-17T15:52:43.128203357Z,10,2,1108,A,A,10,13.990000000,2,313336713,167676,262115170,13.31,10,1,13.28,11,2,13.27,10,1,13.14,1,1,13.13,100,1,13.11,100,1,13.10,100,1,13.04,2,1,13.02,100,1,12.99,100,1,13.40,0,-10,13.59,0,-1,13.60,0,-1,13.63,0,-1,13.64,0,-2,13.66,0,-2,13.67,0,-1,13.68,0,-2,13.69,0,-2,13.70,0,-3,ARL,0
2025-07-17T15:54:24.908483782Z,2025-07-17T15:54:24.908318259Z,10,2,1108,A,B,10,13.290000000,10,315581981,165523,263863872,13.31,10,1,13.29,10,1,13.28,11,2,13.27,10,1,13.14,1,1,13.13,100,1,13.11,100,1,13.10,100,1,13.04,2,1,13.02,100,1,13.40,0,-10,13.59,0,-1,13.60,0,-1,13.63,0,-1,13.64,0,-2,13.66,0,-2,13.67,0,-1,13.68,0,-2,13.69,0,-2,13.70,0,-3,ARL,0
2025-07-17T15:54:26.792478456Z,2025-07-17T15:54:26.792313320Z,10,2,1108,C,B,10,13.290000000,10,315581981,165136,263895481,13.31,10,1,13.28,11,2,13.27,10,1,13.14,1,1,13.13,100,1,13.11,100,1,13.10,100,1,13.04,2,1,13.02,100,1,12.99,100,1,13.40,0,-10,13.59,0,-1,13.60,0,-1,13.63,0,-1,13.64,0,-2,13.66,0,-2,13.67,0,-1,13.68,0,-2,13.69,0,-2,13.70,0,-3,ARL,0
2025-07-17T15:54:52.986116083Z,2025-07-17T15:54:52.985950259Z,10,2,1108,C,A,10,13.990000000,2,313336713,165824,264262615,13.31,10,1,13.28,11,2,13.27,10,1,13.14,1,1,13.13,100,1,13.11,100,1,13.10,100,1,13.04,2,1,13.02,100,1,12.99,100,1,13.40,0,-10,13.59,0,-1,13.60,0,-1,13.63,0,-1,13.64,0,-2,13.66,0,-2,13.67,0,-1,13.68,0,-2,13.69,0,-2,13.70,0,-3,ARL,0
2025-07-17T15:54:52.986116083Z,2025-07-17T15:54:52.985950259Z,10,2,1108,A,A,10,14.100000000,2,316098525,165824,264262615,13.31,10,1,13.28,11,2,13.27,10,1,13.14,1,1,13.13,100,1,13.11,100,1,13.10,100,1,13.04,2,1,13.02,100,1,12.99,100,1,13.40,0,-10,13.59,0,-1,13.60,0,-1,13.63,0,-1,13.64,0,-2,13.66,0,-2,13.67,0,-1,13.68,0,-2,13.69,0,-2,13.70,0,-3,ARL,0
2025-07-17T15:55:33.673598252Z,2025-07-17T15:55:33.673432762Z,10,2,1108,A,B,10,13.290000000,10,316911465,165490,264905534,13.31,10,1,13.29,10,1,13.28,11,2,13.27,10,1,13.14,1,1,13.13,100,1,13.11,100,1,13.10,100,1,13.04,2,1,13.02,100,1,13.40,0,-10,13.59,0,-1,13.60,0,-1,13.63,0,-1,13.64,0,-2,13.66,0,-2,13.67,0,-1,13.68,0,-2,13.69,0,-2,13.70,0,-3,ARL,0
2025-07-17T15:55:34.257417204Z,2025-07-17T15:55:34.257251787Z,10,2,1108,C,B,10,13.260000000,100,312772077,165417,264919835,13.31,10,1,13.28,11,2,13.27,10,1,13.14,1,1,13.13,100,1,13.11,100,1,13.10,100,1,13.04,2,1,13.02,100,1,12.99,100,1,13.40,0,-10,13.59,0,-1,13.60,0,-1,13.63,0,-1,13.64,0,-2,13.66,0,-2,13.67,0,-1,13.68,0,-2,13.69,0,-2,13.70,0,-3,ARL,0
2025-07-17T15:55:34.257417204Z,2025-07-17T15:55:34.257251787Z,10,2,1108,A,B,10,13.280000000,100,316924721,165417,264919835,13.31,10,1,13.28,111,3,13.27,10,1,13.14,1,1,13.13,100,1,13.11,100,1,13.10,100,1,13.04,2,1,13.02,100,1,12.99,100,1,13.40,0,-10,13.59,0,-1,13.60,0,-1,13.63,0,-1,13.64,0,-2,13.66,0,-2,13.67,0,-1,13.68,0,-2,13.69,0,-2,13.70,0,-3,ARL,0
2025-07-17T15:55:40.197750400Z,2025-07-17T15:55:40.197584524Z,10,2,1108,C,B,10,13.290000000,10,316911465,165876,265015966,13.31,10,1,13.28,101,3,13.27,10,1,13.14,1,1,13.13,100,1,13.11,100,1,13.10,100,1,13.04,2,1,13.02,100,1,12.99,100,1,13.40,0,-10,13.59,0,-1,13.60,0,-1,13.63,0,-1,13.64,0,-2,13.66,0,-2,13.67,0,-1,13.68,0,-2,13.69,0,-2,13.70,0,-3,ARL,0
2025-07-17T15:57:51.328863560Z,2025-07-17T15:57:51.328698198Z,10,2,1108,C,A,10,13.870000000,100,312773881,165362,267272430,13.31,10,1,13.28,1,2,13.27,10,1,13.14,1,1,13.13,100,1,13.11,100,1,13.10,100,1,13.04,2,1,13.02,100,1,12.99,100,1,13.40,0,-10,13.59,0,-1,13.60,0,-1,13.63,0,-1,13.64,0,-2,13.66,0,-2,13.67,0,-1,13.68,0,-2,13.69,0,-2,13.70,0,-3,ARL,0
2025-07-17T15:57:51.329613584Z,2025-07-17T15:57:51.329447325Z,10,2,1108,C,A,10,14.950000000,100,312774001,166259,267272438,13.31,10,1,13.28,1,2,13.27,10,1,13.14,1,1,13.13,100,1,13.11,100,1,13.10,100,1,13.04,2,1,13.02,100,1,12.99,100,1,13.40,0,-10,13.59,0,-1,13.60,0,-1,13.63,0,-1,13.64,0,-2,13.66,0,-2,13.67,0,-1,13.68,0,-2,13.69,0,-2,13.70,0,-3,ARL,0
2025-07-17T15:57:51.329613584Z,2025-07-17T15:57:51.329447325Z,10,2,1108,A,A,10,15.000000000,100,319985021,166259,267272438,13.31,10,1,13.28,1,2,13.27,10,1,13.14,1,1,13.13,100,1,13.11,100,1,13.10,100,1,13.04,2,1,13.02,100,1,12.99,100,1,13.40,0,-10,13.59,0,-1,13.60,0,-1,13.63,0,-1,13.64,0,-2,13.66,0,-2,13.67,0,-1,13.68,0,-2,13.69,0,-2,13.70,0,-3,ARL,0
2025-07-17T15:57:51.329857672Z,2025-07-17T15:57:51.329692071Z,10,2,1108,C,A,10,14.760000000,100,312771829,165601,267272442,13.31,10,1,13.28,1,2,13.27,10,1,13.14,1,1,13.13,100,1,13.11,100,1,13.10,100,1,13.04,2,1,13.02,100,1,12.99,100,1,13.40,0,-10,13.59,0,-1,13.60,0,-1,13.63,0,-1,13.64,0,-2,13.66,0,-2,13.67,0,-1,13.68,0,-2,13.69,0,-2,13.70,0,-3,ARL,0
2025-07-17T15:57:51.329857672Z,2025-07-17T15:57:51.329692071Z,10,2,1108,A,A,10,14.890000000,100,319985025,165601,267272442,13.31,10,1,13.28,1,2,13.27,10,1,13.14,1,1,13.13,100,1,13.11,100,1,13.10,100,1,13.04,2,1,13.02,100,1,12.99,100,1,13.40,0,-10,13.59,0,-1,13.60,0,-1,13.63,0,-1,13.64,0,-2,13.66,0,-2,13.67,0,-1,13.68,0,-2,13.69,0,-2,13.70,0,-3,ARL,0
2025-07-17T15:57:51.339328219Z,2025-07-17T15:57:51.339162512Z,10,2,1108,C,A,10,14.150000000,100,312774033,165707,267272660,13.31,10,1,13.28,1,2,13.27,10,1,13.14,1,1,13.13,100,1,13.11,100,1,13.10,100,1,13.04,2,1,13.02,100,1,12.99,100,1,13.40,0,-10,13.59,0,-1,13.60,0,-1,13.63,0,-1,13.64,0,-2,13.66,0,-2,13.67,0,-1,13.68,0,-2,13.69,0,-2,13.70,0,-3,ARL,0
2025-07-17T15:57:51.339382098Z,2025-07-17T15:57:51.339216923Z,10,2,1108,A,A,10,14.260000000,100,319985165,165175,267272665,13.31,10,1,13.28,1,2,13.27,10,1,13.14,1,1,13.13,100,1,13.11,100,1,13.10,100,1,13.04,2,1,13.02,100,1,12.99,100,1,13.40,0,-10,13.59,0,-1,13.60,0,-1,13.63,0,-1,13.64,0,-2,13.66,0,-2,13.67,0,-1,13.68,0,-2,13.69,0,-2,13.70,0,-3,ARL,0
2025-07-17T15:57:51.379736852Z,2025-07-17T15:57:51.379570470Z,10,2,1108,C,A,10,15.000000000,100,319985021,166382,267273071,13.31,10,1,13.28,1,2,13.27,10,1,13.14,1,1,13.13,100,1,13.11,100,1,13.10,100,1,13.04,2,1,13.02,100,1,12.99,100,1,13.40,0,-10,13.59,0,-1,13.60,0,-1,13.63,0,-1,13.64,0,-2,13.66,0,-2,13.67,0,-1,13.68,0,-2,13.69,0,-2,13.70,0,-3,ARL,0
2025-07-17T15:57:51.379736852Z,2025-07-17T15:57:51.379570470Z,10,2,1108,A,A,10,15.060000000,100,319985497,166382,267273071,13.31,10,1,13.28,1,2,13.27,10,1,13.14,1,1,13.13,100,1,13.11,100,1,13.10,100,1,13.04,2,1,13.02,100,1,12.99,100,1,13.40,0,-10,13.59,0,-1,13.60,0,-1,13.63,0,-1,13.64,0,-2,13.66,0,-2,13.67,0,-1,13.68,0,-2,13.69,0,-2,13.70,0,-3,ARL,0
2025-07-17T15:57:52.378369524Z,2025-07-17T15:57:52.378204338Z,10,2,1108,A,A,10,14.110000000,100,320000233,165186,267283873,13.31,10,1,13.28,1,2,13.27,10,1,13.14,1,1,13.13,100,1,13.11,100,1,13.10,100,1,13.04,2,1,13.02,100,1,12.99,100,1,13.40,0,-10,13.59,0,-1,13.60,0,-1,13.63,0,-1,13.64,0,-2,13.66,0,-2,13.67,0,-1,13.68,0,-2,13.69,0,-2,13.70,0,-3,ARL,0
2025-07-17T15:58:14.483909354Z,2025-07-17T15:58:14.483743947Z,10,2,1108,A,A,10,13.760000000,4,320484625,165407,267657011,13.31,10,1,13.28,1,2,13.27,10,1,13.14,1,1,13.13,100,1,13.11,100,1,13.10,100,1,13.04,2,1,13.02,100,1,12.99,100,1,13.40,0,-10,13.59,0,-1,13.60,0,-1,13.63,0,-1,13.64,0,-2,13.66,0,-2,13.67,0,-1,13.68,0,-2,13.69,0,-2,13.70,0,-3,ARL,0
2025-07-17T15:58:14.484164551Z,2025-07-17T15:58:14.483999049Z,10,2,1108,C,A,10,14.110000000,100,320000233,165502,267657013,13.31,10,1,13.28,1,2,13.27,10,1,13.14,1,1,13.13,100,1,13.11,100,1,13.10,100,1,13.04,2,1,13.02,100,1,12.99,100,1,13.40,0,-10,13.59,0,-1,13.60,0,-1,13.63,0,-1,13.64,0,-2,13.66,0,-2,13.67,0,-1,13.68,0,-2,13.69,0,-2,13.70,0,-3,ARL,0
2025-07-17T15:58:14.484164551Z,2025-07-17T15:58:14.483999049Z,10,2,1108,A,A,10,13.770000000,100,320484637,165502,267657013,13.31,10,1,13.28,1,2,13.27,10,1,13.14,1,1,13.13,100,1,13.11,100,1,13.10,100,1,13.04,2,1,13.02,100,1,12.99,100,1,13.40,0,-10,13.59,0,-1,13.60,0,-1,13.63,0,-1,13.64,0,-2,13.66,0,-2,13.67,0,-1,13.68,0,-2,13.69,0,-2,13.70,0,-3,ARL,0
2025-07-17T15:58:14.484183413Z,2025-07-17T15:58:14.484017806Z,10,2,1108,C,B,10,13.280000000,100,316924721,165607,267657014,13.31,10,1,13.28,1,2,13.27,10,1,13.14,1,1,13.13,100,1,13.11,100,1,13.10,100,1,13.04,2,1,13.02,100,1,12.99,100,1,13.40,0,-10,13.59,0,-1,13.60,0,-1,13.63,0,-1,13.64,0,-2,13.66,0,-2,13.67,0,-1,13.68,0,-2,13.69,0,-2,13.70,0,-3,ARL,0
2025-07-17T15:58:14.484312532Z,2025-07-17T15:58:14.484147359Z,10,2,1108,A,A,10,13.790000000,100,320484661,165173,267657020,13.31,10,1,13.28,1,2,13.27,10,1,13.14,1,1,13.13,100,1,13.11,100,1,13.10,100,1,13.04,2,1,13.02,100,1,12.99,100,1,13.40,0,-10,13.59,0,-1,13.60,0,-1,13.63,0,-1,13.64,0,-2,13.66,0,-2,13.67,0,-1,13.68,0,-2,13.69,0,-2,13.70,0,-3,ARL,0
2025-07-17T15:58:14.484902175Z,2025-07-17T15:58:14.484736787Z,10,2,1108,C,A,10,15.060000000,100,319985497,165388,267657063,13.31,10,1,13.28,1,2,13.27,10,1,13.14,1,1,13.13,100,1,13.11,100,1,13.10,100,1,13.04,2,1,13.02,100,1,12.99,100,1,13.40,0,-10,13.59,0,-1,13.60,0,-1,13.63,0,-1,13.64,0,-2,13.66,0,-2,13.67,0,-1,13.68,0,-2,13.69,0,-2,13.70,0,-3,ARL,0
2025-07-17T15:58:14.484902175Z,2025-07-17T15:58:14.484736787Z,10,2,1108,A,A,10,14.840000000,100,320484709,165388,267657063,13.31,10,1,13.28,1,2,13.27,10,1,13.14,1,1,13.13,100,1,13.11,100,1,13.10,100,1,13.04,2,1,13.02,100,1,12.99,100,1,13.40,0,-10,13.59,0,-1,13.60,0,-1,13.63,0,-1,13.64,0,-2,13.66,0,-2,13.67,0,-1,13.68,0,-2,13.69,0,-2,13.70,0,-3,ARL,0
2025-07-17T15:58:14.484927848Z,2025-07-17T15:58:14.484761664Z,10,2,1108,C,A,10,13.760000000,4,320484625,166184,267657070,13.31,10,1,13.28,1,2,13.27,10,1,13.14,1,1,13.13,100,1,13.11,100,1,13.10,100,1,13.04,2,1,13.02,100,1,12.99,100,1,13.40,0,-10,13.59,0,-1,13.60,0,-1,13.63,0,-1,13.64,0,-2,13.66,0,-2,13.67,0,-1,13.68,0,-2,13.69,0,-2,13.70,0,-3,ARL,0
2025-07-17T15:58:14.484963870Z,2025-07-17T15:58:14.484798779Z,10,2,1108,C,A,10,13.770000000,100,320484637,165091,267657073,13.31,10,1,13.28,1,2,13.27,10,1,13.14,1,1,13.13,100,1,13.11,100,1,13.10,100,1,13.04,2,1,13.02,100,1,12.99,100,1,13.40,0,-10,13.59,0,-1,13.60,0,-1,13.63,0,-1,13.64,0,-2,13.66,0,-2,13.67,0,-1,13.68,0,-2,13.69,0,-2,13.70,0,-3,ARL,0
2025-07-17T15:58:14.485392903Z,2025-07-17T15:58:14.485227487Z,10,2,1108,C,A,10,14.810000000,100,312771781,165416,267657092,13.31,10,1,13.28,1,2,13.27,10,1,13.14,1,1,13.13,100,1,13.11,100,1,13.10,100,1,13.04,2,1,13.02,100,1,12.99,100,1,13.40,0,-10,13.59,0,-1,13.60,0,-1,13.63,0,-1,13.64,0,-2,13.66,0,-2,13.67,0,-1,13.68,0,-2,13.69,0,-2,13.70,0,-3,ARL,0
2025-07-17T15:58:14.485392903Z,2025-07-17T15:58:14.485227487Z,10,2,1108,A,A,10,14.680000000,100,320484781,165416,267657092,13.31,10,1,13.28,1,2,13.27,10,1,13.14,1,1,13.13,100,1,13.11,100,1,13.10,100,1,13.04,2,1,13.02,100,1,12.99,100,1,13.40,0,-10,13.59,0,-1,13.60,0,-1,13.63,0,-1,13.64,0,-2,13.66,0,-2,13.67,0,-1,13.68,0,-2,13.69,0,-2,13.70,0,-3,ARL,0
2025-07-17T15:58:14.485831602Z,2025-07-17T15:58:14.485666254Z,10,2,1108,C,A,10,16.020000000,100,312772057,165348,267657097,13.31,10,1,13.28,1,2,13.27,10,1,13.14,1,1,13.13,100,1,13.11,100,1,13.10,100,1,13.04,2,1,13.02,100,1,12.99,100,1,13.40,0,-10,13.59,0,-1,13.60,0,-1,13.63,0,-1,13.64,0,-2,13.66,0,-2,13.67,0,-1,13.68,0,-2,13.69,0,-2,13.70,0,-3,ARL,0
2025-07-17T15:58:14.485831602Z,2025-07-17T15:58:14.485666254Z,10,2,1108,A,A,10,15.860000000,100,320484817,165348,267657097,13.31,10,1,13.28,1,2,13.27,10,1,13.14,1,1,13.13,100,1,13.11,100,1,13.10,100,1,13.04,2,1,13.02,100,1,12.99,100,1,13.40,0,-10,13.59,0,-1,13.60,0,-1,13.63,0,-1,13.64,0,-2,13.66,0,-2,13.67,0,-1,13.68,0,-2,13.69,0,-2,13.70,0,-3,ARL,0
2025-07-17T15:58:14.485850874Z,2025-07-17T15:58:14.485685308Z,10,2,1108,C,A,10,14.960000000,100,312772869,165566,267657098,13.31,10,1,13.28,1,2,13.27,10,1,13.14,1,1,13.13,100,1,13.11,100,1,13.10,100,1,13.04,2,1,13.02,100,1,12.99,100,1,13.40,0,-10,13.59,0,-1,13.60,0,-1,13.63,0,-1,13.64,0,-2,13.66,0,-2,13.67,0,-1,13.68,0,-2,13.69,0,-2,13.70,0,-3,ARL,0
2025-07-17T15:58:14.485850874Z,2025-07-17T15:58:14.485685308Z,10,2,1108,A,A,10,14.760000000,100,320484821,165566,267657098,13.31,10,1,13.28,1,2,13.27,10,1,13.14,1,1,13.13,100,1,13.11,100,1,13.10,100,1,13.04,2,1,13.02,100,1,12.99,100,1,13.40,0,-10,13.59,0,-1,13.60,0,-1,13.63,0,-1,13.64,0,-2,13.66,0,-2,13.67,0,-1,13.68,0,-2,13.69,0,-2,13.70,0,-3,ARL,0
2025-07-17T15:58:14.485989643Z,2025-07-17T15:58:14.485824228Z,10,2,1108,C,A,10,14.890000000,100,319985025,165415,267657101,13.31,10,1,13.28,1,2,13.27,10,1,13.14,1,1,13.13,100,1,13.11,100,1,13.10,100,1,13.04,2,1,13.02,100,1,12.99,100,1,13.40,0,-10,13.59,0,-1,13.60,0,-1,13.63,0,-1,13.64,0,-2,13.66,0,-2,13.67,0,-1,13.68,0,-2,13.69,0,-2,13.70,0,-3,ARL,0
2025-07-17T15:58:14.485989643Z,2025-07-17T15:58:14.485824228Z,10,2,1108,A,A,10,14.690000000,100,320484825,165415,267657101,13.31,10,1,13.28,1,2,13.27,10,1,13.14,1,1,13.13,100,1,13.11,100,1,13.10,100,1,13.04,2,1,13.02,100,1,12.99,100,1,13.40,0,-10,13.59,0,-1,13.60,0,-1,13.63,0,-1,13.64,0,-2,13.66,0,-2,13.67,0,-1,13.68,0,-2,13.69,0,-2,13.70,0,-3,ARL,0
2025-07-17T15:58:14.486406355Z,2025-07-17T15:58:14.486240860Z,10,2,1108,C,A,10,17.700000000,100,312772009,165495,267657116,13.31,10,1,13.28,1,2,13.27,10,1,13.14,1,1,13.13,100,1,13.11,100,1,13.10,100,1,13.04,2,1,13.02,100,1,12.99,100,1,13.40,0,-10,13.59,0,-1,13.60,0,-1,13.63,0,-1,13.64,0,-2,13.66,0,-2,13.67,0,-1,13.68,0,-2,13.69,0,-2,13.70,0,-3,ARL,0
2025-07-17T15:58:14.486406355Z,2025-07-17T15:58:14.486240860Z,10,2,1108,A,A,10,17.520000000,100,320484837,165495,267657116,13.31,10,1,13.28,1,2,13.27,10,1,13.14,1,1,13.13,100,1,13.11,100,1,13.10,100,1,13.04,2,1,13.02,100,1,12.99,100,1,13.40,0,-10,13.59,0,-1,13.60,0,-1,13.63,0,-1,13.64,0,-2,13.66,0,-2,13.67,0,-1,13.68,0,-2,13.69,0,-2,13.70,0,-3,ARL,0
2025-07-17T15:58:14.508177256Z,2025-07-17T15:58:14.508012098Z,10,2,1108,C,A,10,14.260000000,100,319985165,165158,267657330,13.31,10,1,13.28,1,2,13.27,10,1,13.14,1,1,13.13,100,1,13.11,100,1,13.10,100,1,13.04,2,1,13.02,100,1,12.99,100,1,13.40,0,-10,13.59,0,-1,13.60,0,-1,13.63,0,-1,13.64,0,-2,13.66,0,-2,13.67,0,-1,13.68,0,-2,13.69,0,-2,13.70,0,-3,ARL,0
2025-07-17T15:58:14.508227890Z,2025-07-17T15:58:14.508062605Z,10,2,1108,A,A,10,14.050000000,100,320484985,165285,267657333,13.31,10,1,13.28,1,2,13.27,10,1,13.14,1,1,13.13,100,1,13.11,100,1,13.10,100,1,13.04,2,1,13.02,100,1,12.99,100,1,13.40,0,-10,13.59,0,-1,13.60,0,-1,13.63,0,-1,13.64,0,-2,13.66,0,-2,13.67,0,-1,13.68,0,-2,13.69,0,-2,13.70,0,-3,ARL,0
2025-07-17T15:58:14.529557108Z,2025-07-17T15:58:14.529391743Z,10,2,1108,A,B,10,13.020000000,100,320485385,165365,267657561,13.31,10,1,13.28,1,2,13.27,10,1,13.14,1,1,13.13,100,1,13.11,100,1,13.10,100,1,13.04,2,1,13.02,200,2,12.99,100,1,13.40,0,-10,13.59,0,-1,13.60,0,-1,13.63,0,-1,13.64,0,-2,13.66,0,-2,13.67,0,-1,13.68,0,-2,13.69,0,-2,13.70,0,-3,ARL,0
2025-07-17T15:58:14.529578291Z,2025-07-17T15:58:14.529413184Z,10,2,1108,A,A,10,13.800000000,100,320485389,165107,267657562,13.31,10,1,13.28,1,2,13.27,10,1,13.14,1,1,13.13,100,1,13.11,100,1,13.10,100,1,13.04,2,1,13.02,200,2,12.99,100,1,13.40,0,-10,13.59,0,-1,13.60,0,-1,13.63,0,-1,13.64,0,-2,13.66,0,-2,13.67,0,-1,13.68,0,-2,13.69,0,-2,13.70,0,-3,ARL,0
2025-07-17T15:58:14.659899426Z,2025-07-17T15:58:14.659734381Z,10,2,1108,C,A,10,13.790000000,100,320484661,165045,267658873,13.31,10,1,13.28,1,2,13.27,10,1,13.14,1,1,13.13,100,1,13.11,100,1,13.10,100,1,13.04,2,1,13.02,200,2,12.99,100,1,13.40,0,-10,13.59,0,-1,13.60,0,-1,13.63,0,-1,13.64,0,-2,13.66,0,-2,13.67,0,-1,13.68,0,-2,13.69,0,-2,13.70,0,-3,ARL,0
2025-07-17T15:58:14.659939230Z,2025-07-17T15:58:14.659773896Z,10,2,1108,C,A,10,13.800000000,100,320485389,165334,267658879,13.31,10,1,13.28,1,2,13.27,10,1,13.14,1,1,13.13,100,1,13.11,100,1,13.10,100,1,13.04,2,1,13.02,200,2,12.99,100,1,13.40,0,-10,13.59,0,-1,13.60,0,-1,13.63,0,-1,13.64,0,-2,13.66,0,-2,13.67,0,-1,13.68,0,-2,13.69,0,-2,13.70,0,-3,ARL,0
2025-07-17T15:58:14.660667636Z,2025-07-17T15:58:14.660502341Z,10,2,1108,C,A,10,14.840000000,100,320484709,165295,267658892,13.31,10,1,13.28,1,2,13.27,10,1,13.14,1,1,13.13,100,1,13.11,100,1,13.10,100,1,13.04,2,1,13.02,200,2,12.99,100,1,13.40,0,-10,13.59,0,-1,13.60,0,-1,13.63,0,-1,13.64,0,-2,13.66,0,-2,13.67,0,-1,13.68,0,-2,13.69,0,-2,13.70,0,-3,ARL,0
2025-07-17T15:58:14.660667636Z,2025-07-17T15:58:14.660502341Z,10,2,1108,A,A,10,14.910000000,100,320486925,165295,267658892,13.31,10,1,13.28,1,2,13.27,10,1,13.14,1,1,13.13,100,1,13.11,100,1,13.10,100,1,13.04,2,1,13.02,200,2,12.99,100,1,13.40,0,-10,13.59,0,-1,13.60,0,-1,13.63,0,-1,13.64,0,-2,13.66,0,-2,13.67,0,-1,13.68,0,-2,13.69,0,-2,13.70,0,-3,ARL,0
2025-07-17T15:58:14.664378962Z,2025-07-17T15:58:14.664213722Z,10,2,1108,C,A,10,17.520000000,100,320484837,165240,267658928,13.31,10,1,13.28,1,2,13.27,10,1,13.14,1,1,13.13,100,1,13.11,100,1,13.10,100,1,13.04,2,1,13.02,200,2,12.99,100,1,13.40,0,-10,13.59,0,-1,13.60,0,-1,13.63,0,-1,13.64,0,-2,13.66,0,-2,13.67,0,-1,13.68,0,-2,13.69,0,-2,13.70,0,-3,ARL,0
2025-07-17T15:58:14.664378962Z,2025-07-17T15:58:14.664213722Z,10,2,1108,A,A,10,17.760000000,100,320486937,165240,267658928,13.31,10,1,13.28,1,2,13.27,10,1,13.14,1,1,13.13,100,1,13.11,100,1,13.10,100,1,13.04,2,1,13.02,200,2,12.99,100,1,13.40,0,-10,13.59,0,-1,13.60,0,-1,13.63,0,-1,13.64,0,-2,13.66,0,-2,13.67,0,-1,13.68,0,-2,13.69,0,-2,13.70,0,-3,ARL,0
2025-07-17T15:58:14.664939310Z,2025-07-17T15:58:14.664774078Z,10,2,1108,C,A,10,15.860000000,100,320484817,165232,267658931,13.31,10,1,13.28,1,2,13.27,10,1,13.14,1,1,13.13,100,1,13.11,100,1,13.10,100,1,13.04,2,1,13.02,200,2,12.99,100,1,13.40,0,-10,13.59,0,-1,13.60,0,-1,13.63,0,-1,13.64,0,-2,13.66,0,-2,13.67,0,-1,13.68,0,-2,13.69,0,-2,13.70,0,-3,ARL,0
2025-07-17T15:58:14.664939310Z,2025-07-17T15:58:14.664774078Z,10,2,1108,A,A,10,16.080000000,100,320486945,165232,267658931,13.31,10,1,13.28,1,2,13.27,10,1,13.14,1,1,13.13,100,1,13.11,100,1,13.10,100,1,13.04,2,1,13.02,200,2,12.99,100,1,13.40,0,-10,13.59,0,-1,13.60,0,-1,13.63,0,-1,13.64,0,-2,13.66,0,-2,13.67,0,-1,13.68,0,-2,13.69,0,-2,13.70,0,-3,ARL,0
2025-07-17T15:58:14.672315806Z,2025-07-17T15:58:14.672150755Z,10,2,1108,C,A,10,14.050000000,100,320484985,165051,267658982,13.31,10,1,13.28,1,2,13.27,10,1,13.14,1,1,13.13,100,1,13.11,100,1,13.10,100,1,13.04,2,1,13.02,200,2,12.99,100,1,13.40,0,-10,13.59,0,-1,13.60,0,-1,13.63,0,-1,13.64,0,-2,13.66,0,-2,13.67,0,-1,13.68,0,-2,13.69,0,-2,13.70,0,-3,ARL,0
2025-07-17T15:58:14.672365974Z,2025-07-17T15:58:14.672200872Z,10,2,1108,A,A,10,14.120000000,100,320487017,165102,267658983,13.31,10,1,13.28,1,2,13.27,10,1,13.14,1,1,13.13,100,1,13.11,100,1,13.10,100,1,13.04,2,1,13.02,200,2,12.99,100,1,13.40,0,-10,13.59,0,-1,13.60,0,-1,13.63,0,-1,13.64,0,-2,13.66,0,-2,13.67,0,-1,13.68,0,-2,13.69,0,-2,13.70,0,-3,ARL,0
2025-07-17T15:58:14.673184116Z,2025-07-17T15:58:14.673019194Z,10,2,1108,C,A,10,14.120000000,100,320487017,164922,267658989,13.31,10,1,13.28,1,2,13.27,10,1,13.14,1,1,13.13,100,1,13.11,100,1,13.10,100,1,13.04,2,1,13.02,200,2,12.99,100,1,13.40,0,-10,13.59,0,-1,13.60,0,-1,13.63,0,-1,13.64,0,-2,13.66,0,-2,13.67,0,-1,13.68,0,-2,13.69,0,-2,13.70,0,-3,ARL,0
2025-07-17T15:58:14.673230480Z,2025-07-17T15:58:14.673065320Z,10,2,1108,A,A,10,14.260000000,100,320487025,165160,267658990,13.31,10,1,13.28,1,2,13.27,10,1,13.14,1,1,13.13,100,1,13.11,100,1,13.10,100,1,13.04,2,1,13.02,200,2,12.99,100,1,13.40,0,-10,13.59,0,-1,13.60,0,-1,13.63,0,-1,13.64,0,-2,13.66,0,-2,13.67,0,-1,13.68,0,-2,13.69,0,-2,13.70,0,-3,ARL,0
2025-07-17T15:58:14.682945541Z,2025-07-17T15:58:14.682780396Z,10,2,1108,C,A,10,14.760000000,100,320484821,165145,267659018,13.31,10,1,13.28,1,2,13.27,10,1,13.14,1,1,13.13,100,1,13.11,100,1,13.10,100,1,13.04,2,1,13.02,200,2,12.99,100,1,13.40,0,-10,13.59,0,-1,13.60,0,-1,13.63,0,-1,13.64,0,-2,13.66,0,-2,13.67,0,-1,13.68,0,-2,13.69,0,-2,13.70,0,-3,ARL,0
2025-07-17T15:58:14.682945541Z,2025-07-17T15:58:14.682780396Z,10,2,1108,A,A,10,14.960000000,100,320487105,165145,267659018,13.31,10,1,13.28,1,2,13.27,10,1,13.14,1,1,13.13,100,1,13.11,100,1,13.10,100,1,13.04,2,1,13.02,200,2,12.99,100,1,13.40,0,-10,13.59,0,-1,13.60,0,-1,13.63,0,-1,13.64,0,-2,13.66,0,-2,13.67,0,-1,13.68,0,-2,13.69,0,-2,13.70,0,-3,ARL,0
2025-07-17T15:58:14.710787891Z,2025-07-17T15:58:14.710622495Z,10,2,1108,C,A,10,14.910000000,100,320486925,165396,267659178,13.31,10,1,13.28,1,2,13.27,10,1,13.14,1,1,13.13,100,1,13.11,100,1,13.10,100,1,13.04,2,1,13.02,200,2,12.99,100,1,13.40,0,-10,13.59,0,-1,13.60,0,-1,13.63,0,-1,13.64,0,-2,13.66,0,-2,13.67,0,-1,13.68,0,-2,13.69,0,-2,13.70,0,-3,ARL,0
2025-07-17T15:58:14.710787891Z,2025-07-17T15:58:14.710622495Z,10,2,1108,A,A,10,15.060000000,100,320487357,165396,267659178,13.31,10,1,13.28,1,2,13.27,10,1,13.14,1,1,13.13,100,1,13.11,100,1,13.10,100,1,13.04,2,1,13.02,200,2,12.99,100,1,13.40,0,-10,13.59,0,-1,13.60,0,-1,13.63,0,-1,13.64,0,-2,13.66,0,-2,13.67,0,-1,13.68,0,-2,13.69,0,-2,13.70,0,-3,ARL,0
2025-07-17T15:58:15.564070256Z,2025-07-17T15:58:15.563904700Z,10,2,1108,C,A,10,14.680000000,100,320484781,165556,267672469,13.31,10,1,13.28,1,2,13.27,10,1,13.14,1,1,13.13,100,1,13.11,100,1,13.10,100,1,13.04,2,1,13.02,200,2,12.99,100,1,13.40,0,-10,13.59,0,-1,13.60,0,-1,13.63,0,-1,13.64,0,-2,13.66,0,-2,13.67,0,-1,13.68,0,-2,13.69,0,-2,13.70,0,-3,ARL,0
2025-07-17T15:58:15.564070256Z,2025-07-17T15:58:15.563904700Z,10,2,1108,A,A,10,14.870000000,100,320504473,165556,267672469,13.31,10,1,13.28,1,2,13.27,10,1,13.14,1,1,13.13,100,1,13.11,100,1,13.10,100,1,13.04,2,1,13.02,200,2,12.99,100,1,13.40,0,-10,13.59,0,-1,13.60,0,-1,13.63,0,-1,13.64,0,-2,13.66,0,-2,13.67,0,-1,13.68,0,-2,13.69,0,-2,13.70,0,-3,ARL,0
2025-07-17T15:58:15.577719796Z,2025-07-17T15:58:15.577554368Z,10,2,1108,C,A,10,14.690000000,100,320484825,165428,267672549,13.31,10,1,13.28,1,2,13.27,10,1,13.14,1,1,13.13,100,1,13.11,100,1,13.10,100,1,13.04,2,1,13.02,200,2,12.99,100,1,13.40,0,-10,13.59,0,-1,13.60,0,-1,13.63,0,-1,13.64,0,-2,13.66,0,-2,13.67,0,-1,13.68,0,-2,13.69,0,-2,13.70,0,-3,ARL,0
2025-07-17T15:58:15.577719796Z,2025-07-17T15:58:15.577554368Z,10,2,1108,A,A,10,14.880000000,100,320504609,165428,267672549,13.31,10,1,13.28,1,2,13.27,10,1,13.14,1,1,13.13,100,1,13.11,100,1,13.10,100,1,13.04,2,1,13.02,200,2,12.99,100,1,13.40,0,-10,13.59,0,-1,13.60,0,-1,13.63,0,-1,13.64,0,-2,13.66,0,-2,13.67,0,-1,13.68,0,-2,13.69,0,-2,13.70,0,-3,ARL,0
2025-07-17T15:58:16.502080515Z,2025-07-17T15:58:16.501915292Z,10,2,1108,A,A,10,14.110000000,100,320519893,165223,267685252,13.31,10,1,13.28,1,2,13.27,10,1,13.14,1,1,13.13,100,1,13.11,100,1,13.10,100,1,13.04,2,1,13.02,200,2,12.99,100,1,13.40,0,-10,13.59,0,-1,13.60,0,-1,13.63,0,-1,13.64,0,-2,13.66,0,-2,13.67,0,-1,13.68,0,-2,13.69,0,-2,13.70,0,-3,ARL,0
2025-07-17T15:58:19.965200980Z,2025-07-17T15:58:19.965034325Z,10,2,1108,A,A,10,13.940000000,15,320588689,166655,267738403,13.31,10,1,13.28,1,2,13.27,10,1,13.14,1,1,13.13,100,1,13.11,100,1,13.10,100,1,13.04,2,1,13.02,200,2,12.99,100,1,13.40,0,-10,13.59,0,-1,13.60,0,-1,13.63,0,-1,13.64,0,-2,13.66,0,-2,13.67,0,-1,13.68,0,-2,13.69,0,-2,13.70,0,-3,ARL,0
2025-07-17T15:58:20.237833402Z,2025-07-17T15:58:20.237668047Z,10,2,1108,C,A,10,14.110000000,100,320519893,165355,267745213,13.31,10,1,13.28,1,2,13.27,10,1,13.14,1,1,13.13,100,1,13.11,100,1,13.10,100,1,13.04,2,1,13.02,200,2,12.99,100,1,13.40,0,-10,13.59,0,-1,13.60,0,-1,13.63,0,-1,13.64,0,-2,13.66,0,-2,13.67,0,-1,13.68,0,-2,13.69,0,-2,13.70,0,-3,ARL,0
2025-07-17T15:58:20.237833402Z,2025-07-17T15:58:20.237668047Z,10,2,1108,A,A,10,13.950000000,100,320595817,165355,267745213,13.31,10,1,13.28,1,2,13.27,10,1,13.14,1,1,13.13,100,1,13.11,100,1,13.10,100,1,13.04,2,1,13.02,200,2,12.99,100,1,13.40,0,-10,13.59,0,-1,13.60,0,-1,13.63,0,-1,13.64,0,-2,13.66,0,-2,13.67,0,-1,13.68,0,-2,13.69,0,-2,13.70,0,-3,ARL,0
2025-07-17T15:58:20.705512171Z,2025-07-17T15:58:20.705344578Z,10,2,1108,C,A,10,13.940000000,15,320588689,167593,267754327,13.31,10,1,13.28,1,2,13.27,10,1,13.14,1,1,13.13,100,1,13.11,100,1,13.10,100,1,13.04,2,1,13.02,200,2,12.99,100,1,13.40,0,-10,13.59,0,-1,13.60,0,-1,13.63,0,-1,13.64,0,-2,13.66,0,-2,13.67,0,-1,13.68,0,-2,13.69,0,-2,13.70,0,-3,ARL,0
2025-07-17T15:58:30.800053062Z,2025-07-17T15:58:30.799887713Z,10,2,1108,A,A,10,13.890000000,15,320833897,165349,267913947,13.31,10,1,13.28,1,2,13.27,10,1,13.14,1,1,13.13,100,1,13.11,100,1,13.10,100,1,13.04,2,1,13.02,200,2,12.99,100,1,13.40,0,-10,13.59,0,-1,13.60,0,-1,13.63,0,-1,13.64,0,-2,13.66,0,-2,13.67,0,-1,13.68,0,-2,13.69,0,-2,13.70,0,-3,ARL,0
2025-07-17T15:58:30.905657319Z,2025-07-17T15:58:30.905491759Z,10,2,1108,C,A,10,13.950000000,100,320595817,165560,267919515,13.31,10,1,13.28,1,2,13.27,10,1,13.14,1,1,13.13,100,1,13.11,100,1,13.10,100,1,13.04,2,1,13.02,200,2,12.99,100,1,13.40,0,-10,13.59,0,-1,13.60,0,-1,13.63,0,-1,13.64,0,-2,13.66,0,-2,13.67,0,-1,13.68,0,-2,13.69,0,-2,13.70,0,-3,ARL,0
2025-07-17T15:58:30.905657319Z,2025-07-17T15:58:30.905491759Z,10,2,1108,A,A,10,13.900000000,100,320839125,165560,267919515,13.31,10,1,13.28,1,2,13.27,10,1,13.14,1,1,13.13,100,1,13.11,100,1,13.10,100,1,13.04,2,1,13.02,200,2,12.99,100,1,13.40,0,-10,13.59,0,-1,13.60,0,-1,13.63,0,-1,13.64,0,-2,13.66,0,-2,13.67,0,-1,13.68,0,-2,13.69,0,-2,13.70,0,-3,ARL,0
2025-07-17T15:58:30.906412286Z,2025-07-17T15:58:30.906246950Z,10,2,1108,C,A,10,15.060000000,100,320487357,165336,267919540,13.31,10,1,13.28,1,2,13.27,10,1,13.14,1,1,13.13,100,1,13.11,100,1,13.10,100,1,13.04,2,1,13.02,200,2,12.99,100,1,13.40,0,-10,13.59,0,-1,13.60,0,-1,13.63,0,-1,13.64,0,-2,13.66,0,-2,13.67,0,-1,13.68,0,-2,13.69,0,-2,13.70,0,-3,ARL,0
2025-07-17T15:58:30.906412286Z,2025-07-17T15:58:30.906246950Z,10,2,1108,A,A,10,14.980000000,100,320839149,165336,267919540,13.31,10,1,13.28,1,2,13.27,10,1,13.14,1,1,13.13,100,1,13.11,100,1,13.10,100,1,13.04,2,1,13.02,200,2,12.99,100,1,13.40,0,-10,13.59,0,-1,13.60,0,-1,13.63,0,-1,13.64,0,-2,13.66,0,-2,13.67,0,-1,13.68,0,-2,13.69,0,-2,13.70,0,-3,ARL,0
2025-07-17T15:58:30.916726353Z,2025-07-17T15:58:30.916561264Z,10,2,1108,C,A,10,14.260000000,100,320487025,165089,267919917,13.31,10,1,13.28,1,2,13.27,10,1,13.14,1,1,13.13,100,1,13.11,100,1,13.10,100,1,13.04,2,1,13.02,200,2,12.99,100,1,13.40,0,-10,13.59,0,-1,13.60,0,-1,13.63,0,-1,13.64,0,-2,13.66,0,-2,13.67,0,-1,13.68,0,-2,13.69,0,-2,13.70,0,-3,ARL,0
2025-07-17T15:58:30.916784278Z,2025-07-17T15:58:30.916619122Z,10,2,1108,A,A,10,14.180000000,100,320839577,165156,267919919,13.31,10,1,13.28,1,2,13.27,10,1,13.14,1,1,13.13,100,1,13.11,100,1,13.10,100,1,13.04,2,1,13.02,200,2,12.99,100,1,13.40,0,-10,13.59,0,-1,13.60,0,-1,13.63,0,-1,13.64,0,-2,13.66,0,-2,13.67,0,-1,13.68,0,-2,13.69,0,-2,13.70,0,-3,ARL,0
2025-07-17T15:58:31.124388717Z,2025-07-17T15:58:31.124222733Z,10,2,1108,C,A,10,14.870000000,100,320504473,165984,267925564,13.31,10,1,13.28,1,2,13.27,10,1,13.14,1,1,13.13,100,1,13.11,100,1,13.10,100,1,13.04,2,1,13.02,200,2,12.99,100,1,13.40,0,-10,13.59,0,-1,13.60,0,-1,13.63,0,-1,13.64,0,-2,13.66,0,-2,13.67,0,-1,13.68,0,-2,13.69,0,-2,13.70,0,-3,ARL,0
2025-07-17T15:58:31.124388717Z,2025-07-17T15:58:31.124222733Z,10,2,1108,A,A,10,14.760000000,100,320845893,165984,267925564,13.31,10,1,13.28,1,2,13.27,10,1,13.14,1,1,13.13,100,1,13.11,100,1,13.10,100,1,13.04,2,1,13.02,200,2,12.99,100,1,13.40,0,-10,13.59,0,-1,13.60,0,-1,13.63,0,-1,13.64,0,-2,13.66,0,-2,13.67,0,-1,13.68,0,-2,13.69,0,-2,13.70,0,-3,ARL,0
2025-07-17T15:58:31.136439248Z,2025-07-17T15:58:31.136273403Z,10,2,1108,C,A,10,14.880000000,100,320504609,165845,267925951,13.31,10,1,13.28,1,2,13.27,10,1,13.14,1,1,13.13,100,1,13.11,100,1,13.10,100,1,13.04,2,1,13.02,200,2,12.99,100,1,13.40,0,-10,13.59,0,-1,13.60,0,-1,13.63,0,-1,13.64,0,-2,13.66,0,-2,13.67,0,-1,13.68,0,-2,13.69,0,-2,13.70,0,-3,ARL,0
2025-07-17T15:58:31.136439248Z,2025-07-17T15:58:31.136273403Z,10,2,1108,A,A,10,14.770000000,100,320846429,165845,267925951,13.31,10,1,13.28,1,2,13.27,10,1,13.14,1,1,13.13,100,1,13.11,100,1,13.10,100,1,13.04,2,1,13.02,200,2,12.99,100,1,13.40,0,-10,13.59,0,-1,13.60,0,-1,13.63,0,-1,13.64,0,-2,13.66,0,-2,13.67,0,-1,13.68,0,-2,13.69,0,-2,13.70,0,-3,ARL,0
2025-07-17T15:58:40.799952243Z,2025-07-17T15:58:40.799787018Z,10,2,1108,A,A,10,13.830000000,15,321038033,165225,268074431,13.31,10,1,13.28,1,2,13.27,10,1,13.14,1,1,13.13,100,1,13.11,100,1,13.10,100,1,13.04,2,1,13.02,200,2,12.99,100,1,13.40,0,-10,13.59,0,-1,13.60,0,-1,13.63,0,-1,13.64,0,-2,13.66,0,-2,13.67,0,-1,13.68,0,-2,13.69,0,-2,13.70,0,-3,ARL,0
2025-07-17T15:58:43.690244473Z,2025-07-17T15:58:43.690078924Z,10,2,1108,C,A,10,13.900000000,100,320839125,165549,268115228,13.31,10,1,13.28,1,2,13.27,10,1,13.14,1,1,13.13,100,1,13.11,100,1,13.10,100,1,13.04,2,1,13.02,200,2,12.99,100,1,13.40,0,-10,13.59,0,-1,13.60,0,-1,13.63,0,-1,13.64,0,-2,13.66,0,-2,13.67,0,-1,13.68,0,-2,13.69,0,-2,13.70,0,-3,ARL,0
2025-07-17T15:58:43.690244473Z,2025-07-17T15:58:43.690078924Z,10,2,1108,A,A,10,13.840000000,100,321096769,165549,268115228,13.31,10,1,13.28,1,2,13.27,10,1,13.14,1,1,13.13,100,1,13.11,100,1,13.10,100,1,13.04,2,1,13.02,200,2,12.99,100,1,13.40,0,-10,13.59,0,-1,13.60,0,-1,13.63,0,-1,13.64,0,-2,13.66,0,-2,13.67,0,-1,13.68,0,-2,13.69,0,-2,13.70,0,-3,ARL,0
2025-07-17T15:58:43.690988921Z,2025-07-17T15:58:43.690823184Z,10,2,1108,C,A,10,14.980000000,100,320839149,165737,268115235,13.31,10,1,13.28,1,2,13.27,10,1,13.14,1,1,13.13,100,1,13.11,100,1,13.10,100,1,13.04,2,1,13.02,200,2,12.99,100,1,13.40,0,-10,13.59,0,-1,13.60,0,-1,13.63,0,-1,13.64,0,-2,13.66,0,-2,13.67,0,-1,13.68,0,-2,13.69,0,-2,13.70,0,-3,ARL,0
2025-07-17T15:58:43.690988921Z,2025-07-17T15:58:43.690823184Z,10,2,1108,A,A,10,14.910000000,100,321096793,165737,268115235,13.31,10,1,13.28,1,2,13.27,10,1,13.14,1,1,13.13,100,1,13.11,100,1,13.10,100,1,13.04,2,1,13.02,200,2,12.99,100,1,13.40,0,-10,13.59,0,-1,13.60,0,-1,13.63,0,-1,13.64,0,-2,13.66,0,-2,13.67,0,-1,13.68,0,-2,13.69,0,-2,13.70,0,-3,ARL,0
2025-07-17T15:58:43.693394500Z,2025-07-17T15:58:43.693228946Z,10,2,1108,C,A,10,17.760000000,100,320486937,165554,268115265,13.31,10,1,13.28,1,2,13.27,10,1,13.14,1,1,13.13,100,1,13.11,100,1,13.10,100,1,13.04,2,1,13.02,200,2,12.99,100,1,13.40,0,-10,13.59,0,-1,13.60,0,-1,13.63,0,-1,13.64,0,-2,13.66,0,-2,13.67,0,-1,13.68,0,-2,13.69,0,-2,13.70,0,-3,ARL,0
2025-07-17T15:58:43.693394500Z,2025-07-17T15:58:43.693228946Z,10,2,1108,A,A,10,17.580000000,100,321096825,165554,268115265,13.31,10,1,13.28,1,2,13.27,10,1,13.14,1,1,13.13,100,1,13.11,100,1,13.10,100,1,13.04,2,1,13.02,200,2,12.99,100,1,13.40,0,-10,13.59,0,-1,13.60,0,-1,13.63,0,-1,13.64,0,-2,13.66,0,-2,13.67,0,-1,13.68,0,-2,13.69,0,-2,13.70,0,-3,ARL,0
2025-07-17T15:58:43.695055785Z,2025-07-17T15:58:43.694890264Z,10,2,1108,C,A,10,16.080000000,100,320486945,165521,268115287,13.31,10,1,13.28,1,2,13.27,10,1,13.14,1,1,13.13,100,1,13.11,100,1,13.10,100,1,13.04,2,1,13.02,200,2,12.99,100,1,13.40,0,-10,13.59,0,-1,13.60,0,-1,13.63,0,-1,13.64,0,-2,13.66,0,-2,13.67,0,-1,13.68,0,-2,13.69,0,-2,13.70,0,-3,ARL,0
2025-07-17T15:58:43.695055785Z,2025-07-17T15:58:43.694890264Z,10,2,1108,A,A,10,15.920000000,100,321096889,165521,268115287,13.31,10,1,13.28,1,2,13.27,10,1,13.14,1,1,13.13,100,1,13.11,100,1,13.10,100,1,13.04,2,1,13.02,200,2,12.99,100,1,13.40,0,-10,13.59,0,-1,13.60,0,-1,13.63,0,-1,13.64,0,-2,13.66,0,-2,13.67,0,-1,13.68,0,-2,13.69,0,-2,13.70,0,-3,ARL,0
2025-07-17T15:58:43.716437124Z,2025-07-17T15:58:43.716271172Z,10,2,1108,C,A,10,14.960000000,100,320487105,165952,268115456,13.31,10,1,13.28,1,2,13.27,10,1,13.14,1,1,13.13,100,1,13.11,100,1,13.10,100,1,13.04,2,1,13.02,200,2,12.99,100,1,13.40,0,-10,13.59,0,-1,13.60,0,-1,13.63,0,-1,13.64,0,-2,13.66,0,-2,13.67,0,-1,13.68,0,-2,13.69,0,-2,13.70,0,-3,ARL,0
2025-07-17T15:58:43.716437124Z,2025-07-17T15:58:43.716271172Z,10,2,1108,A,A,10,14.810000000,100,321097197,165952,268115456,13.31,10,1,13.28,1,2,13.27,10,1,13.14,1,1,13.13,100,1,13.11,100,1,13.10,100,1,13.04,2,1,13.02,200,2,12.99,100,1,13.40,0,-10,13.59,0,-1,13.60,0,-1,13.63,0,-1,13.64,0,-2,13.66,0,-2,13.67,0,-1,13.68,0,-2,13.69,0,-2,13.70,0,-3,ARL,0
2025-07-17T15:58:44.903740109Z,2025-07-17T15:58:44.903574654Z,10,2,1108,A,A,10,13.830000000,100,321114473,165455,268129040,13.31,10,1,13.28,1,2,13.27,10,1,13.14,1,1,13.13,100,1,13.11,100,1,13.10,100,1,13.04,2,1,13.02,200,2,12.99,100,1,13.40,0,-10,13.59,0,-1,13.60,0,-1,13.63,0,-1,13.64,0,-2,13.66,0,-2,13.67,0,-1,13.68,0,-2,13.69,0,-2,13.70,0,-3,ARL,0
2025-07-17T15:58:44.924114268Z,2025-07-17T15:58:44.923948853Z,10,2,1108,C,A,10,14.180000000,100,320839577,165415,268129217,13.31,10,1,13.28,1,2,13.27,10,1,13.14,1,1,13.13,100,1,13.11,100,1,13.10,100,1,13.04,2,1,13.02,200,2,12.99,100,1,13.40,0,-10,13.59,0,-1,13.60,0,-1,13.63,0,-1,13.64,0,-2,13.66,0,-2,13.67,0,-1,13.68,0,-2,13.69,0,-2,13.70,0,-3,ARL,0
2025-07-17T15:58:44.924165875Z,2025-07-17T15:58:44.924000519Z,10,2,1108,A,A,10,14.110000000,100,321114729,165356,268129218,13.31,10,1,13.28,1,2,13.27,10,1,13.14,1,1,13.13,100,1,13.11,100,1,13.10,100,1,13.04,2,1,13.02,200,2,12.99,100,1,13.40,0,-10,13.59,0,-1,13.60,0,-1,13.63,0,-1,13.64,0,-2,13.66,0,-2,13.67,0,-1,13.68,0,-2,13.69,0,-2,13.70,0,-3,ARL,0
2025-07-17T15:58:51.241342265Z,2025-07-17T15:58:51.241176997Z,10,2,1108,C,A,10,13.890000000,15,320833897,165268,268212338,13.31,10,1,13.28,1,2,13.27,10,1,13.14,1,1,13.13,100,1,13.11,100,1,13.10,100,1,13.04,2,1,13.02,200,2,12.99,100,1,13.40,0,-10,13.59,0,-1,13.60,0,-1,13.63,0,-1,13.64,0,-2,13.66,0,-2,13.67,0,-1,13.68,0,-2,13.69,0,-2,13.70,0,-3,ARL,0
2025-07-17T15:58:51.254127339Z,2025-07-17T15:58:51.253961905Z,10,2,1108,A,A,10,13.800000000,100,321225725,165434,268212497,13.31,10,1,13.28,1,2,13.27,10,1,13.14,1,1,13.13,100,1,13.11,100,1,13.10,100,1,13.04,2,1,13.02,200,2,12.99,100,1,13.40,0,-10,13.59,0,-1,13.60,0,-1,13.63,0,-1,13.64,0,-2,13.66,0,-2,13.67,0,-1,13.68,0,-2,13.69,0,-2,13.70,0,-3,ARL,0
2025-07-17T15:58:51.254871890Z,2025-07-17T15:58:51.254706004Z,10,2,1108,C,A,10,14.910000000,100,321096793,165886,268212499,13.31,10,1,13.28,1,2,13.27,10,1,13.14,1,1,13.13,100,1,13.11,100,1,13.10,100,1,13.04,2,1,13.02,200,2,12.99,100,1,13.40,0,-10,13.59,0,-1,13.60,0,-1,13.63,0,-1,13.64,0,-2,13.66,0,-2,13.67,0,-1,13.68,0,-2,13.69,0,-2,13.70,0,-3,ARL,0
2025-07-17T15:58:51.254871890Z,2025-07-17T15:58:51.254706004Z,10,2,1108,A,A,10,14.870000000,100,321225745,165886,268212499,13.31,10,1,13.28,1,2,13.27,10,1,13.14,1,1,13.13,100,1,13.11,100,1,13.10,100,1,13.04,2,1,13.02,200,2,12.99,100,1,13.40,0,-10,13.59,0,-1,13.60,0,-1,13.63,0,-1,13.64,0,-2,13.66,0,-2,13.67,0,-1,13.68,0,-2,13.69,0,-2,13.70,0,-3,ARL,0
2025-07-17T15:58:51.260753179Z,2025-07-17T15:58:51.260587778Z,10,2,1108,C,A,10,13.830000000,100,321114473,165401,268212534,13.31,10,1,13.28,1,2,13.27,10,1,13.14,1,1,13.13,100,1,13.11,100,1,13.10,100,1,13.04,2,1,13.02,200,2,12.99,100,1,13.40,0,-10,13.59,0,-1,13.60,0,-1,13.63,0,-1,13.64,0,-2,13.66,0,-2,13.67,0,-1,13.68,0,-2,13.69,0,-2,13.70,0,-3,ARL,0
2025-07-17T15:58:53.579628288Z,2025-07-17T15:58:53.579462029Z,10,2,1108,C,A,10,13.830000000,15,321038033,166259,268250290,13.31,10,1,13.28,1,2,13.27,10,1,13.14,1,1,13.13,100,1,13.11,100,1,13.10,100,1,13.04,2,1,13.02,200,2,12.99,100,1,13.40,0,-10,13.59,0,-1,13.60,0,-1,13.63,0,-1,13.64,0,-2,13.66,0,-2,13.67,0,-1,13.68,0,-2,13.69,0,-2,13.70,0,-3,ARL,0
2025-07-17T15:58:53.580217445Z,2025-07-17T15:58:53.580052014Z,10,2,1108,C,A,10,13.840000000,100,321096769,165431,268250346,13.31,10,1,13.28,1,2,13.27,10,1,13.14,1,1,13.13,100,1,13.11,100,1,13.10,100,1,13.04,2,1,13.02,200,2,12.99,100,1,13.40,0,-10,13.59,0,-1,13.60,0,-1,13.63,0,-1,13.64,0,-2,13.66,0,-2,13.67,0,-1,13.68,0,-2,13.69,0,-2,13.70,0,-3,ARL,0
2025-07-17T15:58:53.580217445Z,2025-07-17T15:58:53.580052014Z,10,2,1108,A,A,10,13.810000000,100,321272581,165431,268250346,13.31,10,1,13.28,1,2,13.27,10,1,13.14,1,1,13.13,100,1,13.11,100,1,13.10,100,1,13.04,2,1,13.02,200,2,12.99,100,1,13.40,0,-10,13.59,0,-1,13.60,0,-1,13.63,0,-1,13.64,0,-2,13.66,0,-2,13.67,0,-1,13.68,0,-2,13.69,0,-2,13.70,0,-3,ARL,0
2025-07-17T15:58:54.584124215Z,2025-07-17T15:58:54.583958582Z,10,2,1108,C,A,10,14.770000000,100,320846429,165633,268265585,13.31,10,1,13.28,1,2,13.27,10,1,13.14,1,1,13.13,100,1,13.11,100,1,13.10,100,1,13.04,2,1,13.02,200,2,12.99,100,1,13.40,0,-10,13.59,0,-1,13.60,0,-1,13.63,0,-1,13.64,0,-2,13.66,0,-2,13.67,0,-1,13.68,0,-2,13.69,0,-2,13.70,0,-3,ARL,0
2025-07-17T15:58:54.584124215Z,2025-07-17T15:58:54.583958582Z,10,2,1108,A,A,10,14.650000000,100,321293737,165633,268265585,13.31,10,1,13.28,1,2,13.27,10,1,13.14,1,1,13.13,100,1,13.11,100,1,13.10,100,1,13.04,2,1,13.02,200,2,12.99,100,1,13.40,0,-10,13.59,0,-1,13.60,0,-1,13.63,0,-1,13.64,0,-2,13.66,0,-2,13.67,0,-1,13.68,0,-2,13.69,0,-2,13.70,0,-3,ARL,0
2025-07-17T15:58:54.584260712Z,2025-07-17T15:58:54.584094980Z,10,2,1108,C,A,10,14.760000000,100,320845893,165732,268265586,13.31,10,1,13.28,1,2,13.27,10,1,13.14,1,1,13.13,100,1,13.11,100,1,13.10,100,1,13.04,2,1,13.02,200,2,12.99,100,1,13.40,0,-10,13.59,0,-1,13.60,0,-1,13.63,0,-1,13.64,0,-2,13.66,0,-2,13.67,0,-1,13.68,0,-2,13.69,0,-2,13.70,0,-3,ARL,0
2025-07-17T15:58:54.584260712Z,2025-07-17T15:58:54.584094980Z,10,2,1108,A,A,10,14.640000000,100,321293741,165732,268265586,13.31,10,1,13.28,1,2,13.27,10,1,13.14,1,1,13.13,100,1,13.11,100,1,13.10,100,1,13.04,2,1,13.02,200,2,12.99,100,1,13.40,0,-10,13.59,0,-1,13.60,0,-1,13.63,0,-1,13.64,0,-2,13.66,0,-2,13.67,0,-1,13.68,0,-2,13.69,0,-2,13.70,0,-3,ARL,0
2025-07-17T15:58:55.305104029Z,2025-07-17T15:58:55.304938318Z,10,2,1108,A,A,10,13.780000000,100,321309865,165711,268277940,13.31,10,1,13.28,1,2,13.27,10,1,13.14,1,1,13.13,100,1,13.11,100,1,13.10,100,1,13.04,2,1,13.02,200,2,12.99,100,1,13.40,0,-10,13.59,0,-1,13.60,0,-1,13.63,0,-1,13.64,0,-2,13.66,0,-2,13.67,0,-1,13.68,0,-2,13.69,0,-2,13.70,0,-3,ARL,0
2025-07-17T15:58:55.307508305Z,2025-07-17T15:58:55.307342971Z,10,2,1108,C,A,10,14.720000000,100,312772061,165334,268277999,13.31,10,1,13.28,1,2,13.27,10,1,13.14,1,1,13.13,100,1,13.11,100,1,13.10,100,1,13.04,2,1,13.02,200,2,12.99,100,1,13.40,0,-10,13.59,0,-1,13.60,0,-1,13.63,0,-1,13.64,0,-2,13.66,0,-2,13.67,0,-1,13.68,0,-2,13.69,0,-2,13.70,0,-3,ARL,0
2025-07-17T15:58:55.307637209Z,2025-07-17T15:58:55.307472032Z,10,2,1108,A,A,10,14.580000000,100,321309941,165177,268278004,13.31,10,1,13.28,1,2,13.27,10,1,13.14,1,1,13.13,100,1,13.11,100,1,13.10,100,1,13.04,2,1,13.02,200,2,12.99,100,1,13.40,0,-10,13.59,0,-1,13.60,0,-1,13.63,0,-1,13.64,0,-2,13.66,0,-2,13.67,0,-1,13.68,0,-2,13.69,0,-2,13.70,0,-3,ARL,0
2025-07-17T15:58:55.311899965Z,2025-07-17T15:58:55.311734700Z,10,2,1108,C,A,10,13.800000000,100,321225725,165265,268278030,13.31,10,1,13.28,1,2,13.27,10,1,13.14,1,1,13.13,100,1,13.11,100,1,13.10,100,1,13.04,2,1,13.02,200,2,12.99,100,1,13.40,0,-10,13.59,0,-1,13.60,0,-1,13.63,0,-1,13.64,0,-2,13.66,0,-2,13.67,0,-1,13.68,0,-2,13.69,0,-2,13.70,0,-3,ARL,0
2025-07-17T15:58:58.668252306Z,2025-07-17T15:58:58.668086788Z,10,2,1108,C,A,10,13.810000000,100,321272581,165518,268321684,13.31,10,1,13.28,1,2,13.27,10,1,13.14,1,1,13.13,100,1,13.11,100,1,13.10,100,1,13.04,2,1,13.02,200,2,12.99,100,1,13.40,0,-10,13.59,0,-1,13.60,0,-1,13.63,0,-1,13.64,0,-2,13.66,0,-2,13.67,0,-1,13.68,0,-2,13.69,0,-2,13.70,0,-3,ARL,0
2025-07-17T15:58:58.668252306Z,2025-07-17T15:58:58.668086788Z,10,2,1108,A,A,10,13.790000000,100,321364281,165518,268321684,13.31,10,1,13.28,1,2,13.27,10,1,13.14,1,1,13.13,100,1,13.11,100,1,13.10,100,1,13.04,2,1,13.02,200,2,12.99,100,1,13.40,0,-10,13.59,0,-1,13.60,0,-1,13.63,0,-1,13.64,0,-2,13.66,0,-2,13.67,0,-1,13.68,0,-2,13.69,0,-2,13.70,0,-3,ARL,0
2025-07-17T15:59:03.613692913Z,2025-07-17T15:59:03.613527621Z,10,2,1108,A,A,10,13.720000000,15,321500117,165292,268437919,13.31,10,1,13.28,1,2,13.27,10,1,13.14,1,1,13.13,100,1,13.11,100,1,13.10,100,1,13.04,2,1,13.02,200,2,12.99,100,1,13.40,0,-10,13.59,0,-1,13.60,0,-1,13.63,0,-1,13.64,0,-2,13.66,0,-2,13.67,0,-1,13.68,0,-2,13.69,0,-2,13.70,0,-3,ARL,0
2025-07-17T15:59:03.626346616Z,2025-07-17T15:59:03.626181384Z,10,2,1108,A,A,10,13.760000000,100,321500317,165232,268438110,13.31,10,1,13.28,1,2,13.27,10,1,13.14,1,1,13.13,100,1,13.11,100,1,13.10,100,1,13.04,2,1,13.02,200,2,12.99,100,1,13.40,0,-10,13.59,0,-1,13.60,0,-1,13.63,0,-1,13.64,0,-2,13.66,0,-2,13.67,0,-1,13.68,0,-2,13.69,0,-2,13.70,0,-3,ARL,0
2025-07-17T15:59:03.627086888Z,2025-07-17T15:59:03.626920954Z,10,2,1108,C,A,10,14.870000000,100,321225745,165934,268438112,13.31,10,1,13.28,1,2,13.27,10,1,13.14,1,1,13.13,100,1,13.11,100,1,13.10,100,1,13.04,2,1,13.02,200,2,12.99,100,1,13.40,0,-10,13.59,0,-1,13.60,0,-1,13.63,0,-1,13.64,0,-2,13.66,0,-2,13.67,0,-1,13.68,0,-2,13.69,0,-2,13.70,0,-3,ARL,0
2025-07-17T15:59:03.627086888Z,2025-07-17T15:59:03.626920954Z,10,2,1108,A,A,10,14.830000000,100,321500333,165934,268438112,13.31,10,1,13.28,1,2,13.27,10,1,13.14,1,1,13.13,100,1,13.11,100,1,13.10,100,1,13.04,2,1,13.02,200,2,12.99,100,1,13.40,0,-10,13.59,0,-1,13.60,0,-1,13.63,0,-1,13.64,0,-2,13.66,0,-2,13.67,0,-1,13.68,0,-2,13.69,0,-2,13.70,0,-3,ARL,0
2025-07-17T15:59:03.628945278Z,2025-07-17T15:59:03.628779364Z,10,2,1108,C,A,10,14.890000000,100,312771785,165914,268438129,13.31,10,1,13.28,1,2,13.27,10,1,13.14,1,1,13.13,100,1,13.11,100,1,13.10,100,1,13.04,2,1,13.02,200,2,12.99,100,1,13.40,0,-10,13.59,0,-1,13.60,0,-1,13.63,0,-1,13.64,0,-2,13.66,0,-2,13.67,0,-1,13.68,0,-2,13.69,0,-2,13.70,0,-3,ARL,0
2025-07-17T15:59:03.628945278Z,2025-07-17T15:59:03.628779364Z,10,2,1108,A,A,10,14.730000000,100,321500349,165914,268438129,13.31,10,1,13.28,1,2,13.27,10,1,13.14,1,1,13.13,100,1,13.11,100,1,13.10,100,1,13.04,2,1,13.02,200,2,12.99,100,1,13.40,0,-10,13.59,0,-1,13.60,0,-1,13.63,0,-1,13.64,0,-2,13.66,0,-2,13.67,0,-1,13.68,0,-2,13.69,0,-2,13.70,0,-3,ARL,0
2025-07-17T15:59:03.633093258Z,2025-07-17T15:59:03.632928023Z,10,2,1108,C,A,10,13.780000000,100,321309865,165235,268438149,13.31,10,1,13.28,1,2,13.27,10,1,13.14,1,1,13.13,100,1,13.11,100,1,13.10,100,1,13.04,2,1,13.02,200,2,12.99,100,1,13.40,0,-10,13.59,0,-1,13.60,0,-1,13.63,0,-1,13.64,0,-2,13.66,0,-2,13.67,0,-1,13.68,0,-2,13.69,0,-2,13.70,0,-3,ARL,0
2025-07-17T15:59:03.649282063Z,2025-07-17T15:59:03.649116452Z,10,2,1108,C,A,10,14.110000000,100,321114729,165611,268438330,13.31,10,1,13.28,1,2,13.27,10,1,13.14,1,1,13.13,100,1,13.11,100,1,13.10,100,1,13.04,2,1,13.02,200,2,12.99,100,1,13.40,0,-10,13.59,0,-1,13.60,0,-1,13.63,0,-1,13.64,0,-2,13.66,0,-2,13.67,0,-1,13.68,0,-2,13.69,0,-2,13.70,0,-3,ARL,0
2025-07-17T15:59:03.649332873Z,2025-07-17T15:59:03.649167617Z,10,2,1108,A,A,10,14.040000000,100,321500957,165256,268438331,13.31,10,1,13.28,1,2,13.27,10,1,13.14,1,1,13.13,100,1,13.11,100,1,13.10,100,1,13.04,2,1,13.02,200,2,12.99,100,1,13.40,0,-10,13.59,0,-1,13.60,0,-1,13.63,0,-1,13.64,0,-2,13.66,0,-2,13.67,0,-1,13.68,0,-2,13.69,0,-2,13.70,0,-3,ARL,0
2025-07-17T15:59:04.224000805Z,2025-07-17T15:59:04.223835151Z,10,2,1108,C,A,10,13.790000000,100,321364281,165654,268447989,13.31,10,1,13.28,1,2,13.27,10,1,13.14,1,1,13.13,100,1,13.11,100,1,13.10,100,1,13.04,2,1,13.02,200,2,12.99,100,1,13.40,0,-10,13.59,0,-1,13.60,0,-1,13.63,0,-1,13.64,0,-2,13.66,0,-2,13.67,0,-1,13.68,0,-2,13.69,0,-2,13.70,0,-3,ARL,0
2025-07-17T15:59:04.224000805Z,2025-07-17T15:59:04.223835151Z,10,2,1108,A,A,10,13.730000000,100,321511377,165654,268447989,13.31,10,1,13.28,1,2,13.27,10,1,13.14,1,1,13.13,100,1,13.11,100,1,13.10,100,1,13.04,2,1,13.02,200,2,12.99,100,1,13.40,0,-10,13.59,0,-1,13.60,0,-1,13.63,0,-1,13.64,0,-2,13.66,0,-2,13.67,0,-1,13.68,0,-2,13.69,0,-2,13.70,0,-3,ARL,0
2025-07-17T15:59:04.224749333Z,2025-07-17T15:59:04.224583946Z,10,2,1108,C,A,10,14.830000000,100,321500333,165387,268448014,13.31,10,1,13.28,1,2,13.27,10,1,13.14,1,1,13.13,100,1,13.11,100,1,13.10,100,1,13.04,2,1,13.02,200,2,12.99,100,1,13.40,0,-10,13.59,0,-1,13.60,0,-1,13.63,0,-1,13.64,0,-2,13.66,0,-2,13.67,0,-1,13.68,0,-2,13.69,0,-2,13.70,0,-3,ARL,0
2025-07-17T15:59:04.224749333Z,2025-07-17T15:59:04.224583946Z,10,2,1108,A,A,10,14.790000000,100,321511477,165387,268448014,13.31,10,1,13.28,1,2,13.27,10,1,13.14,1,1,13.13,100,1,13.11,100,1,13.10,100,1,13.04,2,1,13.02,200,2,12.99,100,1,13.40,0,-10,13.59,0,-1,13.60,0,-1,13.63,0,-1,13.64,0,-2,13.66,0,-2,13.67,0,-1,13.68,0,-2,13.69,0,-2,13.70,0,-3,ARL,0
2025-07-17T15:59:04.799998642Z,2025-07-17T15:59:04.799833206Z,10,2,1108,C,A,10,13.720000000,15,321500117,165436,268457531,13.31,10,1,13.28,1,2,13.27,10,1,13.14,1,1,13.13,100,1,13.11,100,1,13.10,100,1,13.04,2,1,13.02,200,2,12.99,100,1,13.40,0,-10,13.59,0,-1,13.60,0,-1,13.63,0,-1,13.64,0,-2,13.66,0,-2,13.67,0,-1,13.68,0,-2,13.69,0,-2,13.70,0,-3,ARL,0
2025-07-17T16:00:13.989937414Z,2025-07-17T16:00:13.989771852Z,10,2,1108,C,A,10,14.100000000,2,316098525,165562,269514876,13.31,10,1,13.28,1,2,13.27,10,1,13.14,1,1,13.13,100,1,13.11,100,1,13.10,100,1,13.04,2,1,13.02,200,2,12.99,100,1,13.40,0,-10,13.59,0,-1,13.60,0,-1,13.63,0,-1,13.64,0,-2,13.66,0,-2,13.67,0,-1,13.68,0,-2,13.69,0,-2,13.70,0,-3,ARL,0
2025-07-17T16:00:13.989937414Z,2025-07-17T16:00:13.989771852Z,10,2,1108,A,A,10,14.010000000,2,322898193,165562,269514876,13.31,10,1,13.28,1,2,13.27,10,1,13.14,1,1,13.13,100,1,13.11,100,1,13.10,100,1,13.04,2,1,13.02,200,2,12.99,100,1,13.40,0,-10,13.59,0,-1,13.60,0,-1,13.63,0,-1,13.64,0,-2,13.66,0,-2,13.67,0,-1,13.68,0,-2,13.69,0,-2,13.70,0,-3,ARL,0
2025-07-17T16:00:28.803015930Z,2025-07-17T16:00:28.802849928Z,10,2,1108,A,A,10,13.720000000,15,323238809,166002,269765653,13.31,10,1,13.28,1,2,13.27,10,1,13.14,1,1,13.13,100,1,13.11,100,1,13.10,100,1,13.04,2,1,13.02,200,2,12.99,100,1,13.40,0,-10,13.59,0,-1,13.60,0,-1,13.63,0,-1,13.64,0,-2,13.66,0,-2,13.67,0,-1,13.68,0,-2,13.69,0,-2,13.70,0,-3,ARL,0
2025-07-17T16:00:32.549412616Z,2025-07-17T16:00:32.549247168Z,10,2,1108,A,A,10,13.740000000,100,323370569,165448,269878282,13.31,10,1,13.28,1,2,13.27,10,1,13.14,1,1,13.13,100,1,13.11,100,1,13.10,100,1,13.04,2,1,13.02,200,2,12.99,100,1,13.40,0,-10,13.59,0,-1,13.60,0,-1,13.63,0,-1,13.64,0,-2,13.66,0,-2,13.67,0,-1,13.68,0,-2,13.69,0,-2,13.70,0,-3,ARL,0
2025-07-17T16:00:32.560989093Z,2025-07-17T16:00:32.560823786Z,10,2,1108,C,A,10,13.760000000,100,321500317,165307,269878639,13.31,10,1,13.28,1,2,13.27,10,1,13.14,1,1,13.13,100,1,13.11,100,1,13.10,100,1,13.04,2,1,13.02,200,2,12.99,100,1,13.40,0,-10,13.59,0,-1,13.60,0,-1,13.63,0,-1,13.64,0,-2,13.66,0,-2,13.67,0,-1,13.68,0,-2,13.69,0,-2,13.70,0,-3,ARL,0
2025-07-17T16:00:35.513164458Z,2025-07-17T16:00:35.512999155Z,10,2,1108,A,A,10,13.690000000,15,323455221,165303,269940539,13.31,10,1,13.28,1,2,13.27,10,1,13.14,1,1,13.13,100,1,13.11,100,1,13.10,100,1,13.04,2,1,13.02,200,2,12.99,100,1,13.40,0,-10,13.59,0,-1,13.60,0,-1,13.63,0,-1,13.64,0,-2,13.66,0,-2,13.67,0,-1,13.68,0,-2,13.69,0,-2,13.70,0,-3,ARL,0
2025-07-17T16:00:42.614229184Z,2025-07-17T16:00:42.614063415Z,10,2,1108,C,A,10,13.730000000,100,321511377,165769,270051089,13.31,10,1,13.28,1,2,13.27,10,1,13.14,1,1,13.13,100,1,13.11,100,1,13.10,100,1,13.04,2,1,13.02,200,2,12.99,100,1,13.40,0,-10,13.59,0,-1,13.60,0,-1,13.63,0,-1,13.64,0,-2,13.66,0,-2,13.67,0,-1,13.68,0,-2,13.69,0,-3,13.70,0,-3,ARL,0
2025-07-17T16:00:42.614229184Z,2025-07-17T16:00:42.614063415Z,10,2,1108,A,A,10,13.700000000,100,323599605,165769,270051089,13.31,10,1,13.28,1,2,13.27,10,1,13.14,1,1,13.13,100,1,13.11,100,1,13.10,100,1,13.04,2,1,13.02,200,2,12.99,100,1,13.40,0,-10,13.59,0,-1,13.60,0,-1,13.63,0,-1,13.64,0,-2,13.66,0,-2,13.67,0,-1,13.68,0,-2,13.69,0,-3,13.70,0,-3,ARL,0
2025-07-17T16:00:42.614254199Z,2025-07-17T16:00:42.614088947Z,10,2,1108,A,A,10,13.720000000,100,323599609,165252,270051090,13.31,10,1,13.28,1,2,13.27,10,1,13.14,1,1,13.13,100,1,13.11,100,1,13.10,100,1,13.04,2,1,13.02,200,2,12.99,100,1,13.40,0,-10,13.59,0,-1,13.60,0,-1,13.63,0,-1,13.64,0,-2,13.66,0,-2,13.67,0,-1,13.68,0,-2,13.69,0,-3,13.70,0,-3,ARL,0
2025-07-17T16:00:42.614396214Z,2025-07-17T16:00:42.614231125Z,10,2,1108,C,A,10,13.740000000,100,323370569,165089,270051092,13.31,10,1,13.28,1,2,13.27,10,1,13.14,1,1,13.13,100,1,13.11,100,1,13.10,100,1,13.04,2,1,13.02,200,2,12.99,100,1,13.40,0,-10,13.59,0,-1,13.60,0,-1,13.63,0,-1,13.64,0,-2,13.66,0,-2,13.67,0,-1,13.68,0,-2,13.69,0,-3,13.70,0,-3,ARL,0
2025-07-17T16:00:42.616178962Z,2025-07-17T16:00:42.616013371Z,10,2,1108,C,A,10,14.810000000,100,321097197,165591,270051093,13.31,10,1,13.28,1,2,13.27,10,1,13.14,1,1,13.13,100,1,13.11,100,1,13.10,100,1,13.04,2,1,13.02,200,2,12.99,100,1,13.40,0,-10,13.59,0,-1,13.60,0,-1,13.63,0,-1,13.64,0,-2,13.66,0,-2,13.67,0,-1,13.68,0,-2,13.69,0,-3,13.70,0,-3,ARL,0
2025-07-17T16:00:42.616178962Z,2025-07-17T16:00:42.616013371Z,10,2,1108,A,A,10,14.660000000,100,323599625,165591,270051093,13.31,10,1,13.28,1,2,13.27,10,1,13.14,1,1,13.13,100,1,13.11,100,1,13.10,100,1,13.04,2,1,13.02,200,2,12.99,100,1,13.40,0,-10,13.59,0,-1,13.60,0,-1,13.63,0,-1,13.64,0,-2,13.66,0,-2,13.67,0,-1,13.68,0,-2,13.69,0,-3,13.70,0,-3,ARL,0
2025-07-17T16:00:42.616321879Z,2025-07-17T16:00:42.616156310Z,10,2,1108,C,A,10,15.920000000,100,321096889,165569,270051094,13.31,10,1,13.28,1,2,13.27,10,1,13.14,1,1,13.13,100,1,13.11,100,1,13.10,100,1,13.04,2,1,13.02,200,2,12.99,100,1,13.40,0,-10,13.59,0,-1,13.60,0,-1,13.63,0,-1,13.64,0,-2,13.66,0,-2,13.67,0,-1,13.68,0,-2,13.69,0,-3,13.70,0,-3,ARL,0
2025-07-17T16:00:42.616321879Z,2025-07-17T16:00:42.616156310Z,10,2,1108,A,A,10,15.760000000,100,323599629,165569,270051094,13.31,10,1,13.28,1,2,13.27,10,1,13.14,1,1,13.13,100,1,13.11,100,1,13.10,100,1,13.04,2,1,13.02,200,2,12.99,100,1,13.40,0,-10,13.59,0,-1,13.60,0,-1,13.63,0,-1,13.64,0,-2,13.66,0,-2,13.67,0,-1,13.68,0,-2,13.69,0,-3,13.70,0,-3,ARL,0
2025-07-17T16:00:42.616352247Z,2025-07-17T16:00:42.616186901Z,10,2,1108,C,A,10,17.580000000,100,321096825,165346,270051095,13.31,10,1,13.28,1,2,13.27,10,1,13.14,1,1,13.13,100,1,13.11,100,1,13.10,100,1,13.04,2,1,13.02,200,2,12.99,100,1,13.40,0,-10,13.59,0,-1,13.60,0,-1,13.63,0,-1,13.64,0,-2,13.66,0,-2,13.67,0,-1,13.68,0,-2,13.69,0,-3,13.70,0,-3,ARL,0
2025-07-17T16:00:42.616352247Z,2025-07-17T16:00:42.616186901Z,10,2,1108,A,A,10,17.400000000,100,323599633,165346,270051095,13.31,10,1,13.28,1,2,13.27,10,1,13.14,1,1,13.13,100,1,13.11,100,1,13.10,100,1,13.04,2,1,13.02,200,2,12.99,100,1,13.40,0,-10,13.59,0,-1,13.60,0,-1,13.63,0,-1,13.64,0,-2,13.66,0,-2,13.67,0,-1,13.68,0,-2,13.69,0,-3,13.70,0,-3,ARL,0
2025-07-17T16:00:42.636761176Z,2025-07-17T16:00:42.636595817Z,10,2,1108,C,A,10,14.040000000,100,321500957,165359,270051179,13.31,10,1,13.28,1,2,13.27,10,1,13.14,1,1,13.13,100,1,13.11,100,1,13.10,100,1,13.04,2,1,13.02,200,2,12.99,100,1,13.40,0,-10,13.59,0,-1,13.60,0,-1,13.63,0,-1,13.64,0,-2,13.66,0,-2,13.67,0,-1,13.68,0,-2,13.69,0,-3,13.70,0,-3,ARL,0
2025-07-17T16:00:42.636814704Z,2025-07-17T16:00:42.636649389Z,10,2,1108,A,A,10,13.970000000,100,323599765,165315,270051181,13.31,10,1,13.28,1,2,13.27,10,1,13.14,1,1,13.13,100,1,13.11,100,1,13.10,100,1,13.04,2,1,13.02,200,2,12.99,100,1,13.40,0,-10,13.59,0,-1,13.60,0,-1,13.63,0,-1,13.64,0,-2,13.66,0,-2,13.67,0,-1,13.68,0,-2,13.69,0,-3,13.70,0,-3,ARL,0
2025-07-17T16:00:46.803262460Z,2025-07-17T16:00:46.803097192Z,10,2,1108,C,A,10,13.720000000,15,323238809,165268,270102799,13.31,10,1,13.28,1,2,13.27,10,1,13.14,1,1,13.13,100,1,13.11,100,1,13.10,100,1,13.04,2,1,13.02,200,2,12.99,100,1,13.40,0,-10,13.59,0,-1,13.60,0,-1,13.63,0,-1,13.64,0,-2,13.66,0,-2,13.67,0,-1,13.68,0,-2,13.69,0,-3,13.70,0,-3,ARL,0
2025-07-17T16:00:49.255631264Z,2025-07-17T16:00:49.255465939Z,10,2,1108,A,A,10,13.660000000,15,323720189,165325,270140405,13.31,10,1,13.28,1,2,13.27,10,1,13.14,1,1,13.13,100,1,13.11,100,1,13.10,100,1,13.04,2,1,13.02,200,2,12.99,100,1,13.40,0,-10,13.59,0,-1,13.60,0,-1,13.63,0,-1,13.64,0,-2,13.66,0,-2,13.67,0,-1,13.68,0,-2,13.69,0,-3,13.70,0,-3,ARL,0
2025-07-17T16:00:49.739644604Z,2025-07-17T16:00:49.739479408Z,10,2,1108,A,A,10,13.700000000,100,323730309,165196,270146528,13.31,10,1,13.28,1,2,13.27,10,1,13.14,1,1,13.13,100,1,13.11,100,1,13.10,100,1,13.04,2,1,13.02,200,2,12.99,100,1,13.40,0,-10,13.59,0,-1,13.60,0,-1,13.63,0,-1,13.64,0,-2,13.66,0,-2,13.67,0,-1,13.68,0,-2,13.69,0,-3,13.70,0,-3,ARL,0
2025-07-17T16:00:49.745038261Z,2025-07-17T16:00:49.744872763Z,10,2,1108,C,A,10,13.700000000,100,323599605,165498,270146577,13.31,10,1,13.28,1,2,13.27,10,1,13.14,1,1,13.13,100,1,13.11,100,1,13.10,100,1,13.04,2,1,13.02,200,2,12.99,100,1,13.40,0,-10,13.59,0,-1,13.60,0,-1,13.63,0,-1,13.64,0,-2,13.66,0,-2,13.67,0,-1,13.68,0,-2,13.69,0,-3,13.70,0,-4,ARL,0
2025-07-17T16:00:49.745038261Z,2025-07-17T16:00:49.744872763Z,10,2,1108,A,A,10,13.670000000,100,323730353,165498,270146577,13.31,10,1,13.28,1,2,13.27,10,1,13.14,1,1,13.13,100,1,13.11,100,1,13.10,100,1,13.04,2,1,13.02,200,2,12.99,100,1,13.40,0,-10,13.59,0,-1,13.60,0,-1,13.63,0,-1,13.64,0,-2,13.66,0,-2,13.67,0,-1,13.68,0,-2,13.69,0,-3,13.70,0,-4,ARL,0
2025-07-17T16:00:49.745778725Z,2025-07-17T16:00:49.745613051Z,10,2,1108,C,A,10,14.790000000,100,321511477,165674,270146581,13.31,10,1,13.28,1,2,13.27,10,1,13.14,1,1,13.13,100,1,13.11,100,1,13.10,100,1,13.04,2,1,13.02,200,2,12.99,100,1,13.40,0,-10,13.59,0,-1,13.60,0,-1,13.63,0,-1,13.64,0,-2,13.66,0,-2,13.67,0,-2,13.68,0,-2,13.69,0,-3,13.70,0,-4,ARL,0
2025-07-17T16:00:49.745778725Z,2025-07-17T16:00:49.745613051Z,10,2,1108,A,A,10,14.730000000,100,323730369,165674,270146581,13.31,10,1,13.28,1,2,13.27,10,1,13.14,1,1,13.13,100,1,13.11,100,1,13.10,100,1,13.04,2,1,13.02,200,2,12.99,100,1,13.40,0,-10,13.59,0,-1,13.60,0,-1,13.63,0,-1,13.64,0,-2,13.66,0,-2,13.67,0,-2,13.68,0,-2,13.69,0,-3,13.70,0,-4,ARL,0
2025-07-17T16:00:49.746422142Z,2025-07-17T16:00:49.746256906Z,10,2,1108,C,A,10,13.720000000,100,323599609,165236,270146586,13.31,10,1,13.28,1,2,13.27,10,1,13.14,1,1,13.13,100,1,13.11,100,1,13.10,100,1,13.04,2,1,13.02,200,2,12.99,100,1,13.40,0,-10,13.59,0,-1,13.60,0,-1,13.63,0,-1,13.64,0,-2,13.66,0,-2,13.67,0,-2,13.68,0,-2,13.69,0,-3,13.70,0,-4,ARL,0
2025-07-17T16:00:49.772631967Z,2025-07-17T16:00:49.772466772Z,10,2,1108,A,A,10,15.590000000,100,323730697,165195,270146838,13.31,10,1,13.28,1,2,13.27,10,1,13.14,1,1,13.13,100,1,13.11,100,1,13.10,100,1,13.04,2,1,13.02,200,2,12.99,100,1,13.40,0,-10,13.59,0,-1,13.60,0,-1,13.63,0,-1,13.64,0,-2,13.66,0,-2,13.67,0,-2,13.68,0,-2,13.69,0,-3,13.70,0,-4,ARL,0
2025-07-17T16:00:49.772645303Z,2025-07-17T16:00:49.772479921Z,10,2,1108,C,A,10,15.860000000,100,312771645,165382,270146839,13.31,10,1,13.28,1,2,13.27,10,1,13.14,1,1,13.13,100,1,13.11,100,1,13.10,100,1,13.04,2,1,13.02,200,2,12.99,100,1,13.40,0,-10,13.59,0,-1,13.60,0,-1,13.63,0,-1,13.64,0,-2,13.66,0,-2,13.67,0,-2,13.68,0,-2,13.69,0,-3,13.70,0,-4,ARL,0
2025-07-17T16:00:51.624811889Z,2025-07-17T16:00:51.624646272Z,10,2,1108,C,A,10,14.650000000,100,321293737,165617,270181394,13.31,10,1,13.28,1,2,13.27,10,1,13.14,1,1,13.13,100,1,13.11,100,1,13.10,100,1,13.04,2,1,13.02,200,2,12.99,100,1,13.40,0,-10,13.59,0,-1,13.60,0,-1,13.63,0,-1,13.64,0,-2,13.66,0,-2,13.67,0,-2,13.68,0,-2,13.69,0,-3,13.70,0,-4,ARL,0
2025-07-17T16:00:51.624811889Z,2025-07-17T16:00:51.624646272Z,10,2,1108,A,A,10,14.540000000,100,323775433,165617,270181394,13.31,10,1,13.28,1,2,13.27,10,1,13.14,1,1,13.13,100,1,13.11,100,1,13.10,100,1,13.04,2,1,13.02,200,2,12.99,100,1,13.40,0,-10,13.59,0,-1,13.60,0,-1,13.63,0,-1,13.64,0,-2,13.66,0,-2,13.67,0,-2,13.68,0,-2,13.69,0,-3,13.70,0,-4,ARL,0
2025-07-17T16:00:51.625372516Z,2025-07-17T16:00:51.625206675Z,10,2,1108,C,A,10,14.640000000,100,321293741,165841,270181399,13.31,10,1,13.28,1,2,13.27,10,1,13.14,1,1,13.13,100,1,13.11,100,1,13.10,100,1,13.04,2,1,13.02,200,2,12.99,100,1,13.40,0,-10,13.59,0,-1,13.60,0,-1,13.63,0,-1,13.64,0,-2,13.66,0,-2,13.67,0,-2,13.68,0,-2,13.69,0,-3,13.70,0,-4,ARL,0
2025-07-17T16:00:51.625372516Z,2025-07-17T16:00:51.625206675Z,10,2,1108,A,A,10,14.530000000,100,323775457,165841,270181399,13.31,10,1,13.28,1,2,13.27,10,1,13.14,1,1,13.13,100,1,13.11,100,1,13.10,100,1,13.04,2,1,13.02,200,2,12.99,100,1,13.40,0,-10,13.59,0,-1,13.60,0,-1,13.63,0,-1,13.64,0,-2,13.66,0,-2,13.67,0,-2,13.68,0,-2,13.69,0,-3,13.70,0,-4,ARL,0
2025-07-17T16:00:53.749335010Z,2025-07-17T16:00:53.749169565Z,10,2,1108,A,A,10,13.670000000,100,323803301,165445,270204567,13.31,10,1,13.28,1,2,13.27,10,1,13.14,1,1,13.13,100,1,13.11,100,1,13.10,100,1,13.04,2,1,13.02,200,2,12.99,100,1,13.40,0,-10,13.59,0,-1,13.60,0,-1,13.63,0,-1,13.64,0,-2,13.66,0,-2,13.67,0,-2,13.68,0,-2,13.69,0,-3,13.70,0,-4,ARL,0
2025-07-17T16:00:53.755966680Z,2025-07-17T16:00:53.755801462Z,10,2,1108,C,A,10,13.700000000,100,323730309,165218,270204616,13.31,10,1,13.28,1,2,13.27,10,1,13.14,1,1,13.13,100,1,13.11,100,1,13.10,100,1,13.04,2,1,13.02,200,2,12.99,100,1,13.40,0,-10,13.59,0,-1,13.60,0,-1,13.63,0,-1,13.64,0,-2,13.66,0,-2,13.67,0,-3,13.68,0,-2,13.69,0,-3,13.70,0,-4,ARL,0
2025-07-17T16:01:00.801342739Z,2025-07-17T16:01:00.801177403Z,10,2,1108,C,A,10,13.690000000,15,323455221,165336,270319932,13.31,10,1,13.28,1,2,13.27,10,1,13.14,1,1,13.13,100,1,13.11,100,1,13.10,100,1,13.04,2,1,13.02,200,2,12.99,100,1,13.40,0,-10,13.59,0,-1,13.60,0,-1,13.63,0,-1,13.64,0,-2,13.66,0,-2,13.67,0,-3,13.68,0,-2,13.69,0,-3,13.70,0,-4,ARL,0
2025-07-17T16:01:10.802877570Z,2025-07-17T16:01:10.802712247Z,10,2,1108,A,A,10,13.620000000,15,324161541,165323,270493149,13.31,10,1,13.28,1,2,13.27,10,1,13.14,1,1,13.13,100,1,13.11,100,1,13.10,100,1,13.04,2,1,13.02,200,2,12.99,100,1,13.40,0,-10,13.59,0,-1,13.60,0,-1,13.63,0,-1,13.64,0,-2,13.66,0,-2,13.67,0,-3,13.68,0,-2,13.69,0,-3,13.70,0,-4,ARL,0
2025-07-17T16:01:11.418837472Z,2025-07-17T16:01:11.418671671Z,10,2,1108,A,A,10,13.650000000,100,324175569,165801,270503944,13.31,10,1,13.28,1,2,13.27,10,1,13.14,1,1,13.13,100,1,13.11,100,1,13.10,100,1,13.04,2,1,13.02,200,2,12.99,100,1,13.40,0,-10,13.59,0,-1,13.60,0,-1,13.63,0,-1,13.64,0,-2,13.66,0,-2,13.67,0,-3,13.68,0,-2,13.69,0,-3,13.70,0,-4,ARL,0
2025-07-17T16:01:11.425922184Z,2025-07-17T16:01:11.425757014Z,10,2,1108,C,A,10,13.670000000,100,323803301,165170,270504009,13.31,10,1,13.28,1,2,13.27,10,1,13.14,1,1,13.13,100,1,13.11,100,1,13.10,100,1,13.04,2,1,13.02,200,2,12.99,100,1,13.40,0,-10,13.59,0,-1,13.60,0,-1,13.63,0,-1,13.64,0,-2,13.65,0,-1,13.66,0,-2,13.67,0,-3,13.68,0,-2,13.69,0,-3,ARL,0
2025-07-17T16:01:11.820753616Z,2025-07-17T16:01:11.820588141Z,10,2,1108,C,A,10,13.670000000,100,323730353,165475,270509970,13.31,10,1,13.28,1,2,13.27,10,1,13.14,1,1,13.13,100,1,13.11,100,1,13.10,100,1,13.04,2,1,13.02,200,2,12.99,100,1,13.40,0,-10,13.59,0,-1,13.60,0,-1,13.63,0,-1,13.64,0,-2,13.65,0,-1,13.66,0,-2,13.67,0,-3,13.68,0,-2,13.69,0,-3,ARL,0
2025-07-17T16:01:11.820753616Z,2025-07-17T16:01:11.820588141Z,10,2,1108,A,A,10,13.630000000,100,324186213,165475,270509970,13.31,10,1,13.28,1,2,13.27,10,1,13.14,1,1,13.13,100,1,13.11,100,1,13.10,100,1,13.04,2,1,13.02,200,2,12.99,100,1,13.40,0,-10,13.59,0,-1,13.60,0,-1,13.63,0,-1,13.64,0,-2,13.65,0,-1,13.66,0,-2,13.67,0,-3,13.68,0,-2,13.69,0,-3,ARL,0
2025-07-17T16:01:11.821515043Z,2025-07-17T16:01:11.821349600Z,10,2,1108,C,A,10,14.730000000,100,323730369,165443,270509983,13.31,10,1,13.28,1,2,13.27,10,1,13.14,1,1,13.13,100,1,13.11,100,1,13.10,100,1,13.04,2,1,13.02,200,2,12.99,100,1,13.40,0,-10,13.59,0,-1,13.60,0,-1,13.63,0,-2,13.64,0,-2,13.65,0,-1,13.66,0,-2,13.67,0,-3,13.68,0,-2,13.69,0,-3,ARL,0
2025-07-17T16:01:11.821515043Z,2025-07-17T16:01:11.821349600Z,10,2,1108,A,A,10,14.690000000,100,324186233,165443,270509983,13.31,10,1,13.28,1,2,13.27,10,1,13.14,1,1,13.13,100,1,13.11,100,1,13.10,100,1,13.04,2,1,13.02,200,2,12.99,100,1,13.40,0,-10,13.59,0,-1,13.60,0,-1,13.63,0,-2,13.64,0,-2,13.65,0,-1,13.66,0,-2,13.67,0,-3,13.68,0,-2,13.69,0,-3,ARL,0
2025-07-17T16:01:11.826399871Z,2025-07-17T16:01:11.826234488Z,10,2,1108,C,A,10,13.970000000,100,323599765,165383,270510142,13.31,10,1,13.28,1,2,13.27,10,1,13.14,1,1,13.13,100,1,13.11,100,1,13.10,100,1,13.04,2,1,13.02,200,2,12.99,100,1,13.40,0,-10,13.59,0,-1,13.60,0,-1,13.63,0,-2,13.64,0,-2,13.65,0,-1,13.66,0,-2,13.67,0,-3,13.68,0,-2,13.69,0,-3,ARL,0
2025-07-17T16:01:11.826451447Z,2025-07-17T16:01:11.826286284Z,10,2,1108,A,A,10,13.900000000,100,324186721,165163,270510143,13.31,10,1,13.28,1,2,13.27,10,1,13.14,1,1,13.13,100,1,13.11,100,1,13.10,100,1,13.04,2,1,13.02,200,2,12.99,100,1,13.40,0,-10,13.59,0,-1,13.60,0,-1,13.63,0,-2,13.64,0,-2,13.65,0,-1,13.66,0,-2,13.67,0,-3,13.68,0,-2,13.69,0,-3,ARL,0
2025-07-17T16:01:11.828630414Z,2025-07-17T16:01:11.828464891Z,10,2,1108,C,A,10,14.580000000,100,321309941,165523,270510182,13.31,10,1,13.28,1,2,13.27,10,1,13.14,1,1,13.13,100,1,13.11,100,1,13.10,100,1,13.04,2,1,13.02,200,2,12.99,100,1,13.40,0,-10,13.59,0,-1,13.60,0,-1,13.63,0,-2,13.64,0,-2,13.65,0,-1,13.66,0,-2,13.67,0,-3,13.68,0,-2,13.69,0,-3,ARL,0
2025-07-17T16:01:11.828630414Z,2025-07-17T16:01:11.828464891Z,10,2,1108,A,A,10,14.430000000,100,324186781,165523,270510182,13.31,10,1,13.28,1,2,13.27,10,1,13.14,1,1,13.13,100,1,13.11,100,1,13.10,100,1,13.04,2,1,13.02,200,2,12.99,100,1,13.40,0,-10,13.59,0,-1,13.60,0,-1,13.63,0,-2,13.64,0,-2,13.65,0,-1,13.66,0,-2,13.67,0,-3,13.68,0,-2,13.69,0,-3,ARL,0
2025-07-17T16:01:22.802518536Z,2025-07-17T16:01:22.802353061Z,10,2,1108,C,A,10,13.660000000,15,323720189,165475,270674903,13.31,10,1,13.28,1,2,13.27,10,1,13.14,1,1,13.13,100,1,13.11,100,1,13.10,100,1,13.04,2,1,13.02,200,2,12.99,100,1,13.40,0,-10,13.59,0,-1,13.60,0,-1,13.63,0,-2,13.64,0,-2,13.65,0,-1,13.66,0,-2,13.67,0,-3,13.68,0,-2,13.69,0,-3,ARL,0
2025-07-17T16:01:32.804004639Z,2025-07-17T16:01:32.803839043Z,10,2,1108,A,A,10,13.600000000,15,324619361,165596,270824320,13.31,10,1,13.28,1,2,13.27,10,1,13.14,1,1,13.13,100,1,13.11,100,1,13.10,100,1,13.04,2,1,13.02,200,2,12.99,100,1,13.40,0,-10,13.59,0,-1,13.60,0,-1,13.63,0,-2,13.64,0,-2,13.65,0,-1,13.66,0,-2,13.67,0,-3,13.68,0,-2,13.69,0,-3,ARL,0
2025-07-17T16:01:32.804274168Z,2025-07-17T16:01:32.804108576Z,10,2,1108,C,A,10,13.630000000,100,324186213,165592,270824323,13.31,10,1,13.28,1,2,13.27,10,1,13.14,1,1,13.13,100,1,13.11,100,1,13.10,100,1,13.04,2,1,13.02,200,2,12.99,100,1,13.40,0,-10,13.59,0,-1,13.60,0,-2,13.63,0,-2,13.64,0,-2,13.65,0,-1,13.66,0,-2,13.67,0,-3,13.68,0,-2,13.69,0,-3,ARL,0
2025-07-17T16:01:32.804274168Z,2025-07-17T16:01:32.804108576Z,10,2,1108,A,A,10,13.610000000,100,324619369,165592,270824323,13.31,10,1,13.28,1,2,13.27,10,1,13.14,1,1,13.13,100,1,13.11,100,1,13.10,100,1,13.04,2,1,13.02,200,2,12.99,100,1,13.40,0,-10,13.59,0,-1,13.60,0,-2,13.63,0,-2,13.64,0,-2,13.65,0,-1,13.66,0,-2,13.67,0,-3,13.68,0,-2,13.69,0,-3,ARL,0
2025-07-17T16:01:32.806299464Z,2025-07-17T16:01:32.806134020Z,10,2,1108,C,A,10,14.730000000,100,321500349,165444,270824400,13.31,10,1,13.28,1,2,13.27,10,1,13.14,1,1,13.13,100,1,13.11,100,1,13.10,100,1,13.04,2,1,13.02,200,2,12.99,100,1,13.40,0,-10,13.59,0,-1,13.60,0,-2,13.61,0,-1,13.63,0,-2,13.64,0,-2,13.65,0,-1,13.66,0,-2,13.67,0,-3,13.68,0,-2,ARL,0
2025-07-17T16:01:32.806299464Z,2025-07-17T16:01:32.806134020Z,10,2,1108,A,A,10,14.570000000,100,324619409,165444,270824400,13.31,10,1,13.28,1,2,13.27,10,1,13.14,1,1,13.13,100,1,13.11,100,1,13.10,100,1,13.04,2,1,13.02,200,2,12.99,100,1,13.40,0,-10,13.59,0,-1,13.60,0,-2,13.61,0,-1,13.63,0,-2,13.64,0,-2,13.65,0,-1,13.66,0,-2,13.67,0,-3,13.68,0,-2,ARL,0
2025-07-17T16:01:32.815913520Z,2025-07-17T16:01:32.815748258Z,10,2,1108,A,A,10,13.630000000,100,324619837,165262,270824657,13.31,10,1,13.28,1,2,13.27,10,1,13.14,1,1,13.13,100,1,13.11,100,1,13.10,100,1,13.04,2,1,13.02,200,2,12.99,100,1,13.40,0,-10,13.59,0,-1,13.60,0,-2,13.61,0,-1,13.63,0,-2,13.64,0,-2,13.65,0,-1,13.66,0,-2,13.67,0,-3,13.68,0,-2,ARL,0
2025-07-17T16:01:32.822608966Z,2025-07-17T16:01:32.822443626Z,10,2,1108,C,A,10,13.650000000,100,324175569,165340,270824747,13.31,10,1,13.28,1,2,13.27,10,1,13.14,1,1,13.13,100,1,13.11,100,1,13.10,100,1,13.04,2,1,13.02,200,2,12.99,100,1,13.40,0,-10,13.59,0,-1,13.60,0,-2,13.61,0,-1,13.63,0,-3,13.64,0,-2,13.65,0,-1,13.66,0,-2,13.67,0,-3,13.68,0,-2,ARL,0
2025-07-17T16:01:37.242690420Z,2025-07-17T16:01:37.242525208Z,10,2,1108,C,A,10,13.620000000,15,324161541,165212,270889017,13.31,10,1,13.28,1,2,13.27,10,1,13.14,1,1,13.13,100,1,13.11,100,1,13.10,100,1,13.04,2,1,13.02,200,2,12.99,100,1,13.40,0,-10,13.59,0,-1,13.60,0,-2,13.61,0,-1,13.63,0,-3,13.64,0,-2,13.65,0,-1,13.66,0,-2,13.67,0,-3,13.68,0,-2,ARL,0
2025-07-17T16:01:40.605797765Z,2025-07-17T16:01:40.605632399Z,10,2,1108,A,A,10,13.610000000,100,324782841,165366,270946497,13.31,10,1,13.28,1,2,13.27,10,1,13.14,1,1,13.13,100,1,13.11,100,1,13.10,100,1,13.04,2,1,13.02,200,2,12.99,100,1,13.40,0,-10,13.59,0,-1,13.60,0,-2,13.61,0,-1,13.63,0,-3,13.64,0,-2,13.65,0,-1,13.66,0,-2,13.67,0,-3,13.68,0,-2,ARL,0
2025-07-17T16:01:40.653738176Z,2025-07-17T16:01:40.653572805Z,10,2,1108,C,A,10,13.630000000,100,324619837,165371,270946779,13.31,10,1,13.28,1,2,13.27,10,1,13.14,1,1,13.13,100,1,13.11,100,1,13.10,100,1,13.04,2,1,13.02,200,2,12.99,100,1,13.40,0,-10,13.59,0,-1,13.60,0,-2,13.61,0,-2,13.63,0,-3,13.64,0,-2,13.65,0,-1,13.66,0,-2,13.67,0,-3,13.68,0,-2,ARL,0
2025-07-17T16:01:47.565991684Z,2025-07-17T16:01:47.565825466Z,10,2,1108,A,A,10,13.570000000,15,324934601,166218,271062350,13.31,10,1,13.28,1,2,13.27,10,1,13.14,1,1,13.13,100,1,13.11,100,1,13.10,100,1,13.04,2,1,13.02,200,2,12.99,100,1,13.40,0,-10,13.59,0,-1,13.60,0,-2,13.61,0,-2,13.63,0,-3,13.64,0,-2,13.65,0,-1,13.66,0,-2,13.67,0,-3,13.68,0,-2,ARL,0
2025-07-17T16:01:47.902969773Z,2025-07-17T16:01:47.902804446Z,10,2,1108,C,A,10,13.610000000,100,324619369,165327,271068098,13.31,10,1,13.28,1,2,13.27,10,1,13.14,1,1,13.13,100,1,13.11,100,1,13.10,100,1,13.04,2,1,13.02,200,2,12.99,100,1,13.40,0,-10,13.57,0,-1,13.59,0,-1,13.60,0,-2,13.61,0,-2,13.63,0,-3,13.64,0,-2,13.65,0,-1,13.66,0,-2,13.67,0,-3,ARL,0
2025-07-17T16:01:47.902969773Z,2025-07-17T16:01:47.902804446Z,10,2,1108,A,A,10,13.580000000,100,324942229,165327,271068098,13.31,10,1,13.28,1,2,13.27,10,1,13.14,1,1,13.13,100,1,13.11,100,1,13.10,100,1,13.04,2,1,13.02,200,2,12.99,100,1,13.40,0,-10,13.57,0,-1,13.59,0,-1,13.60,0,-2,13.61,0,-2,13.63,0,-3,13.64,0,-2,13.65,0,-1,13.66,0,-2,13.67,0,-3,ARL,0
2025-07-17T16:01:47.903711757Z,2025-07-17T16:01:47.903546622Z,10,2,1108,C,A,10,14.400000000,100,289726421,165135,271068105,13.31,10,1,13.28,1,2,13.27,10,1,13.14,1,1,13.13,100,1,13.11,100,1,13.10,100,1,13.04,2,1,13.02,200,2,12.99,100,1,13.40,0,-10,13.57,0,-1,13.58,0,-1,13.59,0,-1,13.60,0,-2,13.61,0,-2,13.63,0,-3,13.64,0,-2,13.65,0,-1,13.66,0,-2,ARL,0
2025-07-17T16:01:47.903714323Z,2025-07-17T16:01:47.903548861Z,10,2,1108,C,A,10,14.690000000,100,324186233,165462,271068106,13.31,10,1,13.28,1,2,13.27,10,1,13.14,1,1,13.13,100,1,13.11,100,1,13.10,100,1,13.04,2,1,13.02,200,2,12.99,100,1,13.40,0,-10,13.57,0,-1,13.58,0,-1,13.59,0,-1,13.60,0,-2,13.61,0,-2,13.63,0,-3,13.64,0,-2,13.65,0,-1,13.66,0,-2,ARL,0
2025-07-17T16:01:47.903714323Z,2025-07-17T16:01:47.903548861Z,10,2,1108,A,A,10,14.630000000,100,324942257,165462,271068106,13.31,10,1,13.28,1,2,13.27,10,1,13.14,1,1,13.13,100,1,13.11,100,1,13.10,100,1,13.04,2,1,13.02,200,2,12.99,100,1,13.40,0,-10,13.57,0,-1,13.58,0,-1,13.59,0,-1,13.60,0,-2,13.61,0,-2,13.63,0,-3,13.64,0,-2,13.65,0,-1,13.66,0,-2,ARL,0
2025-07-17T16:01:47.904067686Z,2025-07-17T16:01:47.903902473Z,10,2,1108,A,A,10,14.190000000,100,324942273,165213,271068115,13.31,10,1,13.28,1,2,13.27,10,1,13.14,1,1,13.13,100,1,13.11,100,1,13.10,100,1,13.04,2,1,13.02,200,2,12.99,100,1,13.40,0,-10,13.57,0,-1,13.58,0,-1,13.59,0,-1,13.60,0,-2,13.61,0,-2,13.63,0,-3,13.64,0,-2,13.65,0,-1,13.66,0,-2,ARL,0
2025-07-17T16:01:47.905355779Z,2025-07-17T16:01:47.905189816Z,10,2,1108,C,A,10,15.230000000,100,282776017,165963,271068134,13.31,10,1,13.28,1,2,13.27,10,1,13.14,1,1,13.13,100,1,13.11,100,1,13.10,100,1,13.04,2,1,13.02,200,2,12.99,100,1,13.40,0,-10,13.57,0,-1,13.58,0,-1,13.59,0,-1,13.60,0,-2,13.61,0,-2,13.63,0,-3,13.64,0,-2,13.65,0,-1,13.66,0,-2,ARL,0
2025-07-17T16:01:47.905355779Z,2025-07-17T16:01:47.905189816Z,10,2,1108,A,A,10,14.940000000,100,324942277,165963,271068134,13.31,10,1,13.28,1,2,13.27,10,1,13.14,1,1,13.13,100,1,13.11,100,1,13.10,100,1,13.04,2,1,13.02,200,2,12.99,100,1,13.40,0,-10,13.57,0,-1,13.58,0,-1,13.59,0,-1,13.60,0,-2,13.61,0,-2,13.63,0,-3,13.64,0,-2,13.65,0,-1,13.66,0,-2,ARL,0
2025-07-17T16:01:47.909479724Z,2025-07-17T16:01:47.909314303Z,10,2,1108,C,A,10,17.400000000,100,323599633,165421,271068173,13.31,10,1,13.28,1,2,13.27,10,1,13.14,1,1,13.13,100,1,13.11,100,1,13.10,100,1,13.04,2,1,13.02,200,2,12.99,100,1,13.40,0,-10,13.57,0,-1,13.58,0,-1,13.59,0,-1,13.60,0,-2,13.61,0,-2,13.63,0,-3,13.64,0,-2,13.65,0,-1,13.66,0,-2,ARL,0
2025-07-17T16:01:47.909479724Z,2025-07-17T16:01:47.909314303Z,10,2,1108,A,A,10,17.250000000,100,324942361,165421,271068173,13.31,10,1,13.28,1,2,13.27,10,1,13.14,1,1,13.13,100,1,13.11,100,1,13.10,100,1,13.04,2,1,13.02,200,2,12.99,100,1,13.40,0,-10,13.57,0,-1,13.58,0,-1,13.59,0,-1,13.60,0,-2,13.61,0,-2,13.63,0,-3,13.64,0,-2,13.65,0,-1,13.66,0,-2,ARL,0
2025-07-17T16:01:50.799100504Z,2025-07-17T16:01:50.798934838Z,10,2,1108,A,A,10,13.590000000,100,325022101,165666,271131418,13.31,10,1,13.28,1,2,13.27,10,1,13.14,1,1,13.13,100,1,13.11,100,1,13.10,100,1,13.04,2,1,13.02,200,2,12.99,100,1,13.40,0,-10,13.57,0,-1,13.58,0,-1,13.59,0,-1,13.60,0,-2,13.61,0,-2,13.63,0,-3,13.64,0,-2,13.65,0,-1,13.66,0,-2,ARL,0
2025-07-17T16:01:50.805653961Z,2025-07-17T16:01:50.805488726Z,10,2,1108,C,A,10,13.610000000,100,324782841,165235,271131583,13.31,10,1,13.28,1,2,13.27,10,1,13.14,1,1,13.13,100,1,13.11,100,1,13.10,100,1,13.04,2,1,13.02,200,2,12.99,100,1,13.40,0,-10,13.57,0,-1,13.58,0,-1,13.59,0,-2,13.60,0,-2,13.61,0,-2,13.63,0,-3,13.64,0,-2,13.65,0,-1,13.66,0,-2,ARL,0
2025-07-17T16:01:52.133063761Z,2025-07-17T16:01:52.132898568Z,10,2,1108,C,A,10,13.600000000,15,324619361,165193,271153294,13.31,10,1,13.28,1,2,13.27,10,1,13.14,1,1,13.13,100,1,13.11,100,1,13.10,100,1,13.04,2,1,13.02,200,2,12.99,100,1,13.40,0,-10,13.57,0,-1,13.58,0,-1,13.59,0,-2,13.60,0,-2,13.61,0,-2,13.63,0,-3,13.64,0,-2,13.65,0,-1,13.66,0,-2,ARL,0
2025-07-17T16:01:53.137501962Z,2025-07-17T16:01:53.137336077Z,10,2,1108,A,A,10,13.550000000,15,325109165,165885,271200452,13.31,10,1,13.28,1,2,13.27,10,1,13.14,1,1,13.13,100,1,13.11,100,1,13.10,100,1,13.04,2,1,13.02,200,2,12.99,100,1,13.40,0,-10,13.57,0,-1,13.58,0,-1,13.59,0,-2,13.60,0,-2,13.61,0,-2,13.63,0,-3,13.64,0,-2,13.65,0,-1,13.66,0,-2,ARL,0
2025-07-17T16:01:56.264154095Z,2025-07-17T16:01:56.263988198Z,10,2,1108,C,A,10,13.580000000,100,324942229,165897,271251019,13.31,10,1,13.28,1,2,13.27,10,1,13.14,1,1,13.13,100,1,13.11,100,1,13.10,100,1,13.04,2,1,13.02,200,2,12.99,100,1,13.40,0,-10,13.55,0,-1,13.57,0,-1,13.58,0,-1,13.59,0,-2,13.60,0,-2,13.61,0,-2,13.63,0,-3,13.64,0,-2,13.65,0,-1,ARL,0
2025-07-17T16:01:56.264154095Z,2025-07-17T16:01:56.263988198Z,10,2,1108,A,A,10,13.560000000,100,325176181,165897,271251019,13.31,10,1,13.28,1,2,13.27,10,1,13.14,1,1,13.13,100,1,13.11,100,1,13.10,100,1,13.04,2,1,13.02,200,2,12.99,100,1,13.40,0,-10,13.55,0,-1,13.57,0,-1,13.58,0,-1,13.59,0,-2,13.60,0,-2,13.61,0,-2,13.63,0,-3,13.64,0,-2,13.65,0,-1,ARL,0
2025-07-17T16:01:56.269623788Z,2025-07-17T16:01:56.269458197Z,10,2,1108,C,A,10,13.900000000,100,324186721,165591,271251357,13.31,10,1,13.28,1,2,13.27,10,1,13.14,1,1,13.13,100,1,13.11,100,1,13.10,100,1,13.04,2,1,13.02,200,2,12.99,100,1,13.40,0,-10,13.55,0,-1,13.56,0,-1,13.57,0,-1,13.58,0,-1,13.59,0,-2,13.60,0,-2,13.61,0,-2,13.63,0,-3,13.64,0,-2,ARL,0
2025-07-17T16:01:56.269674232Z,2025-07-17T16:01:56.269508928Z,10,2,1108,A,A,10,13.830000000,100,325176373,165304,271251358,13.31,10,1,13.28,1,2,13.27,10,1,13.14,1,1,13.13,100,1,13.11,100,1,13.10,100,1,13.04,2,1,13.02,200,2,12.99,100,1,13.40,0,-10,13.55,0,-1,13.56,0,-1,13.57,0,-1,13.58,0,-1,13.59,0,-2,13.60,0,-2,13.61,0,-2,13.63,0,-3,13.64,0,-2,ARL,0
2025-07-17T16:01:56.272340730Z,2025-07-17T16:01:56.272175169Z,10,2,1108,C,A,10,15.760000000,100,323599629,165561,271251490,13.31,10,1,13.28,1,2,13.27,10,1,13.14,1,1,13.13,100,1,13.11,100,1,13.10,100,1,13.04,2,1,13.02,200,2,12.99,100,1,13.40,0,-10,13.55,0,-1,13.56,0,-1,13.57,0,-1,13.58,0,-1,13.59,0,-2,13.60,0,-2,13.61,0,-2,13.63,0,-3,13.64,0,-2,ARL,0
2025-07-17T16:01:56.272340730Z,2025-07-17T16:01:56.272175169Z,10,2,1108,A,A,10,15.600000000,100,325176677,165561,271251490,13.31,10,1,13.28,1,2,13.27,10,1,13.14,1,1,13.13,100,1,13.11,100,1,13.10,100,1,13.04,2,1,13.02,200,2,12.99,100,1,13.40,0,-10,13.55,0,-1,13.56,0,-1,13.57,0,-1,13.58,0,-1,13.59,0,-2,13.60,0,-2,13.61,0,-2,13.63,0,-3,13.64,0,-2,ARL,0
2025-07-17T16:01:56.300889378Z,2025-07-17T16:01:56.300723805Z,10,2,1108,C,A,10,14.660000000,100,323599625,165573,271252044,13.31,10,1,13.28,1,2,13.27,10,1,13.14,1,1,13.13,100,1,13.11,100,1,13.10,100,1,13.04,2,1,13.02,200,2,12.99,100,1,13.40,0,-10,13.55,0,-1,13.56,0,-1,13.57,0,-1,13.58,0,-1,13.59,0,-2,13.60,0,-2,13.61,0,-2,13.63,0,-3,13.64,0,-2,ARL,0
2025-07-17T16:01:56.300889378Z,2025-07-17T16:01:56.300723805Z,10,2,1108,A,A,10,14.510000000,100,325177757,165573,271252044,13.31,10,1,13.28,1,2,13.27,10,1,13.14,1,1,13.13,100,1,13.11,100,1,13.10,100,1,13.04,2,1,13.02,200,2,12.99,100,1,13.40,0,-10,13.55,0,-1,13.56,0,-1,13.57,0,-1,13.58,0,-1,13.59,0,-2,13.60,0,-2,13.61,0,-2,13.63,0,-3,13.64,0,-2,ARL,0
2025-07-17T16:02:01.992544607Z,2025-07-17T16:02:01.992379223Z,10,2,1108,C,A,10,14.010000000,2,322898193,165384,271343251,13.31,10,1,13.28,1,2,13.27,10,1,13.14,1,1,13.13,100,1,13.11,100,1,13.10,100,1,13.04,2,1,13.02,200,2,12.99,100,1,13.40,0,-10,13.55,0,-1,13.56,0,-1,13.57,0,-1,13.58,0,-1,13.59,0,-2,13.60,0,-2,13.61,0,-2,13.63,0,-3,13.64,0,-2,ARL,0
2025-07-17T16:02:01.992544607Z,2025-07-17T16:02:01.992379223Z,10,2,1108,A,A,10,13.920000000,2,325297093,165384,271343251,13.31,10,1,13.28,1,2,13.27,10,1,13.14,1,1,13.13,100,1,13.11,100,1,13.10,100,1,13.04,2,1,13.02,200,2,12.99,100,1,13.40,0,-10,13.55,0,-1,13.56,0,-1,13.57,0,-1,13.58,0,-1,13.59,0,-2,13.60,0,-2,13.61,0,-2,13.63,0,-3,13.64,0,-2,ARL,0
2025-07-17T16:02:03.207720826Z,2025-07-17T16:02:03.207555626Z,10,2,1108,C,A,10,13.570000000,15,324934601,165200,271367066,13.31,10,1,13.28,1,2,13.27,10,1,13.14,1,1,13.13,100,1,13.11,100,1,13.10,100,1,13.04,2,1,13.02,200,2,12.99,100,1,13.40,0,-10,13.55,0,-1,13.56,0,-1,13.57,0,-1,13.58,0,-1,13.59,0,-2,13.60,0,-2,13.61,0,-2,13.63,0,-3,13.64,0,-2,ARL,0
2025-07-17T16:02:04.212956339Z,2025-07-17T16:02:04.212791108Z,10,2,1108,A,A,10,13.530000000,15,325382429,165231,271415821,13.31,10,1,13.28,1,2,13.27,10,1,13.14,1,1,13.13,100,1,13.11,100,1,13.10,100,1,13.04,2,1,13.02,200,2,12.99,100,1,13.40,0,-10,13.55,0,-1,13.56,0,-1,13.57,0,-1,13.58,0,-1,13.59,0,-2,13.60,0,-2,13.61,0,-2,13.63,0,-3,13.64,0,-2,ARL,0
2025-07-17T16:02:04.214348814Z,2025-07-17T16:02:04.214183279Z,10,2,1108,C,A,10,14.540000000,100,323775433,165535,271415834,13.31,10,1,13.28,1,2,13.27,10,1,13.14,1,1,13.13,100,1,13.11,100,1,13.10,100,1,13.04,2,1,13.02,200,2,12.99,100,1,13.40,0,-10,13.53,0,-1,13.55,0,-1,13.56,0,-1,13.57,0,-1,13.58,0,-1,13.59,0,-2,13.60,0,-2,13.61,0,-2,13.63,0,-3,ARL,0
2025-07-17T16:02:04.214348814Z,2025-07-17T16:02:04.214183279Z,10,2,1108,A,A,10,14.430000000,100,325382437,165535,271415834,13.31,10,1,13.28,1,2,13.27,10,1,13.14,1,1,13.13,100,1,13.11,100,1,13.10,100,1,13.04,2,1,13.02,200,2,12.99,100,1,13.40,0,-10,13.53,0,-1,13.55,0,-1,13.56,0,-1,13.57,0,-1,13.58,0,-1,13.59,0,-2,13.60,0,-2,13.61,0,-2,13.63,0,-3,ARL,0
2025-07-17T16:02:04.840132668Z,2025-07-17T16:02:04.839967173Z,10,2,1108,C,A,10,13.560000000,100,325176181,165495,271432190,13.31,10,1,13.28,1,2,13.27,10,1,13.14,1,1,13.13,100,1,13.11,100,1,13.10,100,1,13.04,2,1,13.02,200,2,12.99,100,1,13.40,0,-10,13.53,0,-1,13.55,0,-1,13.56,0,-1,13.57,0,-1,13.58,0,-1,13.59,0,-2,13.60,0,-2,13.61,0,-2,13.63,0,-3,ARL,0
2025-07-17T16:02:04.840132668Z,2025-07-17T16:02:04.839967173Z,10,2,1108,A,A,10,13.540000000,100,325400045,165495,271432190,13.31,10,1,13.28,1,2,13.27,10,1,13.14,1,1,13.13,100,1,13.11,100,1,13.10,100,1,13.04,2,1,13.02,200,2,12.99,100,1,13.40,0,-10,13.53,0,-1,13.55,0,-1,13.56,0,-1,13.57,0,-1,13.58,0,-1,13.59,0,-2,13.60,0,-2,13.61,0,-2,13.63,0,-3,ARL,0
2025-07-17T16:02:04.840171240Z,2025-07-17T16:02:04.840006082Z,10,2,1108,A,A,10,14.270000000,700,325400053,165158,271432192,13.31,10,1,13.28,1,2,13.27,10,1,13.14,1,1,13.13,100,1,13.11,100,1,13.10,100,1,13.04,2,1,13.02,200,2,12.99,100,1,13.40,0,-10,13.53,0,-1,13.55,0,-1,13.56,0,-1,13.57,0,-1,13.58,0,-1,13.59,0,-2,13.60,0,-2,13.61,0,-2,13.63,0,-3,ARL,0
2025-07-17T16:02:04.840210880Z,2025-07-17T16:02:04.840045694Z,10,2,1108,C,A,10,14.680000000,700,283592941,165186,271432193,13.31,10,1,13.28,1,2,13.27,10,1,13.14,1,1,13.13,100,1,13.11,100,1,13.10,100,1,13.04,2,1,13.02,200,2,12.99,100,1,13.40,0,-10,13.53,0,-1,13.55,0,-1,13.56,0,-1,13.57,0,-1,13.58,0,-1,13.59,0,-2,13.60,0,-2,13.61,0,-2,13.63,0,-3,ARL,0
2025-07-17T16:02:04.840877603Z,2025-07-17T16:02:04.840711803Z,10,2,1108,C,A,10,14.630000000,100,324942257,165800,271432231,13.31,10,1,13.28,1,2,13.27,10,1,13.14,1,1,13.13,100,1,13.11,100,1,13.10,100,1,13.04,2,1,13.02,200,2,12.99,100,1,13.40,0,-10,13.53,0,-1,13.55,0,-1,13.56,0,-1,13.57,0,-1,13.58,0,-1,13.59,0,-2,13.60,0,-2,13.61,0,-2,13.63,0,-3,ARL,0
2025-07-17T16:02:04.840877603Z,2025-07-17T16:02:04.840711803Z,10,2,1108,A,A,10,14.590000000,100,325400105,165800,271432231,13.31,10,1,13.28,1,2,13.27,10,1,13.14,1,1,13.13,100,1,13.11,100,1,13.10,100,1,13.04,2,1,13.02,200,2,12.99,100,1,13.40,0,-10,13.53,0,-1,13.55,0,-1,13.56,0,-1,13.57,0,-1,13.58,0,-1,13.59,0,-2,13.60,0,-2,13.61,0,-2,13.63,0,-3,ARL,0
2025-07-17T16:02:11.249291142Z,2025-07-17T16:02:11.249125653Z,10,2,1108,C,A,10,14.530000000,100,323775457,165489,271526467,13.31,10,1,13.28,1,2,13.27,10,1,13.14,1,1,13.13,100,1,13.11,100,1,13.10,100,1,13.04,2,1,13.02,200,2,12.99,100,1,13.40,0,-10,13.53,0,-1,13.55,0,-1,13.56,0,-1,13.57,0,-1,13.58,0,-1,13.59,0,-2,13.60,0,-2,13.61,0,-2,13.63,0,-3,ARL,0
2025-07-17T16:02:11.249291142Z,2025-07-17T16:02:11.249125653Z,10,2,1108,A,A,10,14.420000000,100,325520705,165489,271526467,13.31,10,1,13.28,1,2,13.27,10,1,13.14,1,1,13.13,100,1,13.11,100,1,13.10,100,1,13.04,2,1,13.02,200,2,12.99,100,1,13.40,0,-10,13.53,0,-1,13.55,0,-1,13.56,0,-1,13.57,0,-1,13.58,0,-1,13.59,0,-2,13.60,0,-2,13.61,0,-2,13.63,0,-3,ARL,0
2025-07-17T16:02:15.062774661Z,2025-07-17T16:02:15.062605521Z,10,2,1108,C,A,10,13.530000000,15,325382429,169140,271576282,13.31,10,1,13.28,1,2,13.27,10,1,13.14,1,1,13.13,100,1,13.11,100,1,13.10,100,1,13.04,2,1,13.02,200,2,12.99,100,1,13.40,0,-10,13.53,0,-1,13.55,0,-1,13.56,0,-1,13.57,0,-1,13.58,0,-1,13.59,0,-2,13.60,0,-2,13.61,0,-2,13.63,0,-3,ARL,0
2025-07-17T16:02:15.068449048Z,2025-07-17T16:02:15.068283706Z,10,2,1108,C,A,10,13.550000000,15,325109165,165342,271577104,13.31,10,1,13.28,1,2,13.27,10,1,13.14,1,1,13.13,100,1,13.11,100,1,13.10,100,1,13.04,2,1,13.02,200,2,12.99,100,1,13.40,0,-10,13.53,0,-1,13.55,0,-1,13.56,0,-1,13.57,0,-1,13.58,0,-1,13.59,0,-2,13.60,0,-2,13.61,0,-2,13.63,0,-3,ARL,0
2025-07-17T16:02:20.635028489Z,2025-07-17T16:02:20.634863301Z,10,2,1108,C,A,10,13.540000000,100,325400045,165188,271675842,13.31,10,1,13.28,1,2,13.27,10,1,13.14,1,1,13.13,100,1,13.11,100,1,13.10,100,1,13.04,2,1,13.02,200,2,12.99,100,1,13.40,0,-10,13.53,0,-1,13.55,0,-1,13.56,0,-1,13.57,0,-1,13.58,0,-1,13.59,0,-2,13.60,0,-2,13.61,0,-2,13.63,0,-3,ARL,0
2025-07-17T16:02:20.635782472Z,2025-07-17T16:02:20.635616654Z,10,2,1108,C,A,10,14.590000000,100,325400105,165818,271675858,13.31,10,1,13.28,1,2,13.27,10,1,13.14,1,1,13.13,100,1,13.11,100,1,13.10,100,1,13.04,2,1,13.02,200,2,12.99,100,1,13.40,0,-10,13.53,0,-1,13.55,0,-1,13.56,0,-1,13.57,0,-1,13.58,0,-1,13.59,0,-2,13.60,0,-2,13.61,0,-2,13.63,0,-3,ARL,0
2025-07-17T16:02:20.635782472Z,2025-07-17T16:02:20.635616654Z,10,2,1108,A,A,10,14.640000000,100,325714169,165818,271675858,13.31,10,1,13.28,1,2,13.27,10,1,13.14,1,1,13.13,100,1,13.11,100,1,13.10,100,1,13.04,2,1,13.02,200,2,12.99,100,1,13.40,0,-10,13.53,0,-1,13.55,0,-1,13.56,0,-1,13.57,0,-1,13.58,0,-1,13.59,0,-2,13.60,0,-2,13.61,0,-2,13.63,0,-3,ARL,0
2025-07-17T16:02:20.650466751Z,2025-07-17T16:02:20.650301212Z,10,2,1108,C,A,10,13.590000000,100,325022101,165539,271676032,13.31,10,1,13.28,1,2,13.27,10,1,13.14,1,1,13.13,100,1,13.11,100,1,13.10,100,1,13.04,2,1,13.02,200,2,12.99,100,1,13.40,0,-10,13.53,0,-1,13.55,0,-1,13.56,0,-1,13.57,0,-1,13.58,0,-1,13.59,0,-2,13.60,0,-2,13.61,0,-2,13.63,0,-3,ARL,0
2025-07-17T16:02:20.650501448Z,2025-07-17T16:02:20.650335946Z,10,2,1108,C,A,10,14.270000000,700,325400053,165502,271676033,13.31,10,1,13.28,1,2,13.27,10,1,13.14,1,1,13.13,100,1,13.11,100,1,13.10,100,1,13.04,2,1,13.02,200,2,12.99,100,1,13.40,0,-10,13.53,0,-1,13.55,0,-1,13.56,0,-1,13.57,0,-1,13.58,0,-1,13.59,0,-2,13.60,0,-2,13.61,0,-2,13.63,0,-3,ARL,0
2025-07-17T16:02:20.650546483Z,2025-07-17T16:02:20.650381040Z,10,2,1108,A,A,10,14.530000000,700,325714545,165443,271676035,13.31,10,1,13.28,1,2,13.27,10,1,13.14,1,1,13.13,100,1,13.11,100,1,13.10,100,1,13.04,2,1,13.02,200,2,12.99,100,1,13.40,0,-10,13.53,0,-1,13.55,0,-1,13.56,0,-1,13.57,0,-1,13.58,0,-1,13.59,0,-2,13.60,0,-2,13.61,0,-2,13.63,0,-3,ARL,0
2025-07-17T16:02:20.651186537Z,2025-07-17T16:02:20.651020858Z,10,2,1108,C,A,10,14.420000000,100,325520705,165679,271676048,13.31,10,1,13.28,1,2,13.27,10,1,13.14,1,1,13.13,100,1,13.11,100,1,13.10,100,1,13.04,2,1,13.02,200,2,12.99,100,1,13.40,0,-10,13.53,0,-1,13.55,0,-1,13.56,0,-1,13.57,0,-1,13.58,0,-1,13.59,0,-2,13.60,0,-2,13.61,0,-2,13.63,0,-3,ARL,0
2025-07-17T16:02:20.651186537Z,2025-07-17T16:02:20.651020858Z,10,2,1108,A,A,10,14.730000000,100,325714577,165679,271676048,13.31,10,1,13.28,1,2,13.27,10,1,13.14,1,1,13.13,100,1,13.11,100,1,13.10,100,1,13.04,2,1,13.02,200,2,12.99,100,1,13.40,0,-10,13.53,0,-1,13.55,0,-1,13.56,0,-1,13.57,0,-1,13.58,0,-1,13.59,0,-2,13.60,0,-2,13.61,0,-2,13.63,0,-3,ARL,0
2025-07-17T16:02:20.651201182Z,2025-07-17T16:02:20.651035000Z,10,2,1108,C,A,10,14.190000000,100,324942273,166182,271676049,13.31,10,1,13.28,1,2,13.27,10,1,13.14,1,1,13.13,100,1,13.11,100,1,13.10,100,1,13.04,2,1,13.02,200,2,12.99,100,1,13.40,0,-10,13.53,0,-1,13.55,0,-1,13.56,0,-1,13.57,0,-1,13.58,0,-1,13.59,0,-2,13.60,0,-2,13.61,0,-2,13.63,0,-3,ARL,0
2025-07-17T16:02:20.651459317Z,2025-07-17T16:02:20.651293729Z,10,2,1108,C,A,10,17.250000000,100,324942361,165588,271676055,13.31,10,1,13.28,1,2,13.27,10,1,13.14,1,1,13.13,100,1,13.11,100,1,13.10,100,1,13.04,2,1,13.02,200,2,12.99,100,1,13.40,0,-10,13.53,0,-1,13.55,0,-1,13.56,0,-1,13.57,0,-1,13.58,0,-1,13.59,0,-2,13.60,0,-2,13.61,0,-2,13.63,0,-3,ARL,0
2025-07-17T16:02:20.651459317Z,2025-07-17T16:02:20.651293729Z,10,2,1108,A,A,10,17.570000000,100,325714589,165588,271676055,13.31,10,1,13.28,1,2,13.27,10,1,13.14,1,1,13.13,100,1,13.11,100,1,13.10,100,1,13.04,2,1,13.02,200,2,12.99,100,1,13.40,0,-10,13.53,0,-1,13.55,0,-1,13.56,0,-1,13.57,0,-1,13.58,0,-1,13.59,0,-2,13.60,0,-2,13.61,0,-2,13.63,0,-3,ARL,0
2025-07-17T16:02:20.651558948Z,2025-07-17T16:02:20.651393708Z,10,2,1108,A,A,10,14.450000000,100,325714601,165240,271676057,13.31,10,1,13.28,1,2,13.27,10,1,13.14,1,1,13.13,100,1,13.11,100,1,13.10,100,1,13.04,2,1,13.02,200,2,12.99,100,1,13.40,0,-10,13.53,0,-1,13.55,0,-1,13.56,0,-1,13.57,0,-1,13.58,0,-1,13.59,0,-2,13.60,0,-2,13.61,0,-2,13.63,0,-3,ARL,0
2025-07-17T16:02:20.651787813Z,2025-07-17T16:02:20.651618897Z,10,2,1108,C,A,10,14.430000000,100,325382437,168916,271676089,13.31,10,1,13.28,1,2,13.27,10,1,13.14,1,1,13.13,100,1,13.11,100,1,13.10,100,1,13.04,2,1,13.02,200,2,12.99,100,1,13.40,0,-10,13.53,0,-1,13.55,0,-1,13.56,0,-1,13.57,0,-1,13.58,0,-1,13.59,0,-2,13.60,0,-2,13.61,0,-2,13.63,0,-3,ARL,0
2025-07-17T16:02:20.651787813Z,2025-07-17T16:02:20.651618897Z,10,2,1108,A,A,10,14.730000000,100,325714613,168916,271676089,13.31,10,1,13.28,1,2,13.27,10,1,13.14,1,1,13.13,100,1,13.11,100,1,13.10,100,1,13.04,2,1,13.02,200,2,12.99,100,1,13.40,0,-10,13.53,0,-1,13.55,0,-1,13.56,0,-1,13.57,0,-1,13.58,0,-1,13.59,0,-2,13.60,0,-2,13.61,0,-2,13.63,0,-3,ARL,0
2025-07-17T16:02:20.652021618Z,2025-07-17T16:02:20.651854531Z,10,2,1108,C,A,10,14.570000000,100,324619409,167087,271676104,13.31,10,1,13.28,1,2,13.27,10,1,13.14,1,1,13.13,100,1,13.11,100,1,13.10,100,1,13.04,2,1,13.02,200,2,12.99,100,1,13.40,0,-10,13.53,0,-1,13.55,0,-1,13.56,0,-1,13.57,0,-1,13.58,0,-1,13.59,0,-2,13.60,0,-2,13.61,0,-2,13.63,0,-3,ARL,0
2025-07-17T16:02:20.652021618Z,2025-07-17T16:02:20.651854531Z,10,2,1108,A,A,10,14.800000000,100,325714629,167087,271676104,13.31,10,1,13.28,1,2,13.27,10,1,13.14,1,1,13.13,100,1,13.11,100,1,13.10,100,1,13.04,2,1,13.02,200,2,12.99,100,1,13.40,0,-10,13.53,0,-1,13.55,0,-1,13.56,0,-1,13.57,0,-1,13.58,0,-1,13.59,0,-2,13.60,0,-2,13.61,0,-2,13.63,0,-3,ARL,0
2025-07-17T16:02:20.652097288Z,2025-07-17T16:02:20.651932129Z,10,2,1108,C,A,10,14.430000000,100,324186781,165159,271676110,13.31,10,1,13.28,1,2,13.27,10,1,13.14,1,1,13.13,100,1,13.11,100,1,13.10,100,1,13.04,2,1,13.02,200,2,12.99,100,1,13.40,0,-10,13.53,0,-1,13.55,0,-1,13.56,0,-1,13.57,0,-1,13.58,0,-1,13.59,0,-2,13.60,0,-2,13.61,0,-2,13.63,0,-3,ARL,0
2025-07-17T16:02:20.652160470Z,2025-07-17T16:02:20.651994883Z,10,2,1108,C,A,10,15.600000000,100,325176677,165587,271676111,13.31,10,1,13.28,1,2,13.27,10,1,13.14,1,1,13.13,100,1,13.11,100,1,13.10,100,1,13.04,2,1,13.02,200,2,12.99,100,1,13.40,0,-10,13.53,0,-1,13.55,0,-1,13.56,0,-1,13.57,0,-1,13.58,0,-1,13.59,0,-2,13.60,0,-2,13.61,0,-2,13.63,0,-3,ARL,0
2025-07-17T16:02:20.652160470Z,2025-07-17T16:02:20.651994883Z,10,2,1108,A,A,10,15.910000000,100,325714633,165587,271676111,13.31,10,1,13.28,1,2,13.27,10,1,13.14,1,1,13.13,100,1,13.11,100,1,13.10,100,1,13.04,2,1,13.02,200,2,12.99,100,1,13.40,0,-10,13.53,0,-1,13.55,0,-1,13.56,0,-1,13.57,0,-1,13.58,0,-1,13.59,0,-2,13.60,0,-2,13.61,0,-2,13.63,0,-3,ARL,0
2025-07-17T16:02:20.652259931Z,2025-07-17T16:02:20.652094426Z,10,2,1108,A,A,10,14.630000000,100,325714653,165505,271676118,13.31,10,1,13.28,1,2,13.27,10,1,13.14,1,1,13.13,100,1,13.11,100,1,13.10,100,1,13.04,2,1,13.02,200,2,12.99,100,1,13.40,0,-10,13.53,0,-1,13.55,0,-1,13.56,0,-1,13.57,0,-1,13.58,0,-1,13.59,0,-2,13.60,0,-2,13.61,0,-2,13.63,0,-3,ARL,0
2025-07-17T16:02:20.653626391Z,2025-07-17T16:02:20.653460814Z,10,2,1108,A,B,10,13.270000000,10,325714717,165577,271676147,13.31,10,1,13.28,1,2,13.27,20,2,13.14,1,1,13.13,100,1,13.11,100,1,13.10,100,1,13.04,2,1,13.02,200,2,12.99,100,1,13.40,0,-10,13.53,0,-1,13.55,0,-1,13.56,0,-1,13.57,0,-1,13.58,0,-1,13.59,0,-2,13.60,0,-2,13.61,0,-2,13.63,0,-3,ARL,0
2025-07-17T16:02:20.653627232Z,2025-07-17T16:02:20.653461966Z,10,2,1108,A,A,10,13.830000000,15,325714721,165266,271676148,13.31,10,1,13.28,1,2,13.27,20,2,13.14,1,1,13.13,100,1,13.11,100,1,13.10,100,1,13.04,2,1,13.02,200,2,12.99,100,1,13.40,0,-10,13.53,0,-1,13.55,0,-1,13.56,0,-1,13.57,0,-1,13.58,0,-1,13.59,0,-2,13.60,0,-2,13.61,0,-2,13.63,0,-3,ARL,0
2025-07-17T16:02:20.653886896Z,2025-07-17T16:02:20.653721185Z,10,2,1108,C,B,10,13.020000000,100,320485385,165711,271676153,13.31,10,1,13.28,1,2,13.27,20,2,13.14,1,1,13.13,100,1,13.11,100,1,13.10,100,1,13.04,2,1,13.02,200,2,12.99,100,1,13.40,0,-10,13.53,0,-1,13.55,0,-1,13.56,0,-1,13.57,0,-1,13.58,0,-1,13.59,0,-2,13.60,0,-2,13.61,0,-2,13.63,0,-3,ARL,0
2025-07-17T16:02:20.653886896Z,2025-07-17T16:02:20.653721185Z,10,2,1108,A,B,10,13.260000000,100,325714729,165711,271676153,13.31,10,1,13.28,1,2,13.27,20,2,13.26,100,1,13.14,1,1,13.13,100,1,13.11,100,1,13.10,100,1,13.04,2,1,13.02,200,2,13.40,0,-10,13.53,0,-1,13.55,0,-1,13.56,0,-1,13.57,0,-1,13.58,0,-1,13.59,0,-2,13.60,0,-2,13.61,0,-2,13.63,0,-3,ARL,0
2025-07-17T16:02:20.655277066Z,2025-07-17T16:02:20.655111649Z,10,2,1108,C,B,10,13.040000000,2,293594281,165417,271676165,13.31,10,1,13.28,1,2,13.27,20,2,13.26,98,1,13.14,1,1,13.13,100,1,13.11,100,1,13.10,100,1,13.04,2,1,13.02,200,2,13.40,0,-10,13.53,0,-1,13.55,0,-1,13.56,0,-1,13.57,0,-1,13.58,0,-1,13.59,0,-2,13.60,0,-2,13.61,0,-2,13.63,0,-3,ARL,0
2025-07-17T16:02:20.655277066Z,2025-07-17T16:02:20.655111649Z,10,2,1108,A,B,10,12.910000000,2,325714741,165417,271676165,13.31,10,1,13.28,1,2,13.27,20,2,13.26,98,1,13.14,1,1,13.13,100,1,13.11,100,1,13.10,100,1,13.04,2,1,13.02,200,2,13.40,0,-10,13.53,0,-1,13.55,0,-1,13.56,0,-1,13.57,0,-1,13.58,0,-1,13.59,0,-2,13.60,0,-2,13.61,0,-2,13.63,0,-3,ARL,0
2025-07-17T16:02:20.663374576Z,2025-07-17T16:02:20.663209235Z,10,2,1108,C,A,10,13.830000000,100,325176373,165341,271676274,13.31,10,1,13.28,1,2,13.27,20,2,13.26,98,1,13.14,1,1,13.13,100,1,13.11,100,1,13.10,100,1,13.04,2,1,13.02,200,2,13.40,0,-10,13.53,0,-1,13.55,0,-1,13.56,0,-1,13.57,0,-1,13.58,0,-1,13.59,0,-2,13.60,0,-2,13.61,0,-2,13.63,0,-3,ARL,0
2025-07-17T16:02:20.663406861Z,2025-07-17T16:02:20.663241882Z,10,2,1108,C,A,10,14.530000000,700,325714545,164979,271676275,13.31,10,1,13.28,1,2,13.27,20,2,13.26,98,1,13.14,1,1,13.13,100,1,13.11,100,1,13.10,100,1,13.04,2,1,13.02,200,2,13.40,0,-10,13.53,0,-1,13.55,0,-1,13.56,0,-1,13.57,0,-1,13.58,0,-1,13.59,0,-2,13.60,0,-2,13.61,0,-2,13.63,0,-3,ARL,0
2025-07-17T16:02:20.663426974Z,2025-07-17T16:02:20.663261632Z,10,2,1108,A,A,10,14.110000000,100,325714905,165342,271676276,13.31,10,1,13.28,1,2,13.27,20,2,13.26,98,1,13.14,1,1,13.13,100,1,13.11,100,1,13.10,100,1,13.04,2,1,13.02,200,2,13.40,0,-10,13.53,0,-1,13.55,0,-1,13.56,0,-1,13.57,0,-1,13.58,0,-1,13.59,0,-2,13.60,0,-2,13.61,0,-2,13.63,0,-3,ARL,0
2025-07-17T16:02:20.663559466Z,2025-07-17T16:02:20.663394059Z,10,2,1108,A,A,10,15.940000000,100,325714909,165407,271676277,13.31,10,1,13.28,1,2,13.27,20,2,13.26,98,1,13.14,1,1,13.13,100,1,13.11,100,1,13.10,100,1,13.04,2,1,13.02,200,2,13.40,0,-10,13.53,0,-1,13.55,0,-1,13.56,0,-1,13.57,0,-1,13.58,0,-1,13.59,0,-2,13.60,0,-2,13.61,0,-2,13.63,0,-3,ARL,0
2025-07-17T16:02:20.663572634Z,2025-07-17T16:02:20.663407337Z,10,2,1108,C,A,10,15.590000000,100,323730697,165297,271676278,13.31,10,1,13.28,1,2,13.27,20,2,13.26,98,1,13.14,1,1,13.13,100,1,13.11,100,1,13.10,100,1,13.04,2,1,13.02,200,2,13.40,0,-10,13.53,0,-1,13.55,0,-1,13.56,0,-1,13.57,0,-1,13.58,0,-1,13.59,0,-2,13.60,0,-2,13.61,0,-2,13.63,0,-3,ARL,0
2025-07-17T16:02:20.664956400Z,2025-07-17T16:02:20.664790768Z,10,2,1108,C,A,10,17.570000000,100,325714589,165632,271676310,13.31,10,1,13.28,1,2,13.27,20,2,13.26,98,1,13.14,1,1,13.13,100,1,13.11,100,1,13.10,100,1,13.04,2,1,13.02,200,2,13.40,0,-10,13.53,0,-1,13.55,0,-1,13.56,0,-1,13.57,0,-1,13.58,0,-1,13.59,0,-2,13.60,0,-2,13.61,0,-2,13.63,0,-3,ARL,0
2025-07-17T16:02:20.664956400Z,2025-07-17T16:02:20.664790768Z,10,2,1108,A,A,10,17.760000000,100,325714949,165632,271676310,13.31,10,1,13.28,1,2,13.27,20,2,13.26,98,1,13.14,1,1,13.13,100,1,13.11,100,1,13.10,100,1,13.04,2,1,13.02,200,2,13.40,0,-10,13.53,0,-1,13.55,0,-1,13.56,0,-1,13.57,0,-1,13.58,0,-1,13.59,0,-2,13.60,0,-2,13.61,0,-2,13.63,0,-3,ARL,0
2025-07-17T16:02:20.665129279Z,2025-07-17T16:02:20.664963386Z,10,2,1108,C,A,10,14.800000000,100,325714629,165893,271676320,13.31,10,1,13.28,1,2,13.27,20,2,13.26,98,1,13.14,1,1,13.13,100,1,13.11,100,1,13.10,100,1,13.04,2,1,13.02,200,2,13.40,0,-10,13.53,0,-1,13.55,0,-1,13.56,0,-1,13.57,0,-1,13.58,0,-1,13.59,0,-2,13.60,0,-2,13.61,0,-2,13.63,0,-3,ARL,0
2025-07-17T16:02:20.665129279Z,2025-07-17T16:02:20.664963386Z,10,2,1108,A,A,10,14.960000000,100,325714953,165893,271676320,13.31,10,1,13.28,1,2,13.27,20,2,13.26,98,1,13.14,1,1,13.13,100,1,13.11,100,1,13.10,100,1,13.04,2,1,13.02,200,2,13.40,0,-10,13.53,0,-1,13.55,0,-1,13.56,0,-1,13.57,0,-1,13.58,0,-1,13.59,0,-2,13.60,0,-2,13.61,0,-2,13.63,0,-3,ARL,0
2025-07-17T16:02:20.665200392Z,2025-07-17T16:02:20.665034825Z,10,2,1108,C,A,10,15.910000000,100,325714633,165567,271676330,13.31,10,1,13.28,1,2,13.27,20,2,13.26,98,1,13.14,1,1,13.13,100,1,13.11,100,1,13.10,100,1,13.04,2,1,13.02,200,2,13.40,0,-10,13.53,0,-1,13.55,0,-1,13.56,0,-1,13.57,0,-1,13.58,0,-1,13.59,0,-2,13.60,0,-2,13.61,0,-2,13.63,0,-3,ARL,0
2025-07-17T16:02:20.665200392Z,2025-07-17T16:02:20.665034825Z,10,2,1108,A,A,10,16.080000000,100,325714957,165567,271676330,13.31,10,1,13.28,1,2,13.27,20,2,13.26,98,1,13.14,1,1,13.13,100,1,13.11,100,1,13.10,100,1,13.04,2,1,13.02,200,2,13.40,0,-10,13.53,0,-1,13.55,0,-1,13.56,0,-1,13.57,0,-1,13.58,0,-1,13.59,0,-2,13.60,0,-2,13.61,0,-2,13.63,0,-3,ARL,0
2025-07-17T16:02:20.665457595Z,2025-07-17T16:02:20.665292049Z,10,2,1108,C,A,10,14.940000000,100,324942277,165546,271676355,13.31,10,1,13.28,1,2,13.27,20,2,13.26,98,1,13.14,1,1,13.13,100,1,13.11,100,1,13.10,100,1,13.04,2,1,13.02,200,2,13.40,0,-10,13.53,0,-1,13.55,0,-1,13.56,0,-1,13.57,0,-1,13.58,0,-1,13.59,0,-2,13.60,0,-2,13.61,0,-2,13.63,0,-3,ARL,0
2025-07-17T16:02:20.665457595Z,2025-07-17T16:02:20.665292049Z,10,2,1108,A,A,10,15.380000000,100,325714965,165546,271676355,13.31,10,1,13.28,1,2,13.27,20,2,13.26,98,1,13.14,1,1,13.13,100,1,13.11,100,1,13.10,100,1,13.04,2,1,13.02,200,2,13.40,0,-10,13.53,0,-1,13.55,0,-1,13.56,0,-1,13.57,0,-1,13.58,0,-1,13.59,0,-2,13.60,0,-2,13.61,0,-2,13.63,0,-3,ARL,0
2025-07-17T16:02:20.669701452Z,2025-07-17T16:02:20.669536385Z,10,2,1108,C,A,10,14.110000000,100,325714905,165067,271676398,13.31,10,1,13.28,1,2,13.27,20,2,13.26,98,1,13.14,1,1,13.13,100,1,13.11,100,1,13.10,100,1,13.04,2,1,13.02,200,2,13.40,0,-10,13.53,0,-1,13.55,0,-1,13.56,0,-1,13.57,0,-1,13.58,0,-1,13.59,0,-2,13.60,0,-2,13.61,0,-2,13.63,0,-3,ARL,0
2025-07-17T16:02:20.669748954Z,2025-07-17T16:02:20.669583810Z,10,2,1108,A,A,10,14.260000000,100,325715045,165144,271676399,13.31,10,1,13.28,1,2,13.27,20,2,13.26,98,1,13.14,1,1,13.13,100,1,13.11,100,1,13.10,100,1,13.04,2,1,13.02,200,2,13.40,0,-10,13.53,0,-1,13.55,0,-1,13.56,0,-1,13.57,0,-1,13.58,0,-1,13.59,0,-2,13.60,0,-2,13.61,0,-2,13.63,0,-3,ARL,0
2025-07-17T16:02:20.669752979Z,2025-07-17T16:02:20.669587514Z,10,2,1108,C,A,10,14.510000000,100,325177757,165465,271676400,13.31,10,1,13.28,1,2,13.27,20,2,13.26,98,1,13.14,1,1,13.13,100,1,13.11,100,1,13.10,100,1,13.04,2,1,13.02,200,2,13.40,0,-10,13.53,0,-1,13.55,0,-1,13.56,0,-1,13.57,0,-1,13.58,0,-1,13.59,0,-2,13.60,0,-2,13.61,0,-2,13.63,0,-3,ARL,0
2025-07-17T16:02:20.669752979Z,2025-07-17T16:02:20.669587514Z,10,2,1108,A,A,10,14.960000000,100,325715053,165465,271676400,13.31,10,1,13.28,1,2,13.27,20,2,13.26,98,1,13.14,1,1,13.13,100,1,13.11,100,1,13.10,100,1,13.04,2,1,13.02,200,2,13.40,0,-10,13.53,0,-1,13.55,0,-1,13.56,0,-1,13.57,0,-1,13.58,0,-1,13.59,0,-2,13.60,0,-2,13.61,0,-2,13.63,0,-3,ARL,0
2025-07-17T16:02:20.685252049Z,2025-07-17T16:02:20.685086585Z,10,2,1108,C,A,10,14.640000000,100,325714169,165464,271676621,13.31,10,1,13.28,1,2,13.27,20,2,13.26,98,1,13.14,1,1,13.13,100,1,13.11,100,1,13.10,100,1,13.04,2,1,13.02,200,2,13.40,0,-10,13.53,0,-1,13.55,0,-1,13.56,0,-1,13.57,0,-1,13.58,0,-1,13.59,0,-2,13.60,0,-2,13.61,0,-2,13.63,0,-3,ARL,0
2025-07-17T16:02:20.685252049Z,2025-07-17T16:02:20.685086585Z,10,2,1108,A,A,10,15.060000000,100,325715113,165464,271676621,13.31,10,1,13.28,1,2,13.27,20,2,13.26,98,1,13.14,1,1,13.13,100,1,13.11,100,1,13.10,100,1,13.04,2,1,13.02,200,2,13.40,0,-10,13.53,0,-1,13.55,0,-1,13.56,0,-1,13.57,0,-1,13.58,0,-1,13.59,0,-2,13.60,0,-2,13.61,0,-2,13.63,0,-3,ARL,0
2025-07-17T16:02:20.832112637Z,2025-07-17T16:02:20.831947250Z,10,2,1108,A,A,10,14.680000000,700,325716945,165387,271678584,13.31,10,1,13.28,1,2,13.27,20,2,13.26,98,1,13.14,1,1,13.13,100,1,13.11,100,1,13.10,100,1,13.04,2,1,13.02,200,2,13.40,0,-10,13.53,0,-1,13.55,0,-1,13.56,0,-1,13.57,0,-1,13.58,0,-1,13.59,0,-2,13.60,0,-2,13.61,0,-2,13.63,0,-3,ARL,0
2025-07-17T16:02:20.936787418Z,2025-07-17T16:02:20.936622241Z,10,2,1108,C,B,10,13.260000000,100,325714729,165177,271679553,13.31,10,1,13.28,1,2,13.27,20,2,13.26,98,1,13.14,1,1,13.13,100,1,13.11,100,1,13.10,100,1,13.04,2,1,13.02,200,2,13.40,0,-10,13.53,0,-1,13.55,0,-1,13.56,0,-1,13.57,0,-1,13.58,0,-1,13.59,0,-2,13.60,0,-2,13.61,0,-2,13.63,0,-3,ARL,0
2025-07-17T16:02:20.936837611Z,2025-07-17T16:02:20.936672130Z,10,2,1108,A,A,10,13.910000000,5,325718477,165481,271679555,13.31,10,1,13.28,1,2,13.27,20,2,13.26,98,1,13.14,1,1,13.13,100,1,13.11,100,1,13.10,100,1,13.04,2,1,13.02,200,2,13.40,0,-10,13.53,0,-1,13.55,0,-1,13.56,0,-1,13.57,0,-1,13.58,0,-1,13.59,0,-2,13.60,0,-2,13.61,0,-2,13.63,0,-3,ARL,0
2025-07-17T16:02:20.936999211Z,2025-07-17T16:02:20.936833988Z,10,2,1108,A,A,10,13.840000000,100,325718485,165223,271679558,13.31,10,1,13.28,1,2,13.27,20,2,13.26,98,1,13.14,1,1,13.13,100,1,13.11,100,1,13.10,100,1,13.04,2,1,13.02,200,2,13.40,0,-10,13.53,0,-1,13.55,0,-1,13.56,0,-1,13.57,0,-1,13.58,0,-1,13.59,0,-2,13.60,0,-2,13.61,0,-2,13.63,0,-3,ARL,0
2025-07-17T16:02:20.937744264Z,2025-07-17T16:02:20.937578907Z,10,2,1108,C,A,10,15.060000000,100,325715113,165357,271679565,13.31,10,1,13.28,1,2,13.27,20,2,13.26,98,1,13.14,1,1,13.13,100,1,13.11,100,1,13.10,100,1,13.04,2,1,13.02,200,2,13.40,0,-10,13.53,0,-1,13.55,0,-1,13.56,0,-1,13.57,0,-1,13.58,0,-1,13.59,0,-2,13.60,0,-2,13.61,0,-2,13.63,0,-3,ARL,0
2025-07-17T16:02:20.937744264Z,2025-07-17T16:02:20.937578907Z,10,2,1108,A,A,10,14.910000000,100,325718509,165357,271679565,13.31,10,1,13.28,1,2,13.27,20,2,13.26,98,1,13.14,1,1,13.13,100,1,13.11,100,1,13.10,100,1,13.04,2,1,13.02,200,2,13.40,0,-10,13.53,0,-1,13.55,0,-1,13.56,0,-1,13.57,0,-1,13.58,0,-1,13.59,0,-2,13.60,0,-2,13.61,0,-2,13.63,0,-3,ARL,0
2025-07-17T16:02:20.937901293Z,2025-07-17T16:02:20.937736247Z,10,2,1108,C,A,10,13.910000000,5,325718477,165046,271679567,13.31,10,1,13.28,1,2,13.27,20,2,13.26,98,1,13.14,1,1,13.13,100,1,13.11,100,1,13.10,100,1,13.04,2,1,13.02,200,2,13.40,0,-10,13.53,0,-1,13.55,0,-1,13.56,0,-1,13.57,0,-1,13.58,0,-1,13.59,0,-2,13.60,0,-2,13.61,0,-2,13.63,0,-3,ARL,0
2025-07-17T16:02:20.938093286Z,2025-07-17T16:02:20.937927380Z,10,2,1108,C,A,10,14.960000000,100,325715053,165906,271679569,13.31,10,1,13.28,1,2,13.27,20,2,13.26,98,1,13.14,1,1,13.13,100,1,13.11,100,1,13.10,100,1,13.04,2,1,13.02,200,2,13.40,0,-10,13.53,0,-1,13.55,0,-1,13.56,0,-1,13.57,0,-1,13.58,0,-1,13.59,0,-2,13.60,0,-2,13.61,0,-2,13.63,0,-3,ARL,0
2025-07-17T16:02:20.938093286Z,2025-07-17T16:02:20.937927380Z,10,2,1108,A,A,10,14.810000000,100,325718517,165906,271679569,13.31,10,1,13.28,1,2,13.27,20,2,13.26,98,1,13.14,1,1,13.13,100,1,13.11,100,1,13.10,100,1,13.04,2,1,13.02,200,2,13.40,0,-10,13.53,0,-1,13.55,0,-1,13.56,0,-1,13.57,0,-1,13.58,0,-1,13.59,0,-2,13.60,0,-2,13.61,0,-2,13.63,0,-3,ARL,0
2025-07-17T16:02:20.938297839Z,2025-07-17T16:02:20.938132716Z,10,2,1108,C,A,10,16.080000000,100,325714957,165123,271679571,13.31,10,1,13.28,1,2,13.27,20,2,13.26,98,1,13.14,1,1,13.13,100,1,13.11,100,1,13.10,100,1,13.04,2,1,13.02,200,2,13.40,0,-10,13.53,0,-1,13.55,0,-1,13.56,0,-1,13.57,0,-1,13.58,0,-1,13.59,0,-2,13.60,0,-2,13.61,0,-2,13.63,0,-3,ARL,0
2025-07-17T16:02:20.938297839Z,2025-07-17T16:02:20.938132716Z,10,2,1108,A,A,10,15.920000000,100,325718525,165123,271679571,13.31,10,1,13.28,1,2,13.27,20,2,13.26,98,1,13.14,1,1,13.13,100,1,13.11,100,1,13.10,100,1,13.04,2,1,13.02,200,2,13.40,0,-10,13.53,0,-1,13.55,0,-1,13.56,0,-1,13.57,0,-1,13.58,0,-1,13.59,0,-2,13.60,0,-2,13.61,0,-2,13.63,0,-3,ARL,0
2025-07-17T16:02:20.938616654Z,2025-07-17T16:02:20.938451331Z,10,2,1108,C,A,10,14.960000000,100,325714953,165323,271679575,13.31,10,1,13.28,1,2,13.27,20,2,13.26,98,1,13.14,1,1,13.13,100,1,13.11,100,1,13.10,100,1,13.04,2,1,13.02,200,2,13.40,0,-10,13.53,0,-1,13.55,0,-1,13.56,0,-1,13.57,0,-1,13.58,0,-1,13.59,0,-2,13.60,0,-2,13.61,0,-2,13.63,0,-3,ARL,0
2025-07-17T16:02:20.938616654Z,2025-07-17T16:02:20.938451331Z,10,2,1108,A,A,10,14.810000000,100,325718549,165323,271679575,13.31,10,1,13.28,1,2,13.27,20,2,13.26,98,1,13.14,1,1,13.13,100,1,13.11,100,1,13.10,100,1,13.04,2,1,13.02,200,2,13.40,0,-10,13.53,0,-1,13.55,0,-1,13.56,0,-1,13.57,0,-1,13.58,0,-1,13.59,0,-2,13.60,0,-2,13.61,0,-2,13.63,0,-3,ARL,0
2025-07-17T16:02:20.938889819Z,2025-07-17T16:02:20.938724516Z,10,2,1108,C,A,10,17.760000000,100,325714949,165303,271679576,13.31,10,1,13.28,1,2,13.27,20,2,13.26,98,1,13.14,1,1,13.13,100,1,13.11,100,1,13.10,100,1,13.04,2,1,13.02,200,2,13.40,0,-10,13.53,0,-1,13.55,0,-1,13.56,0,-1,13.57,0,-1,13.58,0,-1,13.59,0,-2,13.60,0,-2,13.61,0,-2,13.63,0,-3,ARL,0
2025-07-17T16:02:20.938889819Z,2025-07-17T16:02:20.938724516Z,10,2,1108,A,A,10,17.580000000,100,325718557,165303,271679576,13.31,10,1,13.28,1,2,13.27,20,2,13.26,98,1,13.14,1,1,13.13,100,1,13.11,100,1,13.10,100,1,13.04,2,1,13.02,200,2,13.40,0,-10,13.53,0,-1,13.55,0,-1,13.56,0,-1,13.57,0,-1,13.58,0,-1,13.59,0,-2,13.60,0,-2,13.61,0,-2,13.63,0,-3,ARL,0
2025-07-17T16:02:20.939554686Z,2025-07-17T16:02:20.939389367Z,10,2,1108,A,B,10,13.020000000,100,325718561,165319,271679578,13.31,10,1,13.28,1,2,13.27,20,2,13.26,98,1,13.14,1,1,13.13,100,1,13.11,100,1,13.10,100,1,13.04,2,1,13.02,300,3,13.40,0,-10,13.53,0,-1,13.55,0,-1,13.56,0,-1,13.57,0,-1,13.58,0,-1,13.59,0,-2,13.60,0,-2,13.61,0,-2,13.63,0,-3,ARL,0
2025-07-17T16:02:20.946406202Z,2025-07-17T16:02:20.946240970Z,10,2,1108,C,A,10,14.260000000,100,325715045,165232,271679616,13.31,10,1,13.28,1,2,13.27,20,2,13.26,98,1,13.14,1,1,13.13,100,1,13.11,100,1,13.10,100,1,13.04,2,1,13.02,200,2,13.40,0,-10,13.53,0,-1,13.55,0,-1,13.56,0,-1,13.57,0,-1,13.58,0,-1,13.59,0,-2,13.60,0,-2,13.61,0,-2,13.63,0,-3,ARL,0
2025-07-17T16:02:20.946456786Z,2025-07-17T16:02:20.946291345Z,10,2,1108,A,A,10,14.120000000,100,325718637,165441,271679617,13.31,10,1,13.28,1,2,13.27,20,2,13.26,98,1,13.14,1,1,13.13,100,1,13.11,100,1,13.10,100,1,13.04,2,1,13.02,200,2,13.40,0,-10,13.53,0,-1,13.55,0,-1,13.56,0,-1,13.57,0,-1,13.58,0,-1,13.59,0,-2,13.60,0,-2,13.61,0,-2,13.63,0,-3,ARL,0
2025-07-17T16:02:20.957051613Z,2025-07-17T16:02:20.956886401Z,10,2,1108,C,B,10,13.020000000,100,325718561,165212,271679685,13.31,10,1,13.28,1,2,13.27,20,2,13.26,98,1,13.14,1,1,13.13,100,1,13.11,100,1,13.10,100,1,13.04,2,1,13.02,200,2,13.40,0,-10,13.53,0,-1,13.55,0,-1,13.56,0,-1,13.57,0,-1,13.58,0,-1,13.59,0,-2,13.60,0,-2,13.61,0,-2,13.63,0,-3,ARL,0
2025-07-17T16:02:20.957051613Z,2025-07-17T16:02:20.956886401Z,10,2,1108,A,B,10,13.260000000,100,325718821,165212,271679685,13.31,10,1,13.28,1,2,13.27,20,2,13.26,198,2,13.14,1,1,13.13,100,1,13.11,100,1,13.10,100,1,13.04,2,1,13.02,200,2,13.40,0,-10,13.53,0,-1,13.55,0,-1,13.56,0,-1,13.57,0,-1,13.58,0,-1,13.59,0,-2,13.60,0,-2,13.61,0,-2,13.63,0,-3,ARL,0
2025-07-17T16:02:20.957089143Z,2025-07-17T16:02:20.956923753Z,10,2,1108,A,B,10,13.120000000,100,325718833,165390,271679686,13.31,10,1,13.28,1,2,13.27,20,2,13.26,198,2,13.14,1,1,13.13,100,1,13.12,100,1,13.11,100,1,13.10,100,1,13.04,2,1,13.40,0,-10,13.53,0,-1,13.55,0,-1,13.56,0,-1,13.57,0,-1,13.58,0,-1,13.59,0,-2,13.60,0,-2,13.61,0,-2,13.63,0,-3,ARL,0
2025-07-17T16:02:20.957090484Z,2025-07-17T16:02:20.956925447Z,10,2,1108,A,B,10,13.120000000,100,325718837,165037,271679687,13.31,10,1,13.28,1,2,13.27,20,2,13.26,198,2,13.14,1,1,13.13,100,1,13.12,200,2,13.11,100,1,13.10,100,1,13.04,2,1,13.40,0,-10,13.53,0,-1,13.55,0,-1,13.56,0,-1,13.57,0,-1,13.58,0,-1,13.59,0,-2,13.60,0,-2,13.61,0,-2,13.63,0,-3,ARL,0
2025-07-17T16:02:20.988655870Z,2025-07-17T16:02:20.988490644Z,10,2,1108,A,A,10,13.980000000,100,325719353,165226,271679923,13.31,10,1,13.28,1,2,13.27,20,2,13.26,198,2,13.14,1,1,13.13,100,1,13.12,200,2,13.11,100,1,13.10,100,1,13.04,2,1,13.40,0,-10,13.53,0,-1,13.55,0,-1,13.56,0,-1,13.57,0,-1,13.58,0,-1,13.59,0,-2,13.60,0,-2,13.61,0,-2,13.63,0,-3,ARL,0
2025-07-17T16:02:20.988656944Z,2025-07-17T16:02:20.988491826Z,10,2,1108,A,A,10,13.980000000,100,325719357,165118,271679924,13.31,10,1,13.28,1,2,13.27,20,2,13.26,198,2,13.14,1,1,13.13,100,1,13.12,200,2,13.11,100,1,13.10,100,1,13.04,2,1,13.40,0,-10,13.53,0,-1,13.55,0,-1,13.56,0,-1,13.57,0,-1,13.58,0,-1,13.59,0,-2,13.60,0,-2,13.61,0,-2,13.63,0,-3,ARL,0
2025-07-17T16:02:30.805193695Z,2025-07-17T16:02:30.805028316Z,10,2,1108,C,B,10,13.270000000,10,325714717,165379,271818376,13.31,10,1,13.28,1,2,13.27,20,2,13.26,198,2,13.14,1,1,13.13,100,1,13.12,200,2,13.11,100,1,13.10,100,1,13.04,2,1,13.40,0,-10,13.53,0,-1,13.55,0,-1,13.56,0,-1,13.57,0,-1,13.58,0,-1,13.59,0,-2,13.60,0,-2,13.61,0,-2,13.63,0,-3,ARL,0
2025-07-17T16:02:34.987171397Z,2025-07-17T16:02:34.987005787Z,10,2,1108,C,B,10,12.910000000,2,325714741,165610,271871706,13.31,10,1,13.28,1,2,13.27,20,2,13.26,198,2,13.14,1,1,13.13,100,1,13.12,200,2,13.11,100,1,13.10,100,1,13.04,2,1,13.40,0,-10,13.53,0,-1,13.55,0,-1,13.56,0,-1,13.57,0,-1,13.58,0,-1,13.59,0,-2,13.60,0,-2,13.61,0,-2,13.63,0,-3,ARL,0
2025-07-17T16:02:34.987171397Z,2025-07-17T16:02:34.987005787Z,10,2,1108,A,B,10,13.000000000,2,325967705,165610,271871706,13.31,10,1,13.28,1,2,13.27,20,2,13.26,198,2,13.14,1,1,13.13,100,1,13.12,200,2,13.11,100,1,13.10,100,1,13.04,2,1,13.40,0,-10,13.53,0,-1,13.55,0,-1,13.56,0,-1,13.57,0,-1,13.58,0,-1,13.59,0,-2,13.60,0,-2,13.61,0,-2,13.63,0,-3,ARL,0
2025-07-17T16:02:39.809464961Z,2025-07-17T16:02:39.809299504Z,10,2,1108,A,A,10,13.790000000,15,326077141,165457,271952021,13.31,10,1,13.28,1,2,13.27,20,2,13.26,198,2,13.14,1,1,13.13,100,1,13.12,200,2,13.11,100,1,13.10,100,1,13.04,2,1,13.40,0,-10,13.53,0,-1,13.55,0,-1,13.56,0,-1,13.57,0,-1,13.58,0,-1,13.59,0,-2,13.60,0,-2,13.61,0,-2,13.63,0,-3,ARL,0
2025-07-17T16:02:40.007472020Z,2025-07-17T16:02:40.007306432Z,10,2,1108,C,A,10,13.840000000,100,325718485,165588,271957331,13.31,10,1,13.28,1,2,13.27,20,2,13.26,198,2,13.14,1,1,13.13,100,1,13.12,200,2,13.11,100,1,13.10,100,1,13.04,2,1,13.40,0,-10,13.53,0,-1,13.55,0,-1,13.56,0,-1,13.57,0,-1,13.58,0,-1,13.59,0,-2,13.60,0,-2,13.61,0,-2,13.63,0,-3,ARL,0
2025-07-17T16:02:40.007472020Z,2025-07-17T16:02:40.007306432Z,10,2,1108,A,A,10,13.800000000,100,326082329,165588,271957331,13.31,10,1,13.28,1,2,13.27,20,2,13.26,198,2,13.14,1,1,13.13,100,1,13.12,200,2,13.11,100,1,13.10,100,1,13.04,2,1,13.40,0,-10,13.53,0,-1,13.55,0,-1,13.56,0,-1,13.57,0,-1,13.58,0,-1,13.59,0,-2,13.60,0,-2,13.61,0,-2,13.63,0,-3,ARL,0
2025-07-17T16:02:40.008213654Z,2025-07-17T16:02:40.008048023Z,10,2,1108,C,A,10,14.910000000,100,325718509,165631,271957349,13.31,10,1,13.28,1,2,13.27,20,2,13.26,198,2,13.14,1,1,13.13,100,1,13.12,200,2,13.11,100,1,13.10,100,1,13.04,2,1,13.40,0,-10,13.53,0,-1,13.55,0,-1,13.56,0,-1,13.57,0,-1,13.58,0,-1,13.59,0,-2,13.60,0,-2,13.61,0,-2,13.63,0,-3,ARL,0
2025-07-17T16:02:40.008213654Z,2025-07-17T16:02:40.008048023Z,10,2,1108,A,A,10,14.870000000,100,326082353,165631,271957349,13.31,10,1,13.28,1,2,13.27,20,2,13.26,198,2,13.14,1,1,13.13,100,1,13.12,200,2,13.11,100,1,13.10,100,1,13.04,2,1,13.40,0,-10,13.53,0,-1,13.55,0,-1,13.56,0,-1,13.57,0,-1,13.58,0,-1,13.59,0,-2,13.60,0,-2,13.61,0,-2,13.63,0,-3,ARL,0
2025-07-17T16:02:40.795014471Z,2025-07-17T16:02:40.794847674Z,10,2,1108,C,A,10,13.790000000,15,326077141,166797,271972417,13.31,10,1,13.28,1,2,13.27,20,2,13.26,198,2,13.14,1,1,13.13,100,1,13.12,200,2,13.11,100,1,13.10,100,1,13.04,2,1,13.40,0,-10,13.53,0,-1,13.55,0,-1,13.56,0,-1,13.57,0,-1,13.58,0,-1,13.59,0,-2,13.60,0,-2,13.61,0,-2,13.63,0,-3,ARL,0
