ts_recv,ts_event,rtype,publisher_id,instrument_id,action,side,depth,price,size,flags,ts_in_delta,sequence,bid_px_00,bid_sz_00,bid_ct_00,bid_px_01,bid_sz_01,bid_ct_01,bid_px_02,bid_sz_02,bid_ct_02,bid_px_03,bid_sz_03,bid_ct_03,bid_px_04,bid_sz_04,bid_ct_04,bid_px_05,bid_sz_05,bid_ct_05,bid_px_06,bid_sz_06,bid_ct_06,bid_px_07,bid_sz_07,bid_ct_07,bid_px_08,bid_sz_08,bid_ct_08,bid_px_09,bid_sz_09,bid_ct_09,ask_px_00,ask_sz_00,ask_ct_00,ask_px_01,ask_sz_01,ask_ct_01,ask_px_02,ask_sz_02,ask_ct_02,ask_px_03,ask_sz_03,ask_ct_03,ask_px_04,ask_sz_04,ask_ct_04,ask_px_05,ask_sz_05,ask_ct_05,ask_px_06,ask_sz_06,ask_ct_06,ask_px_07,ask_sz_07,ask_ct_07,ask_px_08,ask_sz_08,ask_ct_08,ask_px_09,ask_sz_09,ask_ct_09,symbol,order_id
2025-07-17T07:05:09.035793433Z,2025-07-17T07:05:09.035627674Z,10,2,1108,R,N,10,,0,0,0,0,,,,,,,,,,,,,,,,,,,,,,,,,,,,,,,,,,,,,,,,,,,,,,,,,,,,,,,,,,,,,ARL,0
2025-07-17T08:05:03.360842448Z,2025-07-17T08:05:03.360677248Z,10,2,1108,A,B,10,5.510000000,100,817593,165200,851012,5.51,100,1,,,,,,,,,,,,,,,,,,,,,,,,,,,,,,,,,,,,,,,,,,,,,,,,,,,,,,,,,,ARL,0
2025-07-17T08:05:03.360848793Z,2025-07-17T08:05:03.360683462Z,10,2,1108,A,A,10,21.330000000,100,817597,165331,851013,5.51,100,1,,,,,,,,,,,,,,,,,,,,,,,,,,,,,,,,,,,,,,,,,,,,,,,,,,,,,,,,,,ARL,0
2025-07-17T08:05:03.361492517Z,2025-07-17T08:05:03.361327319Z,10,2,1108,A,B,10,5.900000000,100,817633,165198,851022,5.90,100,1,5.51,100,1,,,,,,,,,,,,,,,,,,,,,,,,,,,,,,,,,,,,,,,,,,,,,,,,,,,,,,,ARL,0
2025-07-17T08:05:03.361497823Z,2025-07-17T08:05:03.361332576Z,10,2,1108,A,A,10,20.940000000,100,817637,165247,851023,5.90,100,1,5.51,100,1,,,,,,,,,,,,,,,,,,,,,,,,,,,,,,,,,,,,,,,,,,,,,,,,,,,,,,,ARL,0
2025-07-17T08:09:48.860862095Z,2025-07-17T08:09:48.860696464Z,10,2,1108,C,B,10,5.510000000,100,817593,165631,1289631,5.90,100,1,5.51,100,1,,,,,,,,,,,,,,,,,,,,,,,,,20.94,0,-1,,,,,,,,,,,,,,,,,,,,,,,,,,,,ARL,0
2025-07-17T08:09:48.860870885Z,2025-07-17T08:09:48.860705588Z,10,2,1108,A,B,10,5.370000000,100,1263973,165297,1289632,5.90,100,1,5.51,100,1,5.37,100,1,,,,,,,,,,,,,,,,,,,,,,20.94,0,-1,,,,,,,,,,,,,,,,,,,,,,,,,,,,ARL,0
2025-07-17T08:09:49.158061899Z,2025-07-17T08:09:49.157896784Z,10,2,1108,C,B,10,5.900000000,100,817633,165115,1290626,5.90,100,1,5.51,100,1,,,,,,,,,,,,,,,,,,,,,,,,,20.94,0,-1,,,,,,,,,,,,,,,,,,,,,,,,,,,,ARL,0
2025-07-17T08:09:49.158069452Z,2025-07-17T08:09:49.157903443Z,10,2,1108,A,B,10,5.400000000,100,1264721,166009,1290627,5.90,100,1,5.51,100,1,5.40,100,1,,,,,,,,,,,,,,,,,,,,,,20.94,0,-1,,,,,,,,,,,,,,,,,,,,,,,,,,,,ARL,0
2025-07-17T08:09:49.158069452Z,2025-07-17T08:09:49.157903798Z,10,2,1108,C,A,10,20.940000000,100,817637,165654,1290628,5.90,100,1,5.51,100,1,,,,,,,,,,,,,,,,,,,,,,,,,20.94,0,-1,,,,,,,,,,,,,,,,,,,,,,,,,,,,ARL,0
2025-07-17T08:09:49.158074599Z,2025-07-17T08:09:49.157909054Z,10,2,1108,A,A,10,21.470000000,100,1264725,165545,1290629,5.90,100,1,5.51,100,1,,,,,,,,,,,,,,,,,,,,,,,,,20.94,0,-1,,,,,,,,,,,,,,,,,,,,,,,,,,,,ARL,0
2025-07-17T11:00:00.125340914Z,2025-07-17T11:00:00.125174985Z,10,2,1108,C,B,10,5.370000000,100,1263973,165929,10583317,5.90,100,1,5.51,100,1,,,,,,,,,,,,,,,,,,,,,,,,,20.94,0,-1,21.47,0,-1,,,,,,,,,,,,,,,,,,,,,,,,,ARL,0
2025-07-17T11:00:00.125347247Z,2025-07-17T11:00:00.125182048Z,10,2,1108,A,B,10,9.790000000,100,12852457,165199,10583320,9.79,100,1,5.90,100,1,5.51,100,1,,,,,,,,,,,,,,,,,,,,,,20.94,0,-1,21.47,0,-1,,,,,,,,,,,,,,,,,,,,,,,,,ARL,0
2025-07-17T11:00:00.125619742Z,2025-07-17T11:00:00.125454029Z,10,2,1108,C,B,10,5.400000000,100,1264721,165713,10583363,5.90,100,1,5.51,100,1,,,,,,,,,,,,,,,,,,,,,,,,,20.94,0,-1,21.47,0,-1,,,,,,,,,,,,,,,,,,,,,,,,,ARL,0
2025-07-17T11:00:00.125626050Z,2025-07-17T11:00:00.125460962Z,10,2,1108,A,B,10,9.840000000,100,12852537,165088,10583364,9.84,100,1,5.90,100,1,5.51,100,1,,,,,,,,,,,,,,,,,,,,,,20.94,0,-1,21.47,0,-1,,,,,,,,,,,,,,,,,,,,,,,,,ARL,0
2025-07-17T11:00:07.975990221Z,2025-07-17T11:00:07.975824831Z,10,2,1108,C,A,10,21.330000000,100,817597,165390,10674471,5.90,100,1,5.51,100,1,,,,,,,,,,,,,,,,,,,,,,,,,20.94,0,-1,21.47,0,-1,,,,,,,,,,,,,,,,,,,,,,,,,ARL,0
2025-07-17T11:00:07.976003383Z,2025-07-17T11:00:07.975837956Z,10,2,1108,A,A,10,17.440000000,100,12983425,165427,10674472,5.90,100,1,5.51,100,1,,,,,,,,,,,,,,,,,,,,,,,,,20.94,0,-1,21.47,0,-1,,,,,,,,,,,,,,,,,,,,,,,,,ARL,0
2025-07-17T11:00:07.976138102Z,2025-07-17T11:00:07.975972618Z,10,2,1108,C,A,10,21.470000000,100,1264725,165484,10674473,5.90,100,1,5.51,100,1,,,,,,,,,,,,,,,,,,,,,,,,,17.44,0,-1,20.94,0,-1,21.47,0,-1,,,,,,,,,,,,,,,,,,,,,,ARL,0
2025-07-17T11:00:07.976144724Z,2025-07-17T11:00:07.975979367Z,10,2,1108,A,A,10,17.360000000,100,12983429,165357,10674474,5.90,100,1,5.51,100,1,,,,,,,,,,,,,,,,,,,,,,,,,17.44,0,-1,20.94,0,-1,21.47,0,-1,,,,,,,,,,,,,,,,,,,,,,ARL,0
2025-07-17T11:00:08.255140498Z,2025-07-17T11:00:08.254975294Z,10,2,1108,C,A,10,17.440000000,100,12983425,165204,10676310,5.90,100,1,5.51,100,1,,,,,,,,,,,,,,,,,,,,,,,,,17.36,0,-1,17.44,0,-1,20.94,0,-1,21.47,0,-1,,,,,,,,,,,,,,,,,,,ARL,0
2025-07-17T11:00:08.255150459Z,2025-07-17T11:00:08.254985173Z,10,2,1108,A,A,10,18.920000000,100,12985397,165286,10676311,5.90,100,1,5.51,100,1,,,,,,,,,,,,,,,,,,,,,,,,,17.36,0,-1,17.44,0,-1,20.94,0,-1,21.47,0,-1,,,,,,,,,,,,,,,,,,,ARL,0
2025-07-17T11:00:08.255312226Z,2025-07-17T11:00:08.255147130Z,10,2,1108,C,A,10,17.360000000,100,12983429,165096,10676314,5.90,100,1,5.51,100,1,,,,,,,,,,,,,,,,,,,,,,,,,17.36,0,-1,17.44,0,-1,18.92,0,-1,20.94,0,-1,21.47,0,-1,,,,,,,,,,,,,,,,ARL,0
2025-07-17T11:00:08.255320414Z,2025-07-17T11:00:08.255155317Z,10,2,1108,A,A,10,18.840000000,100,12985401,165097,10676315,5.90,100,1,5.51,100,1,,,,,,,,,,,,,,,,,,,,,,,,,17.36,0,-1,17.44,0,-1,18.92,0,-1,20.94,0,-1,21.47,0,-1,,,,,,,,,,,,,,,,ARL,0
2025-07-17T11:00:08.256027692Z,2025-07-17T11:00:08.255862656Z,10,2,1108,C,A,10,18.920000000,100,12985397,165036,10676320,5.90,100,1,5.51,100,1,,,,,,,,,,,,,,,,,,,,,,,,,17.36,0,-1,17.44,0,-1,18.84,0,-1,18.92,0,-1,20.94,0,-1,21.47,0,-1,,,,,,,,,,,,,ARL,0
2025-07-17T11:00:08.256037075Z,2025-07-17T11:00:08.255871843Z,10,2,1108,A,A,10,20.620000000,100,12985405,165232,10676321,5.90,100,1,5.51,100,1,,,,,,,,,,,,,,,,,,,,,,,,,17.36,0,-1,17.44,0,-1,18.84,0,-1,18.92,0,-1,20.94,0,-1,21.47,0,-1,,,,,,,,,,,,,ARL,0
2025-07-17T11:00:08.256333906Z,2025-07-17T11:00:08.256168895Z,10,2,1108,C,A,10,18.840000000,100,12985401,165011,10676324,5.90,100,1,5.51,100,1,,,,,,,,,,,,,,,,,,,,,,,,,17.36,0,-1,17.44,0,-1,18.84,0,-1,18.92,0,-1,20.62,0,-1,20.94,0,-1,21.47,0,-1,,,,,,,,,,ARL,0
2025-07-17T11:00:08.256340615Z,2025-07-17T11:00:08.256175346Z,10,2,1108,A,A,10,20.530000000,100,12985413,165269,10676325,5.90,100,1,5.51,100,1,,,,,,,,,,,,,,,,,,,,,,,,,17.36,0,-1,17.44,0,-1,18.84,0,-1,18.92,0,-1,20.62,0,-1,20.94,0,-1,21.47,0,-1,,,,,,,,,,ARL,0
2025-07-17T11:00:08.257050282Z,2025-07-17T11:00:08.256885010Z,10,2,1108,C,A,10,20.620000000,100,12985405,165272,10676333,5.90,100,1,5.51,100,1,,,,,,,,,,,,,,,,,,,,,,,,,17.36,0,-1,17.44,0,-1,18.84,0,-1,18.92,0,-1,20.53,0,-1,20.62,0,-1,20.94,0,-1,21.47,0,-1,,,,,,,ARL,0
2025-07-17T11:00:08.257058070Z,2025-07-17T11:00:08.256892686Z,10,2,1108,A,A,10,21.470000000,100,12985417,165384,10676334,5.90,100,1,5.51,100,1,,,,,,,,,,,,,,,,,,,,,,,,,17.36,0,-1,17.44,0,-1,18.84,0,-1,18.92,0,-1,20.53,0,-1,20.62,0,-1,20.94,0,-1,21.47,0,-1,,,,,,,ARL,0
2025-07-17T11:00:08.257234812Z,2025-07-17T11:00:08.257069458Z,10,2,1108,C,A,10,20.530000000,100,12985413,165354,10676335,5.90,100,1,5.51,100,1,,,,,,,,,,,,,,,,,,,,,,,,,17.36,0,-1,17.44,0,-1,18.84,0,-1,18.92,0,-1,20.53,0,-1,20.62,0,-1,20.94,0,-1,21.47,0,-2,,,,,,,ARL,0
2025-07-17T11:00:08.257241334Z,2025-07-17T11:00:08.257076085Z,10,2,1108,A,A,10,21.470000000,100,12985421,165249,10676336,5.90,100,1,5.51,100,1,,,,,,,,,,,,,,,,,,,,,,,,,17.36,0,-1,17.44,0,-1,18.84,0,-1,18.92,0,-1,20.53,0,-1,20.62,0,-1,20.94,0,-1,21.47,0,-2,,,,,,,ARL,0
2025-07-17T11:01:05.260586668Z,2025-07-17T11:01:05.260421351Z,10,2,1108,C,A,10,21.470000000,100,12985417,165317,10824633,5.90,100,1,5.51,100,1,,,,,,,,,,,,,,,,,,,,,,,,,17.36,0,-1,17.44,0,-1,18.84,0,-1,18.92,0,-1,20.53,0,-1,20.62,0,-1,20.94,0,-1,21.47,0,-3,,,,,,,ARL,0
2025-07-17T11:01:05.260611137Z,2025-07-17T11:01:05.260445703Z,10,2,1108,A,A,10,17.440000000,100,13174157,165434,10824634,5.90,100,1,5.51,100,1,,,,,,,,,,,,,,,,,,,,,,,,,17.36,0,-1,17.44,0,-1,18.84,0,-1,18.92,0,-1,20.53,0,-1,20.62,0,-1,20.94,0,-1,21.47,0,-3,,,,,,,ARL,0
2025-07-17T11:01:05.260858436Z,2025-07-17T11:01:05.260693130Z,10,2,1108,C,A,10,21.470000000,100,12985421,165306,10824635,5.90,100,1,5.51,100,1,,,,,,,,,,,,,,,,,,,,,,,,,17.36,0,-1,17.44,0,-2,18.84,0,-1,18.92,0,-1,20.53,0,-1,20.62,0,-1,20.94,0,-1,21.47,0,-3,,,,,,,ARL,0
2025-07-17T11:01:05.260874630Z,2025-07-17T11:01:05.260709480Z,10,2,1108,A,A,10,17.360000000,100,13174161,165150,10824636,5.90,100,1,5.51,100,1,,,,,,,,,,,,,,,,,,,,,,,,,17.36,0,-1,17.44,0,-2,18.84,0,-1,18.92,0,-1,20.53,0,-1,20.62,0,-1,20.94,0,-1,21.47,0,-3,,,,,,,ARL,0
2025-07-17T11:56:26.691626843Z,2025-07-17T11:56:26.691461161Z,10,2,1108,C,B,10,9.790000000,100,12852457,165682,14213017,5.90,100,1,5.51,100,1,,,,,,,,,,,,,,,,,,,,,,,,,17.36,0,-2,17.44,0,-2,18.84,0,-1,18.92,0,-1,20.53,0,-1,20.62,0,-1,20.94,0,-1,21.47,0,-3,,,,,,,ARL,0
2025-07-17T11:56:26.691630539Z,2025-07-17T11:56:26.691465204Z,10,2,1108,C,A,10,17.440000000,100,13174157,165335,14213018,5.90,100,1,5.51,100,1,,,,,,,,,,,,,,,,,,,,,,,,,17.36,0,-2,17.44,0,-2,18.84,0,-1,18.92,0,-1,20.53,0,-1,20.62,0,-1,20.94,0,-1,21.47,0,-3,,,,,,,ARL,0
2025-07-17T11:56:26.694933250Z,2025-07-17T11:56:26.694767820Z,10,2,1108,A,B,10,9.790000000,100,19202569,165430,14213075,9.79,100,1,5.90,100,1,5.51,100,1,,,,,,,,,,,,,,,,,,,,,,17.36,0,-2,17.44,0,-2,18.84,0,-1,18.92,0,-1,20.53,0,-1,20.62,0,-1,20.94,0,-1,21.47,0,-3,,,,,,,ARL,0
2025-07-17T11:56:26.694937361Z,2025-07-17T11:56:26.694772016Z,10,2,1108,A,A,10,17.440000000,100,19202573,165345,14213076,9.79,100,1,5.90,100,1,5.51,100,1,,,,,,,,,,,,,,,,,,,,,,17.36,0,-2,17.44,0,-2,18.84,0,-1,18.92,0,-1,20.53,0,-1,20.62,0,-1,20.94,0,-1,21.47,0,-3,,,,,,,ARL,0
2025-07-17T11:56:30.446102409Z,2025-07-17T11:56:30.445937099Z,10,2,1108,C,A,10,17.440000000,100,19202573,165310,14219824,9.79,100,1,5.90,100,1,5.51,100,1,,,,,,,,,,,,,,,,,,,,,,17.36,0,-2,17.44,0,-3,18.84,0,-1,18.92,0,-1,20.53,0,-1,20.62,0,-1,20.94,0,-1,21.47,0,-3,,,,,,,ARL,0
2025-07-17T11:56:30.446117449Z,2025-07-17T11:56:30.445951937Z,10,2,1108,A,A,10,17.930000000,100,19218909,165512,14219825,9.79,100,1,5.90,100,1,5.51,100,1,,,,,,,,,,,,,,,,,,,,,,17.36,0,-2,17.44,0,-3,18.84,0,-1,18.92,0,-1,20.53,0,-1,20.62,0,-1,20.94,0,-1,21.47,0,-3,,,,,,,ARL,0
2025-07-17T11:56:30.446231965Z,2025-07-17T11:56:30.446066952Z,10,2,1108,C,A,10,17.930000000,100,19218909,165013,14219826,9.79,100,1,5.90,100,1,5.51,100,1,,,,,,,,,,,,,,,,,,,,,,17.36,0,-2,17.44,0,-3,17.93,0,-1,18.84,0,-1,18.92,0,-1,20.53,0,-1,20.62,0,-1,20.94,0,-1,21.47,0,-3,,,,ARL,0
2025-07-17T11:56:30.446250148Z,2025-07-17T11:56:30.446084801Z,10,2,1108,A,A,10,17.440000000,100,19218913,165347,14219827,9.79,100,1,5.90,100,1,5.51,100,1,,,,,,,,,,,,,,,,,,,,,,17.36,0,-2,17.44,0,-3,17.93,0,-1,18.84,0,-1,18.92,0,-1,20.53,0,-1,20.62,0,-1,20.94,0,-1,21.47,0,-3,,,,ARL,0
2025-07-17T11:56:30.446357192Z,2025-07-17T11:56:30.446191769Z,10,2,1108,C,A,10,17.360000000,100,13174161,165423,14219828,9.79,100,1,5.90,100,1,5.51,100,1,,,,,,,,,,,,,,,,,,,,,,17.36,0,-2,17.44,0,-4,17.93,0,-1,18.84,0,-1,18.92,0,-1,20.53,0,-1,20.62,0,-1,20.94,0,-1,21.47,0,-3,,,,ARL,0
2025-07-17T11:56:30.446379036Z,2025-07-17T11:56:30.446213519Z,10,2,1108,A,A,10,17.850000000,100,19218917,165517,14219829,9.79,100,1,5.90,100,1,5.51,100,1,,,,,,,,,,,,,,,,,,,,,,17.36,0,-2,17.44,0,-4,17.93,0,-1,18.84,0,-1,18.92,0,-1,20.53,0,-1,20.62,0,-1,20.94,0,-1,21.47,0,-3,,,,ARL,0
2025-07-17T11:56:30.446543637Z,2025-07-17T11:56:30.446378732Z,10,2,1108,C,A,10,17.850000000,100,19218917,164905,14219830,9.79,100,1,5.90,100,1,5.51,100,1,,,,,,,,,,,,,,,,,,,,,,17.36,0,-2,17.44,0,-4,17.85,0,-1,17.93,0,-1,18.84,0,-1,18.92,0,-1,20.53,0,-1,20.62,0,-1,20.94,0,-1,21.47,0,-3,ARL,0
2025-07-17T11:56:30.446723646Z,2025-07-17T11:56:30.446558412Z,10,2,1108,A,A,10,17.360000000,100,19218921,165234,14219831,9.79,100,1,5.90,100,1,5.51,100,1,,,,,,,,,,,,,,,,,,,,,,17.36,0,-2,17.44,0,-4,17.85,0,-1,17.93,0,-1,18.84,0,-1,18.92,0,-1,20.53,0,-1,20.62,0,-1,20.94,0,-1,21.47,0,-3,ARL,0
2025-07-17T11:57:30.222987797Z,2025-07-17T11:57:30.222822537Z,10,2,1108,C,B,10,9.840000000,100,12852537,165260,14325877,9.79,100,1,5.90,100,1,5.51,100,1,,,,,,,,,,,,,,,,,,,,,,17.36,0,-3,17.44,0,-4,17.85,0,-1,17.93,0,-1,18.84,0,-1,18.92,0,-1,20.53,0,-1,20.62,0,-1,20.94,0,-1,21.47,0,-3,ARL,0
2025-07-17T11:57:30.222988778Z,2025-07-17T11:57:30.222823580Z,10,2,1108,C,A,10,17.360000000,100,19218921,165198,14325878,9.79,100,1,5.90,100,1,5.51,100,1,,,,,,,,,,,,,,,,,,,,,,17.36,0,-3,17.44,0,-4,17.85,0,-1,17.93,0,-1,18.84,0,-1,18.92,0,-1,20.53,0,-1,20.62,0,-1,20.94,0,-1,21.47,0,-3,ARL,0
2025-07-17T11:57:30.224151967Z,2025-07-17T11:57:30.223986626Z,10,2,1108,A,B,10,9.840000000,100,19346173,165341,14325937,9.84,100,1,9.79,100,1,5.90,100,1,5.51,100,1,,,,,,,,,,,,,,,,,,,17.36,0,-3,17.44,0,-4,17.85,0,-1,17.93,0,-1,18.84,0,-1,18.92,0,-1,20.53,0,-1,20.62,0,-1,20.94,0,-1,21.47,0,-3,ARL,0
2025-07-17T11:57:30.224156146Z,2025-07-17T11:57:30.223991040Z,10,2,1108,A,A,10,17.360000000,100,19346177,165106,14325938,9.84,100,1,9.79,100,1,5.90,100,1,5.51,100,1,,,,,,,,,,,,,,,,,,,17.36,0,-3,17.44,0,-4,17.85,0,-1,17.93,0,-1,18.84,0,-1,18.92,0,-1,20.53,0,-1,20.62,0,-1,20.94,0,-1,21.47,0,-3,ARL,0
2025-07-17T12:30:01.318008785Z,2025-07-17T12:30:01.317842911Z,10,2,1108,A,A,10,20.480000000,100,23570297,165874,16864046,9.84,100,1,9.79,100,1,5.90,100,1,5.51,100,1,,,,,,,,,,,,,,,,,,,17.36,0,-3,17.44,0,-4,17.85,0,-1,17.93,0,-1,18.84,0,-1,18.92,0,-1,20.53,0,-1,20.62,0,-1,20.94,0,-1,21.47,0,-3,ARL,0
2025-07-17T12:30:03.426465857Z,2025-07-17T12:30:03.426300621Z,10,2,1108,A,B,10,7.740000000,100,23616197,165236,16882670,9.84,100,1,9.79,100,1,7.74,100,1,5.90,100,1,5.51,100,1,,,,,,,,,,,,,,,,17.36,0,-3,17.44,0,-4,17.85,0,-1,17.93,0,-1,18.84,0,-1,18.92,0,-1,20.53,0,-1,20.62,0,-1,20.94,0,-1,21.47,0,-3,ARL,0
2025-07-17T12:30:03.426466862Z,2025-07-17T12:30:03.426301523Z,10,2,1108,A,A,10,20.480000000,100,23616201,165339,16882671,9.84,100,1,9.79,100,1,7.74,100,1,5.90,100,1,5.51,100,1,,,,,,,,,,,,,,,,17.36,0,-3,17.44,0,-4,17.85,0,-1,17.93,0,-1,18.84,0,-1,18.92,0,-1,20.53,0,-1,20.62,0,-1,20.94,0,-1,21.47,0,-3,ARL,0
2025-07-17T12:30:03.604699168Z,2025-07-17T12:30:03.604533925Z,10,2,1108,A,B,10,7.740000000,100,23622101,165243,16886020,9.84,100,1,9.79,100,1,7.74,200,2,5.90,100,1,5.51,100,1,,,,,,,,,,,,,,,,17.36,0,-3,17.44,0,-4,17.85,0,-1,17.93,0,-1,18.84,0,-1,18.92,0,-1,20.53,0,-1,20.62,0,-1,20.94,0,-1,21.47,0,-3,ARL,0
2025-07-17T12:30:51.178394233Z,2025-07-17T12:30:51.178228608Z,10,2,1108,A,A,10,20.480000000,100,24099409,165625,17120703,9.84,100,1,9.79,100,1,7.74,200,2,5.90,100,1,5.51,100,1,,,,,,,,,,,,,,,,17.36,0,-3,17.44,0,-4,17.85,0,-1,17.93,0,-1,18.84,0,-1,18.92,0,-1,20.53,0,-1,20.62,0,-1,20.94,0,-1,21.47,0,-3,ARL,0
2025-07-17T12:30:51.643125167Z,2025-07-17T12:30:51.642959794Z,10,2,1108,A,B,10,7.740000000,100,24102329,165373,17122998,9.84,100,1,9.79,100,1,7.74,300,3,5.90,100,1,5.51,100,1,,,,,,,,,,,,,,,,17.36,0,-3,17.44,0,-4,17.85,0,-1,17.93,0,-1,18.84,0,-1,18.92,0,-1,20.53,0,-1,20.62,0,-1,20.94,0,-1,21.47,0,-3,ARL,0
2025-07-17T13:15:00.032611736Z,2025-07-17T13:15:00.032446132Z,10,2,1108,C,A,10,17.440000000,100,19218913,165604,23080007,9.84,100,1,9.79,100,1,7.74,200,2,5.90,100,1,5.51,100,1,,,,,,,,,,,,,,,,17.36,0,-3,17.44,0,-4,17.85,0,-1,17.93,0,-1,18.84,0,-1,18.92,0,-1,20.53,0,-1,20.62,0,-1,20.94,0,-1,21.47,0,-3,ARL,0
2025-07-17T13:15:00.032651211Z,2025-07-17T13:15:00.032483824Z,10,2,1108,C,B,10,9.790000000,100,19202569,167387,23080041,9.84,100,1,9.79,100,1,7.74,200,2,5.90,100,1,5.51,100,1,,,,,,,,,,,,,,,,17.36,0,-3,17.44,0,-4,17.85,0,-1,17.93,0,-1,18.84,0,-1,18.92,0,-1,20.53,0,-1,20.62,0,-1,20.94,0,-1,21.47,0,-3,ARL,0
2025-07-17T13:15:00.058480238Z,2025-07-17T13:15:00.058314138Z,10,2,1108,C,A,10,17.360000000,100,19346177,166100,23101369,9.84,100,1,9.79,100,1,7.74,200,2,5.90,100,1,5.51,100,1,,,,,,,,,,,,,,,,17.36,0,-3,17.44,0,-4,17.85,0,-1,17.93,0,-1,18.84,0,-1,18.92,0,-1,20.53,0,-1,20.62,0,-1,20.94,0,-1,21.47,0,-3,ARL,0
2025-07-17T13:15:00.058537384Z,2025-07-17T13:15:00.058371545Z,10,2,1108,C,B,10,9.840000000,100,19346173,165839,23101396,9.84,100,1,9.79,100,1,7.74,200,2,5.90,100,1,5.51,100,1,,,,,,,,,,,,,,,,17.36,0,-3,17.44,0,-4,17.85,0,-1,17.93,0,-1,18.84,0,-1,18.92,0,-1,20.53,0,-1,20.62,0,-1,20.94,0,-1,21.47,0,-3,ARL,0
2025-07-17T13:15:01.925239044Z,2025-07-17T13:15:01.925073727Z,10,2,1108,A,B,10,7.740000000,100,31960841,165317,23123943,9.84,100,1,9.79,100,1,7.74,300,3,5.90,100,1,5.51,100,1,,,,,,,,,,,,,,,,17.36,0,-3,17.44,0,-4,17.85,0,-1,17.93,0,-1,18.84,0,-1,18.92,0,-1,20.53,0,-1,20.62,0,-1,20.94,0,-1,21.47,0,-3,ARL,0
2025-07-17T13:15:02.042906947Z,2025-07-17T13:15:02.042741730Z,10,2,1108,A,A,10,20.480000000,100,31962113,165217,23124563,9.84,100,1,9.79,100,1,7.74,300,3,5.90,100,1,5.51,100,1,,,,,,,,,,,,,,,,17.36,0,-3,17.44,0,-4,17.85,0,-1,17.93,0,-1,18.84,0,-1,18.92,0,-1,20.53,0,-1,20.62,0,-1,20.94,0,-1,21.47,0,-3,ARL,0
2025-07-17T13:17:49.831329888Z,2025-07-17T13:17:49.831164624Z,10,2,1108,A,B,10,7.740000000,100,33574717,165264,23465434,9.84,100,1,9.79,100,1,7.74,400,4,5.90,100,1,5.51,100,1,,,,,,,,,,,,,,,,17.36,0,-3,17.44,0,-4,17.85,0,-1,17.93,0,-1,18.84,0,-1,18.92,0,-1,20.53,0,-1,20.62,0,-1,20.94,0,-1,21.47,0,-3,ARL,0
2025-07-17T13:17:49.831709365Z,2025-07-17T13:17:49.831544051Z,10,2,1108,A,A,10,20.480000000,100,33574725,165314,23465435,9.84,100,1,9.79,100,1,7.74,400,4,5.90,100,1,5.51,100,1,,,,,,,,,,,,,,,,17.36,0,-3,17.44,0,-4,17.85,0,-1,17.93,0,-1,18.84,0,-1,18.92,0,-1,20.53,0,-1,20.62,0,-1,20.94,0,-1,21.47,0,-3,ARL,0
2025-07-17T13:19:57.597368321Z,2025-07-17T13:19:57.597203040Z,10,2,1108,A,B,10,8.740000000,100,34790041,165281,23710201,9.84,100,1,9.79,100,1,8.74,100,1,7.74,400,4,5.90,100,1,5.51,100,1,,,,,,,,,,,,,17.36,0,-3,17.44,0,-4,17.85,0,-1,17.93,0,-1,18.84,0,-1,18.92,0,-1,20.53,0,-1,20.62,0,-1,20.94,0,-1,21.47,0,-3,ARL,0
2025-07-17T13:19:57.597456270Z,2025-07-17T13:19:57.597291053Z,10,2,1108,A,A,10,18.350000000,100,34790045,165217,23710202,9.84,100,1,9.79,100,1,8.74,100,1,7.74,400,4,5.90,100,1,5.51,100,1,,,,,,,,,,,,,17.36,0,-3,17.44,0,-4,17.85,0,-1,17.93,0,-1,18.84,0,-1,18.92,0,-1,20.53,0,-1,20.62,0,-1,20.94,0,-1,21.47,0,-3,ARL,0
2025-07-17T13:19:58.492785060Z,2025-07-17T13:19:58.492619751Z,10,2,1108,A,A,10,18.240000000,100,34810233,165309,23728432,9.84,100,1,9.79,100,1,8.74,100,1,7.74,400,4,5.90,100,1,5.51,100,1,,,,,,,,,,,,,17.36,0,-3,17.44,0,-4,17.85,0,-1,17.93,0,-1,18.84,0,-1,18.92,0,-1,20.53,0,-1,20.62,0,-1,20.94,0,-1,21.47,0,-3,ARL,0
2025-07-17T13:19:58.492799826Z,2025-07-17T13:19:58.492634480Z,10,2,1108,A,B,10,9.240000000,100,34810241,165346,23728435,9.84,100,1,9.79,100,1,9.24,100,1,8.74,100,1,7.74,400,4,5.90,100,1,5.51,100,1,,,,,,,,,,17.36,0,-3,17.44,0,-4,17.85,0,-1,17.93,0,-1,18.84,0,-1,18.92,0,-1,20.53,0,-1,20.62,0,-1,20.94,0,-1,21.47,0,-3,ARL,0
2025-07-17T13:20:00.525430361Z,2025-07-17T13:20:00.525263842Z,10,2,1108,C,A,10,18.240000000,100,34810233,166519,23765825,9.84,100,1,9.79,100,1,8.74,100,1,7.74,400,4,5.90,100,1,5.51,100,1,,,,,,,,,,,,,17.36,0,-3,17.44,0,-4,17.85,0,-1,17.93,0,-1,18.84,0,-1,18.92,0,-1,20.53,0,-1,20.62,0,-1,20.94,0,-1,21.47,0,-3,ARL,0
2025-07-17T13:20:00.525430361Z,2025-07-17T13:20:00.525264700Z,10,2,1108,C,B,10,9.240000000,100,34810241,165661,23765826,9.84,100,1,9.79,100,1,8.74,100,1,7.74,400,4,5.90,100,1,5.51,100,1,,,,,,,,,,,,,17.36,0,-3,17.44,0,-4,17.85,0,-1,17.93,0,-1,18.84,0,-1,18.92,0,-1,20.53,0,-1,20.62,0,-1,20.94,0,-1,21.47,0,-3,ARL,0
2025-07-17T13:25:00.157632223Z,2025-07-17T13:25:00.157467184Z,10,2,1108,C,B,10,8.740000000,100,34790041,165039,24448205,9.84,100,1,9.79,100,1,8.74,100,1,7.74,400,4,5.90,100,1,5.51,100,1,,,,,,,,,,,,,17.36,0,-3,17.44,0,-4,17.85,0,-1,17.93,0,-1,18.84,0,-1,18.92,0,-1,20.53,0,-1,20.62,0,-1,20.94,0,-1,21.47,0,-3,ARL,0
2025-07-17T13:25:00.157638512Z,2025-07-17T13:25:00.157473422Z,10,2,1108,C,A,10,18.350000000,100,34790045,165090,24448207,9.84,100,1,9.79,100,1,8.74,100,1,7.74,400,4,5.90,100,1,5.51,100,1,,,,,,,,,,,,,17.36,0,-3,17.44,0,-4,17.85,0,-1,17.93,0,-1,18.84,0,-1,18.92,0,-1,20.53,0,-1,20.62,0,-1,20.94,0,-1,21.47,0,-3,ARL,0
2025-07-17T13:25:01.732485386Z,2025-07-17T13:25:01.732320109Z,10,2,1108,A,B,10,7.740000000,100,38041417,165277,24478872,9.84,100,1,9.79,100,1,8.74,100,1,7.74,500,5,5.90,100,1,5.51,100,1,,,,,,,,,,,,,17.36,0,-3,17.44,0,-4,17.85,0,-1,17.93,0,-1,18.84,0,-1,18.92,0,-1,20.53,0,-1,20.62,0,-1,20.94,0,-1,21.47,0,-3,ARL,0
2025-07-17T13:25:01.819447960Z,2025-07-17T13:25:01.819282823Z,10,2,1108,A,A,10,20.480000000,100,38043741,165137,24480276,9.84,100,1,9.79,100,1,8.74,100,1,7.74,500,5,5.90,100,1,5.51,100,1,,,,,,,,,,,,,17.36,0,-3,17.44,0,-4,17.85,0,-1,17.93,0,-1,18.84,0,-1,18.92,0,-1,20.53,0,-1,20.62,0,-1,20.94,0,-1,21.47,0,-3,ARL,0
2025-07-17T13:28:08.192080463Z,2025-07-17T13:28:08.191915168Z,10,2,1108,A,B,10,7.740000000,100,40617777,165295,25597187,9.84,100,1,9.79,100,1,8.74,100,1,7.74,600,6,5.90,100,1,5.51,100,1,,,,,,,,,,,,,17.36,0,-3,17.44,0,-4,17.85,0,-1,17.93,0,-1,18.84,0,-1,18.92,0,-1,20.53,0,-1,20.62,0,-1,20.94,0,-1,21.47,0,-3,ARL,0
2025-07-17T13:28:08.192147601Z,2025-07-17T13:28:08.191982270Z,10,2,1108,A,A,10,20.480000000,100,40617785,165331,25597189,9.84,100,1,9.79,100,1,8.74,100,1,7.74,600,6,5.90,100,1,5.51,100,1,,,,,,,,,,,,,17.36,0,-3,17.44,0,-4,17.85,0,-1,17.93,0,-1,18.84,0,-1,18.92,0,-1,20.53,0,-1,20.62,0,-1,20.94,0,-1,21.47,0,-3,ARL,0
2025-07-17T13:28:21.011414592Z,2025-07-17T13:28:21.011249114Z,10,2,1108,A,A,10,18.320000000,700,40846101,165478,25907820,9.84,100,1,9.79,100,1,8.74,100,1,7.74,600,6,5.90,100,1,5.51,100,1,,,,,,,,,,,,,17.36,0,-3,17.44,0,-4,17.85,0,-1,17.93,0,-1,18.84,0,-1,18.92,0,-1,20.53,0,-1,20.62,0,-1,20.94,0,-1,21.47,0,-3,ARL,0
2025-07-17T13:28:21.029030365Z,2025-07-17T13:28:21.028865155Z,10,2,1108,A,B,10,9.290000000,700,40851989,165210,25917006,9.84,100,1,9.79,100,1,9.29,700,1,8.74,100,1,7.74,600,6,5.90,100,1,5.51,100,1,,,,,,,,,,17.36,0,-3,17.44,0,-4,17.85,0,-1,17.93,0,-1,18.84,0,-1,18.92,0,-1,20.53,0,-1,20.62,0,-1,20.94,0,-1,21.47,0,-3,ARL,0
2025-07-17T13:28:30.048895468Z,2025-07-17T13:28:30.048730211Z,10,2,1108,A,B,10,9.670000000,100,40999441,165257,26140646,9.84,100,1,9.79,100,1,9.67,100,1,9.29,700,1,8.74,100,1,7.74,600,6,5.90,100,1,5.51,100,1,,,,,,,17.36,0,-3,17.44,0,-4,17.85,0,-1,17.93,0,-1,18.84,0,-1,18.92,0,-1,20.53,0,-1,20.62,0,-1,20.94,0,-1,21.47,0,-3,ARL,0
2025-07-17T13:28:30.048907452Z,2025-07-17T13:28:30.048741690Z,10,2,1108,A,A,10,17.600000000,100,40999449,165762,26140658,9.84,100,1,9.79,100,1,9.67,100,1,9.29,700,1,8.74,100,1,7.74,600,6,5.90,100,1,5.51,100,1,,,,,,,17.36,0,-3,17.44,0,-4,17.85,0,-1,17.93,0,-1,18.84,0,-1,18.92,0,-1,20.53,0,-1,20.62,0,-1,20.94,0,-1,21.47,0,-3,ARL,0
2025-07-17T13:28:30.052061798Z,2025-07-17T13:28:30.051894007Z,10,2,1108,A,B,10,9.990000000,100,41000165,167791,26142104,9.99,100,1,9.84,100,1,9.79,100,1,9.67,100,1,9.29,700,1,8.74,100,1,7.74,600,6,5.90,100,1,5.51,100,1,,,,17.36,0,-3,17.44,0,-4,17.85,0,-1,17.93,0,-1,18.84,0,-1,18.92,0,-1,20.53,0,-1,20.62,0,-1,20.94,0,-1,21.47,0,-3,ARL,0
2025-07-17T13:28:30.052072568Z,2025-07-17T13:28:30.051907073Z,10,2,1108,A,A,10,17.120000000,100,41000173,165495,26142118,9.99,100,1,9.84,100,1,9.79,100,1,9.67,100,1,9.29,700,1,8.74,100,1,7.74,600,6,5.90,100,1,5.51,100,1,,,,17.36,0,-3,17.44,0,-4,17.85,0,-1,17.93,0,-1,18.84,0,-1,18.92,0,-1,20.53,0,-1,20.62,0,-1,20.94,0,-1,21.47,0,-3,ARL,0
2025-07-17T13:28:30.257018844Z,2025-07-17T13:28:30.256853564Z,10,2,1108,A,B,10,9.670000000,100,41021369,165280,26170917,9.99,100,1,9.84,100,1,9.79,100,1,9.67,200,2,9.29,700,1,8.74,100,1,7.74,600,6,5.90,100,1,5.51,100,1,,,,17.36,0,-3,17.44,0,-4,17.85,0,-1,17.93,0,-1,18.84,0,-1,18.92,0,-1,20.53,0,-1,20.62,0,-1,20.94,0,-1,21.47,0,-3,ARL,0
2025-07-17T13:28:30.257031156Z,2025-07-17T13:28:30.256865858Z,10,2,1108,A,A,10,17.600000000,100,41021373,165298,26170918,9.99,100,1,9.84,100,1,9.79,100,1,9.67,200,2,9.29,700,1,8.74,100,1,7.74,600,6,5.90,100,1,5.51,100,1,,,,17.36,0,-3,17.44,0,-4,17.85,0,-1,17.93,0,-1,18.84,0,-1,18.92,0,-1,20.53,0,-1,20.62,0,-1,20.94,0,-1,21.47,0,-3,ARL,0
2025-07-17T13:28:30.277622346Z,2025-07-17T13:28:30.277457031Z,10,2,1108,A,B,10,9.990000000,100,41021837,165315,26171531,9.99,200,2,9.84,100,1,9.79,100,1,9.67,200,2,9.29,700,1,8.74,100,1,7.74,600,6,5.90,100,1,5.51,100,1,,,,17.36,0,-3,17.44,0,-4,17.85,0,-1,17.93,0,-1,18.84,0,-1,18.92,0,-1,20.53,0,-1,20.62,0,-1,20.94,0,-1,21.47,0,-3,ARL,0
2025-07-17T13:28:30.277635645Z,2025-07-17T13:28:30.277470320Z,10,2,1108,A,A,10,17.120000000,100,41021841,165325,26171533,9.99,200,2,9.84,100,1,9.79,100,1,9.67,200,2,9.29,700,1,8.74,100,1,7.74,600,6,5.90,100,1,5.51,100,1,,,,17.36,0,-3,17.44,0,-4,17.85,0,-1,17.93,0,-1,18.84,0,-1,18.92,0,-1,20.53,0,-1,20.62,0,-1,20.94,0,-1,21.47,0,-3,ARL,0
2025-07-17T13:28:30.613482667Z,2025-07-17T13:28:30.613317490Z,10,2,1108,A,B,10,9.130000000,100,41032049,165177,26182390,9.99,200,2,9.84,100,1,9.79,100,1,9.67,200,2,9.29,700,1,9.13,100,1,8.74,100,1,7.74,600,6,5.90,100,1,5.51,100,1,17.36,0,-3,17.44,0,-4,17.85,0,-1,17.93,0,-1,18.84,0,-1,18.92,0,-1,20.53,0,-1,20.62,0,-1,20.94,0,-1,21.47,0,-3,ARL,0
2025-07-17T13:28:30.613495057Z,2025-07-17T13:28:30.613329849Z,10,2,1108,A,A,10,18.400000000,100,41032057,165208,26182393,9.99,200,2,9.84,100,1,9.79,100,1,9.67,200,2,9.29,700,1,9.13,100,1,8.74,100,1,7.74,600,6,5.90,100,1,5.51,100,1,17.36,0,-3,17.44,0,-4,17.85,0,-1,17.93,0,-1,18.84,0,-1,18.92,0,-1,20.53,0,-1,20.62,0,-1,20.94,0,-1,21.47,0,-3,ARL,0
2025-07-17T13:28:41.476876547Z,2025-07-17T13:28:41.476711173Z,10,2,1108,A,B,10,7.840000000,100,41306441,165374,26518296,9.99,200,2,9.84,100,1,9.79,100,1,9.67,200,2,9.29,700,1,9.13,100,1,8.74,100,1,7.84,100,1,7.74,600,6,5.90,100,1,17.36,0,-3,17.44,0,-4,17.85,0,-1,17.93,0,-1,18.84,0,-1,18.92,0,-1,20.53,0,-1,20.62,0,-1,20.94,0,-1,21.47,0,-3,ARL,0
2025-07-17T13:28:41.476887975Z,2025-07-17T13:28:41.476722715Z,10,2,1108,A,A,10,20.320000000,100,41306445,165260,26518297,9.99,200,2,9.84,100,1,9.79,100,1,9.67,200,2,9.29,700,1,9.13,100,1,8.74,100,1,7.84,100,1,7.74,600,6,5.90,100,1,17.36,0,-3,17.44,0,-4,17.85,0,-1,17.93,0,-1,18.84,0,-1,18.92,0,-1,20.53,0,-1,20.62,0,-1,20.94,0,-1,21.47,0,-3,ARL,0
2025-07-17T13:28:46.014904874Z,2025-07-17T13:28:46.014739305Z,10,2,1108,A,A,10,15.300000000,100,41370837,165569,26613800,9.99,200,2,9.84,100,1,9.79,100,1,9.67,200,2,9.29,700,1,9.13,100,1,8.74,100,1,7.84,100,1,7.74,600,6,5.90,100,1,17.36,0,-3,17.44,0,-4,17.85,0,-1,17.93,0,-1,18.84,0,-1,18.92,0,-1,20.53,0,-1,20.62,0,-1,20.94,0,-1,21.47,0,-3,ARL,0
2025-07-17T13:28:46.014968000Z,2025-07-17T13:28:46.014802018Z,10,2,1108,C,A,10,20.480000000,100,23570297,165982,26613836,9.99,200,2,9.84,100,1,9.79,100,1,9.67,200,2,9.29,700,1,9.13,100,1,8.74,100,1,7.84,100,1,7.74,600,6,5.90,100,1,15.30,0,-1,17.36,0,-3,17.44,0,-4,17.85,0,-1,17.93,0,-1,18.84,0,-1,18.92,0,-1,20.53,0,-1,20.62,0,-1,20.94,0,-1,ARL,0
2025-07-17T13:28:46.014968000Z,2025-07-17T13:28:46.014802018Z,10,2,1108,A,A,10,19.580000000,100,41370945,165982,26613836,9.99,200,2,9.84,100,1,9.79,100,1,9.67,200,2,9.29,700,1,9.13,100,1,8.74,100,1,7.84,100,1,7.74,600,6,5.90,100,1,15.30,0,-1,17.36,0,-3,17.44,0,-4,17.85,0,-1,17.93,0,-1,18.84,0,-1,18.92,0,-1,20.53,0,-1,20.62,0,-1,20.94,0,-1,ARL,0
2025-07-17T13:28:46.014969135Z,2025-07-17T13:28:46.014803011Z,10,2,1108,C,A,10,20.480000000,100,23616201,166124,26613837,9.99,200,2,9.84,100,1,9.79,100,1,9.67,200,2,9.29,700,1,9.13,100,1,8.74,100,1,7.84,100,1,7.74,600,6,5.90,100,1,15.30,0,-1,17.36,0,-3,17.44,0,-4,17.85,0,-1,17.93,0,-1,18.84,0,-1,18.92,0,-1,19.58,0,-1,20.53,0,-1,20.62,0,-1,ARL,0
2025-07-17T13:28:46.014969135Z,2025-07-17T13:28:46.014803011Z,10,2,1108,A,A,10,19.580000000,100,41370949,166124,26613837,9.99,200,2,9.84,100,1,9.79,100,1,9.67,200,2,9.29,700,1,9.13,100,1,8.74,100,1,7.84,100,1,7.74,600,6,5.90,100,1,15.30,0,-1,17.36,0,-3,17.44,0,-4,17.85,0,-1,17.93,0,-1,18.84,0,-1,18.92,0,-1,19.58,0,-1,20.53,0,-1,20.62,0,-1,ARL,0
2025-07-17T13:28:46.014970699Z,2025-07-17T13:28:46.014804158Z,10,2,1108,C,A,10,20.480000000,100,24099409,166541,26613838,9.99,200,2,9.84,100,1,9.79,100,1,9.67,200,2,9.29,700,1,9.13,100,1,8.74,100,1,7.84,100,1,7.74,600,6,5.90,100,1,15.30,0,-1,17.36,0,-3,17.44,0,-4,17.85,0,-1,17.93,0,-1,18.84,0,-1,18.92,0,-1,19.58,0,-2,20.53,0,-1,20.62,0,-1,ARL,0
2025-07-17T13:28:46.014970699Z,2025-07-17T13:28:46.014804158Z,10,2,1108,A,A,10,19.580000000,100,41370953,166541,26613838,9.99,200,2,9.84,100,1,9.79,100,1,9.67,200,2,9.29,700,1,9.13,100,1,8.74,100,1,7.84,100,1,7.74,600,6,5.90,100,1,15.30,0,-1,17.36,0,-3,17.44,0,-4,17.85,0,-1,17.93,0,-1,18.84,0,-1,18.92,0,-1,19.58,0,-2,20.53,0,-1,20.62,0,-1,ARL,0
2025-07-17T13:28:46.014970699Z,2025-07-17T13:28:46.014804564Z,10,2,1108,C,A,10,20.480000000,100,31962113,166135,26613839,9.99,200,2,9.84,100,1,9.79,100,1,9.67,200,2,9.29,700,1,9.13,100,1,8.74,100,1,7.84,100,1,7.74,600,6,5.90,100,1,15.30,0,-1,17.36,0,-3,17.44,0,-4,17.85,0,-1,17.93,0,-1,18.84,0,-1,18.92,0,-1,19.58,0,-3,20.53,0,-1,20.62,0,-1,ARL,0
2025-07-17T13:28:46.014970699Z,2025-07-17T13:28:46.014804564Z,10,2,1108,A,A,10,19.580000000,100,41370957,166135,26613839,9.99,200,2,9.84,100,1,9.79,100,1,9.67,200,2,9.29,700,1,9.13,100,1,8.74,100,1,7.84,100,1,7.74,600,6,5.90,100,1,15.30,0,-1,17.36,0,-3,17.44,0,-4,17.85,0,-1,17.93,0,-1,18.84,0,-1,18.92,0,-1,19.58,0,-3,20.53,0,-1,20.62,0,-1,ARL,0
2025-07-17T13:28:46.014972151Z,2025-07-17T13:28:46.014805680Z,10,2,1108,C,A,10,20.480000000,100,33574725,166471,26613840,9.99,200,2,9.84,100,1,9.79,100,1,9.67,200,2,9.29,700,1,9.13,100,1,8.74,100,1,7.84,100,1,7.74,600,6,5.90,100,1,15.30,0,-1,17.36,0,-3,17.44,0,-4,17.85,0,-1,17.93,0,-1,18.84,0,-1,18.92,0,-1,19.58,0,-4,20.53,0,-1,20.62,0,-1,ARL,0
2025-07-17T13:28:46.014972151Z,2025-07-17T13:28:46.014805680Z,10,2,1108,A,A,10,19.580000000,100,41370961,166471,26613840,9.99,200,2,9.84,100,1,9.79,100,1,9.67,200,2,9.29,700,1,9.13,100,1,8.74,100,1,7.84,100,1,7.74,600,6,5.90,100,1,15.30,0,-1,17.36,0,-3,17.44,0,-4,17.85,0,-1,17.93,0,-1,18.84,0,-1,18.92,0,-1,19.58,0,-4,20.53,0,-1,20.62,0,-1,ARL,0
2025-07-17T13:28:46.014972151Z,2025-07-17T13:28:46.014805841Z,10,2,1108,C,A,10,20.480000000,100,38043741,166310,26613841,9.99,200,2,9.84,100,1,9.79,100,1,9.67,200,2,9.29,700,1,9.13,100,1,8.74,100,1,7.84,100,1,7.74,600,6,5.90,100,1,15.30,0,-1,17.36,0,-3,17.44,0,-4,17.85,0,-1,17.93,0,-1,18.84,0,-1,18.92,0,-1,19.58,0,-5,20.53,0,-1,20.62,0,-1,ARL,0
2025-07-17T13:28:46.014972151Z,2025-07-17T13:28:46.014805841Z,10,2,1108,A,A,10,19.580000000,100,41370965,166310,26613841,9.99,200,2,9.84,100,1,9.79,100,1,9.67,200,2,9.29,700,1,9.13,100,1,8.74,100,1,7.84,100,1,7.74,600,6,5.90,100,1,15.30,0,-1,17.36,0,-3,17.44,0,-4,17.85,0,-1,17.93,0,-1,18.84,0,-1,18.92,0,-1,19.58,0,-5,20.53,0,-1,20.62,0,-1,ARL,0
2025-07-17T13:28:46.014973343Z,2025-07-17T13:28:46.014807086Z,10,2,1108,C,A,10,20.480000000,100,40617785,166257,26613842,9.99,200,2,9.84,100,1,9.79,100,1,9.67,200,2,9.29,700,1,9.13,100,1,8.74,100,1,7.84,100,1,7.74,600,6,5.90,100,1,15.30,0,-1,17.36,0,-3,17.44,0,-4,17.85,0,-1,17.93,0,-1,18.84,0,-1,18.92,0,-1,19.58,0,-6,20.53,0,-1,20.62,0,-1,ARL,0
2025-07-17T13:28:46.014973343Z,2025-07-17T13:28:46.014807086Z,10,2,1108,A,A,10,19.580000000,100,41370969,166257,26613842,9.99,200,2,9.84,100,1,9.79,100,1,9.67,200,2,9.29,700,1,9.13,100,1,8.74,100,1,7.84,100,1,7.74,600,6,5.90,100,1,15.30,0,-1,17.36,0,-3,17.44,0,-4,17.85,0,-1,17.93,0,-1,18.84,0,-1,18.92,0,-1,19.58,0,-6,20.53,0,-1,20.62,0,-1,ARL,0
2025-07-17T13:28:46.015690361Z,2025-07-17T13:28:46.015523291Z,10,2,1108,A,B,10,10.180000000,700,41371221,167070,26614152,10.18,700,1,9.99,200,2,9.84,100,1,9.79,100,1,9.67,200,2,9.29,700,1,9.13,100,1,8.74,100,1,7.84,100,1,7.74,600,6,15.30,0,-1,17.36,0,-3,17.44,0,-4,17.85,0,-1,17.93,0,-1,18.84,0,-1,18.92,0,-1,19.58,0,-6,20.53,0,-1,20.62,0,-1,ARL,0
2025-07-17T13:28:46.015691617Z,2025-07-17T13:28:46.015525315Z,10,2,1108,A,A,10,16.110000000,700,41371225,166302,26614155,10.18,700,1,9.99,200,2,9.84,100,1,9.79,100,1,9.67,200,2,9.29,700,1,9.13,100,1,8.74,100,1,7.84,100,1,7.74,600,6,15.30,0,-1,17.36,0,-3,17.44,0,-4,17.85,0,-1,17.93,0,-1,18.84,0,-1,18.92,0,-1,19.58,0,-6,20.53,0,-1,20.62,0,-1,ARL,0
2025-07-17T13:28:46.017375168Z,2025-07-17T13:28:46.017209641Z,10,2,1108,C,A,10,17.120000000,100,41000173,165527,26614961,10.18,700,1,9.99,200,2,9.84,100,1,9.79,100,1,9.67,200,2,9.29,700,1,9.13,100,1,8.74,100,1,7.84,100,1,7.74,600,6,15.30,0,-1,17.36,0,-3,17.44,0,-4,17.85,0,-1,17.93,0,-1,18.84,0,-1,18.92,0,-1,19.58,0,-6,20.53,0,-1,20.62,0,-1,ARL,0
2025-07-17T13:28:46.017375168Z,2025-07-17T13:28:46.017209641Z,10,2,1108,A,A,10,16.380000000,100,41372085,165527,26614961,10.18,700,1,9.99,200,2,9.84,100,1,9.79,100,1,9.67,200,2,9.29,700,1,9.13,100,1,8.74,100,1,7.84,100,1,7.74,600,6,15.30,0,-1,17.36,0,-3,17.44,0,-4,17.85,0,-1,17.93,0,-1,18.84,0,-1,18.92,0,-1,19.58,0,-6,20.53,0,-1,20.62,0,-1,ARL,0
2025-07-17T13:28:46.017425627Z,2025-07-17T13:28:46.017260228Z,10,2,1108,C,A,10,17.600000000,100,40999449,165399,26614991,10.18,700,1,9.99,200,2,9.84,100,1,9.79,100,1,9.67,200,2,9.29,700,1,9.13,100,1,8.74,100,1,7.84,100,1,7.74,600,6,15.30,0,-1,16.38,0,-1,17.36,0,-3,17.44,0,-4,17.85,0,-1,17.93,0,-1,18.84,0,-1,18.92,0,-1,19.58,0,-6,20.53,0,-1,ARL,0
2025-07-17T13:28:46.017425627Z,2025-07-17T13:28:46.017260228Z,10,2,1108,A,A,10,16.830000000,100,41372125,165399,26614991,10.18,700,1,9.99,200,2,9.84,100,1,9.79,100,1,9.67,200,2,9.29,700,1,9.13,100,1,8.74,100,1,7.84,100,1,7.74,600,6,15.30,0,-1,16.38,0,-1,17.36,0,-3,17.44,0,-4,17.85,0,-1,17.93,0,-1,18.84,0,-1,18.92,0,-1,19.58,0,-6,20.53,0,-1,ARL,0
2025-07-17T13:28:46.017696573Z,2025-07-17T13:28:46.017531156Z,10,2,1108,C,A,10,17.120000000,100,41021841,165417,26615138,10.18,700,1,9.99,200,2,9.84,100,1,9.79,100,1,9.67,200,2,9.29,700,1,9.13,100,1,8.74,100,1,7.84,100,1,7.74,600,6,15.30,0,-1,16.38,0,-1,16.83,0,-1,17.36,0,-3,17.44,0,-4,17.85,0,-1,17.93,0,-1,18.84,0,-1,18.92,0,-1,19.58,0,-6,ARL,0
2025-07-17T13:28:46.017696573Z,2025-07-17T13:28:46.017531156Z,10,2,1108,A,A,10,16.380000000,100,41372369,165417,26615138,10.18,700,1,9.99,200,2,9.84,100,1,9.79,100,1,9.67,200,2,9.29,700,1,9.13,100,1,8.74,100,1,7.84,100,1,7.74,600,6,15.30,0,-1,16.38,0,-1,16.83,0,-1,17.36,0,-3,17.44,0,-4,17.85,0,-1,17.93,0,-1,18.84,0,-1,18.92,0,-1,19.58,0,-6,ARL,0
2025-07-17T13:28:46.017823073Z,2025-07-17T13:28:46.017657609Z,10,2,1108,C,A,10,17.600000000,100,41021373,165464,26615203,10.18,700,1,9.99,200,2,9.84,100,1,9.79,100,1,9.67,200,2,9.29,700,1,9.13,100,1,8.74,100,1,7.84,100,1,7.74,600,6,15.30,0,-1,16.38,0,-2,16.83,0,-1,17.36,0,-3,17.44,0,-4,17.85,0,-1,17.93,0,-1,18.84,0,-1,18.92,0,-1,19.58,0,-6,ARL,0
2025-07-17T13:28:46.017823073Z,2025-07-17T13:28:46.017657609Z,10,2,1108,A,A,10,16.830000000,100,41372469,165464,26615203,10.18,700,1,9.99,200,2,9.84,100,1,9.79,100,1,9.67,200,2,9.29,700,1,9.13,100,1,8.74,100,1,7.84,100,1,7.74,600,6,15.30,0,-1,16.38,0,-2,16.83,0,-1,17.36,0,-3,17.44,0,-4,17.85,0,-1,17.93,0,-1,18.84,0,-1,18.92,0,-1,19.58,0,-6,ARL,0
2025-07-17T13:28:46.017886428Z,2025-07-17T13:28:46.017721028Z,10,2,1108,C,A,10,18.400000000,100,41032057,165400,26615230,10.18,700,1,9.99,200,2,9.84,100,1,9.79,100,1,9.67,200,2,9.29,700,1,9.13,100,1,8.74,100,1,7.84,100,1,7.74,600,6,15.30,0,-1,16.38,0,-2,16.83,0,-2,17.36,0,-3,17.44,0,-4,17.85,0,-1,17.93,0,-1,18.84,0,-1,18.92,0,-1,19.58,0,-6,ARL,0
2025-07-17T13:28:46.017886428Z,2025-07-17T13:28:46.017721028Z,10,2,1108,A,A,10,17.600000000,100,41372493,165400,26615230,10.18,700,1,9.99,200,2,9.84,100,1,9.79,100,1,9.67,200,2,9.29,700,1,9.13,100,1,8.74,100,1,7.84,100,1,7.74,600,6,15.30,0,-1,16.38,0,-2,16.83,0,-2,17.36,0,-3,17.44,0,-4,17.85,0,-1,17.93,0,-1,18.84,0,-1,18.92,0,-1,19.58,0,-6,ARL,0
2025-07-17T13:28:46.018003119Z,2025-07-17T13:28:46.017837874Z,10,2,1108,C,A,10,20.320000000,100,41306445,165245,26615283,10.18,700,1,9.99,200,2,9.84,100,1,9.79,100,1,9.67,200,2,9.29,700,1,9.13,100,1,8.74,100,1,7.84,100,1,7.74,600,6,15.30,0,-1,16.38,0,-2,16.83,0,-2,17.36,0,-3,17.44,0,-4,17.60,0,-1,17.85,0,-1,17.93,0,-1,18.84,0,-1,18.92,0,-1,ARL,0
2025-07-17T13:28:46.018003119Z,2025-07-17T13:28:46.017837874Z,10,2,1108,A,A,10,19.440000000,100,41372549,165245,26615283,10.18,700,1,9.99,200,2,9.84,100,1,9.79,100,1,9.67,200,2,9.29,700,1,9.13,100,1,8.74,100,1,7.84,100,1,7.74,600,6,15.30,0,-1,16.38,0,-2,16.83,0,-2,17.36,0,-3,17.44,0,-4,17.60,0,-1,17.85,0,-1,17.93,0,-1,18.84,0,-1,18.92,0,-1,ARL,0
2025-07-17T13:28:46.022262428Z,2025-07-17T13:28:46.022095254Z,10,2,1108,A,B,10,10.050000000,700,41375793,167174,26616844,10.18,700,1,10.05,700,1,9.99,200,2,9.84,100,1,9.79,100,1,9.67,200,2,9.29,700,1,9.13,100,1,8.74,100,1,7.84,100,1,15.30,0,-1,16.38,0,-2,16.83,0,-2,17.36,0,-3,17.44,0,-4,17.60,0,-1,17.85,0,-1,17.93,0,-1,18.84,0,-1,18.92,0,-1,ARL,0
2025-07-17T13:28:46.022988063Z,2025-07-17T13:28:46.022822832Z,10,2,1108,A,A,10,16.300000000,700,41375973,165231,26617168,10.18,700,1,10.05,700,1,9.99,200,2,9.84,100,1,9.79,100,1,9.67,200,2,9.29,700,1,9.13,100,1,8.74,100,1,7.84,100,1,15.30,0,-1,16.38,0,-2,16.83,0,-2,17.36,0,-3,17.44,0,-4,17.60,0,-1,17.85,0,-1,17.93,0,-1,18.84,0,-1,18.92,0,-1,ARL,0
2025-07-17T13:28:46.025981579Z,2025-07-17T13:28:46.025816567Z,10,2,1108,A,B,10,11.760000000,100,41376297,165012,26618403,11.76,100,1,10.18,700,1,10.05,700,1,9.99,200,2,9.84,100,1,9.79,100,1,9.67,200,2,9.29,700,1,9.13,100,1,8.74,100,1,15.30,0,-1,16.38,0,-2,16.83,0,-2,17.36,0,-3,17.44,0,-4,17.60,0,-1,17.85,0,-1,17.93,0,-1,18.84,0,-1,18.92,0,-1,ARL,0
2025-07-17T13:28:46.026037162Z,2025-07-17T13:28:46.025870563Z,10,2,1108,C,B,10,7.740000000,100,23616197,166599,26618436,10.18,700,1,10.05,700,1,9.99,200,2,9.84,100,1,9.79,100,1,9.67,200,2,9.29,700,1,9.13,100,1,8.74,100,1,7.84,100,1,15.30,0,-1,16.38,0,-2,16.83,0,-2,17.36,0,-3,17.44,0,-4,17.60,0,-1,17.85,0,-1,17.93,0,-1,18.84,0,-1,18.92,0,-1,ARL,0
2025-07-17T13:28:46.026037162Z,2025-07-17T13:28:46.025870563Z,10,2,1108,A,B,10,8.470000000,100,41376333,166599,26618436,10.18,700,1,10.05,700,1,9.99,200,2,9.84,100,1,9.79,100,1,9.67,200,2,9.29,700,1,9.13,100,1,8.74,100,1,8.47,100,1,15.30,0,-1,16.38,0,-2,16.83,0,-2,17.36,0,-3,17.44,0,-4,17.60,0,-1,17.85,0,-1,17.93,0,-1,18.84,0,-1,18.92,0,-1,ARL,0
2025-07-17T13:28:46.026038058Z,2025-07-17T13:28:46.025872146Z,10,2,1108,C,B,10,7.740000000,100,23622101,165912,26618438,10.18,700,1,10.05,700,1,9.99,200,2,9.84,100,1,9.79,100,1,9.67,200,2,9.29,700,1,9.13,100,1,8.74,100,1,7.84,100,1,15.30,0,-1,16.38,0,-2,16.83,0,-2,17.36,0,-3,17.44,0,-4,17.60,0,-1,17.85,0,-1,17.93,0,-1,18.84,0,-1,18.92,0,-1,ARL,0
2025-07-17T13:28:46.026038058Z,2025-07-17T13:28:46.025872146Z,10,2,1108,A,B,10,8.470000000,100,41376337,165912,26618438,10.18,700,1,10.05,700,1,9.99,200,2,9.84,100,1,9.79,100,1,9.67,200,2,9.29,700,1,9.13,100,1,8.74,100,1,8.47,100,1,15.30,0,-1,16.38,0,-2,16.83,0,-2,17.36,0,-3,17.44,0,-4,17.60,0,-1,17.85,0,-1,17.93,0,-1,18.84,0,-1,18.92,0,-1,ARL,0
2025-07-17T13:28:46.026039687Z,2025-07-17T13:28:46.025873388Z,10,2,1108,C,B,10,7.740000000,100,24102329,166299,26618439,10.18,700,1,10.05,700,1,9.99,200,2,9.84,100,1,9.79,100,1,9.67,200,2,9.29,700,1,9.13,100,1,8.74,100,1,7.84,100,1,15.30,0,-1,16.38,0,-2,16.83,0,-2,17.36,0,-3,17.44,0,-4,17.60,0,-1,17.85,0,-1,17.93,0,-1,18.84,0,-1,18.92,0,-1,ARL,0
2025-07-17T13:28:46.026039687Z,2025-07-17T13:28:46.025873388Z,10,2,1108,A,B,10,8.470000000,100,41376341,166299,26618439,10.18,700,1,10.05,700,1,9.99,200,2,9.84,100,1,9.79,100,1,9.67,200,2,9.29,700,1,9.13,100,1,8.74,100,1,8.47,100,1,15.30,0,-1,16.38,0,-2,16.83,0,-2,17.36,0,-3,17.44,0,-4,17.60,0,-1,17.85,0,-1,17.93,0,-1,18.84,0,-1,18.92,0,-1,ARL,0
2025-07-17T13:28:46.026045679Z,2025-07-17T13:28:46.025874774Z,10,2,1108,C,B,10,7.740000000,100,31960841,170905,26618441,10.18,700,1,10.05,700,1,9.99,200,2,9.84,100,1,9.79,100,1,9.67,200,2,9.29,700,1,9.13,100,1,8.74,100,1,7.84,100,1,15.30,0,-1,16.38,0,-2,16.83,0,-2,17.36,0,-3,17.44,0,-4,17.60,0,-1,17.85,0,-1,17.93,0,-1,18.84,0,-1,18.92,0,-1,ARL,0
2025-07-17T13:28:46.026045679Z,2025-07-17T13:28:46.025874774Z,10,2,1108,A,B,10,8.470000000,100,41376345,170905,26618441,10.18,700,1,10.05,700,1,9.99,200,2,9.84,100,1,9.79,100,1,9.67,200,2,9.29,700,1,9.13,100,1,8.74,100,1,8.47,100,1,15.30,0,-1,16.38,0,-2,16.83,0,-2,17.36,0,-3,17.44,0,-4,17.60,0,-1,17.85,0,-1,17.93,0,-1,18.84,0,-1,18.92,0,-1,ARL,0
2025-07-17T13:28:46.026045679Z,2025-07-17T13:28:46.025875041Z,10,2,1108,C,B,10,7.740000000,100,33574717,170638,26618442,10.18,700,1,10.05,700,1,9.99,200,2,9.84,100,1,9.79,100,1,9.67,200,2,9.29,700,1,9.13,100,1,8.74,100,1,7.84,100,1,15.30,0,-1,16.38,0,-2,16.83,0,-2,17.36,0,-3,17.44,0,-4,17.60,0,-1,17.85,0,-1,17.93,0,-1,18.84,0,-1,18.92,0,-1,ARL,0
2025-07-17T13:28:46.026045679Z,2025-07-17T13:28:46.025875041Z,10,2,1108,A,B,10,8.470000000,100,41376349,170638,26618442,10.18,700,1,10.05,700,1,9.99,200,2,9.84,100,1,9.79,100,1,9.67,200,2,9.29,700,1,9.13,100,1,8.74,100,1,8.47,100,1,15.30,0,-1,16.38,0,-2,16.83,0,-2,17.36,0,-3,17.44,0,-4,17.60,0,-1,17.85,0,-1,17.93,0,-1,18.84,0,-1,18.92,0,-1,ARL,0
2025-07-17T13:28:46.026045679Z,2025-07-17T13:28:46.025875401Z,10,2,1108,C,B,10,7.740000000,100,38041417,170278,26618443,10.18,700,1,10.05,700,1,9.99,200,2,9.84,100,1,9.79,100,1,9.67,200,2,9.29,700,1,9.13,100,1,8.74,100,1,7.84,100,1,15.30,0,-1,16.38,0,-2,16.83,0,-2,17.36,0,-3,17.44,0,-4,17.60,0,-1,17.85,0,-1,17.93,0,-1,18.84,0,-1,18.92,0,-1,ARL,0
2025-07-17T13:28:46.026045679Z,2025-07-17T13:28:46.025875401Z,10,2,1108,A,B,10,8.470000000,100,41376353,170278,26618443,10.18,700,1,10.05,700,1,9.99,200,2,9.84,100,1,9.79,100,1,9.67,200,2,9.29,700,1,9.13,100,1,8.74,100,1,8.47,100,1,15.30,0,-1,16.38,0,-2,16.83,0,-2,17.36,0,-3,17.44,0,-4,17.60,0,-1,17.85,0,-1,17.93,0,-1,18.84,0,-1,18.92,0,-1,ARL,0
2025-07-17T13:28:46.026045679Z,2025-07-17T13:28:46.025877502Z,10,2,1108,C,B,10,7.740000000,100,40617777,168177,26618447,10.18,700,1,10.05,700,1,9.99,200,2,9.84,100,1,9.79,100,1,9.67,200,2,9.29,700,1,9.13,100,1,8.74,100,1,7.84,100,1,15.30,0,-1,16.38,0,-2,16.83,0,-2,17.36,0,-3,17.44,0,-4,17.60,0,-1,17.85,0,-1,17.93,0,-1,18.84,0,-1,18.92,0,-1,ARL,0
2025-07-17T13:28:46.026045679Z,2025-07-17T13:28:46.025877502Z,10,2,1108,A,B,10,8.470000000,100,41376357,168177,26618447,10.18,700,1,10.05,700,1,9.99,200,2,9.84,100,1,9.79,100,1,9.67,200,2,9.29,700,1,9.13,100,1,8.74,100,1,8.47,100,1,15.30,0,-1,16.38,0,-2,16.83,0,-2,17.36,0,-3,17.44,0,-4,17.60,0,-1,17.85,0,-1,17.93,0,-1,18.84,0,-1,18.92,0,-1,ARL,0
2025-07-17T13:28:46.027725683Z,2025-07-17T13:28:46.027560174Z,10,2,1108,C,B,10,9.990000000,100,41000165,165509,26619144,10.18,700,1,10.05,700,1,9.99,200,2,9.84,100,1,9.79,100,1,9.67,200,2,9.29,700,1,9.13,100,1,8.74,100,1,7.84,100,1,15.30,0,-1,16.38,0,-2,16.83,0,-2,17.36,0,-3,17.44,0,-4,17.60,0,-1,17.85,0,-1,17.93,0,-1,18.84,0,-1,18.92,0,-1,ARL,0
2025-07-17T13:28:46.027725683Z,2025-07-17T13:28:46.027560174Z,10,2,1108,A,B,10,10.930000000,100,41376501,165509,26619144,10.93,100,1,10.18,700,1,10.05,700,1,9.99,200,2,9.84,100,1,9.79,100,1,9.67,200,2,9.29,700,1,9.13,100,1,8.74,100,1,15.30,0,-1,16.38,0,-2,16.83,0,-2,17.36,0,-3,17.44,0,-4,17.60,0,-1,17.85,0,-1,17.93,0,-1,18.84,0,-1,18.92,0,-1,ARL,0
2025-07-17T13:28:46.029726785Z,2025-07-17T13:28:46.029556957Z,10,2,1108,C,B,10,9.670000000,100,40999441,169828,26619966,10.18,700,1,10.05,700,1,9.99,200,2,9.84,100,1,9.79,100,1,9.67,200,2,9.29,700,1,9.13,100,1,8.74,100,1,7.84,100,1,15.30,0,-1,16.38,0,-2,16.83,0,-2,17.36,0,-3,17.44,0,-4,17.60,0,-1,17.85,0,-1,17.93,0,-1,18.84,0,-1,18.92,0,-1,ARL,0
2025-07-17T13:28:46.029726785Z,2025-07-17T13:28:46.029556957Z,10,2,1108,A,B,10,10.580000000,100,41376725,169828,26619966,10.58,100,1,10.18,700,1,10.05,700,1,9.99,200,2,9.84,100,1,9.79,100,1,9.67,200,2,9.29,700,1,9.13,100,1,8.74,100,1,15.30,0,-1,16.38,0,-2,16.83,0,-2,17.36,0,-3,17.44,0,-4,17.60,0,-1,17.85,0,-1,17.93,0,-1,18.84,0,-1,18.92,0,-1,ARL,0
2025-07-17T13:28:46.029775250Z,2025-07-17T13:28:46.029609064Z,10,2,1108,C,B,10,7.840000000,100,41306441,166186,26619999,10.18,700,1,10.05,700,1,9.99,200,2,9.84,100,1,9.79,100,1,9.67,200,2,9.29,700,1,9.13,100,1,8.74,100,1,7.84,100,1,15.30,0,-1,16.38,0,-2,16.83,0,-2,17.36,0,-3,17.44,0,-4,17.60,0,-1,17.85,0,-1,17.93,0,-1,18.84,0,-1,18.92,0,-1,ARL,0
2025-07-17T13:28:46.029775250Z,2025-07-17T13:28:46.029609064Z,10,2,1108,A,B,10,8.580000000,100,41376733,166186,26619999,10.18,700,1,10.05,700,1,9.99,200,2,9.84,100,1,9.79,100,1,9.67,200,2,9.29,700,1,9.13,100,1,8.74,100,1,8.58,100,1,15.30,0,-1,16.38,0,-2,16.83,0,-2,17.36,0,-3,17.44,0,-4,17.60,0,-1,17.85,0,-1,17.93,0,-1,18.84,0,-1,18.92,0,-1,ARL,0
2025-07-17T13:28:46.031239452Z,2025-07-17T13:28:46.031073916Z,10,2,1108,C,B,10,9.130000000,100,41032049,165536,26620530,10.18,700,1,10.05,700,1,9.99,200,2,9.84,100,1,9.79,100,1,9.67,200,2,9.29,700,1,9.13,100,1,8.74,100,1,7.84,100,1,15.30,0,-1,16.38,0,-2,16.83,0,-2,17.36,0,-3,17.44,0,-4,17.60,0,-1,17.85,0,-1,17.93,0,-1,18.84,0,-1,18.92,0,-1,ARL,0
2025-07-17T13:28:46.031239452Z,2025-07-17T13:28:46.031073916Z,10,2,1108,A,B,10,9.990000000,100,41376769,165536,26620530,10.18,700,1,10.05,700,1,9.99,300,3,9.84,100,1,9.79,100,1,9.67,200,2,9.29,700,1,9.13,100,1,8.74,100,1,7.84,100,1,15.30,0,-1,16.38,0,-2,16.83,0,-2,17.36,0,-3,17.44,0,-4,17.60,0,-1,17.85,0,-1,17.93,0,-1,18.84,0,-1,18.92,0,-1,ARL,0
2025-07-17T13:28:46.038120992Z,2025-07-17T13:28:46.037954661Z,10,2,1108,C,B,10,9.670000000,100,41021369,166331,26623213,10.18,700,1,10.05,700,1,9.99,200,2,9.84,100,1,9.79,100,1,9.67,200,2,9.29,700,1,9.13,100,1,8.74,100,1,7.84,100,1,15.30,0,-1,16.38,0,-2,16.83,0,-2,17.36,0,-3,17.44,0,-4,17.60,0,-1,17.85,0,-1,17.93,0,-1,18.84,0,-1,18.92,0,-1,ARL,0
2025-07-17T13:28:46.038120992Z,2025-07-17T13:28:46.037954661Z,10,2,1108,A,B,10,10.580000000,100,41377117,166331,26623213,10.58,100,1,10.18,700,1,10.05,700,1,9.99,200,2,9.84,100,1,9.79,100,1,9.67,200,2,9.29,700,1,9.13,100,1,8.74,100,1,15.30,0,-1,16.38,0,-2,16.83,0,-2,17.36,0,-3,17.44,0,-4,17.60,0,-1,17.85,0,-1,17.93,0,-1,18.84,0,-1,18.92,0,-1,ARL,0
2025-07-17T13:28:46.043024422Z,2025-07-17T13:28:46.042858782Z,10,2,1108,C,B,10,9.990000000,100,41021837,165640,26625366,10.18,700,1,10.05,700,1,9.99,200,2,9.84,100,1,9.79,100,1,9.67,200,2,9.29,700,1,9.13,100,1,8.74,100,1,7.84,100,1,15.30,0,-1,16.38,0,-2,16.83,0,-2,17.36,0,-3,17.44,0,-4,17.60,0,-1,17.85,0,-1,17.93,0,-1,18.84,0,-1,18.92,0,-1,ARL,0
2025-07-17T13:28:46.043024422Z,2025-07-17T13:28:46.042858782Z,10,2,1108,A,B,10,10.930000000,100,41379985,165640,26625366,10.93,100,1,10.18,700,1,10.05,700,1,9.99,200,2,9.84,100,1,9.79,100,1,9.67,200,2,9.29,700,1,9.13,100,1,8.74,100,1,15.30,0,-1,16.38,0,-2,16.83,0,-2,17.36,0,-3,17.44,0,-4,17.60,0,-1,17.85,0,-1,17.93,0,-1,18.84,0,-1,18.92,0,-1,ARL,0
2025-07-17T13:28:52.312460374Z,2025-07-17T13:28:52.312295020Z,10,2,1108,A,B,10,10.750000000,700,41507073,165354,26806665,10.93,100,1,10.75,700,1,10.18,700,1,10.05,700,1,9.99,200,2,9.84,100,1,9.79,100,1,9.67,200,2,9.29,700,1,9.13,100,1,15.30,0,-1,16.38,0,-2,16.83,0,-2,17.36,0,-3,17.44,0,-4,17.60,0,-1,17.85,0,-1,17.93,0,-1,18.84,0,-1,18.92,0,-1,ARL,0
2025-07-17T13:28:52.312496032Z,2025-07-17T13:28:52.312330796Z,10,2,1108,C,B,10,10.050000000,700,41375793,165236,26806666,10.93,100,1,10.18,700,1,10.05,700,1,9.99,200,2,9.84,100,1,9.79,100,1,9.67,200,2,9.29,700,1,9.13,100,1,8.74,100,1,15.30,0,-1,16.38,0,-2,16.83,0,-2,17.36,0,-3,17.44,0,-4,17.60,0,-1,17.85,0,-1,17.93,0,-1,18.84,0,-1,18.92,0,-1,ARL,0
2025-07-17T13:28:52.512457909Z,2025-07-17T13:28:52.512292648Z,10,2,1108,A,B,10,10.990000000,700,41509393,165261,26808221,10.99,700,1,10.93,100,1,10.18,700,1,10.05,700,1,9.99,200,2,9.84,100,1,9.79,100,1,9.67,200,2,9.29,700,1,9.13,100,1,15.30,0,-1,16.38,0,-2,16.83,0,-2,17.36,0,-3,17.44,0,-4,17.60,0,-1,17.85,0,-1,17.93,0,-1,18.84,0,-1,18.92,0,-1,ARL,0
2025-07-17T13:28:52.513255552Z,2025-07-17T13:28:52.513090520Z,10,2,1108,C,B,10,10.750000000,700,41507073,165032,26808222,10.93,100,1,10.18,700,1,10.05,700,1,9.99,200,2,9.84,100,1,9.79,100,1,9.67,200,2,9.29,700,1,9.13,100,1,8.74,100,1,15.30,0,-1,16.38,0,-2,16.83,0,-2,17.36,0,-3,17.44,0,-4,17.60,0,-1,17.85,0,-1,17.93,0,-1,18.84,0,-1,18.92,0,-1,ARL,0
2025-07-17T13:28:53.957233148Z,2025-07-17T13:28:53.957067631Z,10,2,1108,A,A,10,16.150000000,700,41528029,165517,26835971,10.93,100,1,10.18,700,1,10.05,700,1,9.99,200,2,9.84,100,1,9.79,100,1,9.67,200,2,9.29,700,1,9.13,100,1,8.74,100,1,15.30,0,-1,16.38,0,-2,16.83,0,-2,17.36,0,-3,17.44,0,-4,17.60,0,-1,17.85,0,-1,17.93,0,-1,18.84,0,-1,18.92,0,-1,ARL,0
2025-07-17T13:28:53.957281517Z,2025-07-17T13:28:53.957116061Z,10,2,1108,C,A,10,18.320000000,700,40846101,165456,26835974,10.93,100,1,10.18,700,1,10.05,700,1,9.99,200,2,9.84,100,1,9.79,100,1,9.67,200,2,9.29,700,1,9.13,100,1,8.74,100,1,15.30,0,-1,16.15,0,-1,16.38,0,-2,16.83,0,-2,17.36,0,-3,17.44,0,-4,17.60,0,-1,17.85,0,-1,17.93,0,-1,18.84,0,-1,ARL,0
2025-07-17T13:28:54.128476219Z,2025-07-17T13:28:54.128310778Z,10,2,1108,A,B,10,9.990000000,700,41530665,165441,26850111,10.93,100,1,10.18,700,1,10.05,700,1,9.99,900,3,9.84,100,1,9.79,100,1,9.67,200,2,9.29,700,1,9.13,100,1,8.74,100,1,15.30,0,-1,16.15,0,-1,16.38,0,-2,16.83,0,-2,17.36,0,-3,17.44,0,-4,17.60,0,-1,17.85,0,-1,17.93,0,-1,18.84,0,-1,ARL,0
2025-07-17T13:28:54.128503934Z,2025-07-17T13:28:54.128338727Z,10,2,1108,C,B,10,9.290000000,700,40851989,165207,26850112,10.93,100,1,10.18,700,1,10.05,700,1,9.99,200,2,9.84,100,1,9.79,100,1,9.67,200,2,9.29,700,1,9.13,100,1,8.74,100,1,15.30,0,-1,16.15,0,-1,16.38,0,-2,16.83,0,-2,17.36,0,-3,17.44,0,-4,17.60,0,-1,17.85,0,-1,17.93,0,-1,18.84,0,-1,ARL,0
2025-07-17T13:28:54.328652337Z,2025-07-17T13:28:54.328487063Z,10,2,1108,A,B,10,10.260000000,700,41533513,165274,26851888,10.93,100,1,10.26,700,1,10.18,700,1,10.05,700,1,9.99,200,2,9.84,100,1,9.79,100,1,9.67,200,2,9.29,700,1,9.13,100,1,15.30,0,-1,16.15,0,-1,16.38,0,-2,16.83,0,-2,17.36,0,-3,17.44,0,-4,17.60,0,-1,17.85,0,-1,17.93,0,-1,18.84,0,-1,ARL,0
2025-07-17T13:28:54.328684086Z,2025-07-17T13:28:54.328519057Z,10,2,1108,C,B,10,9.990000000,700,41530665,165029,26851889,10.93,100,1,10.18,700,1,10.05,700,1,9.99,200,2,9.84,100,1,9.79,100,1,9.67,200,2,9.29,700,1,9.13,100,1,8.74,100,1,15.30,0,-1,16.15,0,-1,16.38,0,-2,16.83,0,-2,17.36,0,-3,17.44,0,-4,17.60,0,-1,17.85,0,-1,17.93,0,-1,18.84,0,-1,ARL,0
2025-07-17T13:28:54.477620754Z,2025-07-17T13:28:54.477455479Z,10,2,1108,A,B,10,11.140000000,700,41534785,165275,26853475,11.14,700,1,10.93,100,1,10.18,700,1,10.05,700,1,9.99,200,2,9.84,100,1,9.79,100,1,9.67,200,2,9.29,700,1,9.13,100,1,15.30,0,-1,16.15,0,-1,16.38,0,-2,16.83,0,-2,17.36,0,-3,17.44,0,-4,17.60,0,-1,17.85,0,-1,17.93,0,-1,18.84,0,-1,ARL,0
2025-07-17T13:28:54.478018001Z,2025-07-17T13:28:54.477852651Z,10,2,1108,C,B,10,10.180000000,700,41371221,165350,26853478,10.93,100,1,10.18,700,1,10.05,700,1,9.99,200,2,9.84,100,1,9.79,100,1,9.67,200,2,9.29,700,1,9.13,100,1,8.74,100,1,15.30,0,-1,16.15,0,-1,16.38,0,-2,16.83,0,-2,17.36,0,-3,17.44,0,-4,17.60,0,-1,17.85,0,-1,17.93,0,-1,18.84,0,-1,ARL,0
2025-07-17T13:28:54.528708243Z,2025-07-17T13:28:54.528542919Z,10,2,1108,A,B,10,10.530000000,700,41535173,165324,26853925,10.93,100,1,10.53,700,1,10.18,700,1,10.05,700,1,9.99,200,2,9.84,100,1,9.79,100,1,9.67,200,2,9.29,700,1,9.13,100,1,15.30,0,-1,16.15,0,-1,16.38,0,-2,16.83,0,-2,17.36,0,-3,17.44,0,-4,17.60,0,-1,17.85,0,-1,17.93,0,-1,18.84,0,-1,ARL,0
2025-07-17T13:28:54.528736554Z,2025-07-17T13:28:54.528571375Z,10,2,1108,C,B,10,10.260000000,700,41533513,165179,26853926,10.93,100,1,10.18,700,1,10.05,700,1,9.99,200,2,9.84,100,1,9.79,100,1,9.67,200,2,9.29,700,1,9.13,100,1,8.74,100,1,15.30,0,-1,16.15,0,-1,16.38,0,-2,16.83,0,-2,17.36,0,-3,17.44,0,-4,17.60,0,-1,17.85,0,-1,17.93,0,-1,18.84,0,-1,ARL,0
2025-07-17T13:28:54.728740313Z,2025-07-17T13:28:54.728575124Z,10,2,1108,A,B,10,10.800000000,700,41537525,165189,26856081,10.93,100,1,10.80,700,1,10.18,700,1,10.05,700,1,9.99,200,2,9.84,100,1,9.79,100,1,9.67,200,2,9.29,700,1,9.13,100,1,15.30,0,-1,16.15,0,-1,16.38,0,-2,16.83,0,-2,17.36,0,-3,17.44,0,-4,17.60,0,-1,17.85,0,-1,17.93,0,-1,18.84,0,-1,ARL,0
2025-07-17T13:28:54.728816275Z,2025-07-17T13:28:54.728651317Z,10,2,1108,C,B,10,10.530000000,700,41535173,164958,26856082,10.93,100,1,10.18,700,1,10.05,700,1,9.99,200,2,9.84,100,1,9.79,100,1,9.67,200,2,9.29,700,1,9.13,100,1,8.74,100,1,15.30,0,-1,16.15,0,-1,16.38,0,-2,16.83,0,-2,17.36,0,-3,17.44,0,-4,17.60,0,-1,17.85,0,-1,17.93,0,-1,18.84,0,-1,ARL,0
2025-07-17T13:28:54.928577406Z,2025-07-17T13:28:54.928412211Z,10,2,1108,A,B,10,11.070000000,700,41539477,165195,26858349,11.07,700,1,10.93,100,1,10.18,700,1,10.05,700,1,9.99,200,2,9.84,100,1,9.79,100,1,9.67,200,2,9.29,700,1,9.13,100,1,15.30,0,-1,16.15,0,-1,16.38,0,-2,16.83,0,-2,17.36,0,-3,17.44,0,-4,17.60,0,-1,17.85,0,-1,17.93,0,-1,18.84,0,-1,ARL,0
2025-07-17T13:28:54.928653303Z,2025-07-17T13:28:54.928488170Z,10,2,1108,C,B,10,10.800000000,700,41537525,165133,26858351,10.93,100,1,10.18,700,1,10.05,700,1,9.99,200,2,9.84,100,1,9.79,100,1,9.67,200,2,9.29,700,1,9.13,100,1,8.74,100,1,15.30,0,-1,16.15,0,-1,16.38,0,-2,16.83,0,-2,17.36,0,-3,17.44,0,-4,17.60,0,-1,17.85,0,-1,17.93,0,-1,18.84,0,-1,ARL,0
2025-07-17T13:29:00.583276463Z,2025-07-17T13:29:00.583110843Z,10,2,1108,A,B,10,10.840000000,100,41635065,165620,27000961,10.93,100,1,10.84,100,1,10.18,700,1,10.05,700,1,9.99,200,2,9.84,100,1,9.79,100,1,9.67,200,2,9.29,700,1,9.13,100,1,15.30,0,-1,16.15,0,-1,16.38,0,-2,16.83,0,-2,17.36,0,-3,17.44,0,-4,17.60,0,-1,17.85,0,-1,17.93,0,-1,18.84,0,-1,ARL,0
2025-07-17T13:29:00.583289800Z,2025-07-17T13:29:00.583124331Z,10,2,1108,A,A,10,16.490000000,100,41635069,165469,27000962,10.93,100,1,10.84,100,1,10.18,700,1,10.05,700,1,9.99,200,2,9.84,100,1,9.79,100,1,9.67,200,2,9.29,700,1,9.13,100,1,15.30,0,-1,16.15,0,-1,16.38,0,-2,16.83,0,-2,17.36,0,-3,17.44,0,-4,17.60,0,-1,17.85,0,-1,17.93,0,-1,18.84,0,-1,ARL,0
2025-07-17T13:29:31.666650984Z,2025-07-17T13:29:31.666485583Z,10,2,1108,A,B,10,11.050000000,100,42089321,165401,27592251,11.05,100,1,10.93,100,1,10.84,100,1,10.18,700,1,10.05,700,1,9.99,200,2,9.84,100,1,9.79,100,1,9.67,200,2,9.29,700,1,15.30,0,-1,16.15,0,-1,16.38,0,-2,16.83,0,-2,17.36,0,-3,17.44,0,-4,17.60,0,-1,17.85,0,-1,17.93,0,-1,18.84,0,-1,ARL,0
2025-07-17T13:29:31.666676040Z,2025-07-17T13:29:31.666510533Z,10,2,1108,A,A,10,16.220000000,100,42089325,165507,27592252,11.05,100,1,10.93,100,1,10.84,100,1,10.18,700,1,10.05,700,1,9.99,200,2,9.84,100,1,9.79,100,1,9.67,200,2,9.29,700,1,15.30,0,-1,16.15,0,-1,16.38,0,-2,16.83,0,-2,17.36,0,-3,17.44,0,-4,17.60,0,-1,17.85,0,-1,17.93,0,-1,18.84,0,-1,ARL,0
2025-07-17T13:29:32.011253336Z,2025-07-17T13:29:32.011088073Z,10,2,1108,A,B,10,11.290000000,100,42099317,165263,27599196,11.29,100,1,11.05,100,1,10.93,100,1,10.84,100,1,10.18,700,1,10.05,700,1,9.99,200,2,9.84,100,1,9.79,100,1,9.67,200,2,15.30,0,-1,16.15,0,-1,16.38,0,-2,16.83,0,-2,17.36,0,-3,17.44,0,-4,17.60,0,-1,17.85,0,-1,17.93,0,-1,18.84,0,-1,ARL,0
2025-07-17T13:29:32.011257301Z,2025-07-17T13:29:32.011092154Z,10,2,1108,A,A,10,15.910000000,100,42099321,165147,27599197,11.29,100,1,11.05,100,1,10.93,100,1,10.84,100,1,10.18,700,1,10.05,700,1,9.99,200,2,9.84,100,1,9.79,100,1,9.67,200,2,15.30,0,-1,16.15,0,-1,16.38,0,-2,16.83,0,-2,17.36,0,-3,17.44,0,-4,17.60,0,-1,17.85,0,-1,17.93,0,-1,18.84,0,-1,ARL,0
2025-07-17T13:29:39.840138413Z,2025-07-17T13:29:39.839973111Z,10,2,1108,A,B,10,8.470000000,100,42202297,165302,27759427,11.29,100,1,11.05,100,1,10.93,100,1,10.84,100,1,10.18,700,1,10.05,700,1,9.99,200,2,9.84,100,1,9.79,100,1,9.67,200,2,15.30,0,-1,16.15,0,-1,16.38,0,-2,16.83,0,-2,17.36,0,-3,17.44,0,-4,17.60,0,-1,17.85,0,-1,17.93,0,-1,18.84,0,-1,ARL,0
2025-07-17T13:29:40.000349567Z,2025-07-17T13:29:40.000183284Z,10,2,1108,A,A,10,19.580000000,100,42204681,166283,27760200,11.29,100,1,11.05,100,1,10.93,100,1,10.84,100,1,10.18,700,1,10.05,700,1,9.99,200,2,9.84,100,1,9.79,100,1,9.67,200,2,15.30,0,-1,16.15,0,-1,16.38,0,-2,16.83,0,-2,17.36,0,-3,17.44,0,-4,17.60,0,-1,17.85,0,-1,17.93,0,-1,18.84,0,-1,ARL,0
2025-07-17T13:29:55.529348997Z,2025-07-17T13:29:55.529183618Z,10,2,1108,A,B,10,11.520000000,100,42446497,165379,28123971,11.52,100,1,11.29,100,1,11.05,100,1,10.93,100,1,10.84,100,1,10.18,700,1,10.05,700,1,9.99,200,2,9.84,100,1,9.79,100,1,15.30,0,-1,16.15,0,-1,16.38,0,-2,16.83,0,-2,17.36,0,-3,17.44,0,-4,17.60,0,-1,17.85,0,-1,17.93,0,-1,18.84,0,-1,ARL,0
2025-07-17T13:29:55.529365902Z,2025-07-17T13:29:55.529200619Z,10,2,1108,A,A,10,15.610000000,100,42446501,165283,28123973,11.52,100,1,11.29,100,1,11.05,100,1,10.93,100,1,10.84,100,1,10.18,700,1,10.05,700,1,9.99,200,2,9.84,100,1,9.79,100,1,15.30,0,-1,16.15,0,-1,16.38,0,-2,16.83,0,-2,17.36,0,-3,17.44,0,-4,17.60,0,-1,17.85,0,-1,17.93,0,-1,18.84,0,-1,ARL,0
2025-07-17T13:29:59.677450683Z,2025-07-17T13:29:59.677285294Z,10,2,1108,A,B,10,10.110000000,100,42583289,165389,28321241,11.52,100,1,11.29,100,1,11.05,100,1,10.93,100,1,10.84,100,1,10.18,700,1,10.11,100,1,10.05,700,1,9.99,200,2,9.84,100,1,15.30,0,-1,16.15,0,-1,16.38,0,-2,16.83,0,-2,17.36,0,-3,17.44,0,-4,17.60,0,-1,17.85,0,-1,17.93,0,-1,18.84,0,-1,ARL,0
2025-07-17T13:29:59.677457187Z,2025-07-17T13:29:59.677290064Z,10,2,1108,A,A,10,17.450000000,100,42583293,167123,28321242,11.52,100,1,11.29,100,1,11.05,100,1,10.93,100,1,10.84,100,1,10.18,700,1,10.11,100,1,10.05,700,1,9.99,200,2,9.84,100,1,15.30,0,-1,16.15,0,-1,16.38,0,-2,16.83,0,-2,17.36,0,-3,17.44,0,-4,17.60,0,-1,17.85,0,-1,17.93,0,-1,18.84,0,-1,ARL,0
2025-07-17T13:30:00.093085479Z,2025-07-17T13:30:00.092900330Z,10,2,1108,A,B,10,11.010000000,100,42674817,185149,28409476,11.52,100,1,11.29,100,1,11.05,100,1,11.01,100,1,10.93,100,1,10.84,100,1,10.18,700,1,10.11,100,1,10.05,700,1,9.99,200,2,15.30,0,-1,16.15,0,-1,16.38,0,-2,16.83,0,-2,17.36,0,-3,17.44,0,-4,17.60,0,-1,17.85,0,-1,17.93,0,-1,18.84,0,-1,ARL,0
2025-07-17T13:30:00.093164566Z,2025-07-17T13:30:00.092988904Z,10,2,1108,A,A,10,16.100000000,100,42674989,175662,28409593,11.52,100,1,11.29,100,1,11.05,100,1,11.01,100,1,10.93,100,1,10.84,100,1,10.18,700,1,10.11,100,1,10.05,700,1,9.99,200,2,15.30,0,-1,16.15,0,-1,16.38,0,-2,16.83,0,-2,17.36,0,-3,17.44,0,-4,17.60,0,-1,17.85,0,-1,17.93,0,-1,18.84,0,-1,ARL,0
2025-07-17T13:30:00.412816741Z,2025-07-17T13:30:00.412637542Z,10,2,1108,A,A,10,19.580000000,100,42946053,179199,28676200,11.52,100,1,11.29,100,1,11.05,100,1,11.01,100,1,10.93,100,1,10.84,100,1,10.18,700,1,10.11,100,1,10.05,700,1,9.99,200,2,15.30,0,-1,16.15,0,-1,16.38,0,-2,16.83,0,-2,17.36,0,-3,17.44,0,-4,17.60,0,-1,17.85,0,-1,17.93,0,-1,18.84,0,-1,ARL,0
2025-07-17T13:30:00.422103919Z,2025-07-17T13:30:00.421937186Z,10,2,1108,A,B,10,8.470000000,100,42951397,166733,28680759,11.52,100,1,11.29,100,1,11.05,100,1,11.01,100,1,10.93,100,1,10.84,100,1,10.18,700,1,10.11,100,1,10.05,700,1,9.99,200,2,15.30,0,-1,16.15,0,-1,16.38,0,-2,16.83,0,-2,17.36,0,-3,17.44,0,-4,17.60,0,-1,17.85,0,-1,17.93,0,-1,18.84,0,-1,ARL,0
2025-07-17T13:30:00.675725361Z,2025-07-17T13:30:00.675553569Z,10,2,1108,A,B,10,10.920000000,100,43143317,171792,28833560,11.52,100,1,11.29,100,1,11.05,100,1,11.01,100,1,10.93,100,1,10.92,100,1,10.84,100,1,10.18,700,1,10.11,100,1,10.05,700,1,15.30,0,-1,16.15,0,-1,16.38,0,-2,16.83,0,-2,17.36,0,-3,17.44,0,-4,17.60,0,-1,17.85,0,-1,17.93,0,-1,18.84,0,-1,ARL,0
2025-07-17T13:30:00.675748539Z,2025-07-17T13:30:00.675570319Z,10,2,1108,A,A,10,16.200000000,100,43143333,178220,28833574,11.52,100,1,11.29,100,1,11.05,100,1,11.01,100,1,10.93,100,1,10.92,100,1,10.84,100,1,10.18,700,1,10.11,100,1,10.05,700,1,15.30,0,-1,16.15,0,-1,16.38,0,-2,16.83,0,-2,17.36,0,-3,17.44,0,-4,17.60,0,-1,17.85,0,-1,17.93,0,-1,18.84,0,-1,ARL,0
2025-07-17T13:30:00.730859228Z,2025-07-17T13:30:00.730688348Z,10,2,1108,A,B,10,10.920000000,100,43191333,170880,28858298,11.52,100,1,11.29,100,1,11.05,100,1,11.01,100,1,10.93,100,1,10.92,200,2,10.84,100,1,10.18,700,1,10.11,100,1,10.05,700,1,15.30,0,-1,16.15,0,-1,16.38,0,-2,16.83,0,-2,17.36,0,-3,17.44,0,-4,17.60,0,-1,17.85,0,-1,17.93,0,-1,18.84,0,-1,ARL,0
2025-07-17T13:30:00.730867405Z,2025-07-17T13:30:00.730693126Z,10,2,1108,A,A,10,16.200000000,100,43191369,174279,28858300,11.52,100,1,11.29,100,1,11.05,100,1,11.01,100,1,10.93,100,1,10.92,200,2,10.84,100,1,10.18,700,1,10.11,100,1,10.05,700,1,15.30,0,-1,16.15,0,-1,16.38,0,-2,16.83,0,-2,17.36,0,-3,17.44,0,-4,17.60,0,-1,17.85,0,-1,17.93,0,-1,18.84,0,-1,ARL,0
2025-07-17T13:30:00.869893365Z,2025-07-17T13:30:00.869714108Z,10,2,1108,A,B,10,9.410000000,100,43313553,179257,28963643,11.52,100,1,11.29,100,1,11.05,100,1,11.01,100,1,10.93,100,1,10.92,200,2,10.84,100,1,10.18,700,1,10.11,100,1,10.05,700,1,15.30,0,-1,16.15,0,-1,16.38,0,-2,16.83,0,-2,17.36,0,-3,17.44,0,-4,17.60,0,-1,17.85,0,-1,17.93,0,-1,18.84,0,-1,ARL,0
2025-07-17T13:30:00.869893365Z,2025-07-17T13:30:00.869715708Z,10,2,1108,A,A,10,18.360000000,100,43313565,177657,28963646,11.52,100,1,11.29,100,1,11.05,100,1,11.01,100,1,10.93,100,1,10.92,200,2,10.84,100,1,10.18,700,1,10.11,100,1,10.05,700,1,15.30,0,-1,16.15,0,-1,16.38,0,-2,16.83,0,-2,17.36,0,-3,17.44,0,-4,17.60,0,-1,17.85,0,-1,17.93,0,-1,18.84,0,-1,ARL,0
2025-07-17T13:30:00.869922678Z,2025-07-17T13:30:00.869746905Z,10,2,1108,A,A,10,18.360000000,100,43313633,175773,28963685,11.52,100,1,11.29,100,1,11.05,100,1,11.01,100,1,10.93,100,1,10.92,200,2,10.84,100,1,10.18,700,1,10.11,100,1,10.05,700,1,15.30,0,-1,16.15,0,-1,16.38,0,-2,16.83,0,-2,17.36,0,-3,17.44,0,-4,17.60,0,-1,17.85,0,-1,17.93,0,-1,18.84,0,-1,ARL,0
2025-07-17T13:30:00.869941215Z,2025-07-17T13:30:00.869768981Z,10,2,1108,A,B,10,9.410000000,100,43313681,172234,28963699,11.52,100,1,11.29,100,1,11.05,100,1,11.01,100,1,10.93,100,1,10.92,200,2,10.84,100,1,10.18,700,1,10.11,100,1,10.05,700,1,15.30,0,-1,16.15,0,-1,16.38,0,-2,16.83,0,-2,17.36,0,-3,17.44,0,-4,17.60,0,-1,17.85,0,-1,17.93,0,-1,18.84,0,-1,ARL,0
2025-07-17T13:30:00.870056916Z,2025-07-17T13:30:00.869883482Z,10,2,1108,A,B,10,11.240000000,100,43313941,173434,28963823,11.52,100,1,11.29,100,1,11.24,100,1,11.05,100,1,11.01,100,1,10.93,100,1,10.92,200,2,10.84,100,1,10.18,700,1,10.11,100,1,15.30,0,-1,16.15,0,-1,16.38,0,-2,16.83,0,-2,17.36,0,-3,17.44,0,-4,17.60,0,-1,17.85,0,-1,17.93,0,-1,18.84,0,-1,ARL,0
2025-07-17T13:30:00.870086307Z,2025-07-17T13:30:00.869917271Z,10,2,1108,A,A,10,15.980000000,100,43314009,169036,28963843,11.52,100,1,11.29,100,1,11.24,100,1,11.05,100,1,11.01,100,1,10.93,100,1,10.92,200,2,10.84,100,1,10.18,700,1,10.11,100,1,15.30,0,-1,16.15,0,-1,16.38,0,-2,16.83,0,-2,17.36,0,-3,17.44,0,-4,17.60,0,-1,17.85,0,-1,17.93,0,-1,18.84,0,-1,ARL,0
2025-07-17T13:30:00.870161301Z,2025-07-17T13:30:00.869979897Z,10,2,1108,C,B,10,8.470000000,100,41376333,181404,28963935,11.52,100,1,11.29,100,1,11.24,100,1,11.05,100,1,11.01,100,1,10.93,100,1,10.92,200,2,10.84,100,1,10.18,700,1,10.11,100,1,15.30,0,-1,15.98,0,-1,16.15,0,-1,16.38,0,-2,16.83,0,-2,17.36,0,-3,17.44,0,-4,17.60,0,-1,17.85,0,-1,17.93,0,-1,ARL,0
2025-07-17T13:30:00.870161301Z,2025-07-17T13:30:00.869979897Z,10,2,1108,A,B,10,9.550000000,100,43314145,181404,28963935,11.52,100,1,11.29,100,1,11.24,100,1,11.05,100,1,11.01,100,1,10.93,100,1,10.92,200,2,10.84,100,1,10.18,700,1,10.11,100,1,15.30,0,-1,15.98,0,-1,16.15,0,-1,16.38,0,-2,16.83,0,-2,17.36,0,-3,17.44,0,-4,17.60,0,-1,17.85,0,-1,17.93,0,-1,ARL,0
2025-07-17T13:30:00.870161301Z,2025-07-17T13:30:00.869983764Z,10,2,1108,C,B,10,8.470000000,100,41376337,177537,28963938,11.52,100,1,11.29,100,1,11.24,100,1,11.05,100,1,11.01,100,1,10.93,100,1,10.92,200,2,10.84,100,1,10.18,700,1,10.11,100,1,15.30,0,-1,15.98,0,-1,16.15,0,-1,16.38,0,-2,16.83,0,-2,17.36,0,-3,17.44,0,-4,17.60,0,-1,17.85,0,-1,17.93,0,-1,ARL,0
2025-07-17T13:30:00.870161301Z,2025-07-17T13:30:00.869983764Z,10,2,1108,A,B,10,9.550000000,100,43314149,177537,28963938,11.52,100,1,11.29,100,1,11.24,100,1,11.05,100,1,11.01,100,1,10.93,100,1,10.92,200,2,10.84,100,1,10.18,700,1,10.11,100,1,15.30,0,-1,15.98,0,-1,16.15,0,-1,16.38,0,-2,16.83,0,-2,17.36,0,-3,17.44,0,-4,17.60,0,-1,17.85,0,-1,17.93,0,-1,ARL,0
2025-07-17T13:30:00.870165319Z,2025-07-17T13:30:00.869988740Z,10,2,1108,C,B,10,8.470000000,100,41376341,176579,28963943,11.52,100,1,11.29,100,1,11.24,100,1,11.05,100,1,11.01,100,1,10.93,100,1,10.92,200,2,10.84,100,1,10.18,700,1,10.11,100,1,15.30,0,-1,15.98,0,-1,16.15,0,-1,16.38,0,-2,16.83,0,-2,17.36,0,-3,17.44,0,-4,17.60,0,-1,17.85,0,-1,17.93,0,-1,ARL,0
2025-07-17T13:30:00.870165319Z,2025-07-17T13:30:00.869988740Z,10,2,1108,A,B,10,9.550000000,100,43314153,176579,28963943,11.52,100,1,11.29,100,1,11.24,100,1,11.05,100,1,11.01,100,1,10.93,100,1,10.92,200,2,10.84,100,1,10.18,700,1,10.11,100,1,15.30,0,-1,15.98,0,-1,16.15,0,-1,16.38,0,-2,16.83,0,-2,17.36,0,-3,17.44,0,-4,17.60,0,-1,17.85,0,-1,17.93,0,-1,ARL,0
2025-07-17T13:30:00.870165319Z,2025-07-17T13:30:00.869989204Z,10,2,1108,C,B,10,8.470000000,100,41376345,176115,28963944,11.52,100,1,11.29,100,1,11.24,100,1,11.05,100,1,11.01,100,1,10.93,100,1,10.92,200,2,10.84,100,1,10.18,700,1,10.11,100,1,15.30,0,-1,15.98,0,-1,16.15,0,-1,16.38,0,-2,16.83,0,-2,17.36,0,-3,17.44,0,-4,17.60,0,-1,17.85,0,-1,17.93,0,-1,ARL,0
2025-07-17T13:30:00.870165319Z,2025-07-17T13:30:00.869989204Z,10,2,1108,A,B,10,9.550000000,100,43314157,176115,28963944,11.52,100,1,11.29,100,1,11.24,100,1,11.05,100,1,11.01,100,1,10.93,100,1,10.92,200,2,10.84,100,1,10.18,700,1,10.11,100,1,15.30,0,-1,15.98,0,-1,16.15,0,-1,16.38,0,-2,16.83,0,-2,17.36,0,-3,17.44,0,-4,17.60,0,-1,17.85,0,-1,17.93,0,-1,ARL,0
2025-07-17T13:30:00.870174640Z,2025-07-17T13:30:00.869996105Z,10,2,1108,C,B,10,8.470000000,100,41376349,178535,28963952,11.52,100,1,11.29,100,1,11.24,100,1,11.05,100,1,11.01,100,1,10.93,100,1,10.92,200,2,10.84,100,1,10.18,700,1,10.11,100,1,15.30,0,-1,15.98,0,-1,16.15,0,-1,16.38,0,-2,16.83,0,-2,17.36,0,-3,17.44,0,-4,17.60,0,-1,17.85,0,-1,17.93,0,-1,ARL,0
2025-07-17T13:30:00.870174640Z,2025-07-17T13:30:00.869996105Z,10,2,1108,A,B,10,9.550000000,100,43314161,178535,28963952,11.52,100,1,11.29,100,1,11.24,100,1,11.05,100,1,11.01,100,1,10.93,100,1,10.92,200,2,10.84,100,1,10.18,700,1,10.11,100,1,15.30,0,-1,15.98,0,-1,16.15,0,-1,16.38,0,-2,16.83,0,-2,17.36,0,-3,17.44,0,-4,17.60,0,-1,17.85,0,-1,17.93,0,-1,ARL,0
2025-07-17T13:30:00.870174640Z,2025-07-17T13:30:00.869996504Z,10,2,1108,C,B,10,8.470000000,100,41376353,178136,28963953,11.52,100,1,11.29,100,1,11.24,100,1,11.05,100,1,11.01,100,1,10.93,100,1,10.92,200,2,10.84,100,1,10.18,700,1,10.11,100,1,15.30,0,-1,15.98,0,-1,16.15,0,-1,16.38,0,-2,16.83,0,-2,17.36,0,-3,17.44,0,-4,17.60,0,-1,17.85,0,-1,17.93,0,-1,ARL,0
2025-07-17T13:30:00.870174640Z,2025-07-17T13:30:00.869996504Z,10,2,1108,A,B,10,9.550000000,100,43314165,178136,28963953,11.52,100,1,11.29,100,1,11.24,100,1,11.05,100,1,11.01,100,1,10.93,100,1,10.92,200,2,10.84,100,1,10.18,700,1,10.11,100,1,15.30,0,-1,15.98,0,-1,16.15,0,-1,16.38,0,-2,16.83,0,-2,17.36,0,-3,17.44,0,-4,17.60,0,-1,17.85,0,-1,17.93,0,-1,ARL,0
2025-07-17T13:30:00.870174640Z,2025-07-17T13:30:00.869997057Z,10,2,1108,C,B,10,8.470000000,100,41376357,177583,28963954,11.52,100,1,11.29,100,1,11.24,100,1,11.05,100,1,11.01,100,1,10.93,100,1,10.92,200,2,10.84,100,1,10.18,700,1,10.11,100,1,15.30,0,-1,15.98,0,-1,16.15,0,-1,16.38,0,-2,16.83,0,-2,17.36,0,-3,17.44,0,-4,17.60,0,-1,17.85,0,-1,17.93,0,-1,ARL,0
2025-07-17T13:30:00.870174640Z,2025-07-17T13:30:00.869997057Z,10,2,1108,A,B,10,9.550000000,100,43314169,177583,28963954,11.52,100,1,11.29,100,1,11.24,100,1,11.05,100,1,11.01,100,1,10.93,100,1,10.92,200,2,10.84,100,1,10.18,700,1,10.11,100,1,15.30,0,-1,15.98,0,-1,16.15,0,-1,16.38,0,-2,16.83,0,-2,17.36,0,-3,17.44,0,-4,17.60,0,-1,17.85,0,-1,17.93,0,-1,ARL,0
2025-07-17T13:30:00.870179751Z,2025-07-17T13:30:00.870003387Z,10,2,1108,C,B,10,8.470000000,100,42202297,176364,28963962,11.52,100,1,11.29,100,1,11.24,100,1,11.05,100,1,11.01,100,1,10.93,100,1,10.92,200,2,10.84,100,1,10.18,700,1,10.11,100,1,15.30,0,-1,15.98,0,-1,16.15,0,-1,16.38,0,-2,16.83,0,-2,17.36,0,-3,17.44,0,-4,17.60,0,-1,17.85,0,-1,17.93,0,-1,ARL,0
2025-07-17T13:30:00.870179751Z,2025-07-17T13:30:00.870003387Z,10,2,1108,A,B,10,9.550000000,100,43314173,176364,28963962,11.52,100,1,11.29,100,1,11.24,100,1,11.05,100,1,11.01,100,1,10.93,100,1,10.92,200,2,10.84,100,1,10.18,700,1,10.11,100,1,15.30,0,-1,15.98,0,-1,16.15,0,-1,16.38,0,-2,16.83,0,-2,17.36,0,-3,17.44,0,-4,17.60,0,-1,17.85,0,-1,17.93,0,-1,ARL,0
2025-07-17T13:30:00.870179751Z,2025-07-17T13:30:00.870004158Z,10,2,1108,C,B,10,8.470000000,100,42951397,175593,28963963,11.52,100,1,11.29,100,1,11.24,100,1,11.05,100,1,11.01,100,1,10.93,100,1,10.92,200,2,10.84,100,1,10.18,700,1,10.11,100,1,15.30,0,-1,15.98,0,-1,16.15,0,-1,16.38,0,-2,16.83,0,-2,17.36,0,-3,17.44,0,-4,17.60,0,-1,17.85,0,-1,17.93,0,-1,ARL,0
2025-07-17T13:30:00.870179751Z,2025-07-17T13:30:00.870004158Z,10,2,1108,A,B,10,9.550000000,100,43314177,175593,28963963,11.52,100,1,11.29,100,1,11.24,100,1,11.05,100,1,11.01,100,1,10.93,100,1,10.92,200,2,10.84,100,1,10.18,700,1,10.11,100,1,15.30,0,-1,15.98,0,-1,16.15,0,-1,16.38,0,-2,16.83,0,-2,17.36,0,-3,17.44,0,-4,17.60,0,-1,17.85,0,-1,17.93,0,-1,ARL,0
2025-07-17T13:30:00.870186428Z,2025-07-17T13:30:00.870009922Z,10,2,1108,C,A,10,19.580000000,100,41370945,176506,28963970,11.52,100,1,11.29,100,1,11.24,100,1,11.05,100,1,11.01,100,1,10.93,100,1,10.92,200,2,10.84,100,1,10.18,700,1,10.11,100,1,15.30,0,-1,15.98,0,-1,16.15,0,-1,16.38,0,-2,16.83,0,-2,17.36,0,-3,17.44,0,-4,17.60,0,-1,17.85,0,-1,17.93,0,-1,ARL,0
2025-07-17T13:30:00.870186428Z,2025-07-17T13:30:00.870009922Z,10,2,1108,A,A,10,18.380000000,100,43314181,176506,28963970,11.52,100,1,11.29,100,1,11.24,100,1,11.05,100,1,11.01,100,1,10.93,100,1,10.92,200,2,10.84,100,1,10.18,700,1,10.11,100,1,15.30,0,-1,15.98,0,-1,16.15,0,-1,16.38,0,-2,16.83,0,-2,17.36,0,-3,17.44,0,-4,17.60,0,-1,17.85,0,-1,17.93,0,-1,ARL,0
2025-07-17T13:30:00.870186428Z,2025-07-17T13:30:00.870010386Z,10,2,1108,C,A,10,19.580000000,100,41370949,176042,28963971,11.52,100,1,11.29,100,1,11.24,100,1,11.05,100,1,11.01,100,1,10.93,100,1,10.92,200,2,10.84,100,1,10.18,700,1,10.11,100,1,15.30,0,-1,15.98,0,-1,16.15,0,-1,16.38,0,-2,16.83,0,-2,17.36,0,-3,17.44,0,-4,17.60,0,-1,17.85,0,-1,17.93,0,-1,ARL,0
2025-07-17T13:30:00.870186428Z,2025-07-17T13:30:00.870010386Z,10,2,1108,A,A,10,18.380000000,100,43314185,176042,28963971,11.52,100,1,11.29,100,1,11.24,100,1,11.05,100,1,11.01,100,1,10.93,100,1,10.92,200,2,10.84,100,1,10.18,700,1,10.11,100,1,15.30,0,-1,15.98,0,-1,16.15,0,-1,16.38,0,-2,16.83,0,-2,17.36,0,-3,17.44,0,-4,17.60,0,-1,17.85,0,-1,17.93,0,-1,ARL,0
2025-07-17T13:30:00.870194394Z,2025-07-17T13:30:00.870017071Z,10,2,1108,C,A,10,19.580000000,100,41370953,177323,28963981,11.52,100,1,11.29,100,1,11.24,100,1,11.05,100,1,11.01,100,1,10.93,100,1,10.92,200,2,10.84,100,1,10.18,700,1,10.11,100,1,15.30,0,-1,15.98,0,-1,16.15,0,-1,16.38,0,-2,16.83,0,-2,17.36,0,-3,17.44,0,-4,17.60,0,-1,17.85,0,-1,17.93,0,-1,ARL,0
2025-07-17T13:30:00.870194394Z,2025-07-17T13:30:00.870017071Z,10,2,1108,A,A,10,18.380000000,100,43314189,177323,28963981,11.52,100,1,11.29,100,1,11.24,100,1,11.05,100,1,11.01,100,1,10.93,100,1,10.92,200,2,10.84,100,1,10.18,700,1,10.11,100,1,15.30,0,-1,15.98,0,-1,16.15,0,-1,16.38,0,-2,16.83,0,-2,17.36,0,-3,17.44,0,-4,17.60,0,-1,17.85,0,-1,17.93,0,-1,ARL,0
2025-07-17T13:30:00.870194394Z,2025-07-17T13:30:00.870022776Z,10,2,1108,C,A,10,19.580000000,100,41370957,171618,28963983,11.52,100,1,11.29,100,1,11.24,100,1,11.05,100,1,11.01,100,1,10.93,100,1,10.92,200,2,10.84,100,1,10.18,700,1,10.11,100,1,15.30,0,-1,15.98,0,-1,16.15,0,-1,16.38,0,-2,16.83,0,-2,17.36,0,-3,17.44,0,-4,17.60,0,-1,17.85,0,-1,17.93,0,-1,ARL,0
2025-07-17T13:30:00.870194394Z,2025-07-17T13:30:00.870022776Z,10,2,1108,A,A,10,18.380000000,100,43314233,171618,28963983,11.52,100,1,11.29,100,1,11.24,100,1,11.05,100,1,11.01,100,1,10.93,100,1,10.92,200,2,10.84,100,1,10.18,700,1,10.11,100,1,15.30,0,-1,15.98,0,-1,16.15,0,-1,16.38,0,-2,16.83,0,-2,17.36,0,-3,17.44,0,-4,17.60,0,-1,17.85,0,-1,17.93,0,-1,ARL,0
2025-07-17T13:30:00.870194394Z,2025-07-17T13:30:00.870023199Z,10,2,1108,C,A,10,19.580000000,100,41370961,171195,28963984,11.52,100,1,11.29,100,1,11.24,100,1,11.05,100,1,11.01,100,1,10.93,100,1,10.92,200,2,10.84,100,1,10.18,700,1,10.11,100,1,15.30,0,-1,15.98,0,-1,16.15,0,-1,16.38,0,-2,16.83,0,-2,17.36,0,-3,17.44,0,-4,17.60,0,-1,17.85,0,-1,17.93,0,-1,ARL,0
2025-07-17T13:30:00.870194394Z,2025-07-17T13:30:00.870023199Z,10,2,1108,A,A,10,18.380000000,100,43314237,171195,28963984,11.52,100,1,11.29,100,1,11.24,100,1,11.05,100,1,11.01,100,1,10.93,100,1,10.92,200,2,10.84,100,1,10.18,700,1,10.11,100,1,15.30,0,-1,15.98,0,-1,16.15,0,-1,16.38,0,-2,16.83,0,-2,17.36,0,-3,17.44,0,-4,17.60,0,-1,17.85,0,-1,17.93,0,-1,ARL,0
2025-07-17T13:30:00.870194394Z,2025-07-17T13:30:00.870023701Z,10,2,1108,C,A,10,19.580000000,100,41370965,170693,28963985,11.52,100,1,11.29,100,1,11.24,100,1,11.05,100,1,11.01,100,1,10.93,100,1,10.92,200,2,10.84,100,1,10.18,700,1,10.11,100,1,15.30,0,-1,15.98,0,-1,16.15,0,-1,16.38,0,-2,16.83,0,-2,17.36,0,-3,17.44,0,-4,17.60,0,-1,17.85,0,-1,17.93,0,-1,ARL,0
2025-07-17T13:30:00.870194394Z,2025-07-17T13:30:00.870023701Z,10,2,1108,A,A,10,18.380000000,100,43314241,170693,28963985,11.52,100,1,11.29,100,1,11.24,100,1,11.05,100,1,11.01,100,1,10.93,100,1,10.92,200,2,10.84,100,1,10.18,700,1,10.11,100,1,15.30,0,-1,15.98,0,-1,16.15,0,-1,16.38,0,-2,16.83,0,-2,17.36,0,-3,17.44,0,-4,17.60,0,-1,17.85,0,-1,17.93,0,-1,ARL,0
2025-07-17T13:30:00.870229401Z,2025-07-17T13:30:00.870053023Z,10,2,1108,C,A,10,19.580000000,100,41370969,176378,28964015,11.52,100,1,11.29,100,1,11.24,100,1,11.05,100,1,11.01,100,1,10.93,100,1,10.92,200,2,10.84,100,1,10.18,700,1,10.11,100,1,15.30,0,-1,15.98,0,-1,16.15,0,-1,16.38,0,-2,16.83,0,-2,17.36,0,-3,17.44,0,-4,17.60,0,-1,17.85,0,-1,17.93,0,-1,ARL,0
2025-07-17T13:30:00.870229401Z,2025-07-17T13:30:00.870053023Z,10,2,1108,A,A,10,18.380000000,100,43314245,176378,28964015,11.52,100,1,11.29,100,1,11.24,100,1,11.05,100,1,11.01,100,1,10.93,100,1,10.92,200,2,10.84,100,1,10.18,700,1,10.11,100,1,15.30,0,-1,15.98,0,-1,16.15,0,-1,16.38,0,-2,16.83,0,-2,17.36,0,-3,17.44,0,-4,17.60,0,-1,17.85,0,-1,17.93,0,-1,ARL,0
2025-07-17T13:30:00.870229401Z,2025-07-17T13:30:00.870053791Z,10,2,1108,C,A,10,19.580000000,100,42204681,175610,28964016,11.52,100,1,11.29,100,1,11.24,100,1,11.05,100,1,11.01,100,1,10.93,100,1,10.92,200,2,10.84,100,1,10.18,700,1,10.11,100,1,15.30,0,-1,15.98,0,-1,16.15,0,-1,16.38,0,-2,16.83,0,-2,17.36,0,-3,17.44,0,-4,17.60,0,-1,17.85,0,-1,17.93,0,-1,ARL,0
2025-07-17T13:30:00.870229401Z,2025-07-17T13:30:00.870053791Z,10,2,1108,A,A,10,18.380000000,100,43314253,175610,28964016,11.52,100,1,11.29,100,1,11.24,100,1,11.05,100,1,11.01,100,1,10.93,100,1,10.92,200,2,10.84,100,1,10.18,700,1,10.11,100,1,15.30,0,-1,15.98,0,-1,16.15,0,-1,16.38,0,-2,16.83,0,-2,17.36,0,-3,17.44,0,-4,17.60,0,-1,17.85,0,-1,17.93,0,-1,ARL,0
2025-07-17T13:30:00.870229401Z,2025-07-17T13:30:00.870054073Z,10,2,1108,C,A,10,19.580000000,100,42946053,175328,28964017,11.52,100,1,11.29,100,1,11.24,100,1,11.05,100,1,11.01,100,1,10.93,100,1,10.92,200,2,10.84,100,1,10.18,700,1,10.11,100,1,15.30,0,-1,15.98,0,-1,16.15,0,-1,16.38,0,-2,16.83,0,-2,17.36,0,-3,17.44,0,-4,17.60,0,-1,17.85,0,-1,17.93,0,-1,ARL,0
2025-07-17T13:30:00.870229401Z,2025-07-17T13:30:00.870054073Z,10,2,1108,A,A,10,18.380000000,100,43314257,175328,28964017,11.52,100,1,11.29,100,1,11.24,100,1,11.05,100,1,11.01,100,1,10.93,100,1,10.92,200,2,10.84,100,1,10.18,700,1,10.11,100,1,15.30,0,-1,15.98,0,-1,16.15,0,-1,16.38,0,-2,16.83,0,-2,17.36,0,-3,17.44,0,-4,17.60,0,-1,17.85,0,-1,17.93,0,-1,ARL,0
2025-07-17T13:30:00.870236146Z,2025-07-17T13:30:00.870063003Z,10,2,1108,C,A,10,18.360000000,100,43313633,173143,28964020,11.52,100,1,11.29,100,1,11.24,100,1,11.05,100,1,11.01,100,1,10.93,100,1,10.92,200,2,10.84,100,1,10.18,700,1,10.11,100,1,15.30,0,-1,15.98,0,-1,16.15,0,-1,16.38,0,-2,16.83,0,-2,17.36,0,-3,17.44,0,-4,17.60,0,-1,17.85,0,-1,17.93,0,-1,ARL,0
2025-07-17T13:30:00.870236146Z,2025-07-17T13:30:00.870063920Z,10,2,1108,C,B,10,9.410000000,100,43313681,172226,28964021,11.52,100,1,11.29,100,1,11.24,100,1,11.05,100,1,11.01,100,1,10.93,100,1,10.92,200,2,10.84,100,1,10.18,700,1,10.11,100,1,15.30,0,-1,15.98,0,-1,16.15,0,-1,16.38,0,-2,16.83,0,-2,17.36,0,-3,17.44,0,-4,17.60,0,-1,17.85,0,-1,17.93,0,-1,ARL,0
2025-07-17T13:30:00.870319397Z,2025-07-17T13:30:00.870151543Z,10,2,1108,A,B,10,10.610000000,100,43314465,167854,28964128,11.52,100,1,11.29,100,1,11.24,100,1,11.05,100,1,11.01,100,1,10.93,100,1,10.92,200,2,10.84,100,1,10.61,100,1,10.18,700,1,15.30,0,-1,15.98,0,-1,16.15,0,-1,16.38,0,-2,16.83,0,-2,17.36,0,-3,17.44,0,-4,17.60,0,-1,17.85,0,-1,17.93,0,-1,ARL,0
2025-07-17T13:30:00.870390228Z,2025-07-17T13:30:00.870209113Z,10,2,1108,A,A,10,17.230000000,100,43314561,181115,28964207,11.52,100,1,11.29,100,1,11.24,100,1,11.05,100,1,11.01,100,1,10.93,100,1,10.92,200,2,10.84,100,1,10.61,100,1,10.18,700,1,15.30,0,-1,15.98,0,-1,16.15,0,-1,16.38,0,-2,16.83,0,-2,17.36,0,-3,17.44,0,-4,17.60,0,-1,17.85,0,-1,17.93,0,-1,ARL,0
2025-07-17T13:30:00.870452050Z,2025-07-17T13:30:00.870273955Z,10,2,1108,C,B,10,11.240000000,100,43313941,178095,28964259,11.52,100,1,11.29,100,1,11.24,100,1,11.05,100,1,11.01,100,1,10.93,100,1,10.92,200,2,10.84,100,1,10.61,100,1,10.18,700,1,15.30,0,-1,15.98,0,-1,16.15,0,-1,16.38,0,-2,16.83,0,-2,17.23,0,-1,17.36,0,-3,17.44,0,-4,17.60,0,-1,17.85,0,-1,ARL,0
2025-07-17T13:30:00.870452050Z,2025-07-17T13:30:00.870278857Z,10,2,1108,C,A,10,15.980000000,100,43314009,173193,28964260,11.52,100,1,11.29,100,1,11.24,100,1,11.05,100,1,11.01,100,1,10.93,100,1,10.92,200,2,10.84,100,1,10.61,100,1,10.18,700,1,15.30,0,-1,15.98,0,-1,16.15,0,-1,16.38,0,-2,16.83,0,-2,17.23,0,-1,17.36,0,-3,17.44,0,-4,17.60,0,-1,17.85,0,-1,ARL,0
2025-07-17T13:30:00.870748921Z,2025-07-17T13:30:00.870579856Z,10,2,1108,C,B,10,9.410000000,100,43313553,169065,28964629,11.52,100,1,11.29,100,1,11.24,100,1,11.05,100,1,11.01,100,1,10.93,100,1,10.92,200,2,10.84,100,1,10.61,100,1,10.18,700,1,15.30,0,-1,15.98,0,-1,16.15,0,-1,16.38,0,-2,16.83,0,-2,17.23,0,-1,17.36,0,-3,17.44,0,-4,17.60,0,-1,17.85,0,-1,ARL,0
2025-07-17T13:30:00.870748921Z,2025-07-17T13:30:00.870580243Z,10,2,1108,C,A,10,18.360000000,100,43313565,168678,28964630,11.52,100,1,11.29,100,1,11.24,100,1,11.05,100,1,11.01,100,1,10.93,100,1,10.92,200,2,10.84,100,1,10.61,100,1,10.18,700,1,15.30,0,-1,15.98,0,-1,16.15,0,-1,16.38,0,-2,16.83,0,-2,17.23,0,-1,17.36,0,-3,17.44,0,-4,17.60,0,-1,17.85,0,-1,ARL,0
2025-07-17T13:30:00.871024910Z,2025-07-17T13:30:00.870848973Z,10,2,1108,A,B,10,11.400000000,100,43315905,175937,28964903,11.52,100,1,11.40,100,1,11.29,100,1,11.24,100,1,11.05,100,1,11.01,100,1,10.93,100,1,10.92,200,2,10.84,100,1,10.61,100,1,15.30,0,-1,15.98,0,-1,16.15,0,-1,16.38,0,-2,16.83,0,-2,17.23,0,-1,17.36,0,-3,17.44,0,-4,17.60,0,-1,17.85,0,-1,ARL,0
2025-07-17T13:30:00.871047347Z,2025-07-17T13:30:00.870874152Z,10,2,1108,C,B,10,10.110000000,100,42583289,173195,28964931,11.52,100,1,11.29,100,1,11.24,100,1,11.05,100,1,11.01,100,1,10.93,100,1,10.92,200,2,10.84,100,1,10.61,100,1,10.18,700,1,15.30,0,-1,15.98,0,-1,16.15,0,-1,16.38,0,-2,16.83,0,-2,17.23,0,-1,17.36,0,-3,17.44,0,-4,17.60,0,-1,17.85,0,-1,ARL,0
2025-07-17T13:30:00.871535485Z,2025-07-17T13:30:00.871359085Z,10,2,1108,A,A,10,16.380000000,100,43317137,176400,28965402,11.52,100,1,11.29,100,1,11.24,100,1,11.05,100,1,11.01,100,1,10.93,100,1,10.92,200,2,10.84,100,1,10.61,100,1,10.18,700,1,15.30,0,-1,15.98,0,-1,16.15,0,-1,16.38,0,-2,16.83,0,-2,17.23,0,-1,17.36,0,-3,17.44,0,-4,17.60,0,-1,17.85,0,-1,ARL,0
2025-07-17T13:30:00.871544335Z,2025-07-17T13:30:00.871371794Z,10,2,1108,A,B,10,10.610000000,100,43317177,172541,28965409,11.52,100,1,11.29,100,1,11.24,100,1,11.05,100,1,11.01,100,1,10.93,100,1,10.92,200,2,10.84,100,1,10.61,200,2,10.18,700,1,15.30,0,-1,15.98,0,-1,16.15,0,-1,16.38,0,-2,16.83,0,-2,17.23,0,-1,17.36,0,-3,17.44,0,-4,17.60,0,-1,17.85,0,-1,ARL,0
2025-07-17T13:30:00.871552017Z,2025-07-17T13:30:00.871379595Z,10,2,1108,A,A,10,17.230000000,100,43317185,172422,28965416,11.52,100,1,11.29,100,1,11.24,100,1,11.05,100,1,11.01,100,1,10.93,100,1,10.92,200,2,10.84,100,1,10.61,200,2,10.18,700,1,15.30,0,-1,15.98,0,-1,16.15,0,-1,16.38,0,-2,16.83,0,-2,17.23,0,-1,17.36,0,-3,17.44,0,-4,17.60,0,-1,17.85,0,-1,ARL,0
2025-07-17T13:30:00.871552017Z,2025-07-17T13:30:00.871381021Z,10,2,1108,C,A,10,17.450000000,100,42583293,170996,28965418,11.52,100,1,11.29,100,1,11.24,100,1,11.05,100,1,11.01,100,1,10.93,100,1,10.92,200,2,10.84,100,1,10.61,200,2,10.18,700,1,15.30,0,-1,15.98,0,-1,16.15,0,-1,16.38,0,-2,16.83,0,-2,17.23,0,-2,17.36,0,-3,17.44,0,-4,17.60,0,-1,17.85,0,-1,ARL,0
2025-07-17T13:30:00.871701004Z,2025-07-17T13:30:00.871520352Z,10,2,1108,C,B,10,10.840000000,100,41635065,180652,28965571,11.52,100,1,11.29,100,1,11.24,100,1,11.05,100,1,11.01,100,1,10.93,100,1,10.92,200,2,10.84,100,1,10.61,200,2,10.18,700,1,15.30,0,-1,15.98,0,-1,16.15,0,-1,16.38,0,-2,16.83,0,-2,17.23,0,-2,17.36,0,-3,17.44,0,-4,17.60,0,-1,17.85,0,-1,ARL,0
2025-07-17T13:30:00.871701004Z,2025-07-17T13:30:00.871520352Z,10,2,1108,A,B,10,12.230000000,100,43317473,180652,28965571,12.23,100,1,11.52,100,1,11.29,100,1,11.24,100,1,11.05,100,1,11.01,100,1,10.93,100,1,10.92,200,2,10.84,100,1,10.61,200,2,15.30,0,-1,15.98,0,-1,16.15,0,-1,16.38,0,-2,16.83,0,-2,17.23,0,-2,17.36,0,-3,17.44,0,-4,17.60,0,-1,17.85,0,-1,ARL,0
2025-07-17T13:30:00.871723283Z,2025-07-17T13:30:00.871548318Z,10,2,1108,C,A,10,16.490000000,100,41635069,174965,28965592,11.52,100,1,11.29,100,1,11.24,100,1,11.05,100,1,11.01,100,1,10.93,100,1,10.92,200,2,10.84,100,1,10.61,200,2,10.18,700,1,15.30,0,-1,15.98,0,-1,16.15,0,-1,16.38,0,-2,16.83,0,-2,17.23,0,-2,17.36,0,-3,17.44,0,-4,17.60,0,-1,17.85,0,-1,ARL,0
2025-07-17T13:30:00.871723283Z,2025-07-17T13:30:00.871548318Z,10,2,1108,A,A,10,15.470000000,100,43317561,174965,28965592,11.52,100,1,11.29,100,1,11.24,100,1,11.05,100,1,11.01,100,1,10.93,100,1,10.92,200,2,10.84,100,1,10.61,200,2,10.18,700,1,15.30,0,-1,15.98,0,-1,16.15,0,-1,16.38,0,-2,16.83,0,-2,17.23,0,-2,17.36,0,-3,17.44,0,-4,17.60,0,-1,17.85,0,-1,ARL,0
2025-07-17T13:30:00.911711427Z,2025-07-17T13:30:00.911486897Z,10,2,1108,A,B,10,11.690000000,2,43324133,224530,28973032,11.69,2,1,11.52,100,1,11.29,100,1,11.24,100,1,11.05,100,1,11.01,100,1,10.93,100,1,10.92,200,2,10.84,100,1,10.61,200,2,15.30,0,-1,15.98,0,-1,16.15,0,-1,16.38,0,-2,16.83,0,-2,17.23,0,-2,17.36,0,-3,17.44,0,-4,17.60,0,-1,17.85,0,-1,ARL,0
2025-07-17T13:30:00.914528735Z,2025-07-17T13:30:00.914351054Z,10,2,1108,A,A,10,15.310000000,2,43328313,177681,28975648,11.69,2,1,11.52,100,1,11.29,100,1,11.24,100,1,11.05,100,1,11.01,100,1,10.93,100,1,10.92,200,2,10.84,100,1,10.61,200,2,15.30,0,-1,15.98,0,-1,16.15,0,-1,16.38,0,-2,16.83,0,-2,17.23,0,-2,17.36,0,-3,17.44,0,-4,17.60,0,-1,17.85,0,-1,ARL,0
2025-07-17T13:30:00.915372008Z,2025-07-17T13:30:00.915197739Z,10,2,1108,C,B,10,10.580000000,100,41376725,174269,28976307,11.69,2,1,11.52,100,1,11.29,100,1,11.24,100,1,11.05,100,1,11.01,100,1,10.93,100,1,10.92,200,2,10.84,100,1,10.61,200,2,15.30,0,-1,15.31,0,-1,15.98,0,-1,16.15,0,-1,16.38,0,-2,16.83,0,-2,17.23,0,-2,17.36,0,-3,17.44,0,-4,17.60,0,-1,ARL,0
2025-07-17T13:30:00.915372008Z,2025-07-17T13:30:00.915197739Z,10,2,1108,A,B,10,11.930000000,100,43329953,174269,28976307,11.93,100,1,11.69,2,1,11.52,100,1,11.29,100,1,11.24,100,1,11.05,100,1,11.01,100,1,10.93,100,1,10.92,200,2,10.84,100,1,15.30,0,-1,15.31,0,-1,15.98,0,-1,16.15,0,-1,16.38,0,-2,16.83,0,-2,17.23,0,-2,17.36,0,-3,17.44,0,-4,17.60,0,-1,ARL,0
2025-07-17T13:30:00.916507980Z,2025-07-17T13:30:00.916332252Z,10,2,1108,C,A,10,16.830000000,100,41372125,175728,28977103,11.69,2,1,11.52,100,1,11.29,100,1,11.24,100,1,11.05,100,1,11.01,100,1,10.93,100,1,10.92,200,2,10.84,100,1,10.61,200,2,15.30,0,-1,15.31,0,-1,15.98,0,-1,16.15,0,-1,16.38,0,-2,16.83,0,-2,17.23,0,-2,17.36,0,-3,17.44,0,-4,17.60,0,-1,ARL,0
2025-07-17T13:30:00.916507980Z,2025-07-17T13:30:00.916332252Z,10,2,1108,A,A,10,15.800000000,100,43331877,175728,28977103,11.69,2,1,11.52,100,1,11.29,100,1,11.24,100,1,11.05,100,1,11.01,100,1,10.93,100,1,10.92,200,2,10.84,100,1,10.61,200,2,15.30,0,-1,15.31,0,-1,15.98,0,-1,16.15,0,-1,16.38,0,-2,16.83,0,-2,17.23,0,-2,17.36,0,-3,17.44,0,-4,17.60,0,-1,ARL,0
2025-07-17T13:30:00.920319545Z,2025-07-17T13:30:00.920144110Z,10,2,1108,C,A,10,18.380000000,100,43314181,175435,28979475,11.69,2,1,11.52,100,1,11.29,100,1,11.24,100,1,11.05,100,1,11.01,100,1,10.93,100,1,10.92,200,2,10.84,100,1,10.61,200,2,15.30,0,-1,15.31,0,-1,15.80,0,-1,15.98,0,-1,16.15,0,-1,16.38,0,-2,16.83,0,-2,17.23,0,-2,17.36,0,-3,17.44,0,-4,ARL,0
2025-07-17T13:30:00.920319545Z,2025-07-17T13:30:00.920144110Z,10,2,1108,A,A,10,17.150000000,100,43339133,175435,28979475,11.69,2,1,11.52,100,1,11.29,100,1,11.24,100,1,11.05,100,1,11.01,100,1,10.93,100,1,10.92,200,2,10.84,100,1,10.61,200,2,15.30,0,-1,15.31,0,-1,15.80,0,-1,15.98,0,-1,16.15,0,-1,16.38,0,-2,16.83,0,-2,17.23,0,-2,17.36,0,-3,17.44,0,-4,ARL,0
2025-07-17T13:30:00.920319545Z,2025-07-17T13:30:00.920147410Z,10,2,1108,C,A,10,18.380000000,100,43314185,172135,28979478,11.69,2,1,11.52,100,1,11.29,100,1,11.24,100,1,11.05,100,1,11.01,100,1,10.93,100,1,10.92,200,2,10.84,100,1,10.61,200,2,15.30,0,-1,15.31,0,-1,15.80,0,-1,15.98,0,-1,16.15,0,-1,16.38,0,-2,16.83,0,-2,17.15,0,-1,17.23,0,-2,17.36,0,-3,ARL,0
2025-07-17T13:30:00.920319545Z,2025-07-17T13:30:00.920147410Z,10,2,1108,A,A,10,17.150000000,100,43339165,172135,28979478,11.69,2,1,11.52,100,1,11.29,100,1,11.24,100,1,11.05,100,1,11.01,100,1,10.93,100,1,10.92,200,2,10.84,100,1,10.61,200,2,15.30,0,-1,15.31,0,-1,15.80,0,-1,15.98,0,-1,16.15,0,-1,16.38,0,-2,16.83,0,-2,17.15,0,-1,17.23,0,-2,17.36,0,-3,ARL,0
2025-07-17T13:30:00.920380241Z,2025-07-17T13:30:00.920208398Z,10,2,1108,C,A,10,18.380000000,100,43314189,171843,28979515,11.69,2,1,11.52,100,1,11.29,100,1,11.24,100,1,11.05,100,1,11.01,100,1,10.93,100,1,10.92,200,2,10.84,100,1,10.61,200,2,15.30,0,-1,15.31,0,-1,15.80,0,-1,15.98,0,-1,16.15,0,-1,16.38,0,-2,16.83,0,-2,17.15,0,-2,17.23,0,-2,17.36,0,-3,ARL,0
2025-07-17T13:30:00.920380241Z,2025-07-17T13:30:00.920208398Z,10,2,1108,A,A,10,17.150000000,100,43339333,171843,28979515,11.69,2,1,11.52,100,1,11.29,100,1,11.24,100,1,11.05,100,1,11.01,100,1,10.93,100,1,10.92,200,2,10.84,100,1,10.61,200,2,15.30,0,-1,15.31,0,-1,15.80,0,-1,15.98,0,-1,16.15,0,-1,16.38,0,-2,16.83,0,-2,17.15,0,-2,17.23,0,-2,17.36,0,-3,ARL,0
2025-07-17T13:30:00.920380241Z,2025-07-17T13:30:00.920208920Z,10,2,1108,C,A,10,18.380000000,100,43314233,171321,28979516,11.69,2,1,11.52,100,1,11.29,100,1,11.24,100,1,11.05,100,1,11.01,100,1,10.93,100,1,10.92,200,2,10.84,100,1,10.61,200,2,15.30,0,-1,15.31,0,-1,15.80,0,-1,15.98,0,-1,16.15,0,-1,16.38,0,-2,16.83,0,-2,17.15,0,-3,17.23,0,-2,17.36,0,-3,ARL,0
2025-07-17T13:30:00.920380241Z,2025-07-17T13:30:00.920208920Z,10,2,1108,A,A,10,17.150000000,100,43339337,171321,28979516,11.69,2,1,11.52,100,1,11.29,100,1,11.24,100,1,11.05,100,1,11.01,100,1,10.93,100,1,10.92,200,2,10.84,100,1,10.61,200,2,15.30,0,-1,15.31,0,-1,15.80,0,-1,15.98,0,-1,16.15,0,-1,16.38,0,-2,16.83,0,-2,17.15,0,-3,17.23,0,-2,17.36,0,-3,ARL,0
2025-07-17T13:30:00.920390005Z,2025-07-17T13:30:00.920209286Z,10,2,1108,C,A,10,18.380000000,100,43314237,180719,28979517,11.69,2,1,11.52,100,1,11.29,100,1,11.24,100,1,11.05,100,1,11.01,100,1,10.93,100,1,10.92,200,2,10.84,100,1,10.61,200,2,15.30,0,-1,15.31,0,-1,15.80,0,-1,15.98,0,-1,16.15,0,-1,16.38,0,-2,16.83,0,-2,17.15,0,-4,17.23,0,-2,17.36,0,-3,ARL,0
2025-07-17T13:30:00.920390005Z,2025-07-17T13:30:00.920209286Z,10,2,1108,A,A,10,17.150000000,100,43339341,180719,28979517,11.69,2,1,11.52,100,1,11.29,100,1,11.24,100,1,11.05,100,1,11.01,100,1,10.93,100,1,10.92,200,2,10.84,100,1,10.61,200,2,15.30,0,-1,15.31,0,-1,15.80,0,-1,15.98,0,-1,16.15,0,-1,16.38,0,-2,16.83,0,-2,17.15,0,-4,17.23,0,-2,17.36,0,-3,ARL,0
2025-07-17T13:30:00.920390005Z,2025-07-17T13:30:00.920216613Z,10,2,1108,C,A,10,18.380000000,100,43314241,173392,28979521,11.69,2,1,11.52,100,1,11.29,100,1,11.24,100,1,11.05,100,1,11.01,100,1,10.93,100,1,10.92,200,2,10.84,100,1,10.61,200,2,15.30,0,-1,15.31,0,-1,15.80,0,-1,15.98,0,-1,16.15,0,-1,16.38,0,-2,16.83,0,-2,17.15,0,-5,17.23,0,-2,17.36,0,-3,ARL,0
2025-07-17T13:30:00.920390005Z,2025-07-17T13:30:00.920216613Z,10,2,1108,A,A,10,17.150000000,100,43339377,173392,28979521,11.69,2,1,11.52,100,1,11.29,100,1,11.24,100,1,11.05,100,1,11.01,100,1,10.93,100,1,10.92,200,2,10.84,100,1,10.61,200,2,15.30,0,-1,15.31,0,-1,15.80,0,-1,15.98,0,-1,16.15,0,-1,16.38,0,-2,16.83,0,-2,17.15,0,-5,17.23,0,-2,17.36,0,-3,ARL,0
2025-07-17T13:30:00.920390005Z,2025-07-17T13:30:00.920217193Z,10,2,1108,C,A,10,18.380000000,100,43314245,172812,28979522,11.69,2,1,11.52,100,1,11.29,100,1,11.24,100,1,11.05,100,1,11.01,100,1,10.93,100,1,10.92,200,2,10.84,100,1,10.61,200,2,15.30,0,-1,15.31,0,-1,15.80,0,-1,15.98,0,-1,16.15,0,-1,16.38,0,-2,16.83,0,-2,17.15,0,-6,17.23,0,-2,17.36,0,-3,ARL,0
2025-07-17T13:30:00.920390005Z,2025-07-17T13:30:00.920217193Z,10,2,1108,A,A,10,17.150000000,100,43339381,172812,28979522,11.69,2,1,11.52,100,1,11.29,100,1,11.24,100,1,11.05,100,1,11.01,100,1,10.93,100,1,10.92,200,2,10.84,100,1,10.61,200,2,15.30,0,-1,15.31,0,-1,15.80,0,-1,15.98,0,-1,16.15,0,-1,16.38,0,-2,16.83,0,-2,17.15,0,-6,17.23,0,-2,17.36,0,-3,ARL,0
2025-07-17T13:30:00.920390005Z,2025-07-17T13:30:00.920217632Z,10,2,1108,C,A,10,18.380000000,100,43314253,172373,28979523,11.69,2,1,11.52,100,1,11.29,100,1,11.24,100,1,11.05,100,1,11.01,100,1,10.93,100,1,10.92,200,2,10.84,100,1,10.61,200,2,15.30,0,-1,15.31,0,-1,15.80,0,-1,15.98,0,-1,16.15,0,-1,16.38,0,-2,16.83,0,-2,17.15,0,-7,17.23,0,-2,17.36,0,-3,ARL,0
2025-07-17T13:30:00.920390005Z,2025-07-17T13:30:00.920217632Z,10,2,1108,A,A,10,17.150000000,100,43339385,172373,28979523,11.69,2,1,11.52,100,1,11.29,100,1,11.24,100,1,11.05,100,1,11.01,100,1,10.93,100,1,10.92,200,2,10.84,100,1,10.61,200,2,15.30,0,-1,15.31,0,-1,15.80,0,-1,15.98,0,-1,16.15,0,-1,16.38,0,-2,16.83,0,-2,17.15,0,-7,17.23,0,-2,17.36,0,-3,ARL,0
2025-07-17T13:30:00.920530105Z,2025-07-17T13:30:00.920351772Z,10,2,1108,C,A,10,18.380000000,100,43314257,178333,28979649,11.69,2,1,11.52,100,1,11.29,100,1,11.24,100,1,11.05,100,1,11.01,100,1,10.93,100,1,10.92,200,2,10.84,100,1,10.61,200,2,15.30,0,-1,15.31,0,-1,15.80,0,-1,15.98,0,-1,16.15,0,-1,16.38,0,-2,16.83,0,-2,17.15,0,-8,17.23,0,-2,17.36,0,-3,ARL,0
2025-07-17T13:30:00.920530105Z,2025-07-17T13:30:00.920351772Z,10,2,1108,A,A,10,17.150000000,100,43339565,178333,28979649,11.69,2,1,11.52,100,1,11.29,100,1,11.24,100,1,11.05,100,1,11.01,100,1,10.93,100,1,10.92,200,2,10.84,100,1,10.61,200,2,15.30,0,-1,15.31,0,-1,15.80,0,-1,15.98,0,-1,16.15,0,-1,16.38,0,-2,16.83,0,-2,17.15,0,-8,17.23,0,-2,17.36,0,-3,ARL,0
2025-07-17T13:30:00.931605690Z,2025-07-17T13:30:00.931432717Z,10,2,1108,C,A,10,15.800000000,100,43331877,172973,28991138,11.69,2,1,11.52,100,1,11.29,100,1,11.24,100,1,11.05,100,1,11.01,100,1,10.93,100,1,10.92,200,2,10.84,100,1,10.61,200,2,15.30,0,-1,15.31,0,-1,15.80,0,-1,15.98,0,-1,16.15,0,-1,16.38,0,-2,16.83,0,-2,17.15,0,-9,17.23,0,-2,17.36,0,-3,ARL,0
2025-07-17T13:30:00.931605690Z,2025-07-17T13:30:00.931432717Z,10,2,1108,A,A,10,14.740000000,100,43357029,172973,28991138,11.69,2,1,11.52,100,1,11.29,100,1,11.24,100,1,11.05,100,1,11.01,100,1,10.93,100,1,10.92,200,2,10.84,100,1,10.61,200,2,15.30,0,-1,15.31,0,-1,15.80,0,-1,15.98,0,-1,16.15,0,-1,16.38,0,-2,16.83,0,-2,17.15,0,-9,17.23,0,-2,17.36,0,-3,ARL,0
2025-07-17T13:30:00.941082601Z,2025-07-17T13:30:00.940916945Z,10,2,1108,C,A,10,15.470000000,100,43317561,165656,29000554,11.69,2,1,11.52,100,1,11.29,100,1,11.24,100,1,11.05,100,1,11.01,100,1,10.93,100,1,10.92,200,2,10.84,100,1,10.61,200,2,14.74,0,-1,15.30,0,-1,15.31,0,-1,15.80,0,-1,15.98,0,-1,16.15,0,-1,16.38,0,-2,16.83,0,-2,17.15,0,-9,17.23,0,-2,ARL,0
2025-07-17T13:30:00.941082601Z,2025-07-17T13:30:00.940916945Z,10,2,1108,A,A,10,14.440000000,100,43373009,165656,29000554,11.69,2,1,11.52,100,1,11.29,100,1,11.24,100,1,11.05,100,1,11.01,100,1,10.93,100,1,10.92,200,2,10.84,100,1,10.61,200,2,14.74,0,-1,15.30,0,-1,15.31,0,-1,15.80,0,-1,15.98,0,-1,16.15,0,-1,16.38,0,-2,16.83,0,-2,17.15,0,-9,17.23,0,-2,ARL,0
2025-07-17T13:30:00.941236862Z,2025-07-17T13:30:00.941071231Z,10,2,1108,A,A,10,15.280000000,100,43373085,165631,29000677,11.69,2,1,11.52,100,1,11.29,100,1,11.24,100,1,11.05,100,1,11.01,100,1,10.93,100,1,10.92,200,2,10.84,100,1,10.61,200,2,14.74,0,-1,15.30,0,-1,15.31,0,-1,15.80,0,-1,15.98,0,-1,16.15,0,-1,16.38,0,-2,16.83,0,-2,17.15,0,-9,17.23,0,-2,ARL,0
2025-07-17T13:30:00.941255157Z,2025-07-17T13:30:00.941085073Z,10,2,1108,C,A,10,16.380000000,100,43317137,170084,29000688,11.69,2,1,11.52,100,1,11.29,100,1,11.24,100,1,11.05,100,1,11.01,100,1,10.93,100,1,10.92,200,2,10.84,100,1,10.61,200,2,14.74,0,-1,15.28,0,-1,15.30,0,-1,15.31,0,-1,15.80,0,-1,15.98,0,-1,16.15,0,-1,16.38,0,-2,16.83,0,-2,17.15,0,-9,ARL,0
2025-07-17T13:30:01.086605950Z,2025-07-17T13:30:01.086438727Z,10,2,1108,C,B,10,11.010000000,100,42674817,167223,29116818,11.69,2,1,11.52,100,1,11.29,100,1,11.24,100,1,11.05,100,1,11.01,100,1,10.93,100,1,10.92,200,2,10.84,100,1,10.61,200,2,14.74,0,-1,15.28,0,-1,15.30,0,-1,15.31,0,-1,15.80,0,-1,15.98,0,-1,16.15,0,-1,16.38,0,-2,16.83,0,-2,17.15,0,-9,ARL,0
2025-07-17T13:30:01.086605950Z,2025-07-17T13:30:01.086438727Z,10,2,1108,A,B,10,12.470000000,100,43554133,167223,29116818,12.47,100,1,11.69,2,1,11.52,100,1,11.29,100,1,11.24,100,1,11.05,100,1,11.01,100,1,10.93,100,1,10.92,200,2,10.84,100,1,14.74,0,-1,15.28,0,-1,15.30,0,-1,15.31,0,-1,15.80,0,-1,15.98,0,-1,16.15,0,-1,16.38,0,-2,16.83,0,-2,17.15,0,-9,ARL,0
2025-07-17T13:30:01.086625226Z,2025-07-17T13:30:01.086456460Z,10,2,1108,C,A,10,16.100000000,100,42674989,168766,29116862,11.69,2,1,11.52,100,1,11.29,100,1,11.24,100,1,11.05,100,1,11.01,100,1,10.93,100,1,10.92,200,2,10.84,100,1,10.61,200,2,14.74,0,-1,15.28,0,-1,15.30,0,-1,15.31,0,-1,15.80,0,-1,15.98,0,-1,16.15,0,-1,16.38,0,-2,16.83,0,-2,17.15,0,-9,ARL,0
2025-07-17T13:30:01.086625226Z,2025-07-17T13:30:01.086456460Z,10,2,1108,A,A,10,14.200000000,100,43554141,168766,29116862,11.69,2,1,11.52,100,1,11.29,100,1,11.24,100,1,11.05,100,1,11.01,100,1,10.93,100,1,10.92,200,2,10.84,100,1,10.61,200,2,14.74,0,-1,15.28,0,-1,15.30,0,-1,15.31,0,-1,15.80,0,-1,15.98,0,-1,16.15,0,-1,16.38,0,-2,16.83,0,-2,17.15,0,-9,ARL,0
2025-07-17T13:30:01.214882922Z,2025-07-17T13:30:01.214703183Z,10,2,1108,A,B,10,12.670000000,100,43663229,179739,29196804,12.67,100,1,11.69,2,1,11.52,100,1,11.29,100,1,11.24,100,1,11.05,100,1,11.01,100,1,10.93,100,1,10.92,200,2,10.84,100,1,14.74,0,-1,15.28,0,-1,15.30,0,-1,15.31,0,-1,15.80,0,-1,15.98,0,-1,16.15,0,-1,16.38,0,-2,16.83,0,-2,17.15,0,-9,ARL,0
2025-07-17T13:30:01.214882922Z,2025-07-17T13:30:01.214704496Z,10,2,1108,A,A,10,14.000000000,100,43663233,178426,29196805,12.67,100,1,11.69,2,1,11.52,100,1,11.29,100,1,11.24,100,1,11.05,100,1,11.01,100,1,10.93,100,1,10.92,200,2,10.84,100,1,14.74,0,-1,15.28,0,-1,15.30,0,-1,15.31,0,-1,15.80,0,-1,15.98,0,-1,16.15,0,-1,16.38,0,-2,16.83,0,-2,17.15,0,-9,ARL,0
2025-07-17T13:30:01.252386379Z,2025-07-17T13:30:01.252206360Z,10,2,1108,A,B,10,7.740000000,100,27015957,180019,29221770,12.67,100,1,11.69,2,1,11.52,100,1,11.29,100,1,11.24,100,1,11.05,100,1,11.01,100,1,10.93,100,1,10.92,200,2,10.84,100,1,14.74,0,-1,15.28,0,-1,15.30,0,-1,15.31,0,-1,15.80,0,-1,15.98,0,-1,16.15,0,-1,16.38,0,-2,16.83,0,-2,17.15,0,-9,ARL,0
2025-07-17T13:30:01.252386379Z,2025-07-17T13:30:01.252206360Z,10,2,1108,A,A,10,20.480000000,100,27015965,180019,29221771,12.67,100,1,11.69,2,1,11.52,100,1,11.29,100,1,11.24,100,1,11.05,100,1,11.01,100,1,10.93,100,1,10.92,200,2,10.84,100,1,14.74,0,-1,15.28,0,-1,15.30,0,-1,15.31,0,-1,15.80,0,-1,15.98,0,-1,16.15,0,-1,16.38,0,-2,16.83,0,-2,17.15,0,-9,ARL,0
2025-07-17T13:30:01.252386379Z,2025-07-17T13:30:01.252206360Z,10,2,1108,A,B,10,7.740000000,100,38084501,180019,29221772,12.67,100,1,11.69,2,1,11.52,100,1,11.29,100,1,11.24,100,1,11.05,100,1,11.01,100,1,10.93,100,1,10.92,200,2,10.84,100,1,14.74,0,-1,15.28,0,-1,15.30,0,-1,15.31,0,-1,15.80,0,-1,15.98,0,-1,16.15,0,-1,16.38,0,-2,16.83,0,-2,17.15,0,-9,ARL,0
2025-07-17T13:30:01.252386379Z,2025-07-17T13:30:01.252206360Z,10,2,1108,A,A,10,20.480000000,100,38073517,180019,29221773,12.67,100,1,11.69,2,1,11.52,100,1,11.29,100,1,11.24,100,1,11.05,100,1,11.01,100,1,10.93,100,1,10.92,200,2,10.84,100,1,14.74,0,-1,15.28,0,-1,15.30,0,-1,15.31,0,-1,15.80,0,-1,15.98,0,-1,16.15,0,-1,16.38,0,-2,16.83,0,-2,17.15,0,-9,ARL,0
2025-07-17T13:30:01.252386379Z,2025-07-17T13:30:01.252206360Z,10,2,1108,A,B,10,7.740000000,100,38130589,180019,29221774,12.67,100,1,11.69,2,1,11.52,100,1,11.29,100,1,11.24,100,1,11.05,100,1,11.01,100,1,10.93,100,1,10.92,200,2,10.84,100,1,14.74,0,-1,15.28,0,-1,15.30,0,-1,15.31,0,-1,15.80,0,-1,15.98,0,-1,16.15,0,-1,16.38,0,-2,16.83,0,-2,17.15,0,-9,ARL,0
2025-07-17T13:30:01.252386379Z,2025-07-17T13:30:01.252206360Z,10,2,1108,A,A,10,20.480000000,100,38134973,180019,29221775,12.67,100,1,11.69,2,1,11.52,100,1,11.29,100,1,11.24,100,1,11.05,100,1,11.01,100,1,10.93,100,1,10.92,200,2,10.84,100,1,14.74,0,-1,15.28,0,-1,15.30,0,-1,15.31,0,-1,15.80,0,-1,15.98,0,-1,16.15,0,-1,16.38,0,-2,16.83,0,-2,17.15,0,-9,ARL,0
2025-07-17T13:30:01.252386379Z,2025-07-17T13:30:01.252206360Z,10,2,1108,A,B,10,7.740000000,100,38470185,180019,29221776,12.67,100,1,11.69,2,1,11.52,100,1,11.29,100,1,11.24,100,1,11.05,100,1,11.01,100,1,10.93,100,1,10.92,200,2,10.84,100,1,14.74,0,-1,15.28,0,-1,15.30,0,-1,15.31,0,-1,15.80,0,-1,15.98,0,-1,16.15,0,-1,16.38,0,-2,16.83,0,-2,17.15,0,-9,ARL,0
2025-07-17T13:30:01.252386379Z,2025-07-17T13:30:01.252206360Z,10,2,1108,A,A,10,20.480000000,100,38471493,180019,29221777,12.67,100,1,11.69,2,1,11.52,100,1,11.29,100,1,11.24,100,1,11.05,100,1,11.01,100,1,10.93,100,1,10.92,200,2,10.84,100,1,14.74,0,-1,15.28,0,-1,15.30,0,-1,15.31,0,-1,15.80,0,-1,15.98,0,-1,16.15,0,-1,16.38,0,-2,16.83,0,-2,17.15,0,-9,ARL,0
2025-07-17T13:30:01.252386379Z,2025-07-17T13:30:01.252206360Z,10,2,1108,A,B,10,7.740000000,100,38759997,180019,29221778,12.67,100,1,11.69,2,1,11.52,100,1,11.29,100,1,11.24,100,1,11.05,100,1,11.01,100,1,10.93,100,1,10.92,200,2,10.84,100,1,14.74,0,-1,15.28,0,-1,15.30,0,-1,15.31,0,-1,15.80,0,-1,15.98,0,-1,16.15,0,-1,16.38,0,-2,16.83,0,-2,17.15,0,-9,ARL,0
2025-07-17T13:30:01.252386379Z,2025-07-17T13:30:01.252206360Z,10,2,1108,A,A,10,20.480000000,100,38758965,180019,29221779,12.67,100,1,11.69,2,1,11.52,100,1,11.29,100,1,11.24,100,1,11.05,100,1,11.01,100,1,10.93,100,1,10.92,200,2,10.84,100,1,14.74,0,-1,15.28,0,-1,15.30,0,-1,15.31,0,-1,15.80,0,-1,15.98,0,-1,16.15,0,-1,16.38,0,-2,16.83,0,-2,17.15,0,-9,ARL,0
2025-07-17T13:30:01.252386379Z,2025-07-17T13:30:01.252206360Z,10,2,1108,A,B,10,7.740000000,100,38775373,180019,29221780,12.67,100,1,11.69,2,1,11.52,100,1,11.29,100,1,11.24,100,1,11.05,100,1,11.01,100,1,10.93,100,1,10.92,200,2,10.84,100,1,14.74,0,-1,15.28,0,-1,15.30,0,-1,15.31,0,-1,15.80,0,-1,15.98,0,-1,16.15,0,-1,16.38,0,-2,16.83,0,-2,17.15,0,-9,ARL,0
2025-07-17T13:30:01.252386379Z,2025-07-17T13:30:01.252206360Z,10,2,1108,A,A,10,20.480000000,100,38776877,180019,29221781,12.67,100,1,11.69,2,1,11.52,100,1,11.29,100,1,11.24,100,1,11.05,100,1,11.01,100,1,10.93,100,1,10.92,200,2,10.84,100,1,14.74,0,-1,15.28,0,-1,15.30,0,-1,15.31,0,-1,15.80,0,-1,15.98,0,-1,16.15,0,-1,16.38,0,-2,16.83,0,-2,17.15,0,-9,ARL,0
2025-07-17T13:30:01.252386379Z,2025-07-17T13:30:01.252206360Z,10,2,1108,A,B,10,7.740000000,100,38865193,180019,29221782,12.67,100,1,11.69,2,1,11.52,100,1,11.29,100,1,11.24,100,1,11.05,100,1,11.01,100,1,10.93,100,1,10.92,200,2,10.84,100,1,14.74,0,-1,15.28,0,-1,15.30,0,-1,15.31,0,-1,15.80,0,-1,15.98,0,-1,16.15,0,-1,16.38,0,-2,16.83,0,-2,17.15,0,-9,ARL,0
2025-07-17T13:30:01.252386379Z,2025-07-17T13:30:01.252206360Z,10,2,1108,A,A,10,20.480000000,100,38863877,180019,29221783,12.67,100,1,11.69,2,1,11.52,100,1,11.29,100,1,11.24,100,1,11.05,100,1,11.01,100,1,10.93,100,1,10.92,200,2,10.84,100,1,14.74,0,-1,15.28,0,-1,15.30,0,-1,15.31,0,-1,15.80,0,-1,15.98,0,-1,16.15,0,-1,16.38,0,-2,16.83,0,-2,17.15,0,-9,ARL,0
2025-07-17T13:30:01.252444419Z,2025-07-17T13:30:01.252269158Z,10,2,1108,C,B,10,7.740000000,100,27015957,175261,29221828,12.67,100,1,11.69,2,1,11.52,100,1,11.29,100,1,11.24,100,1,11.05,100,1,11.01,100,1,10.93,100,1,10.92,200,2,10.84,100,1,14.74,0,-1,15.28,0,-1,15.30,0,-1,15.31,0,-1,15.80,0,-1,15.98,0,-1,16.15,0,-1,16.38,0,-2,16.83,0,-2,17.15,0,-9,ARL,0
2025-07-17T13:30:01.252444419Z,2025-07-17T13:30:01.252269158Z,10,2,1108,A,B,10,9.550000000,100,43690797,175261,29221828,12.67,100,1,11.69,2,1,11.52,100,1,11.29,100,1,11.24,100,1,11.05,100,1,11.01,100,1,10.93,100,1,10.92,200,2,10.84,100,1,14.74,0,-1,15.28,0,-1,15.30,0,-1,15.31,0,-1,15.80,0,-1,15.98,0,-1,16.15,0,-1,16.38,0,-2,16.83,0,-2,17.15,0,-9,ARL,0
2025-07-17T13:30:01.252444419Z,2025-07-17T13:30:01.252269575Z,10,2,1108,C,B,10,7.740000000,100,38084501,174844,29221829,12.67,100,1,11.69,2,1,11.52,100,1,11.29,100,1,11.24,100,1,11.05,100,1,11.01,100,1,10.93,100,1,10.92,200,2,10.84,100,1,14.74,0,-1,15.28,0,-1,15.30,0,-1,15.31,0,-1,15.80,0,-1,15.98,0,-1,16.15,0,-1,16.38,0,-2,16.83,0,-2,17.15,0,-9,ARL,0
2025-07-17T13:30:01.252444419Z,2025-07-17T13:30:01.252269575Z,10,2,1108,A,B,10,9.550000000,100,43690801,174844,29221829,12.67,100,1,11.69,2,1,11.52,100,1,11.29,100,1,11.24,100,1,11.05,100,1,11.01,100,1,10.93,100,1,10.92,200,2,10.84,100,1,14.74,0,-1,15.28,0,-1,15.30,0,-1,15.31,0,-1,15.80,0,-1,15.98,0,-1,16.15,0,-1,16.38,0,-2,16.83,0,-2,17.15,0,-9,ARL,0
2025-07-17T13:30:01.252444419Z,2025-07-17T13:30:01.252269960Z,10,2,1108,C,B,10,7.740000000,100,38130589,174459,29221830,12.67,100,1,11.69,2,1,11.52,100,1,11.29,100,1,11.24,100,1,11.05,100,1,11.01,100,1,10.93,100,1,10.92,200,2,10.84,100,1,14.74,0,-1,15.28,0,-1,15.30,0,-1,15.31,0,-1,15.80,0,-1,15.98,0,-1,16.15,0,-1,16.38,0,-2,16.83,0,-2,17.15,0,-9,ARL,0
2025-07-17T13:30:01.252444419Z,2025-07-17T13:30:01.252269960Z,10,2,1108,A,B,10,9.550000000,100,43690805,174459,29221830,12.67,100,1,11.69,2,1,11.52,100,1,11.29,100,1,11.24,100,1,11.05,100,1,11.01,100,1,10.93,100,1,10.92,200,2,10.84,100,1,14.74,0,-1,15.28,0,-1,15.30,0,-1,15.31,0,-1,15.80,0,-1,15.98,0,-1,16.15,0,-1,16.38,0,-2,16.83,0,-2,17.15,0,-9,ARL,0
2025-07-17T13:30:01.252444419Z,2025-07-17T13:30:01.252270596Z,10,2,1108,C,B,10,7.740000000,100,38470185,173823,29221831,12.67,100,1,11.69,2,1,11.52,100,1,11.29,100,1,11.24,100,1,11.05,100,1,11.01,100,1,10.93,100,1,10.92,200,2,10.84,100,1,14.74,0,-1,15.28,0,-1,15.30,0,-1,15.31,0,-1,15.80,0,-1,15.98,0,-1,16.15,0,-1,16.38,0,-2,16.83,0,-2,17.15,0,-9,ARL,0
2025-07-17T13:30:01.252444419Z,2025-07-17T13:30:01.252270596Z,10,2,1108,A,B,10,9.550000000,100,43690809,173823,29221831,12.67,100,1,11.69,2,1,11.52,100,1,11.29,100,1,11.24,100,1,11.05,100,1,11.01,100,1,10.93,100,1,10.92,200,2,10.84,100,1,14.74,0,-1,15.28,0,-1,15.30,0,-1,15.31,0,-1,15.80,0,-1,15.98,0,-1,16.15,0,-1,16.38,0,-2,16.83,0,-2,17.15,0,-9,ARL,0
2025-07-17T13:30:01.252444419Z,2025-07-17T13:30:01.252270987Z,10,2,1108,C,B,10,7.740000000,100,38759997,173432,29221832,12.67,100,1,11.69,2,1,11.52,100,1,11.29,100,1,11.24,100,1,11.05,100,1,11.01,100,1,10.93,100,1,10.92,200,2,10.84,100,1,14.74,0,-1,15.28,0,-1,15.30,0,-1,15.31,0,-1,15.80,0,-1,15.98,0,-1,16.15,0,-1,16.38,0,-2,16.83,0,-2,17.15,0,-9,ARL,0
2025-07-17T13:30:01.252444419Z,2025-07-17T13:30:01.252270987Z,10,2,1108,A,B,10,9.550000000,100,43690813,173432,29221832,12.67,100,1,11.69,2,1,11.52,100,1,11.29,100,1,11.24,100,1,11.05,100,1,11.01,100,1,10.93,100,1,10.92,200,2,10.84,100,1,14.74,0,-1,15.28,0,-1,15.30,0,-1,15.31,0,-1,15.80,0,-1,15.98,0,-1,16.15,0,-1,16.38,0,-2,16.83,0,-2,17.15,0,-9,ARL,0
2025-07-17T13:30:01.252444419Z,2025-07-17T13:30:01.252271274Z,10,2,1108,C,B,10,7.740000000,100,38775373,173145,29221833,12.67,100,1,11.69,2,1,11.52,100,1,11.29,100,1,11.24,100,1,11.05,100,1,11.01,100,1,10.93,100,1,10.92,200,2,10.84,100,1,14.74,0,-1,15.28,0,-1,15.30,0,-1,15.31,0,-1,15.80,0,-1,15.98,0,-1,16.15,0,-1,16.38,0,-2,16.83,0,-2,17.15,0,-9,ARL,0
2025-07-17T13:30:01.252444419Z,2025-07-17T13:30:01.252271274Z,10,2,1108,A,B,10,9.550000000,100,43690817,173145,29221833,12.67,100,1,11.69,2,1,11.52,100,1,11.29,100,1,11.24,100,1,11.05,100,1,11.01,100,1,10.93,100,1,10.92,200,2,10.84,100,1,14.74,0,-1,15.28,0,-1,15.30,0,-1,15.31,0,-1,15.80,0,-1,15.98,0,-1,16.15,0,-1,16.38,0,-2,16.83,0,-2,17.15,0,-9,ARL,0
2025-07-17T13:30:01.252444419Z,2025-07-17T13:30:01.252272011Z,10,2,1108,C,B,10,7.740000000,100,38865193,172408,29221834,12.67,100,1,11.69,2,1,11.52,100,1,11.29,100,1,11.24,100,1,11.05,100,1,11.01,100,1,10.93,100,1,10.92,200,2,10.84,100,1,14.74,0,-1,15.28,0,-1,15.30,0,-1,15.31,0,-1,15.80,0,-1,15.98,0,-1,16.15,0,-1,16.38,0,-2,16.83,0,-2,17.15,0,-9,ARL,0
2025-07-17T13:30:01.252444419Z,2025-07-17T13:30:01.252272011Z,10,2,1108,A,B,10,9.550000000,100,43690821,172408,29221834,12.67,100,1,11.69,2,1,11.52,100,1,11.29,100,1,11.24,100,1,11.05,100,1,11.01,100,1,10.93,100,1,10.92,200,2,10.84,100,1,14.74,0,-1,15.28,0,-1,15.30,0,-1,15.31,0,-1,15.80,0,-1,15.98,0,-1,16.15,0,-1,16.38,0,-2,16.83,0,-2,17.15,0,-9,ARL,0
2025-07-17T13:30:01.252457898Z,2025-07-17T13:30:01.252279681Z,10,2,1108,C,A,10,20.480000000,100,27015965,178217,29221840,12.67,100,1,11.69,2,1,11.52,100,1,11.29,100,1,11.24,100,1,11.05,100,1,11.01,100,1,10.93,100,1,10.92,200,2,10.84,100,1,14.74,0,-1,15.28,0,-1,15.30,0,-1,15.31,0,-1,15.80,0,-1,15.98,0,-1,16.15,0,-1,16.38,0,-2,16.83,0,-2,17.15,0,-9,ARL,0
2025-07-17T13:30:01.252457898Z,2025-07-17T13:30:01.252279681Z,10,2,1108,A,A,10,17.150000000,100,43690825,178217,29221840,12.67,100,1,11.69,2,1,11.52,100,1,11.29,100,1,11.24,100,1,11.05,100,1,11.01,100,1,10.93,100,1,10.92,200,2,10.84,100,1,14.74,0,-1,15.28,0,-1,15.30,0,-1,15.31,0,-1,15.80,0,-1,15.98,0,-1,16.15,0,-1,16.38,0,-2,16.83,0,-2,17.15,0,-9,ARL,0
2025-07-17T13:30:01.252457898Z,2025-07-17T13:30:01.252280017Z,10,2,1108,C,A,10,20.480000000,100,38073517,177881,29221841,12.67,100,1,11.69,2,1,11.52,100,1,11.29,100,1,11.24,100,1,11.05,100,1,11.01,100,1,10.93,100,1,10.92,200,2,10.84,100,1,14.74,0,-1,15.28,0,-1,15.30,0,-1,15.31,0,-1,15.80,0,-1,15.98,0,-1,16.15,0,-1,16.38,0,-2,16.83,0,-2,17.15,0,-10,ARL,0
2025-07-17T13:30:01.252457898Z,2025-07-17T13:30:01.252280017Z,10,2,1108,A,A,10,17.150000000,100,43690829,177881,29221841,12.67,100,1,11.69,2,1,11.52,100,1,11.29,100,1,11.24,100,1,11.05,100,1,11.01,100,1,10.93,100,1,10.92,200,2,10.84,100,1,14.74,0,-1,15.28,0,-1,15.30,0,-1,15.31,0,-1,15.80,0,-1,15.98,0,-1,16.15,0,-1,16.38,0,-2,16.83,0,-2,17.15,0,-10,ARL,0
2025-07-17T13:30:01.252457898Z,2025-07-17T13:30:01.252280383Z,10,2,1108,C,A,10,20.480000000,100,38134973,177515,29221842,12.67,100,1,11.69,2,1,11.52,100,1,11.29,100,1,11.24,100,1,11.05,100,1,11.01,100,1,10.93,100,1,10.92,200,2,10.84,100,1,14.74,0,-1,15.28,0,-1,15.30,0,-1,15.31,0,-1,15.80,0,-1,15.98,0,-1,16.15,0,-1,16.38,0,-2,16.83,0,-2,17.15,0,-11,ARL,0
2025-07-17T13:30:01.252457898Z,2025-07-17T13:30:01.252280383Z,10,2,1108,A,A,10,17.150000000,100,43690833,177515,29221842,12.67,100,1,11.69,2,1,11.52,100,1,11.29,100,1,11.24,100,1,11.05,100,1,11.01,100,1,10.93,100,1,10.92,200,2,10.84,100,1,14.74,0,-1,15.28,0,-1,15.30,0,-1,15.31,0,-1,15.80,0,-1,15.98,0,-1,16.15,0,-1,16.38,0,-2,16.83,0,-2,17.15,0,-11,ARL,0
2025-07-17T13:30:01.252457898Z,2025-07-17T13:30:01.252280683Z,10,2,1108,C,A,10,20.480000000,100,38471493,177215,29221843,12.67,100,1,11.69,2,1,11.52,100,1,11.29,100,1,11.24,100,1,11.05,100,1,11.01,100,1,10.93,100,1,10.92,200,2,10.84,100,1,14.74,0,-1,15.28,0,-1,15.30,0,-1,15.31,0,-1,15.80,0,-1,15.98,0,-1,16.15,0,-1,16.38,0,-2,16.83,0,-2,17.15,0,-12,ARL,0
2025-07-17T13:30:01.252457898Z,2025-07-17T13:30:01.252280683Z,10,2,1108,A,A,10,17.150000000,100,43690837,177215,29221843,12.67,100,1,11.69,2,1,11.52,100,1,11.29,100,1,11.24,100,1,11.05,100,1,11.01,100,1,10.93,100,1,10.92,200,2,10.84,100,1,14.74,0,-1,15.28,0,-1,15.30,0,-1,15.31,0,-1,15.80,0,-1,15.98,0,-1,16.15,0,-1,16.38,0,-2,16.83,0,-2,17.15,0,-12,ARL,0
2025-07-17T13:30:01.252457898Z,2025-07-17T13:30:01.252281079Z,10,2,1108,C,A,10,20.480000000,100,38758965,176819,29221844,12.67,100,1,11.69,2,1,11.52,100,1,11.29,100,1,11.24,100,1,11.05,100,1,11.01,100,1,10.93,100,1,10.92,200,2,10.84,100,1,14.74,0,-1,15.28,0,-1,15.30,0,-1,15.31,0,-1,15.80,0,-1,15.98,0,-1,16.15,0,-1,16.38,0,-2,16.83,0,-2,17.15,0,-13,ARL,0
2025-07-17T13:30:01.252457898Z,2025-07-17T13:30:01.252281079Z,10,2,1108,A,A,10,17.150000000,100,43690841,176819,29221844,12.67,100,1,11.69,2,1,11.52,100,1,11.29,100,1,11.24,100,1,11.05,100,1,11.01,100,1,10.93,100,1,10.92,200,2,10.84,100,1,14.74,0,-1,15.28,0,-1,15.30,0,-1,15.31,0,-1,15.80,0,-1,15.98,0,-1,16.15,0,-1,16.38,0,-2,16.83,0,-2,17.15,0,-13,ARL,0
2025-07-17T13:30:01.252457898Z,2025-07-17T13:30:01.252281306Z,10,2,1108,C,A,10,20.480000000,100,38776877,176592,29221845,12.67,100,1,11.69,2,1,11.52,100,1,11.29,100,1,11.24,100,1,11.05,100,1,11.01,100,1,10.93,100,1,10.92,200,2,10.84,100,1,14.74,0,-1,15.28,0,-1,15.30,0,-1,15.31,0,-1,15.80,0,-1,15.98,0,-1,16.15,0,-1,16.38,0,-2,16.83,0,-2,17.15,0,-14,ARL,0
2025-07-17T13:30:01.252457898Z,2025-07-17T13:30:01.252281306Z,10,2,1108,A,A,10,17.150000000,100,43690845,176592,29221845,12.67,100,1,11.69,2,1,11.52,100,1,11.29,100,1,11.24,100,1,11.05,100,1,11.01,100,1,10.93,100,1,10.92,200,2,10.84,100,1,14.74,0,-1,15.28,0,-1,15.30,0,-1,15.31,0,-1,15.80,0,-1,15.98,0,-1,16.15,0,-1,16.38,0,-2,16.83,0,-2,17.15,0,-14,ARL,0
2025-07-17T13:30:01.252457898Z,2025-07-17T13:30:01.252281648Z,10,2,1108,C,A,10,20.480000000,100,38863877,176250,29221846,12.67,100,1,11.69,2,1,11.52,100,1,11.29,100,1,11.24,100,1,11.05,100,1,11.01,100,1,10.93,100,1,10.92,200,2,10.84,100,1,14.74,0,-1,15.28,0,-1,15.30,0,-1,15.31,0,-1,15.80,0,-1,15.98,0,-1,16.15,0,-1,16.38,0,-2,16.83,0,-2,17.15,0,-15,ARL,0
2025-07-17T13:30:01.252457898Z,2025-07-17T13:30:01.252281648Z,10,2,1108,A,A,10,17.150000000,100,43690849,176250,29221846,12.67,100,1,11.69,2,1,11.52,100,1,11.29,100,1,11.24,100,1,11.05,100,1,11.01,100,1,10.93,100,1,10.92,200,2,10.84,100,1,14.74,0,-1,15.28,0,-1,15.30,0,-1,15.31,0,-1,15.80,0,-1,15.98,0,-1,16.15,0,-1,16.38,0,-2,16.83,0,-2,17.15,0,-15,ARL,0
2025-07-17T13:30:01.255007539Z,2025-07-17T13:30:01.254829854Z,10,2,1108,C,B,10,11.690000000,2,43324133,177685,29223480,12.67,100,1,11.69,2,1,11.52,100,1,11.29,100,1,11.24,100,1,11.05,100,1,11.01,100,1,10.93,100,1,10.92,200,2,10.84,100,1,14.74,0,-1,15.28,0,-1,15.30,0,-1,15.31,0,-1,15.80,0,-1,15.98,0,-1,16.15,0,-1,16.38,0,-2,16.83,0,-2,17.15,0,-15,ARL,0
2025-07-17T13:30:01.255007539Z,2025-07-17T13:30:01.254829854Z,10,2,1108,A,B,10,12.330000000,2,43692153,177685,29223480,12.67,100,1,12.33,2,1,11.69,2,1,11.52,100,1,11.29,100,1,11.24,100,1,11.05,100,1,11.01,100,1,10.93,100,1,10.92,200,2,14.74,0,-1,15.28,0,-1,15.30,0,-1,15.31,0,-1,15.80,0,-1,15.98,0,-1,16.15,0,-1,16.38,0,-2,16.83,0,-2,17.15,0,-15,ARL,0
2025-07-17T13:30:01.255016966Z,2025-07-17T13:30:01.254836082Z,10,2,1108,C,A,10,15.310000000,2,43328313,180884,29223485,12.67,100,1,11.69,2,1,11.52,100,1,11.29,100,1,11.24,100,1,11.05,100,1,11.01,100,1,10.93,100,1,10.92,200,2,10.84,100,1,14.74,0,-1,15.28,0,-1,15.30,0,-1,15.31,0,-1,15.80,0,-1,15.98,0,-1,16.15,0,-1,16.38,0,-2,16.83,0,-2,17.15,0,-15,ARL,0
2025-07-17T13:30:01.255016966Z,2025-07-17T13:30:01.254836082Z,10,2,1108,A,A,10,14.650000000,2,43692157,180884,29223485,12.67,100,1,11.69,2,1,11.52,100,1,11.29,100,1,11.24,100,1,11.05,100,1,11.01,100,1,10.93,100,1,10.92,200,2,10.84,100,1,14.74,0,-1,15.28,0,-1,15.30,0,-1,15.31,0,-1,15.80,0,-1,15.98,0,-1,16.15,0,-1,16.38,0,-2,16.83,0,-2,17.15,0,-15,ARL,0
2025-07-17T13:30:01.327109477Z,2025-07-17T13:30:01.326934077Z,10,2,1108,C,B,10,11.520000000,100,42446497,175400,29250087,12.67,100,1,11.69,2,1,11.52,100,1,11.29,100,1,11.24,100,1,11.05,100,1,11.01,100,1,10.93,100,1,10.92,200,2,10.84,100,1,14.65,0,-1,14.74,0,-1,15.28,0,-1,15.30,0,-1,15.31,0,-1,15.80,0,-1,15.98,0,-1,16.15,0,-1,16.38,0,-2,16.83,0,-2,ARL,0
2025-07-17T13:30:01.327894898Z,2025-07-17T13:30:01.327714478Z,10,2,1108,C,A,10,15.610000000,100,42446501,180420,29250293,12.67,100,1,11.69,2,1,11.52,100,1,11.29,100,1,11.24,100,1,11.05,100,1,11.01,100,1,10.93,100,1,10.92,200,2,10.84,100,1,14.65,0,-1,14.74,0,-1,15.28,0,-1,15.30,0,-1,15.31,0,-1,15.80,0,-1,15.98,0,-1,16.15,0,-1,16.38,0,-2,16.83,0,-2,ARL,0
2025-07-17T13:30:01.367410233Z,2025-07-17T13:30:01.367244122Z,10,2,1108,C,B,10,10.930000000,100,41376501,166111,29262273,12.67,100,1,11.69,2,1,11.52,100,1,11.29,100,1,11.24,100,1,11.05,100,1,11.01,100,1,10.93,100,1,10.92,200,2,10.84,100,1,14.65,0,-1,14.74,0,-1,15.28,0,-1,15.30,0,-1,15.31,0,-1,15.80,0,-1,15.98,0,-1,16.15,0,-1,16.38,0,-2,16.83,0,-2,ARL,0
2025-07-17T13:30:01.367410233Z,2025-07-17T13:30:01.367244122Z,10,2,1108,A,B,10,12.330000000,100,43755813,166111,29262273,12.67,100,1,12.33,100,1,11.69,2,1,11.52,100,1,11.29,100,1,11.24,100,1,11.05,100,1,11.01,100,1,10.93,100,1,10.92,200,2,14.65,0,-1,14.74,0,-1,15.28,0,-1,15.30,0,-1,15.31,0,-1,15.80,0,-1,15.98,0,-1,16.15,0,-1,16.38,0,-2,16.83,0,-2,ARL,0
2025-07-17T13:30:01.367421844Z,2025-07-17T13:30:01.367256226Z,10,2,1108,C,A,10,16.380000000,100,41372085,165618,29262274,12.67,100,1,11.69,2,1,11.52,100,1,11.29,100,1,11.24,100,1,11.05,100,1,11.01,100,1,10.93,100,1,10.92,200,2,10.84,100,1,14.65,0,-1,14.74,0,-1,15.28,0,-1,15.30,0,-1,15.31,0,-1,15.80,0,-1,15.98,0,-1,16.15,0,-1,16.38,0,-2,16.83,0,-2,ARL,0
2025-07-17T13:30:01.367421844Z,2025-07-17T13:30:01.367256226Z,10,2,1108,A,A,10,14.340000000,100,43755821,165618,29262274,12.67,100,1,11.69,2,1,11.52,100,1,11.29,100,1,11.24,100,1,11.05,100,1,11.01,100,1,10.93,100,1,10.92,200,2,10.84,100,1,14.65,0,-1,14.74,0,-1,15.28,0,-1,15.30,0,-1,15.31,0,-1,15.80,0,-1,15.98,0,-1,16.15,0,-1,16.38,0,-2,16.83,0,-2,ARL,0
2025-07-17T13:30:01.456631847Z,2025-07-17T13:30:01.456460560Z,10,2,1108,C,B,10,10.920000000,100,43143317,171287,29285993,12.67,100,1,11.69,2,1,11.52,100,1,11.29,100,1,11.24,100,1,11.05,100,1,11.01,100,1,10.93,100,1,10.92,200,2,10.84,100,1,14.34,0,-1,14.65,0,-1,14.74,0,-1,15.28,0,-1,15.30,0,-1,15.31,0,-1,15.80,0,-1,15.98,0,-1,16.15,0,-1,16.38,0,-2,ARL,0
2025-07-17T13:30:01.456631847Z,2025-07-17T13:30:01.456460560Z,10,2,1108,A,B,10,12.360000000,100,43781537,171287,29285993,12.67,100,1,12.36,100,1,11.69,2,1,11.52,100,1,11.29,100,1,11.24,100,1,11.05,100,1,11.01,100,1,10.93,100,1,10.92,200,2,14.34,0,-1,14.65,0,-1,14.74,0,-1,15.28,0,-1,15.30,0,-1,15.31,0,-1,15.80,0,-1,15.98,0,-1,16.15,0,-1,16.38,0,-2,ARL,0
2025-07-17T13:30:01.456642950Z,2025-07-17T13:30:01.456476348Z,10,2,1108,C,A,10,16.200000000,100,43143333,166602,29285996,12.67,100,1,11.69,2,1,11.52,100,1,11.29,100,1,11.24,100,1,11.05,100,1,11.01,100,1,10.93,100,1,10.92,200,2,10.84,100,1,14.34,0,-1,14.65,0,-1,14.74,0,-1,15.28,0,-1,15.30,0,-1,15.31,0,-1,15.80,0,-1,15.98,0,-1,16.15,0,-1,16.38,0,-2,ARL,0
2025-07-17T13:30:01.456642950Z,2025-07-17T13:30:01.456476348Z,10,2,1108,A,A,10,14.900000000,100,43781545,166602,29285996,12.67,100,1,11.69,2,1,11.52,100,1,11.29,100,1,11.24,100,1,11.05,100,1,11.01,100,1,10.93,100,1,10.92,200,2,10.84,100,1,14.34,0,-1,14.65,0,-1,14.74,0,-1,15.28,0,-1,15.30,0,-1,15.31,0,-1,15.80,0,-1,15.98,0,-1,16.15,0,-1,16.38,0,-2,ARL,0
2025-07-17T13:30:01.488050182Z,2025-07-17T13:30:01.487884350Z,10,2,1108,C,B,10,10.920000000,100,43191333,165832,29297612,12.67,100,1,11.69,2,1,11.52,100,1,11.29,100,1,11.24,100,1,11.05,100,1,11.01,100,1,10.93,100,1,10.92,200,2,10.84,100,1,14.34,0,-1,14.65,0,-1,14.74,0,-1,14.90,0,-1,15.28,0,-1,15.30,0,-1,15.31,0,-1,15.80,0,-1,15.98,0,-1,16.15,0,-1,ARL,0
2025-07-17T13:30:01.488050182Z,2025-07-17T13:30:01.487884350Z,10,2,1108,A,B,10,12.360000000,100,43787977,165832,29297612,12.67,100,1,12.36,100,1,11.69,2,1,11.52,100,1,11.29,100,1,11.24,100,1,11.05,100,1,11.01,100,1,10.93,100,1,10.92,200,2,14.34,0,-1,14.65,0,-1,14.74,0,-1,14.90,0,-1,15.28,0,-1,15.30,0,-1,15.31,0,-1,15.80,0,-1,15.98,0,-1,16.15,0,-1,ARL,0
2025-07-17T13:30:01.488082852Z,2025-07-17T13:30:01.487905785Z,10,2,1108,C,A,10,16.200000000,100,43191369,177067,29297619,12.67,100,1,11.69,2,1,11.52,100,1,11.29,100,1,11.24,100,1,11.05,100,1,11.01,100,1,10.93,100,1,10.92,200,2,10.84,100,1,14.34,0,-1,14.65,0,-1,14.74,0,-1,14.90,0,-1,15.28,0,-1,15.30,0,-1,15.31,0,-1,15.80,0,-1,15.98,0,-1,16.15,0,-1,ARL,0
2025-07-17T13:30:01.488082852Z,2025-07-17T13:30:01.487905785Z,10,2,1108,A,A,10,14.900000000,100,43787985,177067,29297619,12.67,100,1,11.69,2,1,11.52,100,1,11.29,100,1,11.24,100,1,11.05,100,1,11.01,100,1,10.93,100,1,10.92,200,2,10.84,100,1,14.34,0,-1,14.65,0,-1,14.74,0,-1,14.90,0,-1,15.28,0,-1,15.30,0,-1,15.31,0,-1,15.80,0,-1,15.98,0,-1,16.15,0,-1,ARL,0
2025-07-17T13:30:01.488981292Z,2025-07-17T13:30:01.488809902Z,10,2,1108,C,A,10,17.230000000,100,43314561,171390,29298089,12.67,100,1,11.69,2,1,11.52,100,1,11.29,100,1,11.24,100,1,11.05,100,1,11.01,100,1,10.93,100,1,10.92,200,2,10.84,100,1,14.34,0,-1,14.65,0,-1,14.74,0,-1,14.90,0,-2,15.28,0,-1,15.30,0,-1,15.31,0,-1,15.80,0,-1,15.98,0,-1,16.15,0,-1,ARL,0
2025-07-17T13:30:01.489038112Z,2025-07-17T13:30:01.488866053Z,10,2,1108,A,A,10,16.080000000,100,43788313,172059,29298118,12.67,100,1,11.69,2,1,11.52,100,1,11.29,100,1,11.24,100,1,11.05,100,1,11.01,100,1,10.93,100,1,10.92,200,2,10.84,100,1,14.34,0,-1,14.65,0,-1,14.74,0,-1,14.90,0,-2,15.28,0,-1,15.30,0,-1,15.31,0,-1,15.80,0,-1,15.98,0,-1,16.15,0,-1,ARL,0
2025-07-17T13:30:01.532444998Z,2025-07-17T13:30:01.532274368Z,10,2,1108,A,B,10,12.460000000,100,43804025,170630,29318499,12.67,100,1,12.46,100,1,11.69,2,1,11.52,100,1,11.29,100,1,11.24,100,1,11.05,100,1,11.01,100,1,10.93,100,1,10.92,200,2,14.34,0,-1,14.65,0,-1,14.74,0,-1,14.90,0,-2,15.28,0,-1,15.30,0,-1,15.31,0,-1,15.80,0,-1,15.98,0,-1,16.15,0,-1,ARL,0
2025-07-17T13:30:01.532474492Z,2025-07-17T13:30:01.532293890Z,10,2,1108,C,B,10,11.050000000,100,42089321,180602,29318513,12.67,100,1,11.69,2,1,11.52,100,1,11.29,100,1,11.24,100,1,11.05,100,1,11.01,100,1,10.93,100,1,10.92,200,2,10.84,100,1,14.34,0,-1,14.65,0,-1,14.74,0,-1,14.90,0,-2,15.28,0,-1,15.30,0,-1,15.31,0,-1,15.80,0,-1,15.98,0,-1,16.15,0,-1,ARL,0
2025-07-17T13:30:01.532498294Z,2025-07-17T13:30:01.532324961Z,10,2,1108,A,A,10,14.200000000,100,43804081,173333,29318528,12.67,100,1,11.69,2,1,11.52,100,1,11.29,100,1,11.24,100,1,11.05,100,1,11.01,100,1,10.93,100,1,10.92,200,2,10.84,100,1,14.34,0,-1,14.65,0,-1,14.74,0,-1,14.90,0,-2,15.28,0,-1,15.30,0,-1,15.31,0,-1,15.80,0,-1,15.98,0,-1,16.15,0,-1,ARL,0
2025-07-17T13:30:01.532528215Z,2025-07-17T13:30:01.532347519Z,10,2,1108,C,A,10,16.220000000,100,42089325,180696,29318534,12.67,100,1,11.69,2,1,11.52,100,1,11.29,100,1,11.24,100,1,11.05,100,1,11.01,100,1,10.93,100,1,10.92,200,2,10.84,100,1,14.20,0,-1,14.34,0,-1,14.65,0,-1,14.74,0,-1,14.90,0,-2,15.28,0,-1,15.30,0,-1,15.31,0,-1,15.80,0,-1,15.98,0,-1,ARL,0
2025-07-17T13:30:01.537373659Z,2025-07-17T13:30:01.537195873Z,10,2,1108,A,B,10,12.990000000,100,43805737,177786,29320724,12.99,100,1,12.67,100,1,11.69,2,1,11.52,100,1,11.29,100,1,11.24,100,1,11.05,100,1,11.01,100,1,10.93,100,1,10.92,200,2,14.20,0,-1,14.34,0,-1,14.65,0,-1,14.74,0,-1,14.90,0,-2,15.28,0,-1,15.30,0,-1,15.31,0,-1,15.80,0,-1,15.98,0,-1,ARL,0
2025-07-17T13:30:01.537387032Z,2025-07-17T13:30:01.537219414Z,10,2,1108,A,A,10,14.650000000,100,43805773,167618,29320743,12.99,100,1,12.67,100,1,11.69,2,1,11.52,100,1,11.29,100,1,11.24,100,1,11.05,100,1,11.01,100,1,10.93,100,1,10.92,200,2,14.20,0,-1,14.34,0,-1,14.65,0,-1,14.74,0,-1,14.90,0,-2,15.28,0,-1,15.30,0,-1,15.31,0,-1,15.80,0,-1,15.98,0,-1,ARL,0
2025-07-17T13:30:01.571558801Z,2025-07-17T13:30:01.571375465Z,10,2,1108,A,B,10,13.200000000,28,43820541,183336,29336931,13.20,28,1,12.99,100,1,12.67,100,1,11.69,2,1,11.52,100,1,11.29,100,1,11.24,100,1,11.05,100,1,11.01,100,1,10.93,100,1,14.20,0,-1,14.34,0,-1,14.65,0,-1,14.74,0,-1,14.90,0,-2,15.28,0,-1,15.30,0,-1,15.31,0,-1,15.80,0,-1,15.98,0,-1,ARL,0
2025-07-17T13:30:01.589767581Z,2025-07-17T13:30:01.589592733Z,10,2,1108,C,A,10,17.230000000,100,43317185,174848,29345825,12.99,100,1,12.67,100,1,11.69,2,1,11.52,100,1,11.29,100,1,11.24,100,1,11.05,100,1,11.01,100,1,10.93,100,1,10.92,200,2,14.20,0,-1,14.34,0,-1,14.65,0,-1,14.74,0,-1,14.90,0,-2,15.28,0,-1,15.30,0,-1,15.31,0,-1,15.80,0,-1,15.98,0,-1,ARL,0
2025-07-17T13:30:01.590564534Z,2025-07-17T13:30:01.590381387Z,10,2,1108,A,A,10,16.080000000,100,43826261,183147,29346224,12.99,100,1,12.67,100,1,11.69,2,1,11.52,100,1,11.29,100,1,11.24,100,1,11.05,100,1,11.01,100,1,10.93,100,1,10.92,200,2,14.20,0,-1,14.34,0,-1,14.65,0,-1,14.74,0,-1,14.90,0,-2,15.28,0,-1,15.30,0,-1,15.31,0,-1,15.80,0,-1,15.98,0,-1,ARL,0
2025-07-17T13:30:01.592691520Z,2025-07-17T13:30:01.592507554Z,10,2,1108,C,B,10,9.990000000,100,41376769,183966,29347436,12.99,100,1,12.67,100,1,11.69,2,1,11.52,100,1,11.29,100,1,11.24,100,1,11.05,100,1,11.01,100,1,10.93,100,1,10.92,200,2,14.20,0,-1,14.34,0,-1,14.65,0,-1,14.74,0,-1,14.90,0,-2,15.28,0,-1,15.30,0,-1,15.31,0,-1,15.80,0,-1,15.98,0,-1,ARL,0
2025-07-17T13:30:01.592691520Z,2025-07-17T13:30:01.592507554Z,10,2,1108,A,B,10,11.270000000,100,43826785,183966,29347436,12.99,100,1,12.67,100,1,11.69,2,1,11.52,100,1,11.29,100,1,11.27,100,1,11.24,100,1,11.05,100,1,11.01,100,1,10.93,100,1,14.20,0,-1,14.34,0,-1,14.65,0,-1,14.74,0,-1,14.90,0,-2,15.28,0,-1,15.30,0,-1,15.31,0,-1,15.80,0,-1,15.98,0,-1,ARL,0
2025-07-17T13:30:01.592712062Z,2025-07-17T13:30:01.592539240Z,10,2,1108,C,A,10,17.600000000,100,41372493,172822,29347463,12.99,100,1,12.67,100,1,11.69,2,1,11.52,100,1,11.29,100,1,11.24,100,1,11.05,100,1,11.01,100,1,10.93,100,1,10.92,200,2,14.20,0,-1,14.34,0,-1,14.65,0,-1,14.74,0,-1,14.90,0,-2,15.28,0,-1,15.30,0,-1,15.31,0,-1,15.80,0,-1,15.98,0,-1,ARL,0
2025-07-17T13:30:01.592712062Z,2025-07-17T13:30:01.592539240Z,10,2,1108,A,A,10,15.410000000,100,43826805,172822,29347463,12.99,100,1,12.67,100,1,11.69,2,1,11.52,100,1,11.29,100,1,11.24,100,1,11.05,100,1,11.01,100,1,10.93,100,1,10.92,200,2,14.20,0,-1,14.34,0,-1,14.65,0,-1,14.74,0,-1,14.90,0,-2,15.28,0,-1,15.30,0,-1,15.31,0,-1,15.80,0,-1,15.98,0,-1,ARL,0
2025-07-17T13:30:01.662123703Z,2025-07-17T13:30:01.661958252Z,10,2,1108,C,B,10,10.580000000,100,41377117,165451,29378719,12.99,100,1,12.67,100,1,11.69,2,1,11.52,100,1,11.29,100,1,11.24,100,1,11.05,100,1,11.01,100,1,10.93,100,1,10.92,200,2,14.20,0,-1,14.34,0,-1,14.65,0,-1,14.74,0,-1,14.90,0,-2,15.28,0,-1,15.30,0,-1,15.31,0,-1,15.41,0,-1,15.80,0,-1,ARL,0
2025-07-17T13:30:01.662123703Z,2025-07-17T13:30:01.661958252Z,10,2,1108,A,B,10,11.930000000,100,43852121,165451,29378719,12.99,100,1,12.67,100,1,11.93,100,1,11.69,2,1,11.52,100,1,11.29,100,1,11.24,100,1,11.05,100,1,11.01,100,1,10.93,100,1,14.20,0,-1,14.34,0,-1,14.65,0,-1,14.74,0,-1,14.90,0,-2,15.28,0,-1,15.30,0,-1,15.31,0,-1,15.41,0,-1,15.80,0,-1,ARL,0
2025-07-17T13:30:01.662159610Z,2025-07-17T13:30:01.661989524Z,10,2,1108,C,A,10,16.830000000,100,41372469,170086,29378727,12.99,100,1,12.67,100,1,11.69,2,1,11.52,100,1,11.29,100,1,11.24,100,1,11.05,100,1,11.01,100,1,10.93,100,1,10.92,200,2,14.20,0,-1,14.34,0,-1,14.65,0,-1,14.74,0,-1,14.90,0,-2,15.28,0,-1,15.30,0,-1,15.31,0,-1,15.41,0,-1,15.80,0,-1,ARL,0
2025-07-17T13:30:01.662159610Z,2025-07-17T13:30:01.661989524Z,10,2,1108,A,A,10,14.740000000,100,43852129,170086,29378727,12.99,100,1,12.67,100,1,11.69,2,1,11.52,100,1,11.29,100,1,11.24,100,1,11.05,100,1,11.01,100,1,10.93,100,1,10.92,200,2,14.20,0,-1,14.34,0,-1,14.65,0,-1,14.74,0,-1,14.90,0,-2,15.28,0,-1,15.30,0,-1,15.31,0,-1,15.41,0,-1,15.80,0,-1,ARL,0
2025-07-17T13:30:01.929560509Z,2025-07-17T13:30:01.929395142Z,10,2,1108,C,A,10,14.650000000,100,43805773,165367,29480243,12.99,100,1,12.67,100,1,11.69,2,1,11.52,100,1,11.29,100,1,11.24,100,1,11.05,100,1,11.01,100,1,10.93,100,1,10.92,200,2,14.20,0,-1,14.34,0,-1,14.65,0,-1,14.74,0,-2,14.90,0,-2,15.28,0,-1,15.30,0,-1,15.31,0,-1,15.41,0,-1,15.80,0,-1,ARL,0
2025-07-17T13:30:01.930966377Z,2025-07-17T13:30:01.930800767Z,10,2,1108,A,A,10,13.670000000,100,43953649,165610,29480698,12.99,100,1,12.67,100,1,11.69,2,1,11.52,100,1,11.29,100,1,11.24,100,1,11.05,100,1,11.01,100,1,10.93,100,1,10.92,200,2,14.20,0,-1,14.34,0,-1,14.65,0,-1,14.74,0,-2,14.90,0,-2,15.28,0,-1,15.30,0,-1,15.31,0,-1,15.41,0,-1,15.80,0,-1,ARL,0
2025-07-17T13:30:02.209154979Z,2025-07-17T13:30:02.208989359Z,10,2,1108,A,A,10,17.150000000,100,44040361,165620,29556866,12.99,100,1,12.67,100,1,11.69,2,1,11.52,100,1,11.29,100,1,11.24,100,1,11.05,100,1,11.01,100,1,10.93,100,1,10.92,200,2,14.20,0,-1,14.34,0,-1,14.65,0,-1,14.74,0,-2,14.90,0,-2,15.28,0,-1,15.30,0,-1,15.31,0,-1,15.41,0,-1,15.80,0,-1,ARL,0
2025-07-17T13:30:02.209170665Z,2025-07-17T13:30:02.209004229Z,10,2,1108,A,B,10,9.550000000,100,44040369,166436,29556867,12.99,100,1,12.67,100,1,11.69,2,1,11.52,100,1,11.29,100,1,11.24,100,1,11.05,100,1,11.01,100,1,10.93,100,1,10.92,200,2,14.20,0,-1,14.34,0,-1,14.65,0,-1,14.74,0,-2,14.90,0,-2,15.28,0,-1,15.30,0,-1,15.31,0,-1,15.41,0,-1,15.80,0,-1,ARL,0
2025-07-17T13:30:02.378440054Z,2025-07-17T13:30:02.378274380Z,10,2,1108,A,B,10,12.730000000,100,44066409,165674,29585499,12.99,100,1,12.73,100,1,12.67,100,1,11.69,2,1,11.52,100,1,11.29,100,1,11.24,100,1,11.05,100,1,11.01,100,1,10.93,100,1,14.20,0,-1,14.34,0,-1,14.65,0,-1,14.74,0,-2,14.90,0,-2,15.28,0,-1,15.30,0,-1,15.31,0,-1,15.41,0,-1,15.80,0,-1,ARL,0
2025-07-17T13:30:02.378446229Z,2025-07-17T13:30:02.378280610Z,10,2,1108,A,A,10,13.930000000,100,44066417,165619,29585501,12.99,100,1,12.73,100,1,12.67,100,1,11.69,2,1,11.52,100,1,11.29,100,1,11.24,100,1,11.05,100,1,11.01,100,1,10.93,100,1,14.20,0,-1,14.34,0,-1,14.65,0,-1,14.74,0,-2,14.90,0,-2,15.28,0,-1,15.30,0,-1,15.31,0,-1,15.41,0,-1,15.80,0,-1,ARL,0
2025-07-17T13:30:02.378454598Z,2025-07-17T13:30:02.378286605Z,10,2,1108,C,B,10,11.290000000,100,42099317,167993,29585502,12.99,100,1,12.73,100,1,12.67,100,1,11.69,2,1,11.52,100,1,11.29,100,1,11.24,100,1,11.05,100,1,11.01,100,1,10.93,100,1,13.93,0,-1,14.20,0,-1,14.34,0,-1,14.65,0,-1,14.74,0,-2,14.90,0,-2,15.28,0,-1,15.30,0,-1,15.31,0,-1,15.41,0,-1,ARL,0
2025-07-17T13:30:02.378458883Z,2025-07-17T13:30:02.378293244Z,10,2,1108,C,A,10,15.910000000,100,42099321,165639,29585504,12.99,100,1,12.73,100,1,12.67,100,1,11.69,2,1,11.52,100,1,11.29,100,1,11.24,100,1,11.05,100,1,11.01,100,1,10.93,100,1,13.93,0,-1,14.20,0,-1,14.34,0,-1,14.65,0,-1,14.74,0,-2,14.90,0,-2,15.28,0,-1,15.30,0,-1,15.31,0,-1,15.41,0,-1,ARL,0
2025-07-17T13:30:02.476983806Z,2025-07-17T13:30:02.476818222Z,10,2,1108,C,A,10,14.900000000,100,43781545,165584,29601178,12.99,100,1,12.73,100,1,12.67,100,1,11.69,2,1,11.52,100,1,11.29,100,1,11.24,100,1,11.05,100,1,11.01,100,1,10.93,100,1,13.93,0,-1,14.20,0,-1,14.34,0,-1,14.65,0,-1,14.74,0,-2,14.90,0,-2,15.28,0,-1,15.30,0,-1,15.31,0,-1,15.41,0,-1,ARL,0
2025-07-17T13:30:02.476983806Z,2025-07-17T13:30:02.476818222Z,10,2,1108,A,A,10,14.570000000,100,44076709,165584,29601178,12.99,100,1,12.73,100,1,12.67,100,1,11.69,2,1,11.52,100,1,11.29,100,1,11.24,100,1,11.05,100,1,11.01,100,1,10.93,100,1,13.93,0,-1,14.20,0,-1,14.34,0,-1,14.65,0,-1,14.74,0,-2,14.90,0,-2,15.28,0,-1,15.30,0,-1,15.31,0,-1,15.41,0,-1,ARL,0
2025-07-17T13:30:02.483297761Z,2025-07-17T13:30:02.483131658Z,10,2,1108,C,A,10,14.900000000,100,43787985,166103,29601999,12.99,100,1,12.73,100,1,12.67,100,1,11.69,2,1,11.52,100,1,11.29,100,1,11.24,100,1,11.05,100,1,11.01,100,1,10.93,100,1,13.93,0,-1,14.20,0,-1,14.34,0,-1,14.57,0,-1,14.65,0,-1,14.74,0,-2,14.90,0,-2,15.28,0,-1,15.30,0,-1,15.31,0,-1,ARL,0
2025-07-17T13:30:02.483297761Z,2025-07-17T13:30:02.483131658Z,10,2,1108,A,A,10,14.570000000,100,44077497,166103,29601999,12.99,100,1,12.73,100,1,12.67,100,1,11.69,2,1,11.52,100,1,11.29,100,1,11.24,100,1,11.05,100,1,11.01,100,1,10.93,100,1,13.93,0,-1,14.20,0,-1,14.34,0,-1,14.57,0,-1,14.65,0,-1,14.74,0,-2,14.90,0,-2,15.28,0,-1,15.30,0,-1,15.31,0,-1,ARL,0
2025-07-17T13:30:02.524921786Z,2025-07-17T13:30:02.524755932Z,10,2,1108,C,B,10,8.580000000,100,41376733,165854,29608933,12.99,100,1,12.73,100,1,12.67,100,1,11.69,2,1,11.52,100,1,11.29,100,1,11.24,100,1,11.05,100,1,11.01,100,1,10.93,100,1,13.93,0,-1,14.20,0,-1,14.34,0,-1,14.57,0,-2,14.65,0,-1,14.74,0,-2,14.90,0,-2,15.28,0,-1,15.30,0,-1,15.31,0,-1,ARL,0
2025-07-17T13:30:02.524921786Z,2025-07-17T13:30:02.524755932Z,10,2,1108,A,B,10,9.670000000,100,44082961,165854,29608933,12.99,100,1,12.73,100,1,12.67,100,1,11.69,2,1,11.52,100,1,11.29,100,1,11.24,100,1,11.05,100,1,11.01,100,1,10.93,100,1,13.93,0,-1,14.20,0,-1,14.34,0,-1,14.57,0,-2,14.65,0,-1,14.74,0,-2,14.90,0,-2,15.28,0,-1,15.30,0,-1,15.31,0,-1,ARL,0
2025-07-17T13:30:02.524935181Z,2025-07-17T13:30:02.524769583Z,10,2,1108,C,A,10,19.440000000,100,41372549,165598,29608936,12.99,100,1,12.73,100,1,12.67,100,1,11.69,2,1,11.52,100,1,11.29,100,1,11.24,100,1,11.05,100,1,11.01,100,1,10.93,100,1,13.93,0,-1,14.20,0,-1,14.34,0,-1,14.57,0,-2,14.65,0,-1,14.74,0,-2,14.90,0,-2,15.28,0,-1,15.30,0,-1,15.31,0,-1,ARL,0
2025-07-17T13:30:02.524935181Z,2025-07-17T13:30:02.524769583Z,10,2,1108,A,A,10,17.020000000,100,44082969,165598,29608936,12.99,100,1,12.73,100,1,12.67,100,1,11.69,2,1,11.52,100,1,11.29,100,1,11.24,100,1,11.05,100,1,11.01,100,1,10.93,100,1,13.93,0,-1,14.20,0,-1,14.34,0,-1,14.57,0,-2,14.65,0,-1,14.74,0,-2,14.90,0,-2,15.28,0,-1,15.30,0,-1,15.31,0,-1,ARL,0
2025-07-17T13:30:02.573774313Z,2025-07-17T13:30:02.573606685Z,10,2,1108,C,B,10,10.930000000,100,41379985,167628,29618524,12.99,100,1,12.73,100,1,12.67,100,1,11.69,2,1,11.52,100,1,11.29,100,1,11.24,100,1,11.05,100,1,11.01,100,1,10.93,100,1,13.93,0,-1,14.20,0,-1,14.34,0,-1,14.57,0,-2,14.65,0,-1,14.74,0,-2,14.90,0,-2,15.28,0,-1,15.30,0,-1,15.31,0,-1,ARL,0
2025-07-17T13:30:02.573774313Z,2025-07-17T13:30:02.573606685Z,10,2,1108,A,B,10,12.330000000,100,44088633,167628,29618524,12.99,100,1,12.73,100,1,12.67,100,1,12.33,100,1,11.69,2,1,11.52,100,1,11.29,100,1,11.24,100,1,11.05,100,1,11.01,100,1,13.93,0,-1,14.20,0,-1,14.34,0,-1,14.57,0,-2,14.65,0,-1,14.74,0,-2,14.90,0,-2,15.28,0,-1,15.30,0,-1,15.31,0,-1,ARL,0
2025-07-17T13:30:02.573792046Z,2025-07-17T13:30:02.573623478Z,10,2,1108,C,A,10,16.380000000,100,41372369,168568,29618531,12.99,100,1,12.73,100,1,12.67,100,1,11.69,2,1,11.52,100,1,11.29,100,1,11.24,100,1,11.05,100,1,11.01,100,1,10.93,100,1,13.93,0,-1,14.20,0,-1,14.34,0,-1,14.57,0,-2,14.65,0,-1,14.74,0,-2,14.90,0,-2,15.28,0,-1,15.30,0,-1,15.31,0,-1,ARL,0
2025-07-17T13:30:02.573792046Z,2025-07-17T13:30:02.573623478Z,10,2,1108,A,A,10,14.340000000,100,44088637,168568,29618531,12.99,100,1,12.73,100,1,12.67,100,1,11.69,2,1,11.52,100,1,11.29,100,1,11.24,100,1,11.05,100,1,11.01,100,1,10.93,100,1,13.93,0,-1,14.20,0,-1,14.34,0,-1,14.57,0,-2,14.65,0,-1,14.74,0,-2,14.90,0,-2,15.28,0,-1,15.30,0,-1,15.31,0,-1,ARL,0
2025-07-17T13:30:06.757549069Z,2025-07-17T13:30:06.757383618Z,10,2,1108,A,A,10,14.270000000,700,44491681,165451,30107583,12.99,100,1,12.73,100,1,12.67,100,1,11.69,2,1,11.52,100,1,11.29,100,1,11.24,100,1,11.05,100,1,11.01,100,1,10.93,100,1,13.93,0,-1,14.20,0,-1,14.34,0,-1,14.57,0,-2,14.65,0,-1,14.74,0,-2,14.90,0,-2,15.28,0,-1,15.30,0,-1,15.31,0,-1,ARL,0
2025-07-17T13:30:06.757600916Z,2025-07-17T13:30:06.757435491Z,10,2,1108,C,A,10,16.150000000,700,41528029,165425,30107590,12.99,100,1,12.73,100,1,12.67,100,1,11.69,2,1,11.52,100,1,11.29,100,1,11.24,100,1,11.05,100,1,11.01,100,1,10.93,100,1,13.93,0,-1,14.20,0,-1,14.27,0,-1,14.34,0,-1,14.57,0,-2,14.65,0,-1,14.74,0,-2,14.90,0,-2,15.28,0,-1,15.30,0,-1,ARL,0
2025-07-17T13:30:07.195006880Z,2025-07-17T13:30:07.194841610Z,10,2,1108,A,A,10,15.300000000,700,44520965,165270,30150210,12.99,100,1,12.73,100,1,12.67,100,1,11.69,2,1,11.52,100,1,11.29,100,1,11.24,100,1,11.05,100,1,11.01,100,1,10.93,100,1,13.93,0,-1,14.20,0,-1,14.27,0,-1,14.34,0,-1,14.57,0,-2,14.65,0,-1,14.74,0,-2,14.90,0,-2,15.28,0,-1,15.30,0,-1,ARL,0
2025-07-17T13:30:07.195046929Z,2025-07-17T13:30:07.194880522Z,10,2,1108,C,A,10,16.300000000,700,41375973,166407,30150214,12.99,100,1,12.73,100,1,12.67,100,1,11.69,2,1,11.52,100,1,11.29,100,1,11.24,100,1,11.05,100,1,11.01,100,1,10.93,100,1,13.93,0,-1,14.20,0,-1,14.27,0,-1,14.34,0,-1,14.57,0,-2,14.65,0,-1,14.74,0,-2,14.90,0,-2,15.28,0,-1,15.30,0,-2,ARL,0
2025-07-17T13:30:07.395047633Z,2025-07-17T13:30:07.394882479Z,10,2,1108,A,A,10,15.000000000,700,44533061,165154,30169157,12.99,100,1,12.73,100,1,12.67,100,1,11.69,2,1,11.52,100,1,11.29,100,1,11.24,100,1,11.05,100,1,11.01,100,1,10.93,100,1,13.93,0,-1,14.20,0,-1,14.27,0,-1,14.34,0,-1,14.57,0,-2,14.65,0,-1,14.74,0,-2,14.90,0,-2,15.28,0,-1,15.30,0,-2,ARL,0
2025-07-17T13:30:07.395522844Z,2025-07-17T13:30:07.395357697Z,10,2,1108,C,A,10,15.300000000,700,44520965,165147,30169278,12.99,100,1,12.73,100,1,12.67,100,1,11.69,2,1,11.52,100,1,11.29,100,1,11.24,100,1,11.05,100,1,11.01,100,1,10.93,100,1,13.93,0,-1,14.20,0,-1,14.27,0,-1,14.34,0,-1,14.57,0,-2,14.65,0,-1,14.74,0,-2,14.90,0,-2,15.00,0,-1,15.28,0,-1,ARL,0
2025-07-17T13:30:07.594948559Z,2025-07-17T13:30:07.594772046Z,10,2,1108,A,A,10,14.700000000,700,44545381,176513,30189080,12.99,100,1,12.73,100,1,12.67,100,1,11.69,2,1,11.52,100,1,11.29,100,1,11.24,100,1,11.05,100,1,11.01,100,1,10.93,100,1,13.93,0,-1,14.20,0,-1,14.27,0,-1,14.34,0,-1,14.57,0,-2,14.65,0,-1,14.74,0,-2,14.90,0,-2,15.00,0,-1,15.28,0,-1,ARL,0
2025-07-17T13:30:07.594962236Z,2025-07-17T13:30:07.594797098Z,10,2,1108,C,A,10,15.000000000,700,44533061,165138,30189120,12.99,100,1,12.73,100,1,12.67,100,1,11.69,2,1,11.52,100,1,11.29,100,1,11.24,100,1,11.05,100,1,11.01,100,1,10.93,100,1,13.93,0,-1,14.20,0,-1,14.27,0,-1,14.34,0,-1,14.57,0,-2,14.65,0,-1,14.70,0,-1,14.74,0,-2,14.90,0,-2,15.00,0,-1,ARL,0
2025-07-17T13:30:07.663249150Z,2025-07-17T13:30:07.663083798Z,10,2,1108,A,A,10,14.460000000,700,44548325,165352,30194197,12.99,100,1,12.73,100,1,12.67,100,1,11.69,2,1,11.52,100,1,11.29,100,1,11.24,100,1,11.05,100,1,11.01,100,1,10.93,100,1,13.93,0,-1,14.20,0,-1,14.27,0,-1,14.34,0,-1,14.57,0,-2,14.65,0,-1,14.70,0,-1,14.74,0,-2,14.90,0,-2,15.00,0,-1,ARL,0
2025-07-17T13:30:07.663963574Z,2025-07-17T13:30:07.663798482Z,10,2,1108,C,A,10,14.700000000,700,44545381,165092,30194234,12.99,100,1,12.73,100,1,12.67,100,1,11.69,2,1,11.52,100,1,11.29,100,1,11.24,100,1,11.05,100,1,11.01,100,1,10.93,100,1,13.93,0,-1,14.20,0,-1,14.27,0,-1,14.34,0,-1,14.46,0,-1,14.57,0,-2,14.65,0,-1,14.70,0,-1,14.74,0,-2,14.90,0,-2,ARL,0
2025-07-17T13:30:07.914437226Z,2025-07-17T13:30:07.914271879Z,10,2,1108,A,B,10,11.760000000,700,44560257,165347,30213834,12.99,100,1,12.73,100,1,12.67,100,1,11.76,700,1,11.69,2,1,11.52,100,1,11.29,100,1,11.24,100,1,11.05,100,1,11.01,100,1,13.93,0,-1,14.20,0,-1,14.27,0,-1,14.34,0,-1,14.46,0,-1,14.57,0,-2,14.65,0,-1,14.70,0,-1,14.74,0,-2,14.90,0,-2,ARL,0
2025-07-17T13:30:07.915115414Z,2025-07-17T13:30:07.914949951Z,10,2,1108,C,B,10,10.990000000,700,41509393,165463,30213941,12.99,100,1,12.73,100,1,12.67,100,1,11.69,2,1,11.52,100,1,11.29,100,1,11.24,100,1,11.05,100,1,11.01,100,1,10.93,100,1,13.93,0,-1,14.20,0,-1,14.27,0,-1,14.34,0,-1,14.46,0,-1,14.57,0,-2,14.65,0,-1,14.70,0,-1,14.74,0,-2,14.90,0,-2,ARL,0
2025-07-17T13:30:08.025826192Z,2025-07-17T13:30:08.025660842Z,10,2,1108,A,B,10,12.020000000,700,44565617,165350,30224657,12.99,100,1,12.73,100,1,12.67,100,1,12.02,700,1,11.69,2,1,11.52,100,1,11.29,100,1,11.24,100,1,11.05,100,1,11.01,100,1,13.93,0,-1,14.20,0,-1,14.27,0,-1,14.34,0,-1,14.46,0,-1,14.57,0,-2,14.65,0,-1,14.70,0,-1,14.74,0,-2,14.90,0,-2,ARL,0
2025-07-17T13:30:08.025838588Z,2025-07-17T13:30:08.025673570Z,10,2,1108,C,B,10,11.760000000,700,44560257,165018,30224658,12.99,100,1,12.73,100,1,12.67,100,1,11.69,2,1,11.52,100,1,11.29,100,1,11.24,100,1,11.05,100,1,11.01,100,1,10.93,100,1,13.93,0,-1,14.20,0,-1,14.27,0,-1,14.34,0,-1,14.46,0,-1,14.57,0,-2,14.65,0,-1,14.70,0,-1,14.74,0,-2,14.90,0,-2,ARL,0
2025-07-17T13:30:08.114437837Z,2025-07-17T13:30:08.114272470Z,10,2,1108,A,B,10,12.260000000,700,44570585,165367,30233944,12.99,100,1,12.73,100,1,12.67,100,1,12.26,700,1,11.69,2,1,11.52,100,1,11.29,100,1,11.24,100,1,11.05,100,1,11.01,100,1,13.93,0,-1,14.20,0,-1,14.27,0,-1,14.34,0,-1,14.46,0,-1,14.57,0,-2,14.65,0,-1,14.70,0,-1,14.74,0,-2,14.90,0,-2,ARL,0
2025-07-17T13:30:08.115234484Z,2025-07-17T13:30:08.115068904Z,10,2,1108,C,B,10,12.020000000,700,44565617,165580,30234078,12.99,100,1,12.73,100,1,12.67,100,1,11.69,2,1,11.52,100,1,11.29,100,1,11.24,100,1,11.05,100,1,11.01,100,1,10.93,100,1,13.93,0,-1,14.20,0,-1,14.27,0,-1,14.34,0,-1,14.46,0,-1,14.57,0,-2,14.65,0,-1,14.70,0,-1,14.74,0,-2,14.90,0,-2,ARL,0
2025-07-17T13:30:08.394538665Z,2025-07-17T13:30:08.394373251Z,10,2,1108,A,B,10,13.250000000,11,44586753,165414,30258008,13.25,11,1,12.99,100,1,12.73,100,1,12.67,100,1,11.69,2,1,11.52,100,1,11.29,100,1,11.24,100,1,11.05,100,1,11.01,100,1,13.93,0,-1,14.20,0,-1,14.27,0,-1,14.34,0,-1,14.46,0,-1,14.57,0,-2,14.65,0,-1,14.70,0,-1,14.74,0,-2,14.90,0,-2,ARL,0
2025-07-17T13:30:08.402177882Z,2025-07-17T13:30:08.402012613Z,10,2,1108,C,B,10,13.200000000,28,43820541,165269,30259240,12.99,100,1,12.73,100,1,12.67,100,1,11.69,2,1,11.52,100,1,11.29,100,1,11.24,100,1,11.05,100,1,11.01,100,1,10.93,100,1,13.93,0,-1,14.20,0,-1,14.27,0,-1,14.34,0,-1,14.46,0,-1,14.57,0,-2,14.65,0,-1,14.70,0,-1,14.74,0,-2,14.90,0,-2,ARL,0
2025-07-17T13:30:08.512744920Z,2025-07-17T13:30:08.512579639Z,10,2,1108,A,A,10,14.260000000,700,44598153,165281,30276907,12.99,100,1,12.73,100,1,12.67,100,1,11.69,2,1,11.52,100,1,11.29,100,1,11.24,100,1,11.05,100,1,11.01,100,1,10.93,100,1,13.93,0,-1,14.20,0,-1,14.27,0,-1,14.34,0,-1,14.46,0,-1,14.57,0,-2,14.65,0,-1,14.70,0,-1,14.74,0,-2,14.90,0,-2,ARL,0
2025-07-17T13:30:08.513140882Z,2025-07-17T13:30:08.512974877Z,10,2,1108,C,A,10,16.110000000,700,41371225,166005,30276990,12.99,100,1,12.73,100,1,12.67,100,1,11.69,2,1,11.52,100,1,11.29,100,1,11.24,100,1,11.05,100,1,11.01,100,1,10.93,100,1,13.93,0,-1,14.20,0,-1,14.26,0,-1,14.27,0,-1,14.34,0,-1,14.46,0,-1,14.57,0,-2,14.65,0,-1,14.70,0,-1,14.74,0,-2,ARL,0
2025-07-17T13:30:09.129158268Z,2025-07-17T13:30:09.128991840Z,10,2,1108,A,B,10,11.760000000,700,44628617,166428,30336805,12.99,100,1,12.73,100,1,12.67,100,1,11.76,700,1,11.69,2,1,11.52,100,1,11.29,100,1,11.24,100,1,11.05,100,1,11.01,100,1,13.93,0,-1,14.20,0,-1,14.26,0,-1,14.27,0,-1,14.34,0,-1,14.46,0,-1,14.57,0,-2,14.65,0,-1,14.70,0,-1,14.74,0,-2,ARL,0
2025-07-17T13:30:09.129171567Z,2025-07-17T13:30:09.129006013Z,10,2,1108,C,B,10,11.070000000,700,41539477,165554,30336807,12.99,100,1,12.73,100,1,12.67,100,1,11.69,2,1,11.52,100,1,11.29,100,1,11.24,100,1,11.05,100,1,11.01,100,1,10.93,100,1,13.93,0,-1,14.20,0,-1,14.26,0,-1,14.27,0,-1,14.34,0,-1,14.46,0,-1,14.57,0,-2,14.65,0,-1,14.70,0,-1,14.74,0,-2,ARL,0
2025-07-17T13:30:09.329216559Z,2025-07-17T13:30:09.329050977Z,10,2,1108,A,B,10,12.020000000,700,44641397,165582,30353905,12.99,100,1,12.73,100,1,12.67,100,1,12.02,700,1,11.69,2,1,11.52,100,1,11.29,100,1,11.24,100,1,11.05,100,1,11.01,100,1,13.93,0,-1,14.20,0,-1,14.26,0,-1,14.27,0,-1,14.34,0,-1,14.46,0,-1,14.57,0,-2,14.65,0,-1,14.70,0,-1,14.74,0,-2,ARL,0
2025-07-17T13:30:09.329283504Z,2025-07-17T13:30:09.329118219Z,10,2,1108,C,B,10,11.760000000,700,44628617,165285,30353910,12.99,100,1,12.73,100,1,12.67,100,1,11.69,2,1,11.52,100,1,11.29,100,1,11.24,100,1,11.05,100,1,11.01,100,1,10.93,100,1,13.93,0,-1,14.20,0,-1,14.26,0,-1,14.27,0,-1,14.34,0,-1,14.46,0,-1,14.57,0,-2,14.65,0,-1,14.70,0,-1,14.74,0,-2,ARL,0
2025-07-17T13:30:10.081340519Z,2025-07-17T13:30:10.081175039Z,10,2,1108,A,A,10,13.400000000,10,44719917,165480,30441651,12.99,100,1,12.73,100,1,12.67,100,1,11.69,2,1,11.52,100,1,11.29,100,1,11.24,100,1,11.05,100,1,11.01,100,1,10.93,100,1,13.93,0,-1,14.20,0,-1,14.26,0,-1,14.27,0,-1,14.34,0,-1,14.46,0,-1,14.57,0,-2,14.65,0,-1,14.70,0,-1,14.74,0,-2,ARL,0
2025-07-17T13:30:10.082315658Z,2025-07-17T13:30:10.082150107Z,10,2,1108,C,A,10,14.570000000,100,44076709,165551,30441855,12.99,100,1,12.73,100,1,12.67,100,1,11.69,2,1,11.52,100,1,11.29,100,1,11.24,100,1,11.05,100,1,11.01,100,1,10.93,100,1,13.40,0,-1,13.93,0,-1,14.20,0,-1,14.26,0,-1,14.27,0,-1,14.34,0,-1,14.46,0,-1,14.57,0,-2,14.65,0,-1,14.70,0,-1,ARL,0
2025-07-17T13:30:10.082315658Z,2025-07-17T13:30:10.082150107Z,10,2,1108,A,A,10,14.290000000,100,44719985,165551,30441855,12.99,100,1,12.73,100,1,12.67,100,1,11.69,2,1,11.52,100,1,11.29,100,1,11.24,100,1,11.05,100,1,11.01,100,1,10.93,100,1,13.40,0,-1,13.93,0,-1,14.20,0,-1,14.26,0,-1,14.27,0,-1,14.34,0,-1,14.46,0,-1,14.57,0,-2,14.65,0,-1,14.70,0,-1,ARL,0
2025-07-17T13:30:10.082828352Z,2025-07-17T13:30:10.082662762Z,10,2,1108,C,A,10,14.570000000,100,44077497,165590,30441930,12.99,100,1,12.73,100,1,12.67,100,1,11.69,2,1,11.52,100,1,11.29,100,1,11.24,100,1,11.05,100,1,11.01,100,1,10.93,100,1,13.40,0,-1,13.93,0,-1,14.20,0,-1,14.26,0,-1,14.27,0,-1,14.29,0,-1,14.34,0,-1,14.46,0,-1,14.57,0,-2,14.65,0,-1,ARL,0
2025-07-17T13:30:10.082828352Z,2025-07-17T13:30:10.082662762Z,10,2,1108,A,A,10,14.290000000,100,44720033,165590,30441930,12.99,100,1,12.73,100,1,12.67,100,1,11.69,2,1,11.52,100,1,11.29,100,1,11.24,100,1,11.05,100,1,11.01,100,1,10.93,100,1,13.40,0,-1,13.93,0,-1,14.20,0,-1,14.26,0,-1,14.27,0,-1,14.29,0,-1,14.34,0,-1,14.46,0,-1,14.57,0,-2,14.65,0,-1,ARL,0
2025-07-17T13:30:10.085062201Z,2025-07-17T13:30:10.084896414Z,10,2,1108,A,B,10,12.420000000,700,44720357,165787,30442720,12.99,100,1,12.73,100,1,12.67,100,1,12.42,700,1,11.69,2,1,11.52,100,1,11.29,100,1,11.24,100,1,11.05,100,1,11.01,100,1,13.40,0,-1,13.93,0,-1,14.20,0,-1,14.26,0,-1,14.27,0,-1,14.29,0,-1,14.34,0,-1,14.46,0,-1,14.57,0,-2,14.65,0,-1,ARL,0
2025-07-17T13:30:10.085497770Z,2025-07-17T13:30:10.085332605Z,10,2,1108,C,B,10,11.140000000,700,41534785,165165,30442750,12.99,100,1,12.73,100,1,12.67,100,1,11.69,2,1,11.52,100,1,11.29,100,1,11.24,100,1,11.05,100,1,11.01,100,1,10.93,100,1,13.40,0,-1,13.93,0,-1,14.20,0,-1,14.26,0,-1,14.27,0,-1,14.29,0,-1,14.34,0,-1,14.46,0,-1,14.57,0,-2,14.65,0,-1,ARL,0
2025-07-17T13:30:12.194748173Z,2025-07-17T13:30:12.194582572Z,10,2,1108,C,A,10,14.650000000,2,43692157,165601,30681385,12.99,100,1,12.73,100,1,12.67,100,1,11.69,2,1,11.52,100,1,11.29,100,1,11.24,100,1,11.05,100,1,11.01,100,1,10.93,100,1,13.40,0,-1,13.93,0,-1,14.20,0,-1,14.26,0,-1,14.27,0,-1,14.29,0,-1,14.34,0,-1,14.46,0,-1,14.57,0,-2,14.65,0,-1,ARL,0
2025-07-17T13:30:12.194748173Z,2025-07-17T13:30:12.194582572Z,10,2,1108,A,A,10,14.430000000,2,44904733,165601,30681385,12.99,100,1,12.73,100,1,12.67,100,1,11.69,2,1,11.52,100,1,11.29,100,1,11.24,100,1,11.05,100,1,11.01,100,1,10.93,100,1,13.40,0,-1,13.93,0,-1,14.20,0,-1,14.26,0,-1,14.27,0,-1,14.29,0,-1,14.34,0,-1,14.46,0,-1,14.57,0,-2,14.65,0,-1,ARL,0
2025-07-17T13:30:14.129097570Z,2025-07-17T13:30:14.128932140Z,10,2,1108,A,B,10,12.370000000,700,45025165,165430,30851531,12.99,100,1,12.73,100,1,12.67,100,1,12.37,700,1,11.69,2,1,11.52,100,1,11.29,100,1,11.24,100,1,11.05,100,1,11.01,100,1,13.40,0,-1,13.93,0,-1,14.20,0,-1,14.26,0,-1,14.27,0,-1,14.29,0,-1,14.34,0,-1,14.46,0,-1,14.57,0,-2,14.65,0,-1,ARL,0
2025-07-17T13:30:14.129174026Z,2025-07-17T13:30:14.129008546Z,10,2,1108,C,B,10,12.020000000,700,44641397,165480,30851532,12.99,100,1,12.73,100,1,12.67,100,1,11.69,2,1,11.52,100,1,11.29,100,1,11.24,100,1,11.05,100,1,11.01,100,1,10.93,100,1,13.40,0,-1,13.93,0,-1,14.20,0,-1,14.26,0,-1,14.27,0,-1,14.29,0,-1,14.34,0,-1,14.46,0,-1,14.57,0,-2,14.65,0,-1,ARL,0
2025-07-17T13:30:23.695729484Z,2025-07-17T13:30:23.695564208Z,10,2,1108,A,A,10,13.400000000,12,45593201,165276,31649134,12.99,100,1,12.73,100,1,12.67,100,1,11.69,2,1,11.52,100,1,11.29,100,1,11.24,100,1,11.05,100,1,11.01,100,1,10.93,100,1,13.40,0,-1,13.93,0,-1,14.20,0,-1,14.26,0,-1,14.27,0,-1,14.29,0,-1,14.34,0,-1,14.46,0,-1,14.57,0,-2,14.65,0,-1,ARL,0
2025-07-17T13:30:25.512235443Z,2025-07-17T13:30:25.512069243Z,10,2,1108,C,A,10,13.400000000,10,44719917,166200,31806233,12.99,100,1,12.73,100,1,12.67,100,1,11.69,2,1,11.52,100,1,11.29,100,1,11.24,100,1,11.05,100,1,11.01,100,1,10.93,100,1,13.40,0,-1,13.93,0,-1,14.20,0,-1,14.26,0,-1,14.27,0,-1,14.29,0,-1,14.34,0,-1,14.46,0,-1,14.57,0,-2,14.65,0,-1,ARL,0
2025-07-17T13:30:26.553325979Z,2025-07-17T13:30:26.553160650Z,10,2,1108,A,A,10,13.400000000,10,45748261,165329,31897785,12.99,100,1,12.73,100,1,12.67,100,1,11.69,2,1,11.52,100,1,11.29,100,1,11.24,100,1,11.05,100,1,11.01,100,1,10.93,100,1,13.40,0,-1,13.93,0,-1,14.20,0,-1,14.26,0,-1,14.27,0,-1,14.29,0,-1,14.34,0,-1,14.46,0,-1,14.57,0,-2,14.65,0,-1,ARL,0
2025-07-17T13:30:35.240569990Z,2025-07-17T13:30:35.240400172Z,10,2,1108,C,A,10,13.400000000,10,45748261,169818,32725426,12.99,100,1,12.73,100,1,12.67,100,1,11.69,2,1,11.52,100,1,11.29,100,1,11.24,100,1,11.05,100,1,11.01,100,1,10.93,100,1,13.40,0,-2,13.93,0,-1,14.20,0,-1,14.26,0,-1,14.27,0,-1,14.29,0,-1,14.34,0,-1,14.46,0,-1,14.57,0,-2,14.65,0,-1,ARL,0
2025-07-17T13:30:43.953164386Z,2025-07-17T13:30:43.952999157Z,10,2,1108,C,A,10,13.400000000,12,45593201,165229,33659635,12.99,100,1,12.73,100,1,12.67,100,1,11.69,2,1,11.52,100,1,11.29,100,1,11.24,100,1,11.05,100,1,11.01,100,1,10.93,100,1,13.40,0,-2,13.93,0,-1,14.20,0,-1,14.26,0,-1,14.27,0,-1,14.29,0,-1,14.34,0,-1,14.46,0,-1,14.57,0,-2,14.65,0,-1,ARL,0
2025-07-17T13:30:43.953528491Z,2025-07-17T13:30:43.953363128Z,10,2,1108,A,A,10,13.400000000,24,46613073,165363,33659657,12.99,100,1,12.73,100,1,12.67,100,1,11.69,2,1,11.52,100,1,11.29,100,1,11.24,100,1,11.05,100,1,11.01,100,1,10.93,100,1,13.40,0,-2,13.93,0,-1,14.20,0,-1,14.26,0,-1,14.27,0,-1,14.29,0,-1,14.34,0,-1,14.46,0,-1,14.57,0,-2,14.65,0,-1,ARL,0
2025-07-17T13:30:47.814275253Z,2025-07-17T13:30:47.814108950Z,10,2,1108,A,A,10,13.400000000,10,46784085,166303,34075767,12.99,100,1,12.73,100,1,12.67,100,1,11.69,2,1,11.52,100,1,11.29,100,1,11.24,100,1,11.05,100,1,11.01,100,1,10.93,100,1,13.40,0,-2,13.93,0,-1,14.20,0,-1,14.26,0,-1,14.27,0,-1,14.29,0,-1,14.34,0,-1,14.46,0,-1,14.57,0,-2,14.65,0,-1,ARL,0
2025-07-17T13:30:48.271777831Z,2025-07-17T13:30:48.271611303Z,10,2,1108,C,A,10,13.400000000,10,46784085,166528,34129837,12.99,100,1,12.73,100,1,12.67,100,1,11.69,2,1,11.52,100,1,11.29,100,1,11.24,100,1,11.05,100,1,11.01,100,1,10.93,100,1,13.40,0,-3,13.93,0,-1,14.20,0,-1,14.26,0,-1,14.27,0,-1,14.29,0,-1,14.34,0,-1,14.46,0,-1,14.57,0,-2,14.65,0,-1,ARL,0
2025-07-17T13:30:56.518448581Z,2025-07-17T13:30:56.518283181Z,10,2,1108,A,A,10,13.400000000,10,47164169,165400,34951153,12.99,100,1,12.73,100,1,12.67,100,1,11.69,2,1,11.52,100,1,11.29,100,1,11.24,100,1,11.05,100,1,11.01,100,1,10.93,100,1,13.40,0,-3,13.93,0,-1,14.20,0,-1,14.26,0,-1,14.27,0,-1,14.29,0,-1,14.34,0,-1,14.46,0,-1,14.57,0,-2,14.65,0,-1,ARL,0
2025-07-17T13:31:01.011909405Z,2025-07-17T13:31:01.011743292Z,10,2,1108,A,A,10,14.200000000,700,47376925,166113,35180694,12.99,100,1,12.73,100,1,12.67,100,1,11.69,2,1,11.52,100,1,11.29,100,1,11.24,100,1,11.05,100,1,11.01,100,1,10.93,100,1,13.40,0,-3,13.93,0,-1,14.20,0,-1,14.26,0,-1,14.27,0,-1,14.29,0,-1,14.34,0,-1,14.46,0,-1,14.57,0,-2,14.65,0,-1,ARL,0
2025-07-17T13:31:01.029013770Z,2025-07-17T13:31:01.028848502Z,10,2,1108,A,B,10,12.430000000,700,47383873,165268,35188622,12.99,100,1,12.73,100,1,12.67,100,1,12.43,700,1,11.69,2,1,11.52,100,1,11.29,100,1,11.24,100,1,11.05,100,1,11.01,100,1,13.40,0,-3,13.93,0,-1,14.20,0,-1,14.26,0,-1,14.27,0,-1,14.29,0,-1,14.34,0,-1,14.46,0,-1,14.57,0,-2,14.65,0,-1,ARL,0
2025-07-17T13:31:01.131725810Z,2025-07-17T13:31:01.131557345Z,10,2,1108,C,A,10,13.400000000,10,47164169,168465,35203355,12.99,100,1,12.73,100,1,12.67,100,1,12.43,690,1,11.69,2,1,11.52,100,1,11.29,100,1,11.24,100,1,11.05,100,1,11.01,100,1,13.40,0,-3,13.93,0,-1,14.20,0,-1,14.26,0,-1,14.27,0,-1,14.29,0,-1,14.34,0,-1,14.46,0,-1,14.57,0,-2,14.65,0,-1,ARL,0
2025-07-17T13:31:08.376486633Z,2025-07-17T13:31:08.376321454Z,10,2,1108,C,A,10,13.400000000,24,46613073,165179,35703639,12.99,100,1,12.73,100,1,12.67,100,1,12.43,666,1,11.69,2,1,11.52,100,1,11.29,100,1,11.24,100,1,11.05,100,1,11.01,100,1,13.40,0,-3,13.93,0,-1,14.20,0,-1,14.26,0,-1,14.27,0,-1,14.29,0,-1,14.34,0,-1,14.46,0,-1,14.57,0,-2,14.65,0,-1,ARL,0
2025-07-17T13:31:08.376858048Z,2025-07-17T13:31:08.376692815Z,10,2,1108,A,A,10,13.400000000,18,47873813,165233,35703653,12.99,100,1,12.73,100,1,12.67,100,1,12.43,666,1,11.69,2,1,11.52,100,1,11.29,100,1,11.24,100,1,11.05,100,1,11.01,100,1,13.40,0,-3,13.93,0,-1,14.20,0,-1,14.26,0,-1,14.27,0,-1,14.29,0,-1,14.34,0,-1,14.46,0,-1,14.57,0,-2,14.65,0,-1,ARL,0
2025-07-17T13:31:08.377188468Z,2025-07-17T13:31:08.377022927Z,10,2,1108,C,A,10,14.290000000,100,44720033,165541,35703666,12.99,100,1,12.73,100,1,12.67,100,1,12.43,666,1,11.69,2,1,11.52,100,1,11.29,100,1,11.24,100,1,11.05,100,1,11.01,100,1,13.40,0,-4,13.93,0,-1,14.20,0,-1,14.26,0,-1,14.27,0,-1,14.29,0,-1,14.34,0,-1,14.46,0,-1,14.57,0,-2,14.65,0,-1,ARL,0
2025-07-17T13:31:08.377188468Z,2025-07-17T13:31:08.377022927Z,10,2,1108,A,A,10,14.560000000,100,47873821,165541,35703666,12.99,100,1,12.73,100,1,12.67,100,1,12.43,666,1,11.69,2,1,11.52,100,1,11.29,100,1,11.24,100,1,11.05,100,1,11.01,100,1,13.40,0,-4,13.93,0,-1,14.20,0,-1,14.26,0,-1,14.27,0,-1,14.29,0,-1,14.34,0,-1,14.46,0,-1,14.57,0,-2,14.65,0,-1,ARL,0
2025-07-17T13:31:09.400094773Z,2025-07-17T13:31:09.399928944Z,10,2,1108,C,A,10,14.560000000,100,47873821,165829,35758774,12.99,100,1,12.73,100,1,12.67,100,1,12.43,666,1,11.69,2,1,11.52,100,1,11.29,100,1,11.24,100,1,11.05,100,1,11.01,100,1,13.40,0,-4,13.93,0,-1,14.20,0,-1,14.26,0,-1,14.27,0,-1,14.29,0,-1,14.34,0,-1,14.46,0,-1,14.56,0,-1,14.57,0,-2,ARL,0
2025-07-17T13:31:09.400094773Z,2025-07-17T13:31:09.399928944Z,10,2,1108,A,A,10,14.290000000,100,47927629,165829,35758774,12.99,100,1,12.73,100,1,12.67,100,1,12.43,666,1,11.69,2,1,11.52,100,1,11.29,100,1,11.24,100,1,11.05,100,1,11.01,100,1,13.40,0,-4,13.93,0,-1,14.20,0,-1,14.26,0,-1,14.27,0,-1,14.29,0,-1,14.34,0,-1,14.46,0,-1,14.56,0,-1,14.57,0,-2,ARL,0
2025-07-17T13:31:16.539042057Z,2025-07-17T13:31:16.538876621Z,10,2,1108,A,A,10,13.400000000,10,48315949,165436,36186495,12.99,100,1,12.73,100,1,12.67,100,1,12.43,666,1,11.69,2,1,11.52,100,1,11.29,100,1,11.24,100,1,11.05,100,1,11.01,100,1,13.40,0,-4,13.93,0,-1,14.20,0,-1,14.26,0,-1,14.27,0,-1,14.29,0,-1,14.34,0,-1,14.46,0,-1,14.56,0,-1,14.57,0,-2,ARL,0
2025-07-17T13:31:17.448727976Z,2025-07-17T13:31:17.448559991Z,10,2,1108,C,A,10,13.400000000,10,48315949,167985,36232894,12.99,100,1,12.73,100,1,12.67,100,1,12.43,666,1,11.69,2,1,11.52,100,1,11.29,100,1,11.24,100,1,11.05,100,1,11.01,100,1,13.40,0,-5,13.93,0,-1,14.20,0,-1,14.26,0,-1,14.27,0,-1,14.29,0,-1,14.34,0,-1,14.46,0,-1,14.56,0,-1,14.57,0,-2,ARL,0
2025-07-17T13:31:34.836102962Z,2025-07-17T13:31:34.835937627Z,10,2,1108,C,A,10,13.400000000,18,47873813,165335,37177882,12.99,100,1,12.73,100,1,12.67,100,1,12.43,666,1,11.69,2,1,11.52,100,1,11.29,100,1,11.24,100,1,11.05,100,1,11.01,100,1,13.40,0,-5,13.93,0,-1,14.20,0,-1,14.26,0,-1,14.27,0,-1,14.29,0,-1,14.34,0,-1,14.46,0,-1,14.56,0,-1,14.57,0,-2,ARL,0
2025-07-17T13:31:34.836860858Z,2025-07-17T13:31:34.836694504Z,10,2,1108,C,A,10,14.290000000,100,44719985,166354,37177896,12.99,100,1,12.73,100,1,12.67,100,1,12.43,666,1,11.69,2,1,11.52,100,1,11.29,100,1,11.24,100,1,11.05,100,1,11.01,100,1,13.40,0,-5,13.93,0,-1,14.20,0,-1,14.26,0,-1,14.27,0,-1,14.29,0,-1,14.34,0,-1,14.46,0,-1,14.56,0,-1,14.57,0,-2,ARL,0
2025-07-17T13:31:34.836860858Z,2025-07-17T13:31:34.836694504Z,10,2,1108,A,A,10,14.560000000,100,49226081,166354,37177896,12.99,100,1,12.73,100,1,12.67,100,1,12.43,666,1,11.69,2,1,11.52,100,1,11.29,100,1,11.24,100,1,11.05,100,1,11.01,100,1,13.40,0,-5,13.93,0,-1,14.20,0,-1,14.26,0,-1,14.27,0,-1,14.29,0,-1,14.34,0,-1,14.46,0,-1,14.56,0,-1,14.57,0,-2,ARL,0
2025-07-17T13:31:34.837265065Z,2025-07-17T13:31:34.837099615Z,10,2,1108,C,A,10,14.290000000,100,47927629,165450,37177905,12.99,100,1,12.73,100,1,12.67,100,1,12.43,666,1,11.69,2,1,11.52,100,1,11.29,100,1,11.24,100,1,11.05,100,1,11.01,100,1,13.40,0,-5,13.93,0,-1,14.20,0,-1,14.26,0,-1,14.27,0,-1,14.29,0,-1,14.34,0,-1,14.46,0,-1,14.56,0,-2,14.57,0,-2,ARL,0
2025-07-17T13:31:34.837265065Z,2025-07-17T13:31:34.837099615Z,10,2,1108,A,A,10,14.560000000,100,49226101,165450,37177905,12.99,100,1,12.73,100,1,12.67,100,1,12.43,666,1,11.69,2,1,11.52,100,1,11.29,100,1,11.24,100,1,11.05,100,1,11.01,100,1,13.40,0,-5,13.93,0,-1,14.20,0,-1,14.26,0,-1,14.27,0,-1,14.29,0,-1,14.34,0,-1,14.46,0,-1,14.56,0,-2,14.57,0,-2,ARL,0
2025-07-17T13:35:00.187694195Z,2025-07-17T13:35:00.187526221Z,10,2,1108,C,B,10,12.330000000,2,43692153,167974,45447658,12.99,100,1,12.73,100,1,12.67,100,1,12.43,666,1,11.69,2,1,11.52,100,1,11.29,100,1,11.24,100,1,11.05,100,1,11.01,100,1,13.40,0,-5,13.93,0,-1,14.20,0,-1,14.26,0,-1,14.27,0,-1,14.29,0,-1,14.34,0,-1,14.46,0,-1,14.56,0,-2,14.57,0,-2,ARL,0
2025-07-17T13:35:00.187694195Z,2025-07-17T13:35:00.187526221Z,10,2,1108,A,B,10,12.880000000,2,58709193,167974,45447658,12.99,100,1,12.88,2,1,12.73,100,1,12.67,100,1,12.43,666,1,11.69,2,1,11.52,100,1,11.29,100,1,11.24,100,1,11.05,100,1,13.40,0,-5,13.93,0,-1,14.20,0,-1,14.26,0,-1,14.27,0,-1,14.29,0,-1,14.34,0,-1,14.46,0,-1,14.56,0,-2,14.57,0,-2,ARL,0
2025-07-17T13:35:00.187694720Z,2025-07-17T13:35:00.187528642Z,10,2,1108,C,A,10,14.430000000,2,44904733,166078,45447661,12.99,100,1,12.73,100,1,12.67,100,1,12.43,666,1,11.69,2,1,11.52,100,1,11.29,100,1,11.24,100,1,11.05,100,1,11.01,100,1,13.40,0,-5,13.93,0,-1,14.20,0,-1,14.26,0,-1,14.27,0,-1,14.29,0,-1,14.34,0,-1,14.46,0,-1,14.56,0,-2,14.57,0,-2,ARL,0
2025-07-17T13:35:00.187694720Z,2025-07-17T13:35:00.187528642Z,10,2,1108,A,A,10,13.780000000,2,58709197,166078,45447661,12.99,100,1,12.73,100,1,12.67,100,1,12.43,666,1,11.69,2,1,11.52,100,1,11.29,100,1,11.24,100,1,11.05,100,1,11.01,100,1,13.40,0,-5,13.93,0,-1,14.20,0,-1,14.26,0,-1,14.27,0,-1,14.29,0,-1,14.34,0,-1,14.46,0,-1,14.56,0,-2,14.57,0,-2,ARL,0
2025-07-17T13:37:31.076320046Z,2025-07-17T13:37:31.076154614Z,10,2,1108,C,A,10,14.560000000,100,49226101,165432,51978366,12.99,100,1,12.73,100,1,12.67,100,1,12.43,666,1,11.69,2,1,11.52,100,1,11.29,100,1,11.24,100,1,11.05,100,1,11.01,100,1,13.40,0,-5,13.78,0,-1,13.93,0,-1,14.20,0,-1,14.26,0,-1,14.27,0,-1,14.29,0,-1,14.34,0,-1,14.46,0,-1,14.56,0,-2,ARL,0
2025-07-17T13:37:31.076320046Z,2025-07-17T13:37:31.076154614Z,10,2,1108,A,A,10,14.290000000,100,65160189,165432,51978366,12.99,100,1,12.73,100,1,12.67,100,1,12.43,666,1,11.69,2,1,11.52,100,1,11.29,100,1,11.24,100,1,11.05,100,1,11.01,100,1,13.40,0,-5,13.78,0,-1,13.93,0,-1,14.20,0,-1,14.26,0,-1,14.27,0,-1,14.29,0,-1,14.34,0,-1,14.46,0,-1,14.56,0,-2,ARL,0
2025-07-17T13:37:31.076496403Z,2025-07-17T13:37:31.076330756Z,10,2,1108,C,A,10,14.560000000,100,49226081,165647,51978372,12.99,100,1,12.73,100,1,12.67,100,1,12.43,666,1,11.69,2,1,11.52,100,1,11.29,100,1,11.24,100,1,11.05,100,1,11.01,100,1,13.40,0,-5,13.78,0,-1,13.93,0,-1,14.20,0,-1,14.26,0,-1,14.27,0,-1,14.29,0,-2,14.34,0,-1,14.46,0,-1,14.56,0,-2,ARL,0
2025-07-17T13:37:31.076496403Z,2025-07-17T13:37:31.076330756Z,10,2,1108,A,A,10,14.290000000,100,65160193,165647,51978372,12.99,100,1,12.73,100,1,12.67,100,1,12.43,666,1,11.69,2,1,11.52,100,1,11.29,100,1,11.24,100,1,11.05,100,1,11.01,100,1,13.40,0,-5,13.78,0,-1,13.93,0,-1,14.20,0,-1,14.26,0,-1,14.27,0,-1,14.29,0,-2,14.34,0,-1,14.46,0,-1,14.56,0,-2,ARL,0
2025-07-17T13:38:08.679910189Z,2025-07-17T13:38:08.679744459Z,10,2,1108,C,A,10,14.290000000,100,65160189,165730,53264917,12.99,100,1,12.73,100,1,12.67,100,1,12.43,666,1,11.69,2,1,11.52,100,1,11.29,100,1,11.24,100,1,11.05,100,1,11.01,100,1,13.40,0,-5,13.78,0,-1,13.93,0,-1,14.20,0,-1,14.26,0,-1,14.27,0,-1,14.29,0,-3,14.34,0,-1,14.46,0,-1,14.56,0,-2,ARL,0
2025-07-17T13:38:08.679910189Z,2025-07-17T13:38:08.679744459Z,10,2,1108,A,A,10,14.560000000,100,66501333,165730,53264917,12.99,100,1,12.73,100,1,12.67,100,1,12.43,666,1,11.69,2,1,11.52,100,1,11.29,100,1,11.24,100,1,11.05,100,1,11.01,100,1,13.40,0,-5,13.78,0,-1,13.93,0,-1,14.20,0,-1,14.26,0,-1,14.27,0,-1,14.29,0,-3,14.34,0,-1,14.46,0,-1,14.56,0,-2,ARL,0
2025-07-17T13:38:08.679917832Z,2025-07-17T13:38:08.679752190Z,10,2,1108,C,A,10,14.290000000,100,65160193,165642,53264918,12.99,100,1,12.73,100,1,12.67,100,1,12.43,666,1,11.69,2,1,11.52,100,1,11.29,100,1,11.24,100,1,11.05,100,1,11.01,100,1,13.40,0,-5,13.78,0,-1,13.93,0,-1,14.20,0,-1,14.26,0,-1,14.27,0,-1,14.29,0,-3,14.34,0,-1,14.46,0,-1,14.56,0,-3,ARL,0
2025-07-17T13:38:08.679917832Z,2025-07-17T13:38:08.679752190Z,10,2,1108,A,A,10,14.560000000,100,66501341,165642,53264918,12.99,100,1,12.73,100,1,12.67,100,1,12.43,666,1,11.69,2,1,11.52,100,1,11.29,100,1,11.24,100,1,11.05,100,1,11.01,100,1,13.40,0,-5,13.78,0,-1,13.93,0,-1,14.20,0,-1,14.26,0,-1,14.27,0,-1,14.29,0,-3,14.34,0,-1,14.46,0,-1,14.56,0,-3,ARL,0
2025-07-17T13:38:09.687028970Z,2025-07-17T13:38:09.686863512Z,10,2,1108,C,A,10,14.560000000,100,66501333,165458,53302839,12.99,100,1,12.73,100,1,12.67,100,1,12.43,666,1,11.69,2,1,11.52,100,1,11.29,100,1,11.24,100,1,11.05,100,1,11.01,100,1,13.40,0,-5,13.78,0,-1,13.93,0,-1,14.20,0,-1,14.26,0,-1,14.27,0,-1,14.29,0,-3,14.34,0,-1,14.46,0,-1,14.56,0,-4,ARL,0
2025-07-17T13:38:09.687028970Z,2025-07-17T13:38:09.686863512Z,10,2,1108,A,A,10,14.290000000,100,66538149,165458,53302839,12.99,100,1,12.73,100,1,12.67,100,1,12.43,666,1,11.69,2,1,11.52,100,1,11.29,100,1,11.24,100,1,11.05,100,1,11.01,100,1,13.40,0,-5,13.78,0,-1,13.93,0,-1,14.20,0,-1,14.26,0,-1,14.27,0,-1,14.29,0,-3,14.34,0,-1,14.46,0,-1,14.56,0,-4,ARL,0
2025-07-17T13:38:09.708195003Z,2025-07-17T13:38:09.708029202Z,10,2,1108,C,A,10,14.560000000,100,66501341,165801,53303094,12.99,100,1,12.73,100,1,12.67,100,1,12.43,666,1,11.69,2,1,11.52,100,1,11.29,100,1,11.24,100,1,11.05,100,1,11.01,100,1,13.40,0,-5,13.78,0,-1,13.93,0,-1,14.20,0,-1,14.26,0,-1,14.27,0,-1,14.29,0,-4,14.34,0,-1,14.46,0,-1,14.56,0,-4,ARL,0
2025-07-17T13:38:09.708195003Z,2025-07-17T13:38:09.708029202Z,10,2,1108,A,A,10,14.290000000,100,66538573,165801,53303094,12.99,100,1,12.73,100,1,12.67,100,1,12.43,666,1,11.69,2,1,11.52,100,1,11.29,100,1,11.24,100,1,11.05,100,1,11.01,100,1,13.40,0,-5,13.78,0,-1,13.93,0,-1,14.20,0,-1,14.26,0,-1,14.27,0,-1,14.29,0,-4,14.34,0,-1,14.46,0,-1,14.56,0,-4,ARL,0
2025-07-17T13:38:44.679122862Z,2025-07-17T13:38:44.678957477Z,10,2,1108,A,A,10,13.400000000,15,67832461,165385,54485050,12.99,100,1,12.73,100,1,12.67,100,1,12.43,666,1,11.69,2,1,11.52,100,1,11.29,100,1,11.24,100,1,11.05,100,1,11.01,100,1,13.40,0,-5,13.78,0,-1,13.93,0,-1,14.20,0,-1,14.26,0,-1,14.27,0,-1,14.29,0,-4,14.34,0,-1,14.46,0,-1,14.56,0,-4,ARL,0
2025-07-17T13:38:44.679444346Z,2025-07-17T13:38:44.679278833Z,10,2,1108,C,A,10,14.290000000,100,66538149,165513,54485052,12.99,100,1,12.73,100,1,12.67,100,1,12.43,666,1,11.69,2,1,11.52,100,1,11.29,100,1,11.24,100,1,11.05,100,1,11.01,100,1,13.40,0,-6,13.78,0,-1,13.93,0,-1,14.20,0,-1,14.26,0,-1,14.27,0,-1,14.29,0,-4,14.34,0,-1,14.46,0,-1,14.56,0,-4,ARL,0
2025-07-17T13:38:44.679444346Z,2025-07-17T13:38:44.679278833Z,10,2,1108,A,A,10,14.560000000,100,67832465,165513,54485052,12.99,100,1,12.73,100,1,12.67,100,1,12.43,666,1,11.69,2,1,11.52,100,1,11.29,100,1,11.24,100,1,11.05,100,1,11.01,100,1,13.40,0,-6,13.78,0,-1,13.93,0,-1,14.20,0,-1,14.26,0,-1,14.27,0,-1,14.29,0,-4,14.34,0,-1,14.46,0,-1,14.56,0,-4,ARL,0
2025-07-17T13:38:45.695430520Z,2025-07-17T13:38:45.695265148Z,10,2,1108,C,A,10,14.560000000,100,67832465,165372,54508575,12.99,100,1,12.73,100,1,12.67,100,1,12.43,666,1,11.69,2,1,11.52,100,1,11.29,100,1,11.24,100,1,11.05,100,1,11.01,100,1,13.40,0,-6,13.78,0,-1,13.93,0,-1,14.20,0,-1,14.26,0,-1,14.27,0,-1,14.29,0,-4,14.34,0,-1,14.46,0,-1,14.56,0,-5,ARL,0
2025-07-17T13:38:45.695430520Z,2025-07-17T13:38:45.695265148Z,10,2,1108,A,A,10,14.290000000,100,67857641,165372,54508575,12.99,100,1,12.73,100,1,12.67,100,1,12.43,666,1,11.69,2,1,11.52,100,1,11.29,100,1,11.24,100,1,11.05,100,1,11.01,100,1,13.40,0,-6,13.78,0,-1,13.93,0,-1,14.20,0,-1,14.26,0,-1,14.27,0,-1,14.29,0,-4,14.34,0,-1,14.46,0,-1,14.56,0,-5,ARL,0
2025-07-17T13:39:08.714072882Z,2025-07-17T13:39:08.713907562Z,10,2,1108,C,A,10,13.400000000,15,67832461,165320,55204868,12.99,100,1,12.73,100,1,12.67,100,1,12.43,666,1,11.69,2,1,11.52,100,1,11.29,100,1,11.24,100,1,11.05,100,1,11.01,100,1,13.40,0,-6,13.78,0,-1,13.93,0,-1,14.20,0,-1,14.26,0,-1,14.27,0,-1,14.29,0,-4,14.34,0,-1,14.46,0,-1,14.56,0,-5,ARL,0
2025-07-17T13:39:08.714449550Z,2025-07-17T13:39:08.714284059Z,10,2,1108,A,A,10,13.400000000,24,68625181,165491,55204884,12.99,100,1,12.73,100,1,12.67,100,1,12.43,666,1,11.69,2,1,11.52,100,1,11.29,100,1,11.24,100,1,11.05,100,1,11.01,100,1,13.40,0,-6,13.78,0,-1,13.93,0,-1,14.20,0,-1,14.26,0,-1,14.27,0,-1,14.29,0,-4,14.34,0,-1,14.46,0,-1,14.56,0,-5,ARL,0
2025-07-17T13:39:39.996998334Z,2025-07-17T13:39:39.996833282Z,10,2,1108,C,A,10,13.400000000,23,68625181,165052,56150114,12.99,100,1,12.73,100,1,12.67,100,1,12.43,666,1,11.69,2,1,11.52,100,1,11.29,100,1,11.24,100,1,11.05,100,1,11.01,100,1,13.40,0,-7,13.78,0,-1,13.93,0,-1,14.20,0,-1,14.26,0,-1,14.27,0,-1,14.29,0,-4,14.34,0,-1,14.46,0,-1,14.56,0,-5,ARL,0
2025-07-17T13:39:39.997309515Z,2025-07-17T13:39:39.997144158Z,10,2,1108,C,A,10,14.290000000,100,66538573,165357,56150130,12.99,100,1,12.73,100,1,12.67,100,1,12.43,666,1,11.69,2,1,11.52,100,1,11.29,100,1,11.24,100,1,11.05,100,1,11.01,100,1,13.40,0,-7,13.78,0,-1,13.93,0,-1,14.20,0,-1,14.26,0,-1,14.27,0,-1,14.29,0,-4,14.34,0,-1,14.46,0,-1,14.56,0,-5,ARL,0
2025-07-17T13:39:39.997309515Z,2025-07-17T13:39:39.997144158Z,10,2,1108,A,A,10,14.570000000,100,69677517,165357,56150130,12.99,100,1,12.73,100,1,12.67,100,1,12.43,666,1,11.69,2,1,11.52,100,1,11.29,100,1,11.24,100,1,11.05,100,1,11.01,100,1,13.40,0,-7,13.78,0,-1,13.93,0,-1,14.20,0,-1,14.26,0,-1,14.27,0,-1,14.29,0,-4,14.34,0,-1,14.46,0,-1,14.56,0,-5,ARL,0
2025-07-17T13:39:39.997376873Z,2025-07-17T13:39:39.997211562Z,10,2,1108,A,A,10,13.400000000,24,69677521,165311,56150131,12.99,100,1,12.73,100,1,12.67,100,1,12.43,666,1,11.69,2,1,11.52,100,1,11.29,100,1,11.24,100,1,11.05,100,1,11.01,100,1,13.40,0,-7,13.78,0,-1,13.93,0,-1,14.20,0,-1,14.26,0,-1,14.27,0,-1,14.29,0,-4,14.34,0,-1,14.46,0,-1,14.56,0,-5,ARL,0
2025-07-17T13:39:41.018948933Z,2025-07-17T13:39:41.018783466Z,10,2,1108,C,A,10,14.570000000,100,69677517,165467,56183429,12.99,100,1,12.73,100,1,12.67,100,1,12.43,666,1,11.69,2,1,11.52,100,1,11.29,100,1,11.24,100,1,11.05,100,1,11.01,100,1,13.40,0,-8,13.78,0,-1,13.93,0,-1,14.20,0,-1,14.26,0,-1,14.27,0,-1,14.29,0,-4,14.34,0,-1,14.46,0,-1,14.56,0,-5,ARL,0
2025-07-17T13:39:41.018948933Z,2025-07-17T13:39:41.018783466Z,10,2,1108,A,A,10,14.300000000,100,69725541,165467,56183429,12.99,100,1,12.73,100,1,12.67,100,1,12.43,666,1,11.69,2,1,11.52,100,1,11.29,100,1,11.24,100,1,11.05,100,1,11.01,100,1,13.40,0,-8,13.78,0,-1,13.93,0,-1,14.20,0,-1,14.26,0,-1,14.27,0,-1,14.29,0,-4,14.34,0,-1,14.46,0,-1,14.56,0,-5,ARL,0
2025-07-17T13:40:08.782549047Z,2025-07-17T13:40:08.782383621Z,10,2,1108,C,A,10,13.400000000,24,69677521,165426,57235944,12.99,100,1,12.73,100,1,12.67,100,1,12.43,666,1,11.69,2,1,11.52,100,1,11.29,100,1,11.24,100,1,11.05,100,1,11.01,100,1,13.40,0,-8,13.78,0,-1,13.93,0,-1,14.20,0,-1,14.26,0,-1,14.27,0,-1,14.29,0,-4,14.34,0,-1,14.46,0,-1,14.56,0,-5,ARL,0
2025-07-17T13:40:08.782923978Z,2025-07-17T13:40:08.782758499Z,10,2,1108,A,A,10,13.400000000,18,70897053,165479,57235956,12.99,100,1,12.73,100,1,12.67,100,1,12.43,666,1,11.69,2,1,11.52,100,1,11.29,100,1,11.24,100,1,11.05,100,1,11.01,100,1,13.40,0,-8,13.78,0,-1,13.93,0,-1,14.20,0,-1,14.26,0,-1,14.27,0,-1,14.29,0,-4,14.34,0,-1,14.46,0,-1,14.56,0,-5,ARL,0
2025-07-17T13:41:08.818876572Z,2025-07-17T13:41:08.818711250Z,10,2,1108,C,A,10,13.400000000,18,70897053,165322,59313726,12.99,100,1,12.73,100,1,12.67,100,1,12.43,666,1,11.69,2,1,11.52,100,1,11.29,100,1,11.24,100,1,11.05,100,1,11.01,100,1,13.40,0,-9,13.78,0,-1,13.93,0,-1,14.20,0,-1,14.26,0,-1,14.27,0,-1,14.29,0,-4,14.34,0,-1,14.46,0,-1,14.56,0,-5,ARL,0
2025-07-17T13:41:08.819249545Z,2025-07-17T13:41:08.819083504Z,10,2,1108,A,A,10,13.400000000,24,73109413,166041,59313736,12.99,100,1,12.73,100,1,12.67,100,1,12.43,666,1,11.69,2,1,11.52,100,1,11.29,100,1,11.24,100,1,11.05,100,1,11.01,100,1,13.40,0,-9,13.78,0,-1,13.93,0,-1,14.20,0,-1,14.26,0,-1,14.27,0,-1,14.29,0,-4,14.34,0,-1,14.46,0,-1,14.56,0,-5,ARL,0
2025-07-17T13:41:08.819270512Z,2025-07-17T13:41:08.819104931Z,10,2,1108,C,A,10,14.300000000,100,69725541,165581,59313739,12.99,100,1,12.73,100,1,12.67,100,1,12.43,666,1,11.69,2,1,11.52,100,1,11.29,100,1,11.24,100,1,11.05,100,1,11.01,100,1,13.40,0,-10,13.78,0,-1,13.93,0,-1,14.20,0,-1,14.26,0,-1,14.27,0,-1,14.29,0,-4,14.34,0,-1,14.46,0,-1,14.56,0,-5,ARL,0
2025-07-17T13:41:08.819270512Z,2025-07-17T13:41:08.819104931Z,10,2,1108,A,A,10,14.570000000,100,73109417,165581,59313739,12.99,100,1,12.73,100,1,12.67,100,1,12.43,666,1,11.69,2,1,11.52,100,1,11.29,100,1,11.24,100,1,11.05,100,1,11.01,100,1,13.40,0,-10,13.78,0,-1,13.93,0,-1,14.20,0,-1,14.26,0,-1,14.27,0,-1,14.29,0,-4,14.34,0,-1,14.46,0,-1,14.56,0,-5,ARL,0
2025-07-17T13:41:09.881251193Z,2025-07-17T13:41:09.881085734Z,10,2,1108,C,A,10,14.570000000,100,73109417,165459,59383199,12.99,100,1,12.73,100,1,12.67,100,1,12.43,666,1,11.69,2,1,11.52,100,1,11.29,100,1,11.24,100,1,11.05,100,1,11.01,100,1,13.40,0,-10,13.78,0,-1,13.93,0,-1,14.20,0,-1,14.26,0,-1,14.27,0,-1,14.29,0,-4,14.34,0,-1,14.46,0,-1,14.56,0,-5,ARL,0
2025-07-17T13:41:09.881251193Z,2025-07-17T13:41:09.881085734Z,10,2,1108,A,A,10,14.300000000,100,73183421,165459,59383199,12.99,100,1,12.73,100,1,12.67,100,1,12.43,666,1,11.69,2,1,11.52,100,1,11.29,100,1,11.24,100,1,11.05,100,1,11.01,100,1,13.40,0,-10,13.78,0,-1,13.93,0,-1,14.20,0,-1,14.26,0,-1,14.27,0,-1,14.29,0,-4,14.34,0,-1,14.46,0,-1,14.56,0,-5,ARL,0
2025-07-17T13:41:44.348660105Z,2025-07-17T13:41:44.348494744Z,10,2,1108,C,A,10,13.400000000,24,73109413,165361,60614543,12.99,100,1,12.73,100,1,12.67,100,1,12.43,666,1,11.69,2,1,11.52,100,1,11.29,100,1,11.24,100,1,11.05,100,1,11.01,100,1,13.40,0,-10,13.78,0,-1,13.93,0,-1,14.20,0,-1,14.26,0,-1,14.27,0,-1,14.29,0,-4,14.34,0,-1,14.46,0,-1,14.56,0,-5,ARL,0
2025-07-17T13:41:44.349581977Z,2025-07-17T13:41:44.349416601Z,10,2,1108,C,A,10,14.300000000,100,73183421,165376,60614557,12.99,100,1,12.73,100,1,12.67,100,1,12.43,666,1,11.69,2,1,11.52,100,1,11.29,100,1,11.24,100,1,11.05,100,1,11.01,100,1,13.40,0,-10,13.78,0,-1,13.93,0,-1,14.20,0,-1,14.26,0,-1,14.27,0,-1,14.29,0,-4,14.30,0,-1,14.34,0,-1,14.46,0,-1,ARL,0
2025-07-17T13:41:44.349581977Z,2025-07-17T13:41:44.349416601Z,10,2,1108,A,A,10,14.570000000,100,74549681,165376,60614557,12.99,100,1,12.73,100,1,12.67,100,1,12.43,666,1,11.69,2,1,11.52,100,1,11.29,100,1,11.24,100,1,11.05,100,1,11.01,100,1,13.40,0,-10,13.78,0,-1,13.93,0,-1,14.20,0,-1,14.26,0,-1,14.27,0,-1,14.29,0,-4,14.30,0,-1,14.34,0,-1,14.46,0,-1,ARL,0
2025-07-17T13:41:45.405178844Z,2025-07-17T13:41:45.405013016Z,10,2,1108,C,A,10,14.570000000,100,74549681,165828,60651462,12.99,100,1,12.73,100,1,12.67,100,1,12.43,666,1,11.69,2,1,11.52,100,1,11.29,100,1,11.24,100,1,11.05,100,1,11.01,100,1,13.40,0,-10,13.78,0,-1,13.93,0,-1,14.20,0,-1,14.26,0,-1,14.27,0,-1,14.29,0,-4,14.30,0,-1,14.34,0,-1,14.46,0,-1,ARL,0
2025-07-17T13:41:45.405178844Z,2025-07-17T13:41:45.405013016Z,10,2,1108,A,A,10,14.300000000,100,74589605,165828,60651462,12.99,100,1,12.73,100,1,12.67,100,1,12.43,666,1,11.69,2,1,11.52,100,1,11.29,100,1,11.24,100,1,11.05,100,1,11.01,100,1,13.40,0,-10,13.78,0,-1,13.93,0,-1,14.20,0,-1,14.26,0,-1,14.27,0,-1,14.29,0,-4,14.30,0,-1,14.34,0,-1,14.46,0,-1,ARL,0
2025-07-17T13:42:08.821320823Z,2025-07-17T13:42:08.821155108Z,10,2,1108,C,A,10,14.290000000,100,67857641,165715,61488742,12.99,100,1,12.73,100,1,12.67,100,1,12.43,666,1,11.69,2,1,11.52,100,1,11.29,100,1,11.24,100,1,11.05,100,1,11.01,100,1,13.40,0,-10,13.78,0,-1,13.93,0,-1,14.20,0,-1,14.26,0,-1,14.27,0,-1,14.29,0,-4,14.30,0,-2,14.34,0,-1,14.46,0,-1,ARL,0
2025-07-17T13:42:08.821320823Z,2025-07-17T13:42:08.821155108Z,10,2,1108,A,A,10,14.570000000,100,75537553,165715,61488742,12.99,100,1,12.73,100,1,12.67,100,1,12.43,666,1,11.69,2,1,11.52,100,1,11.29,100,1,11.24,100,1,11.05,100,1,11.01,100,1,13.40,0,-10,13.78,0,-1,13.93,0,-1,14.20,0,-1,14.26,0,-1,14.27,0,-1,14.29,0,-4,14.30,0,-2,14.34,0,-1,14.46,0,-1,ARL,0
2025-07-17T13:42:09.827057338Z,2025-07-17T13:42:09.826891682Z,10,2,1108,C,A,10,14.570000000,100,75537553,165656,61523538,12.99,100,1,12.73,100,1,12.67,100,1,12.43,666,1,11.69,2,1,11.52,100,1,11.29,100,1,11.24,100,1,11.05,100,1,11.01,100,1,13.40,0,-10,13.78,0,-1,13.93,0,-1,14.20,0,-1,14.26,0,-1,14.27,0,-1,14.29,0,-4,14.30,0,-2,14.34,0,-1,14.46,0,-1,ARL,0
2025-07-17T13:42:09.827057338Z,2025-07-17T13:42:09.826891682Z,10,2,1108,A,A,10,14.300000000,100,75577257,165656,61523538,12.99,100,1,12.73,100,1,12.67,100,1,12.43,666,1,11.69,2,1,11.52,100,1,11.29,100,1,11.24,100,1,11.05,100,1,11.01,100,1,13.40,0,-10,13.78,0,-1,13.93,0,-1,14.20,0,-1,14.26,0,-1,14.27,0,-1,14.29,0,-4,14.30,0,-2,14.34,0,-1,14.46,0,-1,ARL,0
2025-07-17T13:43:08.826244125Z,2025-07-17T13:43:08.826078491Z,10,2,1108,C,A,10,14.300000000,100,75577257,165634,63579150,12.99,100,1,12.73,100,1,12.67,100,1,12.43,666,1,11.69,2,1,11.52,100,1,11.29,100,1,11.24,100,1,11.05,100,1,11.01,100,1,13.40,0,-10,13.78,0,-1,13.93,0,-1,14.20,0,-1,14.26,0,-1,14.27,0,-1,14.29,0,-4,14.30,0,-3,14.34,0,-1,14.46,0,-1,ARL,0
2025-07-17T13:43:08.826244125Z,2025-07-17T13:43:08.826078491Z,10,2,1108,A,A,10,14.570000000,100,77879933,165634,63579150,12.99,100,1,12.73,100,1,12.67,100,1,12.43,666,1,11.69,2,1,11.52,100,1,11.29,100,1,11.24,100,1,11.05,100,1,11.01,100,1,13.40,0,-10,13.78,0,-1,13.93,0,-1,14.20,0,-1,14.26,0,-1,14.27,0,-1,14.29,0,-4,14.30,0,-3,14.34,0,-1,14.46,0,-1,ARL,0
2025-07-17T13:43:09.832572415Z,2025-07-17T13:43:09.832406764Z,10,2,1108,C,A,10,14.570000000,100,77879933,165651,63604352,12.99,100,1,12.73,100,1,12.67,100,1,12.43,666,1,11.69,2,1,11.52,100,1,11.29,100,1,11.24,100,1,11.05,100,1,11.01,100,1,13.40,0,-10,13.78,0,-1,13.93,0,-1,14.20,0,-1,14.26,0,-1,14.27,0,-1,14.29,0,-4,14.30,0,-3,14.34,0,-1,14.46,0,-1,ARL,0
2025-07-17T13:43:09.832572415Z,2025-07-17T13:43:09.832406764Z,10,2,1108,A,A,10,14.300000000,100,77910357,165651,63604352,12.99,100,1,12.73,100,1,12.67,100,1,12.43,666,1,11.69,2,1,11.52,100,1,11.29,100,1,11.24,100,1,11.05,100,1,11.01,100,1,13.40,0,-10,13.78,0,-1,13.93,0,-1,14.20,0,-1,14.26,0,-1,14.27,0,-1,14.29,0,-4,14.30,0,-3,14.34,0,-1,14.46,0,-1,ARL,0
2025-07-17T13:46:09.541016899Z,2025-07-17T13:46:09.540851349Z,10,2,1108,C,A,10,14.200000000,700,47376925,165550,69578535,12.99,100,1,12.73,100,1,12.67,100,1,12.43,666,1,11.69,2,1,11.52,100,1,11.29,100,1,11.24,100,1,11.05,100,1,11.01,100,1,13.40,0,-10,13.78,0,-1,13.93,0,-1,14.20,0,-1,14.26,0,-1,14.27,0,-1,14.29,0,-4,14.30,0,-4,14.34,0,-1,14.46,0,-1,ARL,0
2025-07-17T13:46:09.541058233Z,2025-07-17T13:46:09.540892810Z,10,2,1108,A,A,10,14.360000000,700,84607761,165423,69578537,12.99,100,1,12.73,100,1,12.67,100,1,12.43,666,1,11.69,2,1,11.52,100,1,11.29,100,1,11.24,100,1,11.05,100,1,11.01,100,1,13.40,0,-10,13.78,0,-1,13.93,0,-1,14.20,0,-1,14.26,0,-1,14.27,0,-1,14.29,0,-4,14.30,0,-4,14.34,0,-1,14.46,0,-1,ARL,0
2025-07-17T13:46:09.541097538Z,2025-07-17T13:46:09.540932260Z,10,2,1108,A,A,10,15.590000000,100,84607765,165278,69578539,12.99,100,1,12.73,100,1,12.67,100,1,12.43,666,1,11.69,2,1,11.52,100,1,11.29,100,1,11.24,100,1,11.05,100,1,11.01,100,1,13.40,0,-10,13.78,0,-1,13.93,0,-1,14.20,0,-1,14.26,0,-1,14.27,0,-1,14.29,0,-4,14.30,0,-4,14.34,0,-1,14.46,0,-1,ARL,0
2025-07-17T13:46:09.541109881Z,2025-07-17T13:46:09.540944549Z,10,2,1108,C,A,10,15.280000000,100,43373085,165332,69578540,12.99,100,1,12.73,100,1,12.67,100,1,12.43,666,1,11.69,2,1,11.52,100,1,11.29,100,1,11.24,100,1,11.05,100,1,11.01,100,1,13.40,0,-10,13.78,0,-1,13.93,0,-1,14.20,0,-1,14.26,0,-1,14.27,0,-1,14.29,0,-4,14.30,0,-4,14.34,0,-1,14.46,0,-1,ARL,0
2025-07-17T13:46:09.541434576Z,2025-07-17T13:46:09.541269186Z,10,2,1108,C,A,10,14.440000000,100,43373009,165390,69578543,12.99,100,1,12.73,100,1,12.67,100,1,12.43,666,1,11.69,2,1,11.52,100,1,11.29,100,1,11.24,100,1,11.05,100,1,11.01,100,1,13.40,0,-10,13.78,0,-1,13.93,0,-1,14.20,0,-1,14.26,0,-1,14.27,0,-1,14.29,0,-4,14.30,0,-4,14.34,0,-1,14.46,0,-1,ARL,0
2025-07-17T13:46:09.541434576Z,2025-07-17T13:46:09.541269186Z,10,2,1108,A,A,10,14.490000000,100,84607785,165390,69578543,12.99,100,1,12.73,100,1,12.67,100,1,12.43,666,1,11.69,2,1,11.52,100,1,11.29,100,1,11.24,100,1,11.05,100,1,11.01,100,1,13.40,0,-10,13.78,0,-1,13.93,0,-1,14.20,0,-1,14.26,0,-1,14.27,0,-1,14.29,0,-4,14.30,0,-4,14.34,0,-1,14.46,0,-1,ARL,0
2025-07-17T13:46:09.541492629Z,2025-07-17T13:46:09.541327298Z,10,2,1108,C,A,10,14.000000000,100,43663233,165331,69578544,12.99,100,1,12.73,100,1,12.67,100,1,12.43,666,1,11.69,2,1,11.52,100,1,11.29,100,1,11.24,100,1,11.05,100,1,11.01,100,1,13.40,0,-10,13.78,0,-1,13.93,0,-1,14.20,0,-1,14.26,0,-1,14.27,0,-1,14.29,0,-4,14.30,0,-4,14.34,0,-1,14.46,0,-1,ARL,0
2025-07-17T13:46:09.541795256Z,2025-07-17T13:46:09.541629920Z,10,2,1108,C,A,10,14.340000000,100,43755821,165336,69578547,12.99,100,1,12.73,100,1,12.67,100,1,12.43,666,1,11.69,2,1,11.52,100,1,11.29,100,1,11.24,100,1,11.05,100,1,11.01,100,1,13.40,0,-10,13.78,0,-1,13.93,0,-1,14.20,0,-1,14.26,0,-1,14.27,0,-1,14.29,0,-4,14.30,0,-4,14.34,0,-1,14.46,0,-1,ARL,0
2025-07-17T13:46:09.541795256Z,2025-07-17T13:46:09.541629920Z,10,2,1108,A,A,10,14.630000000,100,84607801,165336,69578547,12.99,100,1,12.73,100,1,12.67,100,1,12.43,666,1,11.69,2,1,11.52,100,1,11.29,100,1,11.24,100,1,11.05,100,1,11.01,100,1,13.40,0,-10,13.78,0,-1,13.93,0,-1,14.20,0,-1,14.26,0,-1,14.27,0,-1,14.29,0,-4,14.30,0,-4,14.34,0,-1,14.46,0,-1,ARL,0
2025-07-17T13:46:09.541846554Z,2025-07-17T13:46:09.541680473Z,10,2,1108,C,A,10,14.740000000,100,43357029,166081,69578550,12.99,100,1,12.73,100,1,12.67,100,1,12.43,666,1,11.69,2,1,11.52,100,1,11.29,100,1,11.24,100,1,11.05,100,1,11.01,100,1,13.40,0,-10,13.78,0,-1,13.93,0,-1,14.20,0,-1,14.26,0,-1,14.27,0,-1,14.29,0,-4,14.30,0,-4,14.34,0,-1,14.46,0,-1,ARL,0
2025-07-17T13:46:09.541846554Z,2025-07-17T13:46:09.541680473Z,10,2,1108,A,A,10,15.040000000,100,84607805,166081,69578550,12.99,100,1,12.73,100,1,12.67,100,1,12.43,666,1,11.69,2,1,11.52,100,1,11.29,100,1,11.24,100,1,11.05,100,1,11.01,100,1,13.40,0,-10,13.78,0,-1,13.93,0,-1,14.20,0,-1,14.26,0,-1,14.27,0,-1,14.29,0,-4,14.30,0,-4,14.34,0,-1,14.46,0,-1,ARL,0
2025-07-17T13:46:09.541847519Z,2025-07-17T13:46:09.541682402Z,10,2,1108,A,A,10,14.280000000,100,84607809,165117,69578551,12.99,100,1,12.73,100,1,12.67,100,1,12.43,666,1,11.69,2,1,11.52,100,1,11.29,100,1,11.24,100,1,11.05,100,1,11.01,100,1,13.40,0,-10,13.78,0,-1,13.93,0,-1,14.20,0,-1,14.26,0,-1,14.27,0,-1,14.29,0,-4,14.30,0,-4,14.34,0,-1,14.46,0,-1,ARL,0
2025-07-17T13:46:09.542961756Z,2025-07-17T13:46:09.542796050Z,10,2,1108,C,A,10,15.410000000,100,43826805,165706,69578574,12.99,100,1,12.73,100,1,12.67,100,1,12.43,666,1,11.69,2,1,11.52,100,1,11.29,100,1,11.24,100,1,11.05,100,1,11.01,100,1,13.40,0,-10,13.78,0,-1,13.93,0,-1,14.20,0,-1,14.26,0,-1,14.27,0,-1,14.28,0,-1,14.29,0,-4,14.30,0,-4,14.34,0,-1,ARL,0
2025-07-17T13:46:09.542961756Z,2025-07-17T13:46:09.542796050Z,10,2,1108,A,A,10,15.730000000,100,84607837,165706,69578574,12.99,100,1,12.73,100,1,12.67,100,1,12.43,666,1,11.69,2,1,11.52,100,1,11.29,100,1,11.24,100,1,11.05,100,1,11.01,100,1,13.40,0,-10,13.78,0,-1,13.93,0,-1,14.20,0,-1,14.26,0,-1,14.27,0,-1,14.28,0,-1,14.29,0,-4,14.30,0,-4,14.34,0,-1,ARL,0
2025-07-17T13:46:09.543510155Z,2025-07-17T13:46:09.543344724Z,10,2,1108,C,A,10,17.020000000,100,44082969,165431,69578598,12.99,100,1,12.73,100,1,12.67,100,1,12.43,666,1,11.69,2,1,11.52,100,1,11.29,100,1,11.24,100,1,11.05,100,1,11.01,100,1,13.40,0,-10,13.78,0,-1,13.93,0,-1,14.20,0,-1,14.26,0,-1,14.27,0,-1,14.28,0,-1,14.29,0,-4,14.30,0,-4,14.34,0,-1,ARL,0
2025-07-17T13:46:09.543510155Z,2025-07-17T13:46:09.543344724Z,10,2,1108,A,A,10,17.370000000,100,84607861,165431,69578598,12.99,100,1,12.73,100,1,12.67,100,1,12.43,666,1,11.69,2,1,11.52,100,1,11.29,100,1,11.24,100,1,11.05,100,1,11.01,100,1,13.40,0,-10,13.78,0,-1,13.93,0,-1,14.20,0,-1,14.26,0,-1,14.27,0,-1,14.28,0,-1,14.29,0,-4,14.30,0,-4,14.34,0,-1,ARL,0
2025-07-17T13:46:09.546546482Z,2025-07-17T13:46:09.546381306Z,10,2,1108,C,A,10,14.200000000,100,43554141,165176,69578814,12.99,100,1,12.73,100,1,12.67,100,1,12.43,666,1,11.69,2,1,11.52,100,1,11.29,100,1,11.24,100,1,11.05,100,1,11.01,100,1,13.40,0,-10,13.78,0,-1,13.93,0,-1,14.20,0,-1,14.26,0,-1,14.27,0,-1,14.28,0,-1,14.29,0,-4,14.30,0,-4,14.34,0,-1,ARL,0
2025-07-17T13:46:09.546656996Z,2025-07-17T13:46:09.546491223Z,10,2,1108,A,A,10,14.470000000,100,84608321,165773,69578831,12.99,100,1,12.73,100,1,12.67,100,1,12.43,666,1,11.69,2,1,11.52,100,1,11.29,100,1,11.24,100,1,11.05,100,1,11.01,100,1,13.40,0,-10,13.78,0,-1,13.93,0,-1,14.20,0,-1,14.26,0,-1,14.27,0,-1,14.28,0,-1,14.29,0,-4,14.30,0,-4,14.34,0,-1,ARL,0
2025-07-17T13:46:09.560918620Z,2025-07-17T13:46:09.560753276Z,10,2,1108,C,A,10,13.670000000,100,43953649,165344,69579444,12.99,100,1,12.73,100,1,12.67,100,1,12.43,666,1,11.69,2,1,11.52,100,1,11.29,100,1,11.24,100,1,11.05,100,1,11.01,100,1,13.40,0,-10,13.78,0,-1,13.93,0,-1,14.20,0,-1,14.26,0,-1,14.27,0,-1,14.28,0,-1,14.29,0,-4,14.30,0,-4,14.34,0,-1,ARL,0
2025-07-17T13:46:09.560953850Z,2025-07-17T13:46:09.560789009Z,10,2,1108,C,A,10,14.360000000,700,84607761,164841,69579446,12.99,100,1,12.73,100,1,12.67,100,1,12.43,666,1,11.69,2,1,11.52,100,1,11.29,100,1,11.24,100,1,11.05,100,1,11.01,100,1,13.40,0,-10,13.78,0,-1,13.93,0,-1,14.20,0,-1,14.26,0,-1,14.27,0,-1,14.28,0,-1,14.29,0,-4,14.30,0,-4,14.34,0,-1,ARL,0
2025-07-17T13:46:09.560968819Z,2025-07-17T13:46:09.560803559Z,10,2,1108,A,A,10,13.940000000,100,84609305,165260,69579448,12.99,100,1,12.73,100,1,12.67,100,1,12.43,666,1,11.69,2,1,11.52,100,1,11.29,100,1,11.24,100,1,11.05,100,1,11.01,100,1,13.40,0,-10,13.78,0,-1,13.93,0,-1,14.20,0,-1,14.26,0,-1,14.27,0,-1,14.28,0,-1,14.29,0,-4,14.30,0,-4,14.34,0,-1,ARL,0
2025-07-17T13:46:09.560981020Z,2025-07-17T13:46:09.560815603Z,10,2,1108,C,A,10,14.270000000,700,44491681,165417,69579449,12.99,100,1,12.73,100,1,12.67,100,1,12.43,666,1,11.69,2,1,11.52,100,1,11.29,100,1,11.24,100,1,11.05,100,1,11.01,100,1,13.40,0,-10,13.78,0,-1,13.93,0,-1,13.94,0,-1,14.20,0,-1,14.26,0,-1,14.27,0,-1,14.28,0,-1,14.29,0,-4,14.30,0,-4,ARL,0
2025-07-17T13:46:09.560990769Z,2025-07-17T13:46:09.560825413Z,10,2,1108,A,A,10,15.890000000,100,84609309,165356,69579450,12.99,100,1,12.73,100,1,12.67,100,1,12.43,666,1,11.69,2,1,11.52,100,1,11.29,100,1,11.24,100,1,11.05,100,1,11.01,100,1,13.40,0,-10,13.78,0,-1,13.93,0,-1,13.94,0,-1,14.20,0,-1,14.26,0,-1,14.27,0,-1,14.28,0,-1,14.29,0,-4,14.30,0,-4,ARL,0
2025-07-17T13:46:09.561002700Z,2025-07-17T13:46:09.560837771Z,10,2,1108,C,A,10,15.590000000,100,84607765,164929,69579453,12.99,100,1,12.73,100,1,12.67,100,1,12.43,666,1,11.69,2,1,11.52,100,1,11.29,100,1,11.24,100,1,11.05,100,1,11.01,100,1,13.40,0,-10,13.78,0,-1,13.93,0,-1,13.94,0,-1,14.20,0,-1,14.26,0,-1,14.27,0,-1,14.28,0,-1,14.29,0,-4,14.30,0,-4,ARL,0
2025-07-17T13:46:09.561059021Z,2025-07-17T13:46:09.560893546Z,10,2,1108,A,A,10,14.700000000,700,84609321,165475,69579455,12.99,100,1,12.73,100,1,12.67,100,1,12.43,666,1,11.69,2,1,11.52,100,1,11.29,100,1,11.24,100,1,11.05,100,1,11.01,100,1,13.40,0,-10,13.78,0,-1,13.93,0,-1,13.94,0,-1,14.20,0,-1,14.26,0,-1,14.27,0,-1,14.28,0,-1,14.29,0,-4,14.30,0,-4,ARL,0
2025-07-17T13:46:09.561710911Z,2025-07-17T13:46:09.561543868Z,10,2,1108,C,A,10,14.260000000,700,44598153,167043,69579488,12.99,100,1,12.73,100,1,12.67,100,1,12.43,666,1,11.69,2,1,11.52,100,1,11.29,100,1,11.24,100,1,11.05,100,1,11.01,100,1,13.40,0,-10,13.78,0,-1,13.93,0,-1,13.94,0,-1,14.20,0,-1,14.26,0,-1,14.27,0,-1,14.28,0,-1,14.29,0,-4,14.30,0,-4,ARL,0
2025-07-17T13:46:09.561954989Z,2025-07-17T13:46:09.561788417Z,10,2,1108,C,A,10,15.040000000,100,84607805,166572,69579536,12.99,100,1,12.73,100,1,12.67,100,1,12.43,666,1,11.69,2,1,11.52,100,1,11.29,100,1,11.24,100,1,11.05,100,1,11.01,100,1,13.40,0,-10,13.78,0,-1,13.93,0,-1,13.94,0,-1,14.20,0,-1,14.26,0,-1,14.27,0,-1,14.28,0,-1,14.29,0,-4,14.30,0,-4,ARL,0
2025-07-17T13:46:09.561954989Z,2025-07-17T13:46:09.561788417Z,10,2,1108,A,A,10,15.330000000,100,84609385,166572,69579536,12.99,100,1,12.73,100,1,12.67,100,1,12.43,666,1,11.69,2,1,11.52,100,1,11.29,100,1,11.24,100,1,11.05,100,1,11.01,100,1,13.40,0,-10,13.78,0,-1,13.93,0,-1,13.94,0,-1,14.20,0,-1,14.26,0,-1,14.27,0,-1,14.28,0,-1,14.29,0,-4,14.30,0,-4,ARL,0
2025-07-17T13:46:09.561954989Z,2025-07-17T13:46:09.561788902Z,10,2,1108,C,A,10,14.630000000,100,84607801,166087,69579537,12.99,100,1,12.73,100,1,12.67,100,1,12.43,666,1,11.69,2,1,11.52,100,1,11.29,100,1,11.24,100,1,11.05,100,1,11.01,100,1,13.40,0,-10,13.78,0,-1,13.93,0,-1,13.94,0,-1,14.20,0,-1,14.26,0,-1,14.27,0,-1,14.28,0,-1,14.29,0,-4,14.30,0,-4,ARL,0
2025-07-17T13:46:09.561954989Z,2025-07-17T13:46:09.561788902Z,10,2,1108,A,A,10,14.910000000,100,84609389,166087,69579537,12.99,100,1,12.73,100,1,12.67,100,1,12.43,666,1,11.69,2,1,11.52,100,1,11.29,100,1,11.24,100,1,11.05,100,1,11.01,100,1,13.40,0,-10,13.78,0,-1,13.93,0,-1,13.94,0,-1,14.20,0,-1,14.26,0,-1,14.27,0,-1,14.28,0,-1,14.29,0,-4,14.30,0,-4,ARL,0
2025-07-17T13:46:09.562157451Z,2025-07-17T13:46:09.561992206Z,10,2,1108,A,A,10,14.670000000,700,84609409,165245,69579579,12.99,100,1,12.73,100,1,12.67,100,1,12.43,666,1,11.69,2,1,11.52,100,1,11.29,100,1,11.24,100,1,11.05,100,1,11.01,100,1,13.40,0,-10,13.78,0,-1,13.93,0,-1,13.94,0,-1,14.20,0,-1,14.26,0,-1,14.27,0,-1,14.28,0,-1,14.29,0,-4,14.30,0,-4,ARL,0
2025-07-17T13:46:09.563782397Z,2025-07-17T13:46:09.563617017Z,10,2,1108,C,A,10,17.370000000,100,84607861,165380,69579787,12.99,100,1,12.73,100,1,12.67,100,1,12.43,666,1,11.69,2,1,11.52,100,1,11.29,100,1,11.24,100,1,11.05,100,1,11.01,100,1,13.40,0,-10,13.78,0,-1,13.93,0,-1,13.94,0,-1,14.20,0,-1,14.26,0,-1,14.27,0,-1,14.28,0,-1,14.29,0,-4,14.30,0,-4,ARL,0
2025-07-17T13:46:09.563782397Z,2025-07-17T13:46:09.563617017Z,10,2,1108,A,A,10,17.700000000,100,84609557,165380,69579787,12.99,100,1,12.73,100,1,12.67,100,1,12.43,666,1,11.69,2,1,11.52,100,1,11.29,100,1,11.24,100,1,11.05,100,1,11.01,100,1,13.40,0,-10,13.78,0,-1,13.93,0,-1,13.94,0,-1,14.20,0,-1,14.26,0,-1,14.27,0,-1,14.28,0,-1,14.29,0,-4,14.30,0,-4,ARL,0
2025-07-17T13:46:09.565379544Z,2025-07-17T13:46:09.565213822Z,10,2,1108,C,A,10,13.780000000,2,58709197,165722,69579892,12.99,100,1,12.73,100,1,12.67,100,1,12.43,666,1,11.69,2,1,11.52,100,1,11.29,100,1,11.24,100,1,11.05,100,1,11.01,100,1,13.40,0,-10,13.78,0,-1,13.93,0,-1,13.94,0,-1,14.20,0,-1,14.26,0,-1,14.27,0,-1,14.28,0,-1,14.29,0,-4,14.30,0,-4,ARL,0
2025-07-17T13:46:09.565379544Z,2025-07-17T13:46:09.565213822Z,10,2,1108,A,A,10,13.930000000,2,84609637,165722,69579892,12.99,100,1,12.73,100,1,12.67,100,1,12.43,666,1,11.69,2,1,11.52,100,1,11.29,100,1,11.24,100,1,11.05,100,1,11.01,100,1,13.40,0,-10,13.78,0,-1,13.93,0,-1,13.94,0,-1,14.20,0,-1,14.26,0,-1,14.27,0,-1,14.28,0,-1,14.29,0,-4,14.30,0,-4,ARL,0
2025-07-17T13:46:09.565403598Z,2025-07-17T13:46:09.565237899Z,10,2,1108,C,A,10,15.730000000,100,84607837,165699,69579893,12.99,100,1,12.73,100,1,12.67,100,1,12.43,666,1,11.69,2,1,11.52,100,1,11.29,100,1,11.24,100,1,11.05,100,1,11.01,100,1,13.40,0,-10,13.78,0,-1,13.93,0,-2,13.94,0,-1,14.20,0,-1,14.26,0,-1,14.27,0,-1,14.28,0,-1,14.29,0,-4,14.30,0,-4,ARL,0
2025-07-17T13:46:09.565403598Z,2025-07-17T13:46:09.565237899Z,10,2,1108,A,A,10,16.020000000,100,84609645,165699,69579893,12.99,100,1,12.73,100,1,12.67,100,1,12.43,666,1,11.69,2,1,11.52,100,1,11.29,100,1,11.24,100,1,11.05,100,1,11.01,100,1,13.40,0,-10,13.78,0,-1,13.93,0,-2,13.94,0,-1,14.20,0,-1,14.26,0,-1,14.27,0,-1,14.28,0,-1,14.29,0,-4,14.30,0,-4,ARL,0
2025-07-17T13:46:09.566687064Z,2025-07-17T13:46:09.566522227Z,10,2,1108,C,A,10,13.940000000,100,84609305,164837,69579922,12.99,100,1,12.73,100,1,12.67,100,1,12.43,666,1,11.69,2,1,11.52,100,1,11.29,100,1,11.24,100,1,11.05,100,1,11.01,100,1,13.40,0,-10,13.78,0,-1,13.93,0,-2,13.94,0,-1,14.20,0,-1,14.26,0,-1,14.27,0,-1,14.28,0,-1,14.29,0,-4,14.30,0,-4,ARL,0
2025-07-17T13:46:09.566736503Z,2025-07-17T13:46:09.566571131Z,10,2,1108,A,A,10,14.210000000,100,84609733,165372,69579923,12.99,100,1,12.73,100,1,12.67,100,1,12.43,666,1,11.69,2,1,11.52,100,1,11.29,100,1,11.24,100,1,11.05,100,1,11.01,100,1,13.40,0,-10,13.78,0,-1,13.93,0,-2,13.94,0,-1,14.20,0,-1,14.26,0,-1,14.27,0,-1,14.28,0,-1,14.29,0,-4,14.30,0,-4,ARL,0
2025-07-17T13:46:09.583735074Z,2025-07-17T13:46:09.583569619Z,10,2,1108,C,A,10,14.740000000,100,43852129,165455,69580598,12.99,100,1,12.73,100,1,12.67,100,1,12.43,666,1,11.69,2,1,11.52,100,1,11.29,100,1,11.24,100,1,11.05,100,1,11.01,100,1,13.40,0,-10,13.78,0,-1,13.93,0,-2,13.94,0,-1,14.20,0,-1,14.21,0,-1,14.26,0,-1,14.27,0,-1,14.28,0,-1,14.29,0,-4,ARL,0
2025-07-17T13:46:09.583735074Z,2025-07-17T13:46:09.583569619Z,10,2,1108,A,A,10,15.330000000,100,84611025,165455,69580598,12.99,100,1,12.73,100,1,12.67,100,1,12.43,666,1,11.69,2,1,11.52,100,1,11.29,100,1,11.24,100,1,11.05,100,1,11.01,100,1,13.40,0,-10,13.78,0,-1,13.93,0,-2,13.94,0,-1,14.20,0,-1,14.21,0,-1,14.26,0,-1,14.27,0,-1,14.28,0,-1,14.29,0,-4,ARL,0
2025-07-17T13:46:09.591552337Z,2025-07-17T13:46:09.591386919Z,10,2,1108,C,A,10,14.490000000,100,84607785,165418,69581249,12.99,100,1,12.73,100,1,12.67,100,1,12.43,666,1,11.69,2,1,11.52,100,1,11.29,100,1,11.24,100,1,11.05,100,1,11.01,100,1,13.40,0,-10,13.78,0,-1,13.93,0,-2,13.94,0,-1,14.20,0,-1,14.21,0,-1,14.26,0,-1,14.27,0,-1,14.28,0,-1,14.29,0,-4,ARL,0
2025-07-17T13:46:09.591552337Z,2025-07-17T13:46:09.591386919Z,10,2,1108,A,A,10,15.010000000,100,84611613,165418,69581249,12.99,100,1,12.73,100,1,12.67,100,1,12.43,666,1,11.69,2,1,11.52,100,1,11.29,100,1,11.24,100,1,11.05,100,1,11.01,100,1,13.40,0,-10,13.78,0,-1,13.93,0,-2,13.94,0,-1,14.20,0,-1,14.21,0,-1,14.26,0,-1,14.27,0,-1,14.28,0,-1,14.29,0,-4,ARL,0
2025-07-17T13:46:09.595667047Z,2025-07-17T13:46:09.595500037Z,10,2,1108,A,A,10,14.630000000,700,84612081,167010,69582059,12.99,100,1,12.73,100,1,12.67,100,1,12.43,666,1,11.69,2,1,11.52,100,1,11.29,100,1,11.24,100,1,11.05,100,1,11.01,100,1,13.40,0,-10,13.78,0,-1,13.93,0,-2,13.94,0,-1,14.20,0,-1,14.21,0,-1,14.26,0,-1,14.27,0,-1,14.28,0,-1,14.29,0,-4,ARL,0
2025-07-17T13:46:09.610291566Z,2025-07-17T13:46:09.610126066Z,10,2,1108,C,A,10,14.340000000,100,44088637,165500,69582709,12.99,100,1,12.73,100,1,12.67,100,1,12.43,666,1,11.69,2,1,11.52,100,1,11.29,100,1,11.24,100,1,11.05,100,1,11.01,100,1,13.40,0,-10,13.78,0,-1,13.93,0,-2,13.94,0,-1,14.20,0,-1,14.21,0,-1,14.26,0,-1,14.27,0,-1,14.28,0,-1,14.29,0,-4,ARL,0
2025-07-17T13:46:09.610291566Z,2025-07-17T13:46:09.610126066Z,10,2,1108,A,A,10,14.910000000,100,84612773,165500,69582709,12.99,100,1,12.73,100,1,12.67,100,1,12.43,666,1,11.69,2,1,11.52,100,1,11.29,100,1,11.24,100,1,11.05,100,1,11.01,100,1,13.40,0,-10,13.78,0,-1,13.93,0,-2,13.94,0,-1,14.20,0,-1,14.21,0,-1,14.26,0,-1,14.27,0,-1,14.28,0,-1,14.29,0,-4,ARL,0
2025-07-17T13:46:09.812938843Z,2025-07-17T13:46:09.812773551Z,10,2,1108,A,A,10,14.760000000,100,84618189,165292,69586965,12.99,100,1,12.73,100,1,12.67,100,1,12.43,666,1,11.69,2,1,11.52,100,1,11.29,100,1,11.24,100,1,11.05,100,1,11.01,100,1,13.40,0,-10,13.78,0,-1,13.93,0,-2,13.94,0,-1,14.20,0,-1,14.21,0,-1,14.26,0,-1,14.27,0,-1,14.28,0,-1,14.29,0,-4,ARL,0
2025-07-17T13:46:09.812950020Z,2025-07-17T13:46:09.812784722Z,10,2,1108,C,A,10,14.200000000,100,43804081,165298,69586966,12.99,100,1,12.73,100,1,12.67,100,1,12.43,666,1,11.69,2,1,11.52,100,1,11.29,100,1,11.24,100,1,11.05,100,1,11.01,100,1,13.40,0,-10,13.78,0,-1,13.93,0,-2,13.94,0,-1,14.20,0,-1,14.21,0,-1,14.26,0,-1,14.27,0,-1,14.28,0,-1,14.29,0,-4,ARL,0
2025-07-17T13:46:09.936895839Z,2025-07-17T13:46:09.936730596Z,10,2,1108,C,A,10,13.930000000,100,44066417,165243,69592193,12.99,100,1,12.73,100,1,12.67,100,1,12.43,666,1,11.69,2,1,11.52,100,1,11.29,100,1,11.24,100,1,11.05,100,1,11.01,100,1,13.40,0,-10,13.78,0,-1,13.93,0,-2,13.94,0,-1,14.20,0,-1,14.21,0,-1,14.26,0,-1,14.27,0,-1,14.28,0,-1,14.29,0,-4,ARL,0
2025-07-17T13:46:09.936896832Z,2025-07-17T13:46:09.936731544Z,10,2,1108,A,A,10,14.480000000,100,84624129,165288,69592194,12.99,100,1,12.73,100,1,12.67,100,1,12.43,666,1,11.69,2,1,11.52,100,1,11.29,100,1,11.24,100,1,11.05,100,1,11.01,100,1,13.40,0,-10,13.78,0,-1,13.93,0,-2,13.94,0,-1,14.20,0,-1,14.21,0,-1,14.26,0,-1,14.27,0,-1,14.28,0,-1,14.29,0,-4,ARL,0
2025-07-17T13:46:09.937622396Z,2025-07-17T13:46:09.937457145Z,10,2,1108,C,A,10,15.010000000,100,84611613,165251,69592231,12.99,100,1,12.73,100,1,12.67,100,1,12.43,666,1,11.69,2,1,11.52,100,1,11.29,100,1,11.24,100,1,11.05,100,1,11.01,100,1,13.40,0,-10,13.78,0,-1,13.93,0,-2,13.94,0,-1,14.20,0,-1,14.21,0,-1,14.26,0,-1,14.27,0,-1,14.28,0,-1,14.29,0,-4,ARL,0
2025-07-17T13:46:09.937622396Z,2025-07-17T13:46:09.937457145Z,10,2,1108,A,A,10,15.060000000,100,84624201,165251,69592231,12.99,100,1,12.73,100,1,12.67,100,1,12.43,666,1,11.69,2,1,11.52,100,1,11.29,100,1,11.24,100,1,11.05,100,1,11.01,100,1,13.40,0,-10,13.78,0,-1,13.93,0,-2,13.94,0,-1,14.20,0,-1,14.21,0,-1,14.26,0,-1,14.27,0,-1,14.28,0,-1,14.29,0,-4,ARL,0
2025-07-17T13:46:10.046960966Z,2025-07-17T13:46:10.046795728Z,10,2,1108,C,A,10,14.700000000,700,84609321,165238,69596523,12.99,100,1,12.73,100,1,12.67,100,1,12.43,666,1,11.69,2,1,11.52,100,1,11.29,100,1,11.24,100,1,11.05,100,1,11.01,100,1,13.40,0,-10,13.78,0,-1,13.93,0,-2,13.94,0,-1,14.20,0,-1,14.21,0,-1,14.26,0,-1,14.27,0,-1,14.28,0,-1,14.29,0,-4,ARL,0
2025-07-17T13:46:10.046962793Z,2025-07-17T13:46:10.046796743Z,10,2,1108,C,A,10,14.630000000,700,84612081,166050,69596524,12.99,100,1,12.73,100,1,12.67,100,1,12.43,666,1,11.69,2,1,11.52,100,1,11.29,100,1,11.24,100,1,11.05,100,1,11.01,100,1,13.40,0,-10,13.78,0,-1,13.93,0,-2,13.94,0,-1,14.20,0,-1,14.21,0,-1,14.26,0,-1,14.27,0,-1,14.28,0,-1,14.29,0,-4,ARL,0
2025-07-17T13:46:10.047001176Z,2025-07-17T13:46:10.046834863Z,10,2,1108,A,A,10,14.990000000,700,84628757,166313,69596525,12.99,100,1,12.73,100,1,12.67,100,1,12.43,666,1,11.69,2,1,11.52,100,1,11.29,100,1,11.24,100,1,11.05,100,1,11.01,100,1,13.40,0,-10,13.78,0,-1,13.93,0,-2,13.94,0,-1,14.20,0,-1,14.21,0,-1,14.26,0,-1,14.27,0,-1,14.28,0,-1,14.29,0,-4,ARL,0
2025-07-17T13:46:10.047001176Z,2025-07-17T13:46:10.046835277Z,10,2,1108,A,A,10,14.910000000,700,84628761,165899,69596526,12.99,100,1,12.73,100,1,12.67,100,1,12.43,666,1,11.69,2,1,11.52,100,1,11.29,100,1,11.24,100,1,11.05,100,1,11.01,100,1,13.40,0,-10,13.78,0,-1,13.93,0,-2,13.94,0,-1,14.20,0,-1,14.21,0,-1,14.26,0,-1,14.27,0,-1,14.28,0,-1,14.29,0,-4,ARL,0
2025-07-17T13:46:10.047030471Z,2025-07-17T13:46:10.046864551Z,10,2,1108,A,A,10,16.200000000,100,84628765,165920,69596527,12.99,100,1,12.73,100,1,12.67,100,1,12.43,666,1,11.69,2,1,11.52,100,1,11.29,100,1,11.24,100,1,11.05,100,1,11.01,100,1,13.40,0,-10,13.78,0,-1,13.93,0,-2,13.94,0,-1,14.20,0,-1,14.21,0,-1,14.26,0,-1,14.27,0,-1,14.28,0,-1,14.29,0,-4,ARL,0
2025-07-17T13:46:10.047042954Z,2025-07-17T13:46:10.046877789Z,10,2,1108,C,A,10,15.890000000,100,84609309,165165,69596529,12.99,100,1,12.73,100,1,12.67,100,1,12.43,666,1,11.69,2,1,11.52,100,1,11.29,100,1,11.24,100,1,11.05,100,1,11.01,100,1,13.40,0,-10,13.78,0,-1,13.93,0,-2,13.94,0,-1,14.20,0,-1,14.21,0,-1,14.26,0,-1,14.27,0,-1,14.28,0,-1,14.29,0,-4,ARL,0
2025-07-17T13:46:10.047089640Z,2025-07-17T13:46:10.046924268Z,10,2,1108,C,A,10,13.930000000,2,84609637,165372,69596531,12.99,100,1,12.73,100,1,12.67,100,1,12.43,666,1,11.69,2,1,11.52,100,1,11.29,100,1,11.24,100,1,11.05,100,1,11.01,100,1,13.40,0,-10,13.78,0,-1,13.93,0,-2,13.94,0,-1,14.20,0,-1,14.21,0,-1,14.26,0,-1,14.27,0,-1,14.28,0,-1,14.29,0,-4,ARL,0
2025-07-17T13:46:10.047089640Z,2025-07-17T13:46:10.046924268Z,10,2,1108,A,A,10,14.200000000,2,84628773,165372,69596531,12.99,100,1,12.73,100,1,12.67,100,1,12.43,666,1,11.69,2,1,11.52,100,1,11.29,100,1,11.24,100,1,11.05,100,1,11.01,100,1,13.40,0,-10,13.78,0,-1,13.93,0,-2,13.94,0,-1,14.20,0,-1,14.21,0,-1,14.26,0,-1,14.27,0,-1,14.28,0,-1,14.29,0,-4,ARL,0
2025-07-17T13:46:10.047429477Z,2025-07-17T13:46:10.047264301Z,10,2,1108,C,A,10,14.280000000,100,84607809,165176,69596542,12.99,100,1,12.73,100,1,12.67,100,1,12.43,666,1,11.69,2,1,11.52,100,1,11.29,100,1,11.24,100,1,11.05,100,1,11.01,100,1,13.40,0,-10,13.78,0,-1,13.93,0,-2,13.94,0,-1,14.20,0,-2,14.21,0,-1,14.26,0,-1,14.27,0,-1,14.28,0,-1,14.29,0,-4,ARL,0
2025-07-17T13:46:10.047479201Z,2025-07-17T13:46:10.047313929Z,10,2,1108,C,A,10,14.670000000,700,84609409,165272,69596543,12.99,100,1,12.73,100,1,12.67,100,1,12.43,666,1,11.69,2,1,11.52,100,1,11.29,100,1,11.24,100,1,11.05,100,1,11.01,100,1,13.40,0,-10,13.78,0,-1,13.93,0,-2,13.94,0,-1,14.20,0,-2,14.21,0,-1,14.26,0,-1,14.27,0,-1,14.28,0,-1,14.29,0,-4,ARL,0
2025-07-17T13:46:10.047784342Z,2025-07-17T13:46:10.047618250Z,10,2,1108,A,A,10,14.830000000,100,84628793,166092,69596548,12.99,100,1,12.73,100,1,12.67,100,1,12.43,666,1,11.69,2,1,11.52,100,1,11.29,100,1,11.24,100,1,11.05,100,1,11.01,100,1,13.40,0,-10,13.78,0,-1,13.93,0,-2,13.94,0,-1,14.20,0,-2,14.21,0,-1,14.26,0,-1,14.27,0,-1,14.28,0,-1,14.29,0,-4,ARL,0
2025-07-17T13:46:10.047806230Z,2025-07-17T13:46:10.047640842Z,10,2,1108,C,A,10,14.460000000,700,44548325,165388,69596550,12.99,100,1,12.73,100,1,12.67,100,1,12.43,666,1,11.69,2,1,11.52,100,1,11.29,100,1,11.24,100,1,11.05,100,1,11.01,100,1,13.40,0,-10,13.78,0,-1,13.93,0,-2,13.94,0,-1,14.20,0,-2,14.21,0,-1,14.26,0,-1,14.27,0,-1,14.28,0,-1,14.29,0,-4,ARL,0
2025-07-17T13:46:10.047885265Z,2025-07-17T13:46:10.047719954Z,10,2,1108,A,A,10,14.950000000,700,84628797,165311,69596551,12.99,100,1,12.73,100,1,12.67,100,1,12.43,666,1,11.69,2,1,11.52,100,1,11.29,100,1,11.24,100,1,11.05,100,1,11.01,100,1,13.40,0,-10,13.78,0,-1,13.93,0,-2,13.94,0,-1,14.20,0,-2,14.21,0,-1,14.26,0,-1,14.27,0,-1,14.28,0,-1,14.29,0,-4,ARL,0
2025-07-17T13:46:10.047929072Z,2025-07-17T13:46:10.047763743Z,10,2,1108,C,A,10,14.910000000,100,84609389,165329,69596552,12.99,100,1,12.73,100,1,12.67,100,1,12.43,666,1,11.69,2,1,11.52,100,1,11.29,100,1,11.24,100,1,11.05,100,1,11.01,100,1,13.40,0,-10,13.78,0,-1,13.93,0,-2,13.94,0,-1,14.20,0,-2,14.21,0,-1,14.26,0,-1,14.27,0,-1,14.28,0,-1,14.29,0,-4,ARL,0
2025-07-17T13:46:10.047929072Z,2025-07-17T13:46:10.047763743Z,10,2,1108,A,A,10,15.200000000,100,84628801,165329,69596552,12.99,100,1,12.73,100,1,12.67,100,1,12.43,666,1,11.69,2,1,11.52,100,1,11.29,100,1,11.24,100,1,11.05,100,1,11.01,100,1,13.40,0,-10,13.78,0,-1,13.93,0,-2,13.94,0,-1,14.20,0,-2,14.21,0,-1,14.26,0,-1,14.27,0,-1,14.28,0,-1,14.29,0,-4,ARL,0
2025-07-17T13:46:10.047983286Z,2025-07-17T13:46:10.047817649Z,10,2,1108,C,A,10,15.060000000,100,84624201,165637,69596553,12.99,100,1,12.73,100,1,12.67,100,1,12.43,666,1,11.69,2,1,11.52,100,1,11.29,100,1,11.24,100,1,11.05,100,1,11.01,100,1,13.40,0,-10,13.78,0,-1,13.93,0,-2,13.94,0,-1,14.20,0,-2,14.21,0,-1,14.26,0,-1,14.27,0,-1,14.28,0,-1,14.29,0,-4,ARL,0
2025-07-17T13:46:10.047983286Z,2025-07-17T13:46:10.047817649Z,10,2,1108,A,A,10,15.300000000,100,84628813,165637,69596553,12.99,100,1,12.73,100,1,12.67,100,1,12.43,666,1,11.69,2,1,11.52,100,1,11.29,100,1,11.24,100,1,11.05,100,1,11.01,100,1,13.40,0,-10,13.78,0,-1,13.93,0,-2,13.94,0,-1,14.20,0,-2,14.21,0,-1,14.26,0,-1,14.27,0,-1,14.28,0,-1,14.29,0,-4,ARL,0
2025-07-17T13:46:10.048529147Z,2025-07-17T13:46:10.048363798Z,10,2,1108,A,A,10,15.140000000,700,84628829,165349,69596568,12.99,100,1,12.73,100,1,12.67,100,1,12.43,666,1,11.69,2,1,11.52,100,1,11.29,100,1,11.24,100,1,11.05,100,1,11.01,100,1,13.40,0,-10,13.78,0,-1,13.93,0,-2,13.94,0,-1,14.20,0,-2,14.21,0,-1,14.26,0,-1,14.27,0,-1,14.28,0,-1,14.29,0,-4,ARL,0
2025-07-17T13:46:10.048840949Z,2025-07-17T13:46:10.048674815Z,10,2,1108,C,A,10,15.330000000,100,84609385,166134,69596577,12.99,100,1,12.73,100,1,12.67,100,1,12.43,666,1,11.69,2,1,11.52,100,1,11.29,100,1,11.24,100,1,11.05,100,1,11.01,100,1,13.40,0,-10,13.78,0,-1,13.93,0,-2,13.94,0,-1,14.20,0,-2,14.21,0,-1,14.26,0,-1,14.27,0,-1,14.28,0,-1,14.29,0,-4,ARL,0
2025-07-17T13:46:10.048840949Z,2025-07-17T13:46:10.048674815Z,10,2,1108,A,A,10,15.640000000,100,84628833,166134,69596577,12.99,100,1,12.73,100,1,12.67,100,1,12.43,666,1,11.69,2,1,11.52,100,1,11.29,100,1,11.24,100,1,11.05,100,1,11.01,100,1,13.40,0,-10,13.78,0,-1,13.93,0,-2,13.94,0,-1,14.20,0,-2,14.21,0,-1,14.26,0,-1,14.27,0,-1,14.28,0,-1,14.29,0,-4,ARL,0
2025-07-17T13:46:10.051935025Z,2025-07-17T13:46:10.051769303Z,10,2,1108,C,A,10,17.700000000,100,84609557,165722,69596649,12.99,100,1,12.73,100,1,12.67,100,1,12.43,666,1,11.69,2,1,11.52,100,1,11.29,100,1,11.24,100,1,11.05,100,1,11.01,100,1,13.40,0,-10,13.78,0,-1,13.93,0,-2,13.94,0,-1,14.20,0,-2,14.21,0,-1,14.26,0,-1,14.27,0,-1,14.28,0,-1,14.29,0,-4,ARL,0
2025-07-17T13:46:10.051935025Z,2025-07-17T13:46:10.051769303Z,10,2,1108,A,A,10,18.050000000,100,84628913,165722,69596649,12.99,100,1,12.73,100,1,12.67,100,1,12.43,666,1,11.69,2,1,11.52,100,1,11.29,100,1,11.24,100,1,11.05,100,1,11.01,100,1,13.40,0,-10,13.78,0,-1,13.93,0,-2,13.94,0,-1,14.20,0,-2,14.21,0,-1,14.26,0,-1,14.27,0,-1,14.28,0,-1,14.29,0,-4,ARL,0
2025-07-17T13:46:10.054332558Z,2025-07-17T13:46:10.054167322Z,10,2,1108,C,A,10,16.020000000,100,84609645,165236,69596777,12.99,100,1,12.73,100,1,12.67,100,1,12.43,666,1,11.69,2,1,11.52,100,1,11.29,100,1,11.24,100,1,11.05,100,1,11.01,100,1,13.40,0,-10,13.78,0,-1,13.93,0,-2,13.94,0,-1,14.20,0,-2,14.21,0,-1,14.26,0,-1,14.27,0,-1,14.28,0,-1,14.29,0,-4,ARL,0
2025-07-17T13:46:10.054332558Z,2025-07-17T13:46:10.054167322Z,10,2,1108,A,A,10,16.350000000,100,84629065,165236,69596777,12.99,100,1,12.73,100,1,12.67,100,1,12.43,666,1,11.69,2,1,11.52,100,1,11.29,100,1,11.24,100,1,11.05,100,1,11.01,100,1,13.40,0,-10,13.78,0,-1,13.93,0,-2,13.94,0,-1,14.20,0,-2,14.21,0,-1,14.26,0,-1,14.27,0,-1,14.28,0,-1,14.29,0,-4,ARL,0
2025-07-17T13:46:10.055434148Z,2025-07-17T13:46:10.055269067Z,10,2,1108,C,A,10,14.210000000,100,84609733,165081,69596798,12.99,100,1,12.73,100,1,12.67,100,1,12.43,666,1,11.69,2,1,11.52,100,1,11.29,100,1,11.24,100,1,11.05,100,1,11.01,100,1,13.40,0,-10,13.78,0,-1,13.93,0,-2,13.94,0,-1,14.20,0,-2,14.21,0,-1,14.26,0,-1,14.27,0,-1,14.28,0,-1,14.29,0,-4,ARL,0
2025-07-17T13:46:10.055483249Z,2025-07-17T13:46:10.055317945Z,10,2,1108,A,A,10,14.480000000,100,84629093,165304,69596799,12.99,100,1,12.73,100,1,12.67,100,1,12.43,666,1,11.69,2,1,11.52,100,1,11.29,100,1,11.24,100,1,11.05,100,1,11.01,100,1,13.40,0,-10,13.78,0,-1,13.93,0,-2,13.94,0,-1,14.20,0,-2,14.21,0,-1,14.26,0,-1,14.27,0,-1,14.28,0,-1,14.29,0,-4,ARL,0
2025-07-17T13:46:10.061411059Z,2025-07-17T13:46:10.061246123Z,10,2,1108,C,A,10,14.480000000,100,84629093,164936,69596987,12.99,100,1,12.73,100,1,12.67,100,1,12.43,666,1,11.69,2,1,11.52,100,1,11.29,100,1,11.24,100,1,11.05,100,1,11.01,100,1,13.40,0,-10,13.78,0,-1,13.93,0,-2,13.94,0,-1,14.20,0,-2,14.21,0,-1,14.26,0,-1,14.27,0,-1,14.28,0,-1,14.29,0,-4,ARL,0
2025-07-17T13:46:10.061459915Z,2025-07-17T13:46:10.061294728Z,10,2,1108,A,A,10,14.590000000,100,84629329,165187,69596990,12.99,100,1,12.73,100,1,12.67,100,1,12.43,666,1,11.69,2,1,11.52,100,1,11.29,100,1,11.24,100,1,11.05,100,1,11.01,100,1,13.40,0,-10,13.78,0,-1,13.93,0,-2,13.94,0,-1,14.20,0,-2,14.21,0,-1,14.26,0,-1,14.27,0,-1,14.28,0,-1,14.29,0,-4,ARL,0
2025-07-17T13:46:10.087891846Z,2025-07-17T13:46:10.087725560Z,10,2,1108,C,A,10,15.330000000,100,84611025,166286,69597697,12.99,100,1,12.73,100,1,12.67,100,1,12.43,666,1,11.69,2,1,11.52,100,1,11.29,100,1,11.24,100,1,11.05,100,1,11.01,100,1,13.40,0,-10,13.78,0,-1,13.93,0,-2,13.94,0,-1,14.20,0,-2,14.21,0,-1,14.26,0,-1,14.27,0,-1,14.28,0,-1,14.29,0,-4,ARL,0
2025-07-17T13:46:10.087891846Z,2025-07-17T13:46:10.087725560Z,10,2,1108,A,A,10,15.730000000,100,84629953,166286,69597697,12.99,100,1,12.73,100,1,12.67,100,1,12.43,666,1,11.69,2,1,11.52,100,1,11.29,100,1,11.24,100,1,11.05,100,1,11.01,100,1,13.40,0,-10,13.78,0,-1,13.93,0,-2,13.94,0,-1,14.20,0,-2,14.21,0,-1,14.26,0,-1,14.27,0,-1,14.28,0,-1,14.29,0,-4,ARL,0
2025-07-17T13:46:10.098194757Z,2025-07-17T13:46:10.098029439Z,10,2,1108,C,A,10,15.300000000,100,84628813,165318,69597813,12.99,100,1,12.73,100,1,12.67,100,1,12.43,666,1,11.69,2,1,11.52,100,1,11.29,100,1,11.24,100,1,11.05,100,1,11.01,100,1,13.40,0,-10,13.78,0,-1,13.93,0,-2,13.94,0,-1,14.20,0,-2,14.21,0,-1,14.26,0,-1,14.27,0,-1,14.28,0,-1,14.29,0,-4,ARL,0
2025-07-17T13:46:10.098194757Z,2025-07-17T13:46:10.098029439Z,10,2,1108,A,A,10,15.410000000,100,84630217,165318,69597813,12.99,100,1,12.73,100,1,12.67,100,1,12.43,666,1,11.69,2,1,11.52,100,1,11.29,100,1,11.24,100,1,11.05,100,1,11.01,100,1,13.40,0,-10,13.78,0,-1,13.93,0,-2,13.94,0,-1,14.20,0,-2,14.21,0,-1,14.26,0,-1,14.27,0,-1,14.28,0,-1,14.29,0,-4,ARL,0
2025-07-17T13:46:10.109235050Z,2025-07-17T13:46:10.109069598Z,10,2,1108,C,A,10,14.910000000,100,84612773,165452,69598154,12.99,100,1,12.73,100,1,12.67,100,1,12.43,666,1,11.69,2,1,11.52,100,1,11.29,100,1,11.24,100,1,11.05,100,1,11.01,100,1,13.40,0,-10,13.78,0,-1,13.93,0,-2,13.94,0,-1,14.20,0,-2,14.21,0,-1,14.26,0,-1,14.27,0,-1,14.28,0,-1,14.29,0,-4,ARL,0
2025-07-17T13:46:10.109235050Z,2025-07-17T13:46:10.109069598Z,10,2,1108,A,A,10,15.310000000,100,84630849,165452,69598154,12.99,100,1,12.73,100,1,12.67,100,1,12.43,666,1,11.69,2,1,11.52,100,1,11.29,100,1,11.24,100,1,11.05,100,1,11.01,100,1,13.40,0,-10,13.78,0,-1,13.93,0,-2,13.94,0,-1,14.20,0,-2,14.21,0,-1,14.26,0,-1,14.27,0,-1,14.28,0,-1,14.29,0,-4,ARL,0
2025-07-17T13:46:10.551481906Z,2025-07-17T13:46:10.551316402Z,10,2,1108,C,A,10,14.470000000,100,84608321,165504,69614455,12.99,100,1,12.73,100,1,12.67,100,1,12.43,666,1,11.69,2,1,11.52,100,1,11.29,100,1,11.24,100,1,11.05,100,1,11.01,100,1,13.40,0,-10,13.78,0,-1,13.93,0,-2,13.94,0,-1,14.20,0,-2,14.21,0,-1,14.26,0,-1,14.27,0,-1,14.28,0,-1,14.29,0,-4,ARL,0
2025-07-17T13:46:10.551481906Z,2025-07-17T13:46:10.551316402Z,10,2,1108,A,A,10,15.090000000,100,84650629,165504,69614455,12.99,100,1,12.73,100,1,12.67,100,1,12.43,666,1,11.69,2,1,11.52,100,1,11.29,100,1,11.24,100,1,11.05,100,1,11.01,100,1,13.40,0,-10,13.78,0,-1,13.93,0,-2,13.94,0,-1,14.20,0,-2,14.21,0,-1,14.26,0,-1,14.27,0,-1,14.28,0,-1,14.29,0,-4,ARL,0
2025-07-17T13:46:10.904838107Z,2025-07-17T13:46:10.904672934Z,10,2,1108,A,A,10,15.160000000,100,84668677,165173,69628781,12.99,100,1,12.73,100,1,12.67,100,1,12.43,666,1,11.69,2,1,11.52,100,1,11.29,100,1,11.24,100,1,11.05,100,1,11.01,100,1,13.40,0,-10,13.78,0,-1,13.93,0,-2,13.94,0,-1,14.20,0,-2,14.21,0,-1,14.26,0,-1,14.27,0,-1,14.28,0,-1,14.29,0,-4,ARL,0
