ts_recv,ts_event,rtype,publisher_id,instrument_id,action,side,depth,price,size,flags,ts_in_delta,sequence,bid_px_00,bid_sz_00,bid_ct_00,bid_px_01,bid_sz_01,bid_ct_01,bid_px_02,bid_sz_02,bid_ct_02,bid_px_03,bid_sz_03,bid_ct_03,bid_px_04,bid_sz_04,bid_ct_04,bid_px_05,bid_sz_05,bid_ct_05,bid_px_06,bid_sz_06,bid_ct_06,bid_px_07,bid_sz_07,bid_ct_07,bid_px_08,bid_sz_08,bid_ct_08,bid_px_09,bid_sz_09,bid_ct_09,ask_px_00,ask_sz_00,ask_ct_00,ask_px_01,ask_sz_01,ask_ct_01,ask_px_02,ask_sz_02,ask_ct_02,ask_px_03,ask_sz_03,ask_ct_03,ask_px_04,ask_sz_04,ask_ct_04,ask_px_05,ask_sz_05,ask_ct_05,ask_px_06,ask_sz_06,ask_ct_06,ask_px_07,ask_sz_07,ask_ct_07,ask_px_08,ask_sz_08,ask_ct_08,ask_px_09,ask_sz_09,ask_ct_09,symbol,order_id
2025-07-17T16:12:40.993818130Z,2025-07-17T16:12:40.993652511Z,10,2,1108,A,A,10,14.850000000,100,338864189,165619,282007882,13.31,10,1,13.28,1,2,13.27,20,2,13.26,198,2,13.14,1,1,13.13,100,1,13.12,200,2,13.11,100,1,13.10,100,1,13.04,2,1,13.40,0,-10,13.48,0,-1,13.49,0,-2,13.50,0,-1,13.51,0,-1,13.53,0,-2,13.54,0,-1,13.55,0,-2,13.56,0,-4,13.57,0,-2,ARL,0
2025-07-17T16:12:40.994783297Z,2025-07-17T16:12:40.994617858Z,10,2,1108,C,A,10,14.490000000,100,337790745,165439,282007892,13.31,10,1,13.28,1,2,13.27,20,2,13.26,198,2,13.14,1,1,13.13,100,1,13.12,200,2,13.11,100,1,13.10,100,1,13.04,2,1,13.40,0,-10,13.48,0,-1,13.49,0,-2,13.50,0,-1,13.51,0,-1,13.53,0,-2,13.54,0,-1,13.55,0,-2,13.56,0,-4,13.57,0,-2,ARL,0
2025-07-17T16:12:40.994783297Z,2025-07-17T16:12:40.994617858Z,10,2,1108,A,A,10,14.760000000,100,338864217,165439,282007892,13.31,10,1,13.28,1,2,13.27,20,2,13.26,198,2,13.14,1,1,13.13,100,1,13.12,200,2,13.11,100,1,13.10,100,1,13.04,2,1,13.40,0,-10,13.48,0,-1,13.49,0,-2,13.50,0,-1,13.51,0,-1,13.53,0,-2,13.54,0,-1,13.55,0,-2,13.56,0,-4,13.57,0,-2,ARL,0
2025-07-17T16:12:40.995078856Z,2025-07-17T16:12:40.994913404Z,10,2,1108,C,A,10,14.840000000,100,338708241,165452,282007894,13.31,10,1,13.28,1,2,13.27,20,2,13.26,198,2,13.14,1,1,13.13,100,1,13.12,200,2,13.11,100,1,13.10,100,1,13.04,2,1,13.40,0,-10,13.48,0,-1,13.49,0,-2,13.50,0,-1,13.51,0,-1,13.53,0,-2,13.54,0,-1,13.55,0,-2,13.56,0,-4,13.57,0,-2,ARL,0
2025-07-17T16:12:40.995078856Z,2025-07-17T16:12:40.994913404Z,10,2,1108,A,A,10,15.170000000,100,338864221,165452,282007894,13.31,10,1,13.28,1,2,13.27,20,2,13.26,198,2,13.14,1,1,13.13,100,1,13.12,200,2,13.11,100,1,13.10,100,1,13.04,2,1,13.40,0,-10,13.48,0,-1,13.49,0,-2,13.50,0,-1,13.51,0,-1,13.53,0,-2,13.54,0,-1,13.55,0,-2,13.56,0,-4,13.57,0,-2,ARL,0
2025-07-17T16:12:40.995349303Z,2025-07-17T16:12:40.995183768Z,10,2,1108,C,A,10,15.600000000,100,337690641,165535,282007898,13.31,10,1,13.28,1,2,13.27,20,2,13.26,198,2,13.14,1,1,13.13,100,1,13.12,200,2,13.11,100,1,13.10,100,1,13.04,2,1,13.40,0,-10,13.48,0,-1,13.49,0,-2,13.50,0,-1,13.51,0,-1,13.53,0,-2,13.54,0,-1,13.55,0,-2,13.56,0,-4,13.57,0,-2,ARL,0
2025-07-17T16:12:40.995349303Z,2025-07-17T16:12:40.995183768Z,10,2,1108,A,A,10,15.860000000,100,338864245,165535,282007898,13.31,10,1,13.28,1,2,13.27,20,2,13.26,198,2,13.14,1,1,13.13,100,1,13.12,200,2,13.11,100,1,13.10,100,1,13.04,2,1,13.40,0,-10,13.48,0,-1,13.49,0,-2,13.50,0,-1,13.51,0,-1,13.53,0,-2,13.54,0,-1,13.55,0,-2,13.56,0,-4,13.57,0,-2,ARL,0
2025-07-17T16:12:40.996460080Z,2025-07-17T16:12:40.996294601Z,10,2,1108,C,A,10,17.260000000,100,336570921,165479,282007909,13.31,10,1,13.28,1,2,13.27,20,2,13.26,198,2,13.14,1,1,13.13,100,1,13.12,200,2,13.11,100,1,13.10,100,1,13.04,2,1,13.40,0,-10,13.48,0,-1,13.49,0,-2,13.50,0,-1,13.51,0,-1,13.53,0,-2,13.54,0,-1,13.55,0,-2,13.56,0,-4,13.57,0,-2,ARL,0
2025-07-17T16:12:40.996460080Z,2025-07-17T16:12:40.996294601Z,10,2,1108,A,A,10,17.520000000,100,338864289,165479,282007909,13.31,10,1,13.28,1,2,13.27,20,2,13.26,198,2,13.14,1,1,13.13,100,1,13.12,200,2,13.11,100,1,13.10,100,1,13.04,2,1,13.40,0,-10,13.48,0,-1,13.49,0,-2,13.50,0,-1,13.51,0,-1,13.53,0,-2,13.54,0,-1,13.55,0,-2,13.56,0,-4,13.57,0,-2,ARL,0
2025-07-17T16:12:40.997300700Z,2025-07-17T16:12:40.997135307Z,10,2,1108,C,A,10,14.330000000,100,337790761,165393,282007914,13.31,10,1,13.28,1,2,13.27,20,2,13.26,198,2,13.14,1,1,13.13,100,1,13.12,200,2,13.11,100,1,13.10,100,1,13.04,2,1,13.40,0,-10,13.48,0,-1,13.49,0,-2,13.50,0,-1,13.51,0,-1,13.53,0,-2,13.54,0,-1,13.55,0,-2,13.56,0,-4,13.57,0,-2,ARL,0
2025-07-17T16:12:40.997422356Z,2025-07-17T16:12:40.997257014Z,10,2,1108,A,A,10,14.580000000,100,338864317,165342,282007916,13.31,10,1,13.28,1,2,13.27,20,2,13.26,198,2,13.14,1,1,13.13,100,1,13.12,200,2,13.11,100,1,13.10,100,1,13.04,2,1,13.40,0,-10,13.48,0,-1,13.49,0,-2,13.50,0,-1,13.51,0,-1,13.53,0,-2,13.54,0,-1,13.55,0,-2,13.56,0,-4,13.57,0,-2,ARL,0
2025-07-17T16:12:41.004229622Z,2025-07-17T16:12:41.004063876Z,10,2,1108,C,A,10,14.490000000,100,337790777,165746,282007959,13.31,10,1,13.28,1,2,13.27,20,2,13.26,198,2,13.14,1,1,13.13,100,1,13.12,200,2,13.11,100,1,13.10,100,1,13.04,2,1,13.40,0,-10,13.48,0,-1,13.49,0,-2,13.50,0,-1,13.51,0,-1,13.53,0,-2,13.54,0,-1,13.55,0,-2,13.56,0,-4,13.57,0,-2,ARL,0
2025-07-17T16:12:41.004229622Z,2025-07-17T16:12:41.004063876Z,10,2,1108,A,A,10,14.760000000,100,338864405,165746,282007959,13.31,10,1,13.28,1,2,13.27,20,2,13.26,198,2,13.14,1,1,13.13,100,1,13.12,200,2,13.11,100,1,13.10,100,1,13.04,2,1,13.40,0,-10,13.48,0,-1,13.49,0,-2,13.50,0,-1,13.51,0,-1,13.53,0,-2,13.54,0,-1,13.55,0,-2,13.56,0,-4,13.57,0,-2,ARL,0
2025-07-17T16:12:41.005576053Z,2025-07-17T16:12:41.005406614Z,10,2,1108,A,A,10,13.490000000,100,338864581,169439,282008256,13.31,10,1,13.28,1,2,13.27,20,2,13.26,198,2,13.14,1,1,13.13,100,1,13.12,200,2,13.11,100,1,13.10,100,1,13.04,2,1,13.40,0,-10,13.48,0,-1,13.49,0,-2,13.50,0,-1,13.51,0,-1,13.53,0,-2,13.54,0,-1,13.55,0,-2,13.56,0,-4,13.57,0,-2,ARL,0
2025-07-17T16:12:41.010638351Z,2025-07-17T16:12:41.010473041Z,10,2,1108,C,A,10,14.760000000,100,338864405,165310,282008884,13.31,10,1,13.28,1,2,13.27,20,2,13.26,198,2,13.14,1,1,13.13,100,1,13.12,200,2,13.11,100,1,13.10,100,1,13.04,2,1,13.40,0,-10,13.48,0,-1,13.49,0,-3,13.50,0,-1,13.51,0,-1,13.53,0,-2,13.54,0,-1,13.55,0,-2,13.56,0,-4,13.57,0,-2,ARL,0
2025-07-17T16:12:41.010638351Z,2025-07-17T16:12:41.010473041Z,10,2,1108,A,A,10,14.440000000,100,338865133,165310,282008884,13.31,10,1,13.28,1,2,13.27,20,2,13.26,198,2,13.14,1,1,13.13,100,1,13.12,200,2,13.11,100,1,13.10,100,1,13.04,2,1,13.40,0,-10,13.48,0,-1,13.49,0,-3,13.50,0,-1,13.51,0,-1,13.53,0,-2,13.54,0,-1,13.55,0,-2,13.56,0,-4,13.57,0,-2,ARL,0
2025-07-17T16:12:41.011160341Z,2025-07-17T16:12:41.010994859Z,10,2,1108,C,A,10,13.790000000,100,338044233,165482,282008914,13.31,10,1,13.28,1,2,13.27,20,2,13.26,198,2,13.14,1,1,13.13,100,1,13.12,200,2,13.11,100,1,13.10,100,1,13.04,2,1,13.40,0,-10,13.48,0,-1,13.49,0,-3,13.50,0,-1,13.51,0,-1,13.53,0,-2,13.54,0,-1,13.55,0,-2,13.56,0,-4,13.57,0,-2,ARL,0
2025-07-17T16:12:41.011211986Z,2025-07-17T16:12:41.011046717Z,10,2,1108,A,A,10,14.060000000,100,338865141,165269,282008916,13.31,10,1,13.28,1,2,13.27,20,2,13.26,198,2,13.14,1,1,13.13,100,1,13.12,200,2,13.11,100,1,13.10,100,1,13.04,2,1,13.40,0,-10,13.48,0,-1,13.49,0,-3,13.50,0,-1,13.51,0,-1,13.53,0,-2,13.54,0,-1,13.55,0,-2,13.56,0,-4,13.57,0,-2,ARL,0
2025-07-17T16:12:41.011555342Z,2025-07-17T16:12:41.011390077Z,10,2,1108,C,A,10,14.760000000,100,338864217,165265,282008942,13.31,10,1,13.28,1,2,13.27,20,2,13.26,198,2,13.14,1,1,13.13,100,1,13.12,200,2,13.11,100,1,13.10,100,1,13.04,2,1,13.40,0,-10,13.48,0,-1,13.49,0,-3,13.50,0,-1,13.51,0,-1,13.53,0,-2,13.54,0,-1,13.55,0,-2,13.56,0,-4,13.57,0,-2,ARL,0
2025-07-17T16:12:41.011555342Z,2025-07-17T16:12:41.011390077Z,10,2,1108,A,A,10,14.440000000,100,338865165,165265,282008942,13.31,10,1,13.28,1,2,13.27,20,2,13.26,198,2,13.14,1,1,13.13,100,1,13.12,200,2,13.11,100,1,13.10,100,1,13.04,2,1,13.40,0,-10,13.48,0,-1,13.49,0,-3,13.50,0,-1,13.51,0,-1,13.53,0,-2,13.54,0,-1,13.55,0,-2,13.56,0,-4,13.57,0,-2,ARL,0
2025-07-17T16:12:41.012044919Z,2025-07-17T16:12:41.011879795Z,10,2,1108,C,A,10,14.060000000,100,338865141,165124,282008953,13.31,10,1,13.28,1,2,13.27,20,2,13.26,198,2,13.14,1,1,13.13,100,1,13.12,200,2,13.11,100,1,13.10,100,1,13.04,2,1,13.40,0,-10,13.48,0,-1,13.49,0,-3,13.50,0,-1,13.51,0,-1,13.53,0,-2,13.54,0,-1,13.55,0,-2,13.56,0,-4,13.57,0,-2,ARL,0
2025-07-17T16:12:41.012094494Z,2025-07-17T16:12:41.011929033Z,10,2,1108,A,A,10,13.760000000,100,338865177,165461,282008954,13.31,10,1,13.28,1,2,13.27,20,2,13.26,198,2,13.14,1,1,13.13,100,1,13.12,200,2,13.11,100,1,13.10,100,1,13.04,2,1,13.40,0,-10,13.48,0,-1,13.49,0,-3,13.50,0,-1,13.51,0,-1,13.53,0,-2,13.54,0,-1,13.55,0,-2,13.56,0,-4,13.57,0,-2,ARL,0
2025-07-17T16:12:41.014974491Z,2025-07-17T16:12:41.014809197Z,10,2,1108,C,A,10,17.520000000,100,338864289,165294,282008990,13.31,10,1,13.28,1,2,13.27,20,2,13.26,198,2,13.14,1,1,13.13,100,1,13.12,200,2,13.11,100,1,13.10,100,1,13.04,2,1,13.40,0,-10,13.48,0,-1,13.49,0,-3,13.50,0,-1,13.51,0,-1,13.53,0,-2,13.54,0,-1,13.55,0,-2,13.56,0,-4,13.57,0,-2,ARL,0
2025-07-17T16:12:41.014974491Z,2025-07-17T16:12:41.014809197Z,10,2,1108,A,A,10,17.140000000,100,338865253,165294,282008990,13.31,10,1,13.28,1,2,13.27,20,2,13.26,198,2,13.14,1,1,13.13,100,1,13.12,200,2,13.11,100,1,13.10,100,1,13.04,2,1,13.40,0,-10,13.48,0,-1,13.49,0,-3,13.50,0,-1,13.51,0,-1,13.53,0,-2,13.54,0,-1,13.55,0,-2,13.56,0,-4,13.57,0,-2,ARL,0
2025-07-17T16:12:41.017837378Z,2025-07-17T16:12:41.017672033Z,10,2,1108,C,A,10,15.860000000,100,338864245,165345,282009053,13.31,10,1,13.28,1,2,13.27,20,2,13.26,198,2,13.14,1,1,13.13,100,1,13.12,200,2,13.11,100,1,13.10,100,1,13.04,2,1,13.40,0,-10,13.48,0,-1,13.49,0,-3,13.50,0,-1,13.51,0,-1,13.53,0,-2,13.54,0,-1,13.55,0,-2,13.56,0,-4,13.57,0,-2,ARL,0
2025-07-17T16:12:41.017837378Z,2025-07-17T16:12:41.017672033Z,10,2,1108,A,A,10,15.520000000,100,338865301,165345,282009053,13.31,10,1,13.28,1,2,13.27,20,2,13.26,198,2,13.14,1,1,13.13,100,1,13.12,200,2,13.11,100,1,13.10,100,1,13.04,2,1,13.40,0,-10,13.48,0,-1,13.49,0,-3,13.50,0,-1,13.51,0,-1,13.53,0,-2,13.54,0,-1,13.55,0,-2,13.56,0,-4,13.57,0,-2,ARL,0
2025-07-17T16:12:41.032270817Z,2025-07-17T16:12:41.032105565Z,10,2,1108,C,A,10,15.170000000,100,338864221,165252,282009412,13.31,10,1,13.28,1,2,13.27,20,2,13.26,198,2,13.14,1,1,13.13,100,1,13.12,200,2,13.11,100,1,13.10,100,1,13.04,2,1,13.40,0,-10,13.48,0,-1,13.49,0,-3,13.50,0,-1,13.51,0,-1,13.53,0,-2,13.54,0,-1,13.55,0,-2,13.56,0,-4,13.57,0,-2,ARL,0
2025-07-17T16:12:41.032270817Z,2025-07-17T16:12:41.032105565Z,10,2,1108,A,A,10,14.840000000,100,338866081,165252,282009412,13.31,10,1,13.28,1,2,13.27,20,2,13.26,198,2,13.14,1,1,13.13,100,1,13.12,200,2,13.11,100,1,13.10,100,1,13.04,2,1,13.40,0,-10,13.48,0,-1,13.49,0,-3,13.50,0,-1,13.51,0,-1,13.53,0,-2,13.54,0,-1,13.55,0,-2,13.56,0,-4,13.57,0,-2,ARL,0
2025-07-17T16:12:41.032312420Z,2025-07-17T16:12:41.032147083Z,10,2,1108,A,A,10,15.380000000,100,338866089,165337,282009414,13.31,10,1,13.28,1,2,13.27,20,2,13.26,198,2,13.14,1,1,13.13,100,1,13.12,200,2,13.11,100,1,13.10,100,1,13.04,2,1,13.40,0,-10,13.48,0,-1,13.49,0,-3,13.50,0,-1,13.51,0,-1,13.53,0,-2,13.54,0,-1,13.55,0,-2,13.56,0,-4,13.57,0,-2,ARL,0
2025-07-17T16:12:41.032324438Z,2025-07-17T16:12:41.032159348Z,10,2,1108,C,A,10,15.710000000,100,338864177,165090,282009415,13.31,10,1,13.28,1,2,13.27,20,2,13.26,198,2,13.14,1,1,13.13,100,1,13.12,200,2,13.11,100,1,13.10,100,1,13.04,2,1,13.40,0,-10,13.48,0,-1,13.49,0,-3,13.50,0,-1,13.51,0,-1,13.53,0,-2,13.54,0,-1,13.55,0,-2,13.56,0,-4,13.57,0,-2,ARL,0
2025-07-17T16:12:41.043406383Z,2025-07-17T16:12:41.043241012Z,10,2,1108,C,A,10,14.850000000,100,338864189,165371,282009482,13.31,10,1,13.28,1,2,13.27,20,2,13.26,198,2,13.14,1,1,13.13,100,1,13.12,200,2,13.11,100,1,13.10,100,1,13.04,2,1,13.40,0,-10,13.48,0,-1,13.49,0,-3,13.50,0,-1,13.51,0,-1,13.53,0,-2,13.54,0,-1,13.55,0,-2,13.56,0,-4,13.57,0,-2,ARL,0
2025-07-17T16:12:41.043406383Z,2025-07-17T16:12:41.043241012Z,10,2,1108,A,A,10,14.540000000,100,338866245,165371,282009482,13.31,10,1,13.28,1,2,13.27,20,2,13.26,198,2,13.14,1,1,13.13,100,1,13.12,200,2,13.11,100,1,13.10,100,1,13.04,2,1,13.40,0,-10,13.48,0,-1,13.49,0,-3,13.50,0,-1,13.51,0,-1,13.53,0,-2,13.54,0,-1,13.55,0,-2,13.56,0,-4,13.57,0,-2,ARL,0
2025-07-17T16:12:42.001347844Z,2025-07-17T16:12:42.001182016Z,10,2,1108,C,A,10,14.580000000,100,338864317,165828,282033913,13.31,10,1,13.28,1,2,13.27,20,2,13.26,198,2,13.14,1,1,13.13,100,1,13.12,200,2,13.11,100,1,13.10,100,1,13.04,2,1,13.40,0,-10,13.48,0,-1,13.49,0,-3,13.50,0,-1,13.51,0,-1,13.53,0,-2,13.54,0,-1,13.55,0,-2,13.56,0,-4,13.57,0,-2,ARL,0
2025-07-17T16:12:42.001347844Z,2025-07-17T16:12:42.001182016Z,10,2,1108,A,A,10,14.280000000,100,338894329,165828,282033913,13.31,10,1,13.28,1,2,13.27,20,2,13.26,198,2,13.14,1,1,13.13,100,1,13.12,200,2,13.11,100,1,13.10,100,1,13.04,2,1,13.40,0,-10,13.48,0,-1,13.49,0,-3,13.50,0,-1,13.51,0,-1,13.53,0,-2,13.54,0,-1,13.55,0,-2,13.56,0,-4,13.57,0,-2,ARL,0
2025-07-17T16:12:42.762154469Z,2025-07-17T16:12:42.761989222Z,10,2,1108,A,A,10,13.460000000,15,338904977,165247,282042242,13.31,10,1,13.28,1,2,13.27,20,2,13.26,198,2,13.14,1,1,13.13,100,1,13.12,200,2,13.11,100,1,13.10,100,1,13.04,2,1,13.40,0,-10,13.48,0,-1,13.49,0,-3,13.50,0,-1,13.51,0,-1,13.53,0,-2,13.54,0,-1,13.55,0,-2,13.56,0,-4,13.57,0,-2,ARL,0
2025-07-17T16:12:43.022127902Z,2025-07-17T16:12:43.021951997Z,10,2,1108,C,A,10,13.490000000,100,338864581,175905,282057719,13.31,10,1,13.28,1,2,13.27,20,2,13.26,198,2,13.14,1,1,13.13,100,1,13.12,200,2,13.11,100,1,13.10,100,1,13.04,2,1,13.40,0,-10,13.46,0,-1,13.48,0,-1,13.49,0,-3,13.50,0,-1,13.51,0,-1,13.53,0,-2,13.54,0,-1,13.55,0,-2,13.56,0,-4,ARL,0
2025-07-17T16:12:43.022127902Z,2025-07-17T16:12:43.021951997Z,10,2,1108,A,A,10,13.470000000,100,338918217,175905,282057719,13.31,10,1,13.28,1,2,13.27,20,2,13.26,198,2,13.14,1,1,13.13,100,1,13.12,200,2,13.11,100,1,13.10,100,1,13.04,2,1,13.40,0,-10,13.46,0,-1,13.48,0,-1,13.49,0,-3,13.50,0,-1,13.51,0,-1,13.53,0,-2,13.54,0,-1,13.55,0,-2,13.56,0,-4,ARL,0
2025-07-17T16:12:43.022612177Z,2025-07-17T16:12:43.022444956Z,10,2,1108,A,A,10,15.690000000,100,338918553,167221,282058085,13.31,10,1,13.28,1,2,13.27,20,2,13.26,198,2,13.14,1,1,13.13,100,1,13.12,200,2,13.11,100,1,13.10,100,1,13.04,2,1,13.40,0,-10,13.46,0,-1,13.48,0,-1,13.49,0,-3,13.50,0,-1,13.51,0,-1,13.53,0,-2,13.54,0,-1,13.55,0,-2,13.56,0,-4,ARL,0
2025-07-17T16:12:43.022627592Z,2025-07-17T16:12:43.022461725Z,10,2,1108,C,A,10,15.380000000,100,338866089,165867,282058088,13.31,10,1,13.28,1,2,13.27,20,2,13.26,198,2,13.14,1,1,13.13,100,1,13.12,200,2,13.11,100,1,13.10,100,1,13.04,2,1,13.40,0,-10,13.46,0,-1,13.48,0,-1,13.49,0,-3,13.50,0,-1,13.51,0,-1,13.53,0,-2,13.54,0,-1,13.55,0,-2,13.56,0,-4,ARL,0
2025-07-17T16:12:43.049284355Z,2025-07-17T16:12:43.049119139Z,10,2,1108,A,A,10,15.360000000,100,338926929,165216,282065940,13.31,10,1,13.28,1,2,13.27,20,2,13.26,198,2,13.14,1,1,13.13,100,1,13.12,200,2,13.11,100,1,13.10,100,1,13.04,2,1,13.40,0,-10,13.46,0,-1,13.48,0,-1,13.49,0,-3,13.50,0,-1,13.51,0,-1,13.53,0,-2,13.54,0,-1,13.55,0,-2,13.56,0,-4,ARL,0
2025-07-17T16:12:43.049298989Z,2025-07-17T16:12:43.049132842Z,10,2,1108,C,A,10,15.690000000,100,338918553,166147,282065943,13.31,10,1,13.28,1,2,13.27,20,2,13.26,198,2,13.14,1,1,13.13,100,1,13.12,200,2,13.11,100,1,13.10,100,1,13.04,2,1,13.40,0,-10,13.46,0,-1,13.48,0,-1,13.49,0,-3,13.50,0,-1,13.51,0,-1,13.53,0,-2,13.54,0,-1,13.55,0,-2,13.56,0,-4,ARL,0
2025-07-17T16:12:43.154952375Z,2025-07-17T16:12:43.154787212Z,10,2,1108,A,A,10,14.270000000,100,338932853,165163,282073056,13.31,10,1,13.28,1,2,13.27,20,2,13.26,198,2,13.14,1,1,13.13,100,1,13.12,200,2,13.11,100,1,13.10,100,1,13.04,2,1,13.40,0,-10,13.46,0,-1,13.48,0,-1,13.49,0,-3,13.50,0,-1,13.51,0,-1,13.53,0,-2,13.54,0,-1,13.55,0,-2,13.56,0,-4,ARL,0
2025-07-17T16:12:43.154965183Z,2025-07-17T16:12:43.154800020Z,10,2,1108,C,A,10,14.560000000,100,296391881,165163,282073058,13.31,10,1,13.28,1,2,13.27,20,2,13.26,198,2,13.14,1,1,13.13,100,1,13.12,200,2,13.11,100,1,13.10,100,1,13.04,2,1,13.40,0,-10,13.46,0,-1,13.48,0,-1,13.49,0,-3,13.50,0,-1,13.51,0,-1,13.53,0,-2,13.54,0,-1,13.55,0,-2,13.56,0,-4,ARL,0
2025-07-17T16:12:43.915552526Z,2025-07-17T16:12:43.915387059Z,10,2,1108,C,A,10,14.280000000,100,302681357,165467,282085822,13.31,10,1,13.28,1,2,13.27,20,2,13.26,198,2,13.14,1,1,13.13,100,1,13.12,200,2,13.11,100,1,13.10,100,1,13.04,2,1,13.40,0,-10,13.46,0,-1,13.48,0,-1,13.49,0,-3,13.50,0,-1,13.51,0,-1,13.53,0,-2,13.54,0,-1,13.55,0,-2,13.56,0,-4,ARL,0
2025-07-17T16:12:43.915555340Z,2025-07-17T16:12:43.915389642Z,10,2,1108,A,A,10,14.000000000,100,338945933,165698,282085823,13.31,10,1,13.28,1,2,13.27,20,2,13.26,198,2,13.14,1,1,13.13,100,1,13.12,200,2,13.11,100,1,13.10,100,1,13.04,2,1,13.40,0,-10,13.46,0,-1,13.48,0,-1,13.49,0,-3,13.50,0,-1,13.51,0,-1,13.53,0,-2,13.54,0,-1,13.55,0,-2,13.56,0,-4,ARL,0
2025-07-17T16:12:50.729244449Z,2025-07-17T16:12:50.729079105Z,10,2,1108,C,A,10,13.460000000,15,338904977,165344,282168721,13.31,10,1,13.28,1,2,13.27,20,2,13.26,198,2,13.14,1,1,13.13,100,1,13.12,200,2,13.11,100,1,13.10,100,1,13.04,2,1,13.40,0,-10,13.46,0,-1,13.48,0,-1,13.49,0,-3,13.50,0,-1,13.51,0,-1,13.53,0,-2,13.54,0,-1,13.55,0,-2,13.56,0,-4,ARL,0
2025-07-17T16:12:50.729418237Z,2025-07-17T16:12:50.729252907Z,10,2,1108,C,A,10,13.480000000,15,338707945,165330,282168744,13.31,10,1,13.28,1,2,13.27,20,2,13.26,198,2,13.14,1,1,13.13,100,1,13.12,200,2,13.11,100,1,13.10,100,1,13.04,2,1,13.40,0,-10,13.46,0,-1,13.48,0,-1,13.49,0,-3,13.50,0,-1,13.51,0,-1,13.53,0,-2,13.54,0,-1,13.55,0,-2,13.56,0,-4,ARL,0
2025-07-17T16:12:50.729575741Z,2025-07-17T16:12:50.729409745Z,10,2,1108,A,A,10,13.470000000,96,339054149,165996,282168754,13.31,10,1,13.28,1,2,13.27,20,2,13.26,198,2,13.14,1,1,13.13,100,1,13.12,200,2,13.11,100,1,13.10,100,1,13.04,2,1,13.40,0,-10,13.46,0,-1,13.48,0,-1,13.49,0,-3,13.50,0,-1,13.51,0,-1,13.53,0,-2,13.54,0,-1,13.55,0,-2,13.56,0,-4,ARL,0
2025-07-17T16:12:53.021914652Z,2025-07-17T16:12:53.021749348Z,10,2,1108,A,A,10,13.460000000,15,339096733,165304,282194154,13.31,10,1,13.28,1,2,13.27,20,2,13.26,198,2,13.14,1,1,13.13,100,1,13.12,200,2,13.11,100,1,13.10,100,1,13.04,2,1,13.40,0,-10,13.46,0,-1,13.48,0,-1,13.49,0,-3,13.50,0,-1,13.51,0,-1,13.53,0,-2,13.54,0,-1,13.55,0,-2,13.56,0,-4,ARL,0
2025-07-17T16:12:53.021959141Z,2025-07-17T16:12:53.021793735Z,10,2,1108,C,A,10,13.470000000,100,338918217,165406,282194157,13.31,10,1,13.28,1,2,13.27,20,2,13.26,198,2,13.14,1,1,13.13,100,1,13.12,200,2,13.11,100,1,13.10,100,1,13.04,2,1,13.40,0,-10,13.46,0,-2,13.48,0,-1,13.49,0,-3,13.50,0,-1,13.51,0,-1,13.53,0,-2,13.54,0,-1,13.55,0,-2,13.56,0,-4,ARL,0
2025-07-17T16:12:53.022230122Z,2025-07-17T16:12:53.022064745Z,10,2,1108,C,A,10,13.470000000,96,339054149,165377,282194159,13.31,10,1,13.28,1,2,13.27,20,2,13.26,198,2,13.14,1,1,13.13,100,1,13.12,200,2,13.11,100,1,13.10,100,1,13.04,2,1,13.40,0,-10,13.46,0,-2,13.48,0,-1,13.49,0,-3,13.50,0,-1,13.51,0,-1,13.53,0,-2,13.54,0,-1,13.55,0,-2,13.56,0,-4,ARL,0
2025-07-17T16:12:53.022572023Z,2025-07-17T16:12:53.022406202Z,10,2,1108,A,A,10,15.690000000,100,339096757,165821,282194161,13.31,10,1,13.28,1,2,13.27,20,2,13.26,198,2,13.14,1,1,13.13,100,1,13.12,200,2,13.11,100,1,13.10,100,1,13.04,2,1,13.40,0,-10,13.46,0,-2,13.48,0,-1,13.49,0,-3,13.50,0,-1,13.51,0,-1,13.53,0,-2,13.54,0,-1,13.55,0,-2,13.56,0,-4,ARL,0
2025-07-17T16:12:53.022584264Z,2025-07-17T16:12:53.022418950Z,10,2,1108,C,A,10,15.360000000,100,338926929,165314,282194162,13.31,10,1,13.28,1,2,13.27,20,2,13.26,198,2,13.14,1,1,13.13,100,1,13.12,200,2,13.11,100,1,13.10,100,1,13.04,2,1,13.40,0,-10,13.46,0,-2,13.48,0,-1,13.49,0,-3,13.50,0,-1,13.51,0,-1,13.53,0,-2,13.54,0,-1,13.55,0,-2,13.56,0,-4,ARL,0
2025-07-17T16:12:53.022962940Z,2025-07-17T16:12:53.022797046Z,10,2,1108,C,A,10,14.540000000,100,338866245,165894,282194167,13.31,10,1,13.28,1,2,13.27,20,2,13.26,198,2,13.14,1,1,13.13,100,1,13.12,200,2,13.11,100,1,13.10,100,1,13.04,2,1,13.40,0,-10,13.46,0,-2,13.48,0,-1,13.49,0,-3,13.50,0,-1,13.51,0,-1,13.53,0,-2,13.54,0,-1,13.55,0,-2,13.56,0,-4,ARL,0
2025-07-17T16:12:53.022962940Z,2025-07-17T16:12:53.022797046Z,10,2,1108,A,A,10,14.830000000,100,339096773,165894,282194167,13.31,10,1,13.28,1,2,13.27,20,2,13.26,198,2,13.14,1,1,13.13,100,1,13.12,200,2,13.11,100,1,13.10,100,1,13.04,2,1,13.40,0,-10,13.46,0,-2,13.48,0,-1,13.49,0,-3,13.50,0,-1,13.51,0,-1,13.53,0,-2,13.54,0,-1,13.55,0,-2,13.56,0,-4,ARL,0
2025-07-17T16:12:53.023589530Z,2025-07-17T16:12:53.023423468Z,10,2,1108,C,A,10,14.440000000,100,338865165,166062,282194181,13.31,10,1,13.28,1,2,13.27,20,2,13.26,198,2,13.14,1,1,13.13,100,1,13.12,200,2,13.11,100,1,13.10,100,1,13.04,2,1,13.40,0,-10,13.46,0,-2,13.48,0,-1,13.49,0,-3,13.50,0,-1,13.51,0,-1,13.53,0,-2,13.54,0,-1,13.55,0,-2,13.56,0,-4,ARL,0
2025-07-17T16:12:53.023589530Z,2025-07-17T16:12:53.023423468Z,10,2,1108,A,A,10,14.730000000,100,339096797,166062,282194181,13.31,10,1,13.28,1,2,13.27,20,2,13.26,198,2,13.14,1,1,13.13,100,1,13.12,200,2,13.11,100,1,13.10,100,1,13.04,2,1,13.40,0,-10,13.46,0,-2,13.48,0,-1,13.49,0,-3,13.50,0,-1,13.51,0,-1,13.53,0,-2,13.54,0,-1,13.55,0,-2,13.56,0,-4,ARL,0
2025-07-17T16:12:53.024069153Z,2025-07-17T16:12:53.023903582Z,10,2,1108,C,A,10,17.140000000,100,338865253,165571,282194183,13.31,10,1,13.28,1,2,13.27,20,2,13.26,198,2,13.14,1,1,13.13,100,1,13.12,200,2,13.11,100,1,13.10,100,1,13.04,2,1,13.40,0,-10,13.46,0,-2,13.48,0,-1,13.49,0,-3,13.50,0,-1,13.51,0,-1,13.53,0,-2,13.54,0,-1,13.55,0,-2,13.56,0,-4,ARL,0
2025-07-17T16:12:53.024069153Z,2025-07-17T16:12:53.023903582Z,10,2,1108,A,A,10,17.480000000,100,339096809,165571,282194183,13.31,10,1,13.28,1,2,13.27,20,2,13.26,198,2,13.14,1,1,13.13,100,1,13.12,200,2,13.11,100,1,13.10,100,1,13.04,2,1,13.40,0,-10,13.46,0,-2,13.48,0,-1,13.49,0,-3,13.50,0,-1,13.51,0,-1,13.53,0,-2,13.54,0,-1,13.55,0,-2,13.56,0,-4,ARL,0
2025-07-17T16:12:53.025583784Z,2025-07-17T16:12:53.025418159Z,10,2,1108,C,A,10,14.840000000,100,338866081,165625,282194188,13.31,10,1,13.28,1,2,13.27,20,2,13.26,198,2,13.14,1,1,13.13,100,1,13.12,200,2,13.11,100,1,13.10,100,1,13.04,2,1,13.40,0,-10,13.46,0,-2,13.48,0,-1,13.49,0,-3,13.50,0,-1,13.51,0,-1,13.53,0,-2,13.54,0,-1,13.55,0,-2,13.56,0,-4,ARL,0
2025-07-17T16:12:53.025583784Z,2025-07-17T16:12:53.025418159Z,10,2,1108,A,A,10,15.140000000,100,339096813,165625,282194188,13.31,10,1,13.28,1,2,13.27,20,2,13.26,198,2,13.14,1,1,13.13,100,1,13.12,200,2,13.11,100,1,13.10,100,1,13.04,2,1,13.40,0,-10,13.46,0,-2,13.48,0,-1,13.49,0,-3,13.50,0,-1,13.51,0,-1,13.53,0,-2,13.54,0,-1,13.55,0,-2,13.56,0,-4,ARL,0
2025-07-17T16:12:53.025651983Z,2025-07-17T16:12:53.025486466Z,10,2,1108,C,A,10,14.440000000,100,338865133,165517,282194189,13.31,10,1,13.28,1,2,13.27,20,2,13.26,198,2,13.14,1,1,13.13,100,1,13.12,200,2,13.11,100,1,13.10,100,1,13.04,2,1,13.40,0,-10,13.46,0,-2,13.48,0,-1,13.49,0,-3,13.50,0,-1,13.51,0,-1,13.53,0,-2,13.54,0,-1,13.55,0,-2,13.56,0,-4,ARL,0
2025-07-17T16:12:53.025651983Z,2025-07-17T16:12:53.025486466Z,10,2,1108,A,A,10,14.730000000,100,339096817,165517,282194189,13.31,10,1,13.28,1,2,13.27,20,2,13.26,198,2,13.14,1,1,13.13,100,1,13.12,200,2,13.11,100,1,13.10,100,1,13.04,2,1,13.40,0,-10,13.46,0,-2,13.48,0,-1,13.49,0,-3,13.50,0,-1,13.51,0,-1,13.53,0,-2,13.54,0,-1,13.55,0,-2,13.56,0,-4,ARL,0
2025-07-17T16:12:53.027715026Z,2025-07-17T16:12:53.027549524Z,10,2,1108,C,A,10,14.280000000,100,338894329,165502,282194224,13.31,10,1,13.28,1,2,13.27,20,2,13.26,198,2,13.14,1,1,13.13,100,1,13.12,200,2,13.11,100,1,13.10,100,1,13.04,2,1,13.40,0,-10,13.46,0,-2,13.48,0,-1,13.49,0,-3,13.50,0,-1,13.51,0,-1,13.53,0,-2,13.54,0,-1,13.55,0,-2,13.56,0,-4,ARL,0
2025-07-17T16:12:53.027866777Z,2025-07-17T16:12:53.027701439Z,10,2,1108,A,A,10,14.550000000,100,339096833,165338,282194226,13.31,10,1,13.28,1,2,13.27,20,2,13.26,198,2,13.14,1,1,13.13,100,1,13.12,200,2,13.11,100,1,13.10,100,1,13.04,2,1,13.40,0,-10,13.46,0,-2,13.48,0,-1,13.49,0,-3,13.50,0,-1,13.51,0,-1,13.53,0,-2,13.54,0,-1,13.55,0,-2,13.56,0,-4,ARL,0
2025-07-17T16:12:53.027987030Z,2025-07-17T16:12:53.027821450Z,10,2,1108,C,A,10,15.520000000,100,338865301,165580,282194228,13.31,10,1,13.28,1,2,13.27,20,2,13.26,198,2,13.14,1,1,13.13,100,1,13.12,200,2,13.11,100,1,13.10,100,1,13.04,2,1,13.40,0,-10,13.46,0,-2,13.48,0,-1,13.49,0,-3,13.50,0,-1,13.51,0,-1,13.53,0,-2,13.54,0,-1,13.55,0,-2,13.56,0,-4,ARL,0
2025-07-17T16:12:53.027987030Z,2025-07-17T16:12:53.027821450Z,10,2,1108,A,A,10,15.830000000,100,339096837,165580,282194228,13.31,10,1,13.28,1,2,13.27,20,2,13.26,198,2,13.14,1,1,13.13,100,1,13.12,200,2,13.11,100,1,13.10,100,1,13.04,2,1,13.40,0,-10,13.46,0,-2,13.48,0,-1,13.49,0,-3,13.50,0,-1,13.51,0,-1,13.53,0,-2,13.54,0,-1,13.55,0,-2,13.56,0,-4,ARL,0
2025-07-17T16:12:53.033266537Z,2025-07-17T16:12:53.033101265Z,10,2,1108,C,A,10,13.760000000,100,338865177,165272,282194348,13.31,10,1,13.28,1,2,13.27,20,2,13.26,198,2,13.14,1,1,13.13,100,1,13.12,200,2,13.11,100,1,13.10,100,1,13.04,2,1,13.40,0,-10,13.46,0,-2,13.48,0,-1,13.49,0,-3,13.50,0,-1,13.51,0,-1,13.53,0,-2,13.54,0,-1,13.55,0,-2,13.56,0,-4,ARL,0
2025-07-17T16:12:53.033302848Z,2025-07-17T16:12:53.033137644Z,10,2,1108,C,A,10,14.470000000,700,338864173,165204,282194349,13.31,10,1,13.28,1,2,13.27,20,2,13.26,198,2,13.14,1,1,13.13,100,1,13.12,200,2,13.11,100,1,13.10,100,1,13.04,2,1,13.40,0,-10,13.46,0,-2,13.48,0,-1,13.49,0,-3,13.50,0,-1,13.51,0,-1,13.53,0,-2,13.54,0,-1,13.55,0,-2,13.56,0,-4,ARL,0
2025-07-17T16:12:53.033318818Z,2025-07-17T16:12:53.033153612Z,10,2,1108,A,A,10,14.040000000,100,339096893,165206,282194350,13.31,10,1,13.28,1,2,13.27,20,2,13.26,198,2,13.14,1,1,13.13,100,1,13.12,200,2,13.11,100,1,13.10,100,1,13.04,2,1,13.40,0,-10,13.46,0,-2,13.48,0,-1,13.49,0,-3,13.50,0,-1,13.51,0,-1,13.53,0,-2,13.54,0,-1,13.55,0,-2,13.56,0,-4,ARL,0
2025-07-17T16:12:53.033349323Z,2025-07-17T16:12:53.033183560Z,10,2,1108,A,A,10,14.680000000,700,339096897,165763,282194351,13.31,10,1,13.28,1,2,13.27,20,2,13.26,198,2,13.14,1,1,13.13,100,1,13.12,200,2,13.11,100,1,13.10,100,1,13.04,2,1,13.40,0,-10,13.46,0,-2,13.48,0,-1,13.49,0,-3,13.50,0,-1,13.51,0,-1,13.53,0,-2,13.54,0,-1,13.55,0,-2,13.56,0,-4,ARL,0
2025-07-17T16:12:53.033762072Z,2025-07-17T16:12:53.033596046Z,10,2,1108,C,A,10,13.740000000,2,338371797,166026,282194354,13.31,10,1,13.28,1,2,13.27,20,2,13.26,198,2,13.14,1,1,13.13,100,1,13.12,200,2,13.11,100,1,13.10,100,1,13.04,2,1,13.40,0,-10,13.46,0,-2,13.48,0,-1,13.49,0,-3,13.50,0,-1,13.51,0,-1,13.53,0,-2,13.54,0,-1,13.55,0,-2,13.56,0,-4,ARL,0
2025-07-17T16:12:53.033762072Z,2025-07-17T16:12:53.033596046Z,10,2,1108,A,A,10,13.980000000,2,339096909,166026,282194354,13.31,10,1,13.28,1,2,13.27,20,2,13.26,198,2,13.14,1,1,13.13,100,1,13.12,200,2,13.11,100,1,13.10,100,1,13.04,2,1,13.40,0,-10,13.46,0,-2,13.48,0,-1,13.49,0,-3,13.50,0,-1,13.51,0,-1,13.53,0,-2,13.54,0,-1,13.55,0,-2,13.56,0,-4,ARL,0
2025-07-17T16:12:53.034000646Z,2025-07-17T16:12:53.033835120Z,10,2,1108,C,A,10,14.250000000,100,336161365,165526,282194360,13.31,10,1,13.28,1,2,13.27,20,2,13.26,198,2,13.14,1,1,13.13,100,1,13.12,200,2,13.11,100,1,13.10,100,1,13.04,2,1,13.40,0,-10,13.46,0,-2,13.48,0,-1,13.49,0,-3,13.50,0,-1,13.51,0,-1,13.53,0,-2,13.54,0,-1,13.55,0,-2,13.56,0,-4,ARL,0
2025-07-17T16:12:53.034142471Z,2025-07-17T16:12:53.033977054Z,10,2,1108,C,A,10,14.730000000,100,339096797,165417,282194361,13.31,10,1,13.28,1,2,13.27,20,2,13.26,198,2,13.14,1,1,13.13,100,1,13.12,200,2,13.11,100,1,13.10,100,1,13.04,2,1,13.40,0,-10,13.46,0,-2,13.48,0,-1,13.49,0,-3,13.50,0,-1,13.51,0,-1,13.53,0,-2,13.54,0,-1,13.55,0,-2,13.56,0,-4,ARL,0
2025-07-17T16:12:53.034142471Z,2025-07-17T16:12:53.033977054Z,10,2,1108,A,A,10,14.960000000,100,339096917,165417,282194361,13.31,10,1,13.28,1,2,13.27,20,2,13.26,198,2,13.14,1,1,13.13,100,1,13.12,200,2,13.11,100,1,13.10,100,1,13.04,2,1,13.40,0,-10,13.46,0,-2,13.48,0,-1,13.49,0,-3,13.50,0,-1,13.51,0,-1,13.53,0,-2,13.54,0,-1,13.55,0,-2,13.56,0,-4,ARL,0
2025-07-17T16:12:53.034178176Z,2025-07-17T16:12:53.034012618Z,10,2,1108,C,A,10,15.830000000,100,339096837,165558,282194362,13.31,10,1,13.28,1,2,13.27,20,2,13.26,198,2,13.14,1,1,13.13,100,1,13.12,200,2,13.11,100,1,13.10,100,1,13.04,2,1,13.40,0,-10,13.46,0,-2,13.48,0,-1,13.49,0,-3,13.50,0,-1,13.51,0,-1,13.53,0,-2,13.54,0,-1,13.55,0,-2,13.56,0,-4,ARL,0
2025-07-17T16:12:53.034178176Z,2025-07-17T16:12:53.034012618Z,10,2,1108,A,A,10,16.080000000,100,339096921,165558,282194362,13.31,10,1,13.28,1,2,13.27,20,2,13.26,198,2,13.14,1,1,13.13,100,1,13.12,200,2,13.11,100,1,13.10,100,1,13.04,2,1,13.40,0,-10,13.46,0,-2,13.48,0,-1,13.49,0,-3,13.50,0,-1,13.51,0,-1,13.53,0,-2,13.54,0,-1,13.55,0,-2,13.56,0,-4,ARL,0
2025-07-17T16:12:53.034353140Z,2025-07-17T16:12:53.034187864Z,10,2,1108,A,A,10,14.600000000,100,339096925,165276,282194365,13.31,10,1,13.28,1,2,13.27,20,2,13.26,198,2,13.14,1,1,13.13,100,1,13.12,200,2,13.11,100,1,13.10,100,1,13.04,2,1,13.40,0,-10,13.46,0,-2,13.48,0,-1,13.49,0,-3,13.50,0,-1,13.51,0,-1,13.53,0,-2,13.54,0,-1,13.55,0,-2,13.56,0,-4,ARL,0
2025-07-17T16:12:53.035411748Z,2025-07-17T16:12:53.035246187Z,10,2,1108,C,A,10,15.050000000,100,335220549,165561,282194373,13.31,10,1,13.28,1,2,13.27,20,2,13.26,198,2,13.14,1,1,13.13,100,1,13.12,200,2,13.11,100,1,13.10,100,1,13.04,2,1,13.40,0,-10,13.46,0,-2,13.48,0,-1,13.49,0,-3,13.50,0,-1,13.51,0,-1,13.53,0,-2,13.54,0,-1,13.55,0,-2,13.56,0,-4,ARL,0
2025-07-17T16:12:53.035411748Z,2025-07-17T16:12:53.035246187Z,10,2,1108,A,A,10,15.380000000,100,339096929,165561,282194373,13.31,10,1,13.28,1,2,13.27,20,2,13.26,198,2,13.14,1,1,13.13,100,1,13.12,200,2,13.11,100,1,13.10,100,1,13.04,2,1,13.40,0,-10,13.46,0,-2,13.48,0,-1,13.49,0,-3,13.50,0,-1,13.51,0,-1,13.53,0,-2,13.54,0,-1,13.55,0,-2,13.56,0,-4,ARL,0
2025-07-17T16:12:53.036307382Z,2025-07-17T16:12:53.036142164Z,10,2,1108,C,A,10,17.480000000,100,339096809,165218,282194381,13.31,10,1,13.28,1,2,13.27,20,2,13.26,198,2,13.14,1,1,13.13,100,1,13.12,200,2,13.11,100,1,13.10,100,1,13.04,2,1,13.40,0,-10,13.46,0,-2,13.48,0,-1,13.49,0,-3,13.50,0,-1,13.51,0,-1,13.53,0,-2,13.54,0,-1,13.55,0,-2,13.56,0,-4,ARL,0
2025-07-17T16:12:53.036307382Z,2025-07-17T16:12:53.036142164Z,10,2,1108,A,A,10,17.760000000,100,339096949,165218,282194381,13.31,10,1,13.28,1,2,13.27,20,2,13.26,198,2,13.14,1,1,13.13,100,1,13.12,200,2,13.11,100,1,13.10,100,1,13.04,2,1,13.40,0,-10,13.46,0,-2,13.48,0,-1,13.49,0,-3,13.50,0,-1,13.51,0,-1,13.53,0,-2,13.54,0,-1,13.55,0,-2,13.56,0,-4,ARL,0
2025-07-17T16:12:53.040045217Z,2025-07-17T16:12:53.039879965Z,10,2,1108,C,A,10,14.730000000,100,339096817,165252,282194416,13.31,10,1,13.28,1,2,13.27,20,2,13.26,198,2,13.14,1,1,13.13,100,1,13.12,200,2,13.11,100,1,13.10,100,1,13.04,2,1,13.40,0,-10,13.46,0,-2,13.48,0,-1,13.49,0,-3,13.50,0,-1,13.51,0,-1,13.53,0,-2,13.54,0,-1,13.55,0,-2,13.56,0,-4,ARL,0
2025-07-17T16:12:53.040045217Z,2025-07-17T16:12:53.039879965Z,10,2,1108,A,A,10,14.960000000,100,339096977,165252,282194416,13.31,10,1,13.28,1,2,13.27,20,2,13.26,198,2,13.14,1,1,13.13,100,1,13.12,200,2,13.11,100,1,13.10,100,1,13.04,2,1,13.40,0,-10,13.46,0,-2,13.48,0,-1,13.49,0,-3,13.50,0,-1,13.51,0,-1,13.53,0,-2,13.54,0,-1,13.55,0,-2,13.56,0,-4,ARL,0
2025-07-17T16:12:53.043727225Z,2025-07-17T16:12:53.043562198Z,10,2,1108,C,A,10,14.040000000,100,339096893,165027,282194436,13.31,10,1,13.28,1,2,13.27,20,2,13.26,198,2,13.14,1,1,13.13,100,1,13.12,200,2,13.11,100,1,13.10,100,1,13.04,2,1,13.40,0,-10,13.46,0,-2,13.48,0,-1,13.49,0,-3,13.50,0,-1,13.51,0,-1,13.53,0,-2,13.54,0,-1,13.55,0,-2,13.56,0,-4,ARL,0
2025-07-17T16:12:53.043775299Z,2025-07-17T16:12:53.043610101Z,10,2,1108,A,A,10,14.260000000,100,339097005,165198,282194438,13.31,10,1,13.28,1,2,13.27,20,2,13.26,198,2,13.14,1,1,13.13,100,1,13.12,200,2,13.11,100,1,13.10,100,1,13.04,2,1,13.40,0,-10,13.46,0,-2,13.48,0,-1,13.49,0,-3,13.50,0,-1,13.51,0,-1,13.53,0,-2,13.54,0,-1,13.55,0,-2,13.56,0,-4,ARL,0
2025-07-17T16:12:53.073052597Z,2025-07-17T16:12:53.072887133Z,10,2,1108,C,A,10,14.830000000,100,339096773,165464,282194725,13.31,10,1,13.28,1,2,13.27,20,2,13.26,198,2,13.14,1,1,13.13,100,1,13.12,200,2,13.11,100,1,13.10,100,1,13.04,2,1,13.40,0,-10,13.46,0,-2,13.48,0,-1,13.49,0,-3,13.50,0,-1,13.51,0,-1,13.53,0,-2,13.54,0,-1,13.55,0,-2,13.56,0,-4,ARL,0
2025-07-17T16:12:53.073052597Z,2025-07-17T16:12:53.072887133Z,10,2,1108,A,A,10,15.060000000,100,339097245,165464,282194725,13.31,10,1,13.28,1,2,13.27,20,2,13.26,198,2,13.14,1,1,13.13,100,1,13.12,200,2,13.11,100,1,13.10,100,1,13.04,2,1,13.40,0,-10,13.46,0,-2,13.48,0,-1,13.49,0,-3,13.50,0,-1,13.51,0,-1,13.53,0,-2,13.54,0,-1,13.55,0,-2,13.56,0,-4,ARL,0
2025-07-17T16:12:53.332729487Z,2025-07-17T16:12:53.332564148Z,10,2,1108,C,A,10,14.000000000,100,338945933,165339,282196976,13.31,10,1,13.28,1,2,13.27,20,2,13.26,198,2,13.14,1,1,13.13,100,1,13.12,200,2,13.11,100,1,13.10,100,1,13.04,2,1,13.40,0,-10,13.46,0,-2,13.48,0,-1,13.49,0,-3,13.50,0,-1,13.51,0,-1,13.53,0,-2,13.54,0,-1,13.55,0,-2,13.56,0,-4,ARL,0
2025-07-17T16:12:53.332730508Z,2025-07-17T16:12:53.332565150Z,10,2,1108,A,A,10,14.530000000,100,339100477,165358,282196977,13.31,10,1,13.28,1,2,13.27,20,2,13.26,198,2,13.14,1,1,13.13,100,1,13.12,200,2,13.11,100,1,13.10,100,1,13.04,2,1,13.40,0,-10,13.46,0,-2,13.48,0,-1,13.49,0,-3,13.50,0,-1,13.51,0,-1,13.53,0,-2,13.54,0,-1,13.55,0,-2,13.56,0,-4,ARL,0
2025-07-17T16:12:53.587788615Z,2025-07-17T16:12:53.587623157Z,10,2,1108,A,A,10,14.810000000,100,339103269,165458,282200199,13.31,10,1,13.28,1,2,13.27,20,2,13.26,198,2,13.14,1,1,13.13,100,1,13.12,200,2,13.11,100,1,13.10,100,1,13.04,2,1,13.40,0,-10,13.46,0,-2,13.48,0,-1,13.49,0,-3,13.50,0,-1,13.51,0,-1,13.53,0,-2,13.54,0,-1,13.55,0,-2,13.56,0,-4,ARL,0
2025-07-17T16:12:53.587810242Z,2025-07-17T16:12:53.587644886Z,10,2,1108,C,A,10,14.270000000,100,338932853,165356,282200200,13.31,10,1,13.28,1,2,13.27,20,2,13.26,198,2,13.14,1,1,13.13,100,1,13.12,200,2,13.11,100,1,13.10,100,1,13.04,2,1,13.40,0,-10,13.46,0,-2,13.48,0,-1,13.49,0,-3,13.50,0,-1,13.51,0,-1,13.53,0,-2,13.54,0,-1,13.55,0,-2,13.56,0,-4,ARL,0
2025-07-17T16:12:54.015217279Z,2025-07-17T16:12:54.015051915Z,10,2,1108,A,A,10,13.470000000,100,339110853,165364,282207405,13.31,10,1,13.28,1,2,13.27,20,2,13.26,198,2,13.14,1,1,13.13,100,1,13.12,200,2,13.11,100,1,13.10,100,1,13.04,2,1,13.40,0,-10,13.46,0,-2,13.48,0,-1,13.49,0,-3,13.50,0,-1,13.51,0,-1,13.53,0,-2,13.54,0,-1,13.55,0,-2,13.56,0,-4,ARL,0
2025-07-17T16:12:54.015951319Z,2025-07-17T16:12:54.015785325Z,10,2,1108,C,A,10,14.600000000,100,339096925,165994,282207428,13.31,10,1,13.28,1,2,13.27,20,2,13.26,198,2,13.14,1,1,13.13,100,1,13.12,200,2,13.11,100,1,13.10,100,1,13.04,2,1,13.40,0,-10,13.46,0,-2,13.47,0,-1,13.48,0,-1,13.49,0,-3,13.50,0,-1,13.51,0,-1,13.53,0,-2,13.54,0,-1,13.55,0,-2,ARL,0
2025-07-17T16:12:54.015954059Z,2025-07-17T16:12:54.015788678Z,10,2,1108,C,A,10,15.060000000,100,339097245,165381,282207429,13.31,10,1,13.28,1,2,13.27,20,2,13.26,198,2,13.14,1,1,13.13,100,1,13.12,200,2,13.11,100,1,13.10,100,1,13.04,2,1,13.40,0,-10,13.46,0,-2,13.47,0,-1,13.48,0,-1,13.49,0,-3,13.50,0,-1,13.51,0,-1,13.53,0,-2,13.54,0,-1,13.55,0,-2,ARL,0
2025-07-17T16:12:54.015954059Z,2025-07-17T16:12:54.015788678Z,10,2,1108,A,A,10,14.520000000,100,339110897,165381,282207429,13.31,10,1,13.28,1,2,13.27,20,2,13.26,198,2,13.14,1,1,13.13,100,1,13.12,200,2,13.11,100,1,13.10,100,1,13.04,2,1,13.40,0,-10,13.46,0,-2,13.47,0,-1,13.48,0,-1,13.49,0,-3,13.50,0,-1,13.51,0,-1,13.53,0,-2,13.54,0,-1,13.55,0,-2,ARL,0
2025-07-17T16:12:54.016305036Z,2025-07-17T16:12:54.016139684Z,10,2,1108,A,A,10,14.070000000,100,339110909,165352,282207437,13.31,10,1,13.28,1,2,13.27,20,2,13.26,198,2,13.14,1,1,13.13,100,1,13.12,200,2,13.11,100,1,13.10,100,1,13.04,2,1,13.40,0,-10,13.46,0,-2,13.47,0,-1,13.48,0,-1,13.49,0,-3,13.50,0,-1,13.51,0,-1,13.53,0,-2,13.54,0,-1,13.55,0,-2,ARL,0
2025-07-17T16:12:54.017154493Z,2025-07-17T16:12:54.016988897Z,10,2,1108,C,A,10,14.960000000,100,339096917,165596,282207488,13.31,10,1,13.28,1,2,13.27,20,2,13.26,198,2,13.14,1,1,13.13,100,1,13.12,200,2,13.11,100,1,13.10,100,1,13.04,2,1,13.40,0,-10,13.46,0,-2,13.47,0,-1,13.48,0,-1,13.49,0,-3,13.50,0,-1,13.51,0,-1,13.53,0,-2,13.54,0,-1,13.55,0,-2,ARL,0
2025-07-17T16:12:54.017154493Z,2025-07-17T16:12:54.016988897Z,10,2,1108,A,A,10,14.420000000,100,339110981,165596,282207488,13.31,10,1,13.28,1,2,13.27,20,2,13.26,198,2,13.14,1,1,13.13,100,1,13.12,200,2,13.11,100,1,13.10,100,1,13.04,2,1,13.40,0,-10,13.46,0,-2,13.47,0,-1,13.48,0,-1,13.49,0,-3,13.50,0,-1,13.51,0,-1,13.53,0,-2,13.54,0,-1,13.55,0,-2,ARL,0
2025-07-17T16:12:54.017381126Z,2025-07-17T16:12:54.017215883Z,10,2,1108,C,A,10,13.980000000,2,339096909,165243,282207495,13.31,10,1,13.28,1,2,13.27,20,2,13.26,198,2,13.14,1,1,13.13,100,1,13.12,200,2,13.11,100,1,13.10,100,1,13.04,2,1,13.40,0,-10,13.46,0,-2,13.47,0,-1,13.48,0,-1,13.49,0,-3,13.50,0,-1,13.51,0,-1,13.53,0,-2,13.54,0,-1,13.55,0,-2,ARL,0
2025-07-17T16:12:54.017381126Z,2025-07-17T16:12:54.017215883Z,10,2,1108,A,A,10,13.730000000,2,339110993,165243,282207495,13.31,10,1,13.28,1,2,13.27,20,2,13.26,198,2,13.14,1,1,13.13,100,1,13.12,200,2,13.11,100,1,13.10,100,1,13.04,2,1,13.40,0,-10,13.46,0,-2,13.47,0,-1,13.48,0,-1,13.49,0,-3,13.50,0,-1,13.51,0,-1,13.53,0,-2,13.54,0,-1,13.55,0,-2,ARL,0
2025-07-17T16:12:54.017787766Z,2025-07-17T16:12:54.017622232Z,10,2,1108,C,A,10,15.380000000,100,339096929,165534,282207502,13.31,10,1,13.28,1,2,13.27,20,2,13.26,198,2,13.14,1,1,13.13,100,1,13.12,200,2,13.11,100,1,13.10,100,1,13.04,2,1,13.40,0,-10,13.46,0,-2,13.47,0,-1,13.48,0,-1,13.49,0,-3,13.50,0,-1,13.51,0,-1,13.53,0,-2,13.54,0,-1,13.55,0,-2,ARL,0
2025-07-17T16:12:54.017787766Z,2025-07-17T16:12:54.017622232Z,10,2,1108,A,A,10,14.820000000,100,339111005,165534,282207502,13.31,10,1,13.28,1,2,13.27,20,2,13.26,198,2,13.14,1,1,13.13,100,1,13.12,200,2,13.11,100,1,13.10,100,1,13.04,2,1,13.40,0,-10,13.46,0,-2,13.47,0,-1,13.48,0,-1,13.49,0,-3,13.50,0,-1,13.51,0,-1,13.53,0,-2,13.54,0,-1,13.55,0,-2,ARL,0
2025-07-17T16:12:54.020179178Z,2025-07-17T16:12:54.020013940Z,10,2,1108,C,A,10,14.260000000,100,339097005,165238,282207539,13.31,10,1,13.28,1,2,13.27,20,2,13.26,198,2,13.14,1,1,13.13,100,1,13.12,200,2,13.11,100,1,13.10,100,1,13.04,2,1,13.40,0,-10,13.46,0,-2,13.47,0,-1,13.48,0,-1,13.49,0,-3,13.50,0,-1,13.51,0,-1,13.53,0,-2,13.54,0,-1,13.55,0,-2,ARL,0
2025-07-17T16:12:54.020233019Z,2025-07-17T16:12:54.020067630Z,10,2,1108,A,A,10,13.740000000,100,339111029,165389,282207540,13.31,10,1,13.28,1,2,13.27,20,2,13.26,198,2,13.14,1,1,13.13,100,1,13.12,200,2,13.11,100,1,13.10,100,1,13.04,2,1,13.40,0,-10,13.46,0,-2,13.47,0,-1,13.48,0,-1,13.49,0,-3,13.50,0,-1,13.51,0,-1,13.53,0,-2,13.54,0,-1,13.55,0,-2,ARL,0
2025-07-17T16:12:54.023027943Z,2025-07-17T16:12:54.022862493Z,10,2,1108,C,A,10,17.760000000,100,339096949,165450,282207651,13.31,10,1,13.28,1,2,13.27,20,2,13.26,198,2,13.14,1,1,13.13,100,1,13.12,200,2,13.11,100,1,13.10,100,1,13.04,2,1,13.40,0,-10,13.46,0,-2,13.47,0,-1,13.48,0,-1,13.49,0,-3,13.50,0,-1,13.51,0,-1,13.53,0,-2,13.54,0,-1,13.55,0,-2,ARL,0
2025-07-17T16:12:54.023027943Z,2025-07-17T16:12:54.022862493Z,10,2,1108,A,A,10,17.110000000,100,339111097,165450,282207651,13.31,10,1,13.28,1,2,13.27,20,2,13.26,198,2,13.14,1,1,13.13,100,1,13.12,200,2,13.11,100,1,13.10,100,1,13.04,2,1,13.40,0,-10,13.46,0,-2,13.47,0,-1,13.48,0,-1,13.49,0,-3,13.50,0,-1,13.51,0,-1,13.53,0,-2,13.54,0,-1,13.55,0,-2,ARL,0
2025-07-17T16:12:54.026187354Z,2025-07-17T16:12:54.026021681Z,10,2,1108,C,A,10,16.080000000,100,339096921,165673,282207700,13.31,10,1,13.28,1,2,13.27,20,2,13.26,198,2,13.14,1,1,13.13,100,1,13.12,200,2,13.11,100,1,13.10,100,1,13.04,2,1,13.40,0,-10,13.46,0,-2,13.47,0,-1,13.48,0,-1,13.49,0,-3,13.50,0,-1,13.51,0,-1,13.53,0,-2,13.54,0,-1,13.55,0,-2,ARL,0
2025-07-17T16:12:54.026187354Z,2025-07-17T16:12:54.026021681Z,10,2,1108,A,A,10,15.500000000,100,339111149,165673,282207700,13.31,10,1,13.28,1,2,13.27,20,2,13.26,198,2,13.14,1,1,13.13,100,1,13.12,200,2,13.11,100,1,13.10,100,1,13.04,2,1,13.40,0,-10,13.46,0,-2,13.47,0,-1,13.48,0,-1,13.49,0,-3,13.50,0,-1,13.51,0,-1,13.53,0,-2,13.54,0,-1,13.55,0,-2,ARL,0
2025-07-17T16:12:54.029232379Z,2025-07-17T16:12:54.029066847Z,10,2,1108,C,A,10,14.550000000,100,339096833,165532,282207737,13.31,10,1,13.28,1,2,13.27,20,2,13.26,198,2,13.14,1,1,13.13,100,1,13.12,200,2,13.11,100,1,13.10,100,1,13.04,2,1,13.40,0,-10,13.46,0,-2,13.47,0,-1,13.48,0,-1,13.49,0,-3,13.50,0,-1,13.51,0,-1,13.53,0,-2,13.54,0,-1,13.55,0,-2,ARL,0
2025-07-17T16:12:54.029232379Z,2025-07-17T16:12:54.029066847Z,10,2,1108,A,A,10,14.260000000,100,339111189,165532,282207737,13.31,10,1,13.28,1,2,13.27,20,2,13.26,198,2,13.14,1,1,13.13,100,1,13.12,200,2,13.11,100,1,13.10,100,1,13.04,2,1,13.40,0,-10,13.46,0,-2,13.47,0,-1,13.48,0,-1,13.49,0,-3,13.50,0,-1,13.51,0,-1,13.53,0,-2,13.54,0,-1,13.55,0,-2,ARL,0
2025-07-17T16:12:54.055257401Z,2025-07-17T16:12:54.055092122Z,10,2,1108,A,A,10,15.360000000,100,339112469,165279,282209385,13.31,10,1,13.28,1,2,13.27,20,2,13.26,198,2,13.14,1,1,13.13,100,1,13.12,200,2,13.11,100,1,13.10,100,1,13.04,2,1,13.40,0,-10,13.46,0,-2,13.47,0,-1,13.48,0,-1,13.49,0,-3,13.50,0,-1,13.51,0,-1,13.53,0,-2,13.54,0,-1,13.55,0,-2,ARL,0
2025-07-17T16:12:54.055269406Z,2025-07-17T16:12:54.055104415Z,10,2,1108,C,A,10,15.690000000,100,339096757,164991,282209392,13.31,10,1,13.28,1,2,13.27,20,2,13.26,198,2,13.14,1,1,13.13,100,1,13.12,200,2,13.11,100,1,13.10,100,1,13.04,2,1,13.40,0,-10,13.46,0,-2,13.47,0,-1,13.48,0,-1,13.49,0,-3,13.50,0,-1,13.51,0,-1,13.53,0,-2,13.54,0,-1,13.55,0,-2,ARL,0
2025-07-17T16:12:54.069779810Z,2025-07-17T16:12:54.069614114Z,10,2,1108,C,A,10,14.960000000,100,339096977,165696,282210148,13.31,10,1,13.28,1,2,13.27,20,2,13.26,198,2,13.14,1,1,13.13,100,1,13.12,200,2,13.11,100,1,13.10,100,1,13.04,2,1,13.40,0,-10,13.46,0,-2,13.47,0,-1,13.48,0,-1,13.49,0,-3,13.50,0,-1,13.51,0,-1,13.53,0,-2,13.54,0,-1,13.55,0,-2,ARL,0
2025-07-17T16:12:54.069779810Z,2025-07-17T16:12:54.069614114Z,10,2,1108,A,A,10,14.420000000,100,339112945,165696,282210148,13.31,10,1,13.28,1,2,13.27,20,2,13.26,198,2,13.14,1,1,13.13,100,1,13.12,200,2,13.11,100,1,13.10,100,1,13.04,2,1,13.40,0,-10,13.46,0,-2,13.47,0,-1,13.48,0,-1,13.49,0,-3,13.50,0,-1,13.51,0,-1,13.53,0,-2,13.54,0,-1,13.55,0,-2,ARL,0
2025-07-17T16:12:54.072881596Z,2025-07-17T16:12:54.072716256Z,10,2,1108,C,A,10,15.140000000,100,339096813,165340,282210181,13.31,10,1,13.28,1,2,13.27,20,2,13.26,198,2,13.14,1,1,13.13,100,1,13.12,200,2,13.11,100,1,13.10,100,1,13.04,2,1,13.40,0,-10,13.46,0,-2,13.47,0,-1,13.48,0,-1,13.49,0,-3,13.50,0,-1,13.51,0,-1,13.53,0,-2,13.54,0,-1,13.55,0,-2,ARL,0
2025-07-17T16:12:54.072881596Z,2025-07-17T16:12:54.072716256Z,10,2,1108,A,A,10,14.820000000,100,339112981,165340,282210181,13.31,10,1,13.28,1,2,13.27,20,2,13.26,198,2,13.14,1,1,13.13,100,1,13.12,200,2,13.11,100,1,13.10,100,1,13.04,2,1,13.40,0,-10,13.46,0,-2,13.47,0,-1,13.48,0,-1,13.49,0,-3,13.50,0,-1,13.51,0,-1,13.53,0,-2,13.54,0,-1,13.55,0,-2,ARL,0
2025-07-17T16:12:54.694796063Z,2025-07-17T16:12:54.694630780Z,10,2,1108,A,A,10,14.270000000,100,339126221,165283,282224916,13.31,10,1,13.28,1,2,13.27,20,2,13.26,198,2,13.14,1,1,13.13,100,1,13.12,200,2,13.11,100,1,13.10,100,1,13.04,2,1,13.40,0,-10,13.46,0,-2,13.47,0,-1,13.48,0,-1,13.49,0,-3,13.50,0,-1,13.51,0,-1,13.53,0,-2,13.54,0,-1,13.55,0,-2,ARL,0
2025-07-17T16:12:54.694809520Z,2025-07-17T16:12:54.694644316Z,10,2,1108,C,A,10,14.810000000,100,339103269,165204,282224917,13.31,10,1,13.28,1,2,13.27,20,2,13.26,198,2,13.14,1,1,13.13,100,1,13.12,200,2,13.11,100,1,13.10,100,1,13.04,2,1,13.40,0,-10,13.46,0,-2,13.47,0,-1,13.48,0,-1,13.49,0,-3,13.50,0,-1,13.51,0,-1,13.53,0,-2,13.54,0,-1,13.55,0,-2,ARL,0
2025-07-17T16:12:55.255327586Z,2025-07-17T16:12:55.255162003Z,10,2,1108,A,A,10,14.000000000,100,339133353,165583,282231441,13.31,10,1,13.28,1,2,13.27,20,2,13.26,198,2,13.14,1,1,13.13,100,1,13.12,200,2,13.11,100,1,13.10,100,1,13.04,2,1,13.40,0,-10,13.46,0,-2,13.47,0,-1,13.48,0,-1,13.49,0,-3,13.50,0,-1,13.51,0,-1,13.53,0,-2,13.54,0,-1,13.55,0,-2,ARL,0
2025-07-17T16:12:55.255328269Z,2025-07-17T16:12:55.255163083Z,10,2,1108,C,A,10,14.530000000,100,339100477,165186,282231442,13.31,10,1,13.28,1,2,13.27,20,2,13.26,198,2,13.14,1,1,13.13,100,1,13.12,200,2,13.11,100,1,13.10,100,1,13.04,2,1,13.40,0,-10,13.46,0,-2,13.47,0,-1,13.48,0,-1,13.49,0,-3,13.50,0,-1,13.51,0,-1,13.53,0,-2,13.54,0,-1,13.55,0,-2,ARL,0
2025-07-17T16:12:58.302183447Z,2025-07-17T16:12:58.302017238Z,10,2,1108,C,A,10,13.460000000,15,339096733,166209,282279351,13.31,10,1,13.28,1,2,13.27,20,2,13.26,198,2,13.14,1,1,13.13,100,1,13.12,200,2,13.11,100,1,13.10,100,1,13.04,2,1,13.40,0,-10,13.46,0,-2,13.47,0,-1,13.48,0,-1,13.49,0,-3,13.50,0,-1,13.51,0,-1,13.53,0,-2,13.54,0,-1,13.55,0,-2,ARL,0
2025-07-17T16:12:58.420887746Z,2025-07-17T16:12:58.420710579Z,10,2,1108,C,A,10,13.470000000,100,339110853,177167,282288716,13.31,10,1,13.28,1,2,13.27,20,2,13.26,198,2,13.14,1,1,13.13,100,1,13.12,200,2,13.11,100,1,13.10,100,1,13.04,2,1,13.40,0,-10,13.46,0,-2,13.47,0,-1,13.48,0,-1,13.49,0,-3,13.50,0,-1,13.51,0,-1,13.53,0,-2,13.54,0,-1,13.55,0,-2,ARL,0
2025-07-17T16:12:58.420950587Z,2025-07-17T16:12:58.420776003Z,10,2,1108,A,A,10,13.470000000,96,339201549,174584,282288757,13.31,10,1,13.28,1,2,13.27,20,2,13.26,198,2,13.14,1,1,13.13,100,1,13.12,200,2,13.11,100,1,13.10,100,1,13.04,2,1,13.40,0,-10,13.46,0,-2,13.47,0,-1,13.48,0,-1,13.49,0,-3,13.50,0,-1,13.51,0,-1,13.53,0,-2,13.54,0,-1,13.55,0,-2,ARL,0
2025-07-17T16:12:58.421338553Z,2025-07-17T16:12:58.421165414Z,10,2,1108,C,A,10,13.470000000,96,339201549,173139,282289082,13.31,10,1,13.28,1,2,13.27,20,2,13.26,198,2,13.14,1,1,13.13,100,1,13.12,200,2,13.11,100,1,13.10,100,1,13.04,2,1,13.40,0,-10,13.46,0,-2,13.47,0,-2,13.48,0,-1,13.49,0,-3,13.50,0,-1,13.51,0,-1,13.53,0,-2,13.54,0,-1,13.55,0,-2,ARL,0
2025-07-17T16:12:58.421379924Z,2025-07-17T16:12:58.421205027Z,10,2,1108,A,A,10,15.670000000,100,339202065,174897,282289111,13.31,10,1,13.28,1,2,13.27,20,2,13.26,198,2,13.14,1,1,13.13,100,1,13.12,200,2,13.11,100,1,13.10,100,1,13.04,2,1,13.40,0,-10,13.46,0,-2,13.47,0,-2,13.48,0,-1,13.49,0,-3,13.50,0,-1,13.51,0,-1,13.53,0,-2,13.54,0,-1,13.55,0,-2,ARL,0
2025-07-17T16:12:58.421423275Z,2025-07-17T16:12:58.421248082Z,10,2,1108,C,A,10,15.360000000,100,339112469,175193,282289154,13.31,10,1,13.28,1,2,13.27,20,2,13.26,198,2,13.14,1,1,13.13,100,1,13.12,200,2,13.11,100,1,13.10,100,1,13.04,2,1,13.40,0,-10,13.46,0,-2,13.47,0,-2,13.48,0,-1,13.49,0,-3,13.50,0,-1,13.51,0,-1,13.53,0,-2,13.54,0,-1,13.55,0,-2,ARL,0
2025-07-17T16:12:58.421756726Z,2025-07-17T16:12:58.421581692Z,10,2,1108,C,A,10,14.070000000,100,339110909,175034,282289338,13.31,10,1,13.28,1,2,13.27,20,2,13.26,198,2,13.14,1,1,13.13,100,1,13.12,200,2,13.11,100,1,13.10,100,1,13.04,2,1,13.40,0,-10,13.46,0,-2,13.47,0,-2,13.48,0,-1,13.49,0,-3,13.50,0,-1,13.51,0,-1,13.53,0,-2,13.54,0,-1,13.55,0,-2,ARL,0
2025-07-17T16:12:58.422145785Z,2025-07-17T16:12:58.421969675Z,10,2,1108,A,A,10,14.350000000,100,339202733,176110,282289650,13.31,10,1,13.28,1,2,13.27,20,2,13.26,198,2,13.14,1,1,13.13,100,1,13.12,200,2,13.11,100,1,13.10,100,1,13.04,2,1,13.40,0,-10,13.46,0,-2,13.47,0,-2,13.48,0,-1,13.49,0,-3,13.50,0,-1,13.51,0,-1,13.53,0,-2,13.54,0,-1,13.55,0,-2,ARL,0
2025-07-17T16:12:58.422247877Z,2025-07-17T16:12:58.422073305Z,10,2,1108,C,A,10,14.520000000,100,339110897,174572,282289747,13.31,10,1,13.28,1,2,13.27,20,2,13.26,198,2,13.14,1,1,13.13,100,1,13.12,200,2,13.11,100,1,13.10,100,1,13.04,2,1,13.40,0,-10,13.46,0,-2,13.47,0,-2,13.48,0,-1,13.49,0,-3,13.50,0,-1,13.51,0,-1,13.53,0,-2,13.54,0,-1,13.55,0,-2,ARL,0
2025-07-17T16:12:58.422247877Z,2025-07-17T16:12:58.422073305Z,10,2,1108,A,A,10,14.810000000,100,339202805,174572,282289747,13.31,10,1,13.28,1,2,13.27,20,2,13.26,198,2,13.14,1,1,13.13,100,1,13.12,200,2,13.11,100,1,13.10,100,1,13.04,2,1,13.40,0,-10,13.46,0,-2,13.47,0,-2,13.48,0,-1,13.49,0,-3,13.50,0,-1,13.51,0,-1,13.53,0,-2,13.54,0,-1,13.55,0,-2,ARL,0
2025-07-17T16:12:58.424958370Z,2025-07-17T16:12:58.424789366Z,10,2,1108,C,A,10,14.400000000,100,338139585,169004,282290622,13.31,10,1,13.28,1,2,13.27,20,2,13.26,198,2,13.14,1,1,13.13,100,1,13.12,200,2,13.11,100,1,13.10,100,1,13.04,2,1,13.40,0,-10,13.46,0,-2,13.47,0,-2,13.48,0,-1,13.49,0,-3,13.50,0,-1,13.51,0,-1,13.53,0,-2,13.54,0,-1,13.55,0,-2,ARL,0
2025-07-17T16:12:58.424958370Z,2025-07-17T16:12:58.424789366Z,10,2,1108,A,A,10,14.570000000,100,339203693,169004,282290622,13.31,10,1,13.28,1,2,13.27,20,2,13.26,198,2,13.14,1,1,13.13,100,1,13.12,200,2,13.11,100,1,13.10,100,1,13.04,2,1,13.40,0,-10,13.46,0,-2,13.47,0,-2,13.48,0,-1,13.49,0,-3,13.50,0,-1,13.51,0,-1,13.53,0,-2,13.54,0,-1,13.55,0,-2,ARL,0
2025-07-17T16:12:58.425450176Z,2025-07-17T16:12:58.425283932Z,10,2,1108,C,A,10,14.400000000,100,338139601,166244,282290769,13.31,10,1,13.28,1,2,13.27,20,2,13.26,198,2,13.14,1,1,13.13,100,1,13.12,200,2,13.11,100,1,13.10,100,1,13.04,2,1,13.40,0,-10,13.46,0,-2,13.47,0,-2,13.48,0,-1,13.49,0,-3,13.50,0,-1,13.51,0,-1,13.53,0,-2,13.54,0,-1,13.55,0,-2,ARL,0
2025-07-17T16:12:58.425450176Z,2025-07-17T16:12:58.425283932Z,10,2,1108,A,A,10,14.570000000,100,339203897,166244,282290769,13.31,10,1,13.28,1,2,13.27,20,2,13.26,198,2,13.14,1,1,13.13,100,1,13.12,200,2,13.11,100,1,13.10,100,1,13.04,2,1,13.40,0,-10,13.46,0,-2,13.47,0,-2,13.48,0,-1,13.49,0,-3,13.50,0,-1,13.51,0,-1,13.53,0,-2,13.54,0,-1,13.55,0,-2,ARL,0
2025-07-17T16:12:58.426423622Z,2025-07-17T16:12:58.426258092Z,10,2,1108,C,A,10,14.260000000,100,339111189,165530,282290946,13.31,10,1,13.28,1,2,13.27,20,2,13.26,198,2,13.14,1,1,13.13,100,1,13.12,200,2,13.11,100,1,13.10,100,1,13.04,2,1,13.40,0,-10,13.46,0,-2,13.47,0,-2,13.48,0,-1,13.49,0,-3,13.50,0,-1,13.51,0,-1,13.53,0,-2,13.54,0,-1,13.55,0,-2,ARL,0
2025-07-17T16:12:58.426544477Z,2025-07-17T16:12:58.426378483Z,10,2,1108,A,A,10,14.530000000,100,339204077,165994,282290959,13.31,10,1,13.28,1,2,13.27,20,2,13.26,198,2,13.14,1,1,13.13,100,1,13.12,200,2,13.11,100,1,13.10,100,1,13.04,2,1,13.40,0,-10,13.46,0,-2,13.47,0,-2,13.48,0,-1,13.49,0,-3,13.50,0,-1,13.51,0,-1,13.53,0,-2,13.54,0,-1,13.55,0,-2,ARL,0
2025-07-17T16:12:58.430830694Z,2025-07-17T16:12:58.430665639Z,10,2,1108,C,A,10,13.740000000,100,339111029,165055,282291933,13.31,10,1,13.28,1,2,13.27,20,2,13.26,198,2,13.14,1,1,13.13,100,1,13.12,200,2,13.11,100,1,13.10,100,1,13.04,2,1,13.40,0,-10,13.46,0,-2,13.47,0,-2,13.48,0,-1,13.49,0,-3,13.50,0,-1,13.51,0,-1,13.53,0,-2,13.54,0,-1,13.55,0,-2,ARL,0
2025-07-17T16:12:58.430888526Z,2025-07-17T16:12:58.430720526Z,10,2,1108,A,A,10,14.010000000,100,339205213,168000,282291946,13.31,10,1,13.28,1,2,13.27,20,2,13.26,198,2,13.14,1,1,13.13,100,1,13.12,200,2,13.11,100,1,13.10,100,1,13.04,2,1,13.40,0,-10,13.46,0,-2,13.47,0,-2,13.48,0,-1,13.49,0,-3,13.50,0,-1,13.51,0,-1,13.53,0,-2,13.54,0,-1,13.55,0,-2,ARL,0
2025-07-17T16:12:58.432901795Z,2025-07-17T16:12:58.432736189Z,10,2,1108,C,A,10,14.820000000,100,339111005,165606,282292390,13.31,10,1,13.28,1,2,13.27,20,2,13.26,198,2,13.14,1,1,13.13,100,1,13.12,200,2,13.11,100,1,13.10,100,1,13.04,2,1,13.40,0,-10,13.46,0,-2,13.47,0,-2,13.48,0,-1,13.49,0,-3,13.50,0,-1,13.51,0,-1,13.53,0,-2,13.54,0,-1,13.55,0,-2,ARL,0
2025-07-17T16:12:58.432901795Z,2025-07-17T16:12:58.432736189Z,10,2,1108,A,A,10,15.380000000,100,339206141,165606,282292390,13.31,10,1,13.28,1,2,13.27,20,2,13.26,198,2,13.14,1,1,13.13,100,1,13.12,200,2,13.11,100,1,13.10,100,1,13.04,2,1,13.40,0,-10,13.46,0,-2,13.47,0,-2,13.48,0,-1,13.49,0,-3,13.50,0,-1,13.51,0,-1,13.53,0,-2,13.54,0,-1,13.55,0,-2,ARL,0
2025-07-17T16:12:58.438073339Z,2025-07-17T16:12:58.437907652Z,10,2,1108,C,B,10,12.920000000,2,338044113,165687,282292938,13.31,10,1,13.28,1,2,13.27,20,2,13.26,198,2,13.14,1,1,13.13,100,1,13.12,200,2,13.11,100,1,13.10,100,1,13.04,2,1,13.40,0,-10,13.46,0,-2,13.47,0,-2,13.48,0,-1,13.49,0,-3,13.50,0,-1,13.51,0,-1,13.53,0,-2,13.54,0,-1,13.55,0,-2,ARL,0
2025-07-17T16:12:58.438073339Z,2025-07-17T16:12:58.437907652Z,10,2,1108,A,B,10,13.020000000,2,339207125,165687,282292938,13.31,10,1,13.28,1,2,13.27,20,2,13.26,198,2,13.14,1,1,13.13,100,1,13.12,200,2,13.11,100,1,13.10,100,1,13.04,2,1,13.40,0,-10,13.46,0,-2,13.47,0,-2,13.48,0,-1,13.49,0,-3,13.50,0,-1,13.51,0,-1,13.53,0,-2,13.54,0,-1,13.55,0,-2,ARL,0
2025-07-17T16:12:58.438076762Z,2025-07-17T16:12:58.437911392Z,10,2,1108,C,A,10,13.730000000,2,339110993,165370,282292939,13.31,10,1,13.28,1,2,13.27,20,2,13.26,198,2,13.14,1,1,13.13,100,1,13.12,200,2,13.11,100,1,13.10,100,1,13.04,2,1,13.40,0,-10,13.46,0,-2,13.47,0,-2,13.48,0,-1,13.49,0,-3,13.50,0,-1,13.51,0,-1,13.53,0,-2,13.54,0,-1,13.55,0,-2,ARL,0
2025-07-17T16:12:58.438076762Z,2025-07-17T16:12:58.437911392Z,10,2,1108,A,A,10,13.980000000,2,339207129,165370,282292939,13.31,10,1,13.28,1,2,13.27,20,2,13.26,198,2,13.14,1,1,13.13,100,1,13.12,200,2,13.11,100,1,13.10,100,1,13.04,2,1,13.40,0,-10,13.46,0,-2,13.47,0,-2,13.48,0,-1,13.49,0,-3,13.50,0,-1,13.51,0,-1,13.53,0,-2,13.54,0,-1,13.55,0,-2,ARL,0
2025-07-17T16:12:58.438843944Z,2025-07-17T16:12:58.438678961Z,10,2,1108,C,A,10,14.010000000,100,339205213,164983,282293023,13.31,10,1,13.28,1,2,13.27,20,2,13.26,198,2,13.14,1,1,13.13,100,1,13.12,200,2,13.11,100,1,13.10,100,1,13.04,2,1,13.40,0,-10,13.46,0,-2,13.47,0,-2,13.48,0,-1,13.49,0,-3,13.50,0,-1,13.51,0,-1,13.53,0,-2,13.54,0,-1,13.55,0,-2,ARL,0
2025-07-17T16:12:58.438894336Z,2025-07-17T16:12:58.438728994Z,10,2,1108,A,A,10,14.240000000,100,339207197,165342,282293026,13.31,10,1,13.28,1,2,13.27,20,2,13.26,198,2,13.14,1,1,13.13,100,1,13.12,200,2,13.11,100,1,13.10,100,1,13.04,2,1,13.40,0,-10,13.46,0,-2,13.47,0,-2,13.48,0,-1,13.49,0,-3,13.50,0,-1,13.51,0,-1,13.53,0,-2,13.54,0,-1,13.55,0,-2,ARL,0
2025-07-17T16:12:58.441834497Z,2025-07-17T16:12:58.441669159Z,10,2,1108,C,A,10,14.420000000,100,339110981,165338,282293191,13.31,10,1,13.28,1,2,13.27,20,2,13.26,198,2,13.14,1,1,13.13,100,1,13.12,200,2,13.11,100,1,13.10,100,1,13.04,2,1,13.40,0,-10,13.46,0,-2,13.47,0,-2,13.48,0,-1,13.49,0,-3,13.50,0,-1,13.51,0,-1,13.53,0,-2,13.54,0,-1,13.55,0,-2,ARL,0
2025-07-17T16:12:58.441834497Z,2025-07-17T16:12:58.441669159Z,10,2,1108,A,A,10,14.960000000,100,339207505,165338,282293191,13.31,10,1,13.28,1,2,13.27,20,2,13.26,198,2,13.14,1,1,13.13,100,1,13.12,200,2,13.11,100,1,13.10,100,1,13.04,2,1,13.40,0,-10,13.46,0,-2,13.47,0,-2,13.48,0,-1,13.49,0,-3,13.50,0,-1,13.51,0,-1,13.53,0,-2,13.54,0,-1,13.55,0,-2,ARL,0
2025-07-17T16:12:58.454376675Z,2025-07-17T16:12:58.454211242Z,10,2,1108,C,A,10,17.110000000,100,339111097,165433,282293811,13.31,10,1,13.28,1,2,13.27,20,2,13.26,198,2,13.14,1,1,13.13,100,1,13.12,200,2,13.11,100,1,13.10,100,1,13.04,2,1,13.40,0,-10,13.46,0,-2,13.47,0,-2,13.48,0,-1,13.49,0,-3,13.50,0,-1,13.51,0,-1,13.53,0,-2,13.54,0,-1,13.55,0,-2,ARL,0
2025-07-17T16:12:58.454376675Z,2025-07-17T16:12:58.454211242Z,10,2,1108,A,A,10,17.760000000,100,339208377,165433,282293811,13.31,10,1,13.28,1,2,13.27,20,2,13.26,198,2,13.14,1,1,13.13,100,1,13.12,200,2,13.11,100,1,13.10,100,1,13.04,2,1,13.40,0,-10,13.46,0,-2,13.47,0,-2,13.48,0,-1,13.49,0,-3,13.50,0,-1,13.51,0,-1,13.53,0,-2,13.54,0,-1,13.55,0,-2,ARL,0
2025-07-17T16:12:58.472292476Z,2025-07-17T16:12:58.472126777Z,10,2,1108,C,A,10,15.500000000,100,339111149,165699,282294411,13.31,10,1,13.28,1,2,13.27,20,2,13.26,198,2,13.14,1,1,13.13,100,1,13.12,200,2,13.11,100,1,13.10,100,1,13.04,2,1,13.40,0,-10,13.46,0,-2,13.47,0,-2,13.48,0,-1,13.49,0,-3,13.50,0,-1,13.51,0,-1,13.53,0,-2,13.54,0,-1,13.55,0,-2,ARL,0
2025-07-17T16:12:58.472292476Z,2025-07-17T16:12:58.472126777Z,10,2,1108,A,A,10,16.080000000,100,339209241,165699,282294411,13.31,10,1,13.28,1,2,13.27,20,2,13.26,198,2,13.14,1,1,13.13,100,1,13.12,200,2,13.11,100,1,13.10,100,1,13.04,2,1,13.40,0,-10,13.46,0,-2,13.47,0,-2,13.48,0,-1,13.49,0,-3,13.50,0,-1,13.51,0,-1,13.53,0,-2,13.54,0,-1,13.55,0,-2,ARL,0
2025-07-17T16:12:58.472624779Z,2025-07-17T16:12:58.472458830Z,10,2,1108,C,A,10,14.810000000,100,339202805,165949,282294423,13.31,10,1,13.28,1,2,13.27,20,2,13.26,198,2,13.14,1,1,13.13,100,1,13.12,200,2,13.11,100,1,13.10,100,1,13.04,2,1,13.40,0,-10,13.46,0,-2,13.47,0,-2,13.48,0,-1,13.49,0,-3,13.50,0,-1,13.51,0,-1,13.53,0,-2,13.54,0,-1,13.55,0,-2,ARL,0
2025-07-17T16:12:58.472624779Z,2025-07-17T16:12:58.472458830Z,10,2,1108,A,A,10,15.040000000,100,339209257,165949,282294423,13.31,10,1,13.28,1,2,13.27,20,2,13.26,198,2,13.14,1,1,13.13,100,1,13.12,200,2,13.11,100,1,13.10,100,1,13.04,2,1,13.40,0,-10,13.46,0,-2,13.47,0,-2,13.48,0,-1,13.49,0,-3,13.50,0,-1,13.51,0,-1,13.53,0,-2,13.54,0,-1,13.55,0,-2,ARL,0
2025-07-17T16:12:58.571845708Z,2025-07-17T16:12:58.571679985Z,10,2,1108,C,A,10,14.820000000,100,339112981,165723,282298942,13.31,10,1,13.28,1,2,13.27,20,2,13.26,198,2,13.14,1,1,13.13,100,1,13.12,200,2,13.11,100,1,13.10,100,1,13.04,2,1,13.40,0,-10,13.46,0,-2,13.47,0,-2,13.48,0,-1,13.49,0,-3,13.50,0,-1,13.51,0,-1,13.53,0,-2,13.54,0,-1,13.55,0,-2,ARL,0
2025-07-17T16:12:58.571845708Z,2025-07-17T16:12:58.571679985Z,10,2,1108,A,A,10,15.380000000,100,339215205,165723,282298942,13.31,10,1,13.28,1,2,13.27,20,2,13.26,198,2,13.14,1,1,13.13,100,1,13.12,200,2,13.11,100,1,13.10,100,1,13.04,2,1,13.40,0,-10,13.46,0,-2,13.47,0,-2,13.48,0,-1,13.49,0,-3,13.50,0,-1,13.51,0,-1,13.53,0,-2,13.54,0,-1,13.55,0,-2,ARL,0
2025-07-17T16:12:58.619404102Z,2025-07-17T16:12:58.619238614Z,10,2,1108,C,A,10,14.420000000,100,339112945,165488,282299781,13.31,10,1,13.28,1,2,13.27,20,2,13.26,198,2,13.14,1,1,13.13,100,1,13.12,200,2,13.11,100,1,13.10,100,1,13.04,2,1,13.40,0,-10,13.46,0,-2,13.47,0,-2,13.48,0,-1,13.49,0,-3,13.50,0,-1,13.51,0,-1,13.53,0,-2,13.54,0,-1,13.55,0,-2,ARL,0
2025-07-17T16:12:58.619404102Z,2025-07-17T16:12:58.619238614Z,10,2,1108,A,A,10,14.960000000,100,339216161,165488,282299781,13.31,10,1,13.28,1,2,13.27,20,2,13.26,198,2,13.14,1,1,13.13,100,1,13.12,200,2,13.11,100,1,13.10,100,1,13.04,2,1,13.40,0,-10,13.46,0,-2,13.47,0,-2,13.48,0,-1,13.49,0,-3,13.50,0,-1,13.51,0,-1,13.53,0,-2,13.54,0,-1,13.55,0,-2,ARL,0
2025-07-17T16:12:58.986093948Z,2025-07-17T16:12:58.985928594Z,10,2,1108,C,B,10,13.020000000,2,339207125,165354,282305386,13.31,10,1,13.28,1,2,13.27,20,2,13.26,198,2,13.14,1,1,13.13,100,1,13.12,200,2,13.11,100,1,13.10,100,1,13.04,2,1,13.40,0,-10,13.46,0,-2,13.47,0,-2,13.48,0,-1,13.49,0,-3,13.50,0,-1,13.51,0,-1,13.53,0,-2,13.54,0,-1,13.55,0,-2,ARL,0
2025-07-17T16:12:58.986093948Z,2025-07-17T16:12:58.985928594Z,10,2,1108,A,B,10,12.860000000,2,339222617,165354,282305386,13.31,10,1,13.28,1,2,13.27,20,2,13.26,198,2,13.14,1,1,13.13,100,1,13.12,200,2,13.11,100,1,13.10,100,1,13.04,2,1,13.40,0,-10,13.46,0,-2,13.47,0,-2,13.48,0,-1,13.49,0,-3,13.50,0,-1,13.51,0,-1,13.53,0,-2,13.54,0,-1,13.55,0,-2,ARL,0
2025-07-17T16:12:59.063108412Z,2025-07-17T16:12:59.062943193Z,10,2,1108,A,A,10,13.990000000,100,339224109,165219,282306400,13.31,10,1,13.28,1,2,13.27,20,2,13.26,198,2,13.14,1,1,13.13,100,1,13.12,200,2,13.11,100,1,13.10,100,1,13.04,2,1,13.40,0,-10,13.46,0,-2,13.47,0,-2,13.48,0,-1,13.49,0,-3,13.50,0,-1,13.51,0,-1,13.53,0,-2,13.54,0,-1,13.55,0,-2,ARL,0
2025-07-17T16:12:59.082855570Z,2025-07-17T16:12:59.082690430Z,10,2,1108,C,A,10,14.000000000,100,339133353,165140,282307908,13.31,10,1,13.28,1,2,13.27,20,2,13.26,198,2,13.14,1,1,13.13,100,1,13.12,200,2,13.11,100,1,13.10,100,1,13.04,2,1,13.40,0,-10,13.46,0,-2,13.47,0,-2,13.48,0,-1,13.49,0,-3,13.50,0,-1,13.51,0,-1,13.53,0,-2,13.54,0,-1,13.55,0,-2,ARL,0
2025-07-17T16:12:59.082856640Z,2025-07-17T16:12:59.082691385Z,10,2,1108,A,A,10,14.530000000,100,339225769,165255,282307909,13.31,10,1,13.28,1,2,13.27,20,2,13.26,198,2,13.14,1,1,13.13,100,1,13.12,200,2,13.11,100,1,13.10,100,1,13.04,2,1,13.40,0,-10,13.46,0,-2,13.47,0,-2,13.48,0,-1,13.49,0,-3,13.50,0,-1,13.51,0,-1,13.53,0,-2,13.54,0,-1,13.55,0,-2,ARL,0
2025-07-17T16:12:59.088794570Z,2025-07-17T16:12:59.088629294Z,10,2,1108,A,A,10,14.810000000,100,339225885,165276,282308093,13.31,10,1,13.28,1,2,13.27,20,2,13.26,198,2,13.14,1,1,13.13,100,1,13.12,200,2,13.11,100,1,13.10,100,1,13.04,2,1,13.40,0,-10,13.46,0,-2,13.47,0,-2,13.48,0,-1,13.49,0,-3,13.50,0,-1,13.51,0,-1,13.53,0,-2,13.54,0,-1,13.55,0,-2,ARL,0
2025-07-17T16:12:59.088808117Z,2025-07-17T16:12:59.088642718Z,10,2,1108,C,A,10,14.270000000,100,339126221,165399,282308094,13.31,10,1,13.28,1,2,13.27,20,2,13.26,198,2,13.14,1,1,13.13,100,1,13.12,200,2,13.11,100,1,13.10,100,1,13.04,2,1,13.40,0,-10,13.46,0,-2,13.47,0,-2,13.48,0,-1,13.49,0,-3,13.50,0,-1,13.51,0,-1,13.53,0,-2,13.54,0,-1,13.55,0,-2,ARL,0
2025-07-17T16:12:59.092927842Z,2025-07-17T16:12:59.092762564Z,10,2,1108,C,A,10,14.350000000,100,339202733,165278,282308154,13.31,10,1,13.28,1,2,13.27,20,2,13.26,198,2,13.14,1,1,13.13,100,1,13.12,200,2,13.11,100,1,13.10,100,1,13.04,2,1,13.40,0,-10,13.46,0,-2,13.47,0,-2,13.48,0,-1,13.49,0,-3,13.50,0,-1,13.51,0,-1,13.53,0,-2,13.54,0,-1,13.55,0,-2,ARL,0
2025-07-17T16:12:59.093278915Z,2025-07-17T16:12:59.093113488Z,10,2,1108,A,A,10,14.600000000,100,339226021,165427,282308163,13.31,10,1,13.28,1,2,13.27,20,2,13.26,198,2,13.14,1,1,13.13,100,1,13.12,200,2,13.11,100,1,13.10,100,1,13.04,2,1,13.40,0,-10,13.46,0,-2,13.47,0,-2,13.48,0,-1,13.49,0,-3,13.50,0,-1,13.51,0,-1,13.53,0,-2,13.54,0,-1,13.55,0,-2,ARL,0
2025-07-17T16:12:59.430486012Z,2025-07-17T16:12:59.430320610Z,10,2,1108,C,A,10,14.530000000,100,339204077,165402,282313368,13.31,10,1,13.28,1,2,13.27,20,2,13.26,198,2,13.14,1,1,13.13,100,1,13.12,200,2,13.11,100,1,13.10,100,1,13.04,2,1,13.40,0,-10,13.46,0,-2,13.47,0,-2,13.48,0,-1,13.49,0,-3,13.50,0,-1,13.51,0,-1,13.53,0,-2,13.54,0,-1,13.55,0,-2,ARL,0
2025-07-17T16:12:59.430486012Z,2025-07-17T16:12:59.430320610Z,10,2,1108,A,A,10,14.770000000,100,339232213,165402,282313368,13.31,10,1,13.28,1,2,13.27,20,2,13.26,198,2,13.14,1,1,13.13,100,1,13.12,200,2,13.11,100,1,13.10,100,1,13.04,2,1,13.40,0,-10,13.46,0,-2,13.47,0,-2,13.48,0,-1,13.49,0,-3,13.50,0,-1,13.51,0,-1,13.53,0,-2,13.54,0,-1,13.55,0,-2,ARL,0
2025-07-17T16:13:04.825902166Z,2025-07-17T16:13:04.825736034Z,10,2,1108,A,A,10,13.660000000,15,339332865,166132,282392593,13.31,10,1,13.28,1,2,13.27,20,2,13.26,198,2,13.14,1,1,13.13,100,1,13.12,200,2,13.11,100,1,13.10,100,1,13.04,2,1,13.40,0,-10,13.46,0,-2,13.47,0,-2,13.48,0,-1,13.49,0,-3,13.50,0,-1,13.51,0,-1,13.53,0,-2,13.54,0,-1,13.55,0,-2,ARL,0
2025-07-17T16:13:06.189275812Z,2025-07-17T16:13:06.189110140Z,10,2,1108,C,B,10,12.860000000,2,339222617,165672,282411935,13.31,10,1,13.28,1,2,13.27,20,2,13.26,198,2,13.14,1,1,13.13,100,1,13.12,200,2,13.11,100,1,13.10,100,1,13.04,2,1,13.40,0,-10,13.46,0,-2,13.47,0,-2,13.48,0,-1,13.49,0,-3,13.50,0,-1,13.51,0,-1,13.53,0,-2,13.54,0,-1,13.55,0,-2,ARL,0
2025-07-17T16:13:06.189275812Z,2025-07-17T16:13:06.189110140Z,10,2,1108,A,B,10,12.960000000,2,339356397,165672,282411935,13.31,10,1,13.28,1,2,13.27,20,2,13.26,198,2,13.14,1,1,13.13,100,1,13.12,200,2,13.11,100,1,13.10,100,1,13.04,2,1,13.40,0,-10,13.46,0,-2,13.47,0,-2,13.48,0,-1,13.49,0,-3,13.50,0,-1,13.51,0,-1,13.53,0,-2,13.54,0,-1,13.55,0,-2,ARL,0
2025-07-17T16:13:06.224898389Z,2025-07-17T16:13:06.224732787Z,10,2,1108,C,A,10,13.990000000,100,339224109,165602,282413599,13.31,10,1,13.28,1,2,13.27,20,2,13.26,198,2,13.14,1,1,13.13,100,1,13.12,200,2,13.11,100,1,13.10,100,1,13.04,2,1,13.40,0,-10,13.46,0,-2,13.47,0,-2,13.48,0,-1,13.49,0,-3,13.50,0,-1,13.51,0,-1,13.53,0,-2,13.54,0,-1,13.55,0,-2,ARL,0
2025-07-17T16:13:06.224898389Z,2025-07-17T16:13:06.224732787Z,10,2,1108,A,A,10,13.670000000,100,339358233,165602,282413599,13.31,10,1,13.28,1,2,13.27,20,2,13.26,198,2,13.14,1,1,13.13,100,1,13.12,200,2,13.11,100,1,13.10,100,1,13.04,2,1,13.40,0,-10,13.46,0,-2,13.47,0,-2,13.48,0,-1,13.49,0,-3,13.50,0,-1,13.51,0,-1,13.53,0,-2,13.54,0,-1,13.55,0,-2,ARL,0
2025-07-17T16:13:06.225642781Z,2025-07-17T16:13:06.225475518Z,10,2,1108,C,A,10,15.040000000,100,339209257,167263,282413677,13.31,10,1,13.28,1,2,13.27,20,2,13.26,198,2,13.14,1,1,13.13,100,1,13.12,200,2,13.11,100,1,13.10,100,1,13.04,2,1,13.40,0,-10,13.46,0,-2,13.47,0,-2,13.48,0,-1,13.49,0,-3,13.50,0,-1,13.51,0,-1,13.53,0,-2,13.54,0,-1,13.55,0,-2,ARL,0
2025-07-17T16:13:06.225642781Z,2025-07-17T16:13:06.225475518Z,10,2,1108,A,A,10,14.730000000,100,339358293,167263,282413677,13.31,10,1,13.28,1,2,13.27,20,2,13.26,198,2,13.14,1,1,13.13,100,1,13.12,200,2,13.11,100,1,13.10,100,1,13.04,2,1,13.40,0,-10,13.46,0,-2,13.47,0,-2,13.48,0,-1,13.49,0,-3,13.50,0,-1,13.51,0,-1,13.53,0,-2,13.54,0,-1,13.55,0,-2,ARL,0
2025-07-17T16:13:06.225642781Z,2025-07-17T16:13:06.225475906Z,10,2,1108,C,A,10,14.600000000,100,339226021,166875,282413678,13.31,10,1,13.28,1,2,13.27,20,2,13.26,198,2,13.14,1,1,13.13,100,1,13.12,200,2,13.11,100,1,13.10,100,1,13.04,2,1,13.40,0,-10,13.46,0,-2,13.47,0,-2,13.48,0,-1,13.49,0,-3,13.50,0,-1,13.51,0,-1,13.53,0,-2,13.54,0,-1,13.55,0,-2,ARL,0
2025-07-17T16:13:06.225995297Z,2025-07-17T16:13:06.225829921Z,10,2,1108,A,A,10,14.280000000,100,339358333,165376,282413699,13.31,10,1,13.28,1,2,13.27,20,2,13.26,198,2,13.14,1,1,13.13,100,1,13.12,200,2,13.11,100,1,13.10,100,1,13.04,2,1,13.40,0,-10,13.46,0,-2,13.47,0,-2,13.48,0,-1,13.49,0,-3,13.50,0,-1,13.51,0,-1,13.53,0,-2,13.54,0,-1,13.55,0,-2,ARL,0
2025-07-17T16:13:06.226789913Z,2025-07-17T16:13:06.226624084Z,10,2,1108,C,A,10,15.380000000,100,339206141,165829,282413738,13.31,10,1,13.28,1,2,13.27,20,2,13.26,198,2,13.14,1,1,13.13,100,1,13.12,200,2,13.11,100,1,13.10,100,1,13.04,2,1,13.40,0,-10,13.46,0,-2,13.47,0,-2,13.48,0,-1,13.49,0,-3,13.50,0,-1,13.51,0,-1,13.53,0,-2,13.54,0,-1,13.55,0,-2,ARL,0
2025-07-17T16:13:06.226789913Z,2025-07-17T16:13:06.226624084Z,10,2,1108,A,A,10,15.040000000,100,339358349,165829,282413738,13.31,10,1,13.28,1,2,13.27,20,2,13.26,198,2,13.14,1,1,13.13,100,1,13.12,200,2,13.11,100,1,13.10,100,1,13.04,2,1,13.40,0,-10,13.46,0,-2,13.47,0,-2,13.48,0,-1,13.49,0,-3,13.50,0,-1,13.51,0,-1,13.53,0,-2,13.54,0,-1,13.55,0,-2,ARL,0
2025-07-17T16:13:06.226882302Z,2025-07-17T16:13:06.226716697Z,10,2,1108,C,A,10,14.960000000,100,339207505,165605,282413745,13.31,10,1,13.28,1,2,13.27,20,2,13.26,198,2,13.14,1,1,13.13,100,1,13.12,200,2,13.11,100,1,13.10,100,1,13.04,2,1,13.40,0,-10,13.46,0,-2,13.47,0,-2,13.48,0,-1,13.49,0,-3,13.50,0,-1,13.51,0,-1,13.53,0,-2,13.54,0,-1,13.55,0,-2,ARL,0
2025-07-17T16:13:06.226882302Z,2025-07-17T16:13:06.226716697Z,10,2,1108,A,A,10,14.630000000,100,339358353,165605,282413745,13.31,10,1,13.28,1,2,13.27,20,2,13.26,198,2,13.14,1,1,13.13,100,1,13.12,200,2,13.11,100,1,13.10,100,1,13.04,2,1,13.40,0,-10,13.46,0,-2,13.47,0,-2,13.48,0,-1,13.49,0,-3,13.50,0,-1,13.51,0,-1,13.53,0,-2,13.54,0,-1,13.55,0,-2,ARL,0
2025-07-17T16:13:06.229858538Z,2025-07-17T16:13:06.229693020Z,10,2,1108,C,A,10,13.980000000,2,339207129,165518,282413801,13.31,10,1,13.28,1,2,13.27,20,2,13.26,198,2,13.14,1,1,13.13,100,1,13.12,200,2,13.11,100,1,13.10,100,1,13.04,2,1,13.40,0,-10,13.46,0,-2,13.47,0,-2,13.48,0,-1,13.49,0,-3,13.50,0,-1,13.51,0,-1,13.53,0,-2,13.54,0,-1,13.55,0,-2,ARL,0
2025-07-17T16:13:06.229858538Z,2025-07-17T16:13:06.229693020Z,10,2,1108,A,A,10,13.810000000,2,339358409,165518,282413801,13.31,10,1,13.28,1,2,13.27,20,2,13.26,198,2,13.14,1,1,13.13,100,1,13.12,200,2,13.11,100,1,13.10,100,1,13.04,2,1,13.40,0,-10,13.46,0,-2,13.47,0,-2,13.48,0,-1,13.49,0,-3,13.50,0,-1,13.51,0,-1,13.53,0,-2,13.54,0,-1,13.55,0,-2,ARL,0
2025-07-17T16:13:06.235594115Z,2025-07-17T16:13:06.235428434Z,10,2,1108,C,A,10,17.760000000,100,339208377,165681,282414050,13.31,10,1,13.28,1,2,13.27,20,2,13.26,198,2,13.14,1,1,13.13,100,1,13.12,200,2,13.11,100,1,13.10,100,1,13.04,2,1,13.40,0,-10,13.46,0,-2,13.47,0,-2,13.48,0,-1,13.49,0,-3,13.50,0,-1,13.51,0,-1,13.53,0,-2,13.54,0,-1,13.55,0,-2,ARL,0
2025-07-17T16:13:06.235594115Z,2025-07-17T16:13:06.235428434Z,10,2,1108,A,A,10,17.370000000,100,339358609,165681,282414050,13.31,10,1,13.28,1,2,13.27,20,2,13.26,198,2,13.14,1,1,13.13,100,1,13.12,200,2,13.11,100,1,13.10,100,1,13.04,2,1,13.40,0,-10,13.46,0,-2,13.47,0,-2,13.48,0,-1,13.49,0,-3,13.50,0,-1,13.51,0,-1,13.53,0,-2,13.54,0,-1,13.55,0,-2,ARL,0
2025-07-17T16:13:06.236567790Z,2025-07-17T16:13:06.236401579Z,10,2,1108,C,A,10,14.240000000,100,339207197,166211,282414131,13.31,10,1,13.28,1,2,13.27,20,2,13.26,198,2,13.14,1,1,13.13,100,1,13.12,200,2,13.11,100,1,13.10,100,1,13.04,2,1,13.40,0,-10,13.46,0,-2,13.47,0,-2,13.48,0,-1,13.49,0,-3,13.50,0,-1,13.51,0,-1,13.53,0,-2,13.54,0,-1,13.55,0,-2,ARL,0
2025-07-17T16:13:06.236621535Z,2025-07-17T16:13:06.236456489Z,10,2,1108,A,A,10,13.940000000,100,339358741,165046,282414141,13.31,10,1,13.28,1,2,13.27,20,2,13.26,198,2,13.14,1,1,13.13,100,1,13.12,200,2,13.11,100,1,13.10,100,1,13.04,2,1,13.40,0,-10,13.46,0,-2,13.47,0,-2,13.48,0,-1,13.49,0,-3,13.50,0,-1,13.51,0,-1,13.53,0,-2,13.54,0,-1,13.55,0,-2,ARL,0
2025-07-17T16:13:06.243909112Z,2025-07-17T16:13:06.243743642Z,10,2,1108,C,A,10,16.080000000,100,339209241,165470,282414340,13.31,10,1,13.28,1,2,13.27,20,2,13.26,198,2,13.14,1,1,13.13,100,1,13.12,200,2,13.11,100,1,13.10,100,1,13.04,2,1,13.40,0,-10,13.46,0,-2,13.47,0,-2,13.48,0,-1,13.49,0,-3,13.50,0,-1,13.51,0,-1,13.53,0,-2,13.54,0,-1,13.55,0,-2,ARL,0
2025-07-17T16:13:06.243909112Z,2025-07-17T16:13:06.243743642Z,10,2,1108,A,A,10,15.730000000,100,339359077,165470,282414340,13.31,10,1,13.28,1,2,13.27,20,2,13.26,198,2,13.14,1,1,13.13,100,1,13.12,200,2,13.11,100,1,13.10,100,1,13.04,2,1,13.40,0,-10,13.46,0,-2,13.47,0,-2,13.48,0,-1,13.49,0,-3,13.50,0,-1,13.51,0,-1,13.53,0,-2,13.54,0,-1,13.55,0,-2,ARL,0
2025-07-17T16:13:06.268052093Z,2025-07-17T16:13:06.267886189Z,10,2,1108,C,A,10,15.380000000,100,339215205,165904,282414570,13.31,10,1,13.28,1,2,13.27,20,2,13.26,198,2,13.14,1,1,13.13,100,1,13.12,200,2,13.11,100,1,13.10,100,1,13.04,2,1,13.40,0,-10,13.46,0,-2,13.47,0,-2,13.48,0,-1,13.49,0,-3,13.50,0,-1,13.51,0,-1,13.53,0,-2,13.54,0,-1,13.55,0,-2,ARL,0
2025-07-17T16:13:06.268052093Z,2025-07-17T16:13:06.267886189Z,10,2,1108,A,A,10,15.040000000,100,339359357,165904,282414570,13.31,10,1,13.28,1,2,13.27,20,2,13.26,198,2,13.14,1,1,13.13,100,1,13.12,200,2,13.11,100,1,13.10,100,1,13.04,2,1,13.40,0,-10,13.46,0,-2,13.47,0,-2,13.48,0,-1,13.49,0,-3,13.50,0,-1,13.51,0,-1,13.53,0,-2,13.54,0,-1,13.55,0,-2,ARL,0
2025-07-17T16:13:06.275886461Z,2025-07-17T16:13:06.275720866Z,10,2,1108,C,A,10,14.960000000,100,339216161,165595,282414642,13.31,10,1,13.28,1,2,13.27,20,2,13.26,198,2,13.14,1,1,13.13,100,1,13.12,200,2,13.11,100,1,13.10,100,1,13.04,2,1,13.40,0,-10,13.46,0,-2,13.47,0,-2,13.48,0,-1,13.49,0,-3,13.50,0,-1,13.51,0,-1,13.53,0,-2,13.54,0,-1,13.55,0,-2,ARL,0
2025-07-17T16:13:06.275886461Z,2025-07-17T16:13:06.275720866Z,10,2,1108,A,A,10,14.630000000,100,339359401,165595,282414642,13.31,10,1,13.28,1,2,13.27,20,2,13.26,198,2,13.14,1,1,13.13,100,1,13.12,200,2,13.11,100,1,13.10,100,1,13.04,2,1,13.40,0,-10,13.46,0,-2,13.47,0,-2,13.48,0,-1,13.49,0,-3,13.50,0,-1,13.51,0,-1,13.53,0,-2,13.54,0,-1,13.55,0,-2,ARL,0
2025-07-17T16:13:06.277048260Z,2025-07-17T16:13:06.276882863Z,10,2,1108,C,A,10,14.770000000,100,339232213,165397,282414659,13.31,10,1,13.28,1,2,13.27,20,2,13.26,198,2,13.14,1,1,13.13,100,1,13.12,200,2,13.11,100,1,13.10,100,1,13.04,2,1,13.40,0,-10,13.46,0,-2,13.47,0,-2,13.48,0,-1,13.49,0,-3,13.50,0,-1,13.51,0,-1,13.53,0,-2,13.54,0,-1,13.55,0,-2,ARL,0
2025-07-17T16:13:06.277178914Z,2025-07-17T16:13:06.277013512Z,10,2,1108,A,A,10,14.460000000,100,339359421,165402,282414660,13.31,10,1,13.28,1,2,13.27,20,2,13.26,198,2,13.14,1,1,13.13,100,1,13.12,200,2,13.11,100,1,13.10,100,1,13.04,2,1,13.40,0,-10,13.46,0,-2,13.47,0,-2,13.48,0,-1,13.49,0,-3,13.50,0,-1,13.51,0,-1,13.53,0,-2,13.54,0,-1,13.55,0,-2,ARL,0
2025-07-17T16:13:06.622659102Z,2025-07-17T16:13:06.622493734Z,10,2,1108,A,A,10,14.220000000,100,339365193,165368,282418746,13.31,10,1,13.28,1,2,13.27,20,2,13.26,198,2,13.14,1,1,13.13,100,1,13.12,200,2,13.11,100,1,13.10,100,1,13.04,2,1,13.40,0,-10,13.46,0,-2,13.47,0,-2,13.48,0,-1,13.49,0,-3,13.50,0,-1,13.51,0,-1,13.53,0,-2,13.54,0,-1,13.55,0,-2,ARL,0
2025-07-17T16:13:06.663836744Z,2025-07-17T16:13:06.663671305Z,10,2,1108,C,A,10,14.530000000,100,339225769,165439,282418921,13.31,10,1,13.28,1,2,13.27,20,2,13.26,198,2,13.14,1,1,13.13,100,1,13.12,200,2,13.11,100,1,13.10,100,1,13.04,2,1,13.40,0,-10,13.46,0,-2,13.47,0,-2,13.48,0,-1,13.49,0,-3,13.50,0,-1,13.51,0,-1,13.53,0,-2,13.54,0,-1,13.55,0,-2,ARL,0
2025-07-17T16:13:06.759791103Z,2025-07-17T16:13:06.759625628Z,10,2,1108,A,A,10,14.490000000,100,339366385,165475,282419471,13.31,10,1,13.28,1,2,13.27,20,2,13.26,198,2,13.14,1,1,13.13,100,1,13.12,200,2,13.11,100,1,13.10,100,1,13.04,2,1,13.40,0,-10,13.46,0,-2,13.47,0,-2,13.48,0,-1,13.49,0,-3,13.50,0,-1,13.51,0,-1,13.53,0,-2,13.54,0,-1,13.55,0,-2,ARL,0
2025-07-17T16:13:06.759804641Z,2025-07-17T16:13:06.759638890Z,10,2,1108,C,A,10,14.810000000,100,339225885,165751,282419472,13.31,10,1,13.28,1,2,13.27,20,2,13.26,198,2,13.14,1,1,13.13,100,1,13.12,200,2,13.11,100,1,13.10,100,1,13.04,2,1,13.40,0,-10,13.46,0,-2,13.47,0,-2,13.48,0,-1,13.49,0,-3,13.50,0,-1,13.51,0,-1,13.53,0,-2,13.54,0,-1,13.55,0,-2,ARL,0
2025-07-17T16:13:09.354048740Z,2025-07-17T16:13:09.353883614Z,10,2,1108,A,A,10,13.640000000,15,339425837,165126,282469242,13.31,10,1,13.28,1,2,13.27,20,2,13.26,198,2,13.14,1,1,13.13,100,1,13.12,200,2,13.11,100,1,13.10,100,1,13.04,2,1,13.40,0,-10,13.46,0,-2,13.47,0,-2,13.48,0,-1,13.49,0,-3,13.50,0,-1,13.51,0,-1,13.53,0,-2,13.54,0,-1,13.55,0,-2,ARL,0
2025-07-17T16:13:09.368197659Z,2025-07-17T16:13:09.368030843Z,10,2,1108,C,A,10,13.670000000,100,339358233,166816,282470466,13.31,10,1,13.28,1,2,13.27,20,2,13.26,198,2,13.14,1,1,13.13,100,1,13.12,200,2,13.11,100,1,13.10,100,1,13.04,2,1,13.40,0,-10,13.46,0,-2,13.47,0,-2,13.48,0,-1,13.49,0,-3,13.50,0,-1,13.51,0,-1,13.53,0,-2,13.54,0,-1,13.55,0,-2,ARL,0
2025-07-17T16:13:09.368197659Z,2025-07-17T16:13:09.368030843Z,10,2,1108,A,A,10,13.650000000,100,339427217,166816,282470466,13.31,10,1,13.28,1,2,13.27,20,2,13.26,198,2,13.14,1,1,13.13,100,1,13.12,200,2,13.11,100,1,13.10,100,1,13.04,2,1,13.40,0,-10,13.46,0,-2,13.47,0,-2,13.48,0,-1,13.49,0,-3,13.50,0,-1,13.51,0,-1,13.53,0,-2,13.54,0,-1,13.55,0,-2,ARL,0
2025-07-17T16:13:14.046267875Z,2025-07-17T16:13:14.046102556Z,10,2,1108,C,A,10,13.660000000,15,339332865,165319,282563502,13.31,10,1,13.28,1,2,13.27,20,2,13.26,198,2,13.14,1,1,13.13,100,1,13.12,200,2,13.11,100,1,13.10,100,1,13.04,2,1,13.40,0,-10,13.46,0,-2,13.47,0,-2,13.48,0,-1,13.49,0,-3,13.50,0,-1,13.51,0,-1,13.53,0,-2,13.54,0,-1,13.55,0,-2,ARL,0
2025-07-17T16:13:17.775210916Z,2025-07-17T16:13:17.775045316Z,10,2,1108,A,A,10,13.570000000,15,339610637,165600,282616566,13.31,10,1,13.28,1,2,13.27,20,2,13.26,198,2,13.14,1,1,13.13,100,1,13.12,200,2,13.11,100,1,13.10,100,1,13.04,2,1,13.40,0,-10,13.46,0,-2,13.47,0,-2,13.48,0,-1,13.49,0,-3,13.50,0,-1,13.51,0,-1,13.53,0,-2,13.54,0,-1,13.55,0,-2,ARL,0
2025-07-17T16:13:19.781143691Z,2025-07-17T16:13:19.780978185Z,10,2,1108,C,A,10,13.650000000,100,339427217,165506,282644181,13.31,10,1,13.28,1,2,13.27,20,2,13.26,198,2,13.14,1,1,13.13,100,1,13.12,200,2,13.11,100,1,13.10,100,1,13.04,2,1,13.40,0,-10,13.46,0,-2,13.47,0,-2,13.48,0,-1,13.49,0,-3,13.50,0,-1,13.51,0,-1,13.53,0,-2,13.54,0,-1,13.55,0,-2,ARL,0
2025-07-17T16:13:19.781143691Z,2025-07-17T16:13:19.780978185Z,10,2,1108,A,A,10,13.580000000,100,339641813,165506,282644181,13.31,10,1,13.28,1,2,13.27,20,2,13.26,198,2,13.14,1,1,13.13,100,1,13.12,200,2,13.11,100,1,13.10,100,1,13.04,2,1,13.40,0,-10,13.46,0,-2,13.47,0,-2,13.48,0,-1,13.49,0,-3,13.50,0,-1,13.51,0,-1,13.53,0,-2,13.54,0,-1,13.55,0,-2,ARL,0
2025-07-17T16:13:19.781889805Z,2025-07-17T16:13:19.781723964Z,10,2,1108,C,A,10,14.730000000,100,339358293,165841,282644189,13.31,10,1,13.28,1,2,13.27,20,2,13.26,198,2,13.14,1,1,13.13,100,1,13.12,200,2,13.11,100,1,13.10,100,1,13.04,2,1,13.40,0,-10,13.46,0,-2,13.47,0,-2,13.48,0,-1,13.49,0,-3,13.50,0,-1,13.51,0,-1,13.53,0,-2,13.54,0,-1,13.55,0,-2,ARL,0
2025-07-17T16:13:19.781889805Z,2025-07-17T16:13:19.781723964Z,10,2,1108,A,A,10,14.630000000,100,339641865,165841,282644189,13.31,10,1,13.28,1,2,13.27,20,2,13.26,198,2,13.14,1,1,13.13,100,1,13.12,200,2,13.11,100,1,13.10,100,1,13.04,2,1,13.40,0,-10,13.46,0,-2,13.47,0,-2,13.48,0,-1,13.49,0,-3,13.50,0,-1,13.51,0,-1,13.53,0,-2,13.54,0,-1,13.55,0,-2,ARL,0
2025-07-17T16:13:19.789771458Z,2025-07-17T16:13:19.789606057Z,10,2,1108,C,A,10,13.940000000,100,339358741,165401,282644321,13.31,10,1,13.28,1,2,13.27,20,2,13.26,198,2,13.14,1,1,13.13,100,1,13.12,200,2,13.11,100,1,13.10,100,1,13.04,2,1,13.40,0,-10,13.46,0,-2,13.47,0,-2,13.48,0,-1,13.49,0,-3,13.50,0,-1,13.51,0,-1,13.53,0,-2,13.54,0,-1,13.55,0,-2,ARL,0
2025-07-17T16:13:19.789822010Z,2025-07-17T16:13:19.789656689Z,10,2,1108,A,A,10,13.850000000,100,339642033,165321,282644322,13.31,10,1,13.28,1,2,13.27,20,2,13.26,198,2,13.14,1,1,13.13,100,1,13.12,200,2,13.11,100,1,13.10,100,1,13.04,2,1,13.40,0,-10,13.46,0,-2,13.47,0,-2,13.48,0,-1,13.49,0,-3,13.50,0,-1,13.51,0,-1,13.53,0,-2,13.54,0,-1,13.55,0,-2,ARL,0
2025-07-17T16:13:19.863618706Z,2025-07-17T16:13:19.863452537Z,10,2,1108,C,A,10,13.570000000,15,339610637,166169,282645966,13.31,10,1,13.28,1,2,13.27,20,2,13.26,198,2,13.14,1,1,13.13,100,1,13.12,200,2,13.11,100,1,13.10,100,1,13.04,2,1,13.40,0,-10,13.46,0,-2,13.47,0,-2,13.48,0,-1,13.49,0,-3,13.50,0,-1,13.51,0,-1,13.53,0,-2,13.54,0,-1,13.55,0,-2,ARL,0
2025-07-17T16:13:19.863790083Z,2025-07-17T16:13:19.863624798Z,10,2,1108,C,A,10,13.640000000,15,339425837,165285,282646001,13.31,10,1,13.28,1,2,13.27,20,2,13.26,198,2,13.14,1,1,13.13,100,1,13.12,200,2,13.11,100,1,13.10,100,1,13.04,2,1,13.40,0,-10,13.46,0,-2,13.47,0,-2,13.48,0,-1,13.49,0,-3,13.50,0,-1,13.51,0,-1,13.53,0,-2,13.54,0,-1,13.55,0,-2,ARL,0
2025-07-17T16:13:19.863968792Z,2025-07-17T16:13:19.863803503Z,10,2,1108,A,A,10,13.580000000,96,339643285,165289,282646014,13.31,10,1,13.28,1,2,13.27,20,2,13.26,198,2,13.14,1,1,13.13,100,1,13.12,200,2,13.11,100,1,13.10,100,1,13.04,2,1,13.40,0,-10,13.46,0,-2,13.47,0,-2,13.48,0,-1,13.49,0,-3,13.50,0,-1,13.51,0,-1,13.53,0,-2,13.54,0,-1,13.55,0,-2,ARL,0
2025-07-17T16:13:24.182625011Z,2025-07-17T16:13:24.182459676Z,10,2,1108,A,A,10,13.570000000,15,339710089,165335,282694909,13.31,10,1,13.28,1,2,13.27,20,2,13.26,198,2,13.14,1,1,13.13,100,1,13.12,200,2,13.11,100,1,13.10,100,1,13.04,2,1,13.40,0,-10,13.46,0,-2,13.47,0,-2,13.48,0,-1,13.49,0,-3,13.50,0,-1,13.51,0,-1,13.53,0,-2,13.54,0,-1,13.55,0,-2,ARL,0
2025-07-17T16:13:24.182918202Z,2025-07-17T16:13:24.182753004Z,10,2,1108,C,A,10,13.580000000,96,339643285,165198,282694924,13.31,10,1,13.28,1,2,13.27,20,2,13.26,198,2,13.14,1,1,13.13,100,1,13.12,200,2,13.11,100,1,13.10,100,1,13.04,2,1,13.40,0,-10,13.46,0,-2,13.47,0,-2,13.48,0,-1,13.49,0,-3,13.50,0,-1,13.51,0,-1,13.53,0,-2,13.54,0,-1,13.55,0,-2,ARL,0
2025-07-17T16:13:24.627374514Z,2025-07-17T16:13:24.627209125Z,10,2,1108,A,A,10,14.260000000,700,339716321,165389,282700118,13.31,10,1,13.28,1,2,13.27,20,2,13.26,198,2,13.14,1,1,13.13,100,1,13.12,200,2,13.11,100,1,13.10,100,1,13.04,2,1,13.40,0,-10,13.46,0,-2,13.47,0,-2,13.48,0,-1,13.49,0,-3,13.50,0,-1,13.51,0,-1,13.53,0,-2,13.54,0,-1,13.55,0,-2,ARL,0
2025-07-17T16:13:24.627430447Z,2025-07-17T16:13:24.627265040Z,10,2,1108,C,A,10,14.680000000,700,339096897,165407,282700120,13.31,10,1,13.28,1,2,13.27,20,2,13.26,198,2,13.14,1,1,13.13,100,1,13.12,200,2,13.11,100,1,13.10,100,1,13.04,2,1,13.40,0,-10,13.46,0,-2,13.47,0,-2,13.48,0,-1,13.49,0,-3,13.50,0,-1,13.51,0,-1,13.53,0,-2,13.54,0,-1,13.55,0,-2,ARL,0
2025-07-17T16:13:25.962717944Z,2025-07-17T16:13:25.962552288Z,10,2,1108,C,A,10,14.570000000,100,339203693,165656,282719507,13.31,10,1,13.28,1,2,13.27,20,2,13.26,198,2,13.14,1,1,13.13,100,1,13.12,200,2,13.11,100,1,13.10,100,1,13.04,2,1,13.40,0,-10,13.46,0,-2,13.47,0,-2,13.48,0,-1,13.49,0,-3,13.50,0,-1,13.51,0,-1,13.53,0,-2,13.54,0,-1,13.55,0,-2,ARL,0
2025-07-17T16:13:25.962717944Z,2025-07-17T16:13:25.962552288Z,10,2,1108,A,A,10,14.460000000,100,339739285,165656,282719507,13.31,10,1,13.28,1,2,13.27,20,2,13.26,198,2,13.14,1,1,13.13,100,1,13.12,200,2,13.11,100,1,13.10,100,1,13.04,2,1,13.40,0,-10,13.46,0,-2,13.47,0,-2,13.48,0,-1,13.49,0,-3,13.50,0,-1,13.51,0,-1,13.53,0,-2,13.54,0,-1,13.55,0,-2,ARL,0
2025-07-17T16:13:25.963209328Z,2025-07-17T16:13:25.963043858Z,10,2,1108,C,A,10,14.570000000,100,339203897,165470,282719515,13.31,10,1,13.28,1,2,13.27,20,2,13.26,198,2,13.14,1,1,13.13,100,1,13.12,200,2,13.11,100,1,13.10,100,1,13.04,2,1,13.40,0,-10,13.46,0,-2,13.47,0,-2,13.48,0,-1,13.49,0,-3,13.50,0,-1,13.51,0,-1,13.53,0,-2,13.54,0,-1,13.55,0,-2,ARL,0
2025-07-17T16:13:25.963209328Z,2025-07-17T16:13:25.963043858Z,10,2,1108,A,A,10,14.460000000,100,339739297,165470,282719515,13.31,10,1,13.28,1,2,13.27,20,2,13.26,198,2,13.14,1,1,13.13,100,1,13.12,200,2,13.11,100,1,13.10,100,1,13.04,2,1,13.40,0,-10,13.46,0,-2,13.47,0,-2,13.48,0,-1,13.49,0,-3,13.50,0,-1,13.51,0,-1,13.53,0,-2,13.54,0,-1,13.55,0,-2,ARL,0
2025-07-17T16:13:34.825229037Z,2025-07-17T16:13:34.825063658Z,10,2,1108,A,A,10,13.550000000,15,339897885,165379,282849136,13.31,10,1,13.28,1,2,13.27,20,2,13.26,198,2,13.14,1,1,13.13,100,1,13.12,200,2,13.11,100,1,13.10,100,1,13.04,2,1,13.40,0,-10,13.46,0,-2,13.47,0,-2,13.48,0,-1,13.49,0,-3,13.50,0,-1,13.51,0,-1,13.53,0,-2,13.54,0,-1,13.55,0,-2,ARL,0
2025-07-17T16:13:36.525450545Z,2025-07-17T16:13:36.525285006Z,10,2,1108,C,A,10,13.580000000,100,339641813,165539,282880671,13.31,10,1,13.28,1,2,13.27,20,2,13.26,198,2,13.14,1,1,13.13,100,1,13.12,200,2,13.11,100,1,13.10,100,1,13.04,2,1,13.40,0,-10,13.46,0,-2,13.47,0,-2,13.48,0,-1,13.49,0,-3,13.50,0,-1,13.51,0,-1,13.53,0,-2,13.54,0,-1,13.55,0,-3,ARL,0
2025-07-17T16:13:36.525450545Z,2025-07-17T16:13:36.525285006Z,10,2,1108,A,A,10,13.560000000,100,339937253,165539,282880671,13.31,10,1,13.28,1,2,13.27,20,2,13.26,198,2,13.14,1,1,13.13,100,1,13.12,200,2,13.11,100,1,13.10,100,1,13.04,2,1,13.40,0,-10,13.46,0,-2,13.47,0,-2,13.48,0,-1,13.49,0,-3,13.50,0,-1,13.51,0,-1,13.53,0,-2,13.54,0,-1,13.55,0,-3,ARL,0
2025-07-17T16:13:36.528326337Z,2025-07-17T16:13:36.528160728Z,10,2,1108,C,A,10,17.370000000,100,339358609,165609,282880690,13.31,10,1,13.28,1,2,13.27,20,2,13.26,198,2,13.14,1,1,13.13,100,1,13.12,200,2,13.11,100,1,13.10,100,1,13.04,2,1,13.40,0,-10,13.46,0,-2,13.47,0,-2,13.48,0,-1,13.49,0,-3,13.50,0,-1,13.51,0,-1,13.53,0,-2,13.54,0,-1,13.55,0,-3,ARL,0
2025-07-17T16:13:36.528326337Z,2025-07-17T16:13:36.528160728Z,10,2,1108,A,A,10,17.230000000,100,339937293,165609,282880690,13.31,10,1,13.28,1,2,13.27,20,2,13.26,198,2,13.14,1,1,13.13,100,1,13.12,200,2,13.11,100,1,13.10,100,1,13.04,2,1,13.40,0,-10,13.46,0,-2,13.47,0,-2,13.48,0,-1,13.49,0,-3,13.50,0,-1,13.51,0,-1,13.53,0,-2,13.54,0,-1,13.55,0,-3,ARL,0
2025-07-17T16:13:40.166698198Z,2025-07-17T16:13:40.166532673Z,10,2,1108,C,A,10,13.570000000,15,339710089,165525,282934517,13.31,10,1,13.28,1,2,13.27,20,2,13.26,198,2,13.14,1,1,13.13,100,1,13.12,200,2,13.11,100,1,13.10,100,1,13.04,2,1,13.40,0,-10,13.46,0,-2,13.47,0,-2,13.48,0,-1,13.49,0,-3,13.50,0,-1,13.51,0,-1,13.53,0,-2,13.54,0,-1,13.55,0,-3,ARL,0
2025-07-17T16:13:41.168681977Z,2025-07-17T16:13:41.168516592Z,10,2,1108,A,A,10,13.530000000,15,340027925,165385,282947373,13.31,10,1,13.28,1,2,13.27,20,2,13.26,198,2,13.14,1,1,13.13,100,1,13.12,200,2,13.11,100,1,13.10,100,1,13.04,2,1,13.40,0,-10,13.46,0,-2,13.47,0,-2,13.48,0,-1,13.49,0,-3,13.50,0,-1,13.51,0,-1,13.53,0,-2,13.54,0,-1,13.55,0,-3,ARL,0
2025-07-17T16:13:41.810648775Z,2025-07-17T16:13:41.810482971Z,10,2,1108,C,A,10,13.560000000,100,339937253,165804,282959674,13.31,10,1,13.28,1,2,13.27,20,2,13.26,198,2,13.14,1,1,13.13,100,1,13.12,200,2,13.11,100,1,13.10,100,1,13.04,2,1,13.40,0,-10,13.46,0,-2,13.47,0,-2,13.48,0,-1,13.49,0,-3,13.50,0,-1,13.51,0,-1,13.53,0,-3,13.54,0,-1,13.55,0,-3,ARL,0
2025-07-17T16:13:41.810648775Z,2025-07-17T16:13:41.810482971Z,10,2,1108,A,A,10,13.540000000,100,340046965,165804,282959674,13.31,10,1,13.28,1,2,13.27,20,2,13.26,198,2,13.14,1,1,13.13,100,1,13.12,200,2,13.11,100,1,13.10,100,1,13.04,2,1,13.40,0,-10,13.46,0,-2,13.47,0,-2,13.48,0,-1,13.49,0,-3,13.50,0,-1,13.51,0,-1,13.53,0,-3,13.54,0,-1,13.55,0,-3,ARL,0
2025-07-17T16:13:41.811397213Z,2025-07-17T16:13:41.811231743Z,10,2,1108,C,A,10,14.630000000,100,339641865,165470,282959705,13.31,10,1,13.28,1,2,13.27,20,2,13.26,198,2,13.14,1,1,13.13,100,1,13.12,200,2,13.11,100,1,13.10,100,1,13.04,2,1,13.40,0,-10,13.46,0,-2,13.47,0,-2,13.48,0,-1,13.49,0,-3,13.50,0,-1,13.51,0,-1,13.53,0,-3,13.54,0,-2,13.55,0,-3,ARL,0
2025-07-17T16:13:41.811397213Z,2025-07-17T16:13:41.811231743Z,10,2,1108,A,A,10,14.590000000,100,340047001,165470,282959705,13.31,10,1,13.28,1,2,13.27,20,2,13.26,198,2,13.14,1,1,13.13,100,1,13.12,200,2,13.11,100,1,13.10,100,1,13.04,2,1,13.40,0,-10,13.46,0,-2,13.47,0,-2,13.48,0,-1,13.49,0,-3,13.50,0,-1,13.51,0,-1,13.53,0,-3,13.54,0,-2,13.55,0,-3,ARL,0
2025-07-17T16:13:41.846549822Z,2025-07-17T16:13:41.846384162Z,10,2,1108,C,A,10,15.730000000,100,339359077,165660,282960440,13.31,10,1,13.28,1,2,13.27,20,2,13.26,198,2,13.14,1,1,13.13,100,1,13.12,200,2,13.11,100,1,13.10,100,1,13.04,2,1,13.40,0,-10,13.46,0,-2,13.47,0,-2,13.48,0,-1,13.49,0,-3,13.50,0,-1,13.51,0,-1,13.53,0,-3,13.54,0,-2,13.55,0,-3,ARL,0
2025-07-17T16:13:41.846549822Z,2025-07-17T16:13:41.846384162Z,10,2,1108,A,A,10,15.580000000,100,340047805,165660,282960440,13.31,10,1,13.28,1,2,13.27,20,2,13.26,198,2,13.14,1,1,13.13,100,1,13.12,200,2,13.11,100,1,13.10,100,1,13.04,2,1,13.40,0,-10,13.46,0,-2,13.47,0,-2,13.48,0,-1,13.49,0,-3,13.50,0,-1,13.51,0,-1,13.53,0,-3,13.54,0,-2,13.55,0,-3,ARL,0
2025-07-17T16:13:53.138391930Z,2025-07-17T16:13:53.138226660Z,10,2,1108,C,A,10,13.530000000,15,340027925,165270,283090735,13.31,10,1,13.28,1,2,13.27,20,2,13.26,198,2,13.14,1,1,13.13,100,1,13.12,200,2,13.11,100,1,13.10,100,1,13.04,2,1,13.40,0,-10,13.46,0,-2,13.47,0,-2,13.48,0,-1,13.49,0,-3,13.50,0,-1,13.51,0,-1,13.53,0,-3,13.54,0,-2,13.55,0,-3,ARL,0
2025-07-17T16:13:53.784302227Z,2025-07-17T16:13:53.784124590Z,10,2,1108,C,A,10,13.550000000,15,339897885,177637,283098338,13.31,10,1,13.28,1,2,13.27,20,2,13.26,198,2,13.14,1,1,13.13,100,1,13.12,200,2,13.11,100,1,13.10,100,1,13.04,2,1,13.40,0,-10,13.46,0,-2,13.47,0,-2,13.48,0,-1,13.49,0,-3,13.50,0,-1,13.51,0,-1,13.53,0,-3,13.54,0,-2,13.55,0,-3,ARL,0
2025-07-17T16:14:06.190866982Z,2025-07-17T16:14:06.190701389Z,10,2,1108,C,A,10,13.810000000,2,339358409,165593,283262191,13.31,10,1,13.28,1,2,13.27,20,2,13.26,198,2,13.14,1,1,13.13,100,1,13.12,200,2,13.11,100,1,13.10,100,1,13.04,2,1,13.40,0,-10,13.46,0,-2,13.47,0,-2,13.48,0,-1,13.49,0,-3,13.50,0,-1,13.51,0,-1,13.53,0,-3,13.54,0,-2,13.55,0,-3,ARL,0
2025-07-17T16:14:06.190866982Z,2025-07-17T16:14:06.190701389Z,10,2,1108,A,A,10,13.740000000,2,340449865,165593,283262191,13.31,10,1,13.28,1,2,13.27,20,2,13.26,198,2,13.14,1,1,13.13,100,1,13.12,200,2,13.11,100,1,13.10,100,1,13.04,2,1,13.40,0,-10,13.46,0,-2,13.47,0,-2,13.48,0,-1,13.49,0,-3,13.50,0,-1,13.51,0,-1,13.53,0,-3,13.54,0,-2,13.55,0,-3,ARL,0
2025-07-17T16:14:10.827419207Z,2025-07-17T16:14:10.827253317Z,10,2,1108,A,A,10,13.510000000,15,340526285,165890,283315922,13.31,10,1,13.28,1,2,13.27,20,2,13.26,198,2,13.14,1,1,13.13,100,1,13.12,200,2,13.11,100,1,13.10,100,1,13.04,2,1,13.40,0,-10,13.46,0,-2,13.47,0,-2,13.48,0,-1,13.49,0,-3,13.50,0,-1,13.51,0,-1,13.53,0,-3,13.54,0,-2,13.55,0,-3,ARL,0
2025-07-17T16:14:10.876894854Z,2025-07-17T16:14:10.876729278Z,10,2,1108,C,A,10,13.540000000,100,340046965,165576,283317356,13.31,10,1,13.28,1,2,13.27,20,2,13.26,198,2,13.14,1,1,13.13,100,1,13.12,200,2,13.11,100,1,13.10,100,1,13.04,2,1,13.40,0,-10,13.46,0,-2,13.47,0,-2,13.48,0,-1,13.49,0,-3,13.50,0,-1,13.51,0,-2,13.53,0,-3,13.54,0,-2,13.55,0,-3,ARL,0
2025-07-17T16:14:10.876894854Z,2025-07-17T16:14:10.876729278Z,10,2,1108,A,A,10,13.520000000,100,340527921,165576,283317356,13.31,10,1,13.28,1,2,13.27,20,2,13.26,198,2,13.14,1,1,13.13,100,1,13.12,200,2,13.11,100,1,13.10,100,1,13.04,2,1,13.40,0,-10,13.46,0,-2,13.47,0,-2,13.48,0,-1,13.49,0,-3,13.50,0,-1,13.51,0,-2,13.53,0,-3,13.54,0,-2,13.55,0,-3,ARL,0
2025-07-17T16:14:10.878601199Z,2025-07-17T16:14:10.878435316Z,10,2,1108,C,A,10,14.630000000,100,339358353,165883,283317367,13.31,10,1,13.28,1,2,13.27,20,2,13.26,198,2,13.14,1,1,13.13,100,1,13.12,200,2,13.11,100,1,13.10,100,1,13.04,2,1,13.40,0,-10,13.46,0,-2,13.47,0,-2,13.48,0,-1,13.49,0,-3,13.50,0,-1,13.51,0,-2,13.52,0,-1,13.53,0,-3,13.54,0,-2,ARL,0
2025-07-17T16:14:10.878601199Z,2025-07-17T16:14:10.878435316Z,10,2,1108,A,A,10,14.470000000,100,340527969,165883,283317367,13.31,10,1,13.28,1,2,13.27,20,2,13.26,198,2,13.14,1,1,13.13,100,1,13.12,200,2,13.11,100,1,13.10,100,1,13.04,2,1,13.40,0,-10,13.46,0,-2,13.47,0,-2,13.48,0,-1,13.49,0,-3,13.50,0,-1,13.51,0,-2,13.52,0,-1,13.53,0,-3,13.54,0,-2,ARL,0
2025-07-17T16:14:10.892679514Z,2025-07-17T16:14:10.892513823Z,10,2,1108,C,A,10,14.630000000,100,339359401,165691,283317451,13.31,10,1,13.28,1,2,13.27,20,2,13.26,198,2,13.14,1,1,13.13,100,1,13.12,200,2,13.11,100,1,13.10,100,1,13.04,2,1,13.40,0,-10,13.46,0,-2,13.47,0,-2,13.48,0,-1,13.49,0,-3,13.50,0,-1,13.51,0,-2,13.52,0,-1,13.53,0,-3,13.54,0,-2,ARL,0
2025-07-17T16:14:10.892679514Z,2025-07-17T16:14:10.892513823Z,10,2,1108,A,A,10,14.470000000,100,340528121,165691,283317451,13.31,10,1,13.28,1,2,13.27,20,2,13.26,198,2,13.14,1,1,13.13,100,1,13.12,200,2,13.11,100,1,13.10,100,1,13.04,2,1,13.40,0,-10,13.46,0,-2,13.47,0,-2,13.48,0,-1,13.49,0,-3,13.50,0,-1,13.51,0,-2,13.52,0,-1,13.53,0,-3,13.54,0,-2,ARL,0
2025-07-17T16:14:10.985507716Z,2025-07-17T16:14:10.985342000Z,10,2,1108,C,A,10,14.460000000,100,339359421,165716,283318181,13.31,10,1,13.28,1,2,13.27,20,2,13.26,198,2,13.14,1,1,13.13,100,1,13.12,200,2,13.11,100,1,13.10,100,1,13.04,2,1,13.40,0,-10,13.46,0,-2,13.47,0,-2,13.48,0,-1,13.49,0,-3,13.50,0,-1,13.51,0,-2,13.52,0,-1,13.53,0,-3,13.54,0,-2,ARL,0
2025-07-17T16:14:10.985507716Z,2025-07-17T16:14:10.985342000Z,10,2,1108,A,A,10,14.310000000,100,340529021,165716,283318181,13.31,10,1,13.28,1,2,13.27,20,2,13.26,198,2,13.14,1,1,13.13,100,1,13.12,200,2,13.11,100,1,13.10,100,1,13.04,2,1,13.40,0,-10,13.46,0,-2,13.47,0,-2,13.48,0,-1,13.49,0,-3,13.50,0,-1,13.51,0,-2,13.52,0,-1,13.53,0,-3,13.54,0,-2,ARL,0
2025-07-17T16:14:19.528488233Z,2025-07-17T16:14:19.528322793Z,10,2,1108,A,A,10,13.490000000,15,340664453,165440,283419160,13.31,10,1,13.28,1,2,13.27,20,2,13.26,198,2,13.14,1,1,13.13,100,1,13.12,200,2,13.11,100,1,13.10,100,1,13.04,2,1,13.40,0,-10,13.46,0,-2,13.47,0,-2,13.48,0,-1,13.49,0,-3,13.50,0,-1,13.51,0,-2,13.52,0,-1,13.53,0,-3,13.54,0,-2,ARL,0
2025-07-17T16:14:21.306764970Z,2025-07-17T16:14:21.306599291Z,10,2,1108,C,A,10,13.520000000,100,340527921,165679,283454179,13.31,10,1,13.28,1,2,13.27,20,2,13.26,198,2,13.14,1,1,13.13,100,1,13.12,200,2,13.11,100,1,13.10,100,1,13.04,2,1,13.40,0,-10,13.46,0,-2,13.47,0,-2,13.48,0,-1,13.49,0,-4,13.50,0,-1,13.51,0,-2,13.52,0,-1,13.53,0,-3,13.54,0,-2,ARL,0
2025-07-17T16:14:21.306764970Z,2025-07-17T16:14:21.306599291Z,10,2,1108,A,A,10,13.500000000,100,340704401,165679,283454179,13.31,10,1,13.28,1,2,13.27,20,2,13.26,198,2,13.14,1,1,13.13,100,1,13.12,200,2,13.11,100,1,13.10,100,1,13.04,2,1,13.40,0,-10,13.46,0,-2,13.47,0,-2,13.48,0,-1,13.49,0,-4,13.50,0,-1,13.51,0,-2,13.52,0,-1,13.53,0,-3,13.54,0,-2,ARL,0
2025-07-17T16:14:21.307512009Z,2025-07-17T16:14:21.307346403Z,10,2,1108,C,A,10,14.590000000,100,340047001,165606,283454259,13.31,10,1,13.28,1,2,13.27,20,2,13.26,198,2,13.14,1,1,13.13,100,1,13.12,200,2,13.11,100,1,13.10,100,1,13.04,2,1,13.40,0,-10,13.46,0,-2,13.47,0,-2,13.48,0,-1,13.49,0,-4,13.50,0,-2,13.51,0,-2,13.52,0,-1,13.53,0,-3,13.54,0,-2,ARL,0
2025-07-17T16:14:21.307512009Z,2025-07-17T16:14:21.307346403Z,10,2,1108,A,A,10,14.550000000,100,340704465,165606,283454259,13.31,10,1,13.28,1,2,13.27,20,2,13.26,198,2,13.14,1,1,13.13,100,1,13.12,200,2,13.11,100,1,13.10,100,1,13.04,2,1,13.40,0,-10,13.46,0,-2,13.47,0,-2,13.48,0,-1,13.49,0,-4,13.50,0,-2,13.51,0,-2,13.52,0,-1,13.53,0,-3,13.54,0,-2,ARL,0
2025-07-17T16:14:21.317261991Z,2025-07-17T16:14:21.317096752Z,10,2,1108,C,A,10,13.850000000,100,339642033,165239,283454878,13.31,10,1,13.28,1,2,13.27,20,2,13.26,198,2,13.14,1,1,13.13,100,1,13.12,200,2,13.11,100,1,13.10,100,1,13.04,2,1,13.40,0,-10,13.46,0,-2,13.47,0,-2,13.48,0,-1,13.49,0,-4,13.50,0,-2,13.51,0,-2,13.52,0,-1,13.53,0,-3,13.54,0,-2,ARL,0
2025-07-17T16:14:21.317314136Z,2025-07-17T16:14:21.317148983Z,10,2,1108,A,A,10,13.770000000,100,340705133,165153,283454882,13.31,10,1,13.28,1,2,13.27,20,2,13.26,198,2,13.14,1,1,13.13,100,1,13.12,200,2,13.11,100,1,13.10,100,1,13.04,2,1,13.40,0,-10,13.46,0,-2,13.47,0,-2,13.48,0,-1,13.49,0,-4,13.50,0,-2,13.51,0,-2,13.52,0,-1,13.53,0,-3,13.54,0,-2,ARL,0
2025-07-17T16:14:21.343294261Z,2025-07-17T16:14:21.343129166Z,10,2,1108,A,A,10,15.390000000,100,340706373,165095,283455758,13.31,10,1,13.28,1,2,13.27,20,2,13.26,198,2,13.14,1,1,13.13,100,1,13.12,200,2,13.11,100,1,13.10,100,1,13.04,2,1,13.40,0,-10,13.46,0,-2,13.47,0,-2,13.48,0,-1,13.49,0,-4,13.50,0,-2,13.51,0,-2,13.52,0,-1,13.53,0,-3,13.54,0,-2,ARL,0
2025-07-17T16:14:21.343307836Z,2025-07-17T16:14:21.343142096Z,10,2,1108,C,A,10,15.670000000,100,339202065,165740,283455759,13.31,10,1,13.28,1,2,13.27,20,2,13.26,198,2,13.14,1,1,13.13,100,1,13.12,200,2,13.11,100,1,13.10,100,1,13.04,2,1,13.40,0,-10,13.46,0,-2,13.47,0,-2,13.48,0,-1,13.49,0,-4,13.50,0,-2,13.51,0,-2,13.52,0,-1,13.53,0,-3,13.54,0,-2,ARL,0
2025-07-17T16:14:36.523553349Z,2025-07-17T16:14:36.523382949Z,10,2,1108,C,A,10,13.490000000,15,340664453,170400,283655411,13.31,10,1,13.28,1,2,13.27,20,2,13.26,198,2,13.14,1,1,13.13,100,1,13.12,200,2,13.11,100,1,13.10,100,1,13.04,2,1,13.40,0,-10,13.46,0,-2,13.47,0,-2,13.48,0,-1,13.49,0,-4,13.50,0,-2,13.51,0,-2,13.52,0,-1,13.53,0,-3,13.54,0,-2,ARL,0
2025-07-17T16:14:36.523730500Z,2025-07-17T16:14:36.523564373Z,10,2,1108,C,A,10,13.510000000,15,340526285,166127,283655455,13.31,10,1,13.28,1,2,13.27,20,2,13.26,198,2,13.14,1,1,13.13,100,1,13.12,200,2,13.11,100,1,13.10,100,1,13.04,2,1,13.40,0,-10,13.46,0,-2,13.47,0,-2,13.48,0,-1,13.49,0,-4,13.50,0,-2,13.51,0,-2,13.52,0,-1,13.53,0,-3,13.54,0,-2,ARL,0
2025-07-17T16:14:36.523862340Z,2025-07-17T16:14:36.523696080Z,10,2,1108,A,A,10,13.500000000,99,340971661,166260,283655477,13.31,10,1,13.28,1,2,13.27,20,2,13.26,198,2,13.14,1,1,13.13,100,1,13.12,200,2,13.11,100,1,13.10,100,1,13.04,2,1,13.40,0,-10,13.46,0,-2,13.47,0,-2,13.48,0,-1,13.49,0,-4,13.50,0,-2,13.51,0,-2,13.52,0,-1,13.53,0,-3,13.54,0,-2,ARL,0
2025-07-17T16:14:52.280593678Z,2025-07-17T16:14:52.280428336Z,10,2,1108,C,A,10,13.500000000,99,340971661,165342,283870929,13.31,10,1,13.28,1,2,13.27,20,2,13.26,198,2,13.14,1,1,13.13,100,1,13.12,200,2,13.11,100,1,13.10,100,1,13.04,2,1,13.40,0,-10,13.46,0,-2,13.47,0,-2,13.48,0,-1,13.49,0,-4,13.50,0,-3,13.51,0,-2,13.52,0,-1,13.53,0,-3,13.54,0,-2,ARL,0
2025-07-17T16:14:52.297037125Z,2025-07-17T16:14:52.296871817Z,10,2,1108,A,A,10,13.480000000,15,341248825,165308,283871393,13.31,10,1,13.28,1,2,13.27,20,2,13.26,198,2,13.14,1,1,13.13,100,1,13.12,200,2,13.11,100,1,13.10,100,1,13.04,2,1,13.40,0,-10,13.46,0,-2,13.47,0,-2,13.48,0,-1,13.49,0,-4,13.50,0,-3,13.51,0,-2,13.52,0,-1,13.53,0,-3,13.54,0,-2,ARL,0
2025-07-17T16:14:52.828721867Z,2025-07-17T16:14:52.828556785Z,10,2,1108,C,A,10,13.480000000,15,341248825,165082,283875146,13.31,10,1,13.28,1,2,13.27,20,2,13.26,198,2,13.14,1,1,13.13,100,1,13.12,200,2,13.11,100,1,13.10,100,1,13.04,2,1,13.40,0,-10,13.46,0,-2,13.47,0,-2,13.48,0,-2,13.49,0,-4,13.50,0,-3,13.51,0,-2,13.52,0,-1,13.53,0,-3,13.54,0,-2,ARL,0
2025-07-17T16:14:52.829033713Z,2025-07-17T16:14:52.828868258Z,10,2,1108,A,A,10,13.500000000,99,341253573,165455,283875150,13.31,10,1,13.28,1,2,13.27,20,2,13.26,198,2,13.14,1,1,13.13,100,1,13.12,200,2,13.11,100,1,13.10,100,1,13.04,2,1,13.40,0,-10,13.46,0,-2,13.47,0,-2,13.48,0,-2,13.49,0,-4,13.50,0,-3,13.51,0,-2,13.52,0,-1,13.53,0,-3,13.54,0,-2,ARL,0
2025-07-17T16:15:16.987369971Z,2025-07-17T16:15:16.987204735Z,10,2,1108,C,A,10,13.500000000,99,341253573,165236,284194889,13.31,10,1,13.28,1,2,13.27,20,2,13.26,198,2,13.14,1,1,13.13,100,1,13.12,200,2,13.11,100,1,13.10,100,1,13.04,2,1,13.40,0,-10,13.46,0,-2,13.47,0,-2,13.48,0,-2,13.49,0,-4,13.50,0,-4,13.51,0,-2,13.52,0,-1,13.53,0,-3,13.54,0,-2,ARL,0
2025-07-17T16:15:16.987414675Z,2025-07-17T16:15:16.987249289Z,10,2,1108,C,A,10,13.500000000,100,340704401,165386,284194891,13.31,10,1,13.28,1,2,13.27,20,2,13.26,198,2,13.14,1,1,13.13,100,1,13.12,200,2,13.11,100,1,13.10,100,1,13.04,2,1,13.40,0,-10,13.46,0,-2,13.47,0,-2,13.48,0,-2,13.49,0,-4,13.50,0,-4,13.51,0,-2,13.52,0,-1,13.53,0,-3,13.54,0,-2,ARL,0
2025-07-17T16:15:16.987689493Z,2025-07-17T16:15:16.987524101Z,10,2,1108,C,A,10,14.260000000,700,339716321,165392,284194901,13.31,10,1,13.28,1,2,13.27,20,2,13.26,198,2,13.14,1,1,13.13,100,1,13.12,200,2,13.11,100,1,13.10,100,1,13.04,2,1,13.40,0,-10,13.46,0,-2,13.47,0,-2,13.48,0,-2,13.49,0,-4,13.50,0,-4,13.51,0,-2,13.52,0,-1,13.53,0,-3,13.54,0,-2,ARL,0
2025-07-17T16:15:16.987744468Z,2025-07-17T16:15:16.987579177Z,10,2,1108,A,A,10,14.460000000,700,341661841,165291,284194908,13.31,10,1,13.28,1,2,13.27,20,2,13.26,198,2,13.14,1,1,13.13,100,1,13.12,200,2,13.11,100,1,13.10,100,1,13.04,2,1,13.40,0,-10,13.46,0,-2,13.47,0,-2,13.48,0,-2,13.49,0,-4,13.50,0,-4,13.51,0,-2,13.52,0,-1,13.53,0,-3,13.54,0,-2,ARL,0
2025-07-17T16:15:16.987772549Z,2025-07-17T16:15:16.987607468Z,10,2,1108,A,A,10,15.700000000,100,341661849,165081,284194910,13.31,10,1,13.28,1,2,13.27,20,2,13.26,198,2,13.14,1,1,13.13,100,1,13.12,200,2,13.11,100,1,13.10,100,1,13.04,2,1,13.40,0,-10,13.46,0,-2,13.47,0,-2,13.48,0,-2,13.49,0,-4,13.50,0,-4,13.51,0,-2,13.52,0,-1,13.53,0,-3,13.54,0,-2,ARL,0
2025-07-17T16:15:16.987786087Z,2025-07-17T16:15:16.987620573Z,10,2,1108,C,A,10,15.390000000,100,340706373,165514,284194911,13.31,10,1,13.28,1,2,13.27,20,2,13.26,198,2,13.14,1,1,13.13,100,1,13.12,200,2,13.11,100,1,13.10,100,1,13.04,2,1,13.40,0,-10,13.46,0,-2,13.47,0,-2,13.48,0,-2,13.49,0,-4,13.50,0,-4,13.51,0,-2,13.52,0,-1,13.53,0,-3,13.54,0,-2,ARL,0
2025-07-17T16:15:16.988145770Z,2025-07-17T16:15:16.987980299Z,10,2,1108,C,A,10,14.550000000,100,340704465,165471,284194935,13.31,10,1,13.28,1,2,13.27,20,2,13.26,198,2,13.14,1,1,13.13,100,1,13.12,200,2,13.11,100,1,13.10,100,1,13.04,2,1,13.40,0,-10,13.46,0,-2,13.47,0,-2,13.48,0,-2,13.49,0,-4,13.50,0,-4,13.51,0,-2,13.52,0,-1,13.53,0,-3,13.54,0,-2,ARL,0
2025-07-17T16:15:16.988145770Z,2025-07-17T16:15:16.987980299Z,10,2,1108,A,A,10,14.600000000,100,341661869,165471,284194935,13.31,10,1,13.28,1,2,13.27,20,2,13.26,198,2,13.14,1,1,13.13,100,1,13.12,200,2,13.11,100,1,13.10,100,1,13.04,2,1,13.40,0,-10,13.46,0,-2,13.47,0,-2,13.48,0,-2,13.49,0,-4,13.50,0,-4,13.51,0,-2,13.52,0,-1,13.53,0,-3,13.54,0,-2,ARL,0
2025-07-17T16:15:16.988410269Z,2025-07-17T16:15:16.988244795Z,10,2,1108,C,A,10,14.470000000,100,340527969,165474,284194952,13.31,10,1,13.28,1,2,13.27,20,2,13.26,198,2,13.14,1,1,13.13,100,1,13.12,200,2,13.11,100,1,13.10,100,1,13.04,2,1,13.40,0,-10,13.46,0,-2,13.47,0,-2,13.48,0,-2,13.49,0,-4,13.50,0,-4,13.51,0,-2,13.52,0,-1,13.53,0,-3,13.54,0,-2,ARL,0
2025-07-17T16:15:16.988410269Z,2025-07-17T16:15:16.988244795Z,10,2,1108,A,A,10,14.740000000,100,341661877,165474,284194952,13.31,10,1,13.28,1,2,13.27,20,2,13.26,198,2,13.14,1,1,13.13,100,1,13.12,200,2,13.11,100,1,13.10,100,1,13.04,2,1,13.40,0,-10,13.46,0,-2,13.47,0,-2,13.48,0,-2,13.49,0,-4,13.50,0,-4,13.51,0,-2,13.52,0,-1,13.53,0,-3,13.54,0,-2,ARL,0
2025-07-17T16:15:16.989313102Z,2025-07-17T16:15:16.989147294Z,10,2,1108,C,A,10,15.580000000,100,340047805,165808,284195117,13.31,10,1,13.28,1,2,13.27,20,2,13.26,198,2,13.14,1,1,13.13,100,1,13.12,200,2,13.11,100,1,13.10,100,1,13.04,2,1,13.40,0,-10,13.46,0,-2,13.47,0,-2,13.48,0,-2,13.49,0,-4,13.50,0,-4,13.51,0,-2,13.52,0,-1,13.53,0,-3,13.54,0,-2,ARL,0
2025-07-17T16:15:16.989313102Z,2025-07-17T16:15:16.989147294Z,10,2,1108,A,A,10,15.840000000,100,341661893,165808,284195117,13.31,10,1,13.28,1,2,13.27,20,2,13.26,198,2,13.14,1,1,13.13,100,1,13.12,200,2,13.11,100,1,13.10,100,1,13.04,2,1,13.40,0,-10,13.46,0,-2,13.47,0,-2,13.48,0,-2,13.49,0,-4,13.50,0,-4,13.51,0,-2,13.52,0,-1,13.53,0,-3,13.54,0,-2,ARL,0
2025-07-17T16:15:16.989763697Z,2025-07-17T16:15:16.989598095Z,10,2,1108,C,A,10,17.230000000,100,339937293,165602,284195176,13.31,10,1,13.28,1,2,13.27,20,2,13.26,198,2,13.14,1,1,13.13,100,1,13.12,200,2,13.11,100,1,13.10,100,1,13.04,2,1,13.40,0,-10,13.46,0,-2,13.47,0,-2,13.48,0,-2,13.49,0,-4,13.50,0,-4,13.51,0,-2,13.52,0,-1,13.53,0,-3,13.54,0,-2,ARL,0
2025-07-17T16:15:16.989763697Z,2025-07-17T16:15:16.989598095Z,10,2,1108,A,A,10,17.490000000,100,341661901,165602,284195176,13.31,10,1,13.28,1,2,13.27,20,2,13.26,198,2,13.14,1,1,13.13,100,1,13.12,200,2,13.11,100,1,13.10,100,1,13.04,2,1,13.40,0,-10,13.46,0,-2,13.47,0,-2,13.48,0,-2,13.49,0,-4,13.50,0,-4,13.51,0,-2,13.52,0,-1,13.53,0,-3,13.54,0,-2,ARL,0
2025-07-17T16:15:16.989886697Z,2025-07-17T16:15:16.989720957Z,10,2,1108,C,A,10,14.470000000,100,340528121,165740,284195185,13.31,10,1,13.28,1,2,13.27,20,2,13.26,198,2,13.14,1,1,13.13,100,1,13.12,200,2,13.11,100,1,13.10,100,1,13.04,2,1,13.40,0,-10,13.46,0,-2,13.47,0,-2,13.48,0,-2,13.49,0,-4,13.50,0,-4,13.51,0,-2,13.52,0,-1,13.53,0,-3,13.54,0,-2,ARL,0
2025-07-17T16:15:16.989886697Z,2025-07-17T16:15:16.989720957Z,10,2,1108,A,A,10,14.740000000,100,341661905,165740,284195185,13.31,10,1,13.28,1,2,13.27,20,2,13.26,198,2,13.14,1,1,13.13,100,1,13.12,200,2,13.11,100,1,13.10,100,1,13.04,2,1,13.40,0,-10,13.46,0,-2,13.47,0,-2,13.48,0,-2,13.49,0,-4,13.50,0,-4,13.51,0,-2,13.52,0,-1,13.53,0,-3,13.54,0,-2,ARL,0
2025-07-17T16:15:16.992804347Z,2025-07-17T16:15:16.992638952Z,10,2,1108,C,A,10,14.310000000,100,340529021,165395,284195309,13.31,10,1,13.28,1,2,13.27,20,2,13.26,198,2,13.14,1,1,13.13,100,1,13.12,200,2,13.11,100,1,13.10,100,1,13.04,2,1,13.40,0,-10,13.46,0,-2,13.47,0,-2,13.48,0,-2,13.49,0,-4,13.50,0,-4,13.51,0,-2,13.52,0,-1,13.53,0,-3,13.54,0,-2,ARL,0
2025-07-17T16:15:16.992941967Z,2025-07-17T16:15:16.992776612Z,10,2,1108,A,A,10,14.560000000,100,341661985,165355,284195310,13.31,10,1,13.28,1,2,13.27,20,2,13.26,198,2,13.14,1,1,13.13,100,1,13.12,200,2,13.11,100,1,13.10,100,1,13.04,2,1,13.40,0,-10,13.46,0,-2,13.47,0,-2,13.48,0,-2,13.49,0,-4,13.50,0,-4,13.51,0,-2,13.52,0,-1,13.53,0,-3,13.54,0,-2,ARL,0
2025-07-17T16:15:17.000588174Z,2025-07-17T16:15:17.000422944Z,10,2,1108,C,A,10,13.770000000,100,340705133,165230,284195454,13.31,10,1,13.28,1,2,13.27,20,2,13.26,198,2,13.14,1,1,13.13,100,1,13.12,200,2,13.11,100,1,13.10,100,1,13.04,2,1,13.40,0,-10,13.46,0,-2,13.47,0,-2,13.48,0,-2,13.49,0,-4,13.50,0,-4,13.51,0,-2,13.52,0,-1,13.53,0,-3,13.54,0,-2,ARL,0
2025-07-17T16:15:17.000621056Z,2025-07-17T16:15:17.000456046Z,10,2,1108,C,A,10,14.460000000,700,341661841,165010,284195456,13.31,10,1,13.28,1,2,13.27,20,2,13.26,198,2,13.14,1,1,13.13,100,1,13.12,200,2,13.11,100,1,13.10,100,1,13.04,2,1,13.40,0,-10,13.46,0,-2,13.47,0,-2,13.48,0,-2,13.49,0,-4,13.50,0,-4,13.51,0,-2,13.52,0,-1,13.53,0,-3,13.54,0,-2,ARL,0
2025-07-17T16:15:17.000640033Z,2025-07-17T16:15:17.000474862Z,10,2,1108,A,A,10,14.050000000,100,341662085,165171,284195458,13.31,10,1,13.28,1,2,13.27,20,2,13.26,198,2,13.14,1,1,13.13,100,1,13.12,200,2,13.11,100,1,13.10,100,1,13.04,2,1,13.40,0,-10,13.46,0,-2,13.47,0,-2,13.48,0,-2,13.49,0,-4,13.50,0,-4,13.51,0,-2,13.52,0,-1,13.53,0,-3,13.54,0,-2,ARL,0
2025-07-17T16:15:17.001323406Z,2025-07-17T16:15:17.001158038Z,10,2,1108,C,A,10,14.280000000,100,339358333,165368,284195476,13.31,10,1,13.28,1,2,13.27,20,2,13.26,198,2,13.14,1,1,13.13,100,1,13.12,200,2,13.11,100,1,13.10,100,1,13.04,2,1,13.40,0,-10,13.46,0,-2,13.47,0,-2,13.48,0,-2,13.49,0,-4,13.50,0,-4,13.51,0,-2,13.52,0,-1,13.53,0,-3,13.54,0,-2,ARL,0
2025-07-17T16:15:17.001687312Z,2025-07-17T16:15:17.001522171Z,10,2,1108,A,A,10,14.600000000,100,341662113,165141,284195477,13.31,10,1,13.28,1,2,13.27,20,2,13.26,198,2,13.14,1,1,13.13,100,1,13.12,200,2,13.11,100,1,13.10,100,1,13.04,2,1,13.40,0,-10,13.46,0,-2,13.47,0,-2,13.48,0,-2,13.49,0,-4,13.50,0,-4,13.51,0,-2,13.52,0,-1,13.53,0,-3,13.54,0,-2,ARL,0
2025-07-17T16:15:17.002229963Z,2025-07-17T16:15:17.002064284Z,10,2,1108,C,A,10,14.740000000,100,341661905,165679,284195479,13.31,10,1,13.28,1,2,13.27,20,2,13.26,198,2,13.14,1,1,13.13,100,1,13.12,200,2,13.11,100,1,13.10,100,1,13.04,2,1,13.40,0,-10,13.46,0,-2,13.47,0,-2,13.48,0,-2,13.49,0,-4,13.50,0,-4,13.51,0,-2,13.52,0,-1,13.53,0,-3,13.54,0,-2,ARL,0
2025-07-17T16:15:17.002229963Z,2025-07-17T16:15:17.002064284Z,10,2,1108,A,A,10,14.960000000,100,341662117,165679,284195479,13.31,10,1,13.28,1,2,13.27,20,2,13.26,198,2,13.14,1,1,13.13,100,1,13.12,200,2,13.11,100,1,13.10,100,1,13.04,2,1,13.40,0,-10,13.46,0,-2,13.47,0,-2,13.48,0,-2,13.49,0,-4,13.50,0,-4,13.51,0,-2,13.52,0,-1,13.53,0,-3,13.54,0,-2,ARL,0
2025-07-17T16:15:17.002790290Z,2025-07-17T16:15:17.002625119Z,10,2,1108,C,A,10,17.490000000,100,341661901,165171,284195482,13.31,10,1,13.28,1,2,13.27,20,2,13.26,198,2,13.14,1,1,13.13,100,1,13.12,200,2,13.11,100,1,13.10,100,1,13.04,2,1,13.40,0,-10,13.46,0,-2,13.47,0,-2,13.48,0,-2,13.49,0,-4,13.50,0,-4,13.51,0,-2,13.52,0,-1,13.53,0,-3,13.54,0,-2,ARL,0
2025-07-17T16:15:17.002790290Z,2025-07-17T16:15:17.002625119Z,10,2,1108,A,A,10,17.760000000,100,341662125,165171,284195482,13.31,10,1,13.28,1,2,13.27,20,2,13.26,198,2,13.14,1,1,13.13,100,1,13.12,200,2,13.11,100,1,13.10,100,1,13.04,2,1,13.40,0,-10,13.46,0,-2,13.47,0,-2,13.48,0,-2,13.49,0,-4,13.50,0,-4,13.51,0,-2,13.52,0,-1,13.53,0,-3,13.54,0,-2,ARL,0
2025-07-17T16:15:17.003246802Z,2025-07-17T16:15:17.003081581Z,10,2,1108,C,A,10,14.740000000,100,341661877,165221,284195486,13.31,10,1,13.28,1,2,13.27,20,2,13.26,198,2,13.14,1,1,13.13,100,1,13.12,200,2,13.11,100,1,13.10,100,1,13.04,2,1,13.40,0,-10,13.46,0,-2,13.47,0,-2,13.48,0,-2,13.49,0,-4,13.50,0,-4,13.51,0,-2,13.52,0,-1,13.53,0,-3,13.54,0,-2,ARL,0
2025-07-17T16:15:17.003246802Z,2025-07-17T16:15:17.003081581Z,10,2,1108,A,A,10,14.960000000,100,341662133,165221,284195486,13.31,10,1,13.28,1,2,13.27,20,2,13.26,198,2,13.14,1,1,13.13,100,1,13.12,200,2,13.11,100,1,13.10,100,1,13.04,2,1,13.40,0,-10,13.46,0,-2,13.47,0,-2,13.48,0,-2,13.49,0,-4,13.50,0,-4,13.51,0,-2,13.52,0,-1,13.53,0,-3,13.54,0,-2,ARL,0
2025-07-17T16:15:17.003381863Z,2025-07-17T16:15:17.003216492Z,10,2,1108,C,A,10,15.840000000,100,341661893,165371,284195487,13.31,10,1,13.28,1,2,13.27,20,2,13.26,198,2,13.14,1,1,13.13,100,1,13.12,200,2,13.11,100,1,13.10,100,1,13.04,2,1,13.40,0,-10,13.46,0,-2,13.47,0,-2,13.48,0,-2,13.49,0,-4,13.50,0,-4,13.51,0,-2,13.52,0,-1,13.53,0,-3,13.54,0,-2,ARL,0
2025-07-17T16:15:17.003381863Z,2025-07-17T16:15:17.003216492Z,10,2,1108,A,A,10,16.080000000,100,341662137,165371,284195487,13.31,10,1,13.28,1,2,13.27,20,2,13.26,198,2,13.14,1,1,13.13,100,1,13.12,200,2,13.11,100,1,13.10,100,1,13.04,2,1,13.40,0,-10,13.46,0,-2,13.47,0,-2,13.48,0,-2,13.49,0,-4,13.50,0,-4,13.51,0,-2,13.52,0,-1,13.53,0,-3,13.54,0,-2,ARL,0
2025-07-17T16:15:17.003874553Z,2025-07-17T16:15:17.003708485Z,10,2,1108,C,A,10,15.040000000,100,339358349,166068,284195498,13.31,10,1,13.28,1,2,13.27,20,2,13.26,198,2,13.14,1,1,13.13,100,1,13.12,200,2,13.11,100,1,13.10,100,1,13.04,2,1,13.40,0,-10,13.46,0,-2,13.47,0,-2,13.48,0,-2,13.49,0,-4,13.50,0,-4,13.51,0,-2,13.52,0,-1,13.53,0,-3,13.54,0,-2,ARL,0
2025-07-17T16:15:17.003874553Z,2025-07-17T16:15:17.003708485Z,10,2,1108,A,A,10,15.380000000,100,341662145,166068,284195498,13.31,10,1,13.28,1,2,13.27,20,2,13.26,198,2,13.14,1,1,13.13,100,1,13.12,200,2,13.11,100,1,13.10,100,1,13.04,2,1,13.40,0,-10,13.46,0,-2,13.47,0,-2,13.48,0,-2,13.49,0,-4,13.50,0,-4,13.51,0,-2,13.52,0,-1,13.53,0,-3,13.54,0,-2,ARL,0
2025-07-17T16:15:17.003883470Z,2025-07-17T16:15:17.003717832Z,10,2,1108,C,A,10,15.040000000,100,339359357,165638,284195499,13.31,10,1,13.28,1,2,13.27,20,2,13.26,198,2,13.14,1,1,13.13,100,1,13.12,200,2,13.11,100,1,13.10,100,1,13.04,2,1,13.40,0,-10,13.46,0,-2,13.47,0,-2,13.48,0,-2,13.49,0,-4,13.50,0,-4,13.51,0,-2,13.52,0,-1,13.53,0,-3,13.54,0,-2,ARL,0
2025-07-17T16:15:17.003883470Z,2025-07-17T16:15:17.003717832Z,10,2,1108,A,A,10,15.380000000,100,341662149,165638,284195499,13.31,10,1,13.28,1,2,13.27,20,2,13.26,198,2,13.14,1,1,13.13,100,1,13.12,200,2,13.11,100,1,13.10,100,1,13.04,2,1,13.40,0,-10,13.46,0,-2,13.47,0,-2,13.48,0,-2,13.49,0,-4,13.50,0,-4,13.51,0,-2,13.52,0,-1,13.53,0,-3,13.54,0,-2,ARL,0
2025-07-17T16:15:17.019567564Z,2025-07-17T16:15:17.019402521Z,10,2,1108,C,A,10,14.050000000,100,341662085,165043,284195602,13.31,10,1,13.28,1,2,13.27,20,2,13.26,198,2,13.14,1,1,13.13,100,1,13.12,200,2,13.11,100,1,13.10,100,1,13.04,2,1,13.40,0,-10,13.46,0,-2,13.47,0,-2,13.48,0,-2,13.49,0,-4,13.50,0,-4,13.51,0,-2,13.52,0,-1,13.53,0,-3,13.54,0,-2,ARL,0
2025-07-17T16:15:17.019617602Z,2025-07-17T16:15:17.019452245Z,10,2,1108,A,A,10,14.260000000,100,341662313,165357,284195603,13.31,10,1,13.28,1,2,13.27,20,2,13.26,198,2,13.14,1,1,13.13,100,1,13.12,200,2,13.11,100,1,13.10,100,1,13.04,2,1,13.40,0,-10,13.46,0,-2,13.47,0,-2,13.48,0,-2,13.49,0,-4,13.50,0,-4,13.51,0,-2,13.52,0,-1,13.53,0,-3,13.54,0,-2,ARL,0
2025-07-17T16:15:17.037261626Z,2025-07-17T16:15:17.037096157Z,10,2,1108,C,A,10,14.600000000,100,341661869,165469,284195665,13.31,10,1,13.28,1,2,13.27,20,2,13.26,198,2,13.14,1,1,13.13,100,1,13.12,200,2,13.11,100,1,13.10,100,1,13.04,2,1,13.40,0,-10,13.46,0,-2,13.47,0,-2,13.48,0,-2,13.49,0,-4,13.50,0,-4,13.51,0,-2,13.52,0,-1,13.53,0,-3,13.54,0,-2,ARL,0
2025-07-17T16:15:17.037261626Z,2025-07-17T16:15:17.037096157Z,10,2,1108,A,A,10,15.060000000,100,341662429,165469,284195665,13.31,10,1,13.28,1,2,13.27,20,2,13.26,198,2,13.14,1,1,13.13,100,1,13.12,200,2,13.11,100,1,13.10,100,1,13.04,2,1,13.40,0,-10,13.46,0,-2,13.47,0,-2,13.48,0,-2,13.49,0,-4,13.50,0,-4,13.51,0,-2,13.52,0,-1,13.53,0,-3,13.54,0,-2,ARL,0
2025-07-17T16:15:17.049066370Z,2025-07-17T16:15:17.048901142Z,10,2,1108,A,A,10,13.750000000,100,341663101,165228,284196195,13.31,10,1,13.28,1,2,13.27,20,2,13.26,198,2,13.14,1,1,13.13,100,1,13.12,200,2,13.11,100,1,13.10,100,1,13.04,2,1,13.40,0,-10,13.46,0,-2,13.47,0,-2,13.48,0,-2,13.49,0,-4,13.50,0,-4,13.51,0,-2,13.52,0,-1,13.53,0,-3,13.54,0,-2,ARL,0
2025-07-17T16:15:17.049108554Z,2025-07-17T16:15:17.048943087Z,10,2,1108,A,A,10,14.680000000,700,341663105,165467,284196196,13.31,10,1,13.28,1,2,13.27,20,2,13.26,198,2,13.14,1,1,13.13,100,1,13.12,200,2,13.11,100,1,13.10,100,1,13.04,2,1,13.40,0,-10,13.46,0,-2,13.47,0,-2,13.48,0,-2,13.49,0,-4,13.50,0,-4,13.51,0,-2,13.52,0,-1,13.53,0,-3,13.54,0,-2,ARL,0
2025-07-17T16:15:17.050812161Z,2025-07-17T16:15:17.050646751Z,10,2,1108,C,A,10,14.960000000,100,341662133,165410,284196235,13.31,10,1,13.28,1,2,13.27,20,2,13.26,198,2,13.14,1,1,13.13,100,1,13.12,200,2,13.11,100,1,13.10,100,1,13.04,2,1,13.40,0,-10,13.46,0,-2,13.47,0,-2,13.48,0,-2,13.49,0,-4,13.50,0,-4,13.51,0,-2,13.52,0,-1,13.53,0,-3,13.54,0,-2,ARL,0
2025-07-17T16:15:17.050812161Z,2025-07-17T16:15:17.050646751Z,10,2,1108,A,A,10,14.720000000,100,341663261,165410,284196235,13.31,10,1,13.28,1,2,13.27,20,2,13.26,198,2,13.14,1,1,13.13,100,1,13.12,200,2,13.11,100,1,13.10,100,1,13.04,2,1,13.40,0,-10,13.46,0,-2,13.47,0,-2,13.48,0,-2,13.49,0,-4,13.50,0,-4,13.51,0,-2,13.52,0,-1,13.53,0,-3,13.54,0,-2,ARL,0
2025-07-17T16:15:17.051644859Z,2025-07-17T16:15:17.051479522Z,10,2,1108,C,A,10,17.760000000,100,341662125,165337,284196242,13.31,10,1,13.28,1,2,13.27,20,2,13.26,198,2,13.14,1,1,13.13,100,1,13.12,200,2,13.11,100,1,13.10,100,1,13.04,2,1,13.40,0,-10,13.46,0,-2,13.47,0,-2,13.48,0,-2,13.49,0,-4,13.50,0,-4,13.51,0,-2,13.52,0,-1,13.53,0,-3,13.54,0,-2,ARL,0
2025-07-17T16:15:17.051644859Z,2025-07-17T16:15:17.051479522Z,10,2,1108,A,A,10,17.470000000,100,341663289,165337,284196242,13.31,10,1,13.28,1,2,13.27,20,2,13.26,198,2,13.14,1,1,13.13,100,1,13.12,200,2,13.11,100,1,13.10,100,1,13.04,2,1,13.40,0,-10,13.46,0,-2,13.47,0,-2,13.48,0,-2,13.49,0,-4,13.50,0,-4,13.51,0,-2,13.52,0,-1,13.53,0,-3,13.54,0,-2,ARL,0
2025-07-17T16:15:17.054159307Z,2025-07-17T16:15:17.053993491Z,10,2,1108,C,A,10,16.080000000,100,341662137,165816,284196273,13.31,10,1,13.28,1,2,13.27,20,2,13.26,198,2,13.14,1,1,13.13,100,1,13.12,200,2,13.11,100,1,13.10,100,1,13.04,2,1,13.40,0,-10,13.46,0,-2,13.47,0,-2,13.48,0,-2,13.49,0,-4,13.50,0,-4,13.51,0,-2,13.52,0,-1,13.53,0,-3,13.54,0,-2,ARL,0
2025-07-17T16:15:17.054159307Z,2025-07-17T16:15:17.053993491Z,10,2,1108,A,A,10,15.820000000,100,341663317,165816,284196273,13.31,10,1,13.28,1,2,13.27,20,2,13.26,198,2,13.14,1,1,13.13,100,1,13.12,200,2,13.11,100,1,13.10,100,1,13.04,2,1,13.40,0,-10,13.46,0,-2,13.47,0,-2,13.48,0,-2,13.49,0,-4,13.50,0,-4,13.51,0,-2,13.52,0,-1,13.53,0,-3,13.54,0,-2,ARL,0
2025-07-17T16:15:17.059504149Z,2025-07-17T16:15:17.059338704Z,10,2,1108,C,A,10,14.260000000,100,341662313,165445,284196314,13.31,10,1,13.28,1,2,13.27,20,2,13.26,198,2,13.14,1,1,13.13,100,1,13.12,200,2,13.11,100,1,13.10,100,1,13.04,2,1,13.40,0,-10,13.46,0,-2,13.47,0,-2,13.48,0,-2,13.49,0,-4,13.50,0,-4,13.51,0,-2,13.52,0,-1,13.53,0,-3,13.54,0,-2,ARL,0
2025-07-17T16:15:17.059552653Z,2025-07-17T16:15:17.059387360Z,10,2,1108,A,A,10,14.030000000,100,341663401,165293,284196315,13.31,10,1,13.28,1,2,13.27,20,2,13.26,198,2,13.14,1,1,13.13,100,1,13.12,200,2,13.11,100,1,13.10,100,1,13.04,2,1,13.40,0,-10,13.46,0,-2,13.47,0,-2,13.48,0,-2,13.49,0,-4,13.50,0,-4,13.51,0,-2,13.52,0,-1,13.53,0,-3,13.54,0,-2,ARL,0
2025-07-17T16:15:17.084101480Z,2025-07-17T16:15:17.083936164Z,10,2,1108,C,A,10,14.960000000,100,341662117,165316,284196410,13.31,10,1,13.28,1,2,13.27,20,2,13.26,198,2,13.14,1,1,13.13,100,1,13.12,200,2,13.11,100,1,13.10,100,1,13.04,2,1,13.40,0,-10,13.46,0,-2,13.47,0,-2,13.48,0,-2,13.49,0,-4,13.50,0,-4,13.51,0,-2,13.52,0,-1,13.53,0,-3,13.54,0,-2,ARL,0
2025-07-17T16:15:17.084101480Z,2025-07-17T16:15:17.083936164Z,10,2,1108,A,A,10,14.720000000,100,341663737,165316,284196410,13.31,10,1,13.28,1,2,13.27,20,2,13.26,198,2,13.14,1,1,13.13,100,1,13.12,200,2,13.11,100,1,13.10,100,1,13.04,2,1,13.40,0,-10,13.46,0,-2,13.47,0,-2,13.48,0,-2,13.49,0,-4,13.50,0,-4,13.51,0,-2,13.52,0,-1,13.53,0,-3,13.54,0,-2,ARL,0
2025-07-17T16:15:17.087853488Z,2025-07-17T16:15:17.087688271Z,10,2,1108,C,A,10,15.060000000,100,341662429,165217,284196429,13.31,10,1,13.28,1,2,13.27,20,2,13.26,198,2,13.14,1,1,13.13,100,1,13.12,200,2,13.11,100,1,13.10,100,1,13.04,2,1,13.40,0,-10,13.46,0,-2,13.47,0,-2,13.48,0,-2,13.49,0,-4,13.50,0,-4,13.51,0,-2,13.52,0,-1,13.53,0,-3,13.54,0,-2,ARL,0
2025-07-17T16:15:17.087853488Z,2025-07-17T16:15:17.087688271Z,10,2,1108,A,A,10,14.820000000,100,341663749,165217,284196429,13.31,10,1,13.28,1,2,13.27,20,2,13.26,198,2,13.14,1,1,13.13,100,1,13.12,200,2,13.11,100,1,13.10,100,1,13.04,2,1,13.40,0,-10,13.46,0,-2,13.47,0,-2,13.48,0,-2,13.49,0,-4,13.50,0,-4,13.51,0,-2,13.52,0,-1,13.53,0,-3,13.54,0,-2,ARL,0
2025-07-17T16:15:17.643818240Z,2025-07-17T16:15:17.643653020Z,10,2,1108,C,A,10,14.600000000,100,341662113,165220,284202090,13.31,10,1,13.28,1,2,13.27,20,2,13.26,198,2,13.14,1,1,13.13,100,1,13.12,200,2,13.11,100,1,13.10,100,1,13.04,2,1,13.40,0,-10,13.46,0,-2,13.47,0,-2,13.48,0,-2,13.49,0,-4,13.50,0,-4,13.51,0,-2,13.52,0,-1,13.53,0,-3,13.54,0,-2,ARL,0
2025-07-17T16:15:17.644168944Z,2025-07-17T16:15:17.644003726Z,10,2,1108,A,A,10,14.360000000,100,341671053,165218,284202091,13.31,10,1,13.28,1,2,13.27,20,2,13.26,198,2,13.14,1,1,13.13,100,1,13.12,200,2,13.11,100,1,13.10,100,1,13.04,2,1,13.40,0,-10,13.46,0,-2,13.47,0,-2,13.48,0,-2,13.49,0,-4,13.50,0,-4,13.51,0,-2,13.52,0,-1,13.53,0,-3,13.54,0,-2,ARL,0
2025-07-17T16:15:35.999140348Z,2025-07-17T16:15:35.998974923Z,10,2,1108,C,B,10,12.360000000,100,336572057,165425,284480502,13.31,10,1,13.28,1,2,13.27,20,2,13.26,198,2,13.14,1,1,13.13,100,1,13.12,200,2,13.11,100,1,13.10,100,1,13.04,2,1,13.40,0,-10,13.46,0,-2,13.47,0,-2,13.48,0,-2,13.49,0,-4,13.50,0,-4,13.51,0,-2,13.52,0,-1,13.53,0,-3,13.54,0,-2,ARL,0
2025-07-17T16:15:35.999140348Z,2025-07-17T16:15:35.998974923Z,10,2,1108,A,B,10,12.220000000,100,342029561,165425,284480502,13.31,10,1,13.28,1,2,13.27,20,2,13.26,198,2,13.14,1,1,13.13,100,1,13.12,200,2,13.11,100,1,13.10,100,1,13.04,2,1,13.40,0,-10,13.46,0,-2,13.47,0,-2,13.48,0,-2,13.49,0,-4,13.50,0,-4,13.51,0,-2,13.52,0,-1,13.53,0,-3,13.54,0,-2,ARL,0
2025-07-17T16:15:35.999762137Z,2025-07-17T16:15:35.999596382Z,10,2,1108,C,B,10,12.360000000,100,336572069,165755,284480519,13.31,10,1,13.28,1,2,13.27,20,2,13.26,198,2,13.14,1,1,13.13,100,1,13.12,200,2,13.11,100,1,13.10,100,1,13.04,2,1,13.40,0,-10,13.46,0,-2,13.47,0,-2,13.48,0,-2,13.49,0,-4,13.50,0,-4,13.51,0,-2,13.52,0,-1,13.53,0,-3,13.54,0,-2,ARL,0
2025-07-17T16:15:35.999762137Z,2025-07-17T16:15:35.999596382Z,10,2,1108,A,B,10,12.220000000,100,342029581,165755,284480519,13.31,10,1,13.28,1,2,13.27,20,2,13.26,198,2,13.14,1,1,13.13,100,1,13.12,200,2,13.11,100,1,13.10,100,1,13.04,2,1,13.40,0,-10,13.46,0,-2,13.47,0,-2,13.48,0,-2,13.49,0,-4,13.50,0,-4,13.51,0,-2,13.52,0,-1,13.53,0,-3,13.54,0,-2,ARL,0
2025-07-17T16:16:30.787448429Z,2025-07-17T16:16:30.787282866Z,10,2,1108,C,B,10,12.960000000,2,339356397,165563,285308466,13.31,10,1,13.28,1,2,13.27,20,2,13.26,198,2,13.14,1,1,13.13,100,1,13.12,200,2,13.11,100,1,13.10,100,1,13.04,2,1,13.40,0,-10,13.46,0,-2,13.47,0,-2,13.48,0,-2,13.49,0,-4,13.50,0,-4,13.51,0,-2,13.52,0,-1,13.53,0,-3,13.54,0,-2,ARL,0
2025-07-17T16:16:30.787448429Z,2025-07-17T16:16:30.787282866Z,10,2,1108,A,B,10,13.030000000,2,343084165,165563,285308466,13.31,10,1,13.28,1,2,13.27,20,2,13.26,198,2,13.14,1,1,13.13,100,1,13.12,200,2,13.11,100,1,13.10,100,1,13.04,2,1,13.40,0,-10,13.46,0,-2,13.47,0,-2,13.48,0,-2,13.49,0,-4,13.50,0,-4,13.51,0,-2,13.52,0,-1,13.53,0,-3,13.54,0,-2,ARL,0
2025-07-17T16:17:22.832948558Z,2025-07-17T16:17:22.832783132Z,10,2,1108,A,A,10,13.470000000,15,344211173,165426,286207282,13.31,10,1,13.28,1,2,13.27,20,2,13.26,198,2,13.14,1,1,13.13,100,1,13.12,200,2,13.11,100,1,13.10,100,1,13.04,2,1,13.40,0,-10,13.46,0,-2,13.47,0,-2,13.48,0,-2,13.49,0,-4,13.50,0,-4,13.51,0,-2,13.52,0,-1,13.53,0,-3,13.54,0,-2,ARL,0
2025-07-17T16:17:23.620456421Z,2025-07-17T16:17:23.620290881Z,10,2,1108,C,A,10,13.750000000,100,341663101,165540,286219821,13.31,10,1,13.28,1,2,13.27,20,2,13.26,198,2,13.14,1,1,13.13,100,1,13.12,200,2,13.11,100,1,13.10,100,1,13.04,2,1,13.40,0,-10,13.46,0,-2,13.47,0,-3,13.48,0,-2,13.49,0,-4,13.50,0,-4,13.51,0,-2,13.52,0,-1,13.53,0,-3,13.54,0,-2,ARL,0
2025-07-17T16:17:23.620456421Z,2025-07-17T16:17:23.620290881Z,10,2,1108,A,A,10,13.480000000,100,344225341,165540,286219821,13.31,10,1,13.28,1,2,13.27,20,2,13.26,198,2,13.14,1,1,13.13,100,1,13.12,200,2,13.11,100,1,13.10,100,1,13.04,2,1,13.40,0,-10,13.46,0,-2,13.47,0,-3,13.48,0,-2,13.49,0,-4,13.50,0,-4,13.51,0,-2,13.52,0,-1,13.53,0,-3,13.54,0,-2,ARL,0
2025-07-17T16:17:23.621199578Z,2025-07-17T16:17:23.621034171Z,10,2,1108,C,A,10,14.360000000,100,341671053,165407,286219868,13.31,10,1,13.28,1,2,13.27,20,2,13.26,198,2,13.14,1,1,13.13,100,1,13.12,200,2,13.11,100,1,13.10,100,1,13.04,2,1,13.40,0,-10,13.46,0,-2,13.47,0,-3,13.48,0,-3,13.49,0,-4,13.50,0,-4,13.51,0,-2,13.52,0,-1,13.53,0,-3,13.54,0,-2,ARL,0
2025-07-17T16:17:23.621205573Z,2025-07-17T16:17:23.621040069Z,10,2,1108,C,A,10,14.820000000,100,341663749,165504,286219869,13.31,10,1,13.28,1,2,13.27,20,2,13.26,198,2,13.14,1,1,13.13,100,1,13.12,200,2,13.11,100,1,13.10,100,1,13.04,2,1,13.40,0,-10,13.46,0,-2,13.47,0,-3,13.48,0,-3,13.49,0,-4,13.50,0,-4,13.51,0,-2,13.52,0,-1,13.53,0,-3,13.54,0,-2,ARL,0
2025-07-17T16:17:23.621205573Z,2025-07-17T16:17:23.621040069Z,10,2,1108,A,A,10,14.530000000,100,344225385,165504,286219869,13.31,10,1,13.28,1,2,13.27,20,2,13.26,198,2,13.14,1,1,13.13,100,1,13.12,200,2,13.11,100,1,13.10,100,1,13.04,2,1,13.40,0,-10,13.46,0,-2,13.47,0,-3,13.48,0,-3,13.49,0,-4,13.50,0,-4,13.51,0,-2,13.52,0,-1,13.53,0,-3,13.54,0,-2,ARL,0
2025-07-17T16:17:23.621387062Z,2025-07-17T16:17:23.621221535Z,10,2,1108,C,A,10,15.820000000,100,341663317,165527,286219879,13.31,10,1,13.28,1,2,13.27,20,2,13.26,198,2,13.14,1,1,13.13,100,1,13.12,200,2,13.11,100,1,13.10,100,1,13.04,2,1,13.40,0,-10,13.46,0,-2,13.47,0,-3,13.48,0,-3,13.49,0,-4,13.50,0,-4,13.51,0,-2,13.52,0,-1,13.53,0,-3,13.54,0,-2,ARL,0
2025-07-17T16:17:23.621387062Z,2025-07-17T16:17:23.621221535Z,10,2,1108,A,A,10,15.510000000,100,344225393,165527,286219879,13.31,10,1,13.28,1,2,13.27,20,2,13.26,198,2,13.14,1,1,13.13,100,1,13.12,200,2,13.11,100,1,13.10,100,1,13.04,2,1,13.40,0,-10,13.46,0,-2,13.47,0,-3,13.48,0,-3,13.49,0,-4,13.50,0,-4,13.51,0,-2,13.52,0,-1,13.53,0,-3,13.54,0,-2,ARL,0
2025-07-17T16:17:23.621555609Z,2025-07-17T16:17:23.621389325Z,10,2,1108,A,A,10,14.080000000,100,344225397,166284,286219881,13.31,10,1,13.28,1,2,13.27,20,2,13.26,198,2,13.14,1,1,13.13,100,1,13.12,200,2,13.11,100,1,13.10,100,1,13.04,2,1,13.40,0,-10,13.46,0,-2,13.47,0,-3,13.48,0,-3,13.49,0,-4,13.50,0,-4,13.51,0,-2,13.52,0,-1,13.53,0,-3,13.54,0,-2,ARL,0
2025-07-17T16:17:23.621978089Z,2025-07-17T16:17:23.621812403Z,10,2,1108,C,A,10,15.380000000,100,341662145,165686,286219887,13.31,10,1,13.28,1,2,13.27,20,2,13.26,198,2,13.14,1,1,13.13,100,1,13.12,200,2,13.11,100,1,13.10,100,1,13.04,2,1,13.40,0,-10,13.46,0,-2,13.47,0,-3,13.48,0,-3,13.49,0,-4,13.50,0,-4,13.51,0,-2,13.52,0,-1,13.53,0,-3,13.54,0,-2,ARL,0
2025-07-17T16:17:23.621978089Z,2025-07-17T16:17:23.621812403Z,10,2,1108,A,A,10,14.830000000,100,344225405,165686,286219887,13.31,10,1,13.28,1,2,13.27,20,2,13.26,198,2,13.14,1,1,13.13,100,1,13.12,200,2,13.11,100,1,13.10,100,1,13.04,2,1,13.40,0,-10,13.46,0,-2,13.47,0,-3,13.48,0,-3,13.49,0,-4,13.50,0,-4,13.51,0,-2,13.52,0,-1,13.53,0,-3,13.54,0,-2,ARL,0
2025-07-17T16:17:23.622834183Z,2025-07-17T16:17:23.622668656Z,10,2,1108,C,A,10,14.720000000,100,341663261,165527,286219894,13.31,10,1,13.28,1,2,13.27,20,2,13.26,198,2,13.14,1,1,13.13,100,1,13.12,200,2,13.11,100,1,13.10,100,1,13.04,2,1,13.40,0,-10,13.46,0,-2,13.47,0,-3,13.48,0,-3,13.49,0,-4,13.50,0,-4,13.51,0,-2,13.52,0,-1,13.53,0,-3,13.54,0,-2,ARL,0
2025-07-17T16:17:23.622834183Z,2025-07-17T16:17:23.622668656Z,10,2,1108,A,A,10,14.430000000,100,344225449,165527,286219894,13.31,10,1,13.28,1,2,13.27,20,2,13.26,198,2,13.14,1,1,13.13,100,1,13.12,200,2,13.11,100,1,13.10,100,1,13.04,2,1,13.40,0,-10,13.46,0,-2,13.47,0,-3,13.48,0,-3,13.49,0,-4,13.50,0,-4,13.51,0,-2,13.52,0,-1,13.53,0,-3,13.54,0,-2,ARL,0
2025-07-17T16:17:23.623011421Z,2025-07-17T16:17:23.622845856Z,10,2,1108,C,A,10,14.560000000,100,341661985,165565,286219895,13.31,10,1,13.28,1,2,13.27,20,2,13.26,198,2,13.14,1,1,13.13,100,1,13.12,200,2,13.11,100,1,13.10,100,1,13.04,2,1,13.40,0,-10,13.46,0,-2,13.47,0,-3,13.48,0,-3,13.49,0,-4,13.50,0,-4,13.51,0,-2,13.52,0,-1,13.53,0,-3,13.54,0,-2,ARL,0
2025-07-17T16:17:23.623011421Z,2025-07-17T16:17:23.622845856Z,10,2,1108,A,A,10,14.270000000,100,344225453,165565,286219895,13.31,10,1,13.28,1,2,13.27,20,2,13.26,198,2,13.14,1,1,13.13,100,1,13.12,200,2,13.11,100,1,13.10,100,1,13.04,2,1,13.40,0,-10,13.46,0,-2,13.47,0,-3,13.48,0,-3,13.49,0,-4,13.50,0,-4,13.51,0,-2,13.52,0,-1,13.53,0,-3,13.54,0,-2,ARL,0
2025-07-17T16:17:23.623052802Z,2025-07-17T16:17:23.622887237Z,10,2,1108,C,A,10,17.470000000,100,341663289,165565,286219896,13.31,10,1,13.28,1,2,13.27,20,2,13.26,198,2,13.14,1,1,13.13,100,1,13.12,200,2,13.11,100,1,13.10,100,1,13.04,2,1,13.40,0,-10,13.46,0,-2,13.47,0,-3,13.48,0,-3,13.49,0,-4,13.50,0,-4,13.51,0,-2,13.52,0,-1,13.53,0,-3,13.54,0,-2,ARL,0
2025-07-17T16:17:23.623052802Z,2025-07-17T16:17:23.622887237Z,10,2,1108,A,A,10,17.120000000,100,344225457,165565,286219896,13.31,10,1,13.28,1,2,13.27,20,2,13.26,198,2,13.14,1,1,13.13,100,1,13.12,200,2,13.11,100,1,13.10,100,1,13.04,2,1,13.40,0,-10,13.46,0,-2,13.47,0,-3,13.48,0,-3,13.49,0,-4,13.50,0,-4,13.51,0,-2,13.52,0,-1,13.53,0,-3,13.54,0,-2,ARL,0
2025-07-17T16:17:23.624578699Z,2025-07-17T16:17:23.624413295Z,10,2,1108,C,A,10,15.380000000,100,341662149,165404,286219909,13.31,10,1,13.28,1,2,13.27,20,2,13.26,198,2,13.14,1,1,13.13,100,1,13.12,200,2,13.11,100,1,13.10,100,1,13.04,2,1,13.40,0,-10,13.46,0,-2,13.47,0,-3,13.48,0,-3,13.49,0,-4,13.50,0,-4,13.51,0,-2,13.52,0,-1,13.53,0,-3,13.54,0,-2,ARL,0
2025-07-17T16:17:23.624578699Z,2025-07-17T16:17:23.624413295Z,10,2,1108,A,A,10,14.830000000,100,344225485,165404,286219909,13.31,10,1,13.28,1,2,13.27,20,2,13.26,198,2,13.14,1,1,13.13,100,1,13.12,200,2,13.11,100,1,13.10,100,1,13.04,2,1,13.40,0,-10,13.46,0,-2,13.47,0,-3,13.48,0,-3,13.49,0,-4,13.50,0,-4,13.51,0,-2,13.52,0,-1,13.53,0,-3,13.54,0,-2,ARL,0
2025-07-17T16:17:23.624638111Z,2025-07-17T16:17:23.624472504Z,10,2,1108,C,A,10,14.720000000,100,341663737,165607,286219911,13.31,10,1,13.28,1,2,13.27,20,2,13.26,198,2,13.14,1,1,13.13,100,1,13.12,200,2,13.11,100,1,13.10,100,1,13.04,2,1,13.40,0,-10,13.46,0,-2,13.47,0,-3,13.48,0,-3,13.49,0,-4,13.50,0,-4,13.51,0,-2,13.52,0,-1,13.53,0,-3,13.54,0,-2,ARL,0
2025-07-17T16:17:23.624638111Z,2025-07-17T16:17:23.624472504Z,10,2,1108,A,A,10,14.430000000,100,344225489,165607,286219911,13.31,10,1,13.28,1,2,13.27,20,2,13.26,198,2,13.14,1,1,13.13,100,1,13.12,200,2,13.11,100,1,13.10,100,1,13.04,2,1,13.40,0,-10,13.46,0,-2,13.47,0,-3,13.48,0,-3,13.49,0,-4,13.50,0,-4,13.51,0,-2,13.52,0,-1,13.53,0,-3,13.54,0,-2,ARL,0
2025-07-17T16:17:23.627653611Z,2025-07-17T16:17:23.627488304Z,10,2,1108,C,A,10,14.030000000,100,341663401,165307,286219940,13.31,10,1,13.28,1,2,13.27,20,2,13.26,198,2,13.14,1,1,13.13,100,1,13.12,200,2,13.11,100,1,13.10,100,1,13.04,2,1,13.40,0,-10,13.46,0,-2,13.47,0,-3,13.48,0,-3,13.49,0,-4,13.50,0,-4,13.51,0,-2,13.52,0,-1,13.53,0,-3,13.54,0,-2,ARL,0
2025-07-17T16:17:23.627704598Z,2025-07-17T16:17:23.627539425Z,10,2,1108,A,A,10,13.750000000,100,344225533,165173,286219941,13.31,10,1,13.28,1,2,13.27,20,2,13.26,198,2,13.14,1,1,13.13,100,1,13.12,200,2,13.11,100,1,13.10,100,1,13.04,2,1,13.40,0,-10,13.46,0,-2,13.47,0,-3,13.48,0,-3,13.49,0,-4,13.50,0,-4,13.51,0,-2,13.52,0,-1,13.53,0,-3,13.54,0,-2,ARL,0
2025-07-17T16:17:23.653807815Z,2025-07-17T16:17:23.653641816Z,10,2,1108,A,A,10,15.370000000,100,344225829,165999,286220138,13.31,10,1,13.28,1,2,13.27,20,2,13.26,198,2,13.14,1,1,13.13,100,1,13.12,200,2,13.11,100,1,13.10,100,1,13.04,2,1,13.40,0,-10,13.46,0,-2,13.47,0,-3,13.48,0,-3,13.49,0,-4,13.50,0,-4,13.51,0,-2,13.52,0,-1,13.53,0,-3,13.54,0,-2,ARL,0
2025-07-17T16:17:23.653821034Z,2025-07-17T16:17:23.653655443Z,10,2,1108,C,A,10,15.700000000,100,341661849,165591,286220139,13.31,10,1,13.28,1,2,13.27,20,2,13.26,198,2,13.14,1,1,13.13,100,1,13.12,200,2,13.11,100,1,13.10,100,1,13.04,2,1,13.40,0,-10,13.46,0,-2,13.47,0,-3,13.48,0,-3,13.49,0,-4,13.50,0,-4,13.51,0,-2,13.52,0,-1,13.53,0,-3,13.54,0,-2,ARL,0
2025-07-17T16:17:24.832340976Z,2025-07-17T16:17:24.832175508Z,10,2,1108,C,A,10,13.470000000,15,344211173,165468,286237340,13.31,10,1,13.28,1,2,13.27,20,2,13.26,198,2,13.14,1,1,13.13,100,1,13.12,200,2,13.11,100,1,13.10,100,1,13.04,2,1,13.40,0,-10,13.46,0,-2,13.47,0,-3,13.48,0,-3,13.49,0,-4,13.50,0,-4,13.51,0,-2,13.52,0,-1,13.53,0,-3,13.54,0,-2,ARL,0
2025-07-17T16:17:26.823562625Z,2025-07-17T16:17:26.823396428Z,10,2,1108,C,A,10,13.480000000,100,344225341,166197,286261717,13.31,10,1,13.28,1,2,13.27,20,2,13.26,198,2,13.14,1,1,13.13,100,1,13.12,200,2,13.11,100,1,13.10,100,1,13.04,2,1,13.40,0,-10,13.46,0,-2,13.47,0,-3,13.48,0,-3,13.49,0,-4,13.50,0,-4,13.51,0,-2,13.52,0,-1,13.53,0,-3,13.54,0,-2,ARL,0
2025-07-17T16:17:26.823923686Z,2025-07-17T16:17:26.823758552Z,10,2,1108,A,A,10,15.680000000,100,344280537,165134,286261727,13.31,10,1,13.28,1,2,13.27,20,2,13.26,198,2,13.14,1,1,13.13,100,1,13.12,200,2,13.11,100,1,13.10,100,1,13.04,2,1,13.40,0,-10,13.46,0,-2,13.47,0,-3,13.48,0,-3,13.49,0,-4,13.50,0,-4,13.51,0,-2,13.52,0,-1,13.53,0,-3,13.54,0,-2,ARL,0
2025-07-17T16:17:26.823937553Z,2025-07-17T16:17:26.823771696Z,10,2,1108,C,A,10,15.370000000,100,344225829,165857,286261728,13.31,10,1,13.28,1,2,13.27,20,2,13.26,198,2,13.14,1,1,13.13,100,1,13.12,200,2,13.11,100,1,13.10,100,1,13.04,2,1,13.40,0,-10,13.46,0,-2,13.47,0,-3,13.48,0,-3,13.49,0,-4,13.50,0,-4,13.51,0,-2,13.52,0,-1,13.53,0,-3,13.54,0,-2,ARL,0
2025-07-17T16:17:26.824304510Z,2025-07-17T16:17:26.824137854Z,10,2,1108,C,A,10,14.530000000,100,344225385,166656,286261743,13.31,10,1,13.28,1,2,13.27,20,2,13.26,198,2,13.14,1,1,13.13,100,1,13.12,200,2,13.11,100,1,13.10,100,1,13.04,2,1,13.40,0,-10,13.46,0,-2,13.47,0,-3,13.48,0,-3,13.49,0,-4,13.50,0,-4,13.51,0,-2,13.52,0,-1,13.53,0,-3,13.54,0,-2,ARL,0
2025-07-17T16:17:26.824304510Z,2025-07-17T16:17:26.824137854Z,10,2,1108,A,A,10,14.580000000,100,344280577,166656,286261743,13.31,10,1,13.28,1,2,13.27,20,2,13.26,198,2,13.14,1,1,13.13,100,1,13.12,200,2,13.11,100,1,13.10,100,1,13.04,2,1,13.40,0,-10,13.46,0,-2,13.47,0,-3,13.48,0,-3,13.49,0,-4,13.50,0,-4,13.51,0,-2,13.52,0,-1,13.53,0,-3,13.54,0,-2,ARL,0
2025-07-17T16:17:26.824304510Z,2025-07-17T16:17:26.824138799Z,10,2,1108,C,A,10,14.080000000,100,344225397,165711,286261744,13.31,10,1,13.28,1,2,13.27,20,2,13.26,198,2,13.14,1,1,13.13,100,1,13.12,200,2,13.11,100,1,13.10,100,1,13.04,2,1,13.40,0,-10,13.46,0,-2,13.47,0,-3,13.48,0,-3,13.49,0,-4,13.50,0,-4,13.51,0,-2,13.52,0,-1,13.53,0,-3,13.54,0,-2,ARL,0
2025-07-17T16:17:26.824657956Z,2025-07-17T16:17:26.824492765Z,10,2,1108,A,A,10,14.360000000,100,344280617,165191,286261759,13.31,10,1,13.28,1,2,13.27,20,2,13.26,198,2,13.14,1,1,13.13,100,1,13.12,200,2,13.11,100,1,13.10,100,1,13.04,2,1,13.40,0,-10,13.46,0,-2,13.47,0,-3,13.48,0,-3,13.49,0,-4,13.50,0,-4,13.51,0,-2,13.52,0,-1,13.53,0,-3,13.54,0,-2,ARL,0
2025-07-17T16:17:26.825988253Z,2025-07-17T16:17:26.825823014Z,10,2,1108,C,A,10,14.270000000,100,344225453,165239,286261769,13.31,10,1,13.28,1,2,13.27,20,2,13.26,198,2,13.14,1,1,13.13,100,1,13.12,200,2,13.11,100,1,13.10,100,1,13.04,2,1,13.40,0,-10,13.46,0,-2,13.47,0,-3,13.48,0,-3,13.49,0,-4,13.50,0,-4,13.51,0,-2,13.52,0,-1,13.53,0,-3,13.54,0,-2,ARL,0
2025-07-17T16:17:26.826051208Z,2025-07-17T16:17:26.825885765Z,10,2,1108,C,A,10,14.430000000,100,344225449,165443,286261770,13.31,10,1,13.28,1,2,13.27,20,2,13.26,198,2,13.14,1,1,13.13,100,1,13.12,200,2,13.11,100,1,13.10,100,1,13.04,2,1,13.40,0,-10,13.46,0,-2,13.47,0,-3,13.48,0,-3,13.49,0,-4,13.50,0,-4,13.51,0,-2,13.52,0,-1,13.53,0,-3,13.54,0,-2,ARL,0
2025-07-17T16:17:26.826051208Z,2025-07-17T16:17:26.825885765Z,10,2,1108,A,A,10,14.720000000,100,344280641,165443,286261770,13.31,10,1,13.28,1,2,13.27,20,2,13.26,198,2,13.14,1,1,13.13,100,1,13.12,200,2,13.11,100,1,13.10,100,1,13.04,2,1,13.40,0,-10,13.46,0,-2,13.47,0,-3,13.48,0,-3,13.49,0,-4,13.50,0,-4,13.51,0,-2,13.52,0,-1,13.53,0,-3,13.54,0,-2,ARL,0
2025-07-17T16:17:26.826159189Z,2025-07-17T16:17:26.825993909Z,10,2,1108,A,A,10,14.540000000,100,344280645,165280,286261771,13.31,10,1,13.28,1,2,13.27,20,2,13.26,198,2,13.14,1,1,13.13,100,1,13.12,200,2,13.11,100,1,13.10,100,1,13.04,2,1,13.40,0,-10,13.46,0,-2,13.47,0,-3,13.48,0,-3,13.49,0,-4,13.50,0,-4,13.51,0,-2,13.52,0,-1,13.53,0,-3,13.54,0,-2,ARL,0
2025-07-17T16:17:26.826294122Z,2025-07-17T16:17:26.826128663Z,10,2,1108,C,A,10,14.830000000,100,344225405,165459,286261775,13.31,10,1,13.28,1,2,13.27,20,2,13.26,198,2,13.14,1,1,13.13,100,1,13.12,200,2,13.11,100,1,13.10,100,1,13.04,2,1,13.40,0,-10,13.46,0,-2,13.47,0,-3,13.48,0,-3,13.49,0,-4,13.50,0,-4,13.51,0,-2,13.52,0,-1,13.53,0,-3,13.54,0,-2,ARL,0
2025-07-17T16:17:26.826294122Z,2025-07-17T16:17:26.826128663Z,10,2,1108,A,A,10,15.130000000,100,344280653,165459,286261775,13.31,10,1,13.28,1,2,13.27,20,2,13.26,198,2,13.14,1,1,13.13,100,1,13.12,200,2,13.11,100,1,13.10,100,1,13.04,2,1,13.40,0,-10,13.46,0,-2,13.47,0,-3,13.48,0,-3,13.49,0,-4,13.50,0,-4,13.51,0,-2,13.52,0,-1,13.53,0,-3,13.54,0,-2,ARL,0
2025-07-17T16:17:26.828538841Z,2025-07-17T16:17:26.828373551Z,10,2,1108,C,A,10,13.750000000,100,344225533,165290,286261785,13.31,10,1,13.28,1,2,13.27,20,2,13.26,198,2,13.14,1,1,13.13,100,1,13.12,200,2,13.11,100,1,13.10,100,1,13.04,2,1,13.40,0,-10,13.46,0,-2,13.47,0,-3,13.48,0,-3,13.49,0,-4,13.50,0,-4,13.51,0,-2,13.52,0,-1,13.53,0,-3,13.54,0,-2,ARL,0
2025-07-17T16:17:26.828589142Z,2025-07-17T16:17:26.828423432Z,10,2,1108,A,A,10,14.030000000,100,344280689,165710,286261786,13.31,10,1,13.28,1,2,13.27,20,2,13.26,198,2,13.14,1,1,13.13,100,1,13.12,200,2,13.11,100,1,13.10,100,1,13.04,2,1,13.40,0,-10,13.46,0,-2,13.47,0,-3,13.48,0,-3,13.49,0,-4,13.50,0,-4,13.51,0,-2,13.52,0,-1,13.53,0,-3,13.54,0,-2,ARL,0
2025-07-17T16:17:26.828846606Z,2025-07-17T16:17:26.828681062Z,10,2,1108,C,A,10,13.740000000,2,340449865,165544,286261788,13.31,10,1,13.28,1,2,13.27,20,2,13.26,198,2,13.14,1,1,13.13,100,1,13.12,200,2,13.11,100,1,13.10,100,1,13.04,2,1,13.40,0,-10,13.46,0,-2,13.47,0,-3,13.48,0,-3,13.49,0,-4,13.50,0,-4,13.51,0,-2,13.52,0,-1,13.53,0,-3,13.54,0,-2,ARL,0
2025-07-17T16:17:26.828846606Z,2025-07-17T16:17:26.828681062Z,10,2,1108,A,A,10,13.970000000,2,344280721,165544,286261788,13.31,10,1,13.28,1,2,13.27,20,2,13.26,198,2,13.14,1,1,13.13,100,1,13.12,200,2,13.11,100,1,13.10,100,1,13.04,2,1,13.40,0,-10,13.46,0,-2,13.47,0,-3,13.48,0,-3,13.49,0,-4,13.50,0,-4,13.51,0,-2,13.52,0,-1,13.53,0,-3,13.54,0,-2,ARL,0
2025-07-17T16:17:26.830066702Z,2025-07-17T16:17:26.829901530Z,10,2,1108,C,A,10,14.720000000,100,344280641,165172,286262023,13.31,10,1,13.28,1,2,13.27,20,2,13.26,198,2,13.14,1,1,13.13,100,1,13.12,200,2,13.11,100,1,13.10,100,1,13.04,2,1,13.40,0,-10,13.46,0,-2,13.47,0,-3,13.48,0,-3,13.49,0,-4,13.50,0,-4,13.51,0,-2,13.52,0,-1,13.53,0,-3,13.54,0,-2,ARL,0
2025-07-17T16:17:26.830066702Z,2025-07-17T16:17:26.829901530Z,10,2,1108,A,A,10,14.960000000,100,344280825,165172,286262023,13.31,10,1,13.28,1,2,13.27,20,2,13.26,198,2,13.14,1,1,13.13,100,1,13.12,200,2,13.11,100,1,13.10,100,1,13.04,2,1,13.40,0,-10,13.46,0,-2,13.47,0,-3,13.48,0,-3,13.49,0,-4,13.50,0,-4,13.51,0,-2,13.52,0,-1,13.53,0,-3,13.54,0,-2,ARL,0
2025-07-17T16:17:26.832026257Z,2025-07-17T16:17:26.831860798Z,10,2,1108,C,A,10,17.120000000,100,344225457,165459,286262118,13.31,10,1,13.28,1,2,13.27,20,2,13.26,198,2,13.14,1,1,13.13,100,1,13.12,200,2,13.11,100,1,13.10,100,1,13.04,2,1,13.40,0,-10,13.46,0,-2,13.47,0,-3,13.48,0,-3,13.49,0,-4,13.50,0,-4,13.51,0,-2,13.52,0,-1,13.53,0,-3,13.54,0,-2,ARL,0
2025-07-17T16:17:26.832026257Z,2025-07-17T16:17:26.831860798Z,10,2,1108,A,A,10,17.760000000,100,344280917,165459,286262118,13.31,10,1,13.28,1,2,13.27,20,2,13.26,198,2,13.14,1,1,13.13,100,1,13.12,200,2,13.11,100,1,13.10,100,1,13.04,2,1,13.40,0,-10,13.46,0,-2,13.47,0,-3,13.48,0,-3,13.49,0,-4,13.50,0,-4,13.51,0,-2,13.52,0,-1,13.53,0,-3,13.54,0,-2,ARL,0
2025-07-17T16:17:26.833194882Z,2025-07-17T16:17:26.833029512Z,10,2,1108,C,A,10,15.510000000,100,344225393,165370,286262137,13.31,10,1,13.28,1,2,13.27,20,2,13.26,198,2,13.14,1,1,13.13,100,1,13.12,200,2,13.11,100,1,13.10,100,1,13.04,2,1,13.40,0,-10,13.46,0,-2,13.47,0,-3,13.48,0,-3,13.49,0,-4,13.50,0,-4,13.51,0,-2,13.52,0,-1,13.53,0,-3,13.54,0,-2,ARL,0
2025-07-17T16:17:26.833194882Z,2025-07-17T16:17:26.833029512Z,10,2,1108,A,A,10,16.080000000,100,344280941,165370,286262137,13.31,10,1,13.28,1,2,13.27,20,2,13.26,198,2,13.14,1,1,13.13,100,1,13.12,200,2,13.11,100,1,13.10,100,1,13.04,2,1,13.40,0,-10,13.46,0,-2,13.47,0,-3,13.48,0,-3,13.49,0,-4,13.50,0,-4,13.51,0,-2,13.52,0,-1,13.53,0,-3,13.54,0,-2,ARL,0
2025-07-17T16:17:26.834911649Z,2025-07-17T16:17:26.834746475Z,10,2,1108,C,A,10,14.030000000,100,344280689,165174,286262165,13.31,10,1,13.28,1,2,13.27,20,2,13.26,198,2,13.14,1,1,13.13,100,1,13.12,200,2,13.11,100,1,13.10,100,1,13.04,2,1,13.40,0,-10,13.46,0,-2,13.47,0,-3,13.48,0,-3,13.49,0,-4,13.50,0,-4,13.51,0,-2,13.52,0,-1,13.53,0,-3,13.54,0,-2,ARL,0
2025-07-17T16:17:26.834961494Z,2025-07-17T16:17:26.834796238Z,10,2,1108,A,A,10,14.250000000,100,344280953,165256,286262166,13.31,10,1,13.28,1,2,13.27,20,2,13.26,198,2,13.14,1,1,13.13,100,1,13.12,200,2,13.11,100,1,13.10,100,1,13.04,2,1,13.40,0,-10,13.46,0,-2,13.47,0,-3,13.48,0,-3,13.49,0,-4,13.50,0,-4,13.51,0,-2,13.52,0,-1,13.53,0,-3,13.54,0,-2,ARL,0
2025-07-17T16:17:26.846567340Z,2025-07-17T16:17:26.846401696Z,10,2,1108,C,A,10,14.830000000,100,344225485,165644,286262231,13.31,10,1,13.28,1,2,13.27,20,2,13.26,198,2,13.14,1,1,13.13,100,1,13.12,200,2,13.11,100,1,13.10,100,1,13.04,2,1,13.40,0,-10,13.46,0,-2,13.47,0,-3,13.48,0,-3,13.49,0,-4,13.50,0,-4,13.51,0,-2,13.52,0,-1,13.53,0,-3,13.54,0,-2,ARL,0
2025-07-17T16:17:26.846567340Z,2025-07-17T16:17:26.846401696Z,10,2,1108,A,A,10,15.380000000,100,344281229,165644,286262231,13.31,10,1,13.28,1,2,13.27,20,2,13.26,198,2,13.14,1,1,13.13,100,1,13.12,200,2,13.11,100,1,13.10,100,1,13.04,2,1,13.40,0,-10,13.46,0,-2,13.47,0,-3,13.48,0,-3,13.49,0,-4,13.50,0,-4,13.51,0,-2,13.52,0,-1,13.53,0,-3,13.54,0,-2,ARL,0
2025-07-17T16:17:26.849670659Z,2025-07-17T16:17:26.849505109Z,10,2,1108,C,A,10,14.430000000,100,344225489,165550,286262262,13.31,10,1,13.28,1,2,13.27,20,2,13.26,198,2,13.14,1,1,13.13,100,1,13.12,200,2,13.11,100,1,13.10,100,1,13.04,2,1,13.40,0,-10,13.46,0,-2,13.47,0,-3,13.48,0,-3,13.49,0,-4,13.50,0,-4,13.51,0,-2,13.52,0,-1,13.53,0,-3,13.54,0,-2,ARL,0
2025-07-17T16:17:26.849670659Z,2025-07-17T16:17:26.849505109Z,10,2,1108,A,A,10,14.960000000,100,344281257,165550,286262262,13.31,10,1,13.28,1,2,13.27,20,2,13.26,198,2,13.14,1,1,13.13,100,1,13.12,200,2,13.11,100,1,13.10,100,1,13.04,2,1,13.40,0,-10,13.46,0,-2,13.47,0,-3,13.48,0,-3,13.49,0,-4,13.50,0,-4,13.51,0,-2,13.52,0,-1,13.53,0,-3,13.54,0,-2,ARL,0
2025-07-17T16:17:26.874430238Z,2025-07-17T16:17:26.874264677Z,10,2,1108,C,A,10,14.580000000,100,344280577,165561,286262413,13.31,10,1,13.28,1,2,13.27,20,2,13.26,198,2,13.14,1,1,13.13,100,1,13.12,200,2,13.11,100,1,13.10,100,1,13.04,2,1,13.40,0,-10,13.46,0,-2,13.47,0,-3,13.48,0,-3,13.49,0,-4,13.50,0,-4,13.51,0,-2,13.52,0,-1,13.53,0,-3,13.54,0,-2,ARL,0
2025-07-17T16:17:26.874430238Z,2025-07-17T16:17:26.874264677Z,10,2,1108,A,A,10,15.050000000,100,344281457,165561,286262413,13.31,10,1,13.28,1,2,13.27,20,2,13.26,198,2,13.14,1,1,13.13,100,1,13.12,200,2,13.11,100,1,13.10,100,1,13.04,2,1,13.40,0,-10,13.46,0,-2,13.47,0,-3,13.48,0,-3,13.49,0,-4,13.50,0,-4,13.51,0,-2,13.52,0,-1,13.53,0,-3,13.54,0,-2,ARL,0
2025-07-17T16:17:27.000782790Z,2025-07-17T16:17:27.000617575Z,10,2,1108,A,A,10,13.980000000,100,344283633,165215,286264622,13.31,10,1,13.28,1,2,13.27,20,2,13.26,198,2,13.14,1,1,13.13,100,1,13.12,200,2,13.11,100,1,13.10,100,1,13.04,2,1,13.40,0,-10,13.46,0,-2,13.47,0,-3,13.48,0,-3,13.49,0,-4,13.50,0,-4,13.51,0,-2,13.52,0,-1,13.53,0,-3,13.54,0,-2,ARL,0
2025-07-17T16:17:27.204893988Z,2025-07-17T16:17:27.204728176Z,10,2,1108,C,A,10,14.220000000,100,339365193,165812,286267644,13.31,10,1,13.28,1,2,13.27,20,2,13.26,198,2,13.14,1,1,13.13,100,1,13.12,200,2,13.11,100,1,13.10,100,1,13.04,2,1,13.40,0,-10,13.46,0,-2,13.47,0,-3,13.48,0,-3,13.49,0,-4,13.50,0,-4,13.51,0,-2,13.52,0,-1,13.53,0,-3,13.54,0,-2,ARL,0
2025-07-17T16:17:27.204895267Z,2025-07-17T16:17:27.204730160Z,10,2,1108,A,A,10,14.530000000,100,344288585,165107,286267645,13.31,10,1,13.28,1,2,13.27,20,2,13.26,198,2,13.14,1,1,13.13,100,1,13.12,200,2,13.11,100,1,13.10,100,1,13.04,2,1,13.40,0,-10,13.46,0,-2,13.47,0,-3,13.48,0,-3,13.49,0,-4,13.50,0,-4,13.51,0,-2,13.52,0,-1,13.53,0,-3,13.54,0,-2,ARL,0
2025-07-17T16:17:27.381792167Z,2025-07-17T16:17:27.381626601Z,10,2,1108,A,A,10,14.810000000,100,344292849,165566,286271009,13.31,10,1,13.28,1,2,13.27,20,2,13.26,198,2,13.14,1,1,13.13,100,1,13.12,200,2,13.11,100,1,13.10,100,1,13.04,2,1,13.40,0,-10,13.46,0,-2,13.47,0,-3,13.48,0,-3,13.49,0,-4,13.50,0,-4,13.51,0,-2,13.52,0,-1,13.53,0,-3,13.54,0,-2,ARL,0
2025-07-17T16:17:27.381809823Z,2025-07-17T16:17:27.381644366Z,10,2,1108,C,A,10,14.490000000,100,339366385,165457,286271010,13.31,10,1,13.28,1,2,13.27,20,2,13.26,198,2,13.14,1,1,13.13,100,1,13.12,200,2,13.11,100,1,13.10,100,1,13.04,2,1,13.40,0,-10,13.46,0,-2,13.47,0,-3,13.48,0,-3,13.49,0,-4,13.50,0,-4,13.51,0,-2,13.52,0,-1,13.53,0,-3,13.54,0,-2,ARL,0
2025-07-17T16:17:27.443162448Z,2025-07-17T16:17:27.442997426Z,10,2,1108,C,A,10,14.360000000,100,344280617,165022,286271749,13.31,10,1,13.28,1,2,13.27,20,2,13.26,198,2,13.14,1,1,13.13,100,1,13.12,200,2,13.11,100,1,13.10,100,1,13.04,2,1,13.40,0,-10,13.46,0,-2,13.47,0,-3,13.48,0,-3,13.49,0,-4,13.50,0,-4,13.51,0,-2,13.52,0,-1,13.53,0,-3,13.54,0,-2,ARL,0
2025-07-17T16:17:27.443512590Z,2025-07-17T16:17:27.443347265Z,10,2,1108,A,A,10,14.600000000,100,344294245,165325,286271751,13.31,10,1,13.28,1,2,13.27,20,2,13.26,198,2,13.14,1,1,13.13,100,1,13.12,200,2,13.11,100,1,13.10,100,1,13.04,2,1,13.40,0,-10,13.46,0,-2,13.47,0,-3,13.48,0,-3,13.49,0,-4,13.50,0,-4,13.51,0,-2,13.52,0,-1,13.53,0,-3,13.54,0,-2,ARL,0
2025-07-17T16:17:27.829055288Z,2025-07-17T16:17:27.828890080Z,10,2,1108,C,A,10,14.540000000,100,344280645,165208,286275353,13.31,10,1,13.28,1,2,13.27,20,2,13.26,198,2,13.14,1,1,13.13,100,1,13.12,200,2,13.11,100,1,13.10,100,1,13.04,2,1,13.40,0,-10,13.46,0,-2,13.47,0,-3,13.48,0,-3,13.49,0,-4,13.50,0,-4,13.51,0,-2,13.52,0,-1,13.53,0,-3,13.54,0,-2,ARL,0
2025-07-17T16:17:27.829055288Z,2025-07-17T16:17:27.828890080Z,10,2,1108,A,A,10,14.770000000,100,344300085,165208,286275353,13.31,10,1,13.28,1,2,13.27,20,2,13.26,198,2,13.14,1,1,13.13,100,1,13.12,200,2,13.11,100,1,13.10,100,1,13.04,2,1,13.40,0,-10,13.46,0,-2,13.47,0,-3,13.48,0,-3,13.49,0,-4,13.50,0,-4,13.51,0,-2,13.52,0,-1,13.53,0,-3,13.54,0,-2,ARL,0
2025-07-17T16:17:39.514690751Z,2025-07-17T16:17:39.514525397Z,10,2,1108,A,A,10,13.470000000,15,344587533,165354,286508705,13.31,10,1,13.28,1,2,13.27,20,2,13.26,198,2,13.14,1,1,13.13,100,1,13.12,200,2,13.11,100,1,13.10,100,1,13.04,2,1,13.40,0,-10,13.46,0,-2,13.47,0,-3,13.48,0,-3,13.49,0,-4,13.50,0,-4,13.51,0,-2,13.52,0,-1,13.53,0,-3,13.54,0,-2,ARL,0
2025-07-17T16:17:39.829017289Z,2025-07-17T16:17:39.828851797Z,10,2,1108,C,A,10,14.460000000,100,339739285,165492,286513833,13.31,10,1,13.28,1,2,13.27,20,2,13.26,198,2,13.14,1,1,13.13,100,1,13.12,200,2,13.11,100,1,13.10,100,1,13.04,2,1,13.40,0,-10,13.46,0,-2,13.47,0,-4,13.48,0,-3,13.49,0,-4,13.50,0,-4,13.51,0,-2,13.52,0,-1,13.53,0,-3,13.54,0,-2,ARL,0
2025-07-17T16:17:39.829017289Z,2025-07-17T16:17:39.828851797Z,10,2,1108,A,A,10,14.350000000,100,344593405,165492,286513833,13.31,10,1,13.28,1,2,13.27,20,2,13.26,198,2,13.14,1,1,13.13,100,1,13.12,200,2,13.11,100,1,13.10,100,1,13.04,2,1,13.40,0,-10,13.46,0,-2,13.47,0,-4,13.48,0,-3,13.49,0,-4,13.50,0,-4,13.51,0,-2,13.52,0,-1,13.53,0,-3,13.54,0,-2,ARL,0
2025-07-17T16:17:39.829247357Z,2025-07-17T16:17:39.829081898Z,10,2,1108,C,A,10,14.460000000,100,339739297,165459,286513835,13.31,10,1,13.28,1,2,13.27,20,2,13.26,198,2,13.14,1,1,13.13,100,1,13.12,200,2,13.11,100,1,13.10,100,1,13.04,2,1,13.40,0,-10,13.46,0,-2,13.47,0,-4,13.48,0,-3,13.49,0,-4,13.50,0,-4,13.51,0,-2,13.52,0,-1,13.53,0,-3,13.54,0,-2,ARL,0
2025-07-17T16:17:39.829247357Z,2025-07-17T16:17:39.829081898Z,10,2,1108,A,A,10,14.350000000,100,344593409,165459,286513835,13.31,10,1,13.28,1,2,13.27,20,2,13.26,198,2,13.14,1,1,13.13,100,1,13.12,200,2,13.11,100,1,13.10,100,1,13.04,2,1,13.40,0,-10,13.46,0,-2,13.47,0,-4,13.48,0,-3,13.49,0,-4,13.50,0,-4,13.51,0,-2,13.52,0,-1,13.53,0,-3,13.54,0,-2,ARL,0
2025-07-17T16:17:40.321326768Z,2025-07-17T16:17:40.321161439Z,10,2,1108,C,A,10,13.980000000,100,344283633,165329,286524785,13.31,10,1,13.28,1,2,13.27,20,2,13.26,198,2,13.14,1,1,13.13,100,1,13.12,200,2,13.11,100,1,13.10,100,1,13.04,2,1,13.40,0,-10,13.46,0,-2,13.47,0,-4,13.48,0,-3,13.49,0,-4,13.50,0,-4,13.51,0,-2,13.52,0,-1,13.53,0,-3,13.54,0,-2,ARL,0
2025-07-17T16:17:40.321326768Z,2025-07-17T16:17:40.321161439Z,10,2,1108,A,A,10,13.480000000,100,344607833,165329,286524785,13.31,10,1,13.28,1,2,13.27,20,2,13.26,198,2,13.14,1,1,13.13,100,1,13.12,200,2,13.11,100,1,13.10,100,1,13.04,2,1,13.40,0,-10,13.46,0,-2,13.47,0,-4,13.48,0,-3,13.49,0,-4,13.50,0,-4,13.51,0,-2,13.52,0,-1,13.53,0,-3,13.54,0,-2,ARL,0
2025-07-17T16:17:40.322064038Z,2025-07-17T16:17:40.321898765Z,10,2,1108,C,A,10,14.600000000,100,344294245,165273,286524815,13.31,10,1,13.28,1,2,13.27,20,2,13.26,198,2,13.14,1,1,13.13,100,1,13.12,200,2,13.11,100,1,13.10,100,1,13.04,2,1,13.40,0,-10,13.46,0,-2,13.47,0,-4,13.48,0,-4,13.49,0,-4,13.50,0,-4,13.51,0,-2,13.52,0,-1,13.53,0,-3,13.54,0,-2,ARL,0
2025-07-17T16:17:40.322069742Z,2025-07-17T16:17:40.321903984Z,10,2,1108,C,A,10,15.050000000,100,344281457,165758,286524817,13.31,10,1,13.28,1,2,13.27,20,2,13.26,198,2,13.14,1,1,13.13,100,1,13.12,200,2,13.11,100,1,13.10,100,1,13.04,2,1,13.40,0,-10,13.46,0,-2,13.47,0,-4,13.48,0,-4,13.49,0,-4,13.50,0,-4,13.51,0,-2,13.52,0,-1,13.53,0,-3,13.54,0,-2,ARL,0
2025-07-17T16:17:40.322069742Z,2025-07-17T16:17:40.321903984Z,10,2,1108,A,A,10,14.530000000,100,344607889,165758,286524817,13.31,10,1,13.28,1,2,13.27,20,2,13.26,198,2,13.14,1,1,13.13,100,1,13.12,200,2,13.11,100,1,13.10,100,1,13.04,2,1,13.40,0,-10,13.46,0,-2,13.47,0,-4,13.48,0,-4,13.49,0,-4,13.50,0,-4,13.51,0,-2,13.52,0,-1,13.53,0,-3,13.54,0,-2,ARL,0
2025-07-17T16:17:40.322416015Z,2025-07-17T16:17:40.322250847Z,10,2,1108,A,A,10,14.080000000,100,344607893,165168,286524822,13.31,10,1,13.28,1,2,13.27,20,2,13.26,198,2,13.14,1,1,13.13,100,1,13.12,200,2,13.11,100,1,13.10,100,1,13.04,2,1,13.40,0,-10,13.46,0,-2,13.47,0,-4,13.48,0,-4,13.49,0,-4,13.50,0,-4,13.51,0,-2,13.52,0,-1,13.53,0,-3,13.54,0,-2,ARL,0
2025-07-17T16:17:40.329180897Z,2025-07-17T16:17:40.329015669Z,10,2,1108,C,A,10,14.250000000,100,344280953,165228,286524967,13.31,10,1,13.28,1,2,13.27,20,2,13.26,198,2,13.14,1,1,13.13,100,1,13.12,200,2,13.11,100,1,13.10,100,1,13.04,2,1,13.40,0,-10,13.46,0,-2,13.47,0,-4,13.48,0,-4,13.49,0,-4,13.50,0,-4,13.51,0,-2,13.52,0,-1,13.53,0,-3,13.54,0,-2,ARL,0
2025-07-17T16:17:40.329233157Z,2025-07-17T16:17:40.329067996Z,10,2,1108,A,A,10,13.750000000,100,344608193,165161,286524969,13.31,10,1,13.28,1,2,13.27,20,2,13.26,198,2,13.14,1,1,13.13,100,1,13.12,200,2,13.11,100,1,13.10,100,1,13.04,2,1,13.40,0,-10,13.46,0,-2,13.47,0,-4,13.48,0,-4,13.49,0,-4,13.50,0,-4,13.51,0,-2,13.52,0,-1,13.53,0,-3,13.54,0,-2,ARL,0
2025-07-17T16:17:40.330448099Z,2025-07-17T16:17:40.330282519Z,10,2,1108,C,A,10,15.130000000,100,344280653,165580,286524982,13.31,10,1,13.28,1,2,13.27,20,2,13.26,198,2,13.14,1,1,13.13,100,1,13.12,200,2,13.11,100,1,13.10,100,1,13.04,2,1,13.40,0,-10,13.46,0,-2,13.47,0,-4,13.48,0,-4,13.49,0,-4,13.50,0,-4,13.51,0,-2,13.52,0,-1,13.53,0,-3,13.54,0,-2,ARL,0
2025-07-17T16:17:40.330448099Z,2025-07-17T16:17:40.330282519Z,10,2,1108,A,A,10,14.830000000,100,344608205,165580,286524982,13.31,10,1,13.28,1,2,13.27,20,2,13.26,198,2,13.14,1,1,13.13,100,1,13.12,200,2,13.11,100,1,13.10,100,1,13.04,2,1,13.40,0,-10,13.46,0,-2,13.47,0,-4,13.48,0,-4,13.49,0,-4,13.50,0,-4,13.51,0,-2,13.52,0,-1,13.53,0,-3,13.54,0,-2,ARL,0
2025-07-17T16:17:40.331429414Z,2025-07-17T16:17:40.331264268Z,10,2,1108,C,A,10,14.770000000,100,344300085,165146,286524998,13.31,10,1,13.28,1,2,13.27,20,2,13.26,198,2,13.14,1,1,13.13,100,1,13.12,200,2,13.11,100,1,13.10,100,1,13.04,2,1,13.40,0,-10,13.46,0,-2,13.47,0,-4,13.48,0,-4,13.49,0,-4,13.50,0,-4,13.51,0,-2,13.52,0,-1,13.53,0,-3,13.54,0,-2,ARL,0
2025-07-17T16:17:40.331551656Z,2025-07-17T16:17:40.331386492Z,10,2,1108,A,A,10,14.270000000,100,344608225,165164,286525005,13.31,10,1,13.28,1,2,13.27,20,2,13.26,198,2,13.14,1,1,13.13,100,1,13.12,200,2,13.11,100,1,13.10,100,1,13.04,2,1,13.40,0,-10,13.46,0,-2,13.47,0,-4,13.48,0,-4,13.49,0,-4,13.50,0,-4,13.51,0,-2,13.52,0,-1,13.53,0,-3,13.54,0,-2,ARL,0
2025-07-17T16:17:40.333679181Z,2025-07-17T16:17:40.333513866Z,10,2,1108,C,A,10,14.960000000,100,344280825,165315,286525029,13.31,10,1,13.28,1,2,13.27,20,2,13.26,198,2,13.14,1,1,13.13,100,1,13.12,200,2,13.11,100,1,13.10,100,1,13.04,2,1,13.40,0,-10,13.46,0,-2,13.47,0,-4,13.48,0,-4,13.49,0,-4,13.50,0,-4,13.51,0,-2,13.52,0,-1,13.53,0,-3,13.54,0,-2,ARL,0
2025-07-17T16:17:40.333679181Z,2025-07-17T16:17:40.333513866Z,10,2,1108,A,A,10,14.430000000,100,344608253,165315,286525029,13.31,10,1,13.28,1,2,13.27,20,2,13.26,198,2,13.14,1,1,13.13,100,1,13.12,200,2,13.11,100,1,13.10,100,1,13.04,2,1,13.40,0,-10,13.46,0,-2,13.47,0,-4,13.48,0,-4,13.49,0,-4,13.50,0,-4,13.51,0,-2,13.52,0,-1,13.53,0,-3,13.54,0,-2,ARL,0
2025-07-17T16:17:40.348996221Z,2025-07-17T16:17:40.348830748Z,10,2,1108,C,A,10,17.760000000,100,344280917,165473,286525170,13.31,10,1,13.28,1,2,13.27,20,2,13.26,198,2,13.14,1,1,13.13,100,1,13.12,200,2,13.11,100,1,13.10,100,1,13.04,2,1,13.40,0,-10,13.46,0,-2,13.47,0,-4,13.48,0,-4,13.49,0,-4,13.50,0,-4,13.51,0,-2,13.52,0,-1,13.53,0,-3,13.54,0,-2,ARL,0
2025-07-17T16:17:40.348996221Z,2025-07-17T16:17:40.348830748Z,10,2,1108,A,A,10,17.120000000,100,344608637,165473,286525170,13.31,10,1,13.28,1,2,13.27,20,2,13.26,198,2,13.14,1,1,13.13,100,1,13.12,200,2,13.11,100,1,13.10,100,1,13.04,2,1,13.40,0,-10,13.46,0,-2,13.47,0,-4,13.48,0,-4,13.49,0,-4,13.50,0,-4,13.51,0,-2,13.52,0,-1,13.53,0,-3,13.54,0,-2,ARL,0
2025-07-17T16:17:40.349081921Z,2025-07-17T16:17:40.348916703Z,10,2,1108,A,A,10,15.370000000,100,344608641,165218,286525175,13.31,10,1,13.28,1,2,13.27,20,2,13.26,198,2,13.14,1,1,13.13,100,1,13.12,200,2,13.11,100,1,13.10,100,1,13.04,2,1,13.40,0,-10,13.46,0,-2,13.47,0,-4,13.48,0,-4,13.49,0,-4,13.50,0,-4,13.51,0,-2,13.52,0,-1,13.53,0,-3,13.54,0,-2,ARL,0
2025-07-17T16:17:40.349095477Z,2025-07-17T16:17:40.348930117Z,10,2,1108,C,A,10,15.680000000,100,344280537,165360,286525177,13.31,10,1,13.28,1,2,13.27,20,2,13.26,198,2,13.14,1,1,13.13,100,1,13.12,200,2,13.11,100,1,13.10,100,1,13.04,2,1,13.40,0,-10,13.46,0,-2,13.47,0,-4,13.48,0,-4,13.49,0,-4,13.50,0,-4,13.51,0,-2,13.52,0,-1,13.53,0,-3,13.54,0,-2,ARL,0
2025-07-17T16:17:40.357367234Z,2025-07-17T16:17:40.357201846Z,10,2,1108,C,A,10,16.080000000,100,344280941,165388,286525428,13.31,10,1,13.28,1,2,13.27,20,2,13.26,198,2,13.14,1,1,13.13,100,1,13.12,200,2,13.11,100,1,13.10,100,1,13.04,2,1,13.40,0,-10,13.46,0,-2,13.47,0,-4,13.48,0,-4,13.49,0,-4,13.50,0,-4,13.51,0,-2,13.52,0,-1,13.53,0,-3,13.54,0,-2,ARL,0
2025-07-17T16:17:40.357367234Z,2025-07-17T16:17:40.357201846Z,10,2,1108,A,A,10,15.510000000,100,344608797,165388,286525428,13.31,10,1,13.28,1,2,13.27,20,2,13.26,198,2,13.14,1,1,13.13,100,1,13.12,200,2,13.11,100,1,13.10,100,1,13.04,2,1,13.40,0,-10,13.46,0,-2,13.47,0,-4,13.48,0,-4,13.49,0,-4,13.50,0,-4,13.51,0,-2,13.52,0,-1,13.53,0,-3,13.54,0,-2,ARL,0
2025-07-17T16:17:40.403239477Z,2025-07-17T16:17:40.403073956Z,10,2,1108,C,A,10,15.380000000,100,344281229,165521,286526316,13.31,10,1,13.28,1,2,13.27,20,2,13.26,198,2,13.14,1,1,13.13,100,1,13.12,200,2,13.11,100,1,13.10,100,1,13.04,2,1,13.40,0,-10,13.46,0,-2,13.47,0,-4,13.48,0,-4,13.49,0,-4,13.50,0,-4,13.51,0,-2,13.52,0,-1,13.53,0,-3,13.54,0,-2,ARL,0
2025-07-17T16:17:40.403239477Z,2025-07-17T16:17:40.403073956Z,10,2,1108,A,A,10,14.830000000,100,344609897,165521,286526316,13.31,10,1,13.28,1,2,13.27,20,2,13.26,198,2,13.14,1,1,13.13,100,1,13.12,200,2,13.11,100,1,13.10,100,1,13.04,2,1,13.40,0,-10,13.46,0,-2,13.47,0,-4,13.48,0,-4,13.49,0,-4,13.50,0,-4,13.51,0,-2,13.52,0,-1,13.53,0,-3,13.54,0,-2,ARL,0
2025-07-17T16:17:40.426590567Z,2025-07-17T16:17:40.426425205Z,10,2,1108,C,A,10,14.960000000,100,344281257,165362,286526540,13.31,10,1,13.28,1,2,13.27,20,2,13.26,198,2,13.14,1,1,13.13,100,1,13.12,200,2,13.11,100,1,13.10,100,1,13.04,2,1,13.40,0,-10,13.46,0,-2,13.47,0,-4,13.48,0,-4,13.49,0,-4,13.50,0,-4,13.51,0,-2,13.52,0,-1,13.53,0,-3,13.54,0,-2,ARL,0
2025-07-17T16:17:40.426590567Z,2025-07-17T16:17:40.426425205Z,10,2,1108,A,A,10,14.430000000,100,344610073,165362,286526540,13.31,10,1,13.28,1,2,13.27,20,2,13.26,198,2,13.14,1,1,13.13,100,1,13.12,200,2,13.11,100,1,13.10,100,1,13.04,2,1,13.40,0,-10,13.46,0,-2,13.47,0,-4,13.48,0,-4,13.49,0,-4,13.50,0,-4,13.51,0,-2,13.52,0,-1,13.53,0,-3,13.54,0,-2,ARL,0
2025-07-17T16:17:40.474841118Z,2025-07-17T16:17:40.474675991Z,10,2,1108,A,A,10,14.010000000,100,344612049,165127,286527611,13.31,10,1,13.28,1,2,13.27,20,2,13.26,198,2,13.14,1,1,13.13,100,1,13.12,200,2,13.11,100,1,13.10,100,1,13.04,2,1,13.40,0,-10,13.46,0,-2,13.47,0,-4,13.48,0,-4,13.49,0,-4,13.50,0,-4,13.51,0,-2,13.52,0,-1,13.53,0,-3,13.54,0,-2,ARL,0
2025-07-17T16:17:40.474842468Z,2025-07-17T16:17:40.474677082Z,10,2,1108,C,A,10,14.530000000,100,344288585,165386,286527612,13.31,10,1,13.28,1,2,13.27,20,2,13.26,198,2,13.14,1,1,13.13,100,1,13.12,200,2,13.11,100,1,13.10,100,1,13.04,2,1,13.40,0,-10,13.46,0,-2,13.47,0,-4,13.48,0,-4,13.49,0,-4,13.50,0,-4,13.51,0,-2,13.52,0,-1,13.53,0,-3,13.54,0,-2,ARL,0
2025-07-17T16:17:40.697721205Z,2025-07-17T16:17:40.697555911Z,10,2,1108,A,A,10,14.280000000,100,344615393,165294,286530329,13.31,10,1,13.28,1,2,13.27,20,2,13.26,198,2,13.14,1,1,13.13,100,1,13.12,200,2,13.11,100,1,13.10,100,1,13.04,2,1,13.40,0,-10,13.46,0,-2,13.47,0,-4,13.48,0,-4,13.49,0,-4,13.50,0,-4,13.51,0,-2,13.52,0,-1,13.53,0,-3,13.54,0,-2,ARL,0
2025-07-17T16:17:40.697733924Z,2025-07-17T16:17:40.697568713Z,10,2,1108,C,A,10,14.810000000,100,344292849,165211,286530330,13.31,10,1,13.28,1,2,13.27,20,2,13.26,198,2,13.14,1,1,13.13,100,1,13.12,200,2,13.11,100,1,13.10,100,1,13.04,2,1,13.40,0,-10,13.46,0,-2,13.47,0,-4,13.48,0,-4,13.49,0,-4,13.50,0,-4,13.51,0,-2,13.52,0,-1,13.53,0,-3,13.54,0,-2,ARL,0
2025-07-17T16:17:41.586151161Z,2025-07-17T16:17:41.585985709Z,10,2,1108,C,A,10,13.970000000,2,344280721,165452,286543225,13.31,10,1,13.28,1,2,13.27,20,2,13.26,198,2,13.14,1,1,13.13,100,1,13.12,200,2,13.11,100,1,13.10,100,1,13.04,2,1,13.40,0,-10,13.46,0,-2,13.47,0,-4,13.48,0,-4,13.49,0,-4,13.50,0,-4,13.51,0,-2,13.52,0,-1,13.53,0,-3,13.54,0,-2,ARL,0
2025-07-17T16:17:41.586151161Z,2025-07-17T16:17:41.585985709Z,10,2,1108,A,A,10,13.870000000,2,344631921,165452,286543225,13.31,10,1,13.28,1,2,13.27,20,2,13.26,198,2,13.14,1,1,13.13,100,1,13.12,200,2,13.11,100,1,13.10,100,1,13.04,2,1,13.40,0,-10,13.46,0,-2,13.47,0,-4,13.48,0,-4,13.49,0,-4,13.50,0,-4,13.51,0,-2,13.52,0,-1,13.53,0,-3,13.54,0,-2,ARL,0
2025-07-17T16:17:42.553133650Z,2025-07-17T16:17:42.552968542Z,10,2,1108,A,A,10,13.450000000,15,344653009,165108,286561347,13.31,10,1,13.28,1,2,13.27,20,2,13.26,198,2,13.14,1,1,13.13,100,1,13.12,200,2,13.11,100,1,13.10,100,1,13.04,2,1,13.40,0,-10,13.46,0,-2,13.47,0,-4,13.48,0,-4,13.49,0,-4,13.50,0,-4,13.51,0,-2,13.52,0,-1,13.53,0,-3,13.54,0,-2,ARL,0
2025-07-17T16:17:44.014614049Z,2025-07-17T16:17:44.014448587Z,10,2,1108,C,A,10,13.480000000,100,344607833,165462,286577648,13.31,10,1,13.28,1,2,13.27,20,2,13.26,198,2,13.14,1,1,13.13,100,1,13.12,200,2,13.11,100,1,13.10,100,1,13.04,2,1,13.40,0,-10,13.45,0,-1,13.46,0,-2,13.47,0,-4,13.48,0,-4,13.49,0,-4,13.50,0,-4,13.51,0,-2,13.52,0,-1,13.53,0,-3,ARL,0
2025-07-17T16:17:44.014614049Z,2025-07-17T16:17:44.014448587Z,10,2,1108,A,A,10,13.460000000,100,344673481,165462,286577648,13.31,10,1,13.28,1,2,13.27,20,2,13.26,198,2,13.14,1,1,13.13,100,1,13.12,200,2,13.11,100,1,13.10,100,1,13.04,2,1,13.40,0,-10,13.45,0,-1,13.46,0,-2,13.47,0,-4,13.48,0,-4,13.49,0,-4,13.50,0,-4,13.51,0,-2,13.52,0,-1,13.53,0,-3,ARL,0
2025-07-17T16:17:44.014977545Z,2025-07-17T16:17:44.014812396Z,10,2,1108,A,A,10,15.680000000,100,344673501,165149,286577651,13.31,10,1,13.28,1,2,13.27,20,2,13.26,198,2,13.14,1,1,13.13,100,1,13.12,200,2,13.11,100,1,13.10,100,1,13.04,2,1,13.40,0,-10,13.45,0,-1,13.46,0,-2,13.47,0,-4,13.48,0,-4,13.49,0,-4,13.50,0,-4,13.51,0,-2,13.52,0,-1,13.53,0,-3,ARL,0
2025-07-17T16:17:44.014991037Z,2025-07-17T16:17:44.014825581Z,10,2,1108,C,A,10,15.370000000,100,344608641,165456,286577652,13.31,10,1,13.28,1,2,13.27,20,2,13.26,198,2,13.14,1,1,13.13,100,1,13.12,200,2,13.11,100,1,13.10,100,1,13.04,2,1,13.40,0,-10,13.45,0,-1,13.46,0,-2,13.47,0,-4,13.48,0,-4,13.49,0,-4,13.50,0,-4,13.51,0,-2,13.52,0,-1,13.53,0,-3,ARL,0
2025-07-17T16:17:44.042976984Z,2025-07-17T16:17:44.042811526Z,10,2,1108,A,A,10,15.350000000,100,344674517,165458,286578356,13.31,10,1,13.28,1,2,13.27,20,2,13.26,198,2,13.14,1,1,13.13,100,1,13.12,200,2,13.11,100,1,13.10,100,1,13.04,2,1,13.40,0,-10,13.45,0,-1,13.46,0,-2,13.47,0,-4,13.48,0,-4,13.49,0,-4,13.50,0,-4,13.51,0,-2,13.52,0,-1,13.53,0,-3,ARL,0
2025-07-17T16:17:44.042989197Z,2025-07-17T16:17:44.042824242Z,10,2,1108,C,A,10,15.680000000,100,344673501,164955,286578357,13.31,10,1,13.28,1,2,13.27,20,2,13.26,198,2,13.14,1,1,13.13,100,1,13.12,200,2,13.11,100,1,13.10,100,1,13.04,2,1,13.40,0,-10,13.45,0,-1,13.46,0,-2,13.47,0,-4,13.48,0,-4,13.49,0,-4,13.50,0,-4,13.51,0,-2,13.52,0,-1,13.53,0,-3,ARL,0
2025-07-17T16:17:46.828260391Z,2025-07-17T16:17:46.828095134Z,10,2,1108,A,A,10,14.180000000,700,344724301,165257,286618024,13.31,10,1,13.28,1,2,13.27,20,2,13.26,198,2,13.14,1,1,13.13,100,1,13.12,200,2,13.11,100,1,13.10,100,1,13.04,2,1,13.40,0,-10,13.45,0,-1,13.46,0,-2,13.47,0,-4,13.48,0,-4,13.49,0,-4,13.50,0,-4,13.51,0,-2,13.52,0,-1,13.53,0,-3,ARL,0
2025-07-17T16:17:46.828325564Z,2025-07-17T16:17:46.828160338Z,10,2,1108,C,A,10,14.680000000,700,341663105,165226,286618025,13.31,10,1,13.28,1,2,13.27,20,2,13.26,198,2,13.14,1,1,13.13,100,1,13.12,200,2,13.11,100,1,13.10,100,1,13.04,2,1,13.40,0,-10,13.45,0,-1,13.46,0,-2,13.47,0,-4,13.48,0,-4,13.49,0,-4,13.50,0,-4,13.51,0,-2,13.52,0,-1,13.53,0,-3,ARL,0
2025-07-17T16:17:49.387530942Z,2025-07-17T16:17:49.387365405Z,10,2,1108,C,A,10,13.870000000,2,344631921,165537,286651544,13.31,10,1,13.28,1,2,13.27,20,2,13.26,198,2,13.14,1,1,13.13,100,1,13.12,200,2,13.11,100,1,13.10,100,1,13.04,2,1,13.40,0,-10,13.45,0,-1,13.46,0,-2,13.47,0,-4,13.48,0,-4,13.49,0,-4,13.50,0,-4,13.51,0,-2,13.52,0,-1,13.53,0,-3,ARL,0
2025-07-17T16:17:49.387530942Z,2025-07-17T16:17:49.387365405Z,10,2,1108,A,A,10,13.790000000,2,344765077,165537,286651544,13.31,10,1,13.28,1,2,13.27,20,2,13.26,198,2,13.14,1,1,13.13,100,1,13.12,200,2,13.11,100,1,13.10,100,1,13.04,2,1,13.40,0,-10,13.45,0,-1,13.46,0,-2,13.47,0,-4,13.48,0,-4,13.49,0,-4,13.50,0,-4,13.51,0,-2,13.52,0,-1,13.53,0,-3,ARL,0
2025-07-17T16:17:52.834173973Z,2025-07-17T16:17:52.834008196Z,10,2,1108,C,A,10,13.470000000,15,344587533,165777,286689853,13.31,10,1,13.28,1,2,13.27,20,2,13.26,198,2,13.14,1,1,13.13,100,1,13.12,200,2,13.11,100,1,13.10,100,1,13.04,2,1,13.40,0,-10,13.45,0,-1,13.46,0,-2,13.47,0,-4,13.48,0,-4,13.49,0,-4,13.50,0,-4,13.51,0,-2,13.52,0,-1,13.53,0,-3,ARL,0
2025-07-17T16:17:58.033327053Z,2025-07-17T16:17:58.033161898Z,10,2,1108,C,A,10,13.450000000,15,344653009,165155,286753046,13.31,10,1,13.28,1,2,13.27,20,2,13.26,198,2,13.14,1,1,13.13,100,1,13.12,200,2,13.11,100,1,13.10,100,1,13.04,2,1,13.40,0,-10,13.45,0,-1,13.46,0,-2,13.47,0,-4,13.48,0,-4,13.49,0,-4,13.50,0,-4,13.51,0,-2,13.52,0,-1,13.53,0,-3,ARL,0
2025-07-17T16:17:58.036588469Z,2025-07-17T16:17:58.036423237Z,10,2,1108,C,A,10,13.460000000,100,344673481,165232,286753126,13.31,10,1,13.28,1,2,13.27,20,2,13.26,198,2,13.14,1,1,13.13,100,1,13.12,200,2,13.11,100,1,13.10,100,1,13.04,2,1,13.40,0,-10,13.45,0,-1,13.46,0,-2,13.47,0,-4,13.48,0,-4,13.49,0,-4,13.50,0,-4,13.51,0,-2,13.52,0,-1,13.53,0,-3,ARL,0
2025-07-17T16:17:58.036861922Z,2025-07-17T16:17:58.036696806Z,10,2,1108,C,A,10,14.180000000,700,344724301,165116,286753127,13.31,10,1,13.28,1,2,13.27,20,2,13.26,198,2,13.14,1,1,13.13,100,1,13.12,200,2,13.11,100,1,13.10,100,1,13.04,2,1,13.40,0,-10,13.45,0,-1,13.46,0,-2,13.47,0,-4,13.48,0,-4,13.49,0,-4,13.50,0,-4,13.51,0,-2,13.52,0,-1,13.53,0,-3,ARL,0
2025-07-17T16:17:58.036914002Z,2025-07-17T16:17:58.036748831Z,10,2,1108,A,A,10,14.440000000,700,344897921,165171,286753128,13.31,10,1,13.28,1,2,13.27,20,2,13.26,198,2,13.14,1,1,13.13,100,1,13.12,200,2,13.11,100,1,13.10,100,1,13.04,2,1,13.40,0,-10,13.45,0,-1,13.46,0,-2,13.47,0,-4,13.48,0,-4,13.49,0,-4,13.50,0,-4,13.51,0,-2,13.52,0,-1,13.53,0,-3,ARL,0
2025-07-17T16:17:58.036971455Z,2025-07-17T16:17:58.036806229Z,10,2,1108,A,A,10,15.680000000,100,344897933,165226,286753129,13.31,10,1,13.28,1,2,13.27,20,2,13.26,198,2,13.14,1,1,13.13,100,1,13.12,200,2,13.11,100,1,13.10,100,1,13.04,2,1,13.40,0,-10,13.45,0,-1,13.46,0,-2,13.47,0,-4,13.48,0,-4,13.49,0,-4,13.50,0,-4,13.51,0,-2,13.52,0,-1,13.53,0,-3,ARL,0
2025-07-17T16:17:58.036983460Z,2025-07-17T16:17:58.036818196Z,10,2,1108,C,A,10,15.350000000,100,344674517,165264,286753132,13.31,10,1,13.28,1,2,13.27,20,2,13.26,198,2,13.14,1,1,13.13,100,1,13.12,200,2,13.11,100,1,13.10,100,1,13.04,2,1,13.40,0,-10,13.45,0,-1,13.46,0,-2,13.47,0,-4,13.48,0,-4,13.49,0,-4,13.50,0,-4,13.51,0,-2,13.52,0,-1,13.53,0,-3,ARL,0
2025-07-17T16:17:58.037325671Z,2025-07-17T16:17:58.037160197Z,10,2,1108,C,A,10,14.530000000,100,344607889,165474,286753136,13.31,10,1,13.28,1,2,13.27,20,2,13.26,198,2,13.14,1,1,13.13,100,1,13.12,200,2,13.11,100,1,13.10,100,1,13.04,2,1,13.40,0,-10,13.45,0,-1,13.46,0,-2,13.47,0,-4,13.48,0,-4,13.49,0,-4,13.50,0,-4,13.51,0,-2,13.52,0,-1,13.53,0,-3,ARL,0
2025-07-17T16:17:58.037325671Z,2025-07-17T16:17:58.037160197Z,10,2,1108,A,A,10,14.820000000,100,344897945,165474,286753136,13.31,10,1,13.28,1,2,13.27,20,2,13.26,198,2,13.14,1,1,13.13,100,1,13.12,200,2,13.11,100,1,13.10,100,1,13.04,2,1,13.40,0,-10,13.45,0,-1,13.46,0,-2,13.47,0,-4,13.48,0,-4,13.49,0,-4,13.50,0,-4,13.51,0,-2,13.52,0,-1,13.53,0,-3,ARL,0
2025-07-17T16:17:58.037330946Z,2025-07-17T16:17:58.037165870Z,10,2,1108,C,A,10,14.080000000,100,344607893,165076,286753137,13.31,10,1,13.28,1,2,13.27,20,2,13.26,198,2,13.14,1,1,13.13,100,1,13.12,200,2,13.11,100,1,13.10,100,1,13.04,2,1,13.40,0,-10,13.45,0,-1,13.46,0,-2,13.47,0,-4,13.48,0,-4,13.49,0,-4,13.50,0,-4,13.51,0,-2,13.52,0,-1,13.53,0,-3,ARL,0
2025-07-17T16:17:58.037686676Z,2025-07-17T16:17:58.037521442Z,10,2,1108,A,A,10,14.360000000,100,344897953,165234,286753149,13.31,10,1,13.28,1,2,13.27,20,2,13.26,198,2,13.14,1,1,13.13,100,1,13.12,200,2,13.11,100,1,13.10,100,1,13.04,2,1,13.40,0,-10,13.45,0,-1,13.46,0,-2,13.47,0,-4,13.48,0,-4,13.49,0,-4,13.50,0,-4,13.51,0,-2,13.52,0,-1,13.53,0,-3,ARL,0
2025-07-17T16:17:58.038759735Z,2025-07-17T16:17:58.038594284Z,10,2,1108,C,A,10,14.430000000,100,344608253,165451,286753168,13.31,10,1,13.28,1,2,13.27,20,2,13.26,198,2,13.14,1,1,13.13,100,1,13.12,200,2,13.11,100,1,13.10,100,1,13.04,2,1,13.40,0,-10,13.45,0,-1,13.46,0,-2,13.47,0,-4,13.48,0,-4,13.49,0,-4,13.50,0,-4,13.51,0,-2,13.52,0,-1,13.53,0,-3,ARL,0
2025-07-17T16:17:58.038759735Z,2025-07-17T16:17:58.038594284Z,10,2,1108,A,A,10,14.720000000,100,344897989,165451,286753168,13.31,10,1,13.28,1,2,13.27,20,2,13.26,198,2,13.14,1,1,13.13,100,1,13.12,200,2,13.11,100,1,13.10,100,1,13.04,2,1,13.40,0,-10,13.45,0,-1,13.46,0,-2,13.47,0,-4,13.48,0,-4,13.49,0,-4,13.50,0,-4,13.51,0,-2,13.52,0,-1,13.53,0,-3,ARL,0
2025-07-17T16:17:58.039381900Z,2025-07-17T16:17:58.039215838Z,10,2,1108,C,A,10,14.830000000,100,344608205,166062,286753172,13.31,10,1,13.28,1,2,13.27,20,2,13.26,198,2,13.14,1,1,13.13,100,1,13.12,200,2,13.11,100,1,13.10,100,1,13.04,2,1,13.40,0,-10,13.45,0,-1,13.46,0,-2,13.47,0,-4,13.48,0,-4,13.49,0,-4,13.50,0,-4,13.51,0,-2,13.52,0,-1,13.53,0,-3,ARL,0
2025-07-17T16:17:58.039381900Z,2025-07-17T16:17:58.039215838Z,10,2,1108,A,A,10,15.130000000,100,344897997,166062,286753172,13.31,10,1,13.28,1,2,13.27,20,2,13.26,198,2,13.14,1,1,13.13,100,1,13.12,200,2,13.11,100,1,13.10,100,1,13.04,2,1,13.40,0,-10,13.45,0,-1,13.46,0,-2,13.47,0,-4,13.48,0,-4,13.49,0,-4,13.50,0,-4,13.51,0,-2,13.52,0,-1,13.53,0,-3,ARL,0
2025-07-17T16:17:58.047862207Z,2025-07-17T16:17:58.047696769Z,10,2,1108,C,A,10,17.120000000,100,344608637,165438,286753519,13.31,10,1,13.28,1,2,13.27,20,2,13.26,198,2,13.14,1,1,13.13,100,1,13.12,200,2,13.11,100,1,13.10,100,1,13.04,2,1,13.40,0,-10,13.45,0,-1,13.46,0,-2,13.47,0,-4,13.48,0,-4,13.49,0,-4,13.50,0,-4,13.51,0,-2,13.52,0,-1,13.53,0,-3,ARL,0
2025-07-17T16:17:58.047862207Z,2025-07-17T16:17:58.047696769Z,10,2,1108,A,A,10,17.470000000,100,344898485,165438,286753519,13.31,10,1,13.28,1,2,13.27,20,2,13.26,198,2,13.14,1,1,13.13,100,1,13.12,200,2,13.11,100,1,13.10,100,1,13.04,2,1,13.40,0,-10,13.45,0,-1,13.46,0,-2,13.47,0,-4,13.48,0,-4,13.49,0,-4,13.50,0,-4,13.51,0,-2,13.52,0,-1,13.53,0,-3,ARL,0
2025-07-17T16:17:58.051632876Z,2025-07-17T16:17:58.051466948Z,10,2,1108,C,A,10,15.510000000,100,344608797,165928,286753581,13.31,10,1,13.28,1,2,13.27,20,2,13.26,198,2,13.14,1,1,13.13,100,1,13.12,200,2,13.11,100,1,13.10,100,1,13.04,2,1,13.40,0,-10,13.45,0,-1,13.46,0,-2,13.47,0,-4,13.48,0,-4,13.49,0,-4,13.50,0,-4,13.51,0,-2,13.52,0,-1,13.53,0,-3,ARL,0
2025-07-17T16:17:58.051632876Z,2025-07-17T16:17:58.051466948Z,10,2,1108,A,A,10,15.820000000,100,344898677,165928,286753581,13.31,10,1,13.28,1,2,13.27,20,2,13.26,198,2,13.14,1,1,13.13,100,1,13.12,200,2,13.11,100,1,13.10,100,1,13.04,2,1,13.40,0,-10,13.45,0,-1,13.46,0,-2,13.47,0,-4,13.48,0,-4,13.49,0,-4,13.50,0,-4,13.51,0,-2,13.52,0,-1,13.53,0,-3,ARL,0
2025-07-17T16:17:58.054049362Z,2025-07-17T16:17:58.053883828Z,10,2,1108,C,A,10,13.750000000,100,344608193,165534,286753747,13.31,10,1,13.28,1,2,13.27,20,2,13.26,198,2,13.14,1,1,13.13,100,1,13.12,200,2,13.11,100,1,13.10,100,1,13.04,2,1,13.40,0,-10,13.45,0,-1,13.46,0,-2,13.47,0,-4,13.48,0,-4,13.49,0,-4,13.50,0,-4,13.51,0,-2,13.52,0,-1,13.53,0,-3,ARL,0
2025-07-17T16:17:58.054100805Z,2025-07-17T16:17:58.053934652Z,10,2,1108,C,A,10,14.440000000,700,344897921,166153,286753751,13.31,10,1,13.28,1,2,13.27,20,2,13.26,198,2,13.14,1,1,13.13,100,1,13.12,200,2,13.11,100,1,13.10,100,1,13.04,2,1,13.40,0,-10,13.45,0,-1,13.46,0,-2,13.47,0,-4,13.48,0,-4,13.49,0,-4,13.50,0,-4,13.51,0,-2,13.52,0,-1,13.53,0,-3,ARL,0
2025-07-17T16:17:58.054101429Z,2025-07-17T16:17:58.053935872Z,10,2,1108,A,A,10,14.030000000,100,344898949,165557,286753752,13.31,10,1,13.28,1,2,13.27,20,2,13.26,198,2,13.14,1,1,13.13,100,1,13.12,200,2,13.11,100,1,13.10,100,1,13.04,2,1,13.40,0,-10,13.45,0,-1,13.46,0,-2,13.47,0,-4,13.48,0,-4,13.49,0,-4,13.50,0,-4,13.51,0,-2,13.52,0,-1,13.53,0,-3,ARL,0
2025-07-17T16:17:58.056965001Z,2025-07-17T16:17:58.056799769Z,10,2,1108,C,A,10,14.720000000,100,344897989,165232,286753926,13.31,10,1,13.28,1,2,13.27,20,2,13.26,198,2,13.14,1,1,13.13,100,1,13.12,200,2,13.11,100,1,13.10,100,1,13.04,2,1,13.40,0,-10,13.45,0,-1,13.46,0,-2,13.47,0,-4,13.48,0,-4,13.49,0,-4,13.50,0,-4,13.51,0,-2,13.52,0,-1,13.53,0,-3,ARL,0
2025-07-17T16:17:58.056965001Z,2025-07-17T16:17:58.056799769Z,10,2,1108,A,A,10,14.960000000,100,344899081,165232,286753926,13.31,10,1,13.28,1,2,13.27,20,2,13.26,198,2,13.14,1,1,13.13,100,1,13.12,200,2,13.11,100,1,13.10,100,1,13.04,2,1,13.40,0,-10,13.45,0,-1,13.46,0,-2,13.47,0,-4,13.48,0,-4,13.49,0,-4,13.50,0,-4,13.51,0,-2,13.52,0,-1,13.53,0,-3,ARL,0
2025-07-17T16:17:58.057809322Z,2025-07-17T16:17:58.057644161Z,10,2,1108,C,A,10,15.820000000,100,344898677,165161,286753935,13.31,10,1,13.28,1,2,13.27,20,2,13.26,198,2,13.14,1,1,13.13,100,1,13.12,200,2,13.11,100,1,13.10,100,1,13.04,2,1,13.40,0,-10,13.45,0,-1,13.46,0,-2,13.47,0,-4,13.48,0,-4,13.49,0,-4,13.50,0,-4,13.51,0,-2,13.52,0,-1,13.53,0,-3,ARL,0
2025-07-17T16:17:58.057809322Z,2025-07-17T16:17:58.057644161Z,10,2,1108,A,A,10,16.080000000,100,344899093,165161,286753935,13.31,10,1,13.28,1,2,13.27,20,2,13.26,198,2,13.14,1,1,13.13,100,1,13.12,200,2,13.11,100,1,13.10,100,1,13.04,2,1,13.40,0,-10,13.45,0,-1,13.46,0,-2,13.47,0,-4,13.48,0,-4,13.49,0,-4,13.50,0,-4,13.51,0,-2,13.52,0,-1,13.53,0,-3,ARL,0
2025-07-17T16:17:58.061670860Z,2025-07-17T16:17:58.061505885Z,10,2,1108,C,A,10,14.030000000,100,344898949,164975,286754272,13.31,10,1,13.28,1,2,13.27,20,2,13.26,198,2,13.14,1,1,13.13,100,1,13.12,200,2,13.11,100,1,13.10,100,1,13.04,2,1,13.40,0,-10,13.45,0,-1,13.46,0,-2,13.47,0,-4,13.48,0,-4,13.49,0,-4,13.50,0,-4,13.51,0,-2,13.52,0,-1,13.53,0,-3,ARL,0
2025-07-17T16:17:58.061730836Z,2025-07-17T16:17:58.061563628Z,10,2,1108,A,A,10,14.250000000,100,344899417,167208,286754286,13.31,10,1,13.28,1,2,13.27,20,2,13.26,198,2,13.14,1,1,13.13,100,1,13.12,200,2,13.11,100,1,13.10,100,1,13.04,2,1,13.40,0,-10,13.45,0,-1,13.46,0,-2,13.47,0,-4,13.48,0,-4,13.49,0,-4,13.50,0,-4,13.51,0,-2,13.52,0,-1,13.53,0,-3,ARL,0
2025-07-17T16:17:58.062137122Z,2025-07-17T16:17:58.061971960Z,10,2,1108,C,A,10,17.470000000,100,344898485,165162,286754339,13.31,10,1,13.28,1,2,13.27,20,2,13.26,198,2,13.14,1,1,13.13,100,1,13.12,200,2,13.11,100,1,13.10,100,1,13.04,2,1,13.40,0,-10,13.45,0,-1,13.46,0,-2,13.47,0,-4,13.48,0,-4,13.49,0,-4,13.50,0,-4,13.51,0,-2,13.52,0,-1,13.53,0,-3,ARL,0
2025-07-17T16:17:58.062137122Z,2025-07-17T16:17:58.061971960Z,10,2,1108,A,A,10,17.760000000,100,344899449,165162,286754339,13.31,10,1,13.28,1,2,13.27,20,2,13.26,198,2,13.14,1,1,13.13,100,1,13.12,200,2,13.11,100,1,13.10,100,1,13.04,2,1,13.40,0,-10,13.45,0,-1,13.46,0,-2,13.47,0,-4,13.48,0,-4,13.49,0,-4,13.50,0,-4,13.51,0,-2,13.52,0,-1,13.53,0,-3,ARL,0
2025-07-17T16:17:58.086582033Z,2025-07-17T16:17:58.086415950Z,10,2,1108,C,A,10,14.270000000,100,344608225,166083,286754819,13.31,10,1,13.28,1,2,13.27,20,2,13.26,198,2,13.14,1,1,13.13,100,1,13.12,200,2,13.11,100,1,13.10,100,1,13.04,2,1,13.40,0,-10,13.45,0,-1,13.46,0,-2,13.47,0,-4,13.48,0,-4,13.49,0,-4,13.50,0,-4,13.51,0,-2,13.52,0,-1,13.53,0,-3,ARL,0
2025-07-17T16:17:58.086582033Z,2025-07-17T16:17:58.086415950Z,10,2,1108,A,A,10,14.540000000,100,344899913,166083,286754819,13.31,10,1,13.28,1,2,13.27,20,2,13.26,198,2,13.14,1,1,13.13,100,1,13.12,200,2,13.11,100,1,13.10,100,1,13.04,2,1,13.40,0,-10,13.45,0,-1,13.46,0,-2,13.47,0,-4,13.48,0,-4,13.49,0,-4,13.50,0,-4,13.51,0,-2,13.52,0,-1,13.53,0,-3,ARL,0
2025-07-17T16:17:58.087829372Z,2025-07-17T16:17:58.087663773Z,10,2,1108,C,A,10,14.820000000,100,344897945,165599,286754826,13.31,10,1,13.28,1,2,13.27,20,2,13.26,198,2,13.14,1,1,13.13,100,1,13.12,200,2,13.11,100,1,13.10,100,1,13.04,2,1,13.40,0,-10,13.45,0,-1,13.46,0,-2,13.47,0,-4,13.48,0,-4,13.49,0,-4,13.50,0,-4,13.51,0,-2,13.52,0,-1,13.53,0,-3,ARL,0
2025-07-17T16:17:58.087829372Z,2025-07-17T16:17:58.087663773Z,10,2,1108,A,A,10,15.050000000,100,344899937,165599,286754826,13.31,10,1,13.28,1,2,13.27,20,2,13.26,198,2,13.14,1,1,13.13,100,1,13.12,200,2,13.11,100,1,13.10,100,1,13.04,2,1,13.40,0,-10,13.45,0,-1,13.46,0,-2,13.47,0,-4,13.48,0,-4,13.49,0,-4,13.50,0,-4,13.51,0,-2,13.52,0,-1,13.53,0,-3,ARL,0
2025-07-17T16:17:58.113382320Z,2025-07-17T16:17:58.113216665Z,10,2,1108,C,A,10,14.830000000,100,344609897,165655,286755076,13.31,10,1,13.28,1,2,13.27,20,2,13.26,198,2,13.14,1,1,13.13,100,1,13.12,200,2,13.11,100,1,13.10,100,1,13.04,2,1,13.40,0,-10,13.45,0,-1,13.46,0,-2,13.47,0,-4,13.48,0,-4,13.49,0,-4,13.50,0,-4,13.51,0,-2,13.52,0,-1,13.53,0,-3,ARL,0
2025-07-17T16:17:58.113382320Z,2025-07-17T16:17:58.113216665Z,10,2,1108,A,A,10,15.380000000,100,344900289,165655,286755076,13.31,10,1,13.28,1,2,13.27,20,2,13.26,198,2,13.14,1,1,13.13,100,1,13.12,200,2,13.11,100,1,13.10,100,1,13.04,2,1,13.40,0,-10,13.45,0,-1,13.46,0,-2,13.47,0,-4,13.48,0,-4,13.49,0,-4,13.50,0,-4,13.51,0,-2,13.52,0,-1,13.53,0,-3,ARL,0
2025-07-17T16:17:58.145548497Z,2025-07-17T16:17:58.145382853Z,10,2,1108,C,A,10,14.430000000,100,344610073,165644,286755340,13.31,10,1,13.28,1,2,13.27,20,2,13.26,198,2,13.14,1,1,13.13,100,1,13.12,200,2,13.11,100,1,13.10,100,1,13.04,2,1,13.40,0,-10,13.45,0,-1,13.46,0,-2,13.47,0,-4,13.48,0,-4,13.49,0,-4,13.50,0,-4,13.51,0,-2,13.52,0,-1,13.53,0,-3,ARL,0
2025-07-17T16:17:58.145548497Z,2025-07-17T16:17:58.145382853Z,10,2,1108,A,A,10,14.960000000,100,344900597,165644,286755340,13.31,10,1,13.28,1,2,13.27,20,2,13.26,198,2,13.14,1,1,13.13,100,1,13.12,200,2,13.11,100,1,13.10,100,1,13.04,2,1,13.40,0,-10,13.45,0,-1,13.46,0,-2,13.47,0,-4,13.48,0,-4,13.49,0,-4,13.50,0,-4,13.51,0,-2,13.52,0,-1,13.53,0,-3,ARL,0
2025-07-17T16:17:58.173831273Z,2025-07-17T16:17:58.173665745Z,10,2,1108,A,A,10,14.810000000,100,344900925,165528,286755602,13.31,10,1,13.28,1,2,13.27,20,2,13.26,198,2,13.14,1,1,13.13,100,1,13.12,200,2,13.11,100,1,13.10,100,1,13.04,2,1,13.40,0,-10,13.45,0,-1,13.46,0,-2,13.47,0,-4,13.48,0,-4,13.49,0,-4,13.50,0,-4,13.51,0,-2,13.52,0,-1,13.53,0,-3,ARL,0
2025-07-17T16:17:58.173852767Z,2025-07-17T16:17:58.173687330Z,10,2,1108,C,A,10,14.280000000,100,344615393,165437,286755603,13.31,10,1,13.28,1,2,13.27,20,2,13.26,198,2,13.14,1,1,13.13,100,1,13.12,200,2,13.11,100,1,13.10,100,1,13.04,2,1,13.40,0,-10,13.45,0,-1,13.46,0,-2,13.47,0,-4,13.48,0,-4,13.49,0,-4,13.50,0,-4,13.51,0,-2,13.52,0,-1,13.53,0,-3,ARL,0
2025-07-17T16:17:58.235788576Z,2025-07-17T16:17:58.235623452Z,10,2,1108,A,A,10,14.680000000,700,344902153,165124,286756143,13.31,10,1,13.28,1,2,13.27,20,2,13.26,198,2,13.14,1,1,13.13,100,1,13.12,200,2,13.11,100,1,13.10,100,1,13.04,2,1,13.40,0,-10,13.45,0,-1,13.46,0,-2,13.47,0,-4,13.48,0,-4,13.49,0,-4,13.50,0,-4,13.51,0,-2,13.52,0,-1,13.53,0,-3,ARL,0
2025-07-17T16:17:58.502856372Z,2025-07-17T16:17:58.502691073Z,10,2,1108,A,A,10,14.530000000,100,344905321,165299,286758830,13.31,10,1,13.28,1,2,13.27,20,2,13.26,198,2,13.14,1,1,13.13,100,1,13.12,200,2,13.11,100,1,13.10,100,1,13.04,2,1,13.40,0,-10,13.45,0,-1,13.46,0,-2,13.47,0,-4,13.48,0,-4,13.49,0,-4,13.50,0,-4,13.51,0,-2,13.52,0,-1,13.53,0,-3,ARL,0
2025-07-17T16:17:58.502858100Z,2025-07-17T16:17:58.502692641Z,10,2,1108,C,A,10,14.010000000,100,344612049,165459,286758831,13.31,10,1,13.28,1,2,13.27,20,2,13.26,198,2,13.14,1,1,13.13,100,1,13.12,200,2,13.11,100,1,13.10,100,1,13.04,2,1,13.40,0,-10,13.45,0,-1,13.46,0,-2,13.47,0,-4,13.48,0,-4,13.49,0,-4,13.50,0,-4,13.51,0,-2,13.52,0,-1,13.53,0,-3,ARL,0
2025-07-17T16:17:58.704865076Z,2025-07-17T16:17:58.704699676Z,10,2,1108,C,A,10,14.360000000,100,344897953,165400,286760091,13.31,10,1,13.28,1,2,13.27,20,2,13.26,198,2,13.14,1,1,13.13,100,1,13.12,200,2,13.11,100,1,13.10,100,1,13.04,2,1,13.40,0,-10,13.45,0,-1,13.46,0,-2,13.47,0,-4,13.48,0,-4,13.49,0,-4,13.50,0,-4,13.51,0,-2,13.52,0,-1,13.53,0,-3,ARL,0
2025-07-17T16:17:58.705216838Z,2025-07-17T16:17:58.705051532Z,10,2,1108,A,A,10,14.600000000,100,344906945,165306,286760096,13.31,10,1,13.28,1,2,13.27,20,2,13.26,198,2,13.14,1,1,13.13,100,1,13.12,200,2,13.11,100,1,13.10,100,1,13.04,2,1,13.40,0,-10,13.45,0,-1,13.46,0,-2,13.47,0,-4,13.48,0,-4,13.49,0,-4,13.50,0,-4,13.51,0,-2,13.52,0,-1,13.53,0,-3,ARL,0
2025-07-17T16:17:59.086439158Z,2025-07-17T16:17:59.086273873Z,10,2,1108,C,A,10,14.540000000,100,344899913,165285,286766349,13.31,10,1,13.28,1,2,13.27,20,2,13.26,198,2,13.14,1,1,13.13,100,1,13.12,200,2,13.11,100,1,13.10,100,1,13.04,2,1,13.40,0,-10,13.45,0,-1,13.46,0,-2,13.47,0,-4,13.48,0,-4,13.49,0,-4,13.50,0,-4,13.51,0,-2,13.52,0,-1,13.53,0,-3,ARL,0
2025-07-17T16:17:59.086561438Z,2025-07-17T16:17:59.086395964Z,10,2,1108,A,A,10,14.770000000,100,344914361,165474,286766355,13.31,10,1,13.28,1,2,13.27,20,2,13.26,198,2,13.14,1,1,13.13,100,1,13.12,200,2,13.11,100,1,13.10,100,1,13.04,2,1,13.40,0,-10,13.45,0,-1,13.46,0,-2,13.47,0,-4,13.48,0,-4,13.49,0,-4,13.50,0,-4,13.51,0,-2,13.52,0,-1,13.53,0,-3,ARL,0
2025-07-17T16:18:02.178629167Z,2025-07-17T16:18:02.178463984Z,10,2,1108,A,A,10,13.800000000,100,344989393,165183,286829047,13.31,10,1,13.28,1,2,13.27,20,2,13.26,198,2,13.14,1,1,13.13,100,1,13.12,200,2,13.11,100,1,13.10,100,1,13.04,2,1,13.40,0,-10,13.45,0,-1,13.46,0,-2,13.47,0,-4,13.48,0,-4,13.49,0,-4,13.50,0,-4,13.51,0,-2,13.52,0,-1,13.53,0,-3,ARL,0
2025-07-17T16:18:02.179379565Z,2025-07-17T16:18:02.179214149Z,10,2,1108,C,A,10,15.050000000,100,344899937,165416,286829057,13.31,10,1,13.28,1,2,13.27,20,2,13.26,198,2,13.14,1,1,13.13,100,1,13.12,200,2,13.11,100,1,13.10,100,1,13.04,2,1,13.40,0,-10,13.45,0,-1,13.46,0,-2,13.47,0,-4,13.48,0,-4,13.49,0,-4,13.50,0,-4,13.51,0,-2,13.52,0,-1,13.53,0,-3,ARL,0
2025-07-17T16:18:02.179379565Z,2025-07-17T16:18:02.179214149Z,10,2,1108,A,A,10,14.870000000,100,344989421,165416,286829057,13.31,10,1,13.28,1,2,13.27,20,2,13.26,198,2,13.14,1,1,13.13,100,1,13.12,200,2,13.11,100,1,13.10,100,1,13.04,2,1,13.40,0,-10,13.45,0,-1,13.46,0,-2,13.47,0,-4,13.48,0,-4,13.49,0,-4,13.50,0,-4,13.51,0,-2,13.52,0,-1,13.53,0,-3,ARL,0
2025-07-17T16:18:02.181473898Z,2025-07-17T16:18:02.181307241Z,10,2,1108,C,A,10,14.960000000,100,344899081,166657,286829106,13.31,10,1,13.28,1,2,13.27,20,2,13.26,198,2,13.14,1,1,13.13,100,1,13.12,200,2,13.11,100,1,13.10,100,1,13.04,2,1,13.40,0,-10,13.45,0,-1,13.46,0,-2,13.47,0,-4,13.48,0,-4,13.49,0,-4,13.50,0,-4,13.51,0,-2,13.52,0,-1,13.53,0,-3,ARL,0
2025-07-17T16:18:02.181473898Z,2025-07-17T16:18:02.181307241Z,10,2,1108,A,A,10,14.770000000,100,344989525,166657,286829106,13.31,10,1,13.28,1,2,13.27,20,2,13.26,198,2,13.14,1,1,13.13,100,1,13.12,200,2,13.11,100,1,13.10,100,1,13.04,2,1,13.40,0,-10,13.45,0,-1,13.46,0,-2,13.47,0,-4,13.48,0,-4,13.49,0,-4,13.50,0,-4,13.51,0,-2,13.52,0,-1,13.53,0,-3,ARL,0
2025-07-17T16:18:02.182474498Z,2025-07-17T16:18:02.182309015Z,10,2,1108,C,A,10,17.760000000,100,344899449,165483,286829137,13.31,10,1,13.28,1,2,13.27,20,2,13.26,198,2,13.14,1,1,13.13,100,1,13.12,200,2,13.11,100,1,13.10,100,1,13.04,2,1,13.40,0,-10,13.45,0,-1,13.46,0,-2,13.47,0,-4,13.48,0,-4,13.49,0,-4,13.50,0,-4,13.51,0,-2,13.52,0,-1,13.53,0,-3,ARL,0
2025-07-17T16:18:02.182474498Z,2025-07-17T16:18:02.182309015Z,10,2,1108,A,A,10,17.530000000,100,344989557,165483,286829137,13.31,10,1,13.28,1,2,13.27,20,2,13.26,198,2,13.14,1,1,13.13,100,1,13.12,200,2,13.11,100,1,13.10,100,1,13.04,2,1,13.40,0,-10,13.45,0,-1,13.46,0,-2,13.47,0,-4,13.48,0,-4,13.49,0,-4,13.50,0,-4,13.51,0,-2,13.52,0,-1,13.53,0,-3,ARL,0
2025-07-17T16:18:02.184788371Z,2025-07-17T16:18:02.184622698Z,10,2,1108,C,A,10,14.250000000,100,344899417,165673,286829173,13.31,10,1,13.28,1,2,13.27,20,2,13.26,198,2,13.14,1,1,13.13,100,1,13.12,200,2,13.11,100,1,13.10,100,1,13.04,2,1,13.40,0,-10,13.45,0,-1,13.46,0,-2,13.47,0,-4,13.48,0,-4,13.49,0,-4,13.50,0,-4,13.51,0,-2,13.52,0,-1,13.53,0,-3,ARL,0
2025-07-17T16:18:02.184840010Z,2025-07-17T16:18:02.184674810Z,10,2,1108,A,A,10,14.080000000,100,344989601,165200,286829174,13.31,10,1,13.28,1,2,13.27,20,2,13.26,198,2,13.14,1,1,13.13,100,1,13.12,200,2,13.11,100,1,13.10,100,1,13.04,2,1,13.40,0,-10,13.45,0,-1,13.46,0,-2,13.47,0,-4,13.48,0,-4,13.49,0,-4,13.50,0,-4,13.51,0,-2,13.52,0,-1,13.53,0,-3,ARL,0
2025-07-17T16:18:02.186910586Z,2025-07-17T16:18:02.186745185Z,10,2,1108,C,A,10,14.770000000,100,344914361,165401,286829206,13.31,10,1,13.28,1,2,13.27,20,2,13.26,198,2,13.14,1,1,13.13,100,1,13.12,200,2,13.11,100,1,13.10,100,1,13.04,2,1,13.40,0,-10,13.45,0,-1,13.46,0,-2,13.47,0,-4,13.48,0,-4,13.49,0,-4,13.50,0,-4,13.51,0,-2,13.52,0,-1,13.53,0,-3,ARL,0
2025-07-17T16:18:02.186910586Z,2025-07-17T16:18:02.186745185Z,10,2,1108,A,A,10,14.590000000,100,344989661,165401,286829206,13.31,10,1,13.28,1,2,13.27,20,2,13.26,198,2,13.14,1,1,13.13,100,1,13.12,200,2,13.11,100,1,13.10,100,1,13.04,2,1,13.40,0,-10,13.45,0,-1,13.46,0,-2,13.47,0,-4,13.48,0,-4,13.49,0,-4,13.50,0,-4,13.51,0,-2,13.52,0,-1,13.53,0,-3,ARL,0
2025-07-17T16:18:02.189536873Z,2025-07-17T16:18:02.189371317Z,10,2,1108,C,A,10,16.080000000,100,344899093,165556,286829251,13.31,10,1,13.28,1,2,13.27,20,2,13.26,198,2,13.14,1,1,13.13,100,1,13.12,200,2,13.11,100,1,13.10,100,1,13.04,2,1,13.40,0,-10,13.45,0,-1,13.46,0,-2,13.47,0,-4,13.48,0,-4,13.49,0,-4,13.50,0,-4,13.51,0,-2,13.52,0,-1,13.53,0,-3,ARL,0
2025-07-17T16:18:02.189536873Z,2025-07-17T16:18:02.189371317Z,10,2,1108,A,A,10,15.870000000,100,344989713,165556,286829251,13.31,10,1,13.28,1,2,13.27,20,2,13.26,198,2,13.14,1,1,13.13,100,1,13.12,200,2,13.11,100,1,13.10,100,1,13.04,2,1,13.40,0,-10,13.45,0,-1,13.46,0,-2,13.47,0,-4,13.48,0,-4,13.49,0,-4,13.50,0,-4,13.51,0,-2,13.52,0,-1,13.53,0,-3,ARL,0
2025-07-17T16:18:02.271602472Z,2025-07-17T16:18:02.271437003Z,10,2,1108,C,A,10,14.960000000,100,344900597,165469,286830984,13.31,10,1,13.28,1,2,13.27,20,2,13.26,198,2,13.14,1,1,13.13,100,1,13.12,200,2,13.11,100,1,13.10,100,1,13.04,2,1,13.40,0,-10,13.45,0,-1,13.46,0,-2,13.47,0,-4,13.48,0,-4,13.49,0,-4,13.50,0,-4,13.51,0,-2,13.52,0,-1,13.53,0,-3,ARL,0
2025-07-17T16:18:02.271602472Z,2025-07-17T16:18:02.271437003Z,10,2,1108,A,A,10,14.770000000,100,344990837,165469,286830984,13.31,10,1,13.28,1,2,13.27,20,2,13.26,198,2,13.14,1,1,13.13,100,1,13.12,200,2,13.11,100,1,13.10,100,1,13.04,2,1,13.40,0,-10,13.45,0,-1,13.46,0,-2,13.47,0,-4,13.48,0,-4,13.49,0,-4,13.50,0,-4,13.51,0,-2,13.52,0,-1,13.53,0,-3,ARL,0
2025-07-17T16:18:44.836233374Z,2025-07-17T16:18:44.836067409Z,10,2,1108,A,A,10,13.470000000,15,345869437,165965,287534438,13.31,10,1,13.28,1,2,13.27,20,2,13.26,198,2,13.14,1,1,13.13,100,1,13.12,200,2,13.11,100,1,13.10,100,1,13.04,2,1,13.40,0,-10,13.45,0,-1,13.46,0,-2,13.47,0,-4,13.48,0,-4,13.49,0,-4,13.50,0,-4,13.51,0,-2,13.52,0,-1,13.53,0,-3,ARL,0
2025-07-17T16:18:45.977564112Z,2025-07-17T16:18:45.977398557Z,10,2,1108,C,A,10,13.800000000,100,344989393,165555,287547865,13.31,10,1,13.28,1,2,13.27,20,2,13.26,198,2,13.14,1,1,13.13,100,1,13.12,200,2,13.11,100,1,13.10,100,1,13.04,2,1,13.40,0,-10,13.45,0,-1,13.46,0,-2,13.47,0,-5,13.48,0,-4,13.49,0,-4,13.50,0,-4,13.51,0,-2,13.52,0,-1,13.53,0,-3,ARL,0
2025-07-17T16:18:45.977564112Z,2025-07-17T16:18:45.977398557Z,10,2,1108,A,A,10,13.480000000,100,345889137,165555,287547865,13.31,10,1,13.28,1,2,13.27,20,2,13.26,198,2,13.14,1,1,13.13,100,1,13.12,200,2,13.11,100,1,13.10,100,1,13.04,2,1,13.40,0,-10,13.45,0,-1,13.46,0,-2,13.47,0,-5,13.48,0,-4,13.49,0,-4,13.50,0,-4,13.51,0,-2,13.52,0,-1,13.53,0,-3,ARL,0
2025-07-17T16:18:45.978304784Z,2025-07-17T16:18:45.978139497Z,10,2,1108,C,A,10,14.600000000,100,344906945,165287,287547870,13.31,10,1,13.28,1,2,13.27,20,2,13.26,198,2,13.14,1,1,13.13,100,1,13.12,200,2,13.11,100,1,13.10,100,1,13.04,2,1,13.40,0,-10,13.45,0,-1,13.46,0,-2,13.47,0,-5,13.48,0,-5,13.49,0,-4,13.50,0,-4,13.51,0,-2,13.52,0,-1,13.53,0,-3,ARL,0
2025-07-17T16:18:45.978307201Z,2025-07-17T16:18:45.978141738Z,10,2,1108,C,A,10,14.870000000,100,344989421,165463,287547871,13.31,10,1,13.28,1,2,13.27,20,2,13.26,198,2,13.14,1,1,13.13,100,1,13.12,200,2,13.11,100,1,13.10,100,1,13.04,2,1,13.40,0,-10,13.45,0,-1,13.46,0,-2,13.47,0,-5,13.48,0,-5,13.49,0,-4,13.50,0,-4,13.51,0,-2,13.52,0,-1,13.53,0,-3,ARL,0
2025-07-17T16:18:45.978307201Z,2025-07-17T16:18:45.978141738Z,10,2,1108,A,A,10,14.530000000,100,345889161,165463,287547871,13.31,10,1,13.28,1,2,13.27,20,2,13.26,198,2,13.14,1,1,13.13,100,1,13.12,200,2,13.11,100,1,13.10,100,1,13.04,2,1,13.40,0,-10,13.45,0,-1,13.46,0,-2,13.47,0,-5,13.48,0,-5,13.49,0,-4,13.50,0,-4,13.51,0,-2,13.52,0,-1,13.53,0,-3,ARL,0
2025-07-17T16:18:45.978659056Z,2025-07-17T16:18:45.978493799Z,10,2,1108,A,A,10,14.080000000,100,345889165,165257,287547872,13.31,10,1,13.28,1,2,13.27,20,2,13.26,198,2,13.14,1,1,13.13,100,1,13.12,200,2,13.11,100,1,13.10,100,1,13.04,2,1,13.40,0,-10,13.45,0,-1,13.46,0,-2,13.47,0,-5,13.48,0,-5,13.49,0,-4,13.50,0,-4,13.51,0,-2,13.52,0,-1,13.53,0,-3,ARL,0
2025-07-17T16:18:45.979197330Z,2025-07-17T16:18:45.979031886Z,10,2,1108,C,A,10,15.130000000,100,344897997,165444,287547882,13.31,10,1,13.28,1,2,13.27,20,2,13.26,198,2,13.14,1,1,13.13,100,1,13.12,200,2,13.11,100,1,13.10,100,1,13.04,2,1,13.40,0,-10,13.45,0,-1,13.46,0,-2,13.47,0,-5,13.48,0,-5,13.49,0,-4,13.50,0,-4,13.51,0,-2,13.52,0,-1,13.53,0,-3,ARL,0
2025-07-17T16:18:45.979197330Z,2025-07-17T16:18:45.979031886Z,10,2,1108,A,A,10,14.830000000,100,345889185,165444,287547882,13.31,10,1,13.28,1,2,13.27,20,2,13.26,198,2,13.14,1,1,13.13,100,1,13.12,200,2,13.11,100,1,13.10,100,1,13.04,2,1,13.40,0,-10,13.45,0,-1,13.46,0,-2,13.47,0,-5,13.48,0,-5,13.49,0,-4,13.50,0,-4,13.51,0,-2,13.52,0,-1,13.53,0,-3,ARL,0
2025-07-17T16:18:45.979453023Z,2025-07-17T16:18:45.979287575Z,10,2,1108,C,A,10,14.770000000,100,344990837,165448,287547885,13.31,10,1,13.28,1,2,13.27,20,2,13.26,198,2,13.14,1,1,13.13,100,1,13.12,200,2,13.11,100,1,13.10,100,1,13.04,2,1,13.40,0,-10,13.45,0,-1,13.46,0,-2,13.47,0,-5,13.48,0,-5,13.49,0,-4,13.50,0,-4,13.51,0,-2,13.52,0,-1,13.53,0,-3,ARL,0
2025-07-17T16:18:45.979453023Z,2025-07-17T16:18:45.979287575Z,10,2,1108,A,A,10,14.430000000,100,345889189,165448,287547885,13.31,10,1,13.28,1,2,13.27,20,2,13.26,198,2,13.14,1,1,13.13,100,1,13.12,200,2,13.11,100,1,13.10,100,1,13.04,2,1,13.40,0,-10,13.45,0,-1,13.46,0,-2,13.47,0,-5,13.48,0,-5,13.49,0,-4,13.50,0,-4,13.51,0,-2,13.52,0,-1,13.53,0,-3,ARL,0
2025-07-17T16:18:45.979897527Z,2025-07-17T16:18:45.979732081Z,10,2,1108,C,A,10,15.870000000,100,344989713,165446,287547887,13.31,10,1,13.28,1,2,13.27,20,2,13.26,198,2,13.14,1,1,13.13,100,1,13.12,200,2,13.11,100,1,13.10,100,1,13.04,2,1,13.40,0,-10,13.45,0,-1,13.46,0,-2,13.47,0,-5,13.48,0,-5,13.49,0,-4,13.50,0,-4,13.51,0,-2,13.52,0,-1,13.53,0,-3,ARL,0
2025-07-17T16:18:45.979897527Z,2025-07-17T16:18:45.979732081Z,10,2,1108,A,A,10,15.510000000,100,345889193,165446,287547887,13.31,10,1,13.28,1,2,13.27,20,2,13.26,198,2,13.14,1,1,13.13,100,1,13.12,200,2,13.11,100,1,13.10,100,1,13.04,2,1,13.40,0,-10,13.45,0,-1,13.46,0,-2,13.47,0,-5,13.48,0,-5,13.49,0,-4,13.50,0,-4,13.51,0,-2,13.52,0,-1,13.53,0,-3,ARL,0
2025-07-17T16:18:45.980137835Z,2025-07-17T16:18:45.979972220Z,10,2,1108,C,A,10,14.770000000,100,344989525,165615,287547890,13.31,10,1,13.28,1,2,13.27,20,2,13.26,198,2,13.14,1,1,13.13,100,1,13.12,200,2,13.11,100,1,13.10,100,1,13.04,2,1,13.40,0,-10,13.45,0,-1,13.46,0,-2,13.47,0,-5,13.48,0,-5,13.49,0,-4,13.50,0,-4,13.51,0,-2,13.52,0,-1,13.53,0,-3,ARL,0
2025-07-17T16:18:45.980137835Z,2025-07-17T16:18:45.979972220Z,10,2,1108,A,A,10,14.430000000,100,345889201,165615,287547890,13.31,10,1,13.28,1,2,13.27,20,2,13.26,198,2,13.14,1,1,13.13,100,1,13.12,200,2,13.11,100,1,13.10,100,1,13.04,2,1,13.40,0,-10,13.45,0,-1,13.46,0,-2,13.47,0,-5,13.48,0,-5,13.49,0,-4,13.50,0,-4,13.51,0,-2,13.52,0,-1,13.53,0,-3,ARL,0
2025-07-17T16:18:45.980197213Z,2025-07-17T16:18:45.980031732Z,10,2,1108,C,A,10,17.530000000,100,344989557,165481,287547891,13.31,10,1,13.28,1,2,13.27,20,2,13.26,198,2,13.14,1,1,13.13,100,1,13.12,200,2,13.11,100,1,13.10,100,1,13.04,2,1,13.40,0,-10,13.45,0,-1,13.46,0,-2,13.47,0,-5,13.48,0,-5,13.49,0,-4,13.50,0,-4,13.51,0,-2,13.52,0,-1,13.53,0,-3,ARL,0
2025-07-17T16:18:45.980197213Z,2025-07-17T16:18:45.980031732Z,10,2,1108,A,A,10,17.120000000,100,345889205,165481,287547891,13.31,10,1,13.28,1,2,13.27,20,2,13.26,198,2,13.14,1,1,13.13,100,1,13.12,200,2,13.11,100,1,13.10,100,1,13.04,2,1,13.40,0,-10,13.45,0,-1,13.46,0,-2,13.47,0,-5,13.48,0,-5,13.49,0,-4,13.50,0,-4,13.51,0,-2,13.52,0,-1,13.53,0,-3,ARL,0
2025-07-17T16:18:45.980205832Z,2025-07-17T16:18:45.980040000Z,10,2,1108,C,A,10,15.380000000,100,344900289,165832,287547892,13.31,10,1,13.28,1,2,13.27,20,2,13.26,198,2,13.14,1,1,13.13,100,1,13.12,200,2,13.11,100,1,13.10,100,1,13.04,2,1,13.40,0,-10,13.45,0,-1,13.46,0,-2,13.47,0,-5,13.48,0,-5,13.49,0,-4,13.50,0,-4,13.51,0,-2,13.52,0,-1,13.53,0,-3,ARL,0
2025-07-17T16:18:45.980205832Z,2025-07-17T16:18:45.980040000Z,10,2,1108,A,A,10,14.830000000,100,345889209,165832,287547892,13.31,10,1,13.28,1,2,13.27,20,2,13.26,198,2,13.14,1,1,13.13,100,1,13.12,200,2,13.11,100,1,13.10,100,1,13.04,2,1,13.40,0,-10,13.45,0,-1,13.46,0,-2,13.47,0,-5,13.48,0,-5,13.49,0,-4,13.50,0,-4,13.51,0,-2,13.52,0,-1,13.53,0,-3,ARL,0
2025-07-17T16:18:45.982963696Z,2025-07-17T16:18:45.982798406Z,10,2,1108,C,A,10,14.590000000,100,344989661,165290,287547919,13.31,10,1,13.28,1,2,13.27,20,2,13.26,198,2,13.14,1,1,13.13,100,1,13.12,200,2,13.11,100,1,13.10,100,1,13.04,2,1,13.40,0,-10,13.45,0,-1,13.46,0,-2,13.47,0,-5,13.48,0,-5,13.49,0,-4,13.50,0,-4,13.51,0,-2,13.52,0,-1,13.53,0,-3,ARL,0
2025-07-17T16:18:45.983098604Z,2025-07-17T16:18:45.982933040Z,10,2,1108,A,A,10,14.270000000,100,345889277,165564,287547921,13.31,10,1,13.28,1,2,13.27,20,2,13.26,198,2,13.14,1,1,13.13,100,1,13.12,200,2,13.11,100,1,13.10,100,1,13.04,2,1,13.40,0,-10,13.45,0,-1,13.46,0,-2,13.47,0,-5,13.48,0,-5,13.49,0,-4,13.50,0,-4,13.51,0,-2,13.52,0,-1,13.53,0,-3,ARL,0
2025-07-17T16:18:45.994306597Z,2025-07-17T16:18:45.994141218Z,10,2,1108,C,A,10,14.080000000,100,344989601,165379,287548000,13.31,10,1,13.28,1,2,13.27,20,2,13.26,198,2,13.14,1,1,13.13,100,1,13.12,200,2,13.11,100,1,13.10,100,1,13.04,2,1,13.40,0,-10,13.45,0,-1,13.46,0,-2,13.47,0,-5,13.48,0,-5,13.49,0,-4,13.50,0,-4,13.51,0,-2,13.52,0,-1,13.53,0,-3,ARL,0
2025-07-17T16:18:45.994356983Z,2025-07-17T16:18:45.994191684Z,10,2,1108,A,A,10,13.750000000,100,345889457,165299,287548002,13.31,10,1,13.28,1,2,13.27,20,2,13.26,198,2,13.14,1,1,13.13,100,1,13.12,200,2,13.11,100,1,13.10,100,1,13.04,2,1,13.40,0,-10,13.45,0,-1,13.46,0,-2,13.47,0,-5,13.48,0,-5,13.49,0,-4,13.50,0,-4,13.51,0,-2,13.52,0,-1,13.53,0,-3,ARL,0
2025-07-17T16:18:46.020770846Z,2025-07-17T16:18:46.020605332Z,10,2,1108,A,A,10,15.370000000,100,345889897,165514,287548308,13.31,10,1,13.28,1,2,13.27,20,2,13.26,198,2,13.14,1,1,13.13,100,1,13.12,200,2,13.11,100,1,13.10,100,1,13.04,2,1,13.40,0,-10,13.45,0,-1,13.46,0,-2,13.47,0,-5,13.48,0,-5,13.49,0,-4,13.50,0,-4,13.51,0,-2,13.52,0,-1,13.53,0,-3,ARL,0
2025-07-17T16:18:46.020783162Z,2025-07-17T16:18:46.020617704Z,10,2,1108,C,A,10,15.680000000,100,344897933,165458,287548309,13.31,10,1,13.28,1,2,13.27,20,2,13.26,198,2,13.14,1,1,13.13,100,1,13.12,200,2,13.11,100,1,13.10,100,1,13.04,2,1,13.40,0,-10,13.45,0,-1,13.46,0,-2,13.47,0,-5,13.48,0,-5,13.49,0,-4,13.50,0,-4,13.51,0,-2,13.52,0,-1,13.53,0,-3,ARL,0
2025-07-17T16:18:46.583802176Z,2025-07-17T16:18:46.583636828Z,10,2,1108,A,A,10,14.280000000,100,345903265,165348,287559115,13.31,10,1,13.28,1,2,13.27,20,2,13.26,198,2,13.14,1,1,13.13,100,1,13.12,200,2,13.11,100,1,13.10,100,1,13.04,2,1,13.40,0,-10,13.45,0,-1,13.46,0,-2,13.47,0,-5,13.48,0,-5,13.49,0,-4,13.50,0,-4,13.51,0,-2,13.52,0,-1,13.53,0,-3,ARL,0
2025-07-17T16:18:46.583815469Z,2025-07-17T16:18:46.583649620Z,10,2,1108,C,A,10,14.810000000,100,344900925,165849,287559119,13.31,10,1,13.28,1,2,13.27,20,2,13.26,198,2,13.14,1,1,13.13,100,1,13.12,200,2,13.11,100,1,13.10,100,1,13.04,2,1,13.40,0,-10,13.45,0,-1,13.46,0,-2,13.47,0,-5,13.48,0,-5,13.49,0,-4,13.50,0,-4,13.51,0,-2,13.52,0,-1,13.53,0,-3,ARL,0
2025-07-17T16:18:46.972854044Z,2025-07-17T16:18:46.972688613Z,10,2,1108,C,A,10,14.530000000,100,344905321,165431,287565224,13.31,10,1,13.28,1,2,13.27,20,2,13.26,198,2,13.14,1,1,13.13,100,1,13.12,200,2,13.11,100,1,13.10,100,1,13.04,2,1,13.40,0,-10,13.45,0,-1,13.46,0,-2,13.47,0,-5,13.48,0,-5,13.49,0,-4,13.50,0,-4,13.51,0,-2,13.52,0,-1,13.53,0,-3,ARL,0
2025-07-17T16:18:46.972855248Z,2025-07-17T16:18:46.972689989Z,10,2,1108,A,A,10,14.010000000,100,345911213,165259,287565225,13.31,10,1,13.28,1,2,13.27,20,2,13.26,198,2,13.14,1,1,13.13,100,1,13.12,200,2,13.11,100,1,13.10,100,1,13.04,2,1,13.40,0,-10,13.45,0,-1,13.46,0,-2,13.47,0,-5,13.48,0,-5,13.49,0,-4,13.50,0,-4,13.51,0,-2,13.52,0,-1,13.53,0,-3,ARL,0
2025-07-17T16:18:47.836167832Z,2025-07-17T16:18:47.836002486Z,10,2,1108,A,A,10,13.450000000,15,345924181,165346,287577128,13.31,10,1,13.28,1,2,13.27,20,2,13.26,198,2,13.14,1,1,13.13,100,1,13.12,200,2,13.11,100,1,13.10,100,1,13.04,2,1,13.40,0,-10,13.45,0,-1,13.46,0,-2,13.47,0,-5,13.48,0,-5,13.49,0,-4,13.50,0,-4,13.51,0,-2,13.52,0,-1,13.53,0,-3,ARL,0
2025-07-17T16:18:47.956236479Z,2025-07-17T16:18:47.956070064Z,10,2,1108,C,A,10,13.480000000,100,345889137,166415,287579474,13.31,10,1,13.28,1,2,13.27,20,2,13.26,198,2,13.14,1,1,13.13,100,1,13.12,200,2,13.11,100,1,13.10,100,1,13.04,2,1,13.40,0,-10,13.45,0,-2,13.46,0,-2,13.47,0,-5,13.48,0,-5,13.49,0,-4,13.50,0,-4,13.51,0,-2,13.52,0,-1,13.53,0,-3,ARL,0
2025-07-17T16:18:47.956236479Z,2025-07-17T16:18:47.956070064Z,10,2,1108,A,A,10,13.460000000,100,345926413,166415,287579474,13.31,10,1,13.28,1,2,13.27,20,2,13.26,198,2,13.14,1,1,13.13,100,1,13.12,200,2,13.11,100,1,13.10,100,1,13.04,2,1,13.40,0,-10,13.45,0,-2,13.46,0,-2,13.47,0,-5,13.48,0,-5,13.49,0,-4,13.50,0,-4,13.51,0,-2,13.52,0,-1,13.53,0,-3,ARL,0
2025-07-17T16:18:47.956614041Z,2025-07-17T16:18:47.956448830Z,10,2,1108,A,A,10,15.680000000,100,345926449,165211,287579583,13.31,10,1,13.28,1,2,13.27,20,2,13.26,198,2,13.14,1,1,13.13,100,1,13.12,200,2,13.11,100,1,13.10,100,1,13.04,2,1,13.40,0,-10,13.45,0,-2,13.46,0,-2,13.47,0,-5,13.48,0,-5,13.49,0,-4,13.50,0,-4,13.51,0,-2,13.52,0,-1,13.53,0,-3,ARL,0
2025-07-17T16:18:47.956628879Z,2025-07-17T16:18:47.956462726Z,10,2,1108,C,A,10,15.370000000,100,345889897,166153,287579592,13.31,10,1,13.28,1,2,13.27,20,2,13.26,198,2,13.14,1,1,13.13,100,1,13.12,200,2,13.11,100,1,13.10,100,1,13.04,2,1,13.40,0,-10,13.45,0,-2,13.46,0,-2,13.47,0,-5,13.48,0,-5,13.49,0,-4,13.50,0,-4,13.51,0,-2,13.52,0,-1,13.53,0,-3,ARL,0
2025-07-17T16:18:47.983287076Z,2025-07-17T16:18:47.983119698Z,10,2,1108,A,A,10,15.350000000,100,345930785,167378,287583059,13.31,10,1,13.28,1,2,13.27,20,2,13.26,198,2,13.14,1,1,13.13,100,1,13.12,200,2,13.11,100,1,13.10,100,1,13.04,2,1,13.40,0,-10,13.45,0,-2,13.46,0,-2,13.47,0,-5,13.48,0,-5,13.49,0,-4,13.50,0,-4,13.51,0,-2,13.52,0,-1,13.53,0,-3,ARL,0
2025-07-17T16:18:47.983312942Z,2025-07-17T16:18:47.983140841Z,10,2,1108,C,A,10,15.680000000,100,345926449,172101,287583076,13.31,10,1,13.28,1,2,13.27,20,2,13.26,198,2,13.14,1,1,13.13,100,1,13.12,200,2,13.11,100,1,13.10,100,1,13.04,2,1,13.40,0,-10,13.45,0,-2,13.46,0,-2,13.47,0,-5,13.48,0,-5,13.49,0,-4,13.50,0,-4,13.51,0,-2,13.52,0,-1,13.53,0,-3,ARL,0
2025-07-17T16:18:51.228439638Z,2025-07-17T16:18:51.228274415Z,10,2,1108,A,A,10,14.180000000,700,345998433,165223,287639434,13.31,10,1,13.28,1,2,13.27,20,2,13.26,198,2,13.14,1,1,13.13,100,1,13.12,200,2,13.11,100,1,13.10,100,1,13.04,2,1,13.40,0,-10,13.45,0,-2,13.46,0,-2,13.47,0,-5,13.48,0,-5,13.49,0,-4,13.50,0,-4,13.51,0,-2,13.52,0,-1,13.53,0,-3,ARL,0
2025-07-17T16:18:51.228516429Z,2025-07-17T16:18:51.228351310Z,10,2,1108,C,A,10,14.680000000,700,344902153,165119,287639437,13.31,10,1,13.28,1,2,13.27,20,2,13.26,198,2,13.14,1,1,13.13,100,1,13.12,200,2,13.11,100,1,13.10,100,1,13.04,2,1,13.40,0,-10,13.45,0,-2,13.46,0,-2,13.47,0,-5,13.48,0,-5,13.49,0,-4,13.50,0,-4,13.51,0,-2,13.52,0,-1,13.53,0,-3,ARL,0
2025-07-17T16:18:57.882365457Z,2025-07-17T16:18:57.882196648Z,10,2,1108,C,A,10,13.470000000,15,345869437,168809,287807679,13.31,10,1,13.28,1,2,13.27,20,2,13.26,198,2,13.14,1,1,13.13,100,1,13.12,200,2,13.11,100,1,13.10,100,1,13.04,2,1,13.40,0,-10,13.45,0,-2,13.46,0,-2,13.47,0,-5,13.48,0,-5,13.49,0,-4,13.50,0,-4,13.51,0,-2,13.52,0,-1,13.53,0,-3,ARL,0
2025-07-17T16:19:04.990890102Z,2025-07-17T16:19:04.990724544Z,10,2,1108,C,A,10,13.790000000,2,344765077,165558,288025773,13.31,10,1,13.28,1,2,13.27,20,2,13.26,198,2,13.14,1,1,13.13,100,1,13.12,200,2,13.11,100,1,13.10,100,1,13.04,2,1,13.40,0,-10,13.45,0,-2,13.46,0,-2,13.47,0,-5,13.48,0,-5,13.49,0,-4,13.50,0,-4,13.51,0,-2,13.52,0,-1,13.53,0,-3,ARL,0
2025-07-17T16:19:04.990890102Z,2025-07-17T16:19:04.990724544Z,10,2,1108,A,A,10,13.720000000,2,346423105,165558,288025773,13.31,10,1,13.28,1,2,13.27,20,2,13.26,198,2,13.14,1,1,13.13,100,1,13.12,200,2,13.11,100,1,13.10,100,1,13.04,2,1,13.40,0,-10,13.45,0,-2,13.46,0,-2,13.47,0,-5,13.48,0,-5,13.49,0,-4,13.50,0,-4,13.51,0,-2,13.52,0,-1,13.53,0,-3,ARL,0
2025-07-17T16:19:08.837286193Z,2025-07-17T16:19:08.837120837Z,10,2,1108,A,A,10,13.430000000,15,346492493,165356,288088546,13.31,10,1,13.28,1,2,13.27,20,2,13.26,198,2,13.14,1,1,13.13,100,1,13.12,200,2,13.11,100,1,13.10,100,1,13.04,2,1,13.40,0,-10,13.45,0,-2,13.46,0,-2,13.47,0,-5,13.48,0,-5,13.49,0,-4,13.50,0,-4,13.51,0,-2,13.52,0,-1,13.53,0,-3,ARL,0
2025-07-17T16:19:11.008353202Z,2025-07-17T16:19:11.008187551Z,10,2,1108,C,A,10,13.460000000,100,345926413,165651,288143215,13.31,10,1,13.28,1,2,13.27,20,2,13.26,198,2,13.14,1,1,13.13,100,1,13.12,200,2,13.11,100,1,13.10,100,1,13.04,2,1,13.40,0,-10,13.43,0,-1,13.45,0,-2,13.46,0,-2,13.47,0,-5,13.48,0,-5,13.49,0,-4,13.50,0,-4,13.51,0,-2,13.52,0,-1,ARL,0
2025-07-17T16:19:11.008353202Z,2025-07-17T16:19:11.008187551Z,10,2,1108,A,A,10,13.440000000,100,346562289,165651,288143215,13.31,10,1,13.28,1,2,13.27,20,2,13.26,198,2,13.14,1,1,13.13,100,1,13.12,200,2,13.11,100,1,13.10,100,1,13.04,2,1,13.40,0,-10,13.43,0,-1,13.45,0,-2,13.46,0,-2,13.47,0,-5,13.48,0,-5,13.49,0,-4,13.50,0,-4,13.51,0,-2,13.52,0,-1,ARL,0
2025-07-17T16:19:11.008765986Z,2025-07-17T16:19:11.008600601Z,10,2,1108,A,A,10,15.680000000,100,346562317,165385,288143223,13.31,10,1,13.28,1,2,13.27,20,2,13.26,198,2,13.14,1,1,13.13,100,1,13.12,200,2,13.11,100,1,13.10,100,1,13.04,2,1,13.40,0,-10,13.43,0,-1,13.45,0,-2,13.46,0,-2,13.47,0,-5,13.48,0,-5,13.49,0,-4,13.50,0,-4,13.51,0,-2,13.52,0,-1,ARL,0
2025-07-17T16:19:11.008779449Z,2025-07-17T16:19:11.008613992Z,10,2,1108,C,A,10,15.350000000,100,345930785,165457,288143225,13.31,10,1,13.28,1,2,13.27,20,2,13.26,198,2,13.14,1,1,13.13,100,1,13.12,200,2,13.11,100,1,13.10,100,1,13.04,2,1,13.40,0,-10,13.43,0,-1,13.45,0,-2,13.46,0,-2,13.47,0,-5,13.48,0,-5,13.49,0,-4,13.50,0,-4,13.51,0,-2,13.52,0,-1,ARL,0
2025-07-17T16:19:11.009089771Z,2025-07-17T16:19:11.008923390Z,10,2,1108,C,A,10,14.530000000,100,345889161,166381,288143233,13.31,10,1,13.28,1,2,13.27,20,2,13.26,198,2,13.14,1,1,13.13,100,1,13.12,200,2,13.11,100,1,13.10,100,1,13.04,2,1,13.40,0,-10,13.43,0,-1,13.45,0,-2,13.46,0,-2,13.47,0,-5,13.48,0,-5,13.49,0,-4,13.50,0,-4,13.51,0,-2,13.52,0,-1,ARL,0
2025-07-17T16:19:11.009089771Z,2025-07-17T16:19:11.008923390Z,10,2,1108,A,A,10,14.480000000,100,346562329,166381,288143233,13.31,10,1,13.28,1,2,13.27,20,2,13.26,198,2,13.14,1,1,13.13,100,1,13.12,200,2,13.11,100,1,13.10,100,1,13.04,2,1,13.40,0,-10,13.43,0,-1,13.45,0,-2,13.46,0,-2,13.47,0,-5,13.48,0,-5,13.49,0,-4,13.50,0,-4,13.51,0,-2,13.52,0,-1,ARL,0
2025-07-17T16:19:11.035380853Z,2025-07-17T16:19:11.035215637Z,10,2,1108,A,A,10,15.330000000,100,346563437,165216,288143789,13.31,10,1,13.28,1,2,13.27,20,2,13.26,198,2,13.14,1,1,13.13,100,1,13.12,200,2,13.11,100,1,13.10,100,1,13.04,2,1,13.40,0,-10,13.43,0,-1,13.45,0,-2,13.46,0,-2,13.47,0,-5,13.48,0,-5,13.49,0,-4,13.50,0,-4,13.51,0,-2,13.52,0,-1,ARL,0
2025-07-17T16:19:11.035392933Z,2025-07-17T16:19:11.035227814Z,10,2,1108,C,A,10,15.680000000,100,346562317,165119,288143791,13.31,10,1,13.28,1,2,13.27,20,2,13.26,198,2,13.14,1,1,13.13,100,1,13.12,200,2,13.11,100,1,13.10,100,1,13.04,2,1,13.40,0,-10,13.43,0,-1,13.45,0,-2,13.46,0,-2,13.47,0,-5,13.48,0,-5,13.49,0,-4,13.50,0,-4,13.51,0,-2,13.52,0,-1,ARL,0
2025-07-17T16:19:20.837507906Z,2025-07-17T16:19:20.837342130Z,10,2,1108,C,A,10,13.450000000,15,345924181,165776,288310746,13.31,10,1,13.28,1,2,13.27,20,2,13.26,198,2,13.14,1,1,13.13,100,1,13.12,200,2,13.11,100,1,13.10,100,1,13.04,2,1,13.40,0,-10,13.43,0,-1,13.45,0,-2,13.46,0,-2,13.47,0,-5,13.48,0,-5,13.49,0,-4,13.50,0,-4,13.51,0,-2,13.52,0,-1,ARL,0
2025-07-17T16:19:26.654075072Z,2025-07-17T16:19:26.653909048Z,10,2,1108,A,A,10,13.410000000,15,346891037,166024,288411319,13.31,10,1,13.28,1,2,13.27,20,2,13.26,198,2,13.14,1,1,13.13,100,1,13.12,200,2,13.11,100,1,13.10,100,1,13.04,2,1,13.40,0,-10,13.43,0,-1,13.45,0,-2,13.46,0,-2,13.47,0,-5,13.48,0,-5,13.49,0,-4,13.50,0,-4,13.51,0,-2,13.52,0,-1,ARL,0
2025-07-17T16:19:27.200595996Z,2025-07-17T16:19:27.200430092Z,10,2,1108,C,A,10,13.440000000,100,346562289,165904,288424564,13.31,10,1,13.28,1,2,13.27,20,2,13.26,198,2,13.14,1,1,13.13,100,1,13.12,200,2,13.11,100,1,13.10,100,1,13.04,2,1,13.40,0,-10,13.41,0,-1,13.43,0,-1,13.45,0,-2,13.46,0,-2,13.47,0,-5,13.48,0,-5,13.49,0,-4,13.50,0,-4,13.51,0,-2,ARL,0
2025-07-17T16:19:27.200595996Z,2025-07-17T16:19:27.200430092Z,10,2,1108,A,A,10,13.420000000,100,346904153,165904,288424564,13.31,10,1,13.28,1,2,13.27,20,2,13.26,198,2,13.14,1,1,13.13,100,1,13.12,200,2,13.11,100,1,13.10,100,1,13.04,2,1,13.40,0,-10,13.41,0,-1,13.43,0,-1,13.45,0,-2,13.46,0,-2,13.47,0,-5,13.48,0,-5,13.49,0,-4,13.50,0,-4,13.51,0,-2,ARL,0
2025-07-17T16:19:27.200986286Z,2025-07-17T16:19:27.200820552Z,10,2,1108,A,A,10,15.680000000,100,346904169,165734,288424568,13.31,10,1,13.28,1,2,13.27,20,2,13.26,198,2,13.14,1,1,13.13,100,1,13.12,200,2,13.11,100,1,13.10,100,1,13.04,2,1,13.40,0,-10,13.41,0,-1,13.43,0,-1,13.45,0,-2,13.46,0,-2,13.47,0,-5,13.48,0,-5,13.49,0,-4,13.50,0,-4,13.51,0,-2,ARL,0
2025-07-17T16:19:27.201000330Z,2025-07-17T16:19:27.200833294Z,10,2,1108,C,A,10,15.330000000,100,346563437,167036,288424570,13.31,10,1,13.28,1,2,13.27,20,2,13.26,198,2,13.14,1,1,13.13,100,1,13.12,200,2,13.11,100,1,13.10,100,1,13.04,2,1,13.40,0,-10,13.41,0,-1,13.43,0,-1,13.45,0,-2,13.46,0,-2,13.47,0,-5,13.48,0,-5,13.49,0,-4,13.50,0,-4,13.51,0,-2,ARL,0
2025-07-17T16:19:27.201378249Z,2025-07-17T16:19:27.201212584Z,10,2,1108,A,A,10,14.190000000,700,346904221,165665,288424582,13.31,10,1,13.28,1,2,13.27,20,2,13.26,198,2,13.14,1,1,13.13,100,1,13.12,200,2,13.11,100,1,13.10,100,1,13.04,2,1,13.40,0,-10,13.41,0,-1,13.43,0,-1,13.45,0,-2,13.46,0,-2,13.47,0,-5,13.48,0,-5,13.49,0,-4,13.50,0,-4,13.51,0,-2,ARL,0
2025-07-17T16:19:27.201777312Z,2025-07-17T16:19:27.201611743Z,10,2,1108,C,A,10,14.560000000,700,282969973,165569,288424585,13.31,10,1,13.28,1,2,13.27,20,2,13.26,198,2,13.14,1,1,13.13,100,1,13.12,200,2,13.11,100,1,13.10,100,1,13.04,2,1,13.40,0,-10,13.41,0,-1,13.43,0,-1,13.45,0,-2,13.46,0,-2,13.47,0,-5,13.48,0,-5,13.49,0,-4,13.50,0,-4,13.51,0,-2,ARL,0
2025-07-17T16:19:27.228463152Z,2025-07-17T16:19:27.228297629Z,10,2,1108,A,A,10,15.300000000,100,346904561,165523,288425148,13.31,10,1,13.28,1,2,13.27,20,2,13.26,198,2,13.14,1,1,13.13,100,1,13.12,200,2,13.11,100,1,13.10,100,1,13.04,2,1,13.40,0,-10,13.41,0,-1,13.43,0,-1,13.45,0,-2,13.46,0,-2,13.47,0,-5,13.48,0,-5,13.49,0,-4,13.50,0,-4,13.51,0,-2,ARL,0
2025-07-17T16:19:27.228473898Z,2025-07-17T16:19:27.228308764Z,10,2,1108,C,A,10,15.680000000,100,346904169,165134,288425149,13.31,10,1,13.28,1,2,13.27,20,2,13.26,198,2,13.14,1,1,13.13,100,1,13.12,200,2,13.11,100,1,13.10,100,1,13.04,2,1,13.40,0,-10,13.41,0,-1,13.43,0,-1,13.45,0,-2,13.46,0,-2,13.47,0,-5,13.48,0,-5,13.49,0,-4,13.50,0,-4,13.51,0,-2,ARL,0
2025-07-17T16:19:28.991308227Z,2025-07-17T16:19:28.991142567Z,10,2,1108,C,B,10,13.030000000,2,343084165,165660,288452523,13.31,10,1,13.28,1,2,13.27,20,2,13.26,198,2,13.14,1,1,13.13,100,1,13.12,200,2,13.11,100,1,13.10,100,1,13.04,2,1,13.40,0,-10,13.41,0,-1,13.43,0,-1,13.45,0,-2,13.46,0,-2,13.47,0,-5,13.48,0,-5,13.49,0,-4,13.50,0,-4,13.51,0,-2,ARL,0
2025-07-17T16:19:28.991308227Z,2025-07-17T16:19:28.991142567Z,10,2,1108,A,B,10,12.950000000,2,346942181,165660,288452523,13.31,10,1,13.28,1,2,13.27,20,2,13.26,198,2,13.14,1,1,13.13,100,1,13.12,200,2,13.11,100,1,13.10,100,1,13.04,2,1,13.40,0,-10,13.41,0,-1,13.43,0,-1,13.45,0,-2,13.46,0,-2,13.47,0,-5,13.48,0,-5,13.49,0,-4,13.50,0,-4,13.51,0,-2,ARL,0
2025-07-17T16:19:30.834459284Z,2025-07-17T16:19:30.834293908Z,10,2,1108,C,A,10,13.410000000,15,346891037,165376,288478995,13.31,10,1,13.28,1,2,13.27,20,2,13.26,198,2,13.14,1,1,13.13,100,1,13.12,200,2,13.11,100,1,13.10,100,1,13.04,2,1,13.40,0,-10,13.41,0,-1,13.43,0,-1,13.45,0,-2,13.46,0,-2,13.47,0,-5,13.48,0,-5,13.49,0,-4,13.50,0,-4,13.51,0,-2,ARL,0
2025-07-17T16:19:30.835008022Z,2025-07-17T16:19:30.834842536Z,10,2,1108,C,A,10,13.420000000,100,346904153,165486,288479015,13.31,10,1,13.28,1,2,13.27,20,2,13.26,198,2,13.14,1,1,13.13,100,1,13.12,200,2,13.11,100,1,13.10,100,1,13.04,2,1,13.40,0,-10,13.41,0,-1,13.43,0,-1,13.45,0,-2,13.46,0,-2,13.47,0,-5,13.48,0,-5,13.49,0,-4,13.50,0,-4,13.51,0,-2,ARL,0
2025-07-17T16:19:30.835569072Z,2025-07-17T16:19:30.835403659Z,10,2,1108,C,A,10,13.430000000,15,346492493,165413,288479032,13.31,10,1,13.28,1,2,13.27,20,2,13.26,198,2,13.14,1,1,13.13,100,1,13.12,200,2,13.11,100,1,13.10,100,1,13.04,2,1,13.40,0,-10,13.41,0,-1,13.43,0,-1,13.45,0,-2,13.46,0,-2,13.47,0,-5,13.48,0,-5,13.49,0,-4,13.50,0,-4,13.51,0,-2,ARL,0
2025-07-17T16:19:32.547487183Z,2025-07-17T16:19:32.547320695Z,10,2,1108,C,A,10,14.180000000,700,345998433,166488,288512762,13.31,10,1,13.28,1,2,13.27,20,2,13.26,198,2,13.14,1,1,13.13,100,1,13.12,200,2,13.11,100,1,13.10,100,1,13.04,2,1,13.40,0,-10,13.41,0,-1,13.43,0,-1,13.45,0,-2,13.46,0,-2,13.47,0,-5,13.48,0,-5,13.49,0,-4,13.50,0,-4,13.51,0,-2,ARL,0
2025-07-17T16:19:32.547527626Z,2025-07-17T16:19:32.547362298Z,10,2,1108,A,A,10,14.440000000,700,347022701,165328,288512763,13.31,10,1,13.28,1,2,13.27,20,2,13.26,198,2,13.14,1,1,13.13,100,1,13.12,200,2,13.11,100,1,13.10,100,1,13.04,2,1,13.40,0,-10,13.41,0,-1,13.43,0,-1,13.45,0,-2,13.46,0,-2,13.47,0,-5,13.48,0,-5,13.49,0,-4,13.50,0,-4,13.51,0,-2,ARL,0
